Workbook
Name Cap_Rate: Assumptions!$C$5
Name HKDCNY: Assumptions!$C$23
Name HKDUSD: Assumptions!$C$22
Name Holding_Period: Assumptions!$C$6
Name Other_Annual_Expense_Percent: Assumptions!#REF!

Sheet Assumptions
B2: Assumptions
B4: Investor Preference | C4: Value | D4: Remarks
B5: Hurdle Cap Rate | C5: 0.04 | D5: typical unlevered hurdle rates range from 4.0%–5.0%
B6: Holding Period | C6: 15
B8: Default Transaction Cost | C8: Value | D8: Remarks
B9: Agency Commissions | C9: 0.01 | D9: 1% of the transaction value for both buyers and sellers;
B10: Transfer Fee | C10: 0.001
B11: Legal Fee | C11: 20000 | D11: 15k-30k normally; 30k-80k for luxury homes or company owned properties.
B12: Property inspection | C12: 5000 | D12: Estimate only
B14: Default NOI tax rate | C14: Value | D14: Remarks
B15: Government Rates | C15: 0.05 | D15: 差餉
B16: Government Rent | C16: 0.03
B17: Maintenance/Repairs/Sinking Fund | C17: 0.08
B18: Vacancy Allowance | C18: 0.02
B19: Exp. Annual Rental Growth rate | C19: 0.02 | D19: Historical HK residential rent CAGR (past 15–20 years): ~2.5–3.5% nominal.
B21: Forex | C21: Value | D21: Remarks
B22: HKDUSD | C22: 7.8
B23: HKDCNY | C23: 0.89
B25: Rateable Value (RV)
B26: as at the valuation reference date, usually October of the prior year
B27: For residential, it's often close to (but not exactly) your expected gross annual rent — typically 80–100% depending on location/condition.
B29: Government Rates
B30: 「住宅物業累進差餉制度」的差餉徵收率，具體如下：
B31: 應課差餉租值為55萬元或以下： | C31: 0.05
B32: 應課差餉租值為55萬元至80萬元： | C32: 0.08
B33: 應課差餉租值為超過80萬元： | C33: 0.12
B34: Simple model: ≈ 5% of gross annual rent (this is a common quick proxy landlords use).
B36: Government Rent (地租或地稅)
B37: 3% of the rateable value
B39: Maintenance / Repairs / Sinking Fund
B40: Typical: 0.5–1.5% of property value per year, or 5–10% of gross rent (higher for older buildings, lower for new ones).
B41: Landlord reality: Many budget 8–10% of gross rent to cover repairs, painting, appliances, minor fixes (tenant damage often recoverable, but not always).
B42: Simple model: Use 8% of gross annual rent as a conservative default.
B44: Vacancy Allowance
B45: Current HK residential vacancy is low in 2025–2026 (strong rental demand from talent schemes and rate cuts), often <5% effective vacancy for good locations/units.
B46: But to be prudent (especially for screening many properties), assume 5–10% vacancy to cover turnover time, bad tenants, or market dips.
B47: Simple model: 5% of gross annual rent (very conservative and easy).
B49: Building Age
... B51: Certificate of Compliance (CC)

Sheet 銀海山莊
B2: Step 1: Gather Basic Property Info | G2: Remarks
B4: Address: | C4: 銀海山莊
B5: Type | C5: Apt.
B6: OP/CC year | C6: 1997
B7: Age | C7: =YEAR(TODAY())-C6 -> 29
B8: Saleable Area (Sqft) | C8: 690
B9: Management Fee ($/Sqft) | C9: 2.5
B10: Holding Period | C10: =Holding_Period -> 15
B12: Step 2: Calculate Market Value with Sales Comparison Approach | G12: Remarks
B14: Scenario | C14: Asking Price | D14: Comparable | E14: IRR Netural Price
B15: Comparable Price/sqft | C15: =C16/C8 -> 18115.942 | D15: 14000 | E15: =E16/C8 -> 13623.188
B16: Price (HKD) | C16: 12500000 | D16: =D15*C$8 -> 9660000 | E16: 9400000
B17: Agency Commissions % | C17: =Assumptions!C9 -> 0.01
B18: Stamp Duty % | C18: 0.0375 | D18: 0.0345 | E18: 0.03
B19: Transfer Fee % | C19: =Assumptions!C10 -> 0.001
B20: Legal | C20: =Assumptions!C11 -> 20000
B21: Inspection Fees | C21: =Assumptions!C12 -> 5000
B22: Other Costs | C22: 150000 | D22: 150000 | E22: 150000 | G22: 香港40年樓齡的舊樓進行強制驗樓及大維修，一般每戶費用約在 HK$30,000 至 HK$150,000 或更高。
B23: Total Consideration | C23: =C16+C16*($C$17+C18+$C$19)+$C$20+$C$21+C22 -> 13281250 | D23: =D16+D16*($C$17+D18+$C$19)+$C$20+$C$21+D22 -> 10274530 | E23: =E16+E16*($C$17+E18+$C$19)+$C$20+$C$21+E22 -> 9960400
B25: Step 3: Calculate Net Operating Income (NOI) | G25: Remarks
B27: Reference Gross Rental Yield | C27: 0.028
B28: Reference market value | C28: =D16 -> 9660000
B29: Implied Monthly Rent (HKD) | C29: =C28*C$27/12 -> 22540
B31: Monthly Management Fee | C31: =C$9*C$8 -> 1725 | D31: =C31/C29 -> 0.076530612
B32: Government Rates | C32: =$C$29*D32 -> 1127 | D32: =Assumptions!C15 -> 0.05
B33: Government Rent | C33: =$C$29*D33 -> 676.2 | D33: =Assumptions!C16 -> 0.03
B34: Maintenance/Repairs/Sinking Fund | C34: =$C$29*D34 -> 1803.2 | D34: =Assumptions!C17 -> 0.08
B35: Old Building Premium Cost | C35: =$C$29*D35 -> 0 | D35: =IF(C$7>=30,4%,0) -> 0
B36: Vacancy Allowance | C36: =$C$29*D36 -> 450.8 | D36: =Assumptions!C18 -> 0.02
B37: Other Monthly Fees | C37: 0 | D37: =C37/C29 -> 0
B38: Monthly NOI (HKD) | C38: =C29-SUM(C31:C37) -> 16757.8 | D38: =C38/C29 -> 0.74346939
B39: Exp. Annual Rental Growth | C39: =Assumptions!C19 -> 0.02
B41: Step 4: Estimate Exit Value | G41: Remarks
B43: Exp. Appreciation % | C43: 0.4 | G43: 景觀好，升值潛力更高
B44: price CAGR | C44: =(1+C43)^(1/C10)-1 -> 0.02268496
B45: Sale price after appreciation | C45: =D16*(1+C$43) -> 13524000
B47: Step 5: Calculate the IRR | G47: Remarks
B49: Scenario | C49: =C14 -> Asking Price | D49: =D14 -> Comparable | E49: =E14 -> IRR Netural Price
B50: Price | C50: =C16 -> 12500000 | D50: =D16 -> 9660000 | E50: =E16 -> 9400000
B51: Total Consideration | C51: =C23 -> 13281250 | D51: =D23 -> 10274530 | E51: =E23 -> 9960400
...

Sheet 早禾坑
B2: Step 1: Gather Basic Property Info | G2: Remarks
B4: Address: | C4: 早禾坑
B5: Type | C5: House
B6: OP/CC year | C6: 1995
B7: Age | C7: =YEAR(TODAY())-C6 -> 31
B8: Saleable Area (Sqft) | C8: 2000
B9: Management Fee ($/Sqft) | C9: 0
B10: Holding Period | C10: =Holding_Period -> 15
B12: Step 2: Calculate Market Value with Sales Comparison Approach | G12: Remarks
B14: Scenario | C14: Asking Price | D14: Comparable | E14: IRR Netural Price
B15: Comparable Price/sqft | C15: =C16/C8 -> 11000 | D15: 10000 | E15: =E16/C8 -> 8583.3582
B16: Price (HKD) | C16: 22000000 | D16: =D15*C$8 -> 20000000 | E16: 17166716
B17: Agency Commissions % | C17: =Assumptions!C9 -> 0.01
B18: Stamp Duty % | C18: 0.0375 | D18: 0.0345 | E18: 0.03
B19: Transfer Fee % | C19: =Assumptions!C10 -> 0.001
B20: Legal | C20: =Assumptions!C11 -> 20000
B21: Inspection Fees | C21: 10000 | G21: 村務驗樓更貴
B22: Other Costs | C22: 150000 | D22: 150000 | E22: 150000 | G22: 香港40年樓齡的舊樓進行強制驗樓及大維修，一般每戶費用約在 HK$30,000 至 HK$150,000 或更高。
B23: Total Consideration | C23: =C16+C16*($C$17+C18+$C$19)+$C$20+$C$21+C22 -> 23247000 | D23: =D16+D16*($C$17+D18+$C$19)+$C$20+$C$21+D22 -> 21090000 | E23: =E16+E16*($C$17+E18+$C$19)+$C$20+$C$21+E22 -> 18050552
B25: Step 3: Calculate Net Operating Income (NOI) | G25: Remarks
B27: Reference Gross Rental Yield | C27: 0.033
B28: Reference market value | C28: =D16 -> 20000000
B29: Implied Monthly Rent (HKD) | C29: =C28*C$27/12 -> 55000
B31: Monthly Management Fee | C31: =C$9*C$8 -> 0 | D31: =C31/C29 -> 0
B32: Government Rates | C32: =$C$29*D32 -> 2750 | D32: =Assumptions!C15 -> 0.05
B33: Government Rent | C33: =$C$29*D33 -> 1650 | D33: =Assumptions!C16 -> 0.03
B34: Maintenance/Repairs/Sinking Fund | C34: =$C$29*D34 -> 1100 | D34: 0.02 | G34: 一般8%，但村屋不交管理費，維護費看物業情況可能較低
B35: Old Building Premium Cost | C35: =$C$29*D35 -> 550 | D35: 0.01
B36: Vacancy Allowance | C36: =$C$29*D36 -> 5500 | D36: 0.1 | G36: 一般2%，但村屋招租更麻煩
B37: Other Monthly Fees | C37: 0 | D37: =C37/C29 -> 0
B38: Monthly NOI (HKD) | C38: =C29-SUM(C31:C37) -> 43450 | D38: =C38/C29 -> 0.79
B39: Exp. Annual Rental Growth | C39: =Assumptions!C19 -> 0.02
B41: Step 4: Estimate Exit Value | G41: Remarks
B43: Exp. Appreciation % | C43: 0.3 | G43: 有游泳池，但早禾坑比較遠
B44: price CAGR | C44: =(1+C43)^(1/C10)-1 -> 0.017644813
B45: Sale price after appreciation | C45: =D16*(1+C$43) -> 26000000
B47: Step 5: Calculate the IRR | G47: Remarks
B49: Scenario | C49: =C14 -> Asking Price | D49: =D14 -> Comparable | E49: =E14 -> IRR Netural Price
B50: Price | C50: =C16 -> 22000000 | D50: =D16 -> 20000000 | E50: =E16 -> 17166716
B51: Total Consideration | C51: =C23 -> 23247000 | D51: =D23 -> 21090000 | E51: =E23 -> 18050552
...

Sheet Quarry bay
B2: Step 1: Gather Basic Property Info
B4: Address: | C4: Quarry bay
B5: Type | C5: Apt.
B6: OP/CC year | C6: 2002
B7: Age | C7: =YEAR(TODAY())-C6 -> 24
B8: Saleable Area (Sqft) | C8: 485
B9: Management Fee ($/Sqft) | C9: 2.2
B10: Holding Period | C10: =Holding_Period -> 15
B12: Step 2: Calculate Market Value with Sales Comparison Approach
B14: Scenario | C14: Asking Price | D14: Comparable | E14: IRR Netural Price
B15: Comparable Price/sqft | C15: =C16/C8 -> 16082.474 | D15: 15500 | E15: =E16/C8 -> 14538.534
B16: Price (HKD) | C16: 7800000 | D16: =D15*C$8 -> 7517500 | E16: 7051188.9
B17: Agency Commissions % | C17: =Assumptions!C9 -> 0.01
B18: Stamp Duty % | C18: 0.03 | D18: 0.03 | E18: 0.03
B19: Transfer Fee % | C19: =Assumptions!C10 -> 0.001
B20: Legal | C20: =Assumptions!C11 -> 20000
B21: Inspection Fees | C21: =Assumptions!C12 -> 5000
B22: Other Costs | C22: 0 | D22: 0 | E22: 0
B23: Total Consideration | C23: =C16+C16*($C$17+C18+$C$19)+$C$20+C22 -> 8139800 | D23: =D16+D16*($C$17+D18+$C$19)+$C$20+D22 -> 7845717.5 | E23: =E16+E16*($C$17+E18+$C$19)+$C$20+E22 -> 7360287.7
B25: Step 3: Calculate Net Operating Income (NOI)
B27: Reference Gross Rental Yield | C27: 0.031
B28: Reference market value | C28: =D16 -> 7517500
B29: Implied Monthly Rent (HKD) | C29: =C28*C$27/12 -> 19420.208
B31: Monthly Management Fee | C31: =C$9*C$8 -> 1067 | D31: =C31/C29 -> 0.054942768
B32: Government Rates | C32: =$C$29*D32 -> 971.01042 | D32: =Assumptions!C15 -> 0.05
B33: Government Rent | C33: =$C$29*D33 -> 582.60625 | D33: =Assumptions!C16 -> 0.03
B34: Maintenance/Repairs/Sinking Fund | C34: =$C$29*D34 -> 1553.6167 | D34: =Assumptions!C17 -> 0.08
B35: Old Building Premium Cost | C35: =$C$29*D35 -> 0 | D35: =IF(C$7>=30,4%,0) -> 0
B36: Vacancy Allowance | C36: =$C$29*D36 -> 388.40417 | D36: =Assumptions!C18 -> 0.02
B37: Other Monthly Fees | C37: 0 | D37: =C37/C29 -> 0
B38: Monthly NOI (HKD) | C38: =C29-SUM(C31:C37) -> 14857.571 | D38: =C38/C29 -> 0.76505723
B39: Exp. Annual Rental Growth | C39: =Assumptions!C19 -> 0.02
B41: Step 4: Estimate Exit Value
B43: Exp. Appreciation % | C43: 0.3
B44: price CAGR | C44: =(1+C43)^(1/C10)-1 -> 0.017644813
B45: Sale price after appreciation | C45: =D16*(1+C$43) -> 9772750
B47: Step 5: Calculate the IRR
B49: Scenario | C49: =C14 -> Asking Price | D49: =D14 -> Comparable | E49: =E14 -> IRR Netural Price
B50: Price | C50: =C16 -> 7800000 | D50: =D16 -> 7517500 | E50: =E16 -> 7051188.9
B51: Total Consideration | C51: =C23 -> 8139800 | D51: =D23 -> 7845717.5 | E51: =E23 -> 7360287.7
...

Sheet 翠荷苑
B2: Step 1: Gather Basic Property Info
B4: Address: | C4: 翠荷苑
B5: Type | C5: Apt.
B6: OP/CC year | C6: 1995
B7: Age | C7: =YEAR(TODAY())-C6 -> 31
B8: Saleable Area (Sqft) | C8: 315
B9: Management Fee ($/Sqft) | C9: 2
B10: Holding Period | C10: =Holding_Period -> 15
B12: Step 2: Calculate Market Value with Sales Comparison Approach
B14: Scenario | C14: Asking Price | D14: Comparable | E14: IRR Netural Price
B15: Comparable Price/sqft | C15: =C16/C8 -> 13587.302 | D15: 13587 | E15: =E16/C8 -> 12262.119
B16: Price (HKD) | C16: 4280000 | D16: =D15*C$8 -> 4279905 | E16: 3862567.5
B17: Agency Commissions % | C17: =Assumptions!C9 -> 0.01
B18: Stamp Duty % | C18: 0.055 | D18: =C18 -> 0.055 | E18: =D18 -> 0.055
B19: Transfer Fee % | C19: =Assumptions!C10 -> 0.001
B20: Legal | C20: =Assumptions!C11 -> 20000
B21: Inspection Fees | C21: =Assumptions!C12 -> 5000
B22: Other Costs | C22: 135000 | D22: 135000 | E22: 135000
B23: Total Consideration | C23: =C16+C16*($C$17+C18+$C$19)+$C$20+C22 -> 4717480 | D23: =D16+D16*($C$17+D18+$C$19)+$C$20+D22 -> 4717378.7 | E23: =E16+E16*($C$17+E18+$C$19)+$C$20+E22 -> 4272497
B25: Step 3: Calculate Net Operating Income (NOI)
B27: Reference Gross Rental Yield | C27: 0.042057008
B28: Reference market value | C28: =D16 -> 4279905
B29: Implied Monthly Rent (HKD) | C29: =C28*C$27/12 -> 15000
B31: Monthly Management Fee | C31: =C$9*C$8 -> 630 | D31: =C31/C29 -> 0.042
B32: Government Rates | C32: =$C$29*D32 -> 750 | D32: =Assumptions!C15 -> 0.05
B33: Government Rent | C33: =$C$29*D33 -> 450 | D33: =Assumptions!C16 -> 0.03
B34: Maintenance/Repairs/Sinking Fund | C34: =$C$29*D34 -> 1200 | D34: =Assumptions!C17 -> 0.08
B35: Old Building Premium Cost | C35: =$C$29*D35 -> 600 | D35: =IF(C$7>=30,4%,0) -> 0.04
B36: Vacancy Allowance | C36: =$C$29*D36 -> 300 | D36: =Assumptions!C18 -> 0.02
B37: Other Monthly Fees | C37: 0 | D37: =C37/C29 -> 0
B38: Monthly NOI (HKD) | C38: =C29-SUM(C31:C37) -> 11070 | D38: =C38/C29 -> 0.738
B39: Exp. Annual Rental Growth | C39: =Assumptions!C19 -> 0.02
B41: Step 4: Estimate Exit Value
B43: Exp. Appreciation % | C43: 0
B44: price CAGR | C44: =(1+C43)^(1/C10)-1 -> 0
B45: Sale price after appreciation | C45: =D16*(1+C$43) -> 4279905
B47: Step 5: Calculate the IRR
B49: Scenario | C49: =C14 -> Asking Price | D49: =D14 -> Comparable | E49: =E14 -> IRR Netural Price
B50: Price | C50: =C16 -> 4280000 | D50: =D16 -> 4279905 | E50: =E16 -> 3862567.5
B51: Total Consideration | C51: =C23 -> 4717480 | D51: =D23 -> 4717378.7 | E51: =E23 -> 4272497
...

Sheet Logic_Summary
B2: How to Analyze a Property Investment Using IRR | D2: 如何使用 IRR 分析物業投資
B4: Core logic: The return comes from two main parts: stable rental income + capital appreciation during the holding period. The lower the purchase price, the higher the rental growth, or the greater the price appreciation, the higher the IRR will be. | D4: 核心邏輯：回報來自兩部分——穩定租金收入+持有期資本增值。 購入價越低、租金增長或價格升幅越大，IRR 越高。
B6: Step 1: Gather Basic Property Info List the key details. The historical and latest Gross rental yield can be found in Rating and Valuation Department's Property Market Statistics. Expected gross rental yield (annual rent as % of market value). Monthly costs (management fees, other ongoing expenses). How long you plan to hold the property Expected total price growth by the end (e.g., percentage increase over the hold period). | D6: 步驟 1：收集基本物業資料 列出以下關鍵信息： 歷史及最新「毛租金回報率」（Gross Rental Yield），可於差餉物業估價署的《物業市場統計》查閱。 預期毛租金回報率（年租金佔市值百分比）。 每月開支（管理費 + 其他持續性費用）。 計劃持有物業的年期。 預期持有期結束時的總價格增長（例如百分比升幅）。
B8: Step 2: Calculate Market Value and Total Consideration to buy Current Market value = Comparable price/sqft * Saleable Area For the Total consideration, start with the purchase price. Add buyer costs: agent commission, stamp duty/taxes, transfer fees, legal/inspection fees. Total consideration = Full acquisition cost (your initial cash outflow). | D8: 步驟 2：計算市值及總購入成本（Total Consideration） 當前市值 = 可比單位呎價 × 實用面積 總購入成本從購入價開始計算： 購入價 + 買家成本 = 總購入成本（即你最初的現金流出）
B10: Step 3: Calculate Net Operating Income (NOI) This is the money left after expenses but before taxes or debt. Estimate annual gross rent = Market value × gross Rental yield. Subtract annual expenses (management + other fees). Result = Annual NOI (your net cash flow each year from rent). | D10: 步驟 3：計算淨營運收入（Net Operating Income，NOI） 這是扣除開支後、但未計稅項或按揭的淨收入。 估計年總租金 = 市值 × 毛租金回報率 減去年開支（管理費 + 其他費用） 結果 = 年 NOI（即每年從租金得到的淨現金流）
B13: Step 4: Estimate Exit Value (Sale Price at End) Apply expected growth to the current market value (not your purchase price). Exit value = Market value × (1 + total growth %). This assumes the property’s value grows over time, regardless of what you paid. | D13: 步驟 4：估計退出價值（最終售價） 將預期增長率應用於當前市值（而不是你付出的購入價）。 退出價值 = 市值 × (1 + 總增長百分比) 這假設物業價值會隨時間增長，與你實際付出的價格無關。
B15: Step 5: Calculate the IRR Imagine the money going in and out over the holding years. IRR is the annual return that makes the total value of all cash flows equal zero today. Year 0: Pay the full acquisition cost (negative amount). Each year 1 to (hold period - 1): Receive annual NOI (positive). Final year: Receive annual NOI + exit sale price (big positive). No debt or major repairs assumed — keep it simple. | D15: 步驟 5：計算 IRR 想像整個持有期間的現金流入流出： 第 0 年：支付總購入成本（負數） 第 1 年至（持有年期 - 1）年：每年收到 NOI（正數） 最後一年：收到當年 NOI + 退出售價（大額正數） IRR 就是令所有現金流的現值總和等於零的年化回報率。 （無按揭、無大額維修假設 — 保持簡單）
B17: Step 8: Compare IRR to Your Target Return (Hurdle Rate) Decide your minimum required annual return (based on risk and other options). If IRR > hurdle → Good deal (expected to beat your target). If IRR = hurdle → Neutral. If IRR < hurdle → Not worth it. | D17: 步驟 6：將 IRR 與你的目標回報率（Hurdle Rate）比較 決定你對此風險水平的最低可接受年回報率（根據風險及其他投資選擇）。 IRR > 目標回報率 → 好投資（預期能超越你的要求） IRR = 目標回報率 → 中性 IRR < 目標回報率 → 不值得投資
