Workbook
Name benchmark: Portfolio_Mgmt!$C$10
Name Cash_Yield: Portfolio_Mgmt!$C$11

Sheet Portfolio_Mgmt
A1: Portfolio Management Plan
A2: Executive Summary
B4: Guidance Note: This plan deploys capital into investments exceeding the benchmark return while strategically reserving cash for future opportunities.
A6: i. | B6: Market Benchmarks
B7: Objective: Determine the optimal capital allocation at current market prices, while reserving capital for strategic deployment.
B9: Key Metrics:
B10: Benchmark Return | C10: =Market_Yield!D16 -> 0.087
B11: Cash Yield | C11: =Market_Yield!C5 -> 0.019
B12: Base Cost of Equity | C12: 0.0725
B14: Cost of Equity: This plan employs a value investing framework, defining true risk as the potential for permanent capital loss due to deteriorating business fundamentals or overvaluation, rather than short-term price volatility (beta). The model uses a standardized base cost of equity as the discount rate in DCF analysis,which serves as the minimum acceptable long-term return threshold, reflecting long-term risk-free rates plus an equity risk premium to account for ownership risks.
B16: Key Calculation:
B17: Market Annual Return (R_i) | C17: Imported from Valuation models to Opportunities Sheet
B18: Excess Return over Benchmark (ERB_i) | C18: = R_i - Benchmark Return
B19: Excess Return over Cash (ERC_i) | C19: = R_i - Cash Yield
B21: Decision Rules:
B22: - Only investments with ERB > 0 and Market Price <= Entry Price are eligible for portfolio allocation.
B23: - Non-selected investments receive 50% of normal allocation.
B24: - Cash reserve is determined by Risk Appetite Score (Step 1) and Portfolio Allocation (Step 2).
A26: ii. | B26: Diversification Rules
B27: Objective: Balance conviction with risk mitigation.
B29: Portfolio Limits | C29: Cap
B30: Maximum Number of Holdings | C30: 6
B31: Single Investment Cap | C31: 0.3
A33: iii. | B33: Valuation Model Assumptions
B35: Assumptions | C35: Cap
B36: Lock-Up Period | C36: 3
B37: Valuation Confidence (p) | C37: 0.55
B38: Expected Loss if wrong (l) | C38: -0.75
B40: Key Definitions:
B41: Valuation Confidence (p): Probability of intrinsic value accuracy.
A43: iii. | B43: Allocation Strategy (Full Kelly)
B45: Parameter
B46: Target Yield | C46: 0.3
B47: Entry Yield | C47: 0.2
B49: Key Definitions:
B50: Expected Return (g): Annualized return over lock-up period at target/entry price when the intrinsic value is correct.
B51: Expected Loss (l): Annualized loss at target/entry price when the intrinsic value is incorrect.
A53: Step 1: Determine Risk Appetite & Cash Reserve
B55: Process: Calculate a Risk Appetite Score (0–10 scale) using four market indicators to set cash reserves.
B57: Cash Allocation Rule:
...

Sheet Opportunities
B1: Stock Monitor | D1: Price | H1: Valuation | K1: Execution | M1: Yield | O1: ROE Analysis | S1: Balance Sheet Strength | V1: Others
B2: Symbol | C2: Name | D2: Price | E2: CCY | F2: Market Yield | G2: Allocation Weight | H2: Target Price | I2: Equity Value | J2: Sell Price | K2: Entry Price | L2: Exit Price | M2: FCFE Yield | N2: Dividend Yield | O2: ROE | P2: Profit/ Sales | Q2: Sales/ Assets | R2: Assets/ Equity | S2: Debt/ Equity | T2: Debt/EBIT | U2: Realizable Value | V2: Comp Group | W2: Growth Classification | X2: Update Required After | Y2: Selected
B3: 000568.SZ | C3: 泸州老窖 | D3: 101.2 | E3: CNY | F3: 0.23274778 | G3: 0.054521391 | H3: 86.739442 | I3: 174.07668 | J3: 151.90347 | K3: 109.44449 | L3: 146.05268 | M3: 0.088483646 | N3: 0.040837945 | O3: 0.37772086 | P3: 0.56520395 | Q3: 0.44445275 | R3: 1.5036272 | S3: 0.058904841 | T3: 0.15503079 | U3: 12.727735 | V3: CNS_01 | W3: Low growth | X3: 46081 | Y3: N
B4: 000858.SZ | C4: 五粮液 | D4: 101.86 | E4: CNY | F4: 0.16424302 | G4: 0 | H4: 73.775725 | I4: 150.70539 | J4: 129.61296 | K4: 93.221662 | L4: 124.59668 | M4: 0.075376235 | N4: 0.028000196 | O4: 0.28867574 | P4: 0.46657784 | Q4: 0.46105525 | R4: 1.3419403 | S4: 0.0014942694 | T4: 0.0051971735 | U4: 24.855396 | V4: CNS_01 | W4: Lower than Inflation rate | X4: 46081 | Y4: N
B5: 603279.SS | C5: 景津装备 | D5: 18.73 | E5: CNY | F5: 0.11129442 | G5: 0 | H5: 12.010834 | I5: 22.158402 | J5: 20.73078 | K5: 15.05602 | L5: 19.949995 | M5: 0.074549936 | N5: 0.0565937 | O5: 0.23262925 | P5: 0.17509285 | Q5: 0.68288968 | R5: 1.9455633 | S5: 0.04338035 | T5: 0.18538213 | U5: -0.4502682 | V5: CNS_01 | W5: Lower than Inflation rate | X5: 46081 | Y5: N

Sheet 投资组合管理
A1: 投资组合管理计划
A2: 执行摘要
B4: 指引说明：本计划将资本配置于超越基准回报的投资标的，同时战略性地保留现金以捕捉未来机会。
A6: i. | B6: 市场基准
B7: 目标：在现行市场价格下确定最优资本配置方案，同时预留战略配置资金。
B9: 核心指标：
B10: 基准回报率 | C10: =benchmark -> 0.087
B11: 现金收益率 | C11: =Cash_Yield -> 0.019
B13: 关键计算公式:
B14: 市场年化回报率(R_i) | C14: 从估值模型导入至机会清单
B15: 超额基准回报(ERB_i) | C15: = R_i - 基准回报率
B16: 超额现金回报(ERC_i) | C16: = R_i - 现金收益率
B18: 决策规则:
B19: - 仅当ERB>0且市场价格≤入场价格时具备配置资格
B20: - 未入选标的获得正常配置额的50%
B21: - 现金储备比例由风险偏好评分(步骤1)和组合配置(步骤2)共同决定
A23: ii. | B23: 分散化规则
B24: 目标：在投资确信度与风险缓释间取得平衡
B26: 组合限制 | C26: 上限
B27: 最大持仓数量 | C27: =Portfolio_Mgmt!C30 -> 6
B28: 单一标的配置上限 | C28: =Portfolio_Mgmt!C31 -> 0.3
A30: iii. | B30: 估值模型假设
B31: 参数 | C31: 数值 | D31: 指标 | E31: 数值
B32: 估值置信度(p) | C32: =Portfolio_Mgmt!C46 -> 0.3 | D32: 错误时预期损失(L) | E32: =Portfolio_Mgmt!E46 -> 0
B33: 目标价回报率(w) | C33: =Portfolio_Mgmt!C47 -> 0.2 | D33: Half Kelly配置 | E33: =(C32*C33+(1-C32)*C34)/(2*C33) -> 0.5
B34: 目标价亏损(l) | C34: =E32+C33 -> 0.2 | D34: 赔率(w/l) | E34: =-C33/C34 -> -1
B35: 入场价回报率(w) | D35: Half Kelly配置
B36: 入场价亏损(l) | D36: 赔率(w/l)
B37: 锁定期 | D37: 基础Cost of Equity
B39: 关键定义:
B40: 估值置信度(p)：内在价值估算准确的概率
B41: 预期损失(L)：内在价值误判时的预期下行偏差
B42: 预期回报(w)：内在价值正确时，按目标/入场价计算的锁定期年化回报
B43: 预期亏损(l)：内在价值错误时，按目标/入场价计算的年化损失
B44: Cost of Equity: 本计划采用价值投资框架，真实风险定义为因基本面恶化或高估值导致的永久性资本损失（而非短期价格波动）。因此，模型采用标准化的Cost of Equity作为DCF贴现率，反映长期无风险利率叠加股权风险溢价的所有权风险补偿要求。
A46: 步骤一：风险偏好与现金储备确定
B48: 流程：通过四大市场指标计算风险偏好评分(0-10分制)，据此设定现金储备比例
B50: 现金配置规则:
B52: 情景 | C52: 最低现金储备
B53: 评分 ≤ 4 | C53: =Portfolio_Mgmt!C60 -> 0.45
...

Sheet Aux>
B1: Allocation Analysis
B3: Goal: Use Kelly's forumla to determine the allocation during your investment horizon.
A5: i. | B5: Valuation Model Assumptions
B6: Metric | C6: Value
B7: Lock-Up Period | C7: =Portfolio_Mgmt!C36 -> 3
B8: Valuation Confidence (p) | C8: 0.6 | D8: Conservatively estimated from experience
B9: q | C9: =1-C8 -> 0.4
B10: Expected Loss if wrong (l) | C10: =Portfolio_Mgmt!C38 -> -0.75
B12: Key Definitions:
B13: Valuation Confidence (p): Probability of intrinsic value accuracy.
B14: Expected Loss (L): the expected downside deviation between the real intrinsic value and the estimated intrinsic value
A16: ii. | B16: Return Targets
B17: Target Returns | C17: Expected annual Gains if right | D17: Expected total Gain if right (g) | E17: Gain/Loss Ratio (b)
B18: Target Return | C18: 0.26 | D18: =(1 + C18) ^ C$7-1 -> 1.000376 | E18: =-D18/C$10 -> 1.3338347
B19: Entry Return | C19: =Portfolio_Mgmt!C47 -> 0.2 | D19: =(1 + C19) ^ C$7-1 -> 0.728 | E19: =-D19/C$10 -> 0.97066667
A21: iii.
B22: Target Prices | C22: Full Kelly Allocation | D22: Half Kelly Allocation
B23: Target Price Allocation | C23: =(E18*C$8-C9)/E18 -> 0.30011276 | D23: =C23/2 -> 0.15005638
B24: Entry Price Allocation | C24: =(E19*C$8-(1-C$8))/E19 -> 0.18791209 | D24: =C24/2 -> 0.093956044

Sheet Market_Yield
B1: Market Yields Tracker
B2: Market Yields:
C3: Riskfree rate | D3: Prime Rate | E3: Risk Premium
B4: US | C4: 0.0432 | D4: 0.0675 | E4: =D4-C4 -> 0.0243
B5: China | C5: 0.019 | D5: 0.031 | E5: =D5-C5 -> 0.012
B6: HK | C6: 0.0345 | D6: 0.0525 | E6: =D6-C6 -> 0.018
B8: Benchmarket Return:
B9: Historical Avg Return | C9: US (1928-2024)
B10: Stocks | C10: 0.0994
B11: Small caps | C11: 0.1174
B12: Bonds | C12: 0.0345
B13: Cash | C13: 0.0331
B14: Real estate | C14: 0.0423
B15: Gold | C15: 0.0512
B16: Benchmarket Return | C16: =MAX(Portfolio_Mgmt!C12,C10:C15) -> 0.1174 | D16: 0.087
B18: Notes
B19: US 10Y Treasury yield | C19: https://fred.stlouisfed.org/series/DGS10
B20: US Fed Fund Rate | C20: https://fred.stlouisfed.org/series/FEDFUNDS
B21: Bank Prime Loan Rate | C21: https://fred.stlouisfed.org/series/DPRIME
B23: CN 10Y Government Bond Yield | C23: https://tradingeconomics.com/china/government-bond-yield
B24: CN Loan Prime Rate | C24: https://tradingeconomics.com/china/interest-rate
B26: HK 10Y Government Bond Yield | C26: https://tradingeconomics.com/hong-kong/government-bond-yield
B27: HK Prime Lending Rate | C27: https://tradingeconomics.com/hong-kong/bank-lending-rate
B29: All-in-One Bond Prices | C29: https://tradingeconomics.com/bonds
B31: Historical Returns | C31: https://awealthofcommonsense.com/2025/01/historical-returns-for-stocks-bonds-cash-real-estate-and-gold/

Sheet Holdings
B1: Current Holdings
B2: Symbol | C2: Company Name | D2: Market Price | E2: Price Currency | F2: Number of Shares | G2: Market Value (HKD) | H2: Actual % | I2: Allocation Weight | J2: Entry Price | K2: Target Price | L2: Exit Price | M2: Sell Price
B3: Cash | D3: nm | E3: HKD | F3: nm | G3: 500000 | H3: =G3/$G$6 -> 1 | I3: =Portfolio_Mgmt!E73 -> 0.3 | J3: nm | K3: nm | L3: nm | M3: nm
B4: 000568.SZ | C4: =VLOOKUP(B4,Opportunities!B$3:E$30,2,FALSE) -> 泸州老窖 | D4: =VLOOKUP(B4,Opportunities!B$3:E$30,3,FALSE) -> 101.2 | E4: =VLOOKUP(B4,Opportunities!B$3:E$30,4,FALSE) -> CNY | F4: 0 | G4: =D4*F4 -> 0 | H4: =G4/$G$6 -> 0 | I4: =VLOOKUP(B4,Opportunities!B$3:G$30,6,FALSE) -> 0.054521391 | J4: =VLOOKUP(B4,Opportunities!B$3:L$30,10,FALSE) -> 109.44449 | K4: =VLOOKUP(B4,Opportunities!B$3:L$30,7,FALSE) -> 86.739442 | L4: =VLOOKUP(B4,Opportunities!B$3:L$30,9,FALSE) -> 151.90347 | M4: =VLOOKUP(B4,Opportunities!B$3:L$30,11,FALSE) -> 146.05268
F6: Total Value | G6: =SUM(G3:G4) -> 500000 | H6: =SUM(H3:H4) -> 1 | I6: =SUM(I3:I4) -> 0.35452139 | J6: nm | K6: nm | L6: nm | M6: nm
B8: Planning
B9: 000568.SZ | C9: =VLOOKUP(B9,Opportunities!B$3:E$30,2,FALSE) -> 泸州老窖 | D9: =VLOOKUP(B9,Opportunities!B$3:E$30,3,FALSE) -> 101.2 | E9: =VLOOKUP(B9,Opportunities!B$3:E$30,4,FALSE) -> CNY | F9: 200 | G9: =-D9*F9 -> -20240 | H9: =-G9/$G$6 -> 0.04048 | I9: =VLOOKUP(B9,Opportunities!B$3:G$30,6,FALSE) -> 0.054521391 | J9: =VLOOKUP(B9,Opportunities!B$3:L$30,10,FALSE) -> 109.44449 | K9: =VLOOKUP(B9,Opportunities!B$3:L$30,7,FALSE) -> 86.739442 | L9: =VLOOKUP(B9,Opportunities!B$3:L$30,9,FALSE) -> 151.90347 | M9: =VLOOKUP(B9,Opportunities!B$3:L$30,11,FALSE) -> 146.05268
B11: End. Cash Balance | D11: nm | E11: HKD | F11: nm | G11: =G3+SUM(G9:G9) -> 479760 | H11: =G11/$G$6 -> 0.95952 | I11: =Portfolio_Mgmt!E73 -> 0.3 | J11: nm | K11: nm | L11: nm | M11: nm
B13: Forex Cost
C14: From | D14: HKDUSD | F14: To
B15: HKD to USD | C15: 200000 | D15: 7.86297 | F15: =C15/D15 -> 25435.681
B16: USD to HKD | C16: =F15 -> 25435.681 | D16: 7.8387 | F16: =C16*D16 -> 199382.68
E18: Est. Cost | F18: =C15-F16 -> 617.32399

Sheet Comp_Group
B1: Guidance Note: Comparison Group Classification System
B2: Overview
B3: The classification uses two mutually exclusive and collectively exhaustive (MECE) layers:
B5: - Layer 1: Broad industry categories (3-character codes).
B6: - Layer 2: Granular subcategories (two-digit numbers, 01–99).
B8: Format: [Layer 1 Code]_[Layer 2 Number] (e.g., TMT_02, CNS_10).
B10: Layer 1: Broad Industry Categories
B11: Purpose: Group investments by overarching industries.
B12: Structure: 3-character codes (e.g., TMT, CNS, FIN).
B14: 9 Standard Industry Codes:
B16: Code | C16: Industry
B17: TMT | C17: Technology, Media, Telecom
B18: CNS | C18: Consumer
B19: FIN | C19: Financials
B20: HLT | C20: Healthcare
B21: IND | C21: Industrials
B22: ENG | C22: Energy
B23: MAT | C23: Materials
B24: RES | C24: Real Estate
B25: UTL | C25: Utilities
B27: Layer 2: Subcategory Numbering
B28: Purpose: Refine peer groups into specific segments within Layer 1 industries.
B29: Purpose: Two-digit numbers (01–99), appended to Layer 1 codes (e.g., TMT_01).
B31: Assigning Classifications
A32: i. | B32: Identify Layer 1:
B33: Map the investment to the broadest applicable industry (e.g., a fintech firm → FIN).
A35: ii. | B35: Assign Layer 2:
B36: Select the most specific subcategory number (e.g., fintech → FIN_10).
B38: Use Cases
B39: Peer Benchmarking: Compare HLT_03 (Biotech) companies against each other.
B40: Portfolio Analysis: Aggregate exposures by Layer 1 (e.g., “30% of portfolio is in TMT”).
B41: Reporting: Standardize disclosures using codes (e.g., “Investment X (CNS_05) outperformed peers”).
