Workbook
Name benchmark: Portfolio_Mgmt!$C$10
Name Cash_Yield: Portfolio_Mgmt!$C$11

Sheet Portfolio_Mgmt
A1: Portfolio Management Plan
A2: Executive Summary
B4: Guidance Note: This plan deploys capital into investments exceeding the benchmark return while strategically reserving cash for future opportunities.
A6: i. | B6: Market Benchmarks
B7: Objective: Determine the optimal capital allocation at current market prices, while reserving capital for strategic deployment.
B9: Key Metrics:
B10: Benchmark Return | C10: =Market_Yield!C16 -> 0.1174
B11: Cash Yield | C11: =Market_Yield!C6 -> 0.0345
B13: Key Calculation:
B14: Market Annual Return (R_i) | C14: Imported from Valuation models to Opportunities Sheet
B15: Excess Return over Benchmark (ERB_i) | C15: = R_i - Benchmark Return
B16: Excess Return over Cash (ERC_i) | C16: = R_i - Cash Yield
B18: Decision Rules:
B19: - Only investments with the Selected Flag are eligible for portfolio allocation.
B20: - Only investments with ERB > 0 are eligible for portfolio allocation.
B21: - Cash reserve is determined by Risk Appetite Score (Step 1) and Portfolio Allocation (Step 2).
A23: ii. | B23: Diversification Rules
B24: Objective: Balance high-conviction bets with diversification rules.
B26: Portfolio Limits | C26: Cap
B27: Maximum Number of Holdings | C27: 6
B28: Single Investment Cap | C28: 0.3
B30: Growth Classification Limits | C30: Cap
B31: Negative or Low Growth | C31: =C27-C32 -> 5
B32: High Growth | C32: 1
A34: iii. | B34: Valuation Model Assumptions
B35: Target Annual Return | C35: 0.3 | D35: assuming a Lock-up period of | E35: 3
B36: Base Cost of Equity | C36: =MAX(8%,Market_Yield!C4:D6) -> 0.08 | D36: open a position at a yield of | E36: 0.2
B38: Notes:
B39: Target Annual Return: The target return reflects the investor’s hurdle rate over the lock-up period.
B40: Cost of Equity: This plan employs a value investing framework, defining true risk as the potential for permanent capital loss due to deteriorating business fundamentals or overvaluation, rather than short-term price volatility (beta). The model uses a standardized base cost of equity as the discount rate in DCF analysis,which serves as the minimum acceptable long-term return threshold, reflecting long-term risk-free rates plus an equity risk premium to account for ownership risks.
A42: Step 1: Determine Risk Appetite & Cash Reserve
B44: Process: Calculate a Risk Appetite Score (0–8 scale) using four market indicators to set cash reserves.
B46: Cash Allocation Rule:
B48: Scenario | C48: Min. Cash Reserve
B49: Score <= 2 | C49: 0.6
B50: Score 3–5 | C50: 0.4
B51: Score >= 6 | C51: 0.3 | D51: Strategic reserve for compelling opportunities.
B53: Indicators and Scoring:
B55: Indicator | C55: Low Risk Appetite (Hold Cash) | D55: High Risk Appetite (Deploy Cash) | E55: Score (0-2)
B56: 1. Market P/E Ratio | C56: > Historical 75th percentile | D56: < Historical 25th percentile | E56: 1
...

Sheet Opportunities
B1: Stock Monitor | D1: Price | G1: Portfolio Management | J1: Valuation | L1: Execution | N1: Yield | P1: Balance Sheet Strength | T1: Others
B2: Symbol | C2: Name | D2: Price | E2: Currency | F2: Market Annual Yield | G2: ERB | H2: ERC | I2: Allocation Weight | J2: Target Price | K2: Equity Value | L2: Entry Price | M2: Sell Price | N2: FCFE Yield | O2: Dividend Yield | P2: Liabilities/ Equity | Q2: Debt/ Equity | R2: Debt/EBIT | S2: Realizable Value | T2: Comp Group | U2: Growth Classification | V2: Update Required After | W2: Selected
B3: 9959.HK | C3: 聯易融科技 | D3: 1.16 | E3: HKD | F3: 0.21955254 | G3: =F3 - Portfolio_Mgmt!$C$10 -> 0.10215254 | H3: =F3 - Portfolio_Mgmt!$C$11 -> 0.18505254 | I3: 0.21955254 | J3: 0.95769999 | K3: 2.1040669 | L3: 1.2176313 | M3: 1.6702761 | N3: 0.0082652209 | O3: 0 | P3: 0.097057481 | Q3: 0.014790655 | R3: 3.4432103 | S3: 2.025824 | T3: FIN_03 | U3: Low Growth Asset Play | V3: 45900 | W3: Y
B4: 3983.HK | C4: 中海石油化学 | D4: 1.95 | E4: HKD | F4: 0.20890029 | G4: =F4 - Portfolio_Mgmt!$C$10 -> 0.09150029 | H4: =F4 - Portfolio_Mgmt!$C$11 -> 0.17440029 | I4: 0.20890029 | J4: 1.5826579 | K4: 3.0780995 | L4: 1.9919557 | M4: 2.7012043 | N4: 0.067112926 | O4: 0.051282051 | P4: 0.23422582 | Q4: 0.10863425 | R4: 2.282457 | S4: 1.7907627 | T4: ENG_02 | U4: Low Growth | V4: 45900 | W4: Y
B5: 2331.HK | C5: 李宁 | D5: 15.38 | E5: HKD | F5: 0.18912882 | G5: =F5 - Portfolio_Mgmt!$C$10 -> 0.071728819 | H5: =F5 - Portfolio_Mgmt!$C$11 -> 0.15462882 | I5: 0.18912882 | J5: 11.866846 | K5: 23.899333 | L5: 14.977386 | M5: 20.375014 | N5: 0.065387553 | O5: 0.035396141 | P5: 0.36794481 | Q5: 0.074171011 | R5: 0.60402077 | S5: 4.5287238 | T5: CNS_02 | U5: Low Growth | V5: 45900 | W5: Y
B6: 0857.HK | C6: 中国石油股份 | D6: 6.11 | E6: HKD | F6: 0.15926922 | G6: =F6 - Portfolio_Mgmt!$C$10 -> 0.041869218 | H6: =F6 - Portfolio_Mgmt!$C$11 -> 0.12476922 | I6: 0.082418347 | J6: 4.4306822 | K6: 7.9708701 | L6: 5.5437095 | M6: 7.4664547 | N6: 0.1267285 | O6: 0.072330525 | P6: 0.61007461 | Q6: 0.16360901 | R6: 1.1309486 | S6: -3.8116415 | T6: ENG_01 | U6: Negative Growth | V6: 45900 | W6: Y
B7: 002304.SZ | C7: 洋河股份 | D7: 68.8 | E7: CNY | F7: 0.15867473 | G7: =F7 - Portfolio_Mgmt!$C$10 -> 0.041274732 | H7: =F7 - Portfolio_Mgmt!$C$11 -> 0.12417473 | I7: 0 | J7: 49.746673 | K7: 90.751911 | L7: 62.307286 | M7: 84.017562 | N7: 0.07674421 | O7: 0.067543605 | P7: 0.30279159 | Q7: 0.00077640984 | R7: 0.0038209153 | S7: 15.284602 | T7: CNS_03 | U7: Low Growth | V7: 45900 | W7: N
B8: 0398.HK | C8: 東方表行集團 | D8: 3.57 | E8: HKD | F8: 0.14834836 | G8: =F8 - Portfolio_Mgmt!$C$10 -> 0.030948358 | H8: =F8 - Portfolio_Mgmt!$C$11 -> 0.11384836 | I8: 0 | J8: 2.4911702 | K8: 4.9623808 | L8: 3.1413778 | M8: 4.2691663 | N8: 0.079541327 | O8: 0.035854342 | P8: 0.40000524 | Q8: 0.10646656 | R8: 0.98048301 | S8: 1.6698226 | T8: CNS_05 | U8: Low Growth | V8: 45808 | W8: Y
B9: 0303.HK | C9: 偉易達 | D9: 55.65 | E9: HKD | F9: 0.13918053 | G9: =F9 - Portfolio_Mgmt!$C$10 -> 0.021780532 | H9: =F9 - Portfolio_Mgmt!$C$11 -> 0.10468053 | I9: 0 | J9: 38.719486 | K9: 64.892912 | L9: 48.204329 | M9: 64.54412 | N9: 0.094703343 | O9: 0.090855166 | P9: 1.2907496 | Q9: 0.2476874 | R9: 0.73855199 | S9: -2.6504984 | T9: CNS_02 | U9: Low Growth | V9: 45808 | W9: Y
B10: SIRI | C10: Sirius XM Holdings Inc. | D10: 21.72 | E10: USD | F10: 0.1299085 | G10: =F10 - Portfolio_Mgmt!$C$10 -> 0.012508497 | H10: =F10 - Portfolio_Mgmt!$C$11 -> 0.095408497 | I10: 0 | J10: 14.418942 | K10: 29.309951 | L10: 18.212185 | M10: 24.796949 | N10: 0.20989694 | O10: 0.02732965 | P10: 1.4851905 | Q10: 0.95241105 | R10: 4.0148803 | S10: -38.360608 | T10: TMT_05 | U10: Low Growth | V10: 45900 | W10: N
B11: 0590.HK | C11: 六福珠宝 | D11: 17.82 | E11: HKD | F11: 0.12099419 | G11: =F11 - Portfolio_Mgmt!$C$10 -> 0.0035941875 | H11: =F11 - Portfolio_Mgmt!$C$11 -> 0.086494187 | I11: 0 | J11: 11.804907 | K11: 20.50898 | L11: 14.733438 | M11: 19.785542 | N11: 0.096968912 | O11: 0.076318743 | P11: 0.31018327 | Q11: 0.1581886 | R11: 1.4550387 | S11: 5.8696004 | T11: CNS_05 | U11: Low Growth | V11: 45808 | W11: Y
B12: 0168.HK | C12: 青島啤酒股份 | D12: 53.55 | E12: HKD | F12: 0.11521291 | G12: =F12 - Portfolio_Mgmt!$C$10 -> -0.0021870868 | H12: =F12 - Portfolio_Mgmt!$C$11 -> 0.080712913 | I12: 0 | J12: 34.394984 | K12: 67.394306 | L12: 43.315385 | M12: 58.777638 | N12: 0.042328511 | O12: 0.038244421 | P12: 0.7220755 | Q12: 0.0095579625 | R12: 0.073592412 | S12: 1.3351547 | T12: CNS_03 | U12: Low Growth | V12: 45900 | W12: N
B13: 0083.HK | C13: SINO LAND | D13: 8.15 | E13: HKD | F13: 0.10840635 | G13: =F13 - Portfolio_Mgmt!$C$10 -> -0.0089936471 | H13: =F13 - Portfolio_Mgmt!$C$11 -> 0.073906353 | I13: 0 | J13: 5.2239463 | K13: 9.16281 | L13: 6.5243113 | M13: 8.7684502 | N13: 0.037901641 | O13: 0.071165644 | P13: 0.083114412 | Q13: 0.018509099 | R13: 1.1933698 | S13: 11.511513 | T13: RES_01 | U13: Negative Growth Asset Play | V13: 45900 | W13: Y
B14: 6601.HK | C14: 朝云集团 | D14: 2.3 | E14: HKD | F14: 0.10392879 | G14: =F14 - Portfolio_Mgmt!$C$10 -> -0.01347121 | H14: =F14 - Portfolio_Mgmt!$C$11 -> 0.06942879 | I14: 0 | J14: 1.4428844 | K14: 2.7168715 | L14: 1.8114973 | M14: 2.4494219 | N14: 0.035980232 | O14: 0.049378384 | P14: 0.2035177 | Q14: 0.010763176 | R14: 0.29882156 | S14: 1.8784843 | T14: CNS_04 | U14: Low Growth Asset Play | V14: 45900 | W14: Y
... B18: 0386.HK | C18: 中國石化 | D18: 3.99 | E18: HKD | F18: -0.3166383 | G18: =F18 - Portfolio_Mgmt!$C$10 -> -0.4340383 | H18: =F18 - Portfolio_Mgmt!$C$11 -> -0.3511383 | I18: 0 | J18: 0.80548128 | K18: 0.6930952 | L18: 0.96944931 | M18: 1.2455313 | N18: 0.097801203 | O18: 0.067621885 | P18: 1.1353948 | Q18: 0.42716992 | R18: 4.217449 | S18: -6.9537022 | T18: ENG_01 | U18: Low Growth | V18: 45900 | W18: N

Sheet Aux>

Sheet Market_Yield
B1: Market Yields Tracker
B2: Market Yields:
C3: Riskfree rate | D3: Prime Rate | E3: Risk Premium
B4: US | C4: 0.0426 | D4: 0.075 | E4: =D4-C4 -> 0.0324
B5: China | C5: 0.019 | D5: 0.031 | E5: =D5-C5 -> 0.012
B6: HK | C6: 0.0345 | D6: 0.0525 | E6: =D6-C6 -> 0.018
B8: Benchmarket Return:
B9: Historical Avg Return | C9: US (1928-2024)
B10: Stocks | C10: 0.0994
B11: Small caps | C11: 0.1174
B12: Bonds | C12: 0.0345
B13: Cash | C13: 0.0331
B14: Real estate | C14: 0.0423
B15: Gold | C15: 0.0512
B16: Benchmarket Return | C16: =MAX(Portfolio_Mgmt!C36,C10:C15) -> 0.1174
B18: Notes
B19: US 10Y Treasury yield | C19: https://fred.stlouisfed.org/series/DGS10
B20: US Fed Fund Rate | C20: https://fred.stlouisfed.org/series/FEDFUNDS
B21: Bank Prime Loan Rate | C21: https://fred.stlouisfed.org/series/DPRIME
B23: CN 10Y Government Bond Yield | C23: https://tradingeconomics.com/china/government-bond-yield
B24: CN Loan Prime Rate | C24: https://tradingeconomics.com/china/interest-rate
B26: HK 10Y Government Bond Yield | C26: https://tradingeconomics.com/hong-kong/government-bond-yield
B27: HK Prime Lending Rate | C27: https://tradingeconomics.com/hong-kong/bank-lending-rate
B29: All-in-One Bond Prices | C29: https://tradingeconomics.com/bonds
B31: Historical Returns | C31: https://awealthofcommonsense.com/2025/01/historical-returns-for-stocks-bonds-cash-real-estate-and-gold/

Sheet Holdings
B1: Current Holdings
B2: Symbol | C2: Market Price | D2: Price Currency | E2: Number of Shares | F2: Market Value (HKD) | G2: Actual % | H2: Allocation Weight
B3: Cash | C3: nm | D3: HKD | E3: nm | F3: 351395.62 | G3: =F3/$F$9 -> 0.39268415 | H3: =Portfolio_Mgmt!E61 -> 0.3
B4: 0590.HK | C4: =VLOOKUP(B4,Opportunities!B$3:E$30,3,FALSE) -> 17.82 | D4: =VLOOKUP(B4,Opportunities!B$3:E$30,4,FALSE) -> HKD | E4: 10000 | F4: =C4*E4 -> 178200 | G4: =F4/$F$9 -> 0.19913827 | H4: =VLOOKUP(B4,Opportunities!B$3:I$30,8,FALSE) -> 0
B5: 0083.HK | C5: =VLOOKUP(B5,Opportunities!B$3:E$30,3,FALSE) -> 8.15 | D5: =VLOOKUP(B5,Opportunities!B$3:E$30,4,FALSE) -> HKD | E5: =2000*10 -> 20000 | F5: =E5*C5 -> 163000 | G5: =F5/$F$9 -> 0.18215229 | H5: =VLOOKUP(B5,Opportunities!B$3:I$30,8,FALSE) -> 0
B6: 0857.HK | C6: =VLOOKUP(B6,Opportunities!B$3:E$30,3,FALSE) -> 6.11 | D6: =VLOOKUP(B6,Opportunities!B$3:E$30,4,FALSE) -> HKD | E6: 18000 | F6: =E6*C6 -> 109980 | G6: =F6/$F$9 -> 0.12290251 | H6: =VLOOKUP(B6,Opportunities!B$3:I$30,8,FALSE) -> 0.082418347
B7: 2331.HK | C7: =VLOOKUP(B7,Opportunities!B$3:E$30,3,FALSE) -> 15.38 | D7: =VLOOKUP(B7,Opportunities!B$3:E$30,4,FALSE) -> HKD | E7: 6000 | F7: =C7*E7 -> 92280 | G7: =F7/$F$9 -> 0.10312278 | H7: =VLOOKUP(B7,Opportunities!B$3:I$30,8,FALSE) -> 0.18912882
E9: Total Value | F9: =SUM(F3:F7) -> 894855.62 | G9: =SUM(G3:G7) -> 1 | H9: =SUM(H4:H7) -> 0.27154717
B11: Planning
B12: 9959.HK | C12: =VLOOKUP(B12,Opportunities!B$3:E$30,3,FALSE) -> 1.16 | D12: =VLOOKUP(B12,Opportunities!B$3:E$30,4,FALSE) -> HKD | E12: =500*140 -> 70000 | F12: =-C12*E12 -> -81200 | G12: =-F12/$F$9 -> 0.090740895 | H12: =VLOOKUP(B12,Opportunities!B$3:I$30,8,FALSE) -> 0.21955254
B13: 0083.HK | C13: =VLOOKUP(B13,Opportunities!B$3:E$30,3,FALSE) -> 8.15 | D13: =VLOOKUP(B13,Opportunities!B$3:E$30,4,FALSE) -> HKD | E13: =-2000*10 -> -20000 | F13: =-C13*E13 -> 163000 | G13: =-F13/$F$9 -> -0.18215229 | H13: =VLOOKUP(B13,Opportunities!B$3:I$30,8,FALSE) -> 0
B14: 3983.HK | C14: =VLOOKUP(B14,Opportunities!B$3:E$30,3,FALSE) -> 1.95 | D14: =VLOOKUP(B14,Opportunities!B$3:E$30,4,FALSE) -> HKD | E14: =2000*20 -> 40000 | F14: =-C14*E14 -> -78000 | G14: =-F14/$F$9 -> 0.087164899 | H14: =VLOOKUP(B14,Opportunities!B$3:I$30,8,FALSE) -> 0.20890029
B16: End. Cash Balance | C16: nm | D16: HKD | E16: nm | F16: =F3+SUM(F12:F14) -> 355195.62 | G16: =F16/$F$9 -> 0.39693065 | H16: =Portfolio_Mgmt!E61 -> 0.3

Sheet Comp_Group
B1: Guidance Note: Comparison Group Classification System
B2: Overview
B3: The classification uses two mutually exclusive and collectively exhaustive (MECE) layers:
B5: - Layer 1: Broad industry categories (3-character codes).
B6: - Layer 2: Granular subcategories (two-digit numbers, 01–99).
B8: Format: [Layer 1 Code]_[Layer 2 Number] (e.g., TMT_02, CNS_10).
B10: Layer 1: Broad Industry Categories
B11: Purpose: Group investments by overarching industries.
B12: Structure: 3-character codes (e.g., TMT, CNS, FIN).
B14: 9 Standard Industry Codes:
B16: Code | C16: Industry
B17: TMT | C17: Technology, Media, Telecom
B18: CNS | C18: Consumer
B19: FIN | C19: Financials
B20: HLT | C20: Healthcare
B21: IND | C21: Industrials
B22: ENG | C22: Energy
B23: MAT | C23: Materials
B24: RES | C24: Real Estate
B25: UTL | C25: Utilities
B27: Layer 2: Subcategory Numbering
B28: Purpose: Refine peer groups into specific segments within Layer 1 industries.
B29: Purpose: Two-digit numbers (01–99), appended to Layer 1 codes (e.g., TMT_01).
B31: Assigning Classifications
A32: i. | B32: Identify Layer 1:
B33: Map the investment to the broadest applicable industry (e.g., a fintech firm → FIN).
A35: ii. | B35: Assign Layer 2:
B36: Select the most specific subcategory number (e.g., fintech → FIN_10).
B38: Use Cases
B39: Peer Benchmarking: Compare HLT_03 (Biotech) companies against each other.
B40: Portfolio Analysis: Aggregate exposures by Layer 1 (e.g., “30% of portfolio is in TMT”).
B41: Reporting: Standardize disclosures using codes (e.g., “Investment X (CNS_05) outperformed peers”).
