Workbook
Name benchmark: Portfolio_Mgmt!$C$10
Name Cash_Yield: Portfolio_Mgmt!$C$11

Sheet Portfolio_Mgmt
A1: Portfolio Management Plan
A2: Executive Summary
B4: Guidance Note: This plan deploys capital into investments exceeding the benchmark return while strategically reserving cash for future opportunities.
A6: i. | B6: Market Benchmarks
B7: Objective: Determine the optimal capital allocation at current market prices, while reserving capital for strategic deployment.
B9: Key Metrics:
B10: Benchmark Return | C10: =Market_Yield!C16 -> 0.1174
B11: Cash Yield | C11: =Market_Yield!C6 -> 0.0345
B13: Key Calculation:
B14: Market Annual Return (R_i) | C14: Imported from Valuation models to Opportunities Sheet
B15: Excess Return over Benchmark (ERB_i) | C15: = R_i - Benchmark Return
B16: Excess Return over Cash (ERC_i) | C16: = R_i - Cash Yield
B18: Decision Rules:
B19: - Only investments with the Selected Flag are eligible for portfolio allocation.
B20: - Only investments with ERB > 0 are eligible for portfolio allocation.
B21: - Cash reserve is determined by Risk Appetite Score (Step 1) and Portfolio Allocation (Step 2).
A23: ii. | B23: Diversification Rules
B24: Objective: Balance high-conviction bets with diversification rules.
B26: Portfolio Limits | C26: Cap
B27: Maximum Number of Holdings | C27: 6
B28: Single Investment Cap | C28: 0.3
B30: Growth Classification Limits | C30: Cap
B31: Negative or Low Growth | C31: =C27-C32 -> 5
B32: High Growth | C32: 1
A34: iii. | B34: Valuation Model Assumptions
B35: Target Annual Return | C35: =E36+15% -> 0.3674 | D35: assuming a Lock-up period of | E35: 3
B36: Base Cost of Equity | C36: =MAX(6%,Market_Yield!C4:D4,Market_Yield!C6:D6) -> 0.075 | D36: open a position at a yield of | E36: =benchmark+10% -> 0.2174
B38: Notes:
B39: Target Annual Return: The target return reflects the investor’s hurdle rate over the lock-up period.
B40: Cost of Equity: This plan employs a value investing framework, defining true risk as the potential for permanent capital loss due to deteriorating business fundamentals or overvaluation, rather than short-term price volatility (beta). The model uses a standardized base cost of equity as the discount rate in DCF analysis,which serves as the minimum acceptable long-term return threshold, reflecting long-term risk-free rates plus an equity risk premium to account for ownership risks.
A42: Step 1: Determine Risk Appetite & Cash Reserve
B44: Process: Calculate a Risk Appetite Score (0–8 scale) using four market indicators to set cash reserves.
B46: Cash Allocation Rule:
B48: Scenario | C48: Min. Cash Reserve
B49: Score <= 2 | C49: 0.5
B50: Score 3–5 | C50: 0.3
B51: Score >= 6 | C51: 0.2 | D51: Strategic reserve for compelling opportunities.
B53: Indicators and Scoring:
B55: Indicator | C55: Low Risk Appetite (Hold Cash) | D55: High Risk Appetite (Deploy Cash) | E55: Score (0-2)
B56: 1. Market P/E Ratio | C56: > Historical 75th percentile | D56: < Historical 25th percentile | E56: 1
...

Sheet Opportunities
B1: Stock Monitor | D1: Price | G1: Portfolio Management | J1: Valuation | M1: Execution | O1: Yield | Q1: ROE Analysis | U1: Balance Sheet Strength | X1: Others
B2: Symbol | C2: Name | D2: Price | E2: CCY | F2: Market Yield | G2: ERB | H2: ERC | I2: Allocation Weight | J2: Target Price | K2: Equity Value | L2: Sell Price | M2: Entry Price | N2: Exit Price | O2: FCFE Yield | P2: Dividend Yield | Q2: ROE | R2: Profit/ Sales | S2: Sales/ Assets | T2: Assets/ Equity | U2: Debt/ Equity | V2: Debt/EBIT | W2: Realizable Value | X2: Comp Group | Y2: Growth Classification | Z2: Update Required After | AA2: Selected
B3: 0639.HK | C3: 首钢资源 | D3: 2.69 | E3: HKD | F3: 0.27199282 | G3: =F3 - Portfolio_Mgmt!$C$10 -> 0.15459282 | H3: =F3 - Portfolio_Mgmt!$C$11 -> 0.23749282 | I3: 0.22209539 | J3: 2.2019752 | K3: 4.4858409 | L3: 4.313067 | M3: 3.0398535 | N3: 3.8666759 | O3: 0.079724725 | P3: 0.10037175 | Q3: 0.10048924 | R3: 0.42143224 | S3: 0.19639123 | T3: 1.2141427 | U3: 0.0023107987 | V3: 0.023228129 | W3: 0.79833937 | X3: MAT_01 | Y3: Low Growth | Z3: 45900 | AA3: Y
B4: 3983.HK | C4: 中海石油化学 | D4: 1.99 | E4: HKD | F4: 0.22075936 | G4: =F4 - Portfolio_Mgmt!$C$10 -> 0.10335936 | H4: =F4 - Portfolio_Mgmt!$C$11 -> 0.18625936 | I4: 0.18026078 | J4: 1.4344999 | K4: 3.2862981 | L4: 2.8793877 | M4: 2.0059433 | N4: 2.5726226 | O4: 0.067833979 | P4: 0.045226131 | Q4: 0.047832973 | R4: 0.078104813 | S4: 0.49619793 | T4: 1.2342258 | U4: 0.10863425 | V4: 2.282457 | W4: 1.8471306 | X4: ENG_02 | Y4: Low Growth | Z4: 45900 | AA4: Y
B5: 0883.HK | C5: 中国海油 | D5: 18.2 | E5: HKD | F5: 0.22062547 | G5: =F5 - Portfolio_Mgmt!$C$10 -> 0.10322547 | H5: =F5 - Portfolio_Mgmt!$C$11 -> 0.18612547 | I5: 0.18015144 | J5: 13.205422 | K5: 28.423994 | L5: 26.156857 | M5: 18.337301 | N5: 23.413073 | O5: 0.1136365 | P5: 0.069230769 | Q5: 0.1603511 | R5: 0.31929962 | S5: 0.35631049 | T5: 1.4094346 | U5: 0.1226082 | V5: 0.75207445 | W5: -0.45826629 | X5: ENG_01 | Y5: Low Growth | Z5: 45900 | AA5: Y
B6: 2331.HK | C6: 李宁 | D6: 15.34 | E6: HKD | F6: 0.21312401 | G6: =F6 - Portfolio_Mgmt!$C$10 -> 0.095724005 | H6: =F6 - Portfolio_Mgmt!$C$11 -> 0.17862401 | I6: 0.1174924 | J6: 10.815599 | K6: 25.613007 | L6: 21.869292 | M6: 15.18284 | N6: 19.519758 | O6: 0.066724191 | P6: 0.031380443 | Q6: 0.12359664 | R6: 0.12331905 | S6: 0.73266921 | T6: 1.3679448 | U6: 0.074171011 | V6: 0.60402077 | W6: 4.6094187 | X6: CNS_02 | Y6: Low Growth | Z6: 45900 | AA6: Y
B7: SIRI | C7: Sirius XM | D7: 21.9 | E7: USD | F7: 0.16575312 | G7: =F7 - Portfolio_Mgmt!$C$10 -> 0.048353122 | H7: =F7 - Portfolio_Mgmt!$C$11 -> 0.13125312 | I7: 0 | J7: 13.685703 | K7: 33.230162 | L7: 27.82954 | M7: 19.269563 | N7: 24.820549 | O7: 0.20817176 | P7: 0.018973516 | Q7: 0.1875261 | R7: 0.23497655 | S7: 0.3211275 | T7: 2.4851905 | U7: 0.95241105 | V7: 4.0148803 | W7: -38.360608 | X7: TMT_05 | Y7: Low Growth | Z7: 45900 | AA7: N
B8: 0303.HK | C8: 偉易達 | D8: 55.8 | E8: HKD | F8: 0.16488224 | G8: =F8 - Portfolio_Mgmt!$C$10 -> 0.047482239 | H8: =F8 - Portfolio_Mgmt!$C$11 -> 0.13038224 | I8: 0 | J8: 35.925416 | K8: 70.23451 | L8: 69.803503 | M8: 49.387813 | N8: 62.650054 | O8: 0.09530357 | P8: 0.091431004 | Q8: 0.32755395 | R8: 0.089976704 | S8: 1.5891875 | T8: 2.2907496 | U8: 0.2476874 | V8: 0.73855199 | W8: -2.6744867 | X8: CNS_03 | Y8: Low Growth | Z8: 45808 | AA8: Y
B9: 0168.HK | C9: 青島啤酒股份 | D9: 50.65 | E9: HKD | F9: 0.16139924 | G9: =F9 - Portfolio_Mgmt!$C$10 -> 0.043999241 | H9: =F9 - Portfolio_Mgmt!$C$11 -> 0.12689924 | I9: 0 | J9: 31.548853 | K9: 72.989038 | L9: 63.462647 | M9: 44.166769 | N9: 56.684687 | O9: 0.045546153 | P9: 0.035753643 | Q9: 0.13507592 | R9: 0.12563568 | S9: 0.62432789 | T9: 1.7220755 | U9: 0.0095579625 | V9: 0.073592412 | W9: 1.3589451 | X9: CNS_02 | Y9: Low Growth | Z9: 45900 | AA9: N
B10: KHC | C10: The Kraft Heinz | D10: 25.79 | E10: USD | F10: 0.15805811 | G10: =F10 - Portfolio_Mgmt!$C$10 -> 0.040658106 | H10: =F10 - Portfolio_Mgmt!$C$11 -> 0.12355811 | I10: 0 | J10: 15.989209 | K10: 36.134622 | L10: 31.999535 | M10: 22.323805 | N10: 28.601981 | O10: 0.098455502 | P10: 0.043427685 | Q10: 0.083350636 | R10: 0.15660043 | S10: 0.29736258 | T10: 1.7899037 | U10: 0.40281804 | V10: 3.9553915 | W10: -26.938494 | X10: CNS_01 | Y10: Low Growth | Z10: 45900 | AA10: N
B11: 0327.HK | C11: 百富环球 | D11: 5.64 | E11: HKD | F11: 0.15172627 | G11: =F11 - Portfolio_Mgmt!$C$10 -> 0.034326268 | H11: =F11 - Portfolio_Mgmt!$C$11 -> 0.11722627 | I11: 0 | J11: 3.4769479 | K11: 7.3642693 | L11: 6.8641357 | M11: 4.819738 | N11: 6.1469537 | O11: 0.065496832 | P11: 0.063829787 | Q11: 0.070630421 | R11: 0.093039179 | S11: 0.62627526 | T11: 1.212162 | U11: 0.011610019 | V11: 0.1638159 | W11: 3.7980767 | X11: IND_02 | Y11: Low Growth | Z11: 45900 | AA11: Y
B12: 1910.HK | C12: 新秀麗 | D12: 14.16 | E12: HKD | F12: 0.14992546 | G12: =F12 - Portfolio_Mgmt!$C$10 -> 0.032525461 | H12: =F12 - Portfolio_Mgmt!$C$11 -> 0.11542546 | I12: 0 | J12: 8.6736297 | K12: 18.604353 | L12: 17.167969 | M12: 12.039782 | N12: 15.368646 | O12: 0.10968132 | P12: 0.059532669 | Q12: 0.26418097 | R12: 0.11373784 | S12: 0.70652859 | T12: 3.2875081 | U12: 1.5035599 | V12: 4.1998197 | W12: -12.276561 | X12: CNS_02 | Y12: High Growth | Z12: 45900 | AA12: N
B13: 0398.HK | C13: 東方表行集團 | D13: 3.76 | E13: HKD | F13: 0.14658767 | G13: =F13 - Portfolio_Mgmt!$C$10 -> 0.029187666 | H13: =F13 - Portfolio_Mgmt!$C$11 -> 0.11208767 | I13: 0 | J13: 2.2556277 | K13: 5.2246963 | L13: 4.5385418 | M13: 3.1582019 | N13: 4.0536685 | O13: 0.075521951 | P13: 0.034042553 | Q13: 0.10112859 | R13: 0.058835781 | S13: 1.2277297 | T13: 1.4000052 | U13: 0.10646656 | V13: 0.98048301 | W13: 1.6698226 | X13: CNS_05 | Y13: Low Growth | Z13: 45808 | AA13: Y
B14: 0857.HK | C14: 中国石油股份 | D14: 7 | E14: HKD | F14: 0.13626555 | G14: =F14 - Portfolio_Mgmt!$C$10 -> 0.018865545 | H14: =F14 - Portfolio_Mgmt!$C$11 -> 0.10176555 | I14: 0 | J14: 4.1425095 | K14: 8.9060031 | L14: 8.2033289 | M14: 5.7516264 | N14: 7.3430724 | O14: 0.11258688 | P14: 0.056820794 | Q14: 0.12477872 | R14: 0.077304832 | S14: 1.0025081 | T14: 1.6100746 | U14: 0.16360901 | V14: 1.1309486 | W14: -3.8795591 | X14: ENG_01 | Y14: Low Growth | Z14: 45900 | AA14: Y
... B19: 1913.HK | C19: PRADA | D19: 47.6 | E19: HKD | F19: -0.079180969 | G19: =F19 - Portfolio_Mgmt!$C$10 -> -0.19658097 | H19: =F19 - Portfolio_Mgmt!$C$11 -> -0.11368097 | I19: 0 | J19: 15.389927 | K19: 33.047848 | L19: 30.468901 | M19: 21.365247 | N19: 27.274655 | O19: 0.05160039 | P19: 0.031237107 | Q19: 0.21039827 | R19: 0.21042753 | S19: 0.516823 | T19: 1.9346294 | U19: 0.19606601 | V19: 0.84886197 | W19: -5.8921637 | X19: CNS_04 | Y19: Low Growth | Z19: 45900 | AA19: Y

Sheet Aux>

Sheet Market_Yield
B1: Market Yields Tracker
B2: Market Yields:
C3: Riskfree rate | D3: Prime Rate | E3: Risk Premium
B4: US | C4: 0.0441 | D4: 0.075 | E4: =D4-C4 -> 0.0309
B5: China | C5: 0.019 | D5: 0.031 | E5: =D5-C5 -> 0.012
B6: HK | C6: 0.0345 | D6: 0.0525 | E6: =D6-C6 -> 0.018
B8: Benchmarket Return:
B9: Historical Avg Return | C9: US (1928-2024)
B10: Stocks | C10: 0.0994
B11: Small caps | C11: 0.1174
B12: Bonds | C12: 0.0345
B13: Cash | C13: 0.0331
B14: Real estate | C14: 0.0423
B15: Gold | C15: 0.0512
B16: Benchmarket Return | C16: =MAX(Portfolio_Mgmt!C36,C10:C15) -> 0.1174
B18: Notes
B19: US 10Y Treasury yield | C19: https://fred.stlouisfed.org/series/DGS10
B20: US Fed Fund Rate | C20: https://fred.stlouisfed.org/series/FEDFUNDS
B21: Bank Prime Loan Rate | C21: https://fred.stlouisfed.org/series/DPRIME
B23: CN 10Y Government Bond Yield | C23: https://tradingeconomics.com/china/government-bond-yield
B24: CN Loan Prime Rate | C24: https://tradingeconomics.com/china/interest-rate
B26: HK 10Y Government Bond Yield | C26: https://tradingeconomics.com/hong-kong/government-bond-yield
B27: HK Prime Lending Rate | C27: https://tradingeconomics.com/hong-kong/bank-lending-rate
B29: All-in-One Bond Prices | C29: https://tradingeconomics.com/bonds
B31: Historical Returns | C31: https://awealthofcommonsense.com/2025/01/historical-returns-for-stocks-bonds-cash-real-estate-and-gold/

Sheet Holdings
B1: Current Holdings
B2: Symbol | C2: Market Price | D2: Price Currency | E2: Number of Shares | F2: Market Value (HKD) | G2: Actual % | H2: Allocation Weight | I2: Entry Price | J2: Target Price | K2: Exit Price | L2: Sell Price
B3: Cash | C3: nm | D3: HKD | E3: nm | F3: =261699.08+56485.43 -> 318184.51 | G3: =F3/$F$11 -> 0.342744 | H3: =Portfolio_Mgmt!E61 -> 0.3 | I3: nm | J3: nm | K3: nm | L3: nm
B4: 0857.HK | C4: =VLOOKUP(B4,Opportunities!B$3:E$30,3,FALSE) -> 7 | D4: =VLOOKUP(B4,Opportunities!B$3:E$30,4,FALSE) -> HKD | E4: 10000 | F4: =E4*C4 -> 70000 | G4: =F4/$F$11 -> 0.075403042 | H4: =VLOOKUP(B4,Opportunities!B$3:I$30,8,FALSE) -> 0 | I4: =VLOOKUP(B4,Opportunities!B$3:N$30,12,FALSE) -> 5.7516264 | J4: =VLOOKUP(B4,Opportunities!B$3:N$30,9,FALSE) -> 4.1425095 | K4: =VLOOKUP(B4,Opportunities!B$3:N$30,11,FALSE) -> 8.2033289 | L4: =VLOOKUP(B4,Opportunities!B$3:N$30,13,FALSE) -> 7.3430724
B5: 2331.HK | C5: =VLOOKUP(B5,Opportunities!B$3:E$30,3,FALSE) -> 15.34 | D5: =VLOOKUP(B5,Opportunities!B$3:E$30,4,FALSE) -> HKD | E5: 9000 | F5: =C5*E5 -> 138060 | G5: =F5/$F$11 -> 0.14871634 | H5: =VLOOKUP(B5,Opportunities!B$3:I$30,8,FALSE) -> 0.1174924 | I5: =VLOOKUP(B5,Opportunities!B$3:N$30,12,FALSE) -> 15.18284 | J5: =VLOOKUP(B5,Opportunities!B$3:N$30,9,FALSE) -> 10.815599 | K5: =VLOOKUP(B5,Opportunities!B$3:N$30,11,FALSE) -> 21.869292 | L5: =VLOOKUP(B5,Opportunities!B$3:N$30,13,FALSE) -> 19.519758
B6: 0883.HK | C6: =VLOOKUP(B6,Opportunities!B$3:E$30,3,FALSE) -> 18.2 | D6: =VLOOKUP(B6,Opportunities!B$3:E$30,4,FALSE) -> HKD | E6: 8000 | F6: =C6*E6 -> 145600 | G6: =F6/$F$11 -> 0.15683833 | H6: =VLOOKUP(B6,Opportunities!B$3:I$30,8,FALSE) -> 0.18015144 | I6: =VLOOKUP(B6,Opportunities!B$3:N$30,12,FALSE) -> 18.337301 | J6: =VLOOKUP(B6,Opportunities!B$3:N$30,9,FALSE) -> 13.205422 | K6: =VLOOKUP(B6,Opportunities!B$3:N$30,11,FALSE) -> 26.156857 | L6: =VLOOKUP(B6,Opportunities!B$3:N$30,13,FALSE) -> 23.413073
B7: 3983.HK | C7: =VLOOKUP(B7,Opportunities!B$3:E$30,3,FALSE) -> 1.99 | D7: =VLOOKUP(B7,Opportunities!B$3:E$30,4,FALSE) -> HKD | E7: =2000*30 -> 60000 | F7: =C7*E7 -> 119400 | G7: =F7/$F$11 -> 0.12861605 | H7: =VLOOKUP(B7,Opportunities!B$3:I$30,8,FALSE) -> 0.18026078 | I7: =VLOOKUP(B7,Opportunities!B$3:N$30,12,FALSE) -> 2.0059433 | J7: =VLOOKUP(B7,Opportunities!B$3:N$30,9,FALSE) -> 1.4344999 | K7: =VLOOKUP(B7,Opportunities!B$3:N$30,11,FALSE) -> 2.8793877 | L7: =VLOOKUP(B7,Opportunities!B$3:N$30,13,FALSE) -> 2.5726226
B8: 0327.HK | C8: =VLOOKUP(B8,Opportunities!B$3:E$30,3,FALSE) -> 5.64 | D8: =VLOOKUP(B8,Opportunities!B$3:E$30,4,FALSE) -> HKD | E8: 10000 | F8: =C8*E8 -> 56400 | G8: =F8/$F$11 -> 0.060753308 | H8: =VLOOKUP(B8,Opportunities!B$3:I$30,8,FALSE) -> 0 | I8: =VLOOKUP(B8,Opportunities!B$3:N$30,12,FALSE) -> 4.819738 | J8: =VLOOKUP(B8,Opportunities!B$3:N$30,9,FALSE) -> 3.4769479 | K8: =VLOOKUP(B8,Opportunities!B$3:N$30,11,FALSE) -> 6.8641357 | L8: =VLOOKUP(B8,Opportunities!B$3:N$30,13,FALSE) -> 6.1469537
B9: 0639.HK | C9: =VLOOKUP(B9,Opportunities!B$3:E$30,3,FALSE) -> 2.69 | D9: =VLOOKUP(B9,Opportunities!B$3:E$30,4,FALSE) -> HKD | E9: 30000 | F9: =C9*E9 -> 80700 | G9: =F9/$F$11 -> 0.086928935 | H9: =VLOOKUP(B9,Opportunities!B$3:I$30,8,FALSE) -> 0.22209539 | I9: =VLOOKUP(B9,Opportunities!B$3:N$30,12,FALSE) -> 3.0398535 | J9: =VLOOKUP(B9,Opportunities!B$3:N$30,9,FALSE) -> 2.2019752 | K9: =VLOOKUP(B9,Opportunities!B$3:N$30,11,FALSE) -> 4.313067 | L9: =VLOOKUP(B9,Opportunities!B$3:N$30,13,FALSE) -> 3.8666759
E11: Total Value | F11: =SUM(F3:F9) -> 928344.51 | G11: =SUM(G3:G9) -> 1 | H11: =SUM(H3:H9) -> 1 | I11: nm | J11: nm | K11: nm | L11: nm
B13: Planning
B14: 0639.HK | C14: =VLOOKUP(B14,Opportunities!B$3:E$30,3,FALSE) -> 2.69 | D14: =VLOOKUP(B14,Opportunities!B$3:E$30,4,FALSE) -> HKD | E14: 0 | F14: =-C14*E14 -> 0 | G14: =-F14/$F$11 -> 0 | H14: =VLOOKUP(B14,Opportunities!B$3:I$30,8,FALSE) -> 0.22209539 | I14: =VLOOKUP(B14,Opportunities!B$3:N$30,12,FALSE) -> 3.0398535 | J14: =VLOOKUP(B14,Opportunities!B$3:N$30,9,FALSE) -> 2.2019752 | K14: =VLOOKUP(B14,Opportunities!B$3:N$30,11,FALSE) -> 4.313067 | L14: =VLOOKUP(B14,Opportunities!B$3:N$30,13,FALSE) -> 3.8666759
B15: 0857.HK | C15: =VLOOKUP(B15,Opportunities!B$3:E$30,3,FALSE) -> 7 | D15: =VLOOKUP(B15,Opportunities!B$3:E$30,4,FALSE) -> HKD | E15: 0 | F15: =-C15*E15 -> 0 | G15: =-F15/$F$11 -> 0 | H15: =VLOOKUP(B15,Opportunities!B$3:I$30,8,FALSE) -> 0 | I15: =VLOOKUP(B15,Opportunities!B$3:N$30,12,FALSE) -> 5.7516264 | J15: =VLOOKUP(B15,Opportunities!B$3:N$30,9,FALSE) -> 4.1425095 | K15: =VLOOKUP(B15,Opportunities!B$3:N$30,11,FALSE) -> 8.2033289 | L15: =VLOOKUP(B15,Opportunities!B$3:N$30,13,FALSE) -> 7.3430724
B16: 0327.HK | C16: =VLOOKUP(B16,Opportunities!B$3:E$30,3,FALSE) -> 5.64 | D16: =VLOOKUP(B16,Opportunities!B$3:E$30,4,FALSE) -> HKD | E16: 0 | F16: =-C16*E16 -> 0 | G16: =-F16/$F$11 -> 0 | H16: =VLOOKUP(B16,Opportunities!B$3:I$30,8,FALSE) -> 0 | I16: =VLOOKUP(B16,Opportunities!B$3:N$30,12,FALSE) -> 4.819738 | J16: =VLOOKUP(B16,Opportunities!B$3:N$30,9,FALSE) -> 3.4769479 | K16: =VLOOKUP(B16,Opportunities!B$3:N$30,11,FALSE) -> 6.8641357 | L16: =VLOOKUP(B16,Opportunities!B$3:N$30,13,FALSE) -> 6.1469537
B17: 0883.HK | C17: =VLOOKUP(B17,Opportunities!B$3:E$30,3,FALSE) -> 18.2 | D17: =VLOOKUP(B17,Opportunities!B$3:E$30,4,FALSE) -> HKD | E17: 0 | F17: =-C17*E17 -> 0 | G17: =-F17/$F$11 -> 0 | H17: =VLOOKUP(B17,Opportunities!B$3:I$30,8,FALSE) -> 0.18015144 | I17: =VLOOKUP(B17,Opportunities!B$3:N$30,12,FALSE) -> 18.337301 | J17: =VLOOKUP(B17,Opportunities!B$3:N$30,9,FALSE) -> 13.205422 | K17: =VLOOKUP(B17,Opportunities!B$3:N$30,11,FALSE) -> 26.156857 | L17: =VLOOKUP(B17,Opportunities!B$3:N$30,13,FALSE) -> 23.413073
B19: End. Cash Balance | C19: nm | D19: HKD | E19: nm | F19: =F3+SUM(F14:F17) -> 318184.51 | G19: =F19/$F$11 -> 0.342744 | H19: =Portfolio_Mgmt!E61 -> 0.3 | I19: nm | J19: nm | K19: nm | L19: nm
B21: Forex Cost
C22: From | D22: HKDUSD | E22: To
B23: HKD to USD | C23: 200000 | D23: 7.86297 | E23: =C23/D23 -> 25435.681
B24: USD to HKD | C24: =E23 -> 25435.681 | D24: 7.8387 | E24: =C24*D24 -> 199382.68
D26: Est. Cost | E26: =C23-E24 -> 617.32399

Sheet Comp_Group
B1: Guidance Note: Comparison Group Classification System
B2: Overview
B3: The classification uses two mutually exclusive and collectively exhaustive (MECE) layers:
B5: - Layer 1: Broad industry categories (3-character codes).
B6: - Layer 2: Granular subcategories (two-digit numbers, 01–99).
B8: Format: [Layer 1 Code]_[Layer 2 Number] (e.g., TMT_02, CNS_10).
B10: Layer 1: Broad Industry Categories
B11: Purpose: Group investments by overarching industries.
B12: Structure: 3-character codes (e.g., TMT, CNS, FIN).
B14: 9 Standard Industry Codes:
B16: Code | C16: Industry
B17: TMT | C17: Technology, Media, Telecom
B18: CNS | C18: Consumer
B19: FIN | C19: Financials
B20: HLT | C20: Healthcare
B21: IND | C21: Industrials
B22: ENG | C22: Energy
B23: MAT | C23: Materials
B24: RES | C24: Real Estate
B25: UTL | C25: Utilities
B27: Layer 2: Subcategory Numbering
B28: Purpose: Refine peer groups into specific segments within Layer 1 industries.
B29: Purpose: Two-digit numbers (01–99), appended to Layer 1 codes (e.g., TMT_01).
B31: Assigning Classifications
A32: i. | B32: Identify Layer 1:
B33: Map the investment to the broadest applicable industry (e.g., a fintech firm → FIN).
A35: ii. | B35: Assign Layer 2:
B36: Select the most specific subcategory number (e.g., fintech → FIN_10).
B38: Use Cases
B39: Peer Benchmarking: Compare HLT_03 (Biotech) companies against each other.
B40: Portfolio Analysis: Aggregate exposures by Layer 1 (e.g., “30% of portfolio is in TMT”).
B41: Reporting: Standardize disclosures using codes (e.g., “Investment X (CNS_05) outperformed peers”).
