Workbook
Name Common_Shares: Thesis!$C$9
Name dividend_tax_rate: Normalized_FCF!$C$96
Name Equity_Cost: Thesis!$E$25
Name Exchange_Rate: Thesis!$E$16
Name FV_adjustments: DDM!$G$9
Name Holding_Period: Thesis!$E$21
Name Market_currency: Thesis!$C$7
Name Market_Price: Thesis!$C$8
Name Reporting_currency: Thesis!$E$17
Name scaling_factor: Data!$C$3
Name Terminal_Growth: Thesis!$C$17

Sheet Thesis
A2: Executive Summary
E3: Last Updated: | F3: 45930
B4: Company: | C4: 兴业银行 | E4: Portfolio: | F4: INT
B5: Symbol: | C5: 601166.SS | E5: Selected: | F5: Y
B6: Comp_Sector: | C6: CNS_01
B7: Market Currency: | C7: HKD
B8: Market Price: | C8: 2.85
B9: Number of Shares: | C9: 2319863422
B10: Market Capitalization: | C10: =Thesis!C8*Common_Shares/1000000 -> 6611.6108 | D10: Implied Annual Return:
B12: Guidance Note: This model evaluates the company using a structured investment process to determine its intrinsic value and target prices. It focuses on sustainable FCF capacity, adjusts for financial structure, incorporates growth scenarios, and calculates expected returns based on the derived intrinsic value.
B14: =Scenarios!B39&" Valuation Conclusion" -> 1-stage DCF Valuation Conclusion
B15: Business Model Risk Premium: | C15: N | D15: Forex Symbol: | E15: =IF(E17=C7,C7,E17&"/"&C7) -> CNY/HKD
B16: Management Risk Premium: | C16: N | D16: Exchange Rate: | E16: 1.09
B17: Terminal Growth Rate (g) | C17: 0 | D17: Reporting Currency: | E17: CNY
B18: Payout Ratio | C18: 0 | D18: Report Interval: | E18: 6
B19: ="Expected Equity Value ("&C7&") :" -> Expected Equity Value (HKD) : | D19: Update Required After: | E19: =EOMONTH(EDATE(#REF!,E18+2),0) -> #REF!
B21: Price Targets | D21: Holding Period | E21: 2
B22: Target Price | D22: @Target return | E22: 0.35
B23: Entry Price | D23: @Entry yield | E23: 0.25
B24: Exit Price | D24: @Benchmark yield | E24: 0.1174
B25: Sell Price | D25: @Base equity cost | E25: 0.075

Sheet Data
B1: =Thesis!E17 -> CNY | C1: 45657 | D1: =EOMONTH(EDATE(C1,-12),0) -> 45291 | E1: =EOMONTH(EDATE(D1,-12),0) -> 44926 | F1: =EOMONTH(EDATE(E1,-12),0) -> 44561 | G1: =EOMONTH(EDATE(F1,-12),0) -> 44196 | H1: =EOMONTH(EDATE(G1,-12),0) -> 43830 | I1: =EOMONTH(EDATE(H1,-12),0) -> 43465 | J1: =EOMONTH(EDATE(I1,-12),0) -> 43100 | K1: =EOMONTH(EDATE(J1,-12),0) -> 42735 | ... M1: =EOMONTH(EDATE(L1,-12),0) -> 42004
B2: Data (Dirty)
B3: Income Statement | C3: 1000
B4: Net Revenue from AUM | C4: 2077484
B5: Net Revenue from Services | C5: 467126
B6: OPEX | C6: 528317
B7: Incl. Selling Expenses | C7: 41597
B8: R&D
B9: Share of JV or associate Results | C9: -2798
B10: Dividend or Interests from FA
B11: Investment property
B12: Interest Expense | C12: 16422
B13: Interest Income | C13: 21811
B14: Income Tax Paid | C14: 313181
B15: Reported Net Income | C15: 497328
B16: Non-controling Interests | C16: 124194
B18: Cash Flow Statement
B19: D&A
B20: WCInv
B21: CFO
B22: CFI
B23: CFF
B24: ="Dividend per share ("&Market_currency&")" -> Dividend per share (HKD)
B26: Balance Sheet
B27: Cash
B28: Securities
B29: JV or associate investments
B30: Total Assets
B31: Interest bearing debt
B32: Total Liabilities
B33: Non-common Interest
B34: Total Equity
B36: IS & CF Statements (Clean)
B37: Income Statement
B38: Sales | C38: =IF(C$4="","",C4) -> 2077484 | D38: =IF(D$4="","",D4) | E38: =IF(E$4="","",E4) | F38: =IF(F$4="","",F4) | G38: =IF(G$4="","",G4) | H38: =IF(H$4="","",H4) | I38: =IF(I$4="","",I4) | J38: =IF(J$4="","",J4) | ... M38: =IF(M$4="","",M4)
B39: COGS | C39: =IF(C$4="","",-C5) -> -467126 | D39: =IF(D$4="","",-D5) | E39: =IF(E$4="","",-E5) | F39: =IF(F$4="","",-F5) | G39: =IF(G$4="","",-G5) | H39: =IF(H$4="","",-H5) | I39: =IF(I$4="","",-I5) | J39: =IF(J$4="","",-J5) | ... M39: =IF(M$4="","",-M5)
B40: Gross Margin | C40: =IF(C38="","",C38+C39) -> 1610358 | D40: =IF(D38="","",D38+D39) | E40: =IF(E38="","",E38+E39) | F40: =IF(F38="","",F38+F39) | G40: =IF(G38="","",G38+G39) | H40: =IF(H38="","",H38+H39) | I40: =IF(I38="","",I38+I39) | J40: =IF(J38="","",J38+J39) | ... M40: =IF(M38="","",M38+M39)
B41: OPEX | C41: =IF(C$4="","",-C6) -> -528317 | D41: =IF(D$4="","",-D6) | E41: =IF(E$4="","",-E6) | F41: =IF(F$4="","",-F6) | G41: =IF(G$4="","",-G6) | H41: =IF(H$4="","",-H6) | I41: =IF(I$4="","",-I6) | J41: =IF(J$4="","",-J6) | ... M41: =IF(M$4="","",-M6)
B42: Incl. Selling Expenses | C42: =IF(C$4="","",-C7) -> -41597 | D42: =IF(D$4="","",-D7) | E42: =IF(E$4="","",-E7) | F42: =IF(F$4="","",-F7) | G42: =IF(G$4="","",-G7) | H42: =IF(H$4="","",-H7) | I42: =IF(I$4="","",-I7) | J42: =IF(J$4="","",-J7) | ... M42: =IF(M$4="","",-M7)
B43: Incl. Other Opex | C43: =IF(C$4="","",C41-C42) -> -486720 | D43: =IF(D$4="","",D41-D42) | E43: =IF(E$4="","",E41-E42) | F43: =IF(F$4="","",F41-F42) | G43: =IF(G$4="","",G41-G42) | H43: =IF(H$4="","",H41-H42) | I43: =IF(I$4="","",I41-I42) | J43: =IF(J$4="","",J41-J42) | ... M43: =IF(M$4="","",M41-M42)
...

Sheet Normalized_FCF
B1: =Thesis!E17 -> CNY | C1: Normalized | G1: =Data!C1 -> 45657 | H1: =EOMONTH(EDATE(G1,-12),0) -> 45291 | I1: =EOMONTH(EDATE(H1,-12),0) -> 44926 | J1: =EOMONTH(EDATE(I1,-12),0) -> 44561 | K1: =EOMONTH(EDATE(J1,-12),0) -> 44196 | L1: =EOMONTH(EDATE(K1,-12),0) -> 43830 | M1: =EOMONTH(EDATE(L1,-12),0) -> 43465 | N1: =EOMONTH(EDATE(M1,-12),0) -> 43100 | O1: =EOMONTH(EDATE(N1,-12),0) -> 42735 | ... Q1: =EOMONTH(EDATE(P1,-12),0) -> 42004
B2: FCFE Analysis | E2: Notes
B3: Normalized FCFE | C3: =scaling_factor -> 1000 | G3: Historical FCFE | H3: =scaling_factor -> 1000
B4: Net Revenue from AUM | C4: =G4*0.7 -> 1454238.8 | G4: =Data!C38 -> 2077484 | H4: =Data!D38 | I4: =Data!E38 | J4: =Data!F38 | K4: =Data!G38 | L4: =Data!H38 | M4: =Data!I38 | N4: =Data!J38 | ... Q4: =Data!M38
B5: Net Revenue from Services | C5: =Data!C5 -> 467126 | G5: =G26 -> 2541812 | H5: =H26 | I5: =I26 | J5: =J26 | K5: =K26 | L5: =L26 | M5: =M26 | N5: =N26 | ... Q5: =Q26
B6: Total Revenue | C6: =C4+C5 -> 1921364.8 | G6: =IF(G4="","",SUM(G4+G5)) -> 4619296 | H6: =IF(H4="","",SUM(H4+H5)) | I6: =IF(I4="","",SUM(I4+I5)) | J6: =IF(J4="","",SUM(J4+J5)) | K6: =IF(K4="","",SUM(K4+K5)) | L6: =IF(L4="","",SUM(L4+L5)) | M6: =IF(M4="","",SUM(M4+M5)) | N6: =IF(N4="","",SUM(N4+N5)) | ... Q6: =IF(Q4="","",SUM(Q4+Q5))
B7: Fixed Costs | C7: =C40 -> -486720 | G7: =G40 -> -486720 | H7: =H40 | I7: =I40 | J7: =J40 | K7: =K40 | L7: =L40 | M7: =M40 | N7: =N40 | ... Q7: =Q40
B8: Operating EBIT | C8: =C6+C7 -> 1434644.8 | G8: =IF(G$4="","",G6+G7) -> 4132576 | H8: =IF(H$4="","",H6+H7) | I8: =IF(I$4="","",I6+I7) | J8: =IF(J$4="","",J6+J7) | K8: =IF(K$4="","",K6+K7) | L8: =IF(L$4="","",L6+L7) | M8: =IF(M$4="","",M6+M7) | N8: =IF(N$4="","",N6+N7) | ... Q8: =IF(Q$4="","",Q6+Q7)
B9: Stable Non-Operating EBIT | C9: =C66 -> #REF! | G9: =G64 -> -2798 | H9: =H64 | I9: =I64 | J9: =J64 | K9: =K64 | L9: =L64 | M9: =M64 | N9: =N64 | ... Q9: =Q64
B10: Interest Expense | C10: =C53 -> #REF! | G10: =G53 -> #REF! | H10: =H53 | I10: =I53 | J10: =J53 | K10: =K53 | L10: =L53 | M10: =M53 | N10: =N53 | ... Q10: =Q53
B11: Pre-tax Profit | C11: =SUM(C8:C10) -> #REF! | G11: =IF(G$4="","",SUM(G8:G10)) -> #REF! | H11: =IF(H$4="","",SUM(H8:H10)) | I11: =IF(I$4="","",SUM(I8:I10)) | J11: =IF(J$4="","",SUM(J8:J10)) | K11: =IF(K$4="","",SUM(K8:K10)) | L11: =IF(L$4="","",SUM(L8:L10)) | M11: =IF(M$4="","",SUM(M8:M10)) | N11: =IF(N$4="","",SUM(N8:N10)) | ... Q11: =IF(Q$4="","",SUM(Q8:Q10))
B12: Income Tax | C12: =-C11*C46 -> #REF! | G12: =Data!C48 -> -313181 | H12: =Data!D48 | I12: =Data!E48 | J12: =Data!F48 | K12: =Data!G48 | L12: =Data!H48 | M12: =Data!I48 | N12: =Data!J48 | ... Q12: =Data!M48
B13: NCI’s Share of Profits | C13: =-C4*C84 -> #REF! | G13: =Data!C50 -> -124194 | H13: =Data!D50 | I13: =Data!E50 | J13: =Data!F50 | K13: =Data!G50 | L13: =Data!H50 | M13: =Data!I50 | N13: =Data!J50 | ... Q13: =Data!M50
B14: After-tax Profit | C14: =SUM(C11:C13) -> #REF! | G14: =IF(G$4="","",SUM(G11:G13)) -> #REF! | H14: =IF(H$4="","",SUM(H11:H13)) | I14: =IF(I$4="","",SUM(I11:I13)) | J14: =IF(J$4="","",SUM(J11:J13)) | K14: =IF(K$4="","",SUM(K11:K13)) | L14: =IF(L$4="","",SUM(L11:L13)) | M14: =IF(M$4="","",SUM(M11:M13)) | N14: =IF(N$4="","",SUM(N11:N13)) | ... Q14: =IF(Q$4="","",SUM(Q11:Q13))
B15: Add Back D&A | C15: =#REF!*#REF! -> #REF! | G15: =IF(Data!C59="","",-Data!C59) -> 0 | H15: =IF(Data!D59="","",-Data!D59) | I15: =IF(Data!E59="","",-Data!E59) | J15: =IF(Data!F59="","",-Data!F59) | K15: =IF(Data!G59="","",-Data!G59) | L15: =IF(Data!H59="","",-Data!H59) | M15: =IF(Data!I59="","",-Data!I59) | N15: =IF(Data!J59="","",-Data!J59) | ... Q15: =IF(Data!M59="","",-Data!M59)
B16: Maintenance Capex | C16: =-C4*C87 -> #REF! | G16: =Data!#REF! -> #REF! | H16: =Data!#REF! -> #REF! | I16: =Data!#REF! -> #REF! | J16: =Data!#REF! -> #REF! | K16: =Data!#REF! -> #REF! | L16: =Data!#REF! -> #REF! | M16: =Data!#REF! -> #REF! | N16: =Data!#REF! -> #REF! | ... Q16: =Data!#REF! -> #REF!
B17: WCInv | C17: =-C4*C88 -> 0 | E17: WCInv is by default excluded
B18: Net Borrowing | C18: 0 | E18: Net borrowing is excluded
B19: FCFE | C19: =C14+C17 -> #REF! | G19: =IF(G$4="","",G14+G17) -> #REF! | H19: =IF(H$4="","",H14+H17) | I19: =IF(I$4="","",I14+I17) | J19: =IF(J$4="","",J14+J17) | K19: =IF(K$4="","",K14+K17) | L19: =IF(L$4="","",L14+L17) | M19: =IF(M$4="","",M14+M17) | N19: =IF(N$4="","",N14+N17) | ... Q19: =IF(Q$4="","",Q14+Q17)
B21: Operating Cost Structure | E21: Notes
B22: Revenue Structure
B23: =B4 -> Net Revenue from AUM | G23: =Data!C4 -> 2077484 | H23: =Data!D39 | I23: =Data!E39 | J23: =Data!F39 | K23: =Data!G39 | L23: =Data!H39 | M23: =Data!I39 | N23: =Data!J39 | O23: =Data!K39 | ... Q23: =Data!M39
B24: =B5 -> Net Revenue from Services | G24: =Data!C5 -> 467126 | H24: =Data!D42 | I24: =Data!E42 | J24: =Data!F42 | K24: =Data!G42 | L24: =Data!H42 | M24: =Data!I42 | N24: =Data!J42 | O24: =Data!K42 | ... Q24: =Data!M42
B25: =B9 -> Stable Non-Operating EBIT | G25: =Data!C9 -> -2798 | H25: =Data!D44 | I25: =Data!E44 | J25: =Data!F44 | K25: =Data!G44 | L25: =Data!H44 | M25: =Data!I44 | N25: =Data!J44 | O25: =Data!K44 | ... Q25: =Data!M44
B26: Total Revenue | G26: =IF(G$4="","",SUM(G23:G25)) -> 2541812 | H26: =IF(H$4="","",SUM(H23:H25)) | I26: =IF(I$4="","",SUM(I23:I25)) | J26: =IF(J$4="","",SUM(J23:J25)) | K26: =IF(K$4="","",SUM(K23:K25)) | L26: =IF(L$4="","",SUM(L23:L25)) | M26: =IF(M$4="","",SUM(M23:M25)) | N26: =IF(N$4="","",SUM(N23:N25)) | ... Q26: =IF(Q$4="","",SUM(Q23:Q25))
B28: Balance Sheet | G28: Latest Asset Value
B29: Total Assets | C29: =#REF! -> #REF! | G29: =IF(G$4="","",G31+G30) -> 0 | H29: =IF(H$4="","",H31+H30) | I29: =IF(I$4="","",I31+I30) | J29: =IF(J$4="","",J31+J30) | K29: =IF(K$4="","",K31+K30) | L29: =IF(L$4="","",L31+L30) | M29: =IF(M$4="","",M31+M30) | N29: =IF(N$4="","",N31+N30) | ... Q29: =IF(Q$4="","",Q31+Q30)
B30: Total Liabilities | C30: =#REF! -> #REF! | G30: =Data!C76 -> 0 | H30: =Data!D76 | I30: =Data!E76 | J30: =Data!F76 | K30: =Data!G76 | L30: =Data!H76 | M30: =Data!I76 | N30: =Data!J76 | ... Q30: =Data!M76
B31: Total Equity | C31: =#REF! -> #REF! | G31: =Data!C77 -> 0 | H31: =Data!D77 | I31: =Data!E77 | J31: =Data!F77 | K31: =Data!G77 | L31: =Data!H77 | M31: =Data!I77 | N31: =Data!J77 | ... Q31: =Data!M77
B33: Return on Assets
B34: Net Revenue from AUM | G34: =G23/G$29 -> #DIV/0!
B35: Net Revenue from Services | G35: =G24/G$29 -> #DIV/0!
B36: Stable Non-Operating EBIT | G36: =G25/G$29 -> #DIV/0!
B37: Total Revenue
B39: Fixed Costs
B40: G&A and other Opex | C40: =G40 -> -486720 | G40: =IF(G4="","",Data!C43) -> -486720 | H40: =IF(H4="","",Data!D43) | I40: =IF(I4="","",Data!E43) | J40: =IF(J4="","",Data!F43) | K40: =IF(K4="","",Data!G43) | L40: =IF(L4="","",Data!H43) | M40: =IF(M4="","",Data!I43) | N40: =IF(N4="","",Data!J43) | ... Q40: =IF(Q4="","",Data!M43)
B42: Fixed Costs % of Sales
B43: G&A and other Opex | C43: =ABS(C40/$C$4) -> 0.33469056 | G43: =IF(G$4="","",ABS(G40/G$4)) -> 0.23428339 | H43: =IF(H$4="","",ABS(H40/H$4)) | I43: =IF(I$4="","",ABS(I40/I$4)) | J43: =IF(J$4="","",ABS(J40/J$4)) | K43: =IF(K$4="","",ABS(K40/K$4)) | L43: =IF(L$4="","",ABS(L40/L$4)) | M43: =IF(M$4="","",ABS(M40/M$4)) | N43: =IF(N$4="","",ABS(N40/N$4)) | ... Q43: =IF(Q$4="","",ABS(Q40/Q$4))
B45: Tax % of Pre-tax Profit
B46: Income Tax Rate | C46: 0.25 | E46: Use the marginal tax rate | G46: =IF(G$4="","",-G12/SUM(G8+G9,G10)) -> #REF! | H46: =IF(H$4="","",-H12/SUM(H8+H9,H10)) | I46: =IF(I$4="","",-I12/SUM(I8+I9,I10)) | J46: =IF(J$4="","",-J12/SUM(J8+J9,J10)) | K46: =IF(K$4="","",-K12/SUM(K8+K9,K10)) | L46: =IF(L$4="","",-L12/SUM(L8+L9,L10)) | M46: =IF(M$4="","",-M12/SUM(M8+M9,M10)) | N46: =IF(N$4="","",-N12/SUM(N8+N9,N10)) | ... Q46: =IF(Q$4="","",-Q12/SUM(Q8+Q9,Q10))
...

Sheet DDM
B2: Baseline DDM Valuation
B3: Baseline DDM | C3: =scaling_factor -> 1000 | F3: Terminal Stage | I3: Normalized Values
B4: After-tax Profit | C4: =Normalized_FCF!C19 -> #REF! | D4: =Reporting_currency -> CNY | F4: Terminal g Rate: | G4: =Terminal_Growth -> 0 | I4: Revenues | O4: =Normalized_FCF!C4 -> 1454238.8
B5: + Additional Equity
B6: *Payout Ratio
B7: /Equity Cost of Capital | C7: =Equity_Cost -> 0.075 | I7: Fixed Costs | O7: =Normalized_FCF!C7 -> -486720
B8: Equity Value | D8: =Reporting_currency -> CNY | I8: Other Income, includes | O8: =O9+O10 -> #REF!
B9: ="*"&Thesis!E15 -> *CNY/HKD | C9: =Exchange_Rate -> 1.09 | D9: =Thesis!E15 -> CNY/HKD | I9: Non-op EBIT | O9: =Normalized_FCF!C9 -> #REF!
B10: Value | C10: =C8*Exchange_Rate -> 0 | D10: =Market_currency -> HKD | I10: =Normalized_FCF!B10 -> Interest Expense | O10: =Normalized_FCF!C10 -> #REF!
B11: Value per share | C11: =(C10*scaling_factor)/Common_Shares -> 0 | D11: =Market_currency -> HKD | I11: =Normalized_FCF!B84 -> NCI’s Share of Profits | O11: =Normalized_FCF!C84 -> #REF!
I12: Tax rate | O12: =Normalized_FCF!C46 -> 0.25
B14: Growth DDM Valuation
B15: Stage | C15: I | F15: Stage | G15: =IF(G18=C18,"I","II") -> I
B16: High g Period (HGP) | C16: =Scenarios!C45 -> 5 | F16: =IF(G15="II","Change year","Terminal Year") -> Terminal Year | G16: =IF(G15="II",_xlfn.CEILING.MATH(C16/2),C16+1) -> 6
B17: High g Rate (HGR) | C17: =Scenarios!C46 -> 0.018613012 | F17: High Growth Rate_II | G17: =Scenarios!C41 -> 0.018613012
B18: Contribution Margin | C18: =Normalized_FCF!C32 -> 0 | F18: Contribution Margin_II | G18: =Scenarios!C40 -> 0 | I18: Output
B19: D&A - maint. Capx | C19: =Normalized_FCF!C86-Normalized_FCF!C87 -> #REF! | F19: D&A - maint. Capx | G19: =IF(G15="II",C19/2,C19) -> #REF! | I19: Value Per Share | O19: =(M53+FV_adjustments)*Exchange_Rate/Common_Shares*scaling_factor -> 0
A21: Stage | B21: Year | C21: Total Net Revenue | D21: Rev. Growth Rate | E21: Asset Man. Yield | F21: Service Rev. Yield | G21: Forecasted AUM | H21: Fixed Cost | I21: After-tax profit | J21: payout ratio | K21: Dividend | L21: Disc. Factor | M21: PV of Dividend/TV | O21: =B19 -> D&A - maint. Capx | P21: FCFE
A22: =IF($C$16<B22,"",IF(B22>=$G$16,"II","I")) -> I | B22: 1 | C22: =O4*(1+D22) -> 1481306.6 | D22: =IF(A22="",0,IF(A22="I",$C$17,$G$17)) -> 0.018613012 | F22: =$C$18 -> 0 | L22: =IF($C$16<B22,0,1/(1+Equity_Cost)^B22) -> 0.93023256 | M22: =O22*L22 -> 0
A23: =IF($C$16<B23,"",IF(B23>=$G$16,"II","I")) -> I | B23: 2 | C23: =IF(A23="",0,C22*(1+D23)) -> 1508878.1 | D23: =IF(A23="",0,IF(A23="I",$C$17,$G$17)) -> 0.018613012 | F23: =IF($C$16<B23,0,IF(B23>=$G$16,$G$18,$C$18)) -> 0 | L23: =IF($C$16<B23,0,1/(1+Equity_Cost)^B23) -> 0.86533261 | M23: =O23*L23 -> 0
A24: =IF($C$16<B24,"",IF(B24>=$G$16,"II","I")) -> I | B24: 3 | C24: =IF(A24="",0,C23*(1+D24)) -> 1536962.9 | D24: =IF(A24="",0,IF(A24="I",$C$17,$G$17)) -> 0.018613012 | F24: =IF($C$16<B24,0,IF(B24>=$G$16,$G$18,$C$18)) -> 0 | L24: =IF($C$16<B24,0,1/(1+Equity_Cost)^B24) -> 0.80496057 | M24: =O24*L24 -> 0
A25: =IF($C$16<B25,"",IF(B25>=$G$16,"II","I")) -> I | B25: 4 | C25: =IF(A25="",0,C24*(1+D25)) -> 1565570.4 | D25: =IF(A25="",0,IF(A25="I",$C$17,$G$17)) -> 0.018613012 | F25: =IF($C$16<B25,0,IF(B25>=$G$16,$G$18,$C$18)) -> 0 | L25: =IF($C$16<B25,0,1/(1+Equity_Cost)^B25) -> 0.74880053 | M25: =O25*L25 -> 0
A26: =IF($C$16<B26,"",IF(B26>=$G$16,"II","I")) -> I | B26: 5 | C26: =IF(A26="",0,C25*(1+D26)) -> 1594710.4 | D26: =IF(A26="",0,IF(A26="I",$C$17,$G$17)) -> 0.018613012 | F26: =IF($C$16<B26,0,IF(B26>=$G$16,$G$18,$C$18)) -> 0 | L26: =IF($C$16<B26,0,1/(1+Equity_Cost)^B26) -> 0.69655863 | M26: =O26*L26 -> 0
A27: =IF($C$16<B27,"",IF(B27>=$G$16,"II","I")) | B27: 6 | C27: =IF(A27="",0,C26*(1+D27)) -> 0 | D27: =IF(A27="",0,IF(A27="I",$C$17,$G$17)) -> 0 | F27: =IF($C$16<B27,0,IF(B27>=$G$16,$G$18,$C$18)) -> 0 | G27: =IF(A27="",0,G26*(1+D27)) -> 0 | H27: =IF(A27="", 0,C27*(1-F27)+G27+$O$8) -> 0 | I27: =IF(A27="",0%,IF(A27="I",$C$19,$G$19)) -> 0 | L27: =IF($C$16<B27,0,1/(1+Equity_Cost)^B27) -> 0 | M27: =O27*L27 -> 0
A28: =IF($C$16<B28,"",IF(B28>=$G$16,"II","I")) | B28: 7 | C28: =IF(A28="",0,C27*(1+D28)) -> 0 | D28: =IF(A28="",0,IF(A28="I",$C$17,$G$17)) -> 0 | F28: =IF($C$16<B28,0,IF(B28>=$G$16,$G$18,$C$18)) -> 0 | G28: =IF(A28="",0,G27*(1+D28)) -> 0 | H28: =IF(A28="", 0,C28*(1-F28)+G28+$O$8) -> 0 | I28: =IF(A28="",0%,IF(A28="I",$C$19,$G$19)) -> 0 | L28: =IF($C$16<B28,0,1/(1+Equity_Cost)^B28) -> 0 | M28: =O28*L28 -> 0
A29: =IF($C$16<B29,"",IF(B29>=$G$16,"II","I")) | B29: 8 | C29: =IF(A29="",0,C28*(1+D29)) -> 0 | D29: =IF(A29="",0,IF(A29="I",$C$17,$G$17)) -> 0 | F29: =IF($C$16<B29,0,IF(B29>=$G$16,$G$18,$C$18)) -> 0 | G29: =IF(A29="",0,G28*(1+D29)) -> 0 | H29: =IF(A29="", 0,C29*(1-F29)+G29+$O$8) -> 0 | I29: =IF(A29="",0%,IF(A29="I",$C$19,$G$19)) -> 0 | L29: =IF($C$16<B29,0,1/(1+Equity_Cost)^B29) -> 0 | M29: =O29*L29 -> 0
A30: =IF($C$16<B30,"",IF(B30>=$G$16,"II","I")) | B30: 9 | C30: =IF(A30="",0,C29*(1+D30)) -> 0 | D30: =IF(A30="",0,IF(A30="I",$C$17,$G$17)) -> 0 | F30: =IF($C$16<B30,0,IF(B30>=$G$16,$G$18,$C$18)) -> 0 | G30: =IF(A30="",0,G29*(1+D30)) -> 0 | H30: =IF(A30="", 0,C30*(1-F30)+G30+$O$8) -> 0 | I30: =IF(A30="",0%,IF(A30="I",$C$19,$G$19)) -> 0 | L30: =IF($C$16<B30,0,1/(1+Equity_Cost)^B30) -> 0 | M30: =O30*L30 -> 0
A31: =IF($C$16<B31,"",IF(B31>=$G$16,"II","I")) | B31: 10 | C31: =IF(A31="",0,C30*(1+D31)) -> 0 | D31: =IF(A31="",0,IF(A31="I",$C$17,$G$17)) -> 0 | F31: =IF($C$16<B31,0,IF(B31>=$G$16,$G$18,$C$18)) -> 0 | G31: =IF(A31="",0,G30*(1+D31)) -> 0 | H31: =IF(A31="", 0,C31*(1-F31)+G31+$O$8) -> 0 | I31: =IF(A31="",0%,IF(A31="I",$C$19,$G$19)) -> 0 | L31: =IF($C$16<B31,0,1/(1+Equity_Cost)^B31) -> 0 | M31: =O31*L31 -> 0
A32: =IF($C$16<B32,"",IF(B32>=$G$16,"II","I")) | B32: 11 | C32: =IF(A32="",0,C31*(1+D32)) -> 0 | D32: =IF(A32="",0,IF(A32="I",$C$17,$G$17)) -> 0 | F32: =IF($C$16<B32,0,IF(B32>=$G$16,$G$18,$C$18)) -> 0 | G32: =IF(A32="",0,G31*(1+D32)) -> 0 | H32: =IF(A32="", 0,C32*(1-F32)+G32+$O$8) -> 0 | I32: =IF(A32="",0%,IF(A32="I",$C$19,$G$19)) -> 0 | L32: =IF($C$16<B32,0,1/(1+Equity_Cost)^B32) -> 0 | M32: =O32*L32 -> 0
A33: =IF($C$16<B33,"",IF(B33>=$G$16,"II","I")) | B33: 12 | C33: =IF(A33="",0,C32*(1+D33)) -> 0 | D33: =IF(A33="",0,IF(A33="I",$C$17,$G$17)) -> 0 | F33: =IF($C$16<B33,0,IF(B33>=$G$16,$G$18,$C$18)) -> 0 | G33: =IF(A33="",0,G32*(1+D33)) -> 0 | H33: =IF(A33="", 0,C33*(1-F33)+G33+$O$8) -> 0 | I33: =IF(A33="",0%,IF(A33="I",$C$19,$G$19)) -> 0 | L33: =IF($C$16<B33,0,1/(1+Equity_Cost)^B33) -> 0 | M33: =O33*L33 -> 0
A34: =IF($C$16<B34,"",IF(B34>=$G$16,"II","I")) | B34: 13 | C34: =IF(A34="",0,C33*(1+D34)) -> 0 | D34: =IF(A34="",0,IF(A34="I",$C$17,$G$17)) -> 0 | F34: =IF($C$16<B34,0,IF(B34>=$G$16,$G$18,$C$18)) -> 0 | G34: =IF(A34="",0,G33*(1+D34)) -> 0 | H34: =IF(A34="", 0,C34*(1-F34)+G34+$O$8) -> 0 | I34: =IF(A34="",0%,IF(A34="I",$C$19,$G$19)) -> 0 | L34: =IF($C$16<B34,0,1/(1+Equity_Cost)^B34) -> 0 | M34: =O34*L34 -> 0
A35: =IF($C$16<B35,"",IF(B35>=$G$16,"II","I")) | B35: 14 | C35: =IF(A35="",0,C34*(1+D35)) -> 0 | D35: =IF(A35="",0,IF(A35="I",$C$17,$G$17)) -> 0 | F35: =IF($C$16<B35,0,IF(B35>=$G$16,$G$18,$C$18)) -> 0 | G35: =IF(A35="",0,G34*(1+D35)) -> 0 | H35: =IF(A35="", 0,C35*(1-F35)+G35+$O$8) -> 0 | I35: =IF(A35="",0%,IF(A35="I",$C$19,$G$19)) -> 0 | L35: =IF($C$16<B35,0,1/(1+Equity_Cost)^B35) -> 0 | M35: =O35*L35 -> 0
A36: =IF($C$16<B36,"",IF(B36>=$G$16,"II","I")) | B36: 15 | C36: =IF(A36="",0,C35*(1+D36)) -> 0 | D36: =IF(A36="",0,IF(A36="I",$C$17,$G$17)) -> 0 | F36: =IF($C$16<B36,0,IF(B36>=$G$16,$G$18,$C$18)) -> 0 | G36: =IF(A36="",0,G35*(1+D36)) -> 0 | H36: =IF(A36="", 0,C36*(1-F36)+G36+$O$8) -> 0 | I36: =IF(A36="",0%,IF(A36="I",$C$19,$G$19)) -> 0 | L36: =IF($C$16<B36,0,1/(1+Equity_Cost)^B36) -> 0 | M36: =O36*L36 -> 0
A37: =IF($C$16<B37,"",IF(B37>=$G$16,"II","I")) | B37: 16 | C37: =IF(A37="",0,C36*(1+D37)) -> 0 | D37: =IF(A37="",0,IF(A37="I",$C$17,$G$17)) -> 0 | F37: =IF($C$16<B37,0,IF(B37>=$G$16,$G$18,$C$18)) -> 0 | G37: =IF(A37="",0,G36*(1+D37)) -> 0 | H37: =IF(A37="", 0,C37*(1-F37)+G37+$O$8) -> 0 | I37: =IF(A37="",0%,IF(A37="I",$C$19,$G$19)) -> 0 | L37: =IF($C$16<B37,0,1/(1+Equity_Cost)^B37) -> 0 | M37: =O37*L37 -> 0
A38: =IF($C$16<B38,"",IF(B38>=$G$16,"II","I")) | B38: 17 | C38: =IF(A38="",0,C37*(1+D38)) -> 0 | D38: =IF(A38="",0,IF(A38="I",$C$17,$G$17)) -> 0 | F38: =IF($C$16<B38,0,IF(B38>=$G$16,$G$18,$C$18)) -> 0 | G38: =IF(A38="",0,G37*(1+D38)) -> 0 | H38: =IF(A38="", 0,C38*(1-F38)+G38+$O$8) -> 0 | I38: =IF(A38="",0%,IF(A38="I",$C$19,$G$19)) -> 0 | L38: =IF($C$16<B38,0,1/(1+Equity_Cost)^B38) -> 0 | M38: =O38*L38 -> 0
... A51: =IF($C$16<B51,"",IF(B51>=$G$16,"II","I")) | B51: 30 | C51: =IF(A51="",0,C50*(1+D51)) -> 0 | D51: =IF(A51="",0,IF(A51="I",$C$17,$G$17)) -> 0 | F51: =IF($C$16<B51,0,IF(B51>=$G$16,$G$18,$C$18)) -> 0 | G51: =IF(A51="",0,G50*(1+D51)) -> 0 | H51: =IF(A51="", 0,C51*(1-F51)+G51+$O$8) -> 0 | I51: =IF(A51="",0%,IF(A51="I",$C$19,$G$19)) -> 0 | L51: =IF($C$16<B51,0,1/(1+Equity_Cost)^B51) -> 0 | M51: =O51*L51 -> 0
A52: T | B52: =C16+1 -> 6 | C52: =VLOOKUP(C16,B22:C51,2,FALSE)*(1+Terminal_Growth) -> 1594710.4 | D52: =Terminal_Growth -> 0 | F52: =G18 -> 0 | G52: =VLOOKUP(C16,B22:G51,5,FALSE)*(1+Terminal_Growth) -> 0 | H52: =C52*(1-F52)+G52+$O$8 -> #REF! | I52: =G19 -> #REF! | L52: =1/(1+Equity_Cost)^C16 -> 0.69655863 | M52: =O52*L52 -> 0
L53: PV of DDM = | M53: =SUM(M22:M52) -> 0
B55: Sensitivity Analysis (Enterprise Value)
A56: =M53 -> 0 | B56: =C87 -> -0.1 | C56: =C86 -> 0.01 | D56: =C85 -> 0.02 | F56: =C84 -> 0.03 | G56: =C83 -> 0.08
...

Sheet Scenarios
B2: Current Situation
B3: Selection | D3: Prompt for fundamental Analysis
B4: Past Years Selected | C4: 2 | D4: ="DDM Model Inputs for " & Thesis!C5 & " – " & Thesis!C4 & ": Please develop Base, Pessimistic, and Optimistic scenarios under the following unified framework. " & "Assume a consistent high-growth period across all cases, with each scenario using a single FCFE CAGR during this phase. " & "Apply a two-stage model only if there is a material shift in FCFE margin or growth, and ensure this structure is used consistently across scenarios. " & "Margins should remain constant within each stage and be identical across all scenarios; any variation in outlook should be reflected through adjustments to the growth rate, not the margin. " & "Terminal growth is fixed at 0%, so modify the high-growth duration or rate accordingly to reflect long-term expectations. " & "Specify the FCFE margin (stage-specific if applicable) for all scenarios. " & "For each scenario, specify the FCFE CAGR during the high-growth period. Accompany each with a concise business narrative and respective probability explaining the key drivers behind the scenario." -> DDM Model Inputs for 601166.SS – 兴业银行: Please develop Base, Pessimistic, and Optimistic scenarios under the following unified framework. Assume a consistent high-growth period across all cases, with each scenario using a single FCFE CAGR during this phase. Apply a two-stage model only if there is a material shift in FCFE margin or growth, and ensure this structure is used consistently across scenarios. Margins should remain constant within each stage and be identical across all scenarios; any variation in outlook should be reflected through adjustments to the growth rate, not the margin. Terminal growth is fixed at 0%, so modify the high-growth duration or rate accordingly to reflect long-term expectations. Specify the FCFE margin (stage-specific if applicable) for all scenarios. For each scenario, specify the FCFE CAGR during the high-growth period. Accompany each with a concise business narrative and respective probability explaining the key drivers behind the scenario.
B6: Latest | C6: =DDM!C3&" "&Reporting_currency -> 1000 CNY
B7: EBIT | C7: =Normalized_FCF!G8 -> 4132576
B8: FCFE | C8: =Normalized_FCF!G19 -> #REF!
B9: Normalized | C9: =Normalized_FCF!C19 -> #REF!
B11: YoY CAGR
B12: Sales | C12: =(Normalized_FCF!G4/OFFSET(Normalized_FCF!G4, 0, $C$4))^(1/$C$4) - 1 -> #VALUE!
B13: Operating EBIT | C13: =(Normalized_FCF!G8/OFFSET(Normalized_FCF!G8, 0, $C$4))^(1/$C$4) - 1 -> #VALUE!
B14: FCFE | C14: =(Normalized_FCF!G19/OFFSET(Normalized_FCF!G19, 0, $C$4))^(1/$C$4) - 1 -> #REF!
B16: Scenarios Analysis
B17: Assumption | E17: Note on Manual Adjustments
B18: High Growth Period (HGP) | C18: 5 | E18: accepts 5-10, 15, 20, 25, or 30
B20: General Scenarios
B21: Scenarios | C21: HGR | D21: HGP | E21: ="Value per share ("&Market_currency&")" -> Value per share (HKD) | F21: Probabilities | G21: Adj. Probabilities
B22: Optimistic | C22: 0.03 | D22: =C18 -> 5 | E22: =DDM!F84 -> 0 | F22: =1-F23-F24 -> 0.2 | G22: =F22*(1-F$29-F$30) -> 0.18
B23: Base | C23: 0.02 | D23: =C18 -> 5 | E23: =DDM!F85 -> 0 | F23: 0.6 | G23: =F23*(1-F$29-F$30) -> 0.54
B24: Pessimistic | C24: 0.01 | D24: =C18 -> 5 | E24: =DDM!F86 -> 0 | F24: 0.2 | G24: =F24*(1-F$29-F$30) -> 0.18
B25: Under General Scenario | C25: =E23*F23+E24*F24+E22*F22 -> 0 | D25: =Market_currency -> HKD
B27: Extreme Scenarios
B28: Scenarios | C28: HGR | D28: HGP | E28: ="Value per share ("&Market_currency&")" -> Value per share (HKD) | F28: Probabilities | G28: Adj. Probabilities
B29: Snowball Scenario | C29: 0.08 | D29: =C18 -> 5 | E29: =DDM!F83 -> 0 | F29: 0.05 | G29: =F29 -> 0.05
B30: Devil's advocate | C30: -0.1 | D30: =C18 -> 5 | E30: =DDM!F87 -> 0 | F30: 0.05 | G30: =F30 -> 0.05
B32: Conclusion
B33: Annual Dividend per share | C33: =Normalized_FCF!C93*(1-dividend_tax_rate) -> 0 | D33: =Market_currency -> HKD | E33: With a holding period of | F33: =Holding_Period -> 2
B34: Market Price | C34: =Market_Price -> 2.85 | D34: =Market_currency -> HKD | E34: Implied Annual Return | F34: =RATE(Holding_Period,$C$33,-C34,$C$36) -> -0.99999988
B35: No-g Model Value per share | C35: =DDM!C11 -> 0 | D35: =Market_currency -> HKD | E35: Implied Annual Return | F35: =RATE(Holding_Period,$C$33,-C35,$C$36) -> #NUM!
B36: g Model Value per share | C36: =E22*G22+E23*G23+E24*G24+E30*G30+E29*G29 -> 0 | D36: =Market_currency -> HKD | E36: is assumed to be the | F36: Expected Value
B38: Stage II Normalized Values
B39: =IF(DDM!G15="II","2","1")&"-stage DCF" -> 1-stage DCF | E39: Note on Manual Adjustments
B40: Contribution Margin_II | C40: =DDM!C18 -> 0 | E40: Try obtain this number by reverse engineering.
B41: High Growth Rate_II | C41: =DDM!C17 -> 0.018613012
B43: Growth Classification
B44: Equity Value Driving Factors | E44: Note on Manual Adjustments
B45: High Growth Period (HGP) | C45: =C18 -> 5 | E45: Use general Scenarios' HGP assumption
B46: High Growth Rate (HGR) | C46: 0.018613012 | E46: Use Excel Goal Seek to find the HGR
B47: Equity Value per share | C47: =DDM!O19 -> 0 | D47: =Market_currency -> HKD | E47: Set to Expected Equity Value
B49: Type of Company | E49: Note on the logic
B50: Negative Growth | C50: =IF(C36<C35,"Y","N") -> N
...
