Workbook
Name Common_Shares: Thesis!$C$7
Name Equity_Cost: Valuation_Model!$C$5
Name Exchange_Rate: Thesis!$C$17
Name Market_currency: Thesis!$D$6
Name Market_Price: Thesis!$C$6
Name Reporting_currency: Thesis!$C$16
Name Terminal_Growth: Valuation_Model!$F$4

Sheet Thesis
B1: Model last updated: | C1: 45730 | E1: Status in Portfolio: | F1: Held
A2: Executive Summary
B4: =D5&" Stock Information" -> 0083.HK Stock Information
B5: Company Name | C5: SINO LAND | D5: 0083.HK
B6: Market Price: | C6: 7.9 | D6: HKD
B7: Number of Shares: | C7: 8171879936
B8: Report Interval: | C8: 6
B9: Update Required After: | C9: =EOMONTH(EDATE(BS!C1,C8+2),0) -> 45716
B10: ="Capitalization ("&Market_currency&"):" -> Capitalization (HKD): | C10: =Thesis!C6*Thesis!C7/1000000 -> 64557.851
B12: Guidance Note: This valuation method estimates the equity value of a company through a five-step process. Each step is designed to systematically derive cash flows available to equity holders, discount them appropriately, and adjust for debt and non-operating assets.
B14: Valuation Overview
B15: Investment Type: | C15: =IF(Scenarios!C69="Y",Scenarios!B69,"")&IF(Scenarios!C70="Y",Scenarios!B70,"")&IF(Scenarios!C71="Y",Scenarios!B71,"")&" "&IF(Scenarios!C72="Y",Scenarios!B72,"") -> Negative Growth Asset Play
B16: Reporting Currency: | C16: HKD
B17: Exchange Rate: | C17: 1 | D17: =IF(C16=D6,D6,C16&"/"&D6) -> HKD
B18: Comp_Sector: | C18: C0003
B19: Target Annual Return: | C19: 0.2
B20: ="Target Buy Price ("&Market_currency&"):" -> Target Buy Price (HKD): | C20: =C127 -> 6.4501768 | D20: assuming a holding period of | E20: 3
B21: Market Annual Return: | C21: =Scenarios!C87 -> 0.11614149
A23: Step 1: Calculate FCFE
B25: FCFE represents the cash available to equity holders after accounting for operating expenses, reinvestments, taxes, and interest obligations.
B26: FCFE = (Normalized Operating EBIT + Depreciation & Amortization – Capital Expenditures) + Stable Non-Operating EBIT + Net Interest Income – Taxes – NCI’s Share of Profits – Working Capital Investment
B28: Key Components | C28: =Data!C3 -> 1000000
B29: • Normalized Operating EBIT: Earnings before interest and taxes from core business operations, adjusted to remove one-time or irregular items for a sustainable earnings base.
B30: Normalized Operating EBIT = | C30: =Normalized_FCF!C8 -> 2591.8203 | D30: =Reporting_currency -> HKD
B32: • Depreciation & Amortization (D&A): Non-cash expenses added back to reflect cash generated from operations. • Capital Expenditures (Capex): Cash outflows required to maintain or expand operational assets
B33: D&A = | C33: =Normalized_FCF!C9 -> 160 | D33: =Reporting_currency -> HKD
B34: Capex = | C34: =Normalized_FCF!C10 -> -160 | D34: =Reporting_currency -> HKD
B36: • Stable Non-Operating EBIT: Consistent earnings from non-core assets, such as fixed-income investments, dividend-paying stocks, or rental properties.
B37: Stable Non-Operating EBIT = | C37: =Normalized_FCF!C11 -> 639 | D37: =Reporting_currency -> HKD
B39: • Net Interest Income: Interest income minus interest expense
B40: Operating Interest Income = | C40: =Normalized_FCF!C48 -> 185.19539 | D40: =Reporting_currency -> HKD
B41: Interest Expense = | C41: =Normalized_FCF!C47 -> -43 | D41: =Reporting_currency -> HKD
B42: Net Interest Income = | C42: =Normalized_FCF!C12 -> 142.19539 | D42: =Reporting_currency -> HKD
B44: • NCI’s Share of Profits: NCI represents the portion of a subsidiary’s equity not owned by the parent company.
B45: Est. NCI’s Share of Profits = | C45: =Normalized_FCF!C15 -> -22.869708 | D45: =Reporting_currency -> HKD
B47: • Taxes: Tax = (Normalized Operating EBIT + Stable Non-Operating EBIT + Interest Income – Interest Expense) × Tax Rate
B48: Taxes = | C48: =Normalized_FCF!C14 -> -809.52376 | D48: =Reporting_currency -> HKD
B50: • Working Capital Investment (WCInv): WCInv is only included if it materially distorts FCFE.
B51: WCInv = | C51: =Normalized_FCF!C17 -> 0 | D51: =Reporting_currency -> HKD
B53: Note on Net Borrowing: In theory, principal repayments are accounted for through Net Borrowing. However, this model aims to avoid explicitly forecasting debt issuance or repayments. Instead, principal repayments are reflected in the Equity Value adjustment through interest-bearing debt.
...

Sheet Data
B1: =Thesis!C16 -> HKD | C1: 45473 | D1: =EOMONTH(EDATE(C1,-12),0) -> 45107 | E1: =EOMONTH(EDATE(D1,-12),0) -> 44742 | F1: =EOMONTH(EDATE(E1,-12),0) -> 44377 | G1: =EOMONTH(EDATE(F1,-12),0) -> 44012 | H1: =EOMONTH(EDATE(G1,-12),0) -> 43646 | I1: =EOMONTH(EDATE(H1,-12),0) -> 43281 | J1: =EOMONTH(EDATE(I1,-12),0) -> 42916 | K1: =EOMONTH(EDATE(J1,-12),0) -> 42551 | ... M1: =EOMONTH(EDATE(L1,-12),0) -> 41820
B2: Data (Dirty)
B3: Income Statement | C3: 1000000
B4: Sales | C4: 8765 | D4: 11881
B5: COGS | C5: 5344 | D5: 6492
B6: OPEX | C6: 1084 | D6: 1129
B7: Incl. Selling Expenses
B8: R&D
B9: Share of JV or associate Results | C9: 639 | D9: 927
B10: Dividend or Interests from FA
B11: Investment property
B12: Interest Expense | C12: 43 | D12: 40.775368
B13: Interest Income | C13: 2340 | D13: 1390.8453
B14: Income Tax Paid | C14: 519 | D14: 860.83483
B15: Reported Net Income | C15: 4251 | D15: 5880
B16: Non-controling Interests | C16: -151 | D16: 31
B18: Cash Flow Statement
B19: D&A | C19: 160 | D19: 198
B20: CAPX | C20: 69 | D20: 108
B21: WCInv | C21: 910 | D21: 2541
B22: ="Dividend per share ("&Market_currency&")" -> Dividend per share (HKD) | C22: 0.58 | D22: 0.58
B24: Balance Sheet
B25: ST AR | D25: 7251
B26: ST Inventory | D26: 16389
B27: Total Liabilities | C27: 14028 | D27: 10902
B28: Total Equity | C28: 166316 | D28: 163105
B29: Non-common Interest
B31: Other Data
B32: Contingent Liabilities
B34: IS & CF Statements (Clean)
B35: Income Statement
B36: Sales | C36: =IF(C$4="","",C4) -> 8765 | D36: =IF(D$4="","",D4) -> 11881 | E36: =IF(E$4="","",E4) | F36: =IF(F$4="","",F4) | G36: =IF(G$4="","",G4) | H36: =IF(H$4="","",H4) | I36: =IF(I$4="","",I4) | J36: =IF(J$4="","",J4) | ... M36: =IF(M$4="","",M4)
B37: COGS | C37: =IF(C$4="","",-C5) -> -5344 | D37: =IF(D$4="","",-D5) -> -6492 | E37: =IF(E$4="","",-E5) | F37: =IF(F$4="","",-F5) | G37: =IF(G$4="","",-G5) | H37: =IF(H$4="","",-H5) | I37: =IF(I$4="","",-I5) | J37: =IF(J$4="","",-J5) | ... M37: =IF(M$4="","",-M5)
B38: Gross Margin | C38: =IF(C36="","",C36+C37) -> 3421 | D38: =IF(D36="","",D36+D37) -> 5389 | E38: =IF(E36="","",E36+E37) | F38: =IF(F36="","",F36+F37) | G38: =IF(G36="","",G36+G37) | H38: =IF(H36="","",H36+H37) | I38: =IF(I36="","",I36+I37) | J38: =IF(J36="","",J36+J37) | ... M38: =IF(M36="","",M36+M37)
B39: OPEX | C39: =IF(C$4="","",-C6) -> -1084 | D39: =IF(D$4="","",-D6) -> -1129 | E39: =IF(E$4="","",-E6) | F39: =IF(F$4="","",-F6) | G39: =IF(G$4="","",-G6) | H39: =IF(H$4="","",-H6) | I39: =IF(I$4="","",-I6) | J39: =IF(J$4="","",-J6) | ... M39: =IF(M$4="","",-M6)
B40: Incl. Selling Expenses | C40: =IF(C$4="","",-C7) -> 0 | D40: =IF(D$4="","",-D7) -> 0 | E40: =IF(E$4="","",-E7) | F40: =IF(F$4="","",-F7) | G40: =IF(G$4="","",-G7) | H40: =IF(H$4="","",-H7) | I40: =IF(I$4="","",-I7) | J40: =IF(J$4="","",-J7) | ... M40: =IF(M$4="","",-M7)
B41: Incl. Other Opex | C41: =IF(C$4="","",C39-C40) -> -1084 | D41: =IF(D$4="","",D39-D40) -> -1129 | E41: =IF(E$4="","",E39-E40) | F41: =IF(F$4="","",F39-F40) | G41: =IF(G$4="","",G39-G40) | H41: =IF(H$4="","",H39-H40) | I41: =IF(I$4="","",I39-I40) | J41: =IF(J$4="","",J39-J40) | ... M41: =IF(M$4="","",M39-M40)
B42: R&D | C42: =IF(C$4="","",-C8) -> 0 | D42: =IF(D$4="","",-D8) -> 0 | E42: =IF(E$4="","",-E8) | F42: =IF(F$4="","",-F8) | G42: =IF(G$4="","",-G8) | H42: =IF(H$4="","",-H8) | I42: =IF(I$4="","",-I8) | J42: =IF(J$4="","",-J8) | ... M42: =IF(M$4="","",-M8)
B43: Operating EBIT | C43: =IF(C$4="","",C38+C39+C42) -> 2337 | D43: =IF(D$4="","",D38+D39+D42) -> 4260 | E43: =IF(E$4="","",E38+E39+E42) | F43: =IF(F$4="","",F38+F39+F42) | G43: =IF(G$4="","",G38+G39+G42) | H43: =IF(H$4="","",H38+H39+H42) | I43: =IF(I$4="","",I38+I39+I42) | J43: =IF(J$4="","",J38+J39+J42) | ... M43: =IF(M$4="","",M38+M39+M42)
B44: Non-operating EBIT | C44: =IF(C$4="","",C47-C46-C45-C43) -> 136 | D44: =IF(D$4="","",D47-D46-D45-D43) -> 1130.7649 | E44: =IF(E$4="","",E47-E46-E45-E43) | F44: =IF(F$4="","",F47-F46-F45-F43) | G44: =IF(G$4="","",G47-G46-G45-G43) | H44: =IF(H$4="","",H47-H46-H45-H43) | I44: =IF(I$4="","",I47-I46-I45-I43) | J44: =IF(J$4="","",J47-J46-J45-J43) | ... M44: =IF(M$4="","",M47-M46-M45-M43)
...

Sheet BS
B1: Most Recent Quarter | C1: 45473 | F1: =IF(MONTH(C1)=MONTH(Normalized_FCF!G1),"FY","Quarter")&" Report" -> FY Report | H1: =Data!C3 -> 1000000
B2: Lastest Balance Sheet
B3: ST Operating Assets | C3: Book | D3: Valued @ | F3: ST Non-Operating Assets | G3: Book | H3: Valued @
B4: ST AR | C4: 8029 | D4: 0.6 | F4: Cash and cash equivalents | G4: 45665 | H4: 0.9
B5: Operating ST Financial Assets | C5: 0 | D5: 0.6 | F5: Restricted cash | G5: 2014 | H5: 0.7
B6: Inventory | C6: 9844 | D6: 0.5 | F6: Securities with stable income | G6: 156 | H6: 0.6
B7: Properties held for sale | C7: 5466 | D7: 0.6 | F7: Other Securities | G7: 0 | H7: 0.6
B8: Properties held for income | C8: 0 | D8: 0.6 | F8: Properties with stable income | G8: 0 | H8: 0.6
B9: Prepayments and Contract Assets | C9: 0 | D9: 0.1 | F9: Other Properties | G9: 0 | H9: 0.6
B10: ST DTA | C10: 10 | D10: 0.9
B11: Other ST Assets | C11: 0 | D11: 0.05
B12: Operating ST Assets | C12: =SUM(C4:C11) -> 23349 | D12: =C4*D4+C5*D5+C9*D9+C6*D6+C8*D8+C7*D7+C10*D10+C11*D11 -> 13028 | F12: Non-Operating ST Assets | G12: =SUM(G4:G9) -> 47835 | H12: =G4*H4+G5*H5+G6*H6+G7*H7+G8*H8+G9*H9 -> 42601.9
B14: LT Operating Assets | C14: Book | D14: Valued @ | F14: LT Non-Operating Assets | G14: Book | H14: Valued @
B15: LT AR | C15: 2757 | D15: 0.4 | F15: LT Depositis | G15: 0 | H15: 0.8
B16: Operating LT Financial Assets | C16: 0 | D16: 0.5 | F16: Securities with stable income | G16: 1373 | H16: 0.6
B17: Properties held for sale | C17: 67668 | D17: 0.6 | F17: Other Securities | G17: 13024 | H17: 0.6
B18: Properties held for income | C18: 0 | D18: 0.6 | F18: JV or associate with stable income | G18: 23696 | H18: 0.1
B19: PP&E & Right of Use Assets | C19: 1284 | D19: 0.1 | F19: Other JV or associate | G19: 0 | H19: 0.1
B20: Biological assets | C20: 0 | D20: 0.05 | F20: Properties with stable income | G20: 0 | H20: 0.2
B21: Intangible assets | C21: 0 | D21: 0.05 | F21: Other Properties | G21: 0 | H21: 0.1
B22: LT DTA | C22: 10 | D22: 0.9
B23: Other assets & Goodwill | C23: 0 | D23: 0
B24: Operating LT Assets | C24: =SUM(C15:C23) -> 71719 | D24: =C15*D15+C16*D16+C18*D18+C17*D17+C19*D19+C20*D20+C21*D21+C22*D22+C23*D23 -> 41841 | F24: Non-Operating LT Assets | G24: =SUM(G15:G21) -> 38093 | H24: =G15*H15+G16*H16+G17*H17+G18*H18+G19*H19+G20*H20+G21*H21 -> 11007.8
B26: ST Liabilities | C26: Book | F26: BS Summary | G26: Book | H26: Valued @
B27: ST Borrowing | C27: 967 | F27: Total Equity | G27: =G32-G30 -> 167107 | H27: =H32-G30 -> 94589.7
B28: ST Lease liabilities | C28: 37 | F28: Incl. Minority Interest (NCI) | G28: 519
B29: ST SH Loan | C29: 0 | F29: Incl. Common Equity | G29: =G27-G28 -> 166588 | H29: =H27-G28 -> 94070.7
B30: ST Financial Liabilities | C30: 0 | F30: Total Liabilities | G30: =C33+C42 -> 13889
B31: ST Interest-bearing Debt | C31: =SUM(C27:C30) -> 1004 | F31: incl. Interest-bearing Debt | G31: =C31+C40 -> 3093
B32: Other ST liabilities | C32: =C33-C31 -> 8048 | F32: Total Assets | G32: =G35+G40 -> 180996 | H32: =H35+H40 -> 108478.7
B33: Current Liabilities | C33: 9052
F34: Assets Summary | G34: Book | H34: Valued @
B35: LT Liabilities | C35: Book | F35: Operating Assets | G35: =C12+C24 -> 95068 | H35: =D12+D24 -> 54869
B36: LT Borrowing | C36: 832 | F36: incl. AR | G36: =C4+C15 -> 10786
B37: LT Lease liabilities | C37: 27 | F37: incl. inventory | G37: =C6 -> 9844
B38: LT SH Loan | C38: 1230 | F38: incl. Properties held for sale | G38: =C7+C17 -> 73134
B39: LT Financial Liabilities | C39: 0 | F39: incl. Fixed Assets | G39: =C7+C17+C19+C20 -> 74418 | H39: =C7*D7+C17*D17+C19*D19+C20*D20 -> 44008.8
B40: LT Interest-bearing Debt | C40: =SUM(C36:C39) -> 2089 | F40: Non-operating Assets | G40: =G12+G24 -> 85928 | H40: =H12+H24 -> 53609.7
B41: Other LT liabilities | C41: =C42-C40 -> 2748 | F41: incl. Assets with stable income | G41: =C70 -> 72904 | H41: =H40-H42 -> 45795.3
B42: Noncurrent Liabilities | C42: 4837 | F42: incl. Other Assets | G42: =C82 -> 13024 | H42: =D82 -> 7814.4
...

Sheet Normalized_FCF
B1: =Thesis!C16 -> HKD | C1: Normalized | G1: =Data!C1 -> 45473 | H1: =EOMONTH(EDATE(G1,-12),0) -> 45107 | I1: =EOMONTH(EDATE(H1,-12),0) -> 44742 | J1: =EOMONTH(EDATE(I1,-12),0) -> 44377 | K1: =EOMONTH(EDATE(J1,-12),0) -> 44012 | L1: =EOMONTH(EDATE(K1,-12),0) -> 43646 | M1: =EOMONTH(EDATE(L1,-12),0) -> 43281 | N1: =EOMONTH(EDATE(M1,-12),0) -> 42916 | O1: =EOMONTH(EDATE(N1,-12),0) -> 42551 | ... Q1: =EOMONTH(EDATE(P1,-12),0) -> 41820
B2: FCFE Analysis | E2: Notes
B3: FCFE | C3: =Data!C3 -> 1000000
B4: Sales | C4: =G4 -> 8765 | G4: =Data!C36 -> 8765 | H4: =Data!D36 -> 11881 | I4: =Data!E36 | J4: =Data!F36 | K4: =Data!G36 | L4: =Data!H36 | M4: =Data!I36 | N4: =Data!J36 | ... Q4: =Data!M36
B5: Variable Costs | C5: =C25 -> -5066.6797 | G5: =G25 -> -5344 | H5: =H25 -> -6492 | I5: =I25 | J5: =J25 | K5: =K25 | L5: =L25 | M5: =M25 | N5: =N25 | ... Q5: =Q25
B6: Contribution Margin | C6: =C4+C5 -> 3698.3203 | G6: =IF(G4="","",G4+G5) -> 3421 | H6: =IF(H4="","",H4+H5) -> 5389 | I6: =IF(I4="","",I4+I5) | J6: =IF(J4="","",J4+J5) | K6: =IF(K4="","",K4+K5) | L6: =IF(L4="","",L4+L5) | M6: =IF(M4="","",M4+M5) | N6: =IF(N4="","",N4+N5) | ... Q6: =IF(Q4="","",Q4+Q5)
B7: Fixed Costs | C7: =C35 -> -1106.5 | G7: =G35 -> -1084 | H7: =H35 -> -1129 | I7: =I35 | J7: =J35 | K7: =K35 | L7: =L35 | M7: =M35 | N7: =N35 | ... Q7: =Q35
B8: Operating EBIT | C8: =C6+C7 -> 2591.8203 | G8: =IF(G$4="","",G6+G7) -> 2337 | H8: =IF(H$4="","",H6+H7) -> 4260 | I8: =IF(I$4="","",I6+I7) | J8: =IF(J$4="","",J6+J7) | K8: =IF(K$4="","",K6+K7) | L8: =IF(L$4="","",L6+L7) | M8: =IF(M$4="","",M6+M7) | N8: =IF(N$4="","",N6+N7) | ... Q8: =IF(Q$4="","",Q6+Q7)
B9: Add Back D&A | C9: =BS!$G$39*BS!D58 -> 160 | G9: =IF(Data!C61="","",-Data!C61) -> 160 | H9: =IF(Data!D61="","",-Data!D61) -> 198 | I9: =IF(Data!E61="","",-Data!E61) | J9: =IF(Data!F61="","",-Data!F61) | K9: =IF(Data!G61="","",-Data!G61) | L9: =IF(Data!H61="","",-Data!H61) | M9: =IF(Data!I61="","",-Data!I61) | N9: =IF(Data!J61="","",-Data!J61) | ... Q9: =IF(Data!M61="","",-Data!M61)
B10: Maintenance Capex | C10: =-C4*C78 -> -160 | G10: =Data!C62 -> -69 | H10: =Data!D62 -> -108 | I10: =Data!E62 | J10: =Data!F62 | K10: =Data!G62 | L10: =Data!H62 | M10: =Data!I62 | N10: =Data!J62 | ... Q10: =Data!M62
B11: Stable Non-Operating EBIT | C11: =C63 -> 639 | G11: =G61 -> 639 | H11: =H61 -> 927 | I11: =I61 | J11: =J61 | K11: =K61 | L11: =L61 | M11: =M61 | N11: =N61 | ... Q11: =Q61
B12: Net Interest Income | C12: =C50 -> 142.19539 | G12: =G50 -> 259.96861 | H12: =H50 -> 139.30261 | I12: =I50 | J12: =J50 | K12: =K50 | L12: =L50 | M12: =M50 | N12: =N50 | ... Q12: =Q50
B13: Pre-tax Profit | C13: =SUM(C8:C12) -> 3373.0157 | G13: =IF(G$4="","",SUM(G8:G12)) -> 3326.9686 | H13: =IF(H$4="","",SUM(H8:H12)) -> 5416.3026 | I13: =IF(I$4="","",SUM(I8:I12)) | J13: =IF(J$4="","",SUM(J8:J12)) | K13: =IF(K$4="","",SUM(K8:K12)) | L13: =IF(L$4="","",SUM(L8:L12)) | M13: =IF(M$4="","",SUM(M8:M12)) | N13: =IF(N$4="","",SUM(N8:N12)) | ... Q13: =IF(Q$4="","",SUM(Q8:Q12))
B14: Income Tax | C14: =-SUM(C8+C11,C12)*C43 -> -809.52376 | G14: =Data!C46 -> -519 | H14: =Data!D46 -> -860.83483 | I14: =Data!E46 | J14: =Data!F46 | K14: =Data!G46 | L14: =Data!H46 | M14: =Data!I46 | N14: =Data!J46 | ... Q14: =Data!M46
B15: NCI’s Share of Profits | C15: =-C4*C83 -> -22.869708 | G15: =Data!C48 -> 0 | H15: =Data!D48 -> -31 | I15: =Data!E48 | J15: =Data!F48 | K15: =Data!G48 | L15: =Data!H48 | M15: =Data!I48 | N15: =Data!J48 | ... Q15: =Data!M48
B16: After-tax Profit | C16: =SUM(C13:C15) -> 2540.6222 | G16: =IF(G$4="","",SUM(G13:G15)) -> 2807.9686 | H16: =IF(H$4="","",SUM(H13:H15)) -> 4524.4678 | I16: =IF(I$4="","",SUM(I13:I15)) | J16: =IF(J$4="","",SUM(J13:J15)) | K16: =IF(K$4="","",SUM(K13:K15)) | L16: =IF(L$4="","",SUM(L13:L15)) | M16: =IF(M$4="","",SUM(M13:M15)) | N16: =IF(N$4="","",SUM(N13:N15)) | ... Q16: =IF(Q$4="","",SUM(Q13:Q15))
B17: WCInv | C17: =-C4*C85 -> 0 | E17: WCInv is by default excluded
B18: Net Borrowing | C18: 0 | E18: Net borrowing is excluded
B19: FCFE | C19: =C16+C17 -> 2540.6222 | G19: =IF(G$4="","",G16+G17) -> 2807.9686 | H19: =IF(H$4="","",H16+H17) -> 4524.4678 | I19: =IF(I$4="","",I16+I17) | J19: =IF(J$4="","",J16+J17) | K19: =IF(K$4="","",K16+K17) | L19: =IF(L$4="","",L16+L17) | M19: =IF(M$4="","",M16+M17) | N19: =IF(N$4="","",N16+N17) | ... Q19: =IF(Q$4="","",Q16+Q17)
B21: Operating Cost Structure | E21: Notes
B22: Variable Costs
B23: COGS | C23: =-C4*C28 -> -5066.6797 | G23: =Data!C37 -> -5344 | H23: =Data!D37 -> -6492 | I23: =Data!E37 | J23: =Data!F37 | K23: =Data!G37 | L23: =Data!H37 | M23: =Data!I37 | N23: =Data!J37 | ... Q23: =Data!M37
B24: Selling Expenses | C24: =-C4*C29 -> 0 | G24: =Data!C40 -> 0 | H24: =Data!D40 -> 0 | I24: =Data!E40 | J24: =Data!F40 | K24: =Data!G40 | L24: =Data!H40 | M24: =Data!I40 | N24: =Data!J40 | ... Q24: =Data!M40
B25: Variable Costs | C25: =C23+C24 -> -5066.6797 | G25: =IF(G$4="","",G23+G24) -> -5344 | H25: =IF(H$4="","",H23+H24) -> -6492 | I25: =IF(I$4="","",I23+I24) | J25: =IF(J$4="","",J23+J24) | K25: =IF(K$4="","",K23+K24) | L25: =IF(L$4="","",L23+L24) | M25: =IF(M$4="","",M23+M24) | N25: =IF(N$4="","",N23+N24) | ... Q25: =IF(Q$4="","",Q23+Q24)
B27: Variable Costs % of Sales
B28: COGS | C28: =AVERAGE(G28:H28) -> 0.57805816 | E28: Historical Average | G28: =IF(G$4="","",ABS(G23/G$4)) -> 0.60969766 | H28: =IF(H$4="","",ABS(H23/H$4)) -> 0.54641865 | I28: =IF(I$4="","",ABS(I23/I$4)) | J28: =IF(J$4="","",ABS(J23/J$4)) | K28: =IF(K$4="","",ABS(K23/K$4)) | L28: =IF(L$4="","",ABS(L23/L$4)) | M28: =IF(M$4="","",ABS(M23/M$4)) | N28: =IF(N$4="","",ABS(N23/N$4)) | ... Q28: =IF(Q$4="","",ABS(Q23/Q$4))
B29: =B24 -> Selling Expenses | C29: =AVERAGE(G29:J29) -> 0 | E29: Historical Average | G29: =IF(G$4="","",ABS(G24/G$4)) -> 0 | H29: =IF(H$4="","",ABS(H24/H$4)) -> 0 | I29: =IF(I$4="","",ABS(I24/I$4)) | J29: =IF(J$4="","",ABS(J24/J$4)) | K29: =IF(K$4="","",ABS(K24/K$4)) | L29: =IF(L$4="","",ABS(L24/L$4)) | M29: =IF(M$4="","",ABS(M24/M$4)) | N29: =IF(N$4="","",ABS(N24/N$4)) | ... Q29: =IF(Q$4="","",ABS(Q24/Q$4))
B30: Variable Costs | C30: =ABS(C25/$C$4) -> 0.57805816 | G30: =IF(G$4="","",ABS(G25/G$4)) -> 0.60969766 | H30: =IF(H$4="","",ABS(H25/H$4)) -> 0.54641865 | I30: =IF(I$4="","",ABS(I25/I$4)) | J30: =IF(J$4="","",ABS(J25/J$4)) | K30: =IF(K$4="","",ABS(K25/K$4)) | L30: =IF(L$4="","",ABS(L25/L$4)) | M30: =IF(M$4="","",ABS(M25/M$4)) | N30: =IF(N$4="","",ABS(N25/N$4)) | ... Q30: =IF(Q$4="","",ABS(Q25/Q$4))
B32: Fixed Costs
B33: G&A and other Opex | C33: =AVERAGE(G33:H33) -> -1106.5 | E33: Historical Average | G33: =Data!C41 -> -1084 | H33: =Data!D41 -> -1129 | I33: =Data!E41 | J33: =Data!F41 | K33: =Data!G41 | L33: =Data!H41 | M33: =Data!I41 | N33: =Data!J41 | ... Q33: =Data!M41
B34: R&D | C34: =AVERAGE(G34:J34) -> 0 | E34: Historical Average | G34: =Data!C42 -> 0 | H34: =Data!D42 -> 0 | I34: =Data!E42 | J34: =Data!F42 | K34: =Data!G42 | L34: =Data!H42 | M34: =Data!I42 | N34: =Data!J42 | ... Q34: =Data!M42
B35: Fixed Costs | C35: =C33+C34 -> -1106.5 | G35: =IF(G4="","",G33+G34) -> -1084 | H35: =IF(H4="","",H33+H34) -> -1129 | I35: =IF(I4="","",I33+I34) | J35: =IF(J4="","",J33+J34) | K35: =IF(K4="","",K33+K34) | L35: =IF(L4="","",L33+L34) | M35: =IF(M4="","",M33+M34) | N35: =IF(N4="","",N33+N34) | ... Q35: =IF(Q4="","",Q33+Q34)
B37: Fixed Costs % of Sales
B38: =B33 -> G&A and other Opex | C38: =ABS(C33/$C$4) -> 0.12624073 | G38: =IF(G$4="","",ABS(G33/G$4)) -> 0.1236737 | H38: =IF(H$4="","",ABS(H33/H$4)) -> 0.095025671 | I38: =IF(I$4="","",ABS(I33/I$4)) | J38: =IF(J$4="","",ABS(J33/J$4)) | K38: =IF(K$4="","",ABS(K33/K$4)) | L38: =IF(L$4="","",ABS(L33/L$4)) | M38: =IF(M$4="","",ABS(M33/M$4)) | N38: =IF(N$4="","",ABS(N33/N$4)) | ... Q38: =IF(Q$4="","",ABS(Q33/Q$4))
B39: =B34 -> R&D | C39: =ABS(C34/$C$4) -> 0 | G39: =IF(G$4="","",ABS(G34/G$4)) -> 0 | H39: =IF(H$4="","",ABS(H34/H$4)) -> 0 | I39: =IF(I$4="","",ABS(I34/I$4)) | J39: =IF(J$4="","",ABS(J34/J$4)) | K39: =IF(K$4="","",ABS(K34/K$4)) | L39: =IF(L$4="","",ABS(L34/L$4)) | M39: =IF(M$4="","",ABS(M34/M$4)) | N39: =IF(N$4="","",ABS(N34/N$4)) | ... Q39: =IF(Q$4="","",ABS(Q34/Q$4))
B40: Fixed Costs | C40: =ABS(C35/$C$4) -> 0.12624073 | G40: =IF(G$4="","",ABS(G35/G$4)) -> 0.1236737 | H40: =IF(H$4="","",ABS(H35/H$4)) -> 0.095025671 | I40: =IF(I$4="","",ABS(I35/I$4)) | J40: =IF(J$4="","",ABS(J35/J$4)) | K40: =IF(K$4="","",ABS(K35/K$4)) | L40: =IF(L$4="","",ABS(L35/L$4)) | M40: =IF(M$4="","",ABS(M35/M$4)) | N40: =IF(N$4="","",ABS(N35/N$4)) | ... Q40: =IF(Q$4="","",ABS(Q35/Q$4))
B42: Tax % of Pre-tax Profit
B43: Income Tax Rate | C43: 0.24 | E43: Use the highest past tax rate | G43: =IF(G$4="","",-G14/SUM(G8+G11,G12)) -> 0.16038474 | H43: =IF(H$4="","",-H14/SUM(H8+H11,H12)) -> 0.16161959 | I43: =IF(I$4="","",-I14/SUM(I8+I11,I12)) | J43: =IF(J$4="","",-J14/SUM(J8+J11,J12)) | K43: =IF(K$4="","",-K14/SUM(K8+K11,K12)) | L43: =IF(L$4="","",-L14/SUM(L8+L11,L12)) | M43: =IF(M$4="","",-M14/SUM(M8+M11,M12)) | N43: =IF(N$4="","",-N14/SUM(N8+N11,N12)) | ... Q43: =IF(Q$4="","",-Q14/SUM(Q8+Q11,Q12))
B45: Non-operating Income | E45: Notes
B46: Interest
...

Sheet Valuation_Model
B2: No-Growth DCF Valuation | H2: Notes
B3: No-Growth DCF | C3: =Normalized_FCF!C3 -> 1000000 | E3: Special Assumption
B4: Adjusted FCFE | C4: =Normalized_FCF!C19 -> 2540.6222 | D4: =Reporting_currency -> HKD | E4: Terminal Growth Rate (g): | F4: =Thesis!C75 -> 0
B5: /Equity Cost of Capital | C5: =Thesis!C70 -> 0.09
B6: Stable Income Value | C6: =(C4*(1+Terminal_Growth))/(Equity_Cost-Terminal_Growth) -> 28229.135 | D6: =Reporting_currency -> HKD | E6: Conservative Valuation: Setting g=0 can be a conservative assumption to avoid overestimating the stock’s value, especially if future growth is uncertain or unreliable.
B7: - Interest-bearing Debt | C7: =BS!G31 -> 3093 | D7: =Reporting_currency -> HKD
B8: + Non-operating Cash | C8: =BS!D66 -> 41505.82 | D8: =Reporting_currency -> HKD
B9: + Other Non-operating Assets | C9: =BS!H42 -> 7814.4 | D9: =Reporting_currency -> HKD
B10: Equity Value | C10: =C6-C7+C8+C9 -> 74456.356 | D10: =Reporting_currency -> HKD
B11: * Exchange rate | C11: =Exchange_Rate -> 1 | D11: =Thesis!D17 -> HKD
B12: Equity Value per share | C12: =(C10*C3)/Common_Shares*C11 -> 9.1112885 | D12: =Market_currency -> HKD
B14: Implied Growth Scenario Analysis
B15: FCFE Projection
B16: High Growth Period (HGP) | C16: =Scenarios!C65 -> -0.0073
B17: High Growth Rate (HGR) | C17: =Scenarios!C64 -> 10
B18: Value Per Share | C18: =(F52-C7+C8+C9)*Exchange_Rate/Common_Shares*C3 -> 9.0321281 | D18: =Market_currency -> HKD
B20: Year | C20: FCFE | D20: Growth Rates | E20: Discount Factor | F20: PV of FCFE
B21: 1 | C21: =C4*(1+D21) -> 2522.0756 | D21: =IF($C$17<B21,0,Valuation_Model!$C$16) -> -0.0073 | E21: =IF($C$17<B21,0,1/(1+Equity_Cost)^B21) -> 0.91743119 | F21: =C21*E21 -> 2313.8309
B22: 2 | C22: =IF(ROW()-ROW($C$21)<$C$17, $C$21*(1+D22)^(ROW()-ROW($C$21)), 0) -> 2503.6645 | D22: =IF($C$17<B22,0,Valuation_Model!$C$16) -> -0.0073 | E22: =IF($C$17<B22,0,1/(1+Equity_Cost)^B22) -> 0.84167999 | F22: =C22*E22 -> 2107.2843
B23: 3 | C23: =IF(ROW()-ROW($C$21)<$C$17, $C$21*(1+D23)^(ROW()-ROW($C$21)), 0) -> 2485.3877 | D23: =IF($C$17<B23,0,Valuation_Model!$C$16) -> -0.0073 | E23: =IF($C$17<B23,0,1/(1+Equity_Cost)^B23) -> 0.77218348 | F23: =C23*E23 -> 1919.1754
B24: 4 | C24: =IF(ROW()-ROW($C$21)<$C$17, $C$21*(1+D24)^(ROW()-ROW($C$21)), 0) -> 2467.2444 | D24: =IF($C$17<B24,0,Valuation_Model!$C$16) -> -0.0073 | E24: =IF($C$17<B24,0,1/(1+Equity_Cost)^B24) -> 0.70842521 | F24: =C24*E24 -> 1747.8581
B25: 5 | C25: =IF(ROW()-ROW($C$21)<$C$17, $C$21*(1+D25)^(ROW()-ROW($C$21)), 0) -> 2449.2335 | D25: =IF($C$17<B25,0,Valuation_Model!$C$16) -> -0.0073 | E25: =IF($C$17<B25,0,1/(1+Equity_Cost)^B25) -> 0.64993139 | F25: =C25*E25 -> 1591.8337
B26: 6 | C26: =IF(ROW()-ROW($C$21)<$C$17, $C$21*(1+D26)^(ROW()-ROW($C$21)), 0) -> 2431.3541 | D26: =IF($C$17<B26,0,Valuation_Model!$C$16) -> -0.0073 | E26: =IF($C$17<B26,0,1/(1+Equity_Cost)^B26) -> 0.59626733 | F26: =C26*E26 -> 1449.737
B27: 7 | C27: =IF(ROW()-ROW($C$21)<$C$17, $C$21*(1+D27)^(ROW()-ROW($C$21)), 0) -> 2413.6052 | D27: =IF($C$17<B27,0,Valuation_Model!$C$16) -> -0.0073 | E27: =IF($C$17<B27,0,1/(1+Equity_Cost)^B27) -> 0.54703424 | F27: =C27*E27 -> 1320.3247
B28: 8 | C28: =IF(ROW()-ROW($C$21)<$C$17, $C$21*(1+D28)^(ROW()-ROW($C$21)), 0) -> 2395.9859 | D28: =IF($C$17<B28,0,Valuation_Model!$C$16) -> -0.0073 | E28: =IF($C$17<B28,0,1/(1+Equity_Cost)^B28) -> 0.50186628 | F28: =C28*E28 -> 1202.4645
B29: 9 | C29: =IF(ROW()-ROW($C$21)<$C$17, $C$21*(1+D29)^(ROW()-ROW($C$21)), 0) -> 2378.4952 | D29: =IF($C$17<B29,0,Valuation_Model!$C$16) -> -0.0073 | E29: =IF($C$17<B29,0,1/(1+Equity_Cost)^B29) -> 0.46042778 | F29: =C29*E29 -> 1095.1253
B30: 10 | C30: =IF(ROW()-ROW($C$21)<$C$17, $C$21*(1+D30)^(ROW()-ROW($C$21)), 0) -> 2361.1322 | D30: =IF($C$17<B30,0,Valuation_Model!$C$16) -> -0.0073 | E30: =IF($C$17<B30,0,1/(1+Equity_Cost)^B30) -> 0.42241081 | F30: =C30*E30 -> 997.36776
B31: 11 | C31: =IF(ROW()-ROW($C$21)<$C$17, $C$21*(1+D31)^(ROW()-ROW($C$21)), 0) -> 0 | D31: =IF($C$17<B31,0,Valuation_Model!$C$16) -> 0 | E31: =IF($C$17<B31,0,1/(1+Equity_Cost)^B31) -> 0 | F31: =C31*E31 -> 0
B32: 12 | C32: =IF(ROW()-ROW($C$21)<$C$17, $C$21*(1+D32)^(ROW()-ROW($C$21)), 0) -> 0 | D32: =IF($C$17<B32,0,Valuation_Model!$C$16) -> 0 | E32: =IF($C$17<B32,0,1/(1+Equity_Cost)^B32) -> 0 | F32: =C32*E32 -> 0
B33: 13 | C33: =IF(ROW()-ROW($C$21)<$C$17, $C$21*(1+D33)^(ROW()-ROW($C$21)), 0) -> 0 | D33: =IF($C$17<B33,0,Valuation_Model!$C$16) -> 0 | E33: =IF($C$17<B33,0,1/(1+Equity_Cost)^B33) -> 0 | F33: =C33*E33 -> 0
... B50: 30 | C50: =IF(ROW()-ROW($C$21)<$C$17, $C$21*(1+D50)^(ROW()-ROW($C$21)), 0) -> 0 | D50: =IF($C$17<B50,0,Valuation_Model!$C$16) -> 0 | E50: =IF($C$17<B50,0,1/(1+Equity_Cost)^B50) -> 0 | F50: =C50*E50 -> 0
B51: Terminal Year | C51: =C$21*(1+Terminal_Growth)^$C$17/Equity_Cost -> 28023.063 | D51: =Terminal_Growth -> 0 | E51: =1/(1+Equity_Cost)^C17 -> 0.42241081 | F51: =C51*E51 -> 11837.245
E52: Total PV | F52: =SUM(F21:F51) -> 27582.246
B54: Sensitivity Analysis (Enterprise Value)
A55: =F52 -> 27582.246 | B55: =C78 -> -0.2 | C55: =C77 -> -0.05 | D55: =C76 -> 0 | E55: =C75 -> 0.02 | F55: =C74 -> 0.05
A56: 5 | B56: 20193.593 | C56: 25999.545 | D56: 28229.135 | E56: 29169.389 | F56: 30635.527
A57: 10 | B57: 16230.164 | C57: 24207.81 | D57: 28229.135 | E57: 30120.812 | F57: 33324.021
A58: 15 | B58: 13140.891 | C58: 22409.643 | D58: 28229.135 | E58: 31246.687 | F58: 36765.067
A59: 20 | B59: 11023.755 | C59: 20922.287 | D59: 28229.135 | E59: 32342.61 | F59: 40406.434
A60: 25 | B60: 9624.4797 | C60: 19795.346 | D60: 28229.135 | E60: 33316.212 | F60: 43938.451
...

Sheet Scenarios
B2: Current Situation | H2: Warning: Do Not Remove this logic
B3: Selection | H3: 0 | I3: =-Market_Price -> -7.9
B4: Past Years Selected | C4: 3 | E4: Tie the business story into the three levers of value: FCFE, growth and risk. | H4: 1 | I4: =IF(ROW()-3 < $C$76, $C$77, IF(ROW()-3 = $C$76, $C$77 + $C$60, "")) -> 0.58
H5: 2 | I5: =IF(ROW()-3 < $C$76, $C$77, IF(ROW()-3 = $C$76, $C$77 + $C$60, "")) -> 0.58
B6: Latest | C6: =Valuation_Model!C3 -> 1000000 | E6: Prompt for fundamental Analysis | H6: 3 | I6: =IF(ROW()-3 < $C$76, $C$77, IF(ROW()-3 = $C$76, $C$77 + $C$60, "")) -> 9.6147055
B7: EBIT | C7: =Normalized_FCF!G8 -> 2337 | D7: =Reporting_currency -> HKD | E7: ="Please develop three logical "&C18&"-year scenarios (Base Case, Pessimistic Case, Optimistic Case) and two extreme "&C46&"-year scenarios (Success Scenario, Devil’s Advocate Scenario) for "&Thesis!C5&"("&Thesis!D5&"). Each scenario should include the Compound Growth Rate, the Probability Assessment, and the Business Narrative." -> Please develop three logical 10-year scenarios (Base Case, Pessimistic Case, Optimistic Case) and two extreme 15-year scenarios (Success Scenario, Devil’s Advocate Scenario) for SINO LAND(0083.HK). Each scenario should include the Compound Growth Rate, the Probability Assessment, and the Business Narrative. | H7: 4 | I7: =IF(ROW()-3 < $C$76, $C$77, IF(ROW()-3 = $C$76, $C$77 + $C$60, ""))
B8: FCFE | C8: =Normalized_FCF!G19 -> 2807.9686 | D8: =Reporting_currency -> HKD | H8: 5 | I8: =IF(ROW()-3 < $C$76, $C$77, IF(ROW()-3 = $C$76, $C$77 + $C$60, ""))
B9: Normalized | C9: =Normalized_FCF!C19 -> 2540.6222 | D9: =Reporting_currency -> HKD | H9: 6 | I9: =IF(ROW()-3 < $C$76, $C$77, IF(ROW()-3 = $C$76, $C$77 + $C$60, ""))
H10: 7 | I10: =IF(ROW()-3 < $C$76, $C$77, IF(ROW()-3 = $C$76, $C$77 + $C$60, ""))
B11: CAGR | H11: 8 | I11: =IF(ROW()-3 < $C$76, $C$77, IF(ROW()-3 = $C$76, $C$77 + $C$60, ""))
B12: Sales | C12: =(Normalized_FCF!G4/OFFSET(Normalized_FCF!G4, 0, $C$4))^(1/$C$4) - 1 -> #VALUE! | H12: 9 | I12: =IF(ROW()-3 < $C$76, $C$77, IF(ROW()-3 = $C$76, $C$77 + $C$60, ""))
B13: Operating EBIT | C13: =(Normalized_FCF!G8/OFFSET(Normalized_FCF!G8, 0, $C$4))^(1/$C$4) - 1 -> #VALUE! | H13: 10 | I13: =IF(ROW()-3 < $C$76, $C$77, IF(ROW()-3 = $C$76, $C$77 + $C$60, ""))
B14: FCFE | C14: =(Normalized_FCF!G19/OFFSET(Normalized_FCF!G19, 0, $C$4))^(1/$C$4) - 1 -> #VALUE!
B16: General Scenarios
B17: Assumption | E17: Guidance Note
B18: High Growth Period (HGP) | C18: 10 | E18: Fundamental analysis and market signal analysis should be combined, with fundamental analysis given priority and market signal analysis serving as a supplement. Market signal analysis predicts a company's future trend, while fundamental analysis interprets the trend and identifies relevant fundamental factors and possibilities.
B20: Reference
B21: Market Price | C21: =Market_Price -> 7.9 | D21: =Market_currency -> HKD
B22: No Growth Value per share | C22: =Valuation_Model!C12 -> 9.1112885 | D22: =Market_currency -> HKD
B24: Base | E24: Business Story
B25: High Growth Period (HGP) | C25: =C18 -> 10
B26: High Growth Rate (HGR) | C26: 0
B27: Value per share | C27: =Valuation_Model!E76 -> 9.1112885 | D27: =Market_currency -> HKD
B28: Probabilities | C28: 0.55
B30: Pessimistic | E30: Business Story
B31: High Growth Period (HGP) | C31: =C18 -> 10
B32: High Growth Rate (HGR) | C32: -0.05
B33: Value per share | C33: =Valuation_Model!E77 -> 8.6191955 | D33: =Market_currency -> HKD
B34: Probabilities | C34: 0.2
B36: Optimistic | E36: Business Story
B37: High Growth Period (HGP) | C37: =C18 -> 10
B38: High Growth Rate (HGR) | C38: 0.02
B39: Value per share | C39: =Valuation_Model!E75 -> 9.3427746 | D39: =Market_currency -> HKD
B40: Probabilities | C40: =1-C28-C34 -> 0.25
B42: Expected Value = | C42: =C27*C28+C33*C34+C39*C40 -> 9.0707414 | D42: =Market_currency -> HKD
B44: Extreme Scenarios
B45: Assumption
B46: High Growth Period (HGP) | C46: 15
B48: Devil's advocate | E48: Business Story
B49: High Growth Period (HGP) | C49: =C46 -> 15
...
