Workbook
Name Common_Shares: Thesis!$C$6
Name Equity_Cost: Thesis!$C$86
Name Exchange_Rate: Thesis!$C$16
Name Market_currency: Thesis!$C$13
Name Market_Price: Thesis!$C$12
Name Reporting_currency: Thesis!$C$25
Name scaling_factor: Data!$C$3
Name Terminal_Growth: Thesis!$C$92
Name valuation_method: Thesis!$E$21

Sheet Thesis
B1: Model last updated: | C1: 45730 | D1: INT | E1: Selected: | F1: Y
A2: Executive Summary
B4: Company Information
B5: Company Name | C5: SINO LAND
B6: Number of Shares: | C6: 8171879936
B7: Report Interval: | C7: 12
B8: Update Required After: | C8: =EOMONTH(EDATE(BS!C1,C7+2),0) -> 45900
B10: Listing Information
B11: Symbol: | C11: 0083.HK
B12: Market Price: | C12: 8.15
B13: Market Currency | C13: HKD
B14: Capitalization: | C14: =Thesis!C12*Common_Shares/1000000 -> 66600.821 | D14: =IF(D11="","",Thesis!D12*Common_Shares/1000000)
B15: Forex Symbol: | C15: =IF(C25=C13,C13,C25&"/"&C13) -> HKD | D15: =IF(D11="","",IF(C25=D13,D13,C25&"/"&D13))
B16: Exchange Rate: | C16: 1
B18: Guidance Note: This model determines a target buy price consistent with defined investment criteria. It follows a logical progression: establishing current sustainable earnings, adjusting for financial structure, incorporating growth scenarios, and finally applying the investor’s required return.
B20: Valuation Overview
B21: Growth Classification: | C21: =IF(Scenarios!C69="Y",Scenarios!B69,"")&IF(Scenarios!C70="Y",Scenarios!B70,"")&IF(Scenarios!C71="Y",Scenarios!B71,"")&" "&IF(Scenarios!C72="Y",Scenarios!B72,"") -> Negative Growth Asset Play | D21: Valuation Method | E21: DCF
B22: Comp_Sector: | C22: RES_01 | D22: =IF(valuation_method="DDM","DDM Terminal Value","")
B23: Business Model Risk Premium: | C23: Y
B24: Management Risk Premium: | C24: N
B25: Reporting Currency: | C25: HKD | D25: =IF(D11="","",Market_currency&"/"&D13&":") | E25: =IF(D11="","",1/Exchange_Rate*D16)
B26: ="Expected Equity Value ("&C13&") :" -> Expected Equity Value (HKD) : | C26: =C132 -> 9.3641571 | D26: Market Implied Annual Return: | E26: =Scenarios!C87 -> 0.1155057
B28: Valuation Outputs | C28: =C145&" ("&Market_currency&")" -> 0083.HK (HKD) | D28: =IF(D11="","",D145&" ("&D13&")") | E28: Holding Period | F28: 3
B29: Target Price | C29: =C149 -> 4.6237469 | D29: =D149 | E29: Target return | F29: 0.3674
B30: Entry Price | C30: =C157 -> 6.3792497 | D30: =D157 | E30: Entry yield | F30: 0.2174
B31: Sell Price | C31: =C165 -> 9.0460821 | D31: =D165 | E31: Base equity cost | F31: 0.075
B32: Exit Price | C32: =C173 -> 8.1111667 | D32: =D173 | E32: Benchmark yield | F32: 0.1174
A34: Step 1: Establishing the Company’s Sustainable Earning Power (Calculating Normalized FCFE)
B36: Goal: To quantify the underlying FCFE the business consistently generates for its equity owners, stripping away temporary fluctuations or accounting choices.The FCFE/Market Cap yield gives a direct measure of this cash generation relative to the current market price.
B37: FCFE = (Normalized Operating EBIT + Depreciation & Amortization – Capital Expenditures) + Stable Non-Operating EBIT + Net Interest Income – Taxes – NCI’s Share of Profits – Working Capital Investment
B39: Key Components | C39: =scaling_factor -> 1000000
B40: • Normalized Operating EBIT: Earnings before interest and taxes from core business operations, adjusted to remove one-time or irregular items for a sustainable earnings base.
B41: Normalized Operating EBIT = | C41: =Normalized_FCF!C8 -> 2591.8203 | D41: =Reporting_currency -> HKD
B43: • Depreciation & Amortization (D&A): Non-cash expenses added back to reflect cash generated from operations. • Capital Expenditures (Capex): Cash outflows required to maintain or expand operational assets
B44: D&A = | C44: =Normalized_FCF!C9 -> 160 | D44: =Reporting_currency -> HKD
B45: Capex = | C45: =Normalized_FCF!C10 -> -160 | D45: =Reporting_currency -> HKD
B47: • Stable Non-Operating EBIT: Consistent earnings from non-core assets, such as fixed-income investments, dividend-paying stocks, or rental properties.
B48: Stable Non-Operating EBIT = | C48: =Normalized_FCF!C11 -> 639 | D48: =Reporting_currency -> HKD
B50: • Net Interest Income: Interest income minus interest expense
B51: Operating Interest Income = | C51: =Normalized_FCF!C48 -> 163.69305 | D51: =Reporting_currency -> HKD
...

Sheet Data
B1: =Thesis!C25 -> HKD | C1: 45473 | D1: =EOMONTH(EDATE(C1,-12),0) -> 45107 | E1: =EOMONTH(EDATE(D1,-12),0) -> 44742 | F1: =EOMONTH(EDATE(E1,-12),0) -> 44377 | G1: =EOMONTH(EDATE(F1,-12),0) -> 44012 | H1: =EOMONTH(EDATE(G1,-12),0) -> 43646 | I1: =EOMONTH(EDATE(H1,-12),0) -> 43281 | J1: =EOMONTH(EDATE(I1,-12),0) -> 42916 | K1: =EOMONTH(EDATE(J1,-12),0) -> 42551 | ... M1: =EOMONTH(EDATE(L1,-12),0) -> 41820
B2: Data (Dirty)
B3: Income Statement | C3: 1000000
B4: Sales | C4: 8765 | D4: 11881 | E4: 15650.563 | F4: 24433.372 | G4: 5887
B5: COGS | C5: 5344 | D5: 6492 | E5: 7482.8818 | F5: 11196.896 | G5: 2437
B6: OPEX | C6: 1084 | D6: 1129 | E6: 867.48328 | F6: 823.28128
B7: Incl. Selling Expenses
B8: R&D
B9: Share of JV or associate Results | C9: 639 | D9: 927
B10: Dividend or Interests from FA
B11: Investment property
B12: Interest Expense | C12: 43 | D12: 40.775368 | E12: 49.197794 | F12: 81.763175
B13: Interest Income | C13: 2340 | D13: 1390.8453 | E13: 337.25969 | F13: 572.18514
B14: Income Tax Paid | C14: 519 | D14: 860.83483 | E14: 1349.1075 | F14: 2530.7695
B15: Reported Net Income | C15: 4251 | D15: 5880 | E15: 5735.3965 | F15: 9646.037
B16: Non-controling Interests | C16: -151 | D16: 31
B18: Cash Flow Statement
B19: D&A | C19: 160 | D19: 198 | E19: 181.018 | F19: 186.147
B20: CAPX | C20: 69 | D20: 108
B21: WCInv | C21: 910 | D21: 2541
B22: CFO
B23: CFI
B24: CFF
B25: ="Dividend per share ("&Market_currency&")" -> Dividend per share (HKD) | C25: 0.58 | D25: 0.58 | E25: 0.57
B27: Balance Sheet | C27: Latest Asset Value
B28: ST AR | C28: =BS!C4 -> 8029 | D28: 7251
B29: ST Inventory | C29: =BS!C6 -> 9844 | D29: 16389
B30: Total Liabilities | C30: =BS!C33+BS!C42 -> 13889 | D30: 10902
B31: Total Equity | C31: =BS!G27 -> 167107 | D31: 163105
B32: Non-common Interest | C32: =BS!G28 -> 519
B34: IS & CF Statements (Clean)
B35: Income Statement
B36: Sales | C36: =IF(C$4="","",C4) -> 8765 | D36: =IF(D$4="","",D4) -> 11881 | E36: =IF(E$4="","",E4) -> 15650.563 | F36: =IF(F$4="","",F4) -> 24433.372 | G36: =IF(G$4="","",G4) -> 5887 | H36: =IF(H$4="","",H4) | I36: =IF(I$4="","",I4) | J36: =IF(J$4="","",J4) | ... M36: =IF(M$4="","",M4)
B37: COGS | C37: =IF(C$4="","",-C5) -> -5344 | D37: =IF(D$4="","",-D5) -> -6492 | E37: =IF(E$4="","",-E5) -> -7482.8818 | F37: =IF(F$4="","",-F5) -> -11196.896 | G37: =IF(G$4="","",-G5) -> -2437 | H37: =IF(H$4="","",-H5) | I37: =IF(I$4="","",-I5) | J37: =IF(J$4="","",-J5) | ... M37: =IF(M$4="","",-M5)
B38: Gross Margin | C38: =IF(C36="","",C36+C37) -> 3421 | D38: =IF(D36="","",D36+D37) -> 5389 | E38: =IF(E36="","",E36+E37) -> 8167.6816 | F38: =IF(F36="","",F36+F37) -> 13236.475 | G38: =IF(G36="","",G36+G37) -> 3450 | H38: =IF(H36="","",H36+H37) | I38: =IF(I36="","",I36+I37) | J38: =IF(J36="","",J36+J37) | ... M38: =IF(M36="","",M36+M37)
B39: OPEX | C39: =IF(C$4="","",-C6) -> -1084 | D39: =IF(D$4="","",-D6) -> -1129 | E39: =IF(E$4="","",-E6) -> -867.48328 | F39: =IF(F$4="","",-F6) -> -823.28128 | G39: =IF(G$4="","",-G6) -> 0 | H39: =IF(H$4="","",-H6) | I39: =IF(I$4="","",-I6) | J39: =IF(J$4="","",-J6) | ... M39: =IF(M$4="","",-M6)
B40: Incl. Selling Expenses | C40: =IF(C$4="","",-C7) -> 0 | D40: =IF(D$4="","",-D7) -> 0 | E40: =IF(E$4="","",-E7) -> 0 | F40: =IF(F$4="","",-F7) -> 0 | G40: =IF(G$4="","",-G7) -> 0 | H40: =IF(H$4="","",-H7) | I40: =IF(I$4="","",-I7) | J40: =IF(J$4="","",-J7) | ... M40: =IF(M$4="","",-M7)
B41: Incl. Other Opex | C41: =IF(C$4="","",C39-C40) -> -1084 | D41: =IF(D$4="","",D39-D40) -> -1129 | E41: =IF(E$4="","",E39-E40) -> -867.48328 | F41: =IF(F$4="","",F39-F40) -> -823.28128 | G41: =IF(G$4="","",G39-G40) -> 0 | H41: =IF(H$4="","",H39-H40) | I41: =IF(I$4="","",I39-I40) | J41: =IF(J$4="","",J39-J40) | ... M41: =IF(M$4="","",M39-M40)
B42: R&D | C42: =IF(C$4="","",-C8) -> 0 | D42: =IF(D$4="","",-D8) -> 0 | E42: =IF(E$4="","",-E8) -> 0 | F42: =IF(F$4="","",-F8) -> 0 | G42: =IF(G$4="","",-G8) -> 0 | H42: =IF(H$4="","",-H8) | I42: =IF(I$4="","",-I8) | J42: =IF(J$4="","",-J8) | ... M42: =IF(M$4="","",-M8)
B43: Operating EBIT | C43: =IF(C$4="","",C38+C39+C42) -> 2337 | D43: =IF(D$4="","",D38+D39+D42) -> 4260 | E43: =IF(E$4="","",E38+E39+E42) -> 7300.1983 | F43: =IF(F$4="","",F38+F39+F42) -> 12413.194 | G43: =IF(G$4="","",G38+G39+G42) -> 3450 | H43: =IF(H$4="","",H38+H39+H42) | I43: =IF(I$4="","",I38+I39+I42) | J43: =IF(J$4="","",J38+J39+J42) | ... M43: =IF(M$4="","",M38+M39+M42)
...

Sheet BS
B1: Most Recent Quarter | C1: 45473 | F1: =IF(MONTH(C1)=MONTH(Normalized_FCF!G1),"FY","Quarter")&" Report" -> FY Report | H1: =scaling_factor -> 1000000
B2: Lastest Balance Sheet
B3: ST Operating Assets | C3: Book | D3: Valued @ | F3: ST Non-Operating Assets | G3: Book | H3: Valued @
B4: ST AR | C4: 8029 | D4: 0.6 | F4: Cash and cash equivalents | G4: 45665 | H4: 0.9
B5: Operating ST Financial Assets | C5: 0 | D5: 0.6 | F5: Restricted cash | G5: 2014 | H5: 0.7
B6: Inventory | C6: 9844 | D6: 0.5 | F6: Securities with stable income | G6: 156 | H6: 0.6
B7: Properties held for sale | C7: 5466 | D7: 0.6 | F7: Other Securities | G7: 0 | H7: 0.6
B8: Properties held for income | C8: 0 | D8: 0.6 | F8: Properties with stable income | G8: 0 | H8: 0.6
B9: Prepayments and Contract Assets | C9: 0 | D9: 0.1 | F9: Other Properties | G9: 0 | H9: 0.6
B10: ST DTA | C10: 10 | D10: 0.9
B11: Other ST Assets | C11: 0 | D11: 0.05
B12: Operating ST Assets | C12: =SUM(C4:C11) -> 23349 | D12: =C4*D4+C5*D5+C9*D9+C6*D6+C8*D8+C7*D7+C10*D10+C11*D11 -> 13028 | F12: Non-Operating ST Assets | G12: =SUM(G4:G9) -> 47835 | H12: =G4*H4+G5*H5+G6*H6+G7*H7+G8*H8+G9*H9 -> 42601.9
B14: LT Operating Assets | C14: Book | D14: Valued @ | F14: LT Non-Operating Assets | G14: Book | H14: Valued @
B15: LT AR | C15: 2757 | D15: 0.4 | F15: LT Depositis | G15: 0 | H15: 0.8
B16: Operating LT Financial Assets | C16: 0 | D16: 0.5 | F16: Securities with stable income | G16: 1373 | H16: 0.6
B17: Properties held for sale | C17: 67668 | D17: 0.6 | F17: Other Securities | G17: 13024 | H17: 0.6
B18: Properties held for income | C18: 0 | D18: 0.6 | F18: JV or associate with stable income | G18: 23696 | H18: 0.1
B19: PP&E & Right of Use Assets | C19: 1284 | D19: 0.1 | F19: Other JV or associate | G19: 0 | H19: 0.1
B20: Biological assets | C20: 0 | D20: 0.05 | F20: Properties with stable income | G20: 0 | H20: 0.2
B21: Intangible assets | C21: 0 | D21: 0.05 | F21: Other Properties | G21: 0 | H21: 0.1
B22: LT DTA | C22: 10 | D22: 0.9
B23: Other assets & Goodwill | C23: 0 | D23: 0
B24: Operating LT Assets | C24: =SUM(C15:C23) -> 71719 | D24: =C15*D15+C16*D16+C18*D18+C17*D17+C19*D19+C20*D20+C21*D21+C22*D22+C23*D23 -> 41841 | F24: Non-Operating LT Assets | G24: =SUM(G15:G21) -> 38093 | H24: =G15*H15+G16*H16+G17*H17+G18*H18+G19*H19+G20*H20+G21*H21 -> 11007.8
B26: ST Liabilities | C26: Book | F26: BS Summary | G26: Book | H26: Valued @
B27: ST Borrowing | C27: 967 | F27: Total Equity | G27: =G32-G30 -> 167107 | H27: =H32-G30 -> 94589.7
B28: ST Lease liabilities | C28: 37 | F28: Incl. Minority Interest (NCI) | G28: 519
B29: ST SH Loan | C29: 0 | F29: Incl. Common Equity | G29: =G27-G28 -> 166588 | H29: =H27-G28 -> 94070.7
B30: ST Financial Liabilities | C30: 0 | F30: Total Liabilities | G30: =C33+C42 -> 13889
B31: ST Interest-bearing Debt | C31: =SUM(C27:C30) -> 1004 | F31: incl. Interest-bearing Debt | G31: =C31+C40 -> 3093
B32: Other ST liabilities | C32: =C33-C31 -> 8048 | F32: Total Assets | G32: =G35+G40 -> 180996 | H32: =H35+H40 -> 108478.7
B33: Current Liabilities | C33: 9052
F34: Assets Summary | G34: Book | H34: Valued @
B35: LT Liabilities | C35: Book | F35: Operating Assets | G35: =C12+C24 -> 95068 | H35: =D12+D24 -> 54869
B36: LT Borrowing | C36: 832 | F36: incl. AR | G36: =C4+C15 -> 10786
B37: LT Lease liabilities | C37: 27 | F37: incl. inventory | G37: =C6 -> 9844
B38: LT SH Loan | C38: 1230 | F38: incl. Properties held for sale | G38: =C7+C17 -> 73134
B39: LT Financial Liabilities | C39: 0 | F39: incl. Fixed Assets | G39: =C7+C17+C19+C20 -> 74418 | H39: =C7*D7+C17*D17+C19*D19+C20*D20 -> 44008.8
B40: LT Interest-bearing Debt | C40: =SUM(C36:C39) -> 2089 | F40: Non-operating Assets | G40: =G12+G24 -> 85928 | H40: =H12+H24 -> 53609.7
B41: Other LT liabilities | C41: =C42-C40 -> 2748 | F41: incl. Assets with stable income | G41: =C70 -> 72904 | H41: =H40-H42 -> 45795.3
B42: Noncurrent Liabilities | C42: 4837 | F42: incl. Other Assets | G42: =C82 -> 13024 | H42: =D82 -> 7814.4
...

Sheet Normalized_FCF
B1: =Thesis!C25 -> HKD | C1: Normalized | G1: =Data!C1 -> 45473 | H1: =EOMONTH(EDATE(G1,-12),0) -> 45107 | I1: =EOMONTH(EDATE(H1,-12),0) -> 44742 | J1: =EOMONTH(EDATE(I1,-12),0) -> 44377 | K1: =EOMONTH(EDATE(J1,-12),0) -> 44012 | L1: =EOMONTH(EDATE(K1,-12),0) -> 43646 | M1: =EOMONTH(EDATE(L1,-12),0) -> 43281 | N1: =EOMONTH(EDATE(M1,-12),0) -> 42916 | O1: =EOMONTH(EDATE(N1,-12),0) -> 42551 | ... Q1: =EOMONTH(EDATE(P1,-12),0) -> 41820
B2: FCFE Analysis | E2: Notes
B3: FCFE | C3: =scaling_factor -> 1000000
B4: Sales | C4: =G4 -> 8765 | G4: =Data!C36 -> 8765 | H4: =Data!D36 -> 11881 | I4: =Data!E36 -> 15650.563 | J4: =Data!F36 -> 24433.372 | K4: =Data!G36 -> 5887 | L4: =Data!H36 | M4: =Data!I36 | N4: =Data!J36 | ... Q4: =Data!M36
B5: Variable Costs | C5: =C25 -> -5066.6797 | G5: =G25 -> -5344 | H5: =H25 -> -6492 | I5: =I25 -> -7482.8818 | J5: =J25 -> -11196.896 | K5: =K25 -> -2437 | L5: =L25 | M5: =M25 | N5: =N25 | ... Q5: =Q25
B6: Contribution Margin | C6: =C4+C5 -> 3698.3203 | G6: =IF(G4="","",G4+G5) -> 3421 | H6: =IF(H4="","",H4+H5) -> 5389 | I6: =IF(I4="","",I4+I5) -> 8167.6816 | J6: =IF(J4="","",J4+J5) -> 13236.475 | K6: =IF(K4="","",K4+K5) -> 3450 | L6: =IF(L4="","",L4+L5) | M6: =IF(M4="","",M4+M5) | N6: =IF(N4="","",N4+N5) | ... Q6: =IF(Q4="","",Q4+Q5)
B7: Fixed Costs | C7: =C35 -> -1106.5 | G7: =G35 -> -1084 | H7: =H35 -> -1129 | I7: =I35 -> -867.48328 | J7: =J35 -> -823.28128 | K7: =K35 -> 0 | L7: =L35 | M7: =M35 | N7: =N35 | ... Q7: =Q35
B8: Operating EBIT | C8: =C6+C7 -> 2591.8203 | G8: =IF(G$4="","",G6+G7) -> 2337 | H8: =IF(H$4="","",H6+H7) -> 4260 | I8: =IF(I$4="","",I6+I7) -> 7300.1983 | J8: =IF(J$4="","",J6+J7) -> 12413.194 | K8: =IF(K$4="","",K6+K7) -> 3450 | L8: =IF(L$4="","",L6+L7) | M8: =IF(M$4="","",M6+M7) | N8: =IF(N$4="","",N6+N7) | ... Q8: =IF(Q$4="","",Q6+Q7)
B9: Add Back D&A | C9: =BS!$G$39*BS!D58 -> 160 | G9: =IF(Data!C61="","",-Data!C61) -> 160 | H9: =IF(Data!D61="","",-Data!D61) -> 198 | I9: =IF(Data!E61="","",-Data!E61) -> 181.018 | J9: =IF(Data!F61="","",-Data!F61) -> 186.147 | K9: =IF(Data!G61="","",-Data!G61) -> 0 | L9: =IF(Data!H61="","",-Data!H61) | M9: =IF(Data!I61="","",-Data!I61) | N9: =IF(Data!J61="","",-Data!J61) | ... Q9: =IF(Data!M61="","",-Data!M61)
B10: Maintenance Capex | C10: =-C4*C78 -> -160 | G10: =Data!C62 -> -69 | H10: =Data!D62 -> -108 | I10: =Data!E62 -> -181.018 | J10: =Data!F62 -> -186.147 | K10: =Data!G62 -> 0 | L10: =Data!H62 | M10: =Data!I62 | N10: =Data!J62 | ... Q10: =Data!M62
B11: Stable Non-Operating EBIT | C11: =C63 -> 639 | G11: =G61 -> 639 | H11: =H61 -> 927 | I11: =I61 -> 0 | J11: =J61 -> 0 | K11: =K61 -> 0 | L11: =L61 | M11: =M61 | N11: =N61 | ... Q11: =Q61
B12: Net Interest Income | C12: =C50 -> 120.69305 | G12: =G50 -> 224.79207 | H12: =H50 -> 118.39444 | I12: =I50 -> -10.601439 | J12: =J50 -> -16.281704 | K12: =K50 -> 0 | L12: =L50 | M12: =M50 | N12: =N50 | ... Q12: =Q50
B13: Pre-tax Profit | C13: =SUM(C8:C12) -> 3351.5133 | G13: =IF(G$4="","",SUM(G8:G12)) -> 3291.7921 | H13: =IF(H$4="","",SUM(H8:H12)) -> 5395.3944 | I13: =IF(I$4="","",SUM(I8:I12)) -> 7289.5968 | J13: =IF(J$4="","",SUM(J8:J12)) -> 12396.912 | K13: =IF(K$4="","",SUM(K8:K12)) -> 3450 | L13: =IF(L$4="","",SUM(L8:L12)) | M13: =IF(M$4="","",SUM(M8:M12)) | N13: =IF(N$4="","",SUM(N8:N12)) | ... Q13: =IF(Q$4="","",SUM(Q8:Q12))
B14: Income Tax | C14: =-SUM(C8+C11,C12)*C43 -> -804.36319 | G14: =Data!C46 -> -519 | H14: =Data!D46 -> -860.83483 | I14: =Data!E46 -> -1349.1075 | J14: =Data!F46 -> -2530.7695 | K14: =Data!G46 -> 0 | L14: =Data!H46 | M14: =Data!I46 | N14: =Data!J46 | ... Q14: =Data!M46
B15: NCI’s Share of Profits | C15: =-C4*C83 -> -22.869708 | G15: =Data!C48 -> 0 | H15: =Data!D48 -> -31 | I15: =Data!E48 -> 0 | J15: =Data!F48 -> 0 | K15: =Data!G48 -> 0 | L15: =Data!H48 | M15: =Data!I48 | N15: =Data!J48 | ... Q15: =Data!M48
B16: After-tax Profit | C16: =SUM(C13:C15) -> 2524.2804 | G16: =IF(G$4="","",SUM(G13:G15)) -> 2772.7921 | H16: =IF(H$4="","",SUM(H13:H15)) -> 4503.5596 | I16: =IF(I$4="","",SUM(I13:I15)) -> 5940.4893 | J16: =IF(J$4="","",SUM(J13:J15)) -> 9866.1428 | K16: =IF(K$4="","",SUM(K13:K15)) -> 3450 | L16: =IF(L$4="","",SUM(L13:L15)) | M16: =IF(M$4="","",SUM(M13:M15)) | N16: =IF(N$4="","",SUM(N13:N15)) | ... Q16: =IF(Q$4="","",SUM(Q13:Q15))
B17: WCInv | C17: =-C4*C85 -> 0 | E17: WCInv is by default excluded
B18: Net Borrowing | C18: 0 | E18: Net borrowing is excluded
B19: FCFE | C19: =C16+C17 -> 2524.2804 | G19: =IF(G$4="","",G16+G17) -> 2772.7921 | H19: =IF(H$4="","",H16+H17) -> 4503.5596 | I19: =IF(I$4="","",I16+I17) -> 5940.4893 | J19: =IF(J$4="","",J16+J17) -> 9866.1428 | K19: =IF(K$4="","",K16+K17) -> 3450 | L19: =IF(L$4="","",L16+L17) | M19: =IF(M$4="","",M16+M17) | N19: =IF(N$4="","",N16+N17) | ... Q19: =IF(Q$4="","",Q16+Q17)
B21: Operating Cost Structure | E21: Notes
B22: Variable Costs
B23: COGS | C23: =-C4*C28 -> -5066.6797 | G23: =Data!C37 -> -5344 | H23: =Data!D37 -> -6492 | I23: =Data!E37 -> -7482.8818 | J23: =Data!F37 -> -11196.896 | K23: =Data!G37 -> -2437 | L23: =Data!H37 | M23: =Data!I37 | N23: =Data!J37 | ... Q23: =Data!M37
B24: Selling Expenses | C24: =-C4*C29 -> 0 | G24: =Data!C40 -> 0 | H24: =Data!D40 -> 0 | I24: =Data!E40 -> 0 | J24: =Data!F40 -> 0 | K24: =Data!G40 -> 0 | L24: =Data!H40 | M24: =Data!I40 | N24: =Data!J40 | ... Q24: =Data!M40
B25: Variable Costs | C25: =C23+C24 -> -5066.6797 | G25: =IF(G$4="","",G23+G24) -> -5344 | H25: =IF(H$4="","",H23+H24) -> -6492 | I25: =IF(I$4="","",I23+I24) -> -7482.8818 | J25: =IF(J$4="","",J23+J24) -> -11196.896 | K25: =IF(K$4="","",K23+K24) -> -2437 | L25: =IF(L$4="","",L23+L24) | M25: =IF(M$4="","",M23+M24) | N25: =IF(N$4="","",N23+N24) | ... Q25: =IF(Q$4="","",Q23+Q24)
B27: Variable Costs % of Sales
B28: COGS | C28: =AVERAGE(G28:H28) -> 0.57805816 | E28: Historical Average | G28: =IF(G$4="","",ABS(G23/G$4)) -> 0.60969766 | H28: =IF(H$4="","",ABS(H23/H$4)) -> 0.54641865 | I28: =IF(I$4="","",ABS(I23/I$4)) -> 0.4781222 | J28: =IF(J$4="","",ABS(J23/J$4)) -> 0.45826244 | K28: =IF(K$4="","",ABS(K23/K$4)) -> 0.41396297 | L28: =IF(L$4="","",ABS(L23/L$4)) | M28: =IF(M$4="","",ABS(M23/M$4)) | N28: =IF(N$4="","",ABS(N23/N$4)) | ... Q28: =IF(Q$4="","",ABS(Q23/Q$4))
B29: =B24 -> Selling Expenses | C29: =AVERAGE(G29:J29) -> 0 | E29: Historical Average | G29: =IF(G$4="","",ABS(G24/G$4)) -> 0 | H29: =IF(H$4="","",ABS(H24/H$4)) -> 0 | I29: =IF(I$4="","",ABS(I24/I$4)) -> 0 | J29: =IF(J$4="","",ABS(J24/J$4)) -> 0 | K29: =IF(K$4="","",ABS(K24/K$4)) -> 0 | L29: =IF(L$4="","",ABS(L24/L$4)) | M29: =IF(M$4="","",ABS(M24/M$4)) | N29: =IF(N$4="","",ABS(N24/N$4)) | ... Q29: =IF(Q$4="","",ABS(Q24/Q$4))
B30: Variable Costs | C30: =ABS(C25/$C$4) -> 0.57805816 | G30: =IF(G$4="","",ABS(G25/G$4)) -> 0.60969766 | H30: =IF(H$4="","",ABS(H25/H$4)) -> 0.54641865 | I30: =IF(I$4="","",ABS(I25/I$4)) -> 0.4781222 | J30: =IF(J$4="","",ABS(J25/J$4)) -> 0.45826244 | K30: =IF(K$4="","",ABS(K25/K$4)) -> 0.41396297 | L30: =IF(L$4="","",ABS(L25/L$4)) | M30: =IF(M$4="","",ABS(M25/M$4)) | N30: =IF(N$4="","",ABS(N25/N$4)) | ... Q30: =IF(Q$4="","",ABS(Q25/Q$4))
B32: Fixed Costs
B33: G&A and other Opex | C33: =AVERAGE(G33:H33) -> -1106.5 | E33: Historical Average | G33: =Data!C41 -> -1084 | H33: =Data!D41 -> -1129 | I33: =Data!E41 -> -867.48328 | J33: =Data!F41 -> -823.28128 | K33: =Data!G41 -> 0 | L33: =Data!H41 | M33: =Data!I41 | N33: =Data!J41 | ... Q33: =Data!M41
B34: R&D | C34: =AVERAGE(G34:J34) -> 0 | E34: Historical Average | G34: =Data!C42 -> 0 | H34: =Data!D42 -> 0 | I34: =Data!E42 -> 0 | J34: =Data!F42 -> 0 | K34: =Data!G42 -> 0 | L34: =Data!H42 | M34: =Data!I42 | N34: =Data!J42 | ... Q34: =Data!M42
B35: Fixed Costs | C35: =C33+C34 -> -1106.5 | G35: =IF(G4="","",G33+G34) -> -1084 | H35: =IF(H4="","",H33+H34) -> -1129 | I35: =IF(I4="","",I33+I34) -> -867.48328 | J35: =IF(J4="","",J33+J34) -> -823.28128 | K35: =IF(K4="","",K33+K34) -> 0 | L35: =IF(L4="","",L33+L34) | M35: =IF(M4="","",M33+M34) | N35: =IF(N4="","",N33+N34) | ... Q35: =IF(Q4="","",Q33+Q34)
B37: Fixed Costs % of Sales
B38: =B33 -> G&A and other Opex | C38: =ABS(C33/$C$4) -> 0.12624073 | G38: =IF(G$4="","",ABS(G33/G$4)) -> 0.1236737 | H38: =IF(H$4="","",ABS(H33/H$4)) -> 0.095025671 | I38: =IF(I$4="","",ABS(I33/I$4)) -> 0.055428246 | J38: =IF(J$4="","",ABS(J33/J$4)) -> 0.033694952 | K38: =IF(K$4="","",ABS(K33/K$4)) -> 0 | L38: =IF(L$4="","",ABS(L33/L$4)) | M38: =IF(M$4="","",ABS(M33/M$4)) | N38: =IF(N$4="","",ABS(N33/N$4)) | ... Q38: =IF(Q$4="","",ABS(Q33/Q$4))
B39: =B34 -> R&D | C39: =ABS(C34/$C$4) -> 0 | G39: =IF(G$4="","",ABS(G34/G$4)) -> 0 | H39: =IF(H$4="","",ABS(H34/H$4)) -> 0 | I39: =IF(I$4="","",ABS(I34/I$4)) -> 0 | J39: =IF(J$4="","",ABS(J34/J$4)) -> 0 | K39: =IF(K$4="","",ABS(K34/K$4)) -> 0 | L39: =IF(L$4="","",ABS(L34/L$4)) | M39: =IF(M$4="","",ABS(M34/M$4)) | N39: =IF(N$4="","",ABS(N34/N$4)) | ... Q39: =IF(Q$4="","",ABS(Q34/Q$4))
B40: Fixed Costs | C40: =ABS(C35/$C$4) -> 0.12624073 | G40: =IF(G$4="","",ABS(G35/G$4)) -> 0.1236737 | H40: =IF(H$4="","",ABS(H35/H$4)) -> 0.095025671 | I40: =IF(I$4="","",ABS(I35/I$4)) -> 0.055428246 | J40: =IF(J$4="","",ABS(J35/J$4)) -> 0.033694952 | K40: =IF(K$4="","",ABS(K35/K$4)) -> 0 | L40: =IF(L$4="","",ABS(L35/L$4)) | M40: =IF(M$4="","",ABS(M35/M$4)) | N40: =IF(N$4="","",ABS(N35/N$4)) | ... Q40: =IF(Q$4="","",ABS(Q35/Q$4))
B42: Tax % of Pre-tax Profit
B43: Income Tax Rate | C43: 0.24 | E43: Use the highest past tax rate | G43: =IF(G$4="","",-G14/SUM(G8+G11,G12)) -> 0.16214737 | H43: =IF(H$4="","",-H14/SUM(H8+H11,H12)) -> 0.16225652 | I43: =IF(I$4="","",-I14/SUM(I8+I11,I12)) -> 0.18507299 | J43: =IF(J$4="","",-J14/SUM(J8+J11,J12)) -> 0.20414515 | K43: =IF(K$4="","",-K14/SUM(K8+K11,K12)) -> 0 | L43: =IF(L$4="","",-L14/SUM(L8+L11,L12)) | M43: =IF(M$4="","",-M14/SUM(M8+M11,M12)) | N43: =IF(N$4="","",-N14/SUM(N8+N11,N12)) | ... Q43: =IF(Q$4="","",-Q14/SUM(Q8+Q11,Q12))
B45: Non-operating Income | E45: Notes
B46: Interest
...

Sheet DCF
B2: No-Growth DCF Valuation | H2: Notes
B3: No-Growth DCF | C3: =scaling_factor -> 1000000 | E3: Special Assumption
B4: Adjusted FCFE | C4: =Normalized_FCF!C19 -> 2524.2804 | D4: =Reporting_currency -> HKD | E4: Terminal Growth Rate (g): | F4: =Terminal_Growth -> 0
B5: /Equity Cost of Capital | C5: =Equity_Cost -> 0.085
B6: Stable Income Value | C6: =(C4*(1+Terminal_Growth))/(Equity_Cost-Terminal_Growth) -> 29697.417 | D6: =Reporting_currency -> HKD | E6: Conservative Valuation: Setting g=0 can be a conservative assumption to avoid overestimating the stock’s value, especially if future growth is uncertain or unreliable.
B7: - Interest-bearing Debt | C7: =BS!G31 -> 3093 | D7: =Reporting_currency -> HKD
B8: + Non-operating Cash | C8: =BS!D66 -> 42222.565 | D8: =Reporting_currency -> HKD
B9: + Other Non-operating Assets | C9: =BS!H42 -> 7814.4 | D9: =Reporting_currency -> HKD
B10: Equity Value | C10: =C6-C7+C8+C9 -> 76641.382 | D10: =Reporting_currency -> HKD
B11: * Exchange rate | C11: =Exchange_Rate -> 1 | D11: =Thesis!C15 -> HKD
B12: Equity Value per share | C12: =(C10*scaling_factor)/Common_Shares*Exchange_Rate -> 9.378672 | D12: =Market_currency -> HKD
B14: Implied Growth Scenario Analysis
B15: FCFE Projection
B16: High Growth Period (HGP) | C16: =Scenarios!C65 -> -0.0015334906
B17: High Growth Rate (HGR) | C17: =Scenarios!C64 -> 10
B18: Value Per Share | C18: =(F52-C7+C8+C9)*Exchange_Rate/Common_Shares*scaling_factor -> 9.3612446 | D18: =Market_currency -> HKD
B20: Year | C20: FCFE | D20: Growth Rates | E20: Discount Factor | F20: PV of FCFE
B21: 1 | C21: =C4*(1+D21) -> 2520.4094 | D21: =IF($C$17<B21,0,DCF!$C$16) -> -0.0015334906 | E21: =IF($C$17<B21,0,1/(1+Equity_Cost)^B21) -> 0.92165899 | F21: =C21*E21 -> 2322.958
B22: 2 | C22: =IF(ROW()-ROW($C$21)<$C$17, $C$21*(1+D22)^(ROW()-ROW($C$21)), 0) -> 2516.5444 | D22: =IF($C$17<B22,0,DCF!$C$16) -> -0.0015334906 | E22: =IF($C$17<B22,0,1/(1+Equity_Cost)^B22) -> 0.84945529 | F22: =C22*E22 -> 2137.692
B23: 3 | C23: =IF(ROW()-ROW($C$21)<$C$17, $C$21*(1+D23)^(ROW()-ROW($C$21)), 0) -> 2512.6853 | D23: =IF($C$17<B23,0,DCF!$C$16) -> -0.0015334906 | E23: =IF($C$17<B23,0,1/(1+Equity_Cost)^B23) -> 0.7829081 | F23: =C23*E23 -> 1967.2017
B24: 4 | C24: =IF(ROW()-ROW($C$21)<$C$17, $C$21*(1+D24)^(ROW()-ROW($C$21)), 0) -> 2508.8321 | D24: =IF($C$17<B24,0,DCF!$C$16) -> -0.0015334906 | E24: =IF($C$17<B24,0,1/(1+Equity_Cost)^B24) -> 0.72157428 | F24: =C24*E24 -> 1810.3088
B25: 5 | C25: =IF(ROW()-ROW($C$21)<$C$17, $C$21*(1+D25)^(ROW()-ROW($C$21)), 0) -> 2504.9849 | D25: =IF($C$17<B25,0,DCF!$C$16) -> -0.0015334906 | E25: =IF($C$17<B25,0,1/(1+Equity_Cost)^B25) -> 0.66504542 | F25: =C25*E25 -> 1665.9287
B26: 6 | C26: =IF(ROW()-ROW($C$21)<$C$17, $C$21*(1+D26)^(ROW()-ROW($C$21)), 0) -> 2501.1435 | D26: =IF($C$17<B26,0,DCF!$C$16) -> -0.0015334906 | E26: =IF($C$17<B26,0,1/(1+Equity_Cost)^B26) -> 0.61294509 | F26: =C26*E26 -> 1533.0636
B27: 7 | C27: =IF(ROW()-ROW($C$21)<$C$17, $C$21*(1+D27)^(ROW()-ROW($C$21)), 0) -> 2497.308 | D27: =IF($C$17<B27,0,DCF!$C$16) -> -0.0015334906 | E27: =IF($C$17<B27,0,1/(1+Equity_Cost)^B27) -> 0.56492635 | F27: =C27*E27 -> 1410.7951
B28: 8 | C28: =IF(ROW()-ROW($C$21)<$C$17, $C$21*(1+D28)^(ROW()-ROW($C$21)), 0) -> 2493.4784 | D28: =IF($C$17<B28,0,DCF!$C$16) -> -0.0015334906 | E28: =IF($C$17<B28,0,1/(1+Equity_Cost)^B28) -> 0.52066945 | F28: =C28*E28 -> 1298.278
B29: 9 | C29: =IF(ROW()-ROW($C$21)<$C$17, $C$21*(1+D29)^(ROW()-ROW($C$21)), 0) -> 2489.6547 | D29: =IF($C$17<B29,0,DCF!$C$16) -> -0.0015334906 | E29: =IF($C$17<B29,0,1/(1+Equity_Cost)^B29) -> 0.47987968 | F29: =C29*E29 -> 1194.7347
B30: 10 | C30: =IF(ROW()-ROW($C$21)<$C$17, $C$21*(1+D30)^(ROW()-ROW($C$21)), 0) -> 2485.8368 | D30: =IF($C$17<B30,0,DCF!$C$16) -> -0.0015334906 | E30: =IF($C$17<B30,0,1/(1+Equity_Cost)^B30) -> 0.44228542 | F30: =C30*E30 -> 1099.4494
B31: 11 | C31: =IF(ROW()-ROW($C$21)<$C$17, $C$21*(1+D31)^(ROW()-ROW($C$21)), 0) -> 0 | D31: =IF($C$17<B31,0,DCF!$C$16) -> 0 | E31: =IF($C$17<B31,0,1/(1+Equity_Cost)^B31) -> 0 | F31: =C31*E31 -> 0
B32: 12 | C32: =IF(ROW()-ROW($C$21)<$C$17, $C$21*(1+D32)^(ROW()-ROW($C$21)), 0) -> 0 | D32: =IF($C$17<B32,0,DCF!$C$16) -> 0 | E32: =IF($C$17<B32,0,1/(1+Equity_Cost)^B32) -> 0 | F32: =C32*E32 -> 0
B33: 13 | C33: =IF(ROW()-ROW($C$21)<$C$17, $C$21*(1+D33)^(ROW()-ROW($C$21)), 0) -> 0 | D33: =IF($C$17<B33,0,DCF!$C$16) -> 0 | E33: =IF($C$17<B33,0,1/(1+Equity_Cost)^B33) -> 0 | F33: =C33*E33 -> 0
... B50: 30 | C50: =IF(ROW()-ROW($C$21)<$C$17, $C$21*(1+D50)^(ROW()-ROW($C$21)), 0) -> 0 | D50: =IF($C$17<B50,0,DCF!$C$16) -> 0 | E50: =IF($C$17<B50,0,1/(1+Equity_Cost)^B50) -> 0 | F50: =C50*E50 -> 0
B51: Terminal Year | C51: =C$21*(1+Terminal_Growth)^$C$17/Equity_Cost -> 29651.876 | D51: =Terminal_Growth -> 0 | E51: =1/(1+Equity_Cost)^C17 -> 0.44228542 | F51: =C51*E51 -> 13114.592
E52: Total PV | F52: =SUM(F21:F51) -> 29555.002
B54: Sensitivity Analysis (Enterprise Value)
A55: =F52 -> 29555.002 | B55: =C78 -> -0.1 | C55: =C77 -> -0.02 | D55: =C76 -> 0 | E55: =C75 -> 0.02 | F55: =C74 -> 0.05
A56: 5 | B56: 25232.901 | C56: 28752.053 | D56: 29697.417 | E56: 30671.415 | F56: 32188.893
A57: 10 | B57: 22207.735 | C57: 27917.91 | D57: 29697.417 | E57: 31652.779 | F57: 34962.383
A58: 15 | B58: 19398.255 | C58: 27002.216 | D58: 29697.417 | E58: 32840.425 | F58: 38592.768
A59: 20 | B59: 17216.6 | C59: 26176.253 | D59: 29697.417 | E59: 34023.09 | F59: 42522.973
A60: 25 | B60: 15642.697 | C60: 25496.51 | D60: 29697.417 | E60: 35098.055 | F60: 46423.357
...

Sheet DDM
B2: No-Growth DDM Valuation | H2: Notes
B3: No-Growth DDM | C3: =scaling_factor -> 1000000 | E3: Special Assumption
B4: Dividend | C4: =Normalized_FCF!C91 -> 4739.6904 | D4: =Market_currency -> HKD | E4: Terminal Growth Rate (g): | F4: =Thesis!E22 -> 0
B5: /Equity Cost of Capital | C5: =Equity_Cost -> 0.085
B6: Dividend Value | C6: =(C4*(1+Terminal_Growth))/(Equity_Cost-Terminal_Growth) -> 55761.063 | D6: =Reporting_currency -> HKD
B7: Dividend Value per share | C7: =(C6*scaling_factor)/Common_Shares*Exchange_Rate -> 6.8235294 | D7: =Market_currency -> HKD
B9: Implied Growth Scenario Analysis
B10: FCFE Projection
B11: High Growth Period (HGP) | C11: =Scenarios!C65 -> -0.0015334906
B12: High Growth Rate (HGR) | C12: =Scenarios!C64 -> 10
B13: Value Per Share | C13: =F47/Common_Shares*scaling_factor -> 6.7908071 | D13: =Market_currency -> HKD
B15: Year | C15: Dividends | D15: Growth Rates | E15: Discount Factor | F15: PV of Dividends
B16: 1 | C16: =C4*(1+D16) -> 4732.4221 | D16: =IF($C$12<B16,0,DDM!$C$11) -> -0.0015334906 | E16: =IF($C$12<B16,0,1/(1+Equity_Cost)^B16) -> 0.92165899 | F16: =C16*E16 -> 4361.6793
B17: 2 | C17: =IF(ROW()-ROW($C$16)<$C$12, $C$16*(1+D17)^(ROW()-ROW($C$16)), 0) -> 4725.165 | D17: =IF($C$12<B17,0,DDM!$C$11) -> -0.0015334906 | E17: =IF($C$12<B17,0,1/(1+Equity_Cost)^B17) -> 0.84945529 | F17: =C17*E17 -> 4013.8164
B18: 3 | C18: =IF(ROW()-ROW($C$16)<$C$12, $C$16*(1+D18)^(ROW()-ROW($C$16)), 0) -> 4717.919 | D18: =IF($C$12<B18,0,DDM!$C$11) -> -0.0015334906 | E18: =IF($C$12<B18,0,1/(1+Equity_Cost)^B18) -> 0.7829081 | F18: =C18*E18 -> 3693.697
B19: 4 | C19: =IF(ROW()-ROW($C$16)<$C$12, $C$16*(1+D19)^(ROW()-ROW($C$16)), 0) -> 4710.6841 | D19: =IF($C$12<B19,0,DDM!$C$11) -> -0.0015334906 | E19: =IF($C$12<B19,0,1/(1+Equity_Cost)^B19) -> 0.72157428 | F19: =C19*E19 -> 3399.1085
B20: 5 | C20: =IF(ROW()-ROW($C$16)<$C$12, $C$16*(1+D20)^(ROW()-ROW($C$16)), 0) -> 4703.4603 | D20: =IF($C$12<B20,0,DDM!$C$11) -> -0.0015334906 | E20: =IF($C$12<B20,0,1/(1+Equity_Cost)^B20) -> 0.66504542 | F20: =C20*E20 -> 3128.0147
B21: 6 | C21: =IF(ROW()-ROW($C$16)<$C$12, $C$16*(1+D21)^(ROW()-ROW($C$16)), 0) -> 4696.2476 | D21: =IF($C$12<B21,0,DDM!$C$11) -> -0.0015334906 | E21: =IF($C$12<B21,0,1/(1+Equity_Cost)^B21) -> 0.61294509 | F21: =C21*E21 -> 2878.5419
B22: 7 | C22: =IF(ROW()-ROW($C$16)<$C$12, $C$16*(1+D22)^(ROW()-ROW($C$16)), 0) -> 4689.0459 | D22: =IF($C$12<B22,0,DDM!$C$11) -> -0.0015334906 | E22: =IF($C$12<B22,0,1/(1+Equity_Cost)^B22) -> 0.56492635 | F22: =C22*E22 -> 2648.9656
B23: 8 | C23: =IF(ROW()-ROW($C$16)<$C$12, $C$16*(1+D23)^(ROW()-ROW($C$16)), 0) -> 4681.8553 | D23: =IF($C$12<B23,0,DDM!$C$11) -> -0.0015334906 | E23: =IF($C$12<B23,0,1/(1+Equity_Cost)^B23) -> 0.52066945 | F23: =C23*E23 -> 2437.699
B24: 9 | C24: =IF(ROW()-ROW($C$16)<$C$12, $C$16*(1+D24)^(ROW()-ROW($C$16)), 0) -> 4674.6757 | D24: =IF($C$12<B24,0,DDM!$C$11) -> -0.0015334906 | E24: =IF($C$12<B24,0,1/(1+Equity_Cost)^B24) -> 0.47987968 | F24: =C24*E24 -> 2243.2819
B25: 10 | C25: =IF(ROW()-ROW($C$16)<$C$12, $C$16*(1+D25)^(ROW()-ROW($C$16)), 0) -> 4667.5072 | D25: =IF($C$12<B25,0,DDM!$C$11) -> -0.0015334906 | E25: =IF($C$12<B25,0,1/(1+Equity_Cost)^B25) -> 0.44228542 | F25: =C25*E25 -> 2064.3703
B26: 11 | C26: =IF(ROW()-ROW($C$16)<$C$12, $C$16*(1+D26)^(ROW()-ROW($C$16)), 0) -> 0 | D26: =IF($C$12<B26,0,DDM!$C$11) -> 0 | E26: =IF($C$12<B26,0,1/(1+Equity_Cost)^B26) -> 0 | F26: =C26*E26 -> 0
B27: 12 | C27: =IF(ROW()-ROW($C$16)<$C$12, $C$16*(1+D27)^(ROW()-ROW($C$16)), 0) -> 0 | D27: =IF($C$12<B27,0,DDM!$C$11) -> 0 | E27: =IF($C$12<B27,0,1/(1+Equity_Cost)^B27) -> 0 | F27: =C27*E27 -> 0
B28: 13 | C28: =IF(ROW()-ROW($C$16)<$C$12, $C$16*(1+D28)^(ROW()-ROW($C$16)), 0) -> 0 | D28: =IF($C$12<B28,0,DDM!$C$11) -> 0 | E28: =IF($C$12<B28,0,1/(1+Equity_Cost)^B28) -> 0 | F28: =C28*E28 -> 0
... B45: 30 | C45: =IF(ROW()-ROW($C$16)<$C$12, $C$16*(1+D45)^(ROW()-ROW($C$16)), 0) -> 0 | D45: =IF($C$12<B45,0,DDM!$C$11) -> 0 | E45: =IF($C$12<B45,0,1/(1+Equity_Cost)^B45) -> 0 | F45: =C45*E45 -> 0
B46: Terminal Year | C46: =C$16*(1+F4)^$C$12/Equity_Cost -> 55675.554 | D46: =Terminal_Growth -> 0 | E46: =1/(1+Equity_Cost)^C12 -> 0.44228542 | F46: =C46*E46 -> 24624.486
E47: Total PV | F47: =SUM(F16:F46) -> 55493.66
B49: Sensitivity Analysis (Enterprise Value)
A50: =F47 -> 55493.66 | B50: =C73 -> -0.1 | C50: =C72 -> -0.02 | D50: =C71 -> 0 | E50: =C70 -> 0.02 | F50: =C69 -> 0.05
A51: 5 | B51: 47378.309 | C51: 53986.01 | D51: 55761.063 | E51: 57589.882 | F51: 60439.16
A52: 10 | B52: 41698.136 | C52: 52419.789 | D52: 55761.063 | E52: 59432.531 | F52: 65646.776
A53: 15 | B53: 36422.943 | C53: 50700.446 | D53: 55761.063 | E53: 61662.502 | F53: 72463.332
A54: 20 | B54: 32326.58 | C54: 49149.584 | D54: 55761.063 | E54: 63883.122 | F54: 79842.844
A55: 25 | B55: 29371.356 | C55: 47873.271 | D55: 55761.063 | E55: 65901.519 | F55: 87166.361
A56: 30 | B56: 27315.301 | C56: 46877.232 | D56: 55761.063 | E56: 67641.511 | F56: 94087.333
B58: Sensitivity Analysis (Equity Value per share)
B59: =B50 -> -0.1 | C59: =C50 -> -0.02 | D59: =D50 -> 0 | E59: =E50 -> 0.02 | F59: =F50 -> 0.05
A60: 0 | B60: =C7 -> 6.8235294 | C60: =C7 -> 6.8235294 | D60: =C7 -> 6.8235294 | E60: =C7 -> 6.8235294 | F60: =C7 -> 6.8235294
A61: =A51 -> 5 | B61: =B51/Common_Shares*$C$3*Exchange_Rate -> 5.7977246 | C61: =C51/Common_Shares*$C$3*Exchange_Rate -> 6.6063146 | D61: =D51/Common_Shares*$C$3*Exchange_Rate -> 6.8235294 | E61: =E51/Common_Shares*$C$3*Exchange_Rate -> 7.0473236 | F61: =F51/Common_Shares*$C$3*Exchange_Rate -> 7.3959922
...

Sheet Scenarios
B2: Current Situation | H2: Warning: Do Not Remove this logic
B3: Selection | H3: 0 | I3: =-Market_Price -> -8.15
B4: Past Years Selected | C4: 3 | E4: Tie the business story into the three levers of value: FCFE, growth and risk. | H4: 1 | I4: =IF(ROW()-3 < $C$76, $C$77, IF(ROW()-3 = $C$76, $C$77 + $C$60, "")) -> 0.58
H5: 2 | I5: =IF(ROW()-3 < $C$76, $C$77, IF(ROW()-3 = $C$76, $C$77 + $C$60, "")) -> 0.58
B6: Latest | C6: =DCF!C3 -> 1000000 | E6: Prompt for fundamental Analysis | H6: 3 | I6: =IF(ROW()-3 < $C$76, $C$77, IF(ROW()-3 = $C$76, $C$77 + $C$60, "")) -> 9.9441571
B7: EBIT | C7: =Normalized_FCF!G8 -> 2337 | D7: =Reporting_currency -> HKD | E7: ="Please develop three logical "&C18&"-year scenarios (Base Case, Pessimistic Case, Optimistic Case) and two extreme "&C46&"-year scenarios (Success Scenario, Devil’s Advocate Scenario) for "&Thesis!C5&"("&Thesis!C11&"). Each scenario should include the Compound Growth Rate, the Probability Assessment, and the Business Narrative." -> Please develop three logical 10-year scenarios (Base Case, Pessimistic Case, Optimistic Case) and two extreme 15-year scenarios (Success Scenario, Devil’s Advocate Scenario) for SINO LAND(0083.HK). Each scenario should include the Compound Growth Rate, the Probability Assessment, and the Business Narrative. | H7: 4 | I7: =IF(ROW()-3 < $C$76, $C$77, IF(ROW()-3 = $C$76, $C$77 + $C$60, ""))
B8: FCFE | C8: =Normalized_FCF!G19 -> 2772.7921 | D8: =Reporting_currency -> HKD | H8: 5 | I8: =IF(ROW()-3 < $C$76, $C$77, IF(ROW()-3 = $C$76, $C$77 + $C$60, ""))
B9: Normalized | C9: =Normalized_FCF!C19 -> 2524.2804 | D9: =Reporting_currency -> HKD | H9: 6 | I9: =IF(ROW()-3 < $C$76, $C$77, IF(ROW()-3 = $C$76, $C$77 + $C$60, ""))
H10: 7 | I10: =IF(ROW()-3 < $C$76, $C$77, IF(ROW()-3 = $C$76, $C$77 + $C$60, ""))
B11: YoY CAGR | H11: 8 | I11: =IF(ROW()-3 < $C$76, $C$77, IF(ROW()-3 = $C$76, $C$77 + $C$60, ""))
B12: Sales | C12: =(Normalized_FCF!G4/OFFSET(Normalized_FCF!G4, 0, $C$4))^(1/$C$4) - 1 -> -0.28945841 | H12: 9 | I12: =IF(ROW()-3 < $C$76, $C$77, IF(ROW()-3 = $C$76, $C$77 + $C$60, ""))
B13: Operating EBIT | C13: =(Normalized_FCF!G8/OFFSET(Normalized_FCF!G8, 0, $C$4))^(1/$C$4) - 1 -> -0.42686307 | H13: 10 | I13: =IF(ROW()-3 < $C$76, $C$77, IF(ROW()-3 = $C$76, $C$77 + $C$60, ""))
B14: FCFE | C14: =(Normalized_FCF!G19/OFFSET(Normalized_FCF!G19, 0, $C$4))^(1/$C$4) - 1 -> -0.34497687
B16: General Scenarios
B17: Assumption | E17: Guidance Note
B18: High Growth Period (HGP) | C18: 10 | E18: Fundamental analysis and market signal analysis should be combined, with fundamental analysis given priority and market signal analysis serving as a supplement. Market signal analysis predicts a company's future trend, while fundamental analysis interprets the trend and identifies relevant fundamental factors and possibilities.
B20: Reference
B21: Market Price | C21: =Market_Price -> 8.15 | D21: =Market_currency -> HKD
B22: No Growth Value per share | C22: =IF(valuation_method="DCF",DCF!C12,DDM!C7) -> 9.378672 | D22: =Market_currency -> HKD
B24: Base | E24: Business Story
B25: High Growth Period (HGP) | C25: =C18 -> 10
B26: High Growth Rate (HGR) | C26: 0
B27: Value per share | C27: =IF(valuation_method="DCF",DCF!E76,DDM!E71) -> 9.378672 | D27: =Market_currency -> HKD
B28: Probabilities | C28: 0.55
B30: Pessimistic | E30: Business Story
B31: High Growth Period (HGP) | C31: =C18 -> 10
B32: High Growth Rate (HGR) | C32: -0.02
B33: Value per share | C33: =IF(valuation_method="DCF",DCF!E77,DDM!E72) -> 9.1609122 | D33: =Market_currency -> HKD
B34: Probabilities | C34: 0.25
B36: Optimistic | E36: Business Story
B37: High Growth Period (HGP) | C37: =C18 -> 10
B38: High Growth Rate (HGR) | C38: 0.02
B39: Value per share | C39: =IF(valuation_method="DCF",DCF!E75,DDM!E70) -> 9.6179514 | D39: =Market_currency -> HKD
B40: Probabilities | C40: =1-C28-C34 -> 0.2
B42: Expected Value = | C42: =C27*C28+C33*C34+C39*C40 -> 9.3720879 | D42: =Market_currency -> HKD
B44: Extreme Scenarios
B45: Assumption
B46: High Growth Period (HGP) | C46: 15
B48: Devil's advocate | E48: Business Story
B49: High Growth Period (HGP) | C49: =C46 -> 15
...
