Workbook
Name Common_Shares: Thesis!$C$11
Name Equity_Cost: Valuation_Model!$C$5
Name Exchange_Rate: Thesis!$C$13
Name Market_currency: Thesis!$D$10
Name Market_Price: Thesis!$C$10
Name Reporting_currency: Thesis!$C$12
Name Terminal_Growth: Valuation_Model!$F$4

Sheet Thesis
B1: Investment Thesis for | C1: 周生生 | D1: 0116.HK
B2: Model last updated: | C2: 45643 | E2: Status: Not Held
A3: Introduction
B4: Comapny Information
B5: Comp_Sector: | C5: C0003
B6: Review Interval: | C6: 8
B7: Review Date: | C7: =EOMONTH(EDATE(BS!C1,Thesis!C6),0) -> 45716
B9: =D1&" Stock Information" -> 0116.HK Stock Information
B10: Market Price: | C10: 7 | D10: HKD
B11: Number of Shares: | C11: 677426000
B12: Reporting Currency: | C12: HKD
B13: Exchange Rate: | C13: 1 | D13: =IF(C12=D10,D10,C12&"/"&D10) -> HKD
B14: Capitalization: | C14: =Thesis!C10*Thesis!C11/1000000 -> 4741.982
A16: Step 1: Calculate FCFE
A18: ="1." -> 1. | B18: Adjusted FCFE Calculation
B19: Formula:
B20: Adjusted FCFE = Net Income + D&A – Maintenance Capex ± WCInv (if material).
B22: Variables | C22: =Data!C3 -> 1000
B23: Operating after-tax Profit = | C23: =Normalized_FCF!C16 -> 336835.71 | D23: =C12 -> HKD
B24: Non-Operating after-tax Profit = | C24: =Normalized_FCF!C11 -> 0
B25: Net Income = | C25: =C23+C24 -> 336835.71
B27: Adjusted FCFE = | C27: =Normalized_FCF!C19 -> 336835.71
B28: Adjusted FCFE per share = | C28: =C27/(Common_Shares/Data!C3) -> 0.49722878
B29: FCFE/Market Price = | C29: =C28/Market_Price -> 0.071032683
B31: Notes:
B32: 1. the model explicitly avoids aggressive growth assumptions and prioritizes downside protection.
B33: 2. Net borrowing is excluded (fixed at 0), and WCInv is only included if it materially distorts FCFE (>5% volatility).
B34: 3. Normalization: 5-year averages will smooth cyclicality for 590.HK.
A36: ="2." -> 2. | B36: Equity Cost of Capital (Buffett Method)
B37: Equity Cost of Capital (r) = | C37: 0.1
B39: Qualitative Adjustments
B40: Nonexistent moats | C40: 0 | D40: HK
B41: Weak balance sheets | C41: 0 | D41: Stable Business
B42: Poor management | C42: 0
B43: Qualitative Adjustments | C43: =SUM(C40:C42) -> 0
A45: ="3." -> 3. | B45: No-Growth DCF Valuation
B46: Key Metrics:
B47: Adjusted Earnings Yield = Adjusted FCFE / Market Cap.
B48: Intrinsic Value (No Growth) = Adjusted FCFE / Equity Cost of Capital.
B50: Decision Rule:
...

Sheet Data
B1: =Thesis!C12 -> HKD | C1: 45291 | D1: =EOMONTH(EDATE(C1,-12),0) -> 44926 | E1: =EOMONTH(EDATE(D1,-12),0) -> 44561 | F1: =EOMONTH(EDATE(E1,-12),0) -> 44196 | G1: =EOMONTH(EDATE(F1,-12),0) -> 43830 | H1: =EOMONTH(EDATE(G1,-12),0) -> 43465 | I1: =EOMONTH(EDATE(H1,-12),0) -> 43100 | J1: =EOMONTH(EDATE(I1,-12),0) -> 42735 | K1: =EOMONTH(EDATE(J1,-12),0) -> 42369 | ... M1: =EOMONTH(EDATE(L1,-12),0) -> 41639
B2: Data (Dirty)
B3: Income Statement | C3: 1000
B4: Sales | C4: 25013339 | D4: 19751940 | E4: 21987559 | F4: 14997541 | G4: 17736226 | H4: 18806342 | I4: 59156.4 | J4: 51245.5
B5: COGS | C5: 18409837 | D5: 15140010 | E5: 16431474 | F5: 10877614 | G5: 12958750 | H5: 14175208 | I5: 42943 | J5: 36282.8
B6: OPEX | C6: 5225366 | D6: 4709830 | E6: 4571128 | F6: 3136777 | G6: 3470831 | H6: 3388718 | I6: 10960.1 | J6: 10347.1
B7: Incl. Selling Expenses
B8: R&D
B9: Share of JV or associate Results
B10: Dividend or Interests from FA
B11: Investment property
B12: Interest Expense | C12: 129899 | D12: 81860 | E12: 60486 | F12: 76137 | G12: 89162 | H12: 36991 | I12: 243.7 | J12: 236.6
B13: Interest Income | C13: 183.1 | D13: 227.8
B14: Income Tax Paid
B15: Reported Net Income | D15: -10604 | E15: -3488 | F15: 0 | G15: 0 | H15: 0 | I15: 108.4 | J15: 95.8
B16: Non-controling Interests | C16: -13497 | D16: -10604 | E16: -3488 | F16: 0 | G16: 0 | H16: 0
B18: Cash Flow Statement
B19: D&A
B20: CAPX
B21: WCInv
B22: ="Dividend per share ("&Market_currency&")" -> Dividend per share (HKD) | C22: 0.55
B24: Balance Sheet
B25: ST AR
B26: ST Inventory
B27: Total Liabilities | C27: 6730302 | D27: 6780629 | E27: 5345297 | F27: 4807353
B28: Total Equity | C28: 12167429 | D28: 11870228 | E28: 12743461 | F28: 12019114
B29: Non-common Interest | C29: -40166 | D29: -20315 | E29: -9659 | F29: 0
B31: Other Data
B32: Contingent Liabilities | C32: 229911 | D32: 119344 | E32: 219055 | F32: 94344
B34: IS & CF Statements (Clean)
B35: Income Statement
B36: Sales | C36: =IF(C$4="","",C4) -> 25013339 | D36: =IF(D$4="","",D4) -> 19751940 | E36: =IF(E$4="","",E4) -> 21987559 | F36: =IF(F$4="","",F4) -> 14997541 | G36: =IF(G$4="","",G4) -> 17736226 | H36: =IF(H$4="","",H4) -> 18806342 | I36: =IF(I$4="","",I4) -> 59156.4 | J36: =IF(J$4="","",J4) -> 51245.5 | ... M36: =IF(M$4="","",M4)
B37: COGS | C37: =IF(C$4="","",-C5) -> -18409837 | D37: =IF(D$4="","",-D5) -> -15140010 | E37: =IF(E$4="","",-E5) -> -16431474 | F37: =IF(F$4="","",-F5) -> -10877614 | G37: =IF(G$4="","",-G5) -> -12958750 | H37: =IF(H$4="","",-H5) -> -14175208 | I37: =IF(I$4="","",-I5) -> -42943 | J37: =IF(J$4="","",-J5) -> -36282.8 | ... M37: =IF(M$4="","",-M5)
B38: Gross Margin | C38: =IF(C36="","",C36+C37) -> 6603502 | D38: =IF(D36="","",D36+D37) -> 4611930 | E38: =IF(E36="","",E36+E37) -> 5556085 | F38: =IF(F36="","",F36+F37) -> 4119927 | G38: =IF(G36="","",G36+G37) -> 4777476 | H38: =IF(H36="","",H36+H37) -> 4631134 | I38: =IF(I36="","",I36+I37) -> 16213.4 | J38: =IF(J36="","",J36+J37) -> 14962.7 | ... M38: =IF(M36="","",M36+M37)
B39: OPEX | C39: =IF(C$4="","",-C6) -> -5225366 | D39: =IF(D$4="","",-D6) -> -4709830 | E39: =IF(E$4="","",-E6) -> -4571128 | F39: =IF(F$4="","",-F6) -> -3136777 | G39: =IF(G$4="","",-G6) -> -3470831 | H39: =IF(H$4="","",-H6) -> -3388718 | I39: =IF(I$4="","",-I6) -> -10960.1 | J39: =IF(J$4="","",-J6) -> -10347.1 | ... M39: =IF(M$4="","",-M6)
B40: Incl. Selling Expenses | C40: =IF(C$4="","",-C7) -> 0 | D40: =IF(D$4="","",-D7) -> 0 | E40: =IF(E$4="","",-E7) -> 0 | F40: =IF(F$4="","",-F7) -> 0 | G40: =IF(G$4="","",-G7) -> 0 | H40: =IF(H$4="","",-H7) -> 0 | I40: =IF(I$4="","",-I7) -> 0 | J40: =IF(J$4="","",-J7) -> 0 | ... M40: =IF(M$4="","",-M7)
B41: Incl. Other Opex | C41: =IF(C$4="","",C39-C40) -> -5225366 | D41: =IF(D$4="","",D39-D40) -> -4709830 | E41: =IF(E$4="","",E39-E40) -> -4571128 | F41: =IF(F$4="","",F39-F40) -> -3136777 | G41: =IF(G$4="","",G39-G40) -> -3470831 | H41: =IF(H$4="","",H39-H40) -> -3388718 | I41: =IF(I$4="","",I39-I40) -> -10960.1 | J41: =IF(J$4="","",J39-J40) -> -10347.1 | ... M41: =IF(M$4="","",M39-M40)
B42: R&D | C42: =IF(C$4="","",-C8) -> 0 | D42: =IF(D$4="","",-D8) -> 0 | E42: =IF(E$4="","",-E8) -> 0 | F42: =IF(F$4="","",-F8) -> 0 | G42: =IF(G$4="","",-G8) -> 0 | H42: =IF(H$4="","",-H8) -> 0 | I42: =IF(I$4="","",-I8) -> 0 | J42: =IF(J$4="","",-J8) -> 0 | ... M42: =IF(M$4="","",-M8)
B43: Operating EBIT | C43: =IF(C$4="","",C38+C39+C42) -> 1378136 | D43: =IF(D$4="","",D38+D39+D42) -> -97900 | E43: =IF(E$4="","",E38+E39+E42) -> 984957 | F43: =IF(F$4="","",F38+F39+F42) -> 983150 | G43: =IF(G$4="","",G38+G39+G42) -> 1306645 | H43: =IF(H$4="","",H38+H39+H42) -> 1242416 | I43: =IF(I$4="","",I38+I39+I42) -> 5253.3 | J43: =IF(J$4="","",J38+J39+J42) -> 4615.6 | ... M43: =IF(M$4="","",M38+M39+M42)
B44: Non-operating EBIT | C44: =IF(C$4="","",C47-C46-C45-C43) -> -1248420.1 | D44: =IF(D$4="","",D47-D46-D45-D43) -> 168928.2 | E44: =IF(E$4="","",E47-E46-E45-E43) -> -927959 | F44: =IF(F$4="","",F47-F46-F45-F43) -> -907013 | G44: =IF(G$4="","",G47-G46-G45-G43) -> -1217483 | H44: =IF(H$4="","",H47-H46-H45-H43) -> -1205425 | I44: =IF(I$4="","",I47-I46-I45-I43) -> -4901.2 | J44: =IF(J$4="","",J47-J46-J45-J43) -> -4283.2 | ... M44: =IF(M$4="","",M47-M46-M45-M43)
...

Sheet Normalized_FCF
B1: =Thesis!C12 -> HKD | C1: Normalized | G1: =Data!C1 -> 45291 | H1: =EOMONTH(EDATE(G1,-12),0) -> 44926 | I1: =EOMONTH(EDATE(H1,-12),0) -> 44561 | J1: =EOMONTH(EDATE(I1,-12),0) -> 44196 | K1: =EOMONTH(EDATE(J1,-12),0) -> 43830 | L1: =EOMONTH(EDATE(K1,-12),0) -> 43465 | M1: =EOMONTH(EDATE(L1,-12),0) -> 43100 | N1: =EOMONTH(EDATE(M1,-12),0) -> 42735 | O1: =EOMONTH(EDATE(N1,-12),0) -> 42369 | ... Q1: =EOMONTH(EDATE(P1,-12),0) -> 41639
B2: FCFE Analysis | E2: Notes
B3: Adjusted FCFE | C3: =Data!C3 -> 1000
B4: Sales | C4: =AVERAGE(G4:I4) -> 22250946 | G4: =Data!C36 -> 25013339 | H4: =Data!D36 -> 19751940 | I4: =Data!E36 -> 21987559 | J4: =Data!F36 -> 14997541 | K4: =Data!G36 -> 17736226 | L4: =Data!H36 -> 18806342 | M4: =Data!I36 -> 59156.4 | N4: =Data!J36 -> 51245.5 | ... Q4: =Data!M36
B5: Variable Costs | C5: =C25 -> -16716115 | G5: =G25 -> -18409837 | H5: =H25 -> -15140010 | I5: =I25 -> -16431474 | J5: =J25 -> -10877614 | K5: =K25 -> -12958750 | L5: =L25 -> -14175208 | M5: =M25 -> -42943 | N5: =N25 -> -36282.8 | ... Q5: =Q25
B6: Contribution Margin | C6: =C4+C5 -> 5534830.8 | G6: =IF(G4="","",G4+G5) -> 6603502 | H6: =IF(H4="","",H4+H5) -> 4611930 | I6: =IF(I4="","",I4+I5) -> 5556085 | J6: =IF(J4="","",J4+J5) -> 4119927 | K6: =IF(K4="","",K4+K5) -> 4777476 | L6: =IF(L4="","",L4+L5) -> 4631134 | M6: =IF(M4="","",M4+M5) -> 16213.4 | N6: =IF(N4="","",N4+N5) -> 14962.7 | ... Q6: =IF(Q4="","",Q4+Q5)
B7: Fixed Costs | C7: =C35 -> -4967598 | G7: =G35 -> -5225366 | H7: =H35 -> -4709830 | I7: =I35 -> -4571128 | J7: =J35 -> -3136777 | K7: =K35 -> -3470831 | L7: =L35 -> -3388718 | M7: =M35 -> -10960.1 | N7: =N35 -> -10347.1 | ... Q7: =Q35
B8: Operating EBIT | C8: =C6+C7 -> 567232.79 | G8: =IF(G$4="","",G6+G7) -> 1378136 | H8: =IF(H$4="","",H6+H7) -> -97900 | I8: =IF(I$4="","",I6+I7) -> 984957 | J8: =IF(J$4="","",J6+J7) -> 983150 | K8: =IF(K$4="","",K6+K7) -> 1306645 | L8: =IF(L$4="","",L6+L7) -> 1242416 | M8: =IF(M$4="","",M6+M7) -> 5253.3 | N8: =IF(N$4="","",N6+N7) -> 4615.6 | ... Q8: =IF(Q$4="","",Q6+Q7)
B9: Add Back D&A | C9: =BS!$G$39*BS!D59 -> 0 | G9: =IF(Data!C61="","",-Data!C61) -> 0 | H9: =IF(Data!D61="","",-Data!D61) -> 0 | I9: =IF(Data!E61="","",-Data!E61) -> 0 | J9: =IF(Data!F61="","",-Data!F61) -> 0 | K9: =IF(Data!G61="","",-Data!G61) -> 0 | L9: =IF(Data!H61="","",-Data!H61) -> 0 | M9: =IF(Data!I61="","",-Data!I61) -> 0 | N9: =IF(Data!J61="","",-Data!J61) -> 0 | ... Q9: =IF(Data!M61="","",-Data!M61)
B10: Maintenance Capex | C10: =-C4*C77 -> 0 | G10: =Data!C62 -> 0 | H10: =Data!D62 -> 0 | I10: =Data!E62 -> 0 | J10: =Data!F62 -> 0 | K10: =Data!G62 -> 0 | L10: =Data!H62 -> 0 | M10: =Data!I62 -> 0 | N10: =Data!J62 -> 0 | ... Q10: =Data!M62
B11: Non-Operating EBIT | C11: =C62 -> 0 | E11: Stable Non-Operating CF | G11: =G62 -> -1248420.1 | H11: =H62 -> 168928.2 | I11: =I62 -> -927959 | J11: =J62 -> -907013 | K11: =K62 -> -1217483 | L11: =L62 -> -1205425 | M11: =M62 -> -4901.2 | N11: =N62 -> -4283.2 | ... Q11: =Q62
B12: Net Interest Income | C12: =C49 -> -129783.82 | G12: =G49 -> -129715.9 | H12: =H49 -> -81632.2 | I12: =I49 -> -60486 | J12: =J49 -> -76137 | K12: =K49 -> -89162 | L12: =L49 -> -36991 | M12: =M49 -> -243.7 | N12: =N49 -> -236.6 | ... Q12: =Q49
B13: Pre-tax Profit | C13: =SUM(C8:C12) -> 437448.97 | G13: =IF(G$4="","",SUM(G8:G12)) -> 0 | H13: =IF(H$4="","",SUM(H8:H12)) -> -10604 | I13: =IF(I$4="","",SUM(I8:I12)) -> -3488 | J13: =IF(J$4="","",SUM(J8:J12)) -> 0 | K13: =IF(K$4="","",SUM(K8:K12)) -> 0 | L13: =IF(L$4="","",SUM(L8:L12)) -> 0 | M13: =IF(M$4="","",SUM(M8:M12)) -> 108.4 | N13: =IF(N$4="","",SUM(N8:N12)) -> 95.8 | ... Q13: =IF(Q$4="","",SUM(Q8:Q12))
B14: Income Tax | C14: =-C13*C43 -> -100613.26 | G14: =Data!C46 -> 0 | H14: =Data!D46 -> 0 | I14: =Data!E46 -> 0 | J14: =Data!F46 -> 0 | K14: =Data!G46 -> 0 | L14: =Data!H46 -> 0 | M14: =Data!I46 -> 0 | N14: =Data!J46 -> 0 | ... Q14: =Data!M46
B15: Non-controling Interests | C15: =-C4*C82 -> 0 | G15: =Data!C48 -> 0 | H15: =Data!D48 -> 0 | I15: =Data!E48 -> 0 | J15: =Data!F48 -> 0 | K15: =Data!G48 -> 0 | L15: =Data!H48 -> 0 | M15: =Data!I48 -> 0 | N15: =Data!J48 -> 0 | ... Q15: =Data!M48
B16: After-tax Profit | C16: =SUM(C13:C15) -> 336835.71 | G16: =IF(G$4="","",SUM(G13:G15)) -> 0 | H16: =IF(H$4="","",SUM(H13:H15)) -> -10604 | I16: =IF(I$4="","",SUM(I13:I15)) -> -3488 | J16: =IF(J$4="","",SUM(J13:J15)) -> 0 | K16: =IF(K$4="","",SUM(K13:K15)) -> 0 | L16: =IF(L$4="","",SUM(L13:L15)) -> 0 | M16: =IF(M$4="","",SUM(M13:M15)) -> 108.4 | N16: =IF(N$4="","",SUM(N13:N15)) -> 95.8 | ... Q16: =IF(Q$4="","",SUM(Q13:Q15))
B17: WCInv | C17: =-C4*C84 -> 0 | E17: WCInv is excluded
B18: Net Borrowing | C18: =-C4*C85 -> 0 | E18: Net borrowing is excluded
B19: Total FCFE | C19: =SUM(C16:C18) -> 336835.71 | G19: =IF(G$4="","",SUM(G16:G18)) -> 0 | H19: =IF(H$4="","",SUM(H16:H18)) -> -10604 | I19: =IF(I$4="","",SUM(I16:I18)) -> -3488 | J19: =IF(J$4="","",SUM(J16:J18)) -> 0 | K19: =IF(K$4="","",SUM(K16:K18)) -> 0 | L19: =IF(L$4="","",SUM(L16:L18)) -> 0 | M19: =IF(M$4="","",SUM(M16:M18)) -> 108.4 | N19: =IF(N$4="","",SUM(N16:N18)) -> 95.8 | ... Q19: =IF(Q$4="","",SUM(Q16:Q18))
B21: Operating Cost Structure | E21: Notes
B22: Variable Costs
B23: COGS | C23: =-C4*C28 -> -16716115 | G23: =Data!C37 -> -18409837 | H23: =Data!D37 -> -15140010 | I23: =Data!E37 -> -16431474 | J23: =Data!F37 -> -10877614 | K23: =Data!G37 -> -12958750 | L23: =Data!H37 -> -14175208 | M23: =Data!I37 -> -42943 | N23: =Data!J37 -> -36282.8 | ... Q23: =Data!M37
B24: Selling Expenses | C24: =-C4*C29 -> 0 | G24: =Data!C40 -> 0 | H24: =Data!D40 -> 0 | I24: =Data!E40 -> 0 | J24: =Data!F40 -> 0 | K24: =Data!G40 -> 0 | L24: =Data!H40 -> 0 | M24: =Data!I40 -> 0 | N24: =Data!J40 -> 0 | ... Q24: =Data!M40
B25: Variable Costs | C25: =C23+C24 -> -16716115 | G25: =IF(G$4="","",G23+G24) -> -18409837 | H25: =IF(H$4="","",H23+H24) -> -15140010 | I25: =IF(I$4="","",I23+I24) -> -16431474 | J25: =IF(J$4="","",J23+J24) -> -10877614 | K25: =IF(K$4="","",K23+K24) -> -12958750 | L25: =IF(L$4="","",L23+L24) -> -14175208 | M25: =IF(M$4="","",M23+M24) -> -42943 | N25: =IF(N$4="","",N23+N24) -> -36282.8 | ... Q25: =IF(Q$4="","",Q23+Q24)
B27: Variable Costs % of Sales
B28: COGS | C28: =AVERAGE(G28:H28) -> 0.75125414 | E28: Historical Average | G28: =IF(G$4="","",ABS(G23/G$4)) -> 0.73600078 | H28: =IF(H$4="","",ABS(H23/H$4)) -> 0.76650749 | I28: =IF(I$4="","",ABS(I23/I$4)) -> 0.74730778 | J28: =IF(J$4="","",ABS(J23/J$4)) -> 0.72529317 | K28: =IF(K$4="","",ABS(K23/K$4)) -> 0.7306374 | L28: =IF(L$4="","",ABS(L23/L$4)) -> 0.75374616 | M28: =IF(M$4="","",ABS(M23/M$4)) -> 0.72592315 | N28: =IF(N$4="","",ABS(N23/N$4)) -> 0.70801924 | ... Q28: =IF(Q$4="","",ABS(Q23/Q$4))
B29: =B24 -> Selling Expenses | C29: =AVERAGE(G29:H29) -> 0 | E29: Historical Average | G29: =IF(G$4="","",ABS(G24/G$4)) -> 0 | H29: =IF(H$4="","",ABS(H24/H$4)) -> 0 | I29: =IF(I$4="","",ABS(I24/I$4)) -> 0 | J29: =IF(J$4="","",ABS(J24/J$4)) -> 0 | K29: =IF(K$4="","",ABS(K24/K$4)) -> 0 | L29: =IF(L$4="","",ABS(L24/L$4)) -> 0 | M29: =IF(M$4="","",ABS(M24/M$4)) -> 0 | N29: =IF(N$4="","",ABS(N24/N$4)) -> 0 | ... Q29: =IF(Q$4="","",ABS(Q24/Q$4))
B30: Variable Costs | C30: =ABS(C25/$C$4) -> 0.75125414 | G30: =IF(G$4="","",ABS(G25/G$4)) -> 0.73600078 | H30: =IF(H$4="","",ABS(H25/H$4)) -> 0.76650749 | I30: =IF(I$4="","",ABS(I25/I$4)) -> 0.74730778 | J30: =IF(J$4="","",ABS(J25/J$4)) -> 0.72529317 | K30: =IF(K$4="","",ABS(K25/K$4)) -> 0.7306374 | L30: =IF(L$4="","",ABS(L25/L$4)) -> 0.75374616 | M30: =IF(M$4="","",ABS(M25/M$4)) -> 0.72592315 | N30: =IF(N$4="","",ABS(N25/N$4)) -> 0.70801924 | ... Q30: =IF(Q$4="","",ABS(Q25/Q$4))
B32: Fixed Costs
B33: G&A and other Opex | C33: =AVERAGE(G33:H33) -> -4967598 | E33: Historical Average | G33: =Data!C41 -> -5225366 | H33: =Data!D41 -> -4709830 | I33: =Data!E41 -> -4571128 | J33: =Data!F41 -> -3136777 | K33: =Data!G41 -> -3470831 | L33: =Data!H41 -> -3388718 | M33: =Data!I41 -> -10960.1 | N33: =Data!J41 -> -10347.1 | ... Q33: =Data!M41
B34: R&D | C34: =AVERAGE(G34:J34) -> 0 | E34: Historical Average | G34: =Data!C42 -> 0 | H34: =Data!D42 -> 0 | I34: =Data!E42 -> 0 | J34: =Data!F42 -> 0 | K34: =Data!G42 -> 0 | L34: =Data!H42 -> 0 | M34: =Data!I42 -> 0 | N34: =Data!J42 -> 0 | ... Q34: =Data!M42
B35: Fixed Costs | C35: =C33+C34 -> -4967598 | G35: =IF(G4="","",G33+G34) -> -5225366 | H35: =IF(H4="","",H33+H34) -> -4709830 | I35: =IF(I4="","",I33+I34) -> -4571128 | J35: =IF(J4="","",J33+J34) -> -3136777 | K35: =IF(K4="","",K33+K34) -> -3470831 | L35: =IF(L4="","",L33+L34) -> -3388718 | M35: =IF(M4="","",M33+M34) -> -10960.1 | N35: =IF(N4="","",N33+N34) -> -10347.1 | ... Q35: =IF(Q4="","",Q33+Q34)
B37: Fixed Costs % of Sales
B38: =B33 -> G&A and other Opex | C38: =ABS(C33/$C$4) -> 0.22325334 | G38: =IF(G$4="","",ABS(G33/G$4)) -> 0.20890318 | H38: =IF(H$4="","",ABS(H33/H$4)) -> 0.23844898 | I38: =IF(I$4="","",ABS(I33/I$4)) -> 0.20789611 | J38: =IF(J$4="","",ABS(J33/J$4)) -> 0.20915275 | K38: =IF(K$4="","",ABS(K33/K$4)) -> 0.19569163 | L38: =IF(L$4="","",ABS(L33/L$4)) -> 0.18019017 | M38: =IF(M$4="","",ABS(M33/M$4)) -> 0.18527328 | N38: =IF(N$4="","",ABS(N33/N$4)) -> 0.20191236 | ... Q38: =IF(Q$4="","",ABS(Q33/Q$4))
B39: =B34 -> R&D | C39: =ABS(C34/$C$4) -> 0 | G39: =IF(G$4="","",ABS(G34/G$4)) -> 0 | H39: =IF(H$4="","",ABS(H34/H$4)) -> 0 | I39: =IF(I$4="","",ABS(I34/I$4)) -> 0 | J39: =IF(J$4="","",ABS(J34/J$4)) -> 0 | K39: =IF(K$4="","",ABS(K34/K$4)) -> 0 | L39: =IF(L$4="","",ABS(L34/L$4)) -> 0 | M39: =IF(M$4="","",ABS(M34/M$4)) -> 0 | N39: =IF(N$4="","",ABS(N34/N$4)) -> 0 | ... Q39: =IF(Q$4="","",ABS(Q34/Q$4))
B40: Fixed Costs | C40: =ABS(C35/$C$4) -> 0.22325334 | G40: =IF(G$4="","",ABS(G35/G$4)) -> 0.20890318 | H40: =IF(H$4="","",ABS(H35/H$4)) -> 0.23844898 | I40: =IF(I$4="","",ABS(I35/I$4)) -> 0.20789611 | J40: =IF(J$4="","",ABS(J35/J$4)) -> 0.20915275 | K40: =IF(K$4="","",ABS(K35/K$4)) -> 0.19569163 | L40: =IF(L$4="","",ABS(L35/L$4)) -> 0.18019017 | M40: =IF(M$4="","",ABS(M35/M$4)) -> 0.18527328 | N40: =IF(N$4="","",ABS(N35/N$4)) -> 0.20191236 | ... Q40: =IF(Q$4="","",ABS(Q35/Q$4))
B42: Tax % of Pre-tax Profit
B43: Income Tax Rate | C43: 0.23 | E43: Use the highest past tax rate | G43: =IF(G$4="","",-G14/G16) -> #DIV/0! | H43: =IF(H$4="","",-H14/H16) -> 0 | I43: =IF(I$4="","",-I14/I16) -> 0 | J43: =IF(J$4="","",-J14/J16) -> #DIV/0! | K43: =IF(K$4="","",-K14/K16) -> #DIV/0! | L43: =IF(L$4="","",-L14/L16) -> #DIV/0! | M43: =IF(M$4="","",-M14/M16) -> 0 | N43: =IF(N$4="","",-N14/N16) -> 0 | ... Q43: =IF(Q$4="","",-Q14/Q16)
B45: Non-operating Income | E45: Notes
B46: Interest
...

Sheet BS
B1: Most Recent Quarter | C1: 45473 | F1: =IF(MONTH(C1)=MONTH(Normalized_FCF!G1),"FY","Quarter")&" Report" -> Quarter Report | H1: =Data!C3 -> 1000
B2: Lastest Balance Sheet
B3: ST Operating Assets | C3: Book | D3: Valued @ | F3: ST Non-Operating Assets | G3: Book | H3: Valued @
B4: ST AR | C4: =5822.2+0.5+26.1 -> 5848.8 | D4: 0.6 | F4: Cash and cash equivalents | G4: 3839.3 | H4: 0.9
B5: Operating ST Financial Assets | C5: 0 | D5: 0.6 | F5: Restricted cash | G5: 0 | H5: 0
B6: Inventory | C6: 67632 | D6: 0.5 | F6: Securities with stable income | G6: 1.5 | H6: 0.6
B7: Properties held for sale | C7: 0 | D7: 0.6 | F7: Other Securities | G7: 0 | H7: 0.6
B8: Properties held for income | C8: 0 | D8: 0.6 | F8: Properties with stable income | G8: 0 | H8: 0.6
B9: Prepayments and Contract Assets | C9: 0 | D9: 0.1 | F9: Other Properties | G9: 0 | H9: 0.6
B10: ST DTA | C10: 2.3 | D10: 0.9
B11: Other ST Assets | C11: 0 | D11: 0.05
B12: Operating ST Assets | C12: =SUM(C4:C11) -> 73483.1 | D12: =C4*D4+C5*D5+C9*D9+C6*D6+C8*D8+C7*D7+C10*D10+C11*D11 -> 37327.35 | F12: Non-Operating ST Assets | G12: =SUM(G4:G9) -> 3840.8 | H12: =G4*H4+G5*H5+G6*H6+G7*H7+G8*H8+G9*H9 -> 3456.27
B14: LT Operating Assets | C14: Book | D14: Valued @ | F14: LT Non-Operating Assets | G14: Book | H14: Valued @
B15: LT AR | C15: 4.8 | D15: 0.4 | F15: LT Depositis | G15: 0 | H15: 0.8
B16: Operating LT Financial Assets | C16: =1520.1 -> 1520.1 | D16: 0.5 | F16: Securities with stable income | G16: 0 | H16: 0.6
B17: Properties held for sale | C17: 0 | D17: 0.6 | F17: Other Securities | G17: 63.2 | H17: 0.6
B18: Properties held for income | C18: 0 | D18: 0.6 | F18: JV or associate with stable income | G18: =41.5+40 -> 81.5 | H18: 0.1
B19: PP&E & Right of Use Assets | C19: =4063.1+1656.3+785.2 -> 6504.6 | D19: 0.1 | F19: Other JV or associate | G19: 0 | H19: 0.1
B20: Biological assets | C20: 0 | D20: 0.05 | F20: Properties with stable income | G20: 0 | H20: 0.2
B21: Intangible assets | C21: 7.7 | D21: 0.05 | F21: Other Properties | G21: 387 | H21: 0.1
B22: LT DTA | C22: 969.9 | D22: 0.9
B23: Other assets & Goodwill | C23: 0 | D23: 0 | F23: Non-Operating LT Assets | G23: =SUM(G15:G21) -> 531.7 | H23: =G15*H15+G16*H16+G17*H17+G18*H18+G19*H19+G20*H20+G21*H21 -> 84.77
B24: Operating LT Assets | C24: =SUM(C15:C23) -> 9007.1 | D24: =C15*D15+C16*D16+C18*D18+C17*D17+C19*D19+C20*D20+C21*D21+C22*D22+C23*D23 -> 2285.725
B26: ST Liabilities | C26: Book | F26: BS Summary | G26: Book | H26: Valued @
B27: ST Borrowing | C27: =2658.1+24506.6 -> 27164.7 | F27: Total Equity | G27: =G32-G30 -> 26381.7 | H27: =H32-G30 -> -17326.885
B28: ST Lease liabilities | C28: 662.5 | F28: Incl. Non-common Interest | G28: 1036.4
B29: ST SH Loan | C29: 0 | F29: Incl. Common Equity | G29: =G27-G28 -> 25345.3 | H29: =H27-G28 -> -18363.285
B30: ST Financial Liabilities | C30: 0 | F30: Total Liabilities | G30: =C33+C42 -> 60481
B31: ST Interest-bearing Debt | C31: =SUM(C27:C30) -> 27827.2 | F31: incl. Interest-bearing Debt | G31: =C31+C40 -> 29640.8
B32: Other ST liabilities | C32: =C33-C31 -> 30241.6 | F32: Total Assets | G32: =G35+G40 -> 86862.7 | H32: =H35+H40 -> 43154.115
B33: Current Liabilities | C33: 58068.8
F34: Assets Summary | G34: Book | H34: Valued @
B35: LT Liabilities | C35: Book | F35: Operating Assets | G35: =C12+C24 -> 82490.2 | H35: =D12+D24 -> 39613.075
B36: LT Borrowing | C36: 1297.9 | F36: incl. AR | G36: =C4+C15 -> 5853.6
B37: LT Lease liabilities | C37: 515.7 | F37: incl. inventory | G37: =C6 -> 67632
B38: LT SH Loan | C38: 0 | F38: incl. Properties held for sale | G38: =C7+C17 -> 0
B39: LT Financial Liabilities | C39: 0 | F39: incl. Fixed Assets | G39: =C7+C17+C19+C20 -> 6504.6 | H39: =C7*D7+C17*D17+C19*D19+C20*D20 -> 650.46
B40: LT Interest-bearing Debt | C40: =SUM(C36:C39) -> 1813.6 | F40: Non-operating Assets | G40: =G12+G23 -> 4372.5 | H40: =H12+H23 -> 3541.04
B41: Other LT liabilities | C41: =C42-C40 -> 598.6 | F41: incl. Assets with stable income | G41: =C69 -> 3922.3 | H41: =H40-H42 -> 3464.42
B42: Noncurrent Liabilities | C42: 2412.2 | F42: incl. Other Assets | G42: =C75 -> 450.2 | H42: =D75 -> 76.62
...

Sheet Valuation_Model
B2: No-Growth DCF Valuation | H2: Notes
B3: No-Growth DCF | C3: =Normalized_FCF!C3 -> 1000 | E3: Special Assumption
B4: Adjusted FCFE | C4: =Normalized_FCF!C19 -> 336835.71 | D4: =Reporting_currency -> HKD | E4: Terminal Growth Rate: | F4: 0
B5: /Equity Cost of Capital | C5: =Thesis!C37 -> 0.1 | E5: - Expects no significant growth at terminal years
B6: Stable Income Value | C6: =(C4*(1+Terminal_Growth))/(Equity_Cost-Terminal_Growth) -> 3368357.1 | D6: =Reporting_currency -> HKD | E6: - Avoids overvaluation.
B7: - Interest-bearing Debt | C7: =BS!G31 -> 29640.8 | D7: =Reporting_currency -> HKD
B8: + Non-operating Cash | C8: =BS!D65 -> 3455.37 | D8: =Reporting_currency -> HKD
B9: + Other Non-operating Assets | C9: =BS!H42 -> 76.62 | D9: =Reporting_currency -> HKD
B10: Equity Value | C10: =C6-C7+C8+C9 -> 3342248.2 | D10: =Reporting_currency -> HKD
B11: * Exchange rate | C11: =Exchange_Rate -> 1 | D11: =Thesis!D13 -> HKD
B12: Equity Value per share | C12: =(C10*C3)/Common_Shares*C11 -> 4.9337466 | D12: =Market_currency -> HKD
B14: Implied Growth Scenario Analysis
B15: FCFE Projection
B16: High Growth Period (HGP) | C16: =Scenarios!C25 -> 0.12
B17: High Growth Rate (HGR) | C17: =Scenarios!C24 -> 15
B18: Value Per Share | C18: =(F52-C7+C8+C9)/Common_Shares*C3 -> 9.9356524 | D18: =IF(ROUND(C18,1)=ROUND(Scenarios!C29,1),"equals Market Price","a Current Projection") -> a Current Projection
B20: Year | C20: FCFE | D20: Growth Rates | E20: Discount Factor | F20: PV of FCFE
B21: 1 | C21: =C4*(1+D21) -> 377255.99 | D21: =IF($C$17<B21,0,Valuation_Model!$C$16) -> 0.12 | E21: =IF($C$17<B21,0,1/(1+Equity_Cost)^B21) -> 0.90909091 | F21: =C21*E21 -> 342959.99
B22: 2 | C22: =IF(ROW()-ROW($C$21)<$C$17, $C$21*(1+D22)^(ROW()-ROW($C$21)), 0) -> 422526.71 | D22: =IF($C$17<B22,0,Valuation_Model!$C$16) -> 0.12 | E22: =IF($C$17<B22,0,1/(1+Equity_Cost)^B22) -> 0.82644628 | F22: =C22*E22 -> 349195.63
B23: 3 | C23: =IF(ROW()-ROW($C$21)<$C$17, $C$21*(1+D23)^(ROW()-ROW($C$21)), 0) -> 473229.91 | D23: =IF($C$17<B23,0,Valuation_Model!$C$16) -> 0.12 | E23: =IF($C$17<B23,0,1/(1+Equity_Cost)^B23) -> 0.7513148 | F23: =C23*E23 -> 355544.64
B24: 4 | C24: =IF(ROW()-ROW($C$21)<$C$17, $C$21*(1+D24)^(ROW()-ROW($C$21)), 0) -> 530017.5 | D24: =IF($C$17<B24,0,Valuation_Model!$C$16) -> 0.12 | E24: =IF($C$17<B24,0,1/(1+Equity_Cost)^B24) -> 0.68301346 | F24: =C24*E24 -> 362009.09
B25: 5 | C25: =IF(ROW()-ROW($C$21)<$C$17, $C$21*(1+D25)^(ROW()-ROW($C$21)), 0) -> 593619.6 | D25: =IF($C$17<B25,0,Valuation_Model!$C$16) -> 0.12 | E25: =IF($C$17<B25,0,1/(1+Equity_Cost)^B25) -> 0.62092132 | F25: =C25*E25 -> 368591.07
B26: 6 | C26: =IF(ROW()-ROW($C$21)<$C$17, $C$21*(1+D26)^(ROW()-ROW($C$21)), 0) -> 664853.96 | D26: =IF($C$17<B26,0,Valuation_Model!$C$16) -> 0.12 | E26: =IF($C$17<B26,0,1/(1+Equity_Cost)^B26) -> 0.56447393 | F26: =C26*E26 -> 375292.73
B27: 7 | C27: =IF(ROW()-ROW($C$21)<$C$17, $C$21*(1+D27)^(ROW()-ROW($C$21)), 0) -> 744636.43 | D27: =IF($C$17<B27,0,Valuation_Model!$C$16) -> 0.12 | E27: =IF($C$17<B27,0,1/(1+Equity_Cost)^B27) -> 0.51315812 | F27: =C27*E27 -> 382116.23
B28: 8 | C28: =IF(ROW()-ROW($C$21)<$C$17, $C$21*(1+D28)^(ROW()-ROW($C$21)), 0) -> 833992.8 | D28: =IF($C$17<B28,0,Valuation_Model!$C$16) -> 0.12 | E28: =IF($C$17<B28,0,1/(1+Equity_Cost)^B28) -> 0.46650738 | F28: =C28*E28 -> 389063.8
B29: 9 | C29: =IF(ROW()-ROW($C$21)<$C$17, $C$21*(1+D29)^(ROW()-ROW($C$21)), 0) -> 934071.94 | D29: =IF($C$17<B29,0,Valuation_Model!$C$16) -> 0.12 | E29: =IF($C$17<B29,0,1/(1+Equity_Cost)^B29) -> 0.42409762 | F29: =C29*E29 -> 396137.69
B30: 10 | C30: =IF(ROW()-ROW($C$21)<$C$17, $C$21*(1+D30)^(ROW()-ROW($C$21)), 0) -> 1046160.6 | D30: =IF($C$17<B30,0,Valuation_Model!$C$16) -> 0.12 | E30: =IF($C$17<B30,0,1/(1+Equity_Cost)^B30) -> 0.38554329 | F30: =C30*E30 -> 403340.19
B31: 11 | C31: =IF(ROW()-ROW($C$21)<$C$17, $C$21*(1+D31)^(ROW()-ROW($C$21)), 0) -> 1171699.8 | D31: =IF($C$17<B31,0,Valuation_Model!$C$16) -> 0.12 | E31: =IF($C$17<B31,0,1/(1+Equity_Cost)^B31) -> 0.3504939 | F31: =C31*E31 -> 410673.65
B32: 12 | C32: =IF(ROW()-ROW($C$21)<$C$17, $C$21*(1+D32)^(ROW()-ROW($C$21)), 0) -> 1312303.8 | D32: =IF($C$17<B32,0,Valuation_Model!$C$16) -> 0.12 | E32: =IF($C$17<B32,0,1/(1+Equity_Cost)^B32) -> 0.31863082 | F32: =C32*E32 -> 418140.44
B33: 13 | C33: =IF(ROW()-ROW($C$21)<$C$17, $C$21*(1+D33)^(ROW()-ROW($C$21)), 0) -> 1469780.3 | D33: =IF($C$17<B33,0,Valuation_Model!$C$16) -> 0.12 | E33: =IF($C$17<B33,0,1/(1+Equity_Cost)^B33) -> 0.28966438 | F33: =C33*E33 -> 425742.99
... B50: 30 | C50: =IF(ROW()-ROW($C$21)<$C$17, $C$21*(1+D50)^(ROW()-ROW($C$21)), 0) -> 0 | D50: =IF($C$17<B50,0,Valuation_Model!$C$16) -> 0 | E50: =IF($C$17<B50,0,1/(1+Equity_Cost)^B50) -> 0 | F50: =C50*E50 -> 0
B51: Terminal Year | C51: =C$21*(1+Terminal_Growth)^$C$17/Equity_Cost -> 3772559.9 | D51: =Terminal_Growth -> 0 | E51: =1/(1+Equity_Cost)^C17 -> 0.23939205 | F51: =C51*E51 -> 903120.85
E52: Total PV | F52: =SUM(F21:F51) -> 6756778
B54: Sensitivity Analysis (Enterprise Value)
A55: =F52 -> 6756778 | B55: =C78 -> -0.05 | C55: =C77 -> 0 | D55: =C76 -> 0.02 | E55: =C75 -> 0.1 | F55: =C74 -> 0.1
A56: 5 | B56: 3095247.6 | C56: 3368357.1 | D56: 3483780.3 | E56: 3984811.7 | F56: 3984811.7
A57: 10 | B57: 2874560.7 | C57: 3368357.1 | D57: 3600894.5 | E57: 4796869.3 | F57: 4796869.3
A58: 15 | B58: 2662733.1 | C58: 3368357.1 | D58: 3733444.6 | E58: 5939529.3 | F58: 5939529.3
A59: 20 | B59: 2495267.4 | C59: 3368357.1 | D59: 3856764.9 | E59: 7287467.4 | F59: 7287467.4
A60: 25 | B60: 2374017.9 | C60: 3368357.1 | D60: 3961456.3 | E60: 8762867.1 | F60: 8762867.1
...

Sheet Scenarios
B2: Current Situation
B3: Selection
B4: Past Years Selected | C4: 4 | E4: Tie the business story into the three levers of value: FCFE, growth and risk.
B6: FCFE | C6: =Valuation_Model!C3 -> 1000 | E6: Prompt for Scenario Analysis
B7: Lastest | C7: =Normalized_FCF!G19 -> 0 | E7: Given 六福珠宝’s (0590.HK) normalized FCFE of HKD 1,270,672,000, please analyze its valuation assumptions under three scenarios (Base, Pessimistic, Optimistic) using a two-stage model, a growth stage and a terminal stage. Define the growth period, growth rates and probabilities for each scenario. Explain the rationale behind the probabilities. Summarize the business drivers and scenario narratives to align with the model’s inputs. For context only, the terminal value assumes 0% growth to prevent overvaluation. The finalized scenarios will be incorporated directly into the valuation framework.”
B8: Normalized | C8: =Normalized_FCF!C19 -> 336835.71
B10: Growth Rate
B11: Sales Growth Rates | C11: =AVERAGE(Normalized_FCF!G94:INDEX(Normalized_FCF!G94:Q94, $C$4)) -> 0.11909073
B12: Op. FCFE Before WCInv
B13: Non-Operating Income
B15: Margin
B16: Contribution Margin
B17: Op. FCFE Before WCInv
B19: Objective Scenarios
B20: No Growth Scenario | E20: Business Story
B21: Value per share | C21: =Valuation_Model!E77 -> 4.9337466 | D21: =Reporting_currency -> HKD | E21: Unbiased Scenario where the company FCFE has no growth and no risk.
B23: Market Scenario
B24: High Growth Period (HGP) | C24: 15
B25: High Growth Rate (HGR) | C25: 0.12
B26: Value per share | C26: =Valuation_Model!C18 -> 9.9356524
B28: Reference Price Points
B29: Market Price | C29: =Market_Price -> 7
B30: 52 week High | C30: 13
B31: 52 week Low
B33: General Scenarios
B34: Assumption
B35: High Growth Period (HGP) | C35: 5
B37: Base | E37: Business Story
B38: High Growth Period (HGP) | C38: =C35 -> 5
B39: High Growth Rate (HGR) | C39: 0.02
B40: Value per share | C40: =Valuation_Model!E76 -> 5.1041316 | D40: =Market_currency -> HKD
B41: Probabilities | C41: 0.6
B43: Pessimistic | E43: Business Story
B44: High Growth Period (HGP) | C44: =C35 -> 5
B45: High Growth Rate (HGR) | C45: 0
B46: Value per share | C46: =Valuation_Model!E77 -> 4.9337466 | D46: =Market_currency -> HKD
B47: Probabilities | C47: 0.2
B49: Optimistic | E49: Business Story
B50: High Growth Period (HGP) | C50: =C35 -> 5
B51: High Growth Rate (HGR) | C51: 0.1
...
