Workbook
Name Common_Shares: Thesis!$C$6
Name Equity_Cost: Valuation_Model!$C$5
Name Exchange_Rate: Thesis!$C$16
Name Market_currency: Thesis!$C$13
Name Market_Price: Thesis!$C$12
Name Reporting_currency: Thesis!$C$22
Name scaling_factor: Data!$C$3
Name Terminal_Growth: Valuation_Model!$F$4

Sheet Thesis
B1: Model last updated: | C1: 45754 | E1: Selected: | F1: N
A2: Executive Summary
B4: Company Information
B5: Company Name | C5: 青島啤酒股份
B6: Number of Shares: | C6: 1364196788
B7: Report Interval: | C7: 6
B8: Update Required After: | C8: =EOMONTH(EDATE(BS!C1,C7+2),0) -> 45900
B10: Listing Information
B11: Symbol: | C11: 0168.HK
B12: Market Price: | C12: 53.55
B13: Market Currency | C13: HKD
B14: Capitalization: | C14: =Thesis!C12*Common_Shares/1000000 -> 73052.738 | D14: =IF(D11="","",Thesis!D12*Common_Shares/1000000)
B15: Forex Symbol: | C15: =IF(C22=C13,C13,C22&"/"&C13) -> CNY/HKD | D15: =IF(D11="","",IF(C22=D13,D13,C22&"/"&D13))
B16: Exchange Rate: | C16: 1.0742247
B18: Guidance Note: This model determines a target buy price consistent with defined investment criteria. It follows a logical progression: establishing current sustainable earnings, adjusting for financial structure, incorporating growth scenarios, and finally applying the investor’s required return.
B20: Valuation Overview
B21: Growth Classification: | C21: =IF(Scenarios!C69="Y",Scenarios!B69,"")&IF(Scenarios!C70="Y",Scenarios!B70,"")&IF(Scenarios!C71="Y",Scenarios!B71,"")&" "&IF(Scenarios!C72="Y",Scenarios!B72,"") -> Low Growth
B22: Reporting Currency: | C22: CNY | D22: =IF(D11="","",Market_currency&"/"&D13&":") | E22: =IF(D11="","",1/Exchange_Rate*D16)
B23: Comp_Sector: | C23: CNS_03
B24: Target Annual Return: | C24: 0.3 | D24: in contrast to a position yield of | E24: 0.2
B25: ="Target Buy Price ("&Market_currency&"):" -> Target Buy Price (HKD): | C25: =C139 -> 34.394984 | D25: assuming a holding period of | E25: 3
B26: Market Implied Annual Return: | C26: =Scenarios!C87 -> 0.11521291
A28: Step 1: Establishing the Company’s Sustainable Earning Power (Calculating Normalized FCFE)
B30: Goal: To quantify the underlying FCFE the business consistently generates for its equity owners, stripping away temporary fluctuations or accounting choices.The FCFE/Market Cap yield gives a direct measure of this cash generation relative to the current market price.
B31: FCFE = (Normalized Operating EBIT + Depreciation & Amortization – Capital Expenditures) + Stable Non-Operating EBIT + Net Interest Income – Taxes – NCI’s Share of Profits – Working Capital Investment
B33: Key Components | C33: =scaling_factor -> 1
B34: • Normalized Operating EBIT: Earnings before interest and taxes from core business operations, adjusted to remove one-time or irregular items for a sustainable earnings base.
B35: Normalized Operating EBIT = | C35: =Normalized_FCF!C8 -> 3.8780681e+09 | D35: =Reporting_currency -> CNY
B37: • Depreciation & Amortization (D&A): Non-cash expenses added back to reflect cash generated from operations. • Capital Expenditures (Capex): Cash outflows required to maintain or expand operational assets
B38: D&A = | C38: =Normalized_FCF!C9 -> 1191305772 | D38: =Reporting_currency -> CNY
B39: Capex = | C39: =Normalized_FCF!C10 -> -1191305772 | D39: =Reporting_currency -> CNY
B41: • Stable Non-Operating EBIT: Consistent earnings from non-core assets, such as fixed-income investments, dividend-paying stocks, or rental properties.
B42: Stable Non-Operating EBIT = | C42: =Normalized_FCF!C11 -> 0 | D42: =Reporting_currency -> CNY
B44: • Net Interest Income: Interest income minus interest expense
B45: Operating Interest Income = | C45: =Normalized_FCF!C48 -> 1.7735368e+08 | D45: =Reporting_currency -> CNY
B46: Interest Expense = | C46: =Normalized_FCF!C47 -> -21837054 | D46: =Reporting_currency -> CNY
B47: Net Interest Income = | C47: =Normalized_FCF!C12 -> 1.5551662e+08 | D47: =Reporting_currency -> CNY
B49: • NCI’s Share of Profits: NCI represents the portion of a subsidiary’s equity not owned by the parent company.
B50: Est. NCI’s Share of Profits = | C50: =Normalized_FCF!C15 -> -1.4663456e+08 | D50: =Reporting_currency -> CNY
B52: • Taxes: Tax = (Normalized Operating EBIT + Stable Non-Operating EBIT + Interest Income – Interest Expense) × Tax Rate
...

Sheet Data
B1: =Thesis!C22 -> CNY | C1: 45657 | D1: =EOMONTH(EDATE(C1,-12),0) -> 45291 | E1: =EOMONTH(EDATE(D1,-12),0) -> 44926 | F1: =EOMONTH(EDATE(E1,-12),0) -> 44561 | G1: =EOMONTH(EDATE(F1,-12),0) -> 44196 | H1: =EOMONTH(EDATE(G1,-12),0) -> 43830 | I1: =EOMONTH(EDATE(H1,-12),0) -> 43465 | J1: =EOMONTH(EDATE(I1,-12),0) -> 43100 | K1: =EOMONTH(EDATE(J1,-12),0) -> 42735 | ... M1: =EOMONTH(EDATE(L1,-12),0) -> 42004
B2: Data (Dirty)
B3: Income Statement | C3: 1
B4: Sales | C4: 32137830111 | D4: 33936522741 | E4: 32171565624 | F4: 30166805377 | G4: 27759710926
B5: COGS | C5: =19209915823+2328256391 -> 21538172214 | D5: =20816889655+2386660732 -> 23203550387 | E5: =20317934822+2390725323 -> 22708660145 | F5: =19091130744+2318835745 -> 21409966489 | G5: =16540609624+2219072099 -> 18759681723
B6: OPEX | C6: =1406578781+C7 -> 6009098645 | D6: =1519063042+D7 -> 6227465840 | E6: =1473368004+E7 -> 5672870751 | F6: =1692545246+F7 -> 5789419371 | G6: =1678050722+G7 -> 6662600559
B7: Incl. Selling Expenses | C7: 4602519864 | D7: 4708402798 | E7: 4199502747 | F7: 4096874125 | G7: 4984549837
B8: R&D | C8: 102766675 | D8: 100637006 | E8: 62954899 | F8: 30890245 | G8: 21467092
B9: Share of JV or associate Results | C9: 48272283 | D9: 15798284 | E9: 19873379 | F9: 20561728 | G9: 18098320
B10: Dividend or Interests from FA
B11: Investment property
B12: Interest Expense | C12: 21837054 | D12: 16430590 | E12: 9237800 | F12: 22685367 | G12: 13662682
B13: Interest Income | C13: 616771200 | D13: 506376003 | E13: 459661656 | F13: 315648307 | G13: 524029340
B14: Income Tax Paid | C14: 1389716314 | D14: 1398208378 | E14: 1201419808 | F14: 1222731595 | G14: 912580519
B15: Reported Net Income | C15: 4491776686 | D15: 4348198924 | E15: 3804721478 | F15: 3256243870 | G15: 2326968805
B16: Non-controling Interests | C16: 146792828 | D16: 80347518 | E16: 94092885 | F16: 100788060 | G16: 125645249
B18: Cash Flow Statement
B19: D&A | C19: 1191305772 | D19: 1140399624 | E19: 1083856796 | F19: 1109733268
B20: CAPX | C20: =C19 -> 1191305772 | D20: =D19 -> 1140399624 | E20: =E19 -> 1083856796 | F20: =F19 -> 1109733268
B21: WCInv | C21: 583532518 | D21: 1575918543 | E21: 878667968 | F21: 2804548241
B22: CFO | C22: 5154661132 | D22: 2777567140 | E22: 4878771322 | F22: 6043111455 | G22: 4953422362
B23: CFI | C23: -7421783375 | D23: -3462971412 | E23: -2199108158 | F23: -10249763562 | G23: -1487738165
B24: CFF | C24: -2983143705 | D24: -2868065880 | E24: -1675712527 | F24: -1613622636 | G24: -356090851
B25: ="Dividend per share ("&Market_currency&")" -> Dividend per share (HKD) | C25: =2.2/Exchange_Rate -> 2.0479887 | D25: =2/Exchange_Rate -> 1.8618079 | E25: =1.3/Exchange_Rate -> 1.2101752 | F25: =1.1/Exchange_Rate -> 1.0239944 | G25: =0.75/Exchange_Rate -> 0.69817798
B27: Balance Sheet | C27: Latest Asset Value
B28: ST AR | C28: =BS!C4 -> 185704725 | D28: 100391321 | E28: 124099728 | F28: 124929816 | G28: 125155008
B29: ST Inventory | C29: =BS!C6 -> 3576387537 | D29: 3539828305 | E29: 4152187132 | F29: 3492997857 | G29: 3281033526
B30: Total Liabilities | C30: =BS!C33+BS!C42 -> 21560843821 | D30: 21001264174 | E30: 24039387261 | F30: 22769313149 | G30: 20146133669
B31: Total Equity | C31: =BS!G27 -> 29859542011 | D31: 28254747175 | E31: 26272312535 | F31: 23793691342 | G31: 21368052166
B32: Non-common Interest | C32: =BS!G28 -> 799157484 | D32: 805268959 | E32: 777490832 | F32: 791846744 | G32: 746091651
B34: IS & CF Statements (Clean)
B35: Income Statement
B36: Sales | C36: =IF(C$4="","",C4) -> 32137830111 | D36: =IF(D$4="","",D4) -> 33936522741 | E36: =IF(E$4="","",E4) -> 32171565624 | F36: =IF(F$4="","",F4) -> 30166805377 | G36: =IF(G$4="","",G4) -> 27759710926 | H36: =IF(H$4="","",H4) | I36: =IF(I$4="","",I4) | J36: =IF(J$4="","",J4) | ... M36: =IF(M$4="","",M4)
B37: COGS | C37: =IF(C$4="","",-C5) -> -21538172214 | D37: =IF(D$4="","",-D5) -> -23203550387 | E37: =IF(E$4="","",-E5) -> -22708660145 | F37: =IF(F$4="","",-F5) -> -21409966489 | G37: =IF(G$4="","",-G5) -> -18759681723 | H37: =IF(H$4="","",-H5) | I37: =IF(I$4="","",-I5) | J37: =IF(J$4="","",-J5) | ... M37: =IF(M$4="","",-M5)
B38: Gross Margin | C38: =IF(C36="","",C36+C37) -> 10599657897 | D38: =IF(D36="","",D36+D37) -> 10732972354 | E38: =IF(E36="","",E36+E37) -> 9462905479 | F38: =IF(F36="","",F36+F37) -> 8756838888 | G38: =IF(G36="","",G36+G37) -> 9000029203 | H38: =IF(H36="","",H36+H37) | I38: =IF(I36="","",I36+I37) | J38: =IF(J36="","",J36+J37) | ... M38: =IF(M36="","",M36+M37)
B39: OPEX | C39: =IF(C$4="","",-C6) -> -6009098645 | D39: =IF(D$4="","",-D6) -> -6227465840 | E39: =IF(E$4="","",-E6) -> -5672870751 | F39: =IF(F$4="","",-F6) -> -5789419371 | G39: =IF(G$4="","",-G6) -> -6662600559 | H39: =IF(H$4="","",-H6) | I39: =IF(I$4="","",-I6) | J39: =IF(J$4="","",-J6) | ... M39: =IF(M$4="","",-M6)
B40: Incl. Selling Expenses | C40: =IF(C$4="","",-C7) -> -4602519864 | D40: =IF(D$4="","",-D7) -> -4708402798 | E40: =IF(E$4="","",-E7) -> -4199502747 | F40: =IF(F$4="","",-F7) -> -4096874125 | G40: =IF(G$4="","",-G7) -> -4984549837 | H40: =IF(H$4="","",-H7) | I40: =IF(I$4="","",-I7) | J40: =IF(J$4="","",-J7) | ... M40: =IF(M$4="","",-M7)
B41: Incl. Other Opex | C41: =IF(C$4="","",C39-C40) -> -1406578781 | D41: =IF(D$4="","",D39-D40) -> -1519063042 | E41: =IF(E$4="","",E39-E40) -> -1473368004 | F41: =IF(F$4="","",F39-F40) -> -1692545246 | G41: =IF(G$4="","",G39-G40) -> -1678050722 | H41: =IF(H$4="","",H39-H40) | I41: =IF(I$4="","",I39-I40) | J41: =IF(J$4="","",J39-J40) | ... M41: =IF(M$4="","",M39-M40)
B42: R&D | C42: =IF(C$4="","",-C8) -> -102766675 | D42: =IF(D$4="","",-D8) -> -100637006 | E42: =IF(E$4="","",-E8) -> -62954899 | F42: =IF(F$4="","",-F8) -> -30890245 | G42: =IF(G$4="","",-G8) -> -21467092 | H42: =IF(H$4="","",-H8) | I42: =IF(I$4="","",-I8) | J42: =IF(J$4="","",-J8) | ... M42: =IF(M$4="","",-M8)
B43: Operating EBIT | C43: =IF(C$4="","",C38+C39+C42) -> 4487792577 | D43: =IF(D$4="","",D38+D39+D42) -> 4404869508 | E43: =IF(E$4="","",E38+E39+E42) -> 3727079829 | F43: =IF(F$4="","",F38+F39+F42) -> 2936529272 | G43: =IF(G$4="","",G38+G39+G42) -> 2315961552 | H43: =IF(H$4="","",H38+H39+H42) | I43: =IF(I$4="","",I38+I39+I42) | J43: =IF(J$4="","",J38+J39+J42) | ... M43: =IF(M$4="","",M38+M39+M42)
...

Sheet BS
B1: Most Recent Quarter | C1: =Normalized_FCF!G1 -> 45657 | F1: =IF(MONTH(C1)=MONTH(Normalized_FCF!G1),"FY","Quarter")&" Report" -> FY Report | H1: =scaling_factor -> 1
B2: Lastest Balance Sheet
B3: ST Operating Assets | C3: Book | D3: Valued @ | F3: ST Non-Operating Assets | G3: Book | H3: Valued @
B4: ST AR | C4: =102420347+83284378 -> 185704725 | D4: 0.6 | F4: Cash and cash equivalents | G4: 17978772896 | H4: 0.9
B5: Operating ST Financial Assets | C5: 0 | D5: 0.6 | F5: Restricted cash | G5: 0 | H5: 0.7
B6: Inventory | C6: 3576387537 | D6: 0.5 | F6: Securities with stable income | G6: 0 | H6: 0.6
B7: Properties held for sale | C7: 0 | D7: 0.6 | F7: Other Securities | G7: 2021804089 | H7: 0.6
B8: Properties held for income | C8: 0 | D8: 0.6 | F8: Properties with stable income | G8: 0 | H8: 0.6
B9: Prepayments and Contract Assets | C9: 241896760 | D9: 0.1 | F9: Other Properties | G9: 0 | H9: 0.6
B10: ST DTA | C10: 0 | D10: 0.9
B11: Other ST Assets | C11: =51713930+1132635624 -> 1184349554 | D11: 0.05
B12: Operating ST Assets | C12: =SUM(C4:C11) -> 5188338576 | D12: =C4*D4+C5*D5+C9*D9+C6*D6+C8*D8+C7*D7+C10*D10+C11*D11 -> 1.9830238e+09 | F12: Non-Operating ST Assets | G12: =SUM(G4:G9) -> 20000576985 | H12: =G4*H4+G5*H5+G6*H6+G7*H7+G8*H8+G9*H9 -> 1.7393978e+10
B14: LT Operating Assets | C14: Book | D14: Valued @ | F14: LT Non-Operating Assets | G14: Book | H14: Valued @
B15: LT AR | C15: 0 | D15: 0.4 | F15: LT Depositis | G15: 0 | H15: 0.8
B16: Operating LT Financial Assets | C16: 0 | D16: 0.5 | F16: Securities with stable income | G16: 0 | H16: 0.6
B17: Properties held for sale | C17: 0 | D17: 0.6 | F17: Other Securities | G17: 2498379750 | H17: 0.6
B18: Properties held for income | C18: 0 | D18: 0.6 | F18: JV or associate with stable income | G18: 0 | H18: 0.1
B19: PP&E & Right of Use Assets | C19: =11817650634+630874619+115672625+85702449 -> 12649900327 | D19: 0.1 | F19: Other JV or associate | G19: 391873803 | H19: 0.1
B20: Biological assets | C20: 0 | D20: 0.05 | F20: Properties with stable income | G20: 0 | H20: 0.2
B21: Intangible assets | C21: 2684120584 | D21: 0.05 | F21: Other Properties | G21: 41138918 | H21: 0.1
B22: LT DTA | C22: 1930039528 | D22: 0.9
B23: Other assets & Goodwill | C23: =1307103982+4728913379 -> 6036017361 | D23: 0
B24: Operating LT Assets | C24: =SUM(C15:C23) -> 23300077800 | D24: =C15*D15+C16*D16+C18*D18+C17*D17+C19*D19+C20*D20+C21*D21+C22*D22+C23*D23 -> 3.1362316e+09 | F24: Non-Operating LT Assets | G24: =SUM(G15:G21) -> 2931392471 | H24: =G15*H15+G16*H16+G17*H17+G18*H18+G19*H19+G20*H20+G21*H21 -> 1.5423291e+09
B26: ST Liabilities | C26: Book | F26: BS Summary | G26: Book | H26: Valued @
B27: ST Borrowing | C27: 0 | F27: Total Equity | G27: =G32-G30 -> 29859542011 | H27: =H32-G30 -> 2.4947188e+09
B28: ST Lease liabilities | C28: 0 | F28: Incl. Minority Interest (NCI) | G28: 799157484
B29: ST SH Loan | C29: 0 | F29: Incl. Common Equity | G29: =G27-G28 -> 29060384527 | H29: =H27-G28 -> 1.6955613e+09
B30: ST Financial Liabilities | C30: 217159673 | F30: Total Liabilities | G30: =C33+C42 -> 21560843821
B31: ST Interest-bearing Debt | C31: =SUM(C27:C30) -> 217159673 | F31: incl. Interest-bearing Debt | G31: =C31+C40 -> 285396383
B32: Other ST liabilities | C32: =C33-C31 -> 17305171626 | F32: Total Assets | G32: =G35+G40 -> 51420385832 | H32: =H35+H40 -> 2.4055563e+10
B33: Current Liabilities | C33: 17522331299
F34: Assets Summary | G34: Book | H34: Valued @
B35: LT Liabilities | C35: Book | F35: Operating Assets | G35: =C12+C24 -> 28488416376 | H35: =D12+D24 -> 5.1192554e+09
B36: LT Borrowing | C36: 0 | F36: incl. AR | G36: =C4+C15 -> 185704725
B37: LT Lease liabilities | C37: 68236710 | F37: incl. inventory | G37: =C6 -> 3576387537
B38: LT SH Loan | C38: 0 | F38: incl. Properties held for sale | G38: =C7+C17 -> 0
B39: LT Financial Liabilities | C39: 0 | F39: incl. Fixed Assets | G39: =C7+C17+C19+C20 -> 12649900327 | H39: =C7*D7+C17*D17+C19*D19+C20*D20 -> 1.26499e+09
B40: LT Interest-bearing Debt | C40: =SUM(C36:C39) -> 68236710 | F40: Non-operating Assets | G40: =G12+G24 -> 22931969456 | H40: =H12+H24 -> 1.8936307e+10
B41: Other LT liabilities | C41: =C42-C40 -> 3970275812 | F41: incl. Assets with stable income | G41: =C70 -> 17978772896 | H41: =H40-H42 -> 1.6180896e+10
B42: Noncurrent Liabilities | C42: 4038512522 | F42: incl. Other Assets | G42: =C82 -> 4953196560 | H42: =D82 -> 2.7554116e+09
...

Sheet Normalized_FCF
B1: =Thesis!C22 -> CNY | C1: Normalized | G1: =Data!C1 -> 45657 | H1: =EOMONTH(EDATE(G1,-12),0) -> 45291 | I1: =EOMONTH(EDATE(H1,-12),0) -> 44926 | J1: =EOMONTH(EDATE(I1,-12),0) -> 44561 | K1: =EOMONTH(EDATE(J1,-12),0) -> 44196 | L1: =EOMONTH(EDATE(K1,-12),0) -> 43830 | M1: =EOMONTH(EDATE(L1,-12),0) -> 43465 | N1: =EOMONTH(EDATE(M1,-12),0) -> 43100 | O1: =EOMONTH(EDATE(N1,-12),0) -> 42735 | ... Q1: =EOMONTH(EDATE(P1,-12),0) -> 42004
B2: FCFE Analysis | E2: Notes
B3: FCFE | C3: =scaling_factor -> 1
B4: Sales | C4: =AVERAGE(G4:J4) -> 3.2103181e+10 | G4: =Data!C36 -> 32137830111 | H4: =Data!D36 -> 33936522741 | I4: =Data!E36 -> 32171565624 | J4: =Data!F36 -> 30166805377 | K4: =Data!G36 -> 27759710926 | L4: =Data!H36 | M4: =Data!I36 | N4: =Data!J36 | ... Q4: =Data!M36
B5: Variable Costs | C5: =C25 -> -2.6627912e+10 | G5: =G25 -> -26140692078 | H5: =H25 -> -27911953185 | I5: =I25 -> -26908162892 | J5: =J25 -> -25506840614 | K5: =K25 -> -23744231560 | L5: =L25 | M5: =M25 | N5: =N25 | ... Q5: =Q25
B6: Contribution Margin | C6: =C4+C5 -> 5.475269e+09 | G6: =IF(G4="","",G4+G5) -> 5997138033 | H6: =IF(H4="","",H4+H5) -> 6024569556 | I6: =IF(I4="","",I4+I5) -> 5263402732 | J6: =IF(J4="","",J4+J5) -> 4659964763 | K6: =IF(K4="","",K4+K5) -> 4015479366 | L6: =IF(L4="","",L4+L5) | M6: =IF(M4="","",M4+M5) | N6: =IF(N4="","",N4+N5) | ... Q6: =IF(Q4="","",Q4+Q5)
B7: Fixed Costs | C7: =C35 -> -1.597201e+09 | G7: =G35 -> -1509345456 | H7: =H35 -> -1619700048 | I7: =I35 -> -1536322903 | J7: =J35 -> -1723435491 | K7: =K35 -> -1699517814 | L7: =L35 | M7: =M35 | N7: =N35 | ... Q7: =Q35
B8: Operating EBIT | C8: =C6+C7 -> 3.8780681e+09 | G8: =IF(G$4="","",G6+G7) -> 4487792577 | H8: =IF(H$4="","",H6+H7) -> 4404869508 | I8: =IF(I$4="","",I6+I7) -> 3727079829 | J8: =IF(J$4="","",J6+J7) -> 2936529272 | K8: =IF(K$4="","",K6+K7) -> 2315961552 | L8: =IF(L$4="","",L6+L7) | M8: =IF(M$4="","",M6+M7) | N8: =IF(N$4="","",N6+N7) | ... Q8: =IF(Q$4="","",Q6+Q7)
B9: Add Back D&A | C9: =BS!$G$39*BS!D58 -> 1191305772 | G9: =IF(Data!C61="","",-Data!C61) -> 1191305772 | H9: =IF(Data!D61="","",-Data!D61) -> 1140399624 | I9: =IF(Data!E61="","",-Data!E61) -> 1083856796 | J9: =IF(Data!F61="","",-Data!F61) -> 1109733268 | K9: =IF(Data!G61="","",-Data!G61) -> 0 | L9: =IF(Data!H61="","",-Data!H61) | M9: =IF(Data!I61="","",-Data!I61) | N9: =IF(Data!J61="","",-Data!J61) | ... Q9: =IF(Data!M61="","",-Data!M61)
B10: Maintenance Capex | C10: =-C4*C78 -> -1191305772 | G10: =Data!C62 -> -1191305772 | H10: =Data!D62 -> -1140399624 | I10: =Data!E62 -> -1083856796 | J10: =Data!F62 -> -1109733268 | K10: =Data!G62 -> 0 | L10: =Data!H62 | M10: =Data!I62 | N10: =Data!J62 | ... Q10: =Data!M62
B11: Stable Non-Operating EBIT | C11: =C63 -> 0 | G11: =G61 -> 48272283 | H11: =H61 -> 15798284 | I11: =I61 -> 19873379 | J11: =J61 -> 20561728 | K11: =K61 -> 18098320 | L11: =L61 | M11: =M61 | N11: =N61 | ... Q11: =Q61
B12: Net Interest Income | C12: =C50 -> 1.5551662e+08 | G12: =G50 -> 1.5551662e+08 | H12: =H50 -> 1.2917875e+08 | I12: =I50 -> 1.2293874e+08 | J12: =J50 -> 68079876 | K12: =K50 -> 1.3702291e+08 | L12: =L50 | M12: =M50 | N12: =N50 | ... Q12: =Q50
B13: Pre-tax Profit | C13: =SUM(C8:C12) -> 4.0335847e+09 | G13: =IF(G$4="","",SUM(G8:G12)) -> 4.6915815e+09 | H13: =IF(H$4="","",SUM(H8:H12)) -> 4.5498465e+09 | I13: =IF(I$4="","",SUM(I8:I12)) -> 3.869892e+09 | J13: =IF(J$4="","",SUM(J8:J12)) -> 3.0251709e+09 | K13: =IF(K$4="","",SUM(K8:K12)) -> 2.4710828e+09 | L13: =IF(L$4="","",SUM(L8:L12)) | M13: =IF(M$4="","",SUM(M8:M12)) | N13: =IF(N$4="","",SUM(N8:N12)) | ... Q13: =IF(Q$4="","",SUM(Q8:Q12))
B14: Income Tax | C14: =-SUM(C8+C11,C12)*C43 -> -1.0083962e+09 | G14: =Data!C46 -> -1389716314 | H14: =Data!D46 -> -1398208378 | I14: =Data!E46 -> -1201419808 | J14: =Data!F46 -> -1222731595 | K14: =Data!G46 -> -912580519 | L14: =Data!H46 | M14: =Data!I46 | N14: =Data!J46 | ... Q14: =Data!M46
B15: NCI’s Share of Profits | C15: =-C4*C83 -> -1.4663456e+08 | G15: =Data!C48 -> -146792828 | H15: =Data!D48 -> -80347518 | I15: =Data!E48 -> -94092885 | J15: =Data!F48 -> -100788060 | K15: =Data!G48 -> -125645249 | L15: =Data!H48 | M15: =Data!I48 | N15: =Data!J48 | ... Q15: =Data!M48
B16: After-tax Profit | C16: =SUM(C13:C15) -> 2.878554e+09 | G16: =IF(G$4="","",SUM(G13:G15)) -> 3.1550723e+09 | H16: =IF(H$4="","",SUM(H13:H15)) -> 3.0712906e+09 | I16: =IF(I$4="","",SUM(I13:I15)) -> 2.5743793e+09 | J16: =IF(J$4="","",SUM(J13:J15)) -> 1.7016512e+09 | K16: =IF(K$4="","",SUM(K13:K15)) -> 1.432857e+09 | L16: =IF(L$4="","",SUM(L13:L15)) | M16: =IF(M$4="","",SUM(M13:M15)) | N16: =IF(N$4="","",SUM(N13:N15)) | ... Q16: =IF(Q$4="","",SUM(Q13:Q15))
B17: WCInv | C17: =-C4*C85 -> 0 | E17: WCInv is by default excluded
B18: Net Borrowing | C18: 0 | E18: Net borrowing is excluded
B19: FCFE | C19: =C16+C17 -> 2.878554e+09 | G19: =IF(G$4="","",G16+G17) -> 3.1550723e+09 | H19: =IF(H$4="","",H16+H17) -> 3.0712906e+09 | I19: =IF(I$4="","",I16+I17) -> 2.5743793e+09 | J19: =IF(J$4="","",J16+J17) -> 1.7016512e+09 | K19: =IF(K$4="","",K16+K17) -> 1.432857e+09 | L19: =IF(L$4="","",L16+L17) | M19: =IF(M$4="","",M16+M17) | N19: =IF(N$4="","",N16+N17) | ... Q19: =IF(Q$4="","",Q16+Q17)
B21: Operating Cost Structure | E21: Notes
B22: Variable Costs
B23: COGS | C23: =-C4*C28 -> -2.2227406e+10 | G23: =Data!C37 -> -21538172214 | H23: =Data!D37 -> -23203550387 | I23: =Data!E37 -> -22708660145 | J23: =Data!F37 -> -21409966489 | K23: =Data!G37 -> -18759681723 | L23: =Data!H37 | M23: =Data!I37 | N23: =Data!J37 | ... Q23: =Data!M37
B24: Selling Expenses | C24: =-C4*C29 -> -4.4005061e+09 | G24: =Data!C40 -> -4602519864 | H24: =Data!D40 -> -4708402798 | I24: =Data!E40 -> -4199502747 | J24: =Data!F40 -> -4096874125 | K24: =Data!G40 -> -4984549837 | L24: =Data!H40 | M24: =Data!I40 | N24: =Data!J40 | ... Q24: =Data!M40
B25: Variable Costs | C25: =C23+C24 -> -2.6627912e+10 | G25: =IF(G$4="","",G23+G24) -> -26140692078 | H25: =IF(H$4="","",H23+H24) -> -27911953185 | I25: =IF(I$4="","",I23+I24) -> -26908162892 | J25: =IF(J$4="","",J23+J24) -> -25506840614 | K25: =IF(K$4="","",K23+K24) -> -23744231560 | L25: =IF(L$4="","",L23+L24) | M25: =IF(M$4="","",M23+M24) | N25: =IF(N$4="","",N23+N24) | ... Q25: =IF(Q$4="","",Q23+Q24)
B27: Variable Costs % of Sales
B28: COGS | C28: =AVERAGE(G28:J28) -> 0.69237394 | E28: Historical Average | G28: =IF(G$4="","",ABS(G23/G$4)) -> 0.67018128 | H28: =IF(H$4="","",ABS(H23/H$4)) -> 0.68373388 | I28: =IF(I$4="","",ABS(I23/I$4)) -> 0.70586121 | J28: =IF(J$4="","",ABS(J23/J$4)) -> 0.70971938 | K28: =IF(K$4="","",ABS(K23/K$4)) -> 0.67578808 | L28: =IF(L$4="","",ABS(L23/L$4)) | M28: =IF(M$4="","",ABS(M23/M$4)) | N28: =IF(N$4="","",ABS(N23/N$4)) | ... Q28: =IF(Q$4="","",ABS(Q23/Q$4))
B29: =B24 -> Selling Expenses | C29: =AVERAGE(G29:J29) -> 0.13707383 | E29: Historical Average | G29: =IF(G$4="","",ABS(G24/G$4)) -> 0.1432119 | H29: =IF(H$4="","",ABS(H24/H$4)) -> 0.13874146 | I29: =IF(I$4="","",ABS(I24/I$4)) -> 0.13053461 | J29: =IF(J$4="","",ABS(J24/J$4)) -> 0.13580736 | K29: =IF(K$4="","",ABS(K24/K$4)) -> 0.17956058 | L29: =IF(L$4="","",ABS(L24/L$4)) | M29: =IF(M$4="","",ABS(M24/M$4)) | N29: =IF(N$4="","",ABS(N24/N$4)) | ... Q29: =IF(Q$4="","",ABS(Q24/Q$4))
B30: Variable Costs | C30: =ABS(C25/$C$4) -> 0.82944777 | G30: =IF(G$4="","",ABS(G25/G$4)) -> 0.81339319 | H30: =IF(H$4="","",ABS(H25/H$4)) -> 0.82247534 | I30: =IF(I$4="","",ABS(I25/I$4)) -> 0.83639582 | J30: =IF(J$4="","",ABS(J25/J$4)) -> 0.84552674 | K30: =IF(K$4="","",ABS(K25/K$4)) -> 0.85534866 | L30: =IF(L$4="","",ABS(L25/L$4)) | M30: =IF(M$4="","",ABS(M25/M$4)) | N30: =IF(N$4="","",ABS(N25/N$4)) | ... Q30: =IF(Q$4="","",ABS(Q25/Q$4))
B32: Fixed Costs
B33: G&A and other Opex | C33: =AVERAGE(G33:J33) -> -1.5228888e+09 | E33: Historical Average | G33: =Data!C41 -> -1406578781 | H33: =Data!D41 -> -1519063042 | I33: =Data!E41 -> -1473368004 | J33: =Data!F41 -> -1692545246 | K33: =Data!G41 -> -1678050722 | L33: =Data!H41 | M33: =Data!I41 | N33: =Data!J41 | ... Q33: =Data!M41
B34: R&D | C34: =AVERAGE(G34:J34) -> -74312206 | E34: Historical Average | G34: =Data!C42 -> -102766675 | H34: =Data!D42 -> -100637006 | I34: =Data!E42 -> -62954899 | J34: =Data!F42 -> -30890245 | K34: =Data!G42 -> -21467092 | L34: =Data!H42 | M34: =Data!I42 | N34: =Data!J42 | ... Q34: =Data!M42
B35: Fixed Costs | C35: =C33+C34 -> -1.597201e+09 | G35: =IF(G4="","",G33+G34) -> -1509345456 | H35: =IF(H4="","",H33+H34) -> -1619700048 | I35: =IF(I4="","",I33+I34) -> -1536322903 | J35: =IF(J4="","",J33+J34) -> -1723435491 | K35: =IF(K4="","",K33+K34) -> -1699517814 | L35: =IF(L4="","",L33+L34) | M35: =IF(M4="","",M33+M34) | N35: =IF(N4="","",N33+N34) | ... Q35: =IF(Q4="","",Q33+Q34)
B37: Fixed Costs % of Sales
B38: =B33 -> G&A and other Opex | C38: =ABS(C33/$C$4) -> 0.047437317 | G38: =IF(G$4="","",ABS(G33/G$4)) -> 0.043767074 | H38: =IF(H$4="","",ABS(H33/H$4)) -> 0.044761894 | I38: =IF(I$4="","",ABS(I33/I$4)) -> 0.045797212 | J38: =IF(J$4="","",ABS(J33/J$4)) -> 0.056106214 | K38: =IF(K$4="","",ABS(K33/K$4)) -> 0.060449143 | L38: =IF(L$4="","",ABS(L33/L$4)) | M38: =IF(M$4="","",ABS(M33/M$4)) | N38: =IF(N$4="","",ABS(N33/N$4)) | ... Q38: =IF(Q$4="","",ABS(Q33/Q$4))
B39: =B34 -> R&D | C39: =ABS(C34/$C$4) -> 0.0023147926 | G39: =IF(G$4="","",ABS(G34/G$4)) -> 0.0031976856 | H39: =IF(H$4="","",ABS(H34/H$4)) -> 0.0029654484 | I39: =IF(I$4="","",ABS(I34/I$4)) -> 0.0019568491 | J39: =IF(J$4="","",ABS(J34/J$4)) -> 0.0010239813 | K39: =IF(K$4="","",ABS(K34/K$4)) -> 0.00077331828 | L39: =IF(L$4="","",ABS(L34/L$4)) | M39: =IF(M$4="","",ABS(M34/M$4)) | N39: =IF(N$4="","",ABS(N34/N$4)) | ... Q39: =IF(Q$4="","",ABS(Q34/Q$4))
B40: Fixed Costs | C40: =ABS(C35/$C$4) -> 0.049752109 | G40: =IF(G$4="","",ABS(G35/G$4)) -> 0.046964759 | H40: =IF(H$4="","",ABS(H35/H$4)) -> 0.047727343 | I40: =IF(I$4="","",ABS(I35/I$4)) -> 0.047754061 | J40: =IF(J$4="","",ABS(J35/J$4)) -> 0.057130196 | K40: =IF(K$4="","",ABS(K35/K$4)) -> 0.061222461 | L40: =IF(L$4="","",ABS(L35/L$4)) | M40: =IF(M$4="","",ABS(M35/M$4)) | N40: =IF(N$4="","",ABS(N35/N$4)) | ... Q40: =IF(Q$4="","",ABS(Q35/Q$4))
B42: Tax % of Pre-tax Profit
B43: Income Tax Rate | C43: 0.25 | E43: Use the highest past tax rate | G43: =IF(G$4="","",-G14/SUM(G8+G11,G12)) -> 0.29621489 | H43: =IF(H$4="","",-H14/SUM(H8+H11,H12)) -> 0.30730891 | I43: =IF(I$4="","",-I14/SUM(I8+I11,I12)) -> 0.31045306 | J43: =IF(J$4="","",-J14/SUM(J8+J11,J12)) -> 0.40418596 | K43: =IF(K$4="","",-K14/SUM(K8+K11,K12)) -> 0.3693039 | L43: =IF(L$4="","",-L14/SUM(L8+L11,L12)) | M43: =IF(M$4="","",-M14/SUM(M8+M11,M12)) | N43: =IF(N$4="","",-N14/SUM(N8+N11,N12)) | ... Q43: =IF(Q$4="","",-Q14/SUM(Q8+Q11,Q12))
B45: Non-operating Income | E45: Notes
B46: Interest
...

Sheet Valuation_Model
B2: No-Growth DCF Valuation | H2: Notes
B3: No-Growth DCF | C3: =scaling_factor -> 1 | E3: Special Assumption
B4: Adjusted FCFE | C4: =Normalized_FCF!C19 -> 2.878554e+09 | D4: =Reporting_currency -> CNY | E4: Terminal Growth Rate (g): | F4: =Thesis!C81 -> 0
B5: /Equity Cost of Capital | C5: =Thesis!C75 -> 0.08
B6: Stable Income Value | C6: =(C4*(1+Terminal_Growth))/(Equity_Cost-Terminal_Growth) -> 3.5981924e+10 | D6: =Reporting_currency -> CNY | E6: Conservative Valuation: Setting g=0 can be a conservative assumption to avoid overestimating the stock’s value, especially if future growth is uncertain or unreliable.
B7: - Interest-bearing Debt | C7: =BS!G31 -> 285396383 | D7: =Reporting_currency -> CNY
B8: + Non-operating Cash | C8: =BS!D66 -> 1.2808944e+10 | D8: =Reporting_currency -> CNY
B9: + Other Non-operating Assets | C9: =BS!H42 -> 2.7554116e+09 | D9: =Reporting_currency -> CNY
B10: Equity Value | C10: =C6-C7+C8+C9 -> 5.1260884e+10 | D10: =Reporting_currency -> CNY
B11: * Exchange rate | C11: =Exchange_Rate -> 1.0742247 | D11: =Thesis!C15 -> CNY/HKD
B12: Equity Value per share | C12: =(C10*scaling_factor)/Common_Shares*Exchange_Rate -> 40.364928 | D12: =Market_currency -> HKD
B14: Implied Growth Scenario Analysis
B15: FCFE Projection
B16: High Growth Period (HGP) | C16: =Scenarios!C65 -> 0.061165848
B17: High Growth Rate (HGR) | C17: =Scenarios!C64 -> 30
B18: Value Per Share | C18: =(F52-C7+C8+C9)*Exchange_Rate/Common_Shares*scaling_factor -> 67.392482 | D18: =Market_currency -> HKD
B20: Year | C20: FCFE | D20: Growth Rates | E20: Discount Factor | F20: PV of FCFE
B21: 1 | C21: =C4*(1+D21) -> 3.0546231e+09 | D21: =IF($C$17<B21,0,Valuation_Model!$C$16) -> 0.061165848 | E21: =IF($C$17<B21,0,1/(1+Equity_Cost)^B21) -> 0.92592593 | F21: =C21*E21 -> 2.8283548e+09
B22: 2 | C22: =IF(ROW()-ROW($C$21)<$C$17, $C$21*(1+D22)^(ROW()-ROW($C$21)), 0) -> 3.2414618e+09 | D22: =IF($C$17<B22,0,Valuation_Model!$C$16) -> 0.061165848 | E22: =IF($C$17<B22,0,1/(1+Equity_Cost)^B22) -> 0.85733882 | F22: =C22*E22 -> 2.779031e+09
B23: 3 | C23: =IF(ROW()-ROW($C$21)<$C$17, $C$21*(1+D23)^(ROW()-ROW($C$21)), 0) -> 3.4397285e+09 | D23: =IF($C$17<B23,0,Valuation_Model!$C$16) -> 0.061165848 | E23: =IF($C$17<B23,0,1/(1+Equity_Cost)^B23) -> 0.79383224 | F23: =C23*E23 -> 2.7305674e+09
B24: 4 | C24: =IF(ROW()-ROW($C$21)<$C$17, $C$21*(1+D24)^(ROW()-ROW($C$21)), 0) -> 3.6501224e+09 | D24: =IF($C$17<B24,0,Valuation_Model!$C$16) -> 0.061165848 | E24: =IF($C$17<B24,0,1/(1+Equity_Cost)^B24) -> 0.73502985 | F24: =C24*E24 -> 2.682949e+09
B25: 5 | C25: =IF(ROW()-ROW($C$21)<$C$17, $C$21*(1+D25)^(ROW()-ROW($C$21)), 0) -> 3.8733853e+09 | D25: =IF($C$17<B25,0,Valuation_Model!$C$16) -> 0.061165848 | E25: =IF($C$17<B25,0,1/(1+Equity_Cost)^B25) -> 0.6805832 | F25: =C25*E25 -> 2.6361609e+09
B26: 6 | C26: =IF(ROW()-ROW($C$21)<$C$17, $C$21*(1+D26)^(ROW()-ROW($C$21)), 0) -> 4.1103042e+09 | D26: =IF($C$17<B26,0,Valuation_Model!$C$16) -> 0.061165848 | E26: =IF($C$17<B26,0,1/(1+Equity_Cost)^B26) -> 0.63016963 | F26: =C26*E26 -> 2.5901888e+09
B27: 7 | C27: =IF(ROW()-ROW($C$21)<$C$17, $C$21*(1+D27)^(ROW()-ROW($C$21)), 0) -> 4.3617144e+09 | D27: =IF($C$17<B27,0,Valuation_Model!$C$16) -> 0.061165848 | E27: =IF($C$17<B27,0,1/(1+Equity_Cost)^B27) -> 0.5834904 | F27: =C27*E27 -> 2.5450185e+09
B28: 8 | C28: =IF(ROW()-ROW($C$21)<$C$17, $C$21*(1+D28)^(ROW()-ROW($C$21)), 0) -> 4.6285024e+09 | D28: =IF($C$17<B28,0,Valuation_Model!$C$16) -> 0.061165848 | E28: =IF($C$17<B28,0,1/(1+Equity_Cost)^B28) -> 0.54026888 | F28: =C28*E28 -> 2.5006358e+09
B29: 9 | C29: =IF(ROW()-ROW($C$21)<$C$17, $C$21*(1+D29)^(ROW()-ROW($C$21)), 0) -> 4.9116086e+09 | D29: =IF($C$17<B29,0,Valuation_Model!$C$16) -> 0.061165848 | E29: =IF($C$17<B29,0,1/(1+Equity_Cost)^B29) -> 0.50024897 | F29: =C29*E29 -> 2.4570271e+09
B30: 10 | C30: =IF(ROW()-ROW($C$21)<$C$17, $C$21*(1+D30)^(ROW()-ROW($C$21)), 0) -> 5.2120313e+09 | D30: =IF($C$17<B30,0,Valuation_Model!$C$16) -> 0.061165848 | E30: =IF($C$17<B30,0,1/(1+Equity_Cost)^B30) -> 0.46319349 | F30: =C30*E30 -> 2.414179e+09
B31: 11 | C31: =IF(ROW()-ROW($C$21)<$C$17, $C$21*(1+D31)^(ROW()-ROW($C$21)), 0) -> 5.5308297e+09 | D31: =IF($C$17<B31,0,Valuation_Model!$C$16) -> 0.061165848 | E31: =IF($C$17<B31,0,1/(1+Equity_Cost)^B31) -> 0.42888286 | F31: =C31*E31 -> 2.372078e+09
B32: 12 | C32: =IF(ROW()-ROW($C$21)<$C$17, $C$21*(1+D32)^(ROW()-ROW($C$21)), 0) -> 5.8691276e+09 | D32: =IF($C$17<B32,0,Valuation_Model!$C$16) -> 0.061165848 | E32: =IF($C$17<B32,0,1/(1+Equity_Cost)^B32) -> 0.39711376 | F32: =C32*E32 -> 2.3307113e+09
B33: 13 | C33: =IF(ROW()-ROW($C$21)<$C$17, $C$21*(1+D33)^(ROW()-ROW($C$21)), 0) -> 6.2281177e+09 | D33: =IF($C$17<B33,0,Valuation_Model!$C$16) -> 0.061165848 | E33: =IF($C$17<B33,0,1/(1+Equity_Cost)^B33) -> 0.36769792 | F33: =C33*E33 -> 2.290066e+09
... B50: 30 | C50: =IF(ROW()-ROW($C$21)<$C$17, $C$21*(1+D50)^(ROW()-ROW($C$21)), 0) -> 1.7087255e+10 | D50: =IF($C$17<B50,0,Valuation_Model!$C$16) -> 0.061165848 | E50: =IF($C$17<B50,0,1/(1+Equity_Cost)^B50) -> 0.099377333 | F50: =C50*E50 -> 1.6980859e+09
B51: Terminal Year | C51: =C$21*(1+Terminal_Growth)^$C$17/Equity_Cost -> 3.8182789e+10 | D51: =Terminal_Growth -> 0 | E51: =1/(1+Equity_Cost)^C17 -> 0.099377333 | F51: =C51*E51 -> 3.7945038e+09
E52: Total PV | F52: =SUM(F21:F51) -> 7.0305194e+10
B54: Sensitivity Analysis (Enterprise Value)
A55: =F52 -> 7.0305194e+10 | B55: =C78 -> 0.02 | C55: =C77 -> 0.04 | D55: =C76 -> 0.06 | E55: =C75 -> 0.08 | F55: =C74 -> 0.1
A56: 5 | B56: 3.714289e+10 | C56: 3.8338625e+10 | D56: 3.9570657e+10 | E56: 4.0840558e+10 | F56: 4.214995e+10
A57: 10 | B57: 3.8304924e+10 | C57: 4.0860751e+10 | D57: 4.367727e+10 | E57: 4.678546e+10 | F57: 5.0219726e+10
A58: 15 | B58: 3.9743264e+10 | C58: 4.4148662e+10 | D58: 4.9326074e+10 | E58: 5.5428753e+10 | F58: 6.2640009e+10
A59: 20 | B59: 4.1208701e+10 | C59: 4.7687526e+10 | D59: 5.5769824e+10 | E59: 6.5908525e+10 | F59: 7.8686872e+10
A60: 25 | B60: 4.2571639e+10 | C60: 5.1173427e+10 | D60: 6.2522678e+10 | E60: 7.7638175e+10 | F60: 9.7931585e+10
...

Sheet Scenarios
B2: Current Situation | H2: Warning: Do Not Remove this logic
B3: Selection | H3: 0 | I3: =-Market_Price -> -53.55
B4: Past Years Selected | C4: 3 | E4: Tie the business story into the three levers of value: FCFE, growth and risk. | H4: 1 | I4: =IF(ROW()-3 < $C$76, $C$77, IF(ROW()-3 = $C$76, $C$77 + $C$60, "")) -> 2.0479887
H5: 2 | I5: =IF(ROW()-3 < $C$76, $C$77, IF(ROW()-3 = $C$76, $C$77 + $C$60, "")) -> 2.0479887
B6: Latest | C6: =Valuation_Model!C3 -> 1 | E6: Prompt for fundamental Analysis | H6: 3 | I6: =IF(ROW()-3 < $C$76, $C$77, IF(ROW()-3 = $C$76, $C$77 + $C$60, "")) -> 69.442294
B7: EBIT | C7: =Normalized_FCF!G8 -> 4487792577 | D7: =Reporting_currency -> CNY | E7: ="Please develop three logical "&C18&"-year scenarios (Base Case, Pessimistic Case, Optimistic Case) and two extreme "&C46&"-year scenarios (Success Scenario, Devil’s Advocate Scenario) for "&Thesis!C5&"("&Thesis!C11&"). Each scenario should include the Compound Growth Rate, the Probability Assessment, and the Business Narrative." -> Please develop three logical 30-year scenarios (Base Case, Pessimistic Case, Optimistic Case) and two extreme 30-year scenarios (Success Scenario, Devil’s Advocate Scenario) for 青島啤酒股份(0168.HK). Each scenario should include the Compound Growth Rate, the Probability Assessment, and the Business Narrative. | H7: 4 | I7: =IF(ROW()-3 < $C$76, $C$77, IF(ROW()-3 = $C$76, $C$77 + $C$60, ""))
B8: FCFE | C8: =Normalized_FCF!G19 -> 3.1550723e+09 | D8: =Reporting_currency -> CNY | H8: 5 | I8: =IF(ROW()-3 < $C$76, $C$77, IF(ROW()-3 = $C$76, $C$77 + $C$60, ""))
B9: Normalized | C9: =Normalized_FCF!C19 -> 2.878554e+09 | D9: =Reporting_currency -> CNY | H9: 6 | I9: =IF(ROW()-3 < $C$76, $C$77, IF(ROW()-3 = $C$76, $C$77 + $C$60, ""))
H10: 7 | I10: =IF(ROW()-3 < $C$76, $C$77, IF(ROW()-3 = $C$76, $C$77 + $C$60, ""))
B11: CAGR | H11: 8 | I11: =IF(ROW()-3 < $C$76, $C$77, IF(ROW()-3 = $C$76, $C$77 + $C$60, ""))
B12: Sales | C12: =(Normalized_FCF!G4/OFFSET(Normalized_FCF!G4, 0, $C$4))^(1/$C$4) - 1 -> 0.021321348 | H12: 9 | I12: =IF(ROW()-3 < $C$76, $C$77, IF(ROW()-3 = $C$76, $C$77 + $C$60, ""))
B13: Operating EBIT | C13: =(Normalized_FCF!G8/OFFSET(Normalized_FCF!G8, 0, $C$4))^(1/$C$4) - 1 -> 0.15185943 | H13: 10 | I13: =IF(ROW()-3 < $C$76, $C$77, IF(ROW()-3 = $C$76, $C$77 + $C$60, ""))
B14: FCFE | C14: =(Normalized_FCF!G19/OFFSET(Normalized_FCF!G19, 0, $C$4))^(1/$C$4) - 1 -> 0.22851253
B16: General Scenarios
B17: Assumption | E17: Guidance Note
B18: High Growth Period (HGP) | C18: 30 | E18: Fundamental analysis and market signal analysis should be combined, with fundamental analysis given priority and market signal analysis serving as a supplement. Market signal analysis predicts a company's future trend, while fundamental analysis interprets the trend and identifies relevant fundamental factors and possibilities.
B20: Reference
B21: Market Price | C21: =Market_Price -> 53.55 | D21: =Market_currency -> HKD
B22: No Growth Value per share | C22: =Valuation_Model!C12 -> 40.364928 | D22: =Market_currency -> HKD
B24: Base | E24: Business Story
B25: High Growth Period (HGP) | C25: =C18 -> 30
B26: High Growth Rate (HGR) | C26: 0.06
B27: Value per share | C27: =Valuation_Model!E76 -> 66.581008 | D27: =Market_currency -> HKD
B28: Probabilities | C28: 0.5
B30: Pessimistic | E30: Business Story
B31: High Growth Period (HGP) | C31: =C18 -> 30
B32: High Growth Rate (HGR) | C32: 0.04
B33: Value per share | C33: =Valuation_Model!E77 -> 54.898005 | D33: =Market_currency -> HKD
B34: Probabilities | C34: 0.3
B36: Optimistic | E36: Business Story
B37: High Growth Period (HGP) | C37: =C18 -> 30
B38: High Growth Rate (HGR) | C38: 0.08
B39: Value per share | C39: =Valuation_Model!E75 -> 83.073014 | D39: =Market_currency -> HKD
B40: Probabilities | C40: =1-C28-C34 -> 0.2
B42: Expected Value = | C42: =C27*C28+C33*C34+C39*C40 -> 66.374508 | D42: =Market_currency -> HKD
B44: Extreme Scenarios
B45: Assumption
B46: High Growth Period (HGP) | C46: 30
B48: Devil's advocate | E48: Business Story
B49: High Growth Period (HGP) | C49: =C46 -> 30
...
