Workbook
Name Common_Shares: Thesis!$C$12
Name Exchange_Rate: Thesis!$C$14

Sheet Thesis
B1: Investment Thesis for | C1: =Inputs!C95 -> 六福珠宝 | D1: =Inputs!C94 -> 0590.HK
B2: Model last updated: | C2: 45643
A3: Introduction
B4: Comapny Information
B5: Comp_Type: | C5: Superior Cycl.
B6: Comp_Sector: | C6: =Inputs!C99 -> C0003
B7: Review Interval: | C7: 8
B8: Review Date: | C8: =EOMONTH(EDATE(Fin_Analysis!D9,Thesis!C7),0) -> 45626
B10: =D1&" Stock Information" -> 0590.HK Stock Information
B11: Current Price: | C11: 13.82 | D11: HKD
B12: Number of Shares: | C12: =Inputs!C100 -> 587107850
B13: Reporting Currency: | C13: =Inputs!C101 -> HKD
B14: Exchange Rate: | C14: 1 | D14: =IF(C13=Thesis!D11,Thesis!D11,C13&"/"&Thesis!D11) -> HKD
B15: Capitalization: | C15: =Thesis!C11*Thesis!C12/1000000 -> 8113.8305
A17: Stock Analysis
A19: ="1." -> 1. | B19: Normalized Income Calculation
B20: Formula:
B21: Variable Cost = COGS + Selling and Distribution Costs + Other Variable Operating Expenses
B26: Net Income = Variable Cost + Fixed Cost
A30: ="1." -> 1. | B30: Adjusted FCFE Calculation
B31: Formula:
B32: Adjusted FCFE = Net Income + D&A – Maintenance Capex ± WCInv (if material).
B34: Variables
B35: Net Income =
B38: Notes:
B39: 1. the model explicitly avoids aggressive growth assumptions and prioritizes downside protection.
B40: 2. Net borrowing is excluded (fixed at 0), and WCInv is only included if it materially distorts FCFE (>5% volatility).
B41: 3. Normalization: 5-year averages will smooth cyclicality for 590.HK.
A43: ="2." -> 2. | B43: Equity Cost of Capital (Buffett Method)
B44: Assumptions:
B45: Risk-Free Rate | C45: HK | D45: =IF(C45="CN",Dashboard!C12,IF(C45="US",Dashboard!C7,IF(C45="HK",Dashboard!D7,Dashboard!D12))) -> 0.075
B46: Base ERP | C46: Stable Business | D46: =IF(LEFT(C46,1)="S",4%,IF(LEFT(C46,1)="M",6%,8%)) -> 0.04
B48: Qualitative Adjustments (2% for each):
B49: Durable moats
B50: Weak balance sheets
B51: Poor management
B53: Formula:
B54: Equity Cost(r) = 4.5% (Risk-Free) + 3.5% (ERP) – 1% (Moat) = 7%.
A56: ="3." -> 3. | B56: No-Growth DCF Valuation
B57: Key Metrics:
...

Sheet Inputs
C1: =C102 -> 45382 | D1: =EOMONTH(EDATE(C1,-12),0) -> 45016 | E1: =EOMONTH(EDATE(D1,-12),0) -> 44651 | F1: =EOMONTH(EDATE(E1,-12),0) -> 44286 | G1: =EOMONTH(EDATE(F1,-12),0) -> 43921 | H1: =EOMONTH(EDATE(G1,-12),0) -> 43555 | I1: =EOMONTH(EDATE(H1,-12),0) -> 43190 | J1: =EOMONTH(EDATE(I1,-12),0) -> 42825 | K1: =EOMONTH(EDATE(J1,-12),0) -> 42460 | ... M1: =EOMONTH(EDATE(L1,-12),0) -> 41729
B2: Financial Statements Inputs
B3: Income Statement
B4: Sales | C4: 15325962 | D4: 11977844 | E4: 11737803 | F4: 8861335 | G4: 11233771 | H4: 15859990
B5: COGS | C5: -11151623 | D5: -8747447 | E5: -8503976 | F5: -6229020 | G5: -7910751 | H5: -11826154 | I5: 0 | J5: 0 | K5: 0 | L5: 0 | M5: 0
B6: Selling and Marketing Expenses | C6: -2043459 | D6: -1517989 | E6: -1491293 | F6: -1412494
B7: Other Variable Operating Expenses
B8: OPEX | C8: -2297566 | D8: -1867515 | E8: -1815111 | F8: -1694480 | G8: -2118252 | H8: -2416769 | I8: 0 | J8: 0 | K8: 0 | L8: 0 | M8: 0
B9: R&D
B10: Interest Expense | C10: -59596 | D10: -20763 | E10: -23097 | F10: -28849 | G10: -63075 | H10: -34253 | I10: 0 | J10: 0 | K10: 0 | L10: 0 | M10: 0
B11: Income Tax Paid
B12: Reported Net Income | C12: 1767305 | D12: 1284757 | E12: 1392364 | F12: 1017335 | G12: 866315
B13: Non-controling Interests | C13: 9467 | D13: 30 | E13: 27 | F13: -1799 | G13: -1337 | H13: -10908 | I13: 0 | J13: 0 | K13: 0 | L13: 0 | M13: 0
B15: Cash Flow Statement
B16: D&A | C16: 456554 | D16: 373191
B17: CAPX | C17: 676387 | D17: 107280 | E17: 455483 | F17: 138937
B18: WCInv | C18: 626583 | D18: 352099 | E18: 1045251 | F18: -818677
B20: Balance Sheet
B21: Total Liabilities | C21: 3990166 | D21: 2466431 | E21: 3908586 | F21: 2946772
B22: Total Equity | C22: 12863898 | D22: 12220942 | E22: 12078528 | F22: 11324224
B23: ST AR | D23: 213823 | E23: 187711 | F23: 277338
B24: ST Inventory | D24: 8852611 | E24: 8769304 | F24: 7321614
B26: Other Data
B27: Contingent Liabilities | C27: =20356+1075000 -> 1095356 | D27: =24308+1075000 -> 1099308 | E27: =32736+1075000 -> 1107736 | F27: =47325+1075000 -> 1122325
B28: Dividend per share | C28: =0.72+0.64 -> 1.36 | D28: =0.55+0.55 -> 1.1 | E28: =0.55+0.55 -> 1.1 | F28: =0.5+0.5 -> 1 | G28: =0.5+0.5 -> 1 | H28: =0.6+0.55 -> 1.15
B29: Dividend Yield | C29: =IF(C28="","",C28*Exchange_Rate/Thesis!$C$11) -> 0.098408104 | D29: =IF(D28="","",D28*Exchange_Rate/Thesis!$C$11) -> 0.07959479 | E29: =IF(E28="","",E28*Exchange_Rate/Thesis!$C$11) -> 0.07959479 | F29: =IF(F28="","",F28*Exchange_Rate/Thesis!$C$11) -> 0.0723589 | G29: =IF(G28="","",G28*Exchange_Rate/Thesis!$C$11) -> 0.0723589 | H29: =IF(H28="","",H28*Exchange_Rate/Thesis!$C$11) -> 0.083212735 | I29: =IF(I28="","",I28*Exchange_Rate/Thesis!$C$11) | J29: =IF(J28="","",J28*Exchange_Rate/Thesis!$C$11) | ... M29: =IF(M28="","",M28*Exchange_Rate/Thesis!$C$11)
B31: ="Last Balance Sheet"&IF(SUM(C32:C56)=C21+C22,"","- Error") -> Last Balance Sheet | C31: Book Figure | D31: Valued @ | E31: is_OP
B32: Cash and cash equivalents | C32: 1998219 | D32: 0.9
B33: Restricted cash | D33: 0.8
B34: ST AR | C34: 265773 | D34: =D35 -> 0.6
B35: ST FV Investments | D35: 0.6
B36: ST non-FV Investments | D36: 0.5
B37: Operating ST Financial Assets | D37: =D34 -> 0.6
B38: Prepayments or Contract Assets | C38: 366595 | D38: 0.1
B39: Inventory | C39: 9672256 | D39: =D36 -> 0.5
B40: Properties held for sale | D40: =D34 -> 0.6 | E40: N
B41: Properties under development | D41: 0.6 | E41: Y
B42: ST DTA | C42: 29465 | D42: =D32 -> 0.9
B43: Other ST Assets | D43: =D54 -> 0.05
B44: LT Depositis | D44: =D33 -> 0.8
...

Sheet Data
B1: ="("&Inputs!C103&" "&Thesis!C13&")" -> (1000 HKD) | C1: Normalized | E1: =E76 -> 45382 | F1: =EOMONTH(EDATE(E1,-12),0) -> 45016 | G1: =EOMONTH(EDATE(F1,-12),0) -> 44651 | H1: =EOMONTH(EDATE(G1,-12),0) -> 44286 | I1: =EOMONTH(EDATE(H1,-12),0) -> 43921 | J1: =EOMONTH(EDATE(I1,-12),0) -> 43555 | K1: =EOMONTH(EDATE(J1,-12),0) -> 43190 | L1: =EOMONTH(EDATE(K1,-12),0) -> 42825 | M1: =EOMONTH(EDATE(L1,-12),0) -> 42460 | ... O1: =EOMONTH(EDATE(N1,-12),0) -> 41729
B2: Financials
B3: Adjusted FCFE
B4: Sales | C4: =AVERAGE(E4:H4) -> 11975736 | E4: =IF(Inputs!C4=""," ",Inputs!C4) -> 15325962 | F4: =IF(Inputs!D4="","",Inputs!D4) -> 11977844 | G4: =IF(Inputs!E4="","",Inputs!E4) -> 11737803 | H4: =IF(Inputs!F4="","",Inputs!F4) -> 8861335 | I4: =IF(Inputs!G4="","",Inputs!G4) -> 11233771 | J4: =IF(Inputs!H4="","",Inputs!H4) -> 15859990 | K4: =IF(Inputs!I4="","",Inputs!I4) | L4: =IF(Inputs!J4="","",Inputs!J4) | M4: =IF(Inputs!K4="","",Inputs!K4) | ... O4: =IF(Inputs!M4="","",Inputs!M4)
B5: COGS | C5: =-C4*C19 -> -8652915.6 | E5: =IF(Inputs!C5="","",Inputs!C5) -> -11151623 | F5: =IF(Inputs!D5="","",Inputs!D5) -> -8747447 | G5: =IF(Inputs!E5="","",Inputs!E5) -> -8503976 | H5: =IF(Inputs!F5="","",Inputs!F5) -> -6229020 | I5: =IF(Inputs!G5="","",Inputs!G5) -> -7910751 | J5: =IF(Inputs!H5="","",Inputs!H5) -> -11826154 | K5: =IF(Inputs!I5="","",Inputs!I5) -> 0 | L5: =IF(Inputs!J5="","",Inputs!J5) -> 0 | ... O5: =IF(Inputs!M5="","",Inputs!M5) -> 0
B6: Gross Profit | C6: =C4+C5 -> 3322820.4 | E6: =IF(E4="","",E4+E5) -> 4174339 | F6: =IF(F4="","",F4+F5) -> 3230397 | G6: =IF(G4="","",G4+G5) -> 3233827 | H6: =IF(H4="","",H4+H5) -> 2632315 | I6: =IF(I4="","",I4+I5) -> 3323020 | J6: =IF(J4="","",J4+J5) -> 4033836 | K6: =IF(K4="","",K4+K5) | L6: =IF(L4="","",L4+L5) | ... O6: =IF(O4="","",O4+O5)
B7: Selling and Marketing Expenses | E7: =IF(Inputs!C6="","",Inputs!C6) -> -2043459 | F7: =IF(Inputs!D6="","",Inputs!D6) -> -1517989 | G7: =IF(Inputs!E6="","",Inputs!E6) -> -1491293 | H7: =IF(Inputs!F6="","",Inputs!F6) -> -1412494 | I7: =IF(Inputs!G6="","",Inputs!G6) | J7: =IF(Inputs!H6="","",Inputs!H6) | K7: =IF(Inputs!I6="","",Inputs!I6) | L7: =IF(Inputs!J6="","",Inputs!J6) | ... O7: =IF(Inputs!M6="","",Inputs!M6)
B8: Other Variable Operating Expenses | E8: =IF(Inputs!C7="",0,Inputs!C7) -> 0 | F8: =IF(Inputs!D7="",0,Inputs!D7) -> 0 | G8: =IF(Inputs!E7="",0,Inputs!E7) -> 0 | H8: =IF(Inputs!F7="",0,Inputs!F7) -> 0 | I8: =IF(Inputs!G7="",0,Inputs!G7) -> 0 | J8: =IF(Inputs!H7="",0,Inputs!H7) -> 0 | K8: =IF(Inputs!I7="",0,Inputs!I7) -> 0 | L8: =IF(Inputs!J7="",0,Inputs!J7) -> 0 | ... O8: =IF(Inputs!M7="",0,Inputs!M7) -> 0
B9: Contribution Margin | E9: =IF(E4="","",E6+E7+E8) -> 2130880 | F9: =IF(F4="","",F6+F7+F8) -> 1712408 | G9: =IF(G4="","",G6+G7+G8) -> 1742534 | H9: =IF(H4="","",H6+H7+H8) -> 1219821 | I9: =IF(I4="","",I6+I7+I8) -> #VALUE! | J9: =IF(J4="","",J6+J7+J8) -> #VALUE!
B10: Other Operating Expenses | E10: =IF(Inputs!C8="","",Inputs!C8-E7) -> -254107 | F10: =IF(Inputs!D8="","",Inputs!D8-F7) -> -349526 | G10: =IF(Inputs!E8="","",Inputs!E8-G7) -> -323818 | H10: =IF(Inputs!F8="","",Inputs!F8-H7) -> -281986 | I10: =IF(Inputs!G8="","",Inputs!G8-I7) -> #VALUE! | J10: =IF(Inputs!H8="","",Inputs!H8-J7) -> #VALUE! | K10: =IF(Inputs!I8="","",Inputs!I8) -> 0 | L10: =IF(Inputs!J8="","",Inputs!J8) -> 0 | M10: =IF(Inputs!K8="","",Inputs!K8) -> 0 | N10: =IF(Inputs!L8="","",Inputs!L8) -> 0 | O10: =IF(Inputs!M8="","",Inputs!M8) -> 0
B11: - R&D | E11: 0 | F11: =IF(Inputs!D9="","",Inputs!D9) | G11: =IF(Inputs!E9="","",Inputs!E9) | H11: =IF(Inputs!F9="","",Inputs!F9) | I11: =IF(Inputs!G9="","",Inputs!G9) | J11: =IF(Inputs!H9="","",Inputs!H9) | K11: =IF(Inputs!I9="","",Inputs!I9) | L11: =IF(Inputs!J9="","",Inputs!J9) | M11: =IF(Inputs!K9="","",Inputs!K9) | ... O11: =IF(Inputs!M9="","",Inputs!M9)
B12: - Pre-tax Non-controling Interests | E12: =IF(Inputs!C13="","",MAX(Inputs!C13,0)/(1-Fin_Analysis!$I$84)) -> 12622.667 | F12: =IF(Inputs!D13="","",MAX(Inputs!D13,0)/(1-Fin_Analysis!$I$84)) -> 40 | G12: =IF(Inputs!E13="","",MAX(Inputs!E13,0)/(1-Fin_Analysis!$I$84)) -> 36 | H12: =IF(Inputs!F13="","",MAX(Inputs!F13,0)/(1-Fin_Analysis!$I$84)) -> 0 | I12: =IF(Inputs!G13="","",MAX(Inputs!G13,0)/(1-Fin_Analysis!$I$84)) -> 0 | J12: =IF(Inputs!H13="","",MAX(Inputs!H13,0)/(1-Fin_Analysis!$I$84)) -> 0 | K12: =IF(Inputs!I13="","",MAX(Inputs!I13,0)/(1-Fin_Analysis!$I$84)) -> 0 | L12: =IF(Inputs!J13="","",MAX(Inputs!J13,0)/(1-Fin_Analysis!$I$84)) -> 0 | ... O12: =IF(Inputs!M13="","",MAX(Inputs!M13,0)/(1-Fin_Analysis!$I$84)) -> 0
B13: EBIT | E13: =E9+E10+E11+E12 -> 1889395.7 | F13: =IF(F4="","",F6-F10-MAX(F11,0)-MAX(F12,0)) -> 3579883 | G13: =IF(G4="","",G6-G10-MAX(G11,0)-MAX(G12,0)) -> 3557609 | H13: =IF(H4="","",H6-H10-MAX(H11,0)-MAX(H12,0)) -> 2914301 | I13: =IF(I4="","",I6-I10-MAX(I11,0)-MAX(I12,0)) -> #VALUE! | J13: =IF(J4="","",J6-J10-MAX(J11,0)-MAX(J12,0)) -> #VALUE! | K13: =IF(K4="","",K6-K10-MAX(K11,0)-MAX(K12,0)) | L13: =IF(L4="","",L6-L10-MAX(L11,0)-MAX(L12,0)) | M13: =IF(M4="","",M6-M10-MAX(M11,0)-MAX(M12,0)) | ... O13: =IF(O4="","",O6-O10-MAX(O11,0)-MAX(O12,0))
B14: Non-Operating Net Income | E14: =IF(E15="","",E15-E13) -> -122090.67 | F14: =IF(F15="","",F15-F13) -> -2295126 | G14: =IF(G15="","",G15-G13) -> -2165245 | H14: =IF(H15="","",H15-H13) -> -1896966 | I14: =IF(I15="","",I15-I13) -> #VALUE! | J14: =IF(J15="","",J15-J13) | K14: =IF(K15="","",K15-K13) | L14: =IF(L15="","",L15-L13) | ... O14: =IF(O15="","",O15-O13)
B15: Reported Net Income | E15: =IF(Inputs!C12="","",Inputs!C12) -> 1767305 | F15: =IF(Inputs!D12="","",Inputs!D12) -> 1284757 | G15: =IF(Inputs!E12="","",Inputs!E12) -> 1392364 | H15: =IF(Inputs!F12="","",Inputs!F12) -> 1017335 | I15: =IF(Inputs!G12="","",Inputs!G12) -> 866315 | J15: =IF(Inputs!H12="","",Inputs!H12) | K15: =IF(Inputs!I12="","",Inputs!I12) | L15: =IF(Inputs!J12="","",Inputs!J12) | ... O15: =IF(Inputs!M12="","",Inputs!M12)
B16: - ΔWC | E16: =IF(Inputs!C18="","",Inputs!C18) -> 626583 | F16: =IF(Inputs!D18="","",Inputs!D18) -> 352099 | G16: =IF(Inputs!E18="","",Inputs!E18) -> 1045251 | H16: =IF(Inputs!F18="","",Inputs!F18) -> -818677 | I16: =IF(Inputs!G18="","",Inputs!G18) | J16: =IF(Inputs!H18="","",Inputs!H18) | K16: =IF(Inputs!I18="","",Inputs!I18) | L16: =IF(Inputs!J18="","",Inputs!J18) | ... O16: =IF(Inputs!M18="","",Inputs!M18)
B18: % Sales
B19: COGS | C19: =AVERAGE(E19:J19) -> 0.72253727 | E19: =IF(E4="","",-E5/E4) -> 0.72762956 | F19: =IF(F4="","",-F5/F4) -> 0.7303023 | G19: =IF(G4="","",-G5/G4) -> 0.72449469 | H19: =IF(H4="","",-H5/H4) -> 0.70294374 | I19: =IF(I4="","",-I5/I4) -> 0.70419372 | J19: =IF(J4="","",-J5/J4) -> 0.74565961 | K19: =IF(K4="","",-K5/K4) | L19: =IF(L4="","",-L5/L4) | ... O19: =IF(O4="","",-O5/O4)
B20: Gross Profit | C20: =C6/C4 -> 0.27746273 | E20: =IF(E4="","",E6/E4) -> 0.27237044 | F20: =IF(F4="","",F6/F4) -> 0.2696977 | G20: =IF(G4="","",G6/G4) -> 0.27550531 | H20: =IF(H4="","",H6/H4) -> 0.29705626 | I20: =IF(I4="","",I6/I4) -> 0.29580628 | J20: =IF(J4="","",J6/J4) -> 0.25434039 | K20: =IF(K4="","",K6/K4) | L20: =IF(L4="","",L6/L4) | ... O20: =IF(O4="","",O6/O4)
B21: Selling and Marketing Expenses
B22: Other Variable Operating Expenses
B23: Contribution Margin | E23: =E9/E4 -> 0.13903728 | F23: =F9/F4 -> 0.14296463 | G23: =G9/G4 -> 0.14845487 | H23: =H9/H4 -> 0.13765657 | I23: =I9/I4 -> #VALUE! | J23: =J9/J4 -> #VALUE!
B24: Other Operating Expenses | E24: =IF(E4="","",(-(E10-E21-E22)/E4)) -> 0.016580166 | F24: =IF(F4="","",(-(F10-F21-F22)/F4)) -> 0.029181045 | G24: =IF(G4="","",(-(G10-G21-G22)/G4)) -> 0.027587616 | H24: =IF(H4="","",(-(H10-H21-H22)/H4)) -> 0.031822067 | I24: =IF(I4="","",(-(I10-I21-I22)/I4)) -> #VALUE! | J24: =IF(J4="","",(-(J10-J21-J22)/J4)) -> #VALUE! | K24: =IF(K4="","",(-(K10-K21-K22)/K4)) | L24: =IF(L4="","",(-(L10-L21-L22)/L4)) | ... O24: =IF(O4="","",(-(O10-O21-O22)/O4))
B25: R&D | E25: =IF(E4="","",MAX(E11,0)/E4) -> 0 | F25: =IF(F4="","",MAX(F11,0)/F4) -> 0 | G25: =IF(G4="","",MAX(G11,0)/G4) -> 0 | H25: =IF(H4="","",MAX(H11,0)/H4) -> 0 | I25: =IF(I4="","",MAX(I11,0)/I4) -> 0 | J25: =IF(J4="","",MAX(J11,0)/J4) -> 0 | K25: =IF(K4="","",MAX(K11,0)/K4) | L25: =IF(L4="","",MAX(L11,0)/L4) | ... O25: =IF(O4="","",MAX(O11,0)/O4)
B26: EBIT Margin | E26: =E13/E4 -> 0.12328072 | F26: =F13/F4 -> 0.29887541 | G26: =G13/G4 -> 0.30308985 | H26: =H13/H4 -> 0.32887832 | I26: =I13/I4 -> #VALUE! | J26: =J13/J4 -> #VALUE!
B27: Interest/Sales | E27: =IF(E4="","",MAX(E32,0)/E4) -> 0 | F27: =IF(F4="","",MAX(F32,0)/F4) -> 0 | G27: =IF(G4="","",MAX(G32,0)/G4) -> 0 | H27: =IF(H4="","",MAX(H32,0)/H4) -> 0 | I27: =IF(I4="","",MAX(I32,0)/I4) -> 0 | J27: =IF(J4="","",MAX(J32,0)/J4) -> 0 | K27: =IF(K4="","",MAX(K32,0)/K4) | L27: =IF(L4="","",MAX(L32,0)/L4) | ... O27: =IF(O4="","",MAX(O32,0)/O4)
B28: EBT Margin
B29: WCInv | E29: =IF(E4="","",MAX(E16,0)/E4) -> 0.040883763 | F29: =IF(F4="","",MAX(F16,0)/F4) -> 0.029395858 | G29: =IF(G4="","",MAX(G16,0)/G4) -> 0.08904997 | H29: =IF(H4="","",MAX(H16,0)/H4) -> 0 | I29: =IF(I4="","",MAX(I16,0)/I4) -> 0 | J29: =IF(J4="","",MAX(J16,0)/J4) -> 0 | K29: =IF(K4="","",MAX(K16,0)/K4) | L29: =IF(L4="","",MAX(L16,0)/L4) | ... O29: =IF(O4="","",MAX(O16,0)/O4)
B30: (CAPX-D&A)/Sales | E30: =IF(E4="","",ABS(MAX(E34,0)-MAX(E33,0))/E4) -> 0.011995462 | F30: =IF(F4="","",ABS(MAX(F34,0)-MAX(F33,0))/F4) -> 0.024948814 | G30: =IF(G4="","",ABS(MAX(G34,0)-MAX(G33,0))/G4) -> 0.00079989415 | H30: =IF(H4="","",ABS(MAX(H34,0)-MAX(H33,0))/H4) -> 0.045986637 | I30: =IF(I4="","",ABS(MAX(I34,0)-MAX(I33,0))/I4) -> 0.054955455 | J30: =IF(J4="","",ABS(MAX(J34,0)-MAX(J33,0))/J4) -> 0 | K30: =IF(K4="","",ABS(MAX(K34,0)-MAX(K33,0))/K4) | L30: =IF(L4="","",ABS(MAX(L34,0)-MAX(L33,0))/L4) | ... O30: =IF(O4="","",ABS(MAX(O34,0)-MAX(O33,0))/O4)
B31: Pre-tax Minority Interests | E31: =IF(E4="","",MAX(E12,0)/E4) -> 0.00082361333 | F31: =IF(F4="","",MAX(F12,0)/F4) -> 3.3394992e-06 | G31: =IF(G4="","",MAX(G12,0)/G4) -> 3.0670135e-06 | H31: =IF(H4="","",MAX(H12,0)/H4) -> 0 | I31: =IF(I4="","",MAX(I12,0)/I4) -> 0 | J31: =IF(J4="","",MAX(J12,0)/J4) -> 0 | K31: =IF(K4="","",MAX(K12,0)/K4) | L31: =IF(L4="","",MAX(L12,0)/L4) | ... O31: =IF(O4="","",MAX(O12,0)/O4)
B32: - Interest Expense | E32: =IF(Inputs!C10="","",Inputs!C10) -> -59596 | F32: =IF(Inputs!D10="","",Inputs!D10) -> -20763 | G32: =IF(Inputs!E10="","",Inputs!E10) -> -23097 | H32: =IF(Inputs!F10="","",Inputs!F10) -> -28849 | I32: =IF(Inputs!G10="","",Inputs!G10) -> -63075 | J32: =IF(Inputs!H10="","",Inputs!H10) -> -34253 | K32: =IF(Inputs!I10="","",Inputs!I10) -> 0 | L32: =IF(Inputs!J10="","",Inputs!J10) -> 0 | ... O32: =IF(Inputs!M10="","",Inputs!M10) -> 0
B33: + D&A | E33: 492545 | F33: 406113 | G33: 464872 | H33: 546440 | I33: 617357 | K33: =IF(Inputs!I16="","",Inputs!I16) | L33: =IF(Inputs!J16="","",Inputs!J16) | M33: =IF(Inputs!K16="","",Inputs!K16) | N33: =IF(Inputs!L16="","",Inputs!L16) | O33: =IF(Inputs!M16="","",Inputs!M16)
B34: - CAPX | E34: =IF(Inputs!C17="","",Inputs!C17) -> 676387 | F34: =IF(Inputs!D17="","",Inputs!D17) -> 107280 | G34: =IF(Inputs!E17="","",Inputs!E17) -> 455483 | H34: =IF(Inputs!F17="","",Inputs!F17) -> 138937 | I34: =IF(Inputs!G17="","",Inputs!G17) | J34: =IF(Inputs!H17="","",Inputs!H17) | K34: =IF(Inputs!I17="","",Inputs!I17) | L34: =IF(Inputs!J17="","",Inputs!J17) | ... O34: =IF(Inputs!M17="","",Inputs!M17)
B35: Est. Pre-tax FCF | E35: =IF(E4="","",E13-MAX(E16,0)-MAX(E32,0)-ABS(MAX(E34,0)-MAX(E33,0))) -> 1078970.7 | F35: =IF(F4="","",F13-MAX(F16,0)-MAX(F32,0)-ABS(MAX(F34,0)-MAX(F33,0))) -> 2928951 | G35: =IF(G4="","",G13-MAX(G16,0)-MAX(G32,0)-ABS(MAX(G34,0)-MAX(G33,0))) -> 2502969 | H35: =IF(H4="","",H13-MAX(H16,0)-MAX(H32,0)-ABS(MAX(H34,0)-MAX(H33,0))) -> 2506798 | I35: =IF(I4="","",I13-MAX(I16,0)-MAX(I32,0)-ABS(MAX(I34,0)-MAX(I33,0))) -> #VALUE! | J35: =IF(J4="","",J13-MAX(J16,0)-MAX(J32,0)-ABS(MAX(J34,0)-MAX(J33,0))) -> #VALUE! | K35: =IF(K4="","",K13-MAX(K16,0)-MAX(K32,0)-ABS(MAX(K34,0)-MAX(K33,0))) | L35: =IF(L4="","",L13-MAX(L16,0)-MAX(L32,0)-ABS(MAX(L34,0)-MAX(L33,0))) | ... O35: =IF(O4="","",O13-MAX(O16,0)-MAX(O32,0)-ABS(MAX(O34,0)-MAX(O33,0)))
B36: After-tax Profit Margin | E36: =IF(E4="","",E37/E4) -> 0.052801123 | F36: =IF(F4="","",F37/F4) -> 0.18339805 | G36: =IF(G4="","",G37/G4) -> 0.15992999 | H36: =IF(H4="","",H37/H4) -> 0.21216876 | I36: =IF(I4="","",I37/I4) -> #VALUE! | J36: =IF(J4="","",J37/J4) -> #VALUE! | K36: =IF(K4="","",K37/K4) | L36: =IF(L4="","",L37/L4) | ... O36: =IF(O4="","",O37/O4)
B37: Est. After-tax FCF | E37: =IF(E4="","",E35*(1-Fin_Analysis!$I$84)) -> 809228 | F37: =IF(F4="","",F35*(1-Fin_Analysis!$I$84)) -> 2196713.2 | G37: =IF(G4="","",G35*(1-Fin_Analysis!$I$84)) -> 1877226.8 | H37: =IF(H4="","",H35*(1-Fin_Analysis!$I$84)) -> 1880098.5 | I37: =IF(I4="","",I35*(1-Fin_Analysis!$I$84)) -> #VALUE! | J37: =IF(J4="","",J35*(1-Fin_Analysis!$I$84)) -> #VALUE! | K37: =IF(K4="","",K35*(1-Fin_Analysis!$I$84)) | L37: =IF(L4="","",L35*(1-Fin_Analysis!$I$84)) | ... O37: =IF(O4="","",O35*(1-Fin_Analysis!$I$84))
B38: After-tax Profit Growth | E38: =IF(F37="","",IF(ABS(E37+F37)=ABS(E37)+ABS(F37),IF(E37<0,-1,1)*(E37-F37)/F37,"Turn")) -> -0.63161874 | F38: =IF(G37="","",IF(ABS(F37+G37)=ABS(F37)+ABS(G37),IF(F37<0,-1,1)*(F37-G37)/G37,"Turn")) -> 0.17019068 | G38: =IF(H37="","",IF(ABS(G37+H37)=ABS(G37)+ABS(H37),IF(G37<0,-1,1)*(G37-H37)/H37,"Turn")) -> -0.0015274466 | H38: =IF(I37="","",IF(ABS(H37+I37)=ABS(H37)+ABS(I37),IF(H37<0,-1,1)*(H37-I37)/I37,"Turn")) -> #VALUE! | I38: =IF(J37="","",IF(ABS(I37+J37)=ABS(I37)+ABS(J37),IF(I37<0,-1,1)*(I37-J37)/J37,"Turn")) -> #VALUE! | J38: =IF(K37="","",IF(ABS(J37+K37)=ABS(J37)+ABS(K37),IF(J37<0,-1,1)*(J37-K37)/K37,"Turn")) | K38: =IF(L37="","",IF(ABS(K37+L37)=ABS(K37)+ABS(L37),IF(K37<0,-1,1)*(K37-L37)/L37,"Turn")) | L38: =IF(M37="","",IF(ABS(L37+M37)=ABS(L37)+ABS(M37),IF(L37<0,-1,1)*(L37-M37)/M37,"Turn")) | ... N38: =IF(O37="","",IF(ABS(N37+O37)=ABS(N37)+ABS(O37),IF(N37<0,-1,1)*(N37-O37)/O37,"Turn")) | O38: =IF(#REF!="","",IF(ABS(O37+#REF!)=ABS(O37)+ABS(#REF!),IF(O37<0,-1,1)*(O37-#REF!)/#REF!,"Turn")) -> #REF!
B40: % Sales
B41: EBIT/Sales | E41: =IF(E13="","",E13/E4) -> 0.12328072 | F41: =IF(F13="","",F13/F4) -> 0.29887541 | G41: =IF(G13="","",G13/G4) -> 0.30308985 | H41: =IF(H13="","",H13/H4) -> 0.32887832 | I41: =IF(I13="","",I13/I4) -> #VALUE! | J41: =IF(J13="","",J13/J4) -> #VALUE! | K41: =IF(K13="","",K13/K4) | L41: =IF(L13="","",L13/L4) | ... O41: =IF(O13="","",O13/O4)
B42: D&A/Sales | E42: =IF(OR(E4="",E33=""),"",E33/E4) -> 0.03213795 | F42: =IF(OR(F4="",F33=""),"",F33/F4) -> 0.033905351 | G42: =IF(OR(G4="",G33=""),"",G33/G4) -> 0.039604686 | H42: =IF(OR(H4="",H33=""),"",H33/H4) -> 0.061665652 | I42: =IF(OR(I4="",I33=""),"",I33/I4) -> 0.054955455 | J42: =IF(OR(J4="",J33=""),"",J33/J4) | K42: =IF(OR(K4="",K33=""),"",K33/K4) | L42: =IF(OR(L4="",L33=""),"",L33/L4) | ... O42: =IF(OR(O4="",O33=""),"",O33/O4)
...

Sheet Dashboard
B2: Company Info: | G2: =IF(Inputs!C107="","",Inputs!C107) -> HOLD
B4: Market Yields | F4: Notes
B5: US Riskfree | C5: 0.042 | F5: https://fred.stlouisfed.org/series/DGS10
B6: US BBB Bond yield | C6: 0.0523 | D6: HK | F6: https://fred.stlouisfed.org/series/BAMLC0A4CBBBEY
B7: Discount Rate (US) | C7: 0.07 | D7: 0.075
B9: CN Riskfree | C9: 0.0181 | F9: https://tradingeconomics.com/china/government-bond-yield
B10: CN Onshore BBB- Bond yield | C10: 0.065 | F10: https://iftp.chinamoney.com.cn/chinese/scsjzqxx/
B11: CN Offshore BBB- Bond yield | C11: 0.16 | D11: =Inputs!C105 -> HK | F11: https://yield.chinabond.com.cn/cbweb-mn/yield_main?locale=en_US
B12: Discount Rate (CN) | C12: 0.08
B14: ROE & Cost Structure | F14: Target
B15: EBIT ROE | C15: =C16*C17*C18 -> 0.14687583 | F15: Target Return | G15: 0.15 | H15: 4
B16: EBIT Margin | C16: =Data!E41 -> 0.12328072
B17: Asset Turnover Ratio | C17: =Data!E63 -> 0.90933332 | F17: Price Indicators
B18: Leverage Ratio | C18: =1/Data!E64 -> 1.3101833 | F18: PB Ratio | G18: =Thesis!C11/(Data!E55*Data!E77/Common_Shares*Exchange_Rate) -> 0.63074431
B19: Interest Expense | C19: =Fin_Analysis!I81 -> -0.003888565 | F19: Normalized PE Ratio | G19: =Thesis!C11/(Fin_Analysis!H86*Thesis!C14) -> 0.51253012
B20: Normalized ΔWC | C20: =Fin_Analysis!I80 -> 0.025 | F20: Normalized Payout Ratio | G20: =Fin_Analysis!I88 -> 0.040794727
B21: Normalized CAPX-D&A | C21: =Fin_Analysis!I80+Fin_Analysis!I82 -> 0.035 | F21: Normalized D/P | G21: =Fin_Analysis!H88*Exchange_Rate/Thesis!C11 -> 0.07959479
B23: Valuation Output: | C23: Lower | D23: Upper | F23: Mid | G23: Base Case Valuation
B24: Value Range | C24: =IF(Fin_Analysis!C117="Profit",Fin_Analysis!D109,IF(Fin_Analysis!C117="Dividend",Fin_Analysis!D112,Fin_Analysis!D115)) -> 13927.52 | D24: =G24*(1+G15) -> 32020.428 | F24: =IF(Fin_Analysis!C117="Profit",Fin_Analysis!F109,IF(Fin_Analysis!C117="Dividend",Fin_Analysis!F112,Fin_Analysis!F115)) -> 17593.959 | G24: =IF(Fin_Analysis!C117="Profit",Fin_Analysis!I109,IF(Fin_Analysis!C117="Dividend",Fin_Analysis!I112,Fin_Analysis!I115)) -> 27843.851
B26: Earnings Power Checklist
B27: Present
B28: 1. Consumer monopoly? | C28: =Inputs!C85 -> Strongly agree
B29: 2. Conservatively financed? | C29: =IF(AND(OR(Fin_Analysis!I26<0.8,Fin_Analysis!I46<0.6),Data!E68<0.8),"Strongly disagree", IF(AND(OR(Fin_Analysis!I26<1,Fin_Analysis!I46<0.8),Data!E68<1),"unclear", IF(AND(OR(Fin_Analysis!I26<1.4,Fin_Analysis!I46<1.2),Data!E68<1.4),"agree","Strongly agree"))) -> #REF!
B30: Market Yields
B31: 3. Upward earnings trend? | C31: =Inputs!C86 -> unclear
B32: 4. Stable margin and ROE? | C32: =Inputs!C87 -> agree
B33: Future
B34: 5. Can earnings be sustained? | C34: =Inputs!C88 -> agree
B35: 6. No big MCX-D&A required? | C35: =Inputs!C89 -> Strongly agree
B37: Consumer Monopoly Test
B38: If you had access to billions of dollars and your pick of the top fifty managers in the country, could you start a business and successfully compete with the business in question? | C38: =Inputs!C90 -> Consumer Monopoly

Sheet Fin_Analysis
B2: Asset Model Output | K2: Note
B3: Total Equity per books = | D3: =Inputs!C22 -> 12863898 | E3: =IF((C49-I49)=D3,"", "Error!") | H3: Common Equity = | I3: =D3-D4 -> 12890860
B4: Non-common Interest = | D4: =Inputs!C70 -> -26962
E5: Discount | H5: Book Current Ratio | I5: =C28/I28 -> 3.5066755
B6: ="Adj. Net Asset in "&Thesis!C13 -> Adj. Net Asset in HKD | D6: =(E49-I49-E53) -> 3511699.1 | E6: =1-D6/D3 -> 0.72701128 | H6: Book Quick Ratio | I6: =(C24+C25)/I28 -> 0.74800394
B7: ="Adj. Net Asset per Shares in "&Thesis!D11 -> Adj. Net Asset per Shares in HKD | D7: =MAX((D6*Exchange_Rate*Data!E77)/Common_Shares, 0) -> 5.9813526 | E7: =Thesis!D11 -> HKD | H7: Book Cash Ratio | I7: =C24/I28 -> 0.64376314
B9: Most Recent Quarter Inputs | D9: =Inputs!C104 -> 45382 | E9: =IF(MONTH(D9)=MONTH(Data!E76),"FY","Quarter") -> FY
B10: Assets | C10: Book Figure | D10: Valued @ | E10: Ajusted Valuation | F10: is_OP | H10: Liabilities | I10: Book Figure
B11: Cash and cash equivalents | C11: =Inputs!C32 -> 1998219 | D11: =Inputs!D32 -> 0.9 | E11: =C11*D11 -> 1798397.1 | H11: ST Borrowing | I11: =Inputs!C57 -> 1427805
B12: Restricted cash | C12: =Inputs!C33 -> 0 | D12: =Inputs!D33 -> 0.8 | E12: =C12*D12 -> 0 | H12: ST Lease liabilities | I12: =Inputs!C58 -> 287697
B13: ST AR | C13: =Inputs!C34 -> 265773 | D13: =Inputs!D34 -> 0.6 | E13: =C13*D13 -> 159463.8 | H13: ST SH Loan | I13: =Inputs!C59 -> 0
B14: ST FV Investments | C14: =Inputs!C35 -> 0 | D14: =Inputs!D35 -> 0.6 | E14: =C14*D14 -> 0 | H14: ST Financial Liabilities | I14: =Inputs!C60 -> 0
B15: ST non-FV Investments | C15: =Inputs!C36 -> 0 | D15: =Inputs!D36 -> 0.5 | E15: =C15*D15 -> 0 | H15: ST Debt | I15: =SUM(I11:I14) -> 1715502
B16: Operating ST Financial Assets | C16: =Inputs!C37 -> 0 | D16: =Inputs!D37 -> 0.6 | E16: =C16*D16 -> 0
B17: Prepayments and Contract Assets | C17: =Inputs!C38 -> 366595 | D17: =Inputs!D38 -> 0.1 | E17: =C17*D17 -> 36659.5
B18: Inventory | C18: =Inputs!C39 -> 9672256 | D18: =Inputs!D39 -> 0.5 | E18: =C18*D18 -> 4836128
B19: Properties held for sale | C19: =Inputs!C40 -> 0 | D19: =Inputs!D40 -> 0.6 | E19: =C19*D19 -> 0 | F19: =Inputs!E40 -> N | G19: =IF(F19="Y",0,1) -> 1
B20: Properties under development | C20: =Inputs!C41 -> 0 | D20: =Inputs!D41 -> 0.6 | E20: =C20*D20 -> 0 | F20: =Inputs!E41 -> Y | G20: =IF(F20="Y",0,1) -> 0
B21: ST DTA | C21: =Inputs!C42 -> 29465 | D21: =Inputs!D42 -> 0.9 | E21: =C21*D21 -> 26518.5
B22: Other ST Assets | C22: =Inputs!C43 -> 0 | D22: =Inputs!D43 -> 0.05 | E22: =C22*D22 -> 0 | H22: Other ST liabilities | I22: =I28-SUM(I11:I14) -> 1801307
F23: %
B24: ST Core-Monetary Asset | C24: =SUM(C11:C14) -> 2263992 | D24: =IF(E24=0,0,E24/C24) -> 0.86478261 | E24: =SUM(E11:E14) -> 1957860.9 | F24: =E24/$E$28 -> 0.28552038
B25: ST Noncore-Monetary Asset | C25: =SUM(C15:C17) -> 366595 | D25: =IF(E25=0,0,E25/C25) -> 0.1 | E25: =SUM(E15:E17) -> 36659.5 | F25: =E25/$E$28 -> 0.0053461583 | H25: ST Current Ratio | I25: =E28/I28 -> 1.9498264
B26: ST Tangible Assets | C26: =C18+C19+C20 -> 9672256 | D26: =IF(E26=0,0,E26/C26) -> 0.5 | E26: =E18+E19+E20 -> 4836128 | F26: =E26/$E$28 -> 0.70526619 | H26: ST Cash-debt Ratio | I26: =E24/($I$28-I22) -> 1.1412758 | J26: =IF(I26<1,"Liquidity Problem!","")
B27: ST Non-tangible Assets | C27: =C21+C22 -> 29465 | D27: =IF(E27=0,0,E27/C27) -> 0.9 | E27: =E21+E22 -> 26518.5 | F27: =E27/$E$28 -> 0.0038672677 | H27: ST Quick Ratio | I27: =(E25+E24)/$I$28 -> 0.56713924 | J27: =IF(OR(I27<0.75,C28<I28),"Liquidity Issue!","") -> Liquidity Issue!
B28: Current Assets | C28: =SUM(C11:C22) -> 12332308 | D28: =E28/C28 -> 0.55603273 | E28: =SUM(E24:E27) -> 6857166.9 | H28: Current Liabilities | I28: =Inputs!C61 -> 3516809 | J28: =IF(J26="",1,0)+IF(J27="",1,0)+IF(J46="",1,0)+IF(J47="",1,0) -> 2
F29: is_OP
B30: LT Depositis | C30: =Inputs!C44 -> 0 | D30: =Inputs!D44 -> 0.8 | E30: 0 | H30: LT Borrowing | I30: =Inputs!C62 -> 0
B31: LT FV Securities | C31: =Inputs!C45 -> 0 | D31: =Inputs!D45 -> 0.6 | E31: =C31*D31 -> 0 | H31: LT Lease liabilities | I31: =Inputs!C63 -> 319420
B32: LT non-FV Securities | C32: =Inputs!C46 -> 0 | D32: =Inputs!D46 -> 0.5 | E32: =C32*D32 -> 0 | H32: LT SH Loan | I32: =Inputs!C64 -> 0
B33: Operating LT Financial Assets | C33: =Inputs!C47 -> 0 | D33: =Inputs!D47 -> 0.5 | E33: =C33*D33 -> 0 | G33: =IF(F33="Y",0,1) -> 1 | H33: LT Financial Liabilities | I33: =Inputs!C65 -> 0
B34: LT AR | C34: =Inputs!C48 -> 103050 | D34: =Inputs!D48 -> 0.4 | E34: =C34*D34 -> 41220 | H34: LT Debt | I34: =SUM(I30:I33) -> 319420
B35: Investments in JV or associate | C35: =Inputs!C49 -> 0 | D35: =Inputs!D49 -> 0.1 | E35: =C35*D35 -> 0 | F35: =Inputs!E49 -> N | G35: =IF(F35="Y",0,1) -> 1
B36: Investment property | C36: =Inputs!C50 -> 925726 | D36: =Inputs!D50 -> 0.2 | E36: =C36*D36 -> 185145.2 | F36: =Inputs!E50 -> N | G36: =IF(F36="Y",0,1) -> 1
B37: Properties under development | C37: =Inputs!C51 -> 0 | D37: =Inputs!D51 -> 0.1 | E37: =C37*D37 -> 0 | F37: =Inputs!E51 -> Y | G37: =IF(F37="Y",0,1) -> 0
B38: PP&E & Right of Use Assets | C38: =Inputs!C52 -> 2522337 | D38: =Inputs!D52 -> 0.1 | E38: =C38*D38 -> 252233.7
B39: Biological assets | C39: =Inputs!C53 -> 0 | D39: =Inputs!D53 -> 0.05 | E39: =C39*D39 -> 0
B40: Intangible assets | C40: =Inputs!C54 -> 538321 | D40: =Inputs!D54 -> 0.05 | E40: =C40*D40 -> 26916.05
B41: LT DTA | C41: =Inputs!C55 -> 154648 | D41: =Inputs!D55 -> 0.9 | E41: =C41*D41 -> 139183.2
B42: Other assets & Goodwill | C42: =Inputs!C56 -> 277674 | D42: =Inputs!D56 -> 0 | E42: =C42*D42 -> 0 | H42: Other LT liabilities | I42: =I48-SUM(I30:I33) -> 153937
...
