Workbook
Name Common_Shares: Thesis!$C$9
Name dividend_tax_rate: Normalized_FCF!$C$91
Name Equity_Cost: Thesis!$C$101
Name Exchange_Rate: Thesis!$E$16
Name FV_adjustments: DCF!$F$7
Name Holding_Period: Thesis!$E$21
Name Market_currency: Thesis!$C$7
Name Market_Price: Thesis!$C$8
Name Reporting_currency: Thesis!$E$17
Name scaling_factor: Data!$C$3
Name Terminal_Growth: Thesis!$C$17

Sheet Thesis
A2: Executive Summary
E3: Last Updated: | F3: 45930
B4: Company: | C4: 首钢资源 | E4: Portfolio: | F4: INT
B5: Symbol: | C5: 0639.HK | E5: Selected: | F5: Y
B6: Comp_Sector: | C6: MAT_01
B7: Market Currency: | C7: HKD
B8: Market Price: | C8: 3.16
B9: Number of Shares: | C9: 5091065770
B10: Market Capitalization: | C10: =Thesis!C8*Common_Shares/1000000 -> 16087.768 | D10: Implied Annual Return: | E10: =Scenarios!F34 -> 0.17337144
B12: Guidance Note: This model evaluates the company using a structured investment process to determine its intrinsic value and target prices. It focuses on sustainable FCF capacity, adjusts for financial structure, incorporates growth scenarios, and calculates expected returns based on the derived intrinsic value.
B14: =Scenarios!B39&" Valuation Conclusion" -> 1-stage DCF Valuation Conclusion
B15: Business Model Risk Premium: | C15: N | D15: Forex Symbol: | E15: =IF(E17=C7,C7,E17&"/"&C7) -> HKD
B16: Management Risk Premium: | C16: N | D16: Exchange Rate: | E16: 1
B17: Terminal Growth Rate (g) | C17: 0 | D17: Reporting Currency: | E17: HKD
B18: ="Expected Equity Value ("&C7&") :" -> Expected Equity Value (HKD) : | C18: =C125 -> 4.1464286 | D18: Report Interval: | E18: 6
B19: Growth Classification: | C19: =IF(Scenarios!C50="Y",Scenarios!B50,"")&IF(Scenarios!C51="Y",Scenarios!B51,"")&IF(Scenarios!C52="Y",Scenarios!B52,"")&" "&IF(Scenarios!C53="Y",Scenarios!B53,"") -> Negative Growth | D19: Update Required After: | E19: =EOMONTH(EDATE(BS!C1,E18+2),0) -> 46081
B21: Price Targets | C21: =C138&" ("&Market_currency&")" -> (HKD) | D21: Holding Period | E21: 3
B22: Target Price | C22: =E140 -> 2.4048565 | D22: @Target return | E22: 0.29465259
B23: Entry Price | C23: =E141 -> 2.9631301 | D23: @Entry yield | E23: 0.20075184
B24: Exit Price | C24: =E144 -> 3.6233986 | D24: @Benchmark yield | E24: 0.1174
B25: Sell Price | C25: =E145 -> 4.0664479 | D25: @Base equity cost | E25: 0.0725
A27: Step 1: Establishing the Company’s Sustainable Earning Power (Calculating Normalized FCFE)
B29: Goal: To quantify the underlying FCFE the business consistently generates, stripping away temporary fluctuations or accounting choices.
B30: FCFE = (Normalized Operating EBIT + Depreciation & Amortization – Capital Expenditures) + Stable Non-Operating EBIT + Net Interest Income – Taxes – NCI’s Share of Profits – Working Capital Investment
B32: Key Components | C32: =scaling_factor -> 1000
B33: • Normalized Operating EBIT: Earnings before interest and taxes from core business operations, adjusted to remove one-time or irregular items for a sustainable earnings base.
B34: Normalized Operating EBIT = | C34: =Normalized_FCF!C8 -> 1900909.5 | D34: =Reporting_currency -> HKD
B36: • Depreciation & Amortization (D&A): Non-cash expenses added back to reflect cash generated from operations. • Capital Expenditures (Capex): Cash outflows required to maintain or expand operational assets
B37: D&A = | C37: =Normalized_FCF!C15 -> 0 | D37: =Reporting_currency -> HKD
B38: Capex = | C38: =Normalized_FCF!C16 -> 0 | D38: =Reporting_currency -> HKD
B40: • Stable Non-Operating EBIT: Consistent earnings from non-core assets, such as fixed-income investments, dividend-paying stocks, or rental properties.
B41: Stable Non-Operating EBIT = | C41: =Normalized_FCF!C9 -> 0 | D41: =Reporting_currency -> HKD
B43: • Net Interest Income: Interest income minus interest expense
B44: Operating Interest Income = | C44: =Normalized_FCF!C46 -> 12533.131 | D44: =Reporting_currency -> HKD
B45: Interest Expense = | C45: =Normalized_FCF!C45 -> -2620.62 | D45: =Reporting_currency -> HKD
B46: Net Interest Income = | C46: =Normalized_FCF!C10 -> 9912.5106 | D46: =Reporting_currency -> HKD
B48: • NCI’s Share of Profits: NCI represents the portion of a subsidiary’s equity not owned by the parent company.
B49: Est. NCI’s Share of Profits = | C49: =Normalized_FCF!C13 -> -335976.4 | D49: =Reporting_currency -> HKD
B51: • Taxes: Tax = (Normalized Operating EBIT + Stable Non-Operating EBIT + Interest Income – Interest Expense) × Tax Rate
B52: Taxes = | C52: =Normalized_FCF!C12 -> -477705.51 | D52: =Reporting_currency -> HKD
...

Sheet Data
B1: =Thesis!E17 -> HKD | C1: 45657 | D1: =EOMONTH(EDATE(C1,-12),0) -> 45291 | E1: =EOMONTH(EDATE(D1,-12),0) -> 44926 | F1: =EOMONTH(EDATE(E1,-12),0) -> 44561 | G1: =EOMONTH(EDATE(F1,-12),0) -> 44196 | H1: =EOMONTH(EDATE(G1,-12),0) -> 43830 | I1: =EOMONTH(EDATE(H1,-12),0) -> 43465 | J1: =EOMONTH(EDATE(I1,-12),0) -> 43100 | K1: =EOMONTH(EDATE(J1,-12),0) -> 42735 | ... M1: =EOMONTH(EDATE(L1,-12),0) -> 42004
B2: Data (Dirty)
B3: Income Statement | C3: 1000
B4: Sales | C4: 5057000 | D4: 5891068 | E4: 8214719 | F4: 7075818 | G4: 3996951 | H4: 3869308 | I4: 3686176 | J4: 3471922 | K4: 1809885 | L4: 1996629
B5: COGS | C5: 2468686 | D5: 2425040 | E5: 2925125 | F5: 2681244 | G5: 2127744 | H5: 1880565 | I5: 1785634 | J5: 1596518 | K5: 1202842 | L5: 1508441
B6: OPEX | C6: 318991 | D6: 415858 | E6: 556324 | F6: 477644 | G6: 498500 | H6: 432342 | I6: 413972 | J6: 408672 | K6: 371167 | L6: 543649
B7: Incl. Selling Expenses | C7: 110092 | D7: 214562 | E7: 348512 | F7: 269741 | G7: 316586 | H7: 250051 | I7: 208621 | J7: 206638 | K7: 167412 | L7: 201907
B8: R&D
B9: Share of JV or associate Results
B10: Dividend or Interests from FA
B11: Investment property
B12: Interest Expense | C12: 1746 | D12: 2921 | E12: 1360 | F12: 1275
B13: Interest Income | C13: 186780 | D13: 173638 | E13: 107067 | F13: 69578
B14: Income Tax Paid | C14: 710922 | D14: 917979 | E14: 1317738 | F14: 1071328 | G14: 425331 | H14: 456674 | I14: 487781 | J14: 465034 | K14: 76600 | L14: -124459
B15: Reported Net Income | C15: 1814975 | D15: 2300938 | E15: 3308155 | F15: 3060831 | G15: 1187283 | H15: 1176141 | I15: 1151928 | J15: 1182584 | K15: 67656 | L15: -711475
B16: Non-controling Interests | C16: 320909 | D16: 411691 | E16: 592781 | F16: 522336 | G16: 107242 | H16: 35728 | I16: 51440 | J16: 101935 | K16: -44139 | L16: -295004
B18: Cash Flow Statement
B19: D&A
B20: CAPX
B21: WCInv
B22: CFO | C22: 2369874 | D22: 4543011 | E22: 3847566 | F22: 3858089 | G22: 836818 | H22: 1922241 | I22: 1642851 | J22: 1535692 | K22: 222071 | L22: 821391
B23: CFI | C23: -182373 | D23: 759311 | E23: -1150823 | F23: -1949086 | G23: 226332 | H23: -727776 | I23: -319345 | J23: 266424 | K23: 377546 | L23: 571097
B24: CFF | C24: -971717 | D24: -2342230 | E24: -2819292 | F24: -913829 | G24: -1490643 | H24: -893331 | I24: -1135313 | J24: -317532 | K24: -1060796 | L24: -1009824
B25: ="Dividend per share ("&Market_currency&")" -> Dividend per share (HKD) | C25: =0.21+0.09 -> 0.3 | D25: =0.18+0.1 -> 0.28 | E25: =0.28+0.15 -> 0.43
B27: Balance Sheet | C27: Latest Asset Value
B28: ST AR | C28: =BS!C4 -> 537904 | D28: 687833 | E28: 2889765 | F28: 3144251 | G28: 2049144 | H28: 1797319 | I28: 2248182 | J28: 2297795 | K28: 1943651 | L28: 1757738
B29: ST Inventory | C29: =BS!C6 -> 137638 | D29: 125636 | E29: 42046 | F29: 142658 | G29: 131170 | H29: 123530 | I29: 130069 | J29: 195983 | K29: 198599 | L29: 167312
B30: Total Liabilities | C30: =BS!C33+BS!C42 -> 4047566 | D30: 4021026 | E30: 4786265 | F30: 5631759 | G30: 4142576 | H30: 4426398 | I30: 4475236 | J30: 4318962 | K30: 3438763 | L30: 3683389
B31: Total Equity | C31: =BS!G27 -> 18901257 | D31: 18470518 | E31: 18677219 | F31: 19148218 | G31: 17291070 | H31: 17046312 | I31: 16775806 | J31: 17375683 | K31: 15665693 | L31: 17044280
B32: Non-common Interest | C32: =BS!G28 -> 2421183 | D32: 2188672 | E32: 1908542 | F32: 1848135 | G32: 1453904 | H32: 1364732 | I32: 1391690 | J32: 1440871 | K32: 1146669 | L32: 1253165
B34: IS & CF Statements (Clean)
B35: Income Statement
B36: Sales | C36: =IF(C$4="","",C4) -> 5057000 | D36: =IF(D$4="","",D4) -> 5891068 | E36: =IF(E$4="","",E4) -> 8214719 | F36: =IF(F$4="","",F4) -> 7075818 | G36: =IF(G$4="","",G4) -> 3996951 | H36: =IF(H$4="","",H4) -> 3869308 | I36: =IF(I$4="","",I4) -> 3686176 | J36: =IF(J$4="","",J4) -> 3471922 | ... M36: =IF(M$4="","",M4)
B37: COGS | C37: =IF(C$4="","",-C5) -> -2468686 | D37: =IF(D$4="","",-D5) -> -2425040 | E37: =IF(E$4="","",-E5) -> -2925125 | F37: =IF(F$4="","",-F5) -> -2681244 | G37: =IF(G$4="","",-G5) -> -2127744 | H37: =IF(H$4="","",-H5) -> -1880565 | I37: =IF(I$4="","",-I5) -> -1785634 | J37: =IF(J$4="","",-J5) -> -1596518 | ... M37: =IF(M$4="","",-M5)
B38: Gross Margin | C38: =IF(C36="","",C36+C37) -> 2588314 | D38: =IF(D36="","",D36+D37) -> 3466028 | E38: =IF(E36="","",E36+E37) -> 5289594 | F38: =IF(F36="","",F36+F37) -> 4394574 | G38: =IF(G36="","",G36+G37) -> 1869207 | H38: =IF(H36="","",H36+H37) -> 1988743 | I38: =IF(I36="","",I36+I37) -> 1900542 | J38: =IF(J36="","",J36+J37) -> 1875404 | ... M38: =IF(M36="","",M36+M37)
B39: OPEX | C39: =IF(C$4="","",-C6) -> -318991 | D39: =IF(D$4="","",-D6) -> -415858 | E39: =IF(E$4="","",-E6) -> -556324 | F39: =IF(F$4="","",-F6) -> -477644 | G39: =IF(G$4="","",-G6) -> -498500 | H39: =IF(H$4="","",-H6) -> -432342 | I39: =IF(I$4="","",-I6) -> -413972 | J39: =IF(J$4="","",-J6) -> -408672 | ... M39: =IF(M$4="","",-M6)
B40: Incl. Selling Expenses | C40: =IF(C$4="","",-C7) -> -110092 | D40: =IF(D$4="","",-D7) -> -214562 | E40: =IF(E$4="","",-E7) -> -348512 | F40: =IF(F$4="","",-F7) -> -269741 | G40: =IF(G$4="","",-G7) -> -316586 | H40: =IF(H$4="","",-H7) -> -250051 | I40: =IF(I$4="","",-I7) -> -208621 | J40: =IF(J$4="","",-J7) -> -206638 | ... M40: =IF(M$4="","",-M7)
B41: Incl. Other Opex | C41: =IF(C$4="","",C39-C40) -> -208899 | D41: =IF(D$4="","",D39-D40) -> -201296 | E41: =IF(E$4="","",E39-E40) -> -207812 | F41: =IF(F$4="","",F39-F40) -> -207903 | G41: =IF(G$4="","",G39-G40) -> -181914 | H41: =IF(H$4="","",H39-H40) -> -182291 | I41: =IF(I$4="","",I39-I40) -> -205351 | J41: =IF(J$4="","",J39-J40) -> -202034 | ... M41: =IF(M$4="","",M39-M40)
B42: R&D | C42: =IF(C$4="","",-C8) -> 0 | D42: =IF(D$4="","",-D8) -> 0 | E42: =IF(E$4="","",-E8) -> 0 | F42: =IF(F$4="","",-F8) -> 0 | G42: =IF(G$4="","",-G8) -> 0 | H42: =IF(H$4="","",-H8) -> 0 | I42: =IF(I$4="","",-I8) -> 0 | J42: =IF(J$4="","",-J8) -> 0 | ... M42: =IF(M$4="","",-M8)
B43: Operating EBIT | C43: =IF(C$4="","",C38+C39+C42) -> 2269323 | D43: =IF(D$4="","",D38+D39+D42) -> 3050170 | E43: =IF(E$4="","",E38+E39+E42) -> 4733270 | F43: =IF(F$4="","",F38+F39+F42) -> 3916930 | G43: =IF(G$4="","",G38+G39+G42) -> 1370707 | H43: =IF(H$4="","",H38+H39+H42) -> 1556401 | I43: =IF(I$4="","",I38+I39+I42) -> 1486570 | J43: =IF(J$4="","",J38+J39+J42) -> 1466732 | ... M43: =IF(M$4="","",M38+M39+M42)
...

Sheet BS
B1: Most Recent Quarter | C1: 45838 | F1: =IF(MONTH(C1)=MONTH(Normalized_FCF!G1),"FY","Quarter")&" Report" -> Quarter Report | H1: =scaling_factor -> 1000
B2: Lastest Balance Sheet
B3: ST Operating Assets | C3: Book | D3: Valued @ | F3: ST Non-Operating Assets | G3: Book | H3: Valued @
B4: ST AR | C4: =519815+18089 -> 537904 | D4: 0.6 | F4: Cash and cash equivalents | G4: =1505443+7675879 -> 9181322 | H4: 0.9
B5: Operating ST Financial Assets | C5: 0 | D5: 0.6 | F5: Restricted cash | G5: 937107 | H5: 0.7
B6: Inventory | C6: 137638 | D6: 0.5 | F6: Securities with stable income | G6: 0 | H6: 0.6
B7: Properties held for sale | C7: 0 | D7: 0.6 | F7: Other Securities | G7: 0 | H7: 0.6
B8: Properties held for income | C8: 0 | D8: 0.6 | F8: Properties with stable income | G8: 0 | H8: 0.6
B9: Prepayments and Contract Assets | C9: 207695 | D9: 0.1 | F9: Other Properties | G9: 0 | H9: 0.6
B10: ST DTA | C10: 0 | D10: 0.9 | F10: Assets held for sale | G10: 0 | H10: 0.6
B11: Other ST Assets | C11: 0 | D11: 0.05
B12: Operating ST Assets | C12: =SUM(C4:C11) -> 883237 | D12: =C4*D4+C5*D5+C9*D9+C6*D6+C8*D8+C7*D7+C10*D10+C11*D11 -> 412330.9 | F12: Non-Operating ST Assets | G12: =SUM(G4:G10) -> 10118429 | H12: =G4*H4+G5*H5+G6*H6+G7*H7+G8*H8+G9*H9+G10*H10 -> 8919164.7
B14: LT Operating Assets | C14: Book | D14: Valued @ | F14: LT Non-Operating Assets | G14: Book | H14: Valued @
B15: LT AR and Prepayments | C15: 453310 | D15: 0.4 | F15: LT Depositis | G15: 0 | H15: 0.8
B16: Operating LT Financial Assets | C16: 0 | D16: 0.5 | F16: Securities with stable income | G16: 0 | H16: 0.6
B17: Properties held for sale | C17: 0 | D17: 0.6 | F17: Other Securities | G17: =439187 -> 439187 | H17: 0.6
B18: Properties held for income | C18: 0 | D18: 0.6 | F18: JV or associate with stable income | G18: 0 | H18: 0.1
B19: PP&E & Right of Use Assets | C19: =3715248+73168+31796 -> 3820212 | D19: 0.1 | F19: Other JV or associate | G19: 0 | H19: 0.1
B20: Biological assets | C20: 0 | D20: 0.05 | F20: Properties with stable income | G20: 0 | H20: 0.2
B21: Intangible assets | C21: 5970133 | D21: 0.05 | F21: Other Properties | G21: 0 | H21: 0.1
B22: LT DTA | C22: 84764 | D22: 0.9
B23: Other assets & Goodwill | C23: =1179551 -> 1179551 | D23: 0
B24: Operating LT Assets | C24: =SUM(C15:C23) -> 11507970 | D24: =C15*D15+C16*D16+C18*D18+C17*D17+C19*D19+C20*D20+C21*D21+C22*D22+C23*D23 -> 938139.45 | F24: Non-Operating LT Assets | G24: =SUM(G15:G21) -> 439187 | H24: =G15*H15+G16*H16+G17*H17+G18*H18+G19*H19+G20*H20+G21*H21 -> 263512.2
B26: ST Liabilities | C26: Book | F26: BS Summary | G26: Book | H26: Valued @
B27: ST Borrowing | C27: 0 | F27: Total Equity | G27: =G32-G30 -> 18901257 | H27: =H32-G30 -> 6485581.2
B28: ST Lease liabilities | C28: 12125 | F28: Incl. Minority Interest (NCI) | G28: 2421183
B29: ST SH Loan | C29: 0 | F29: Incl. Common Equity | G29: =G27-G28 -> 16480074 | H29: =H27-G28 -> 4064398.2
B30: ST Financial Liabilities | C30: 0 | F30: Total Liabilities | G30: =C33+C42 -> 4047566
B31: ST Interest-bearing Debt | C31: =SUM(C27:C30) -> 12125 | F31: incl. Interest-bearing Debt | G31: =C31+C40 -> 43677
B32: Other ST liabilities | C32: =C33-C31 -> 2578910 | F32: Total Assets | G32: =G35+G40 -> 22948823 | H32: =H35+H40 -> 10533147
B33: Current Liabilities | C33: 2591035
F34: Assets Summary | G34: Book | H34: Valued @
B35: LT Liabilities | C35: Book | F35: Operating Assets | G35: =C12+C24 -> 12391207 | H35: =D12+D24 -> 1350470.3
B36: LT Borrowing | C36: 0 | F36: incl. AR | G36: =C4+C15 -> 991214
B37: LT Lease liabilities | C37: 31552 | F37: incl. inventory | G37: =C6 -> 137638
B38: LT SH Loan | C38: 0 | F38: incl. Properties held for sale | G38: =C7+C17 -> 0
B39: LT Financial Liabilities | C39: 0 | F39: incl. Fixed Assets | G39: =C7+C17+C19+C20 -> 3820212 | H39: =C7*D7+C17*D17+C19*D19+C20*D20 -> 382021.2
B40: LT Interest-bearing Debt | C40: =SUM(C36:C39) -> 31552 | F40: Non-operating Assets | G40: =G12+G24 -> 10557616 | H40: =H12+H24 -> 9182676.9
B41: Other LT liabilities | C41: =C42-C40 -> 1424979 | F41: incl. Assets with stable income | G41: =C70 -> 10118429 | H41: =H40-H42 -> 8919164.7
B42: Noncurrent Liabilities | C42: 1456531 | F42: incl. Other Assets | G42: =C82 -> 439187 | H42: =D82 -> 263512.2
...

Sheet Normalized_FCF
B1: =Thesis!E17 -> HKD | C1: Normalized | G1: =Data!C1 -> 45657 | H1: =EOMONTH(EDATE(G1,-12),0) -> 45291 | I1: =EOMONTH(EDATE(H1,-12),0) -> 44926 | J1: =EOMONTH(EDATE(I1,-12),0) -> 44561 | K1: =EOMONTH(EDATE(J1,-12),0) -> 44196 | L1: =EOMONTH(EDATE(K1,-12),0) -> 43830 | M1: =EOMONTH(EDATE(L1,-12),0) -> 43465 | N1: =EOMONTH(EDATE(M1,-12),0) -> 43100 | O1: =EOMONTH(EDATE(N1,-12),0) -> 42735 | ... Q1: =EOMONTH(EDATE(P1,-12),0) -> 42004
B2: FCFE Analysis | E2: Notes
B3: Normalized FCFE | C3: =scaling_factor -> 1000 | G3: Historical FCFE | H3: =scaling_factor -> 1000
B4: Sales | C4: =G4*0.9 -> 4551300 | G4: =Data!C36 -> 5057000 | H4: =Data!D36 -> 5891068 | I4: =Data!E36 -> 8214719 | J4: =Data!F36 -> 7075818 | K4: =Data!G36 -> 3996951 | L4: =Data!H36 -> 3869308 | M4: =Data!I36 -> 3686176 | N4: =Data!J36 -> 3471922 | ... Q4: =Data!M36
B5: Variable Costs | C5: =C26 -> -2441491.5 | G5: =G26 -> -2578778 | H5: =H26 -> -2639602 | I5: =I26 -> -3273637 | J5: =J26 -> -2950985 | K5: =K26 -> -2444330 | L5: =L26 -> -2130616 | M5: =M26 -> -1994255 | N5: =N26 -> -1803156 | ... Q5: =Q26
B6: Contribution Margin | C6: =C4+C5 -> 2109808.5 | G6: =IF(G4="","",G4+G5) -> 2478222 | H6: =IF(H4="","",H4+H5) -> 3251466 | I6: =IF(I4="","",I4+I5) -> 4941082 | J6: =IF(J4="","",J4+J5) -> 4124833 | K6: =IF(K4="","",K4+K5) -> 1552621 | L6: =IF(L4="","",L4+L5) -> 1738692 | M6: =IF(M4="","",M4+M5) -> 1691921 | N6: =IF(N4="","",N4+N5) -> 1668766 | ... Q6: =IF(Q4="","",Q4+Q5)
B7: Fixed Costs | C7: =C35 -> -208899 | G7: =G35 -> -208899 | H7: =H35 -> -201296 | I7: =I35 -> -207812 | J7: =J35 -> -207903 | K7: =K35 -> -181914 | L7: =L35 -> -182291 | M7: =M35 -> -205351 | N7: =N35 -> -202034 | ... Q7: =Q35
B8: Operating EBIT | C8: =C6+C7 -> 1900909.5 | G8: =IF(G$4="","",G6+G7) -> 2269323 | H8: =IF(H$4="","",H6+H7) -> 3050170 | I8: =IF(I$4="","",I6+I7) -> 4733270 | J8: =IF(J$4="","",J6+J7) -> 3916930 | K8: =IF(K$4="","",K6+K7) -> 1370707 | L8: =IF(L$4="","",L6+L7) -> 1556401 | M8: =IF(M$4="","",M6+M7) -> 1486570 | N8: =IF(N$4="","",N6+N7) -> 1466732 | ... Q8: =IF(Q$4="","",Q6+Q7)
B9: Stable Non-Operating EBIT | C9: =C61 -> 0 | G9: =G59 -> 0 | H9: =H59 -> 0 | I9: =I59 -> 0 | J9: =J59 -> 0 | K9: =K59 -> 0 | L9: =L59 -> 0 | M9: =M59 -> 0 | N9: =N59 -> 0 | ... Q9: =Q59
B10: Net Interest Income | C10: =C48 -> 9912.5106 | G10: =G48 -> 36812.985 | H10: =H48 -> 32924.942 | I10: =I48 -> 20742.982 | J10: =J48 -> 13088.728 | K10: =K48 -> 0 | L10: =L48 -> 0 | M10: =M48 -> 0 | N10: =N48 -> 0 | ... Q10: =Q48
B11: Pre-tax Profit | C11: =SUM(C8:C10) -> 1910822 | G11: =IF(G$4="","",SUM(G8:G10)) -> 2306136 | H11: =IF(H$4="","",SUM(H8:H10)) -> 3083094.9 | I11: =IF(I$4="","",SUM(I8:I10)) -> 4754013 | J11: =IF(J$4="","",SUM(J8:J10)) -> 3930018.7 | K11: =IF(K$4="","",SUM(K8:K10)) -> 1370707 | L11: =IF(L$4="","",SUM(L8:L10)) -> 1556401 | M11: =IF(M$4="","",SUM(M8:M10)) -> 1486570 | N11: =IF(N$4="","",SUM(N8:N10)) -> 1466732 | ... Q11: =IF(Q$4="","",SUM(Q8:Q10))
B12: Income Tax | C12: =-C11*C41 -> -477705.51 | G12: =Data!C46 -> -710922 | H12: =Data!D46 -> -917979 | I12: =Data!E46 -> -1317738 | J12: =Data!F46 -> -1071328 | K12: =Data!G46 -> -425331 | L12: =Data!H46 -> -456674 | M12: =Data!I46 -> -487781 | N12: =Data!J46 -> -465034 | ... Q12: =Data!M46
B13: NCI’s Share of Profits | C13: =-C4*C79 -> -335976.4 | G13: =Data!C48 -> -320909 | H13: =Data!D48 -> -411691 | I13: =Data!E48 -> -592781 | J13: =Data!F48 -> -522336 | K13: =Data!G48 -> -107242 | L13: =Data!H48 -> -35728 | M13: =Data!I48 -> -51440 | N13: =Data!J48 -> -101935 | ... Q13: =Data!M48
B14: After-tax Profit | C14: =SUM(C11:C13) -> 1097140.1 | G14: =IF(G$4="","",SUM(G11:G13)) -> 1274305 | H14: =IF(H$4="","",SUM(H11:H13)) -> 1753424.9 | I14: =IF(I$4="","",SUM(I11:I13)) -> 2843494 | J14: =IF(J$4="","",SUM(J11:J13)) -> 2336354.7 | K14: =IF(K$4="","",SUM(K11:K13)) -> 838134 | L14: =IF(L$4="","",SUM(L11:L13)) -> 1063999 | M14: =IF(M$4="","",SUM(M11:M13)) -> 947349 | N14: =IF(N$4="","",SUM(N11:N13)) -> 899763 | ... Q14: =IF(Q$4="","",SUM(Q11:Q13))
B15: Add Back D&A | C15: =BS!$G$39*BS!D58 -> 0 | G15: =IF(Data!C61="","",-Data!C61) -> 0 | H15: =IF(Data!D61="","",-Data!D61) -> 0 | I15: =IF(Data!E61="","",-Data!E61) -> 0 | J15: =IF(Data!F61="","",-Data!F61) -> 0 | K15: =IF(Data!G61="","",-Data!G61) -> 0 | L15: =IF(Data!H61="","",-Data!H61) -> 0 | M15: =IF(Data!I61="","",-Data!I61) -> 0 | N15: =IF(Data!J61="","",-Data!J61) -> 0 | ... Q15: =IF(Data!M61="","",-Data!M61)
B16: Maintenance Capex | C16: =-C4*C82 -> 0 | G16: =Data!C62 -> 0 | H16: =Data!D62 -> 0 | I16: =Data!E62 -> 0 | J16: =Data!F62 -> 0 | K16: =Data!G62 -> 0 | L16: =Data!H62 -> 0 | M16: =Data!I62 -> 0 | N16: =Data!J62 -> 0 | ... Q16: =Data!M62
B17: WCInv | C17: =-C4*C83 -> 0 | E17: WCInv is by default excluded
B18: Net Borrowing | C18: 0 | E18: Net borrowing is excluded
B19: FCFE | C19: =C14+C17 -> 1097140.1 | G19: =IF(G$4="","",G14+G17) -> 1274305 | H19: =IF(H$4="","",H14+H17) -> 1753424.9 | I19: =IF(I$4="","",I14+I17) -> 2843494 | J19: =IF(J$4="","",J14+J17) -> 2336354.7 | K19: =IF(K$4="","",K14+K17) -> 838134 | L19: =IF(L$4="","",L14+L17) -> 1063999 | M19: =IF(M$4="","",M14+M17) -> 947349 | N19: =IF(N$4="","",N14+N17) -> 899763 | ... Q19: =IF(Q$4="","",Q14+Q17)
B21: Operating Cost Structure | E21: Notes
B22: Variable Costs
B23: COGS | C23: =-C4*C29 -> -2283631.2 | G23: =Data!C37 -> -2468686 | H23: =Data!D37 -> -2425040 | I23: =Data!E37 -> -2925125 | J23: =Data!F37 -> -2681244 | K23: =Data!G37 -> -2127744 | L23: =Data!H37 -> -1880565 | M23: =Data!I37 -> -1785634 | N23: =Data!J37 -> -1596518 | ... Q23: =Data!M37
B24: Selling Expenses | C24: =-C4*C30 -> -157860.29 | G24: =Data!C40 -> -110092 | H24: =Data!D40 -> -214562 | I24: =Data!E40 -> -348512 | J24: =Data!F40 -> -269741 | K24: =Data!G40 -> -316586 | L24: =Data!H40 -> -250051 | M24: =Data!I40 -> -208621 | N24: =Data!J40 -> -206638 | ... Q24: =Data!M40
B25: R&D | C25: =-C4*C31 -> 0 | G25: =Data!C42 -> 0 | H25: =Data!D42 -> 0 | I25: =Data!E42 -> 0 | J25: =Data!F42 -> 0 | K25: =Data!G42 -> 0 | L25: =Data!H42 -> 0 | M25: =Data!I42 -> 0 | N25: =Data!J42 -> 0 | ... Q25: =Data!M42
B26: Variable Costs | C26: =SUM(C23:C25) -> -2441491.5 | G26: =IF(G$4="","",SUM(G23:G25)) -> -2578778 | H26: =IF(H$4="","",SUM(H23:H25)) -> -2639602 | I26: =IF(I$4="","",SUM(I23:I25)) -> -3273637 | J26: =IF(J$4="","",SUM(J23:J25)) -> -2950985 | K26: =IF(K$4="","",SUM(K23:K25)) -> -2444330 | L26: =IF(L$4="","",SUM(L23:L25)) -> -2130616 | M26: =IF(M$4="","",SUM(M23:M25)) -> -1994255 | N26: =IF(N$4="","",SUM(N23:N25)) -> -1803156 | ... Q26: =IF(Q$4="","",SUM(Q23:Q25))
B28: Variable Costs % of Sales
B29: COGS | C29: =AVERAGE(G29:P29) -> 0.50175361 | G29: =IF(G$4="","",ABS(G23/G$4)) -> 0.48817204 | H29: =IF(H$4="","",ABS(H23/H$4)) -> 0.41164692 | I29: =IF(I$4="","",ABS(I23/I$4)) -> 0.35608339 | J29: =IF(J$4="","",ABS(J23/J$4)) -> 0.37893061 | K29: =IF(K$4="","",ABS(K23/K$4)) -> 0.53234178 | L29: =IF(L$4="","",ABS(L23/L$4)) -> 0.48602101 | M29: =IF(M$4="","",ABS(M23/M$4)) -> 0.48441366 | N29: =IF(N$4="","",ABS(N23/N$4)) -> 0.45983694 | ... Q29: =IF(Q$4="","",ABS(Q23/Q$4))
B30: =B24 -> Selling Expenses | C30: =AVERAGE(G30:J30) -> 0.034684659 | G30: =IF(G$4="","",ABS(G24/G$4)) -> 0.021770219 | H30: =IF(H$4="","",ABS(H24/H$4)) -> 0.036421579 | I30: =IF(I$4="","",ABS(I24/I$4)) -> 0.04242531 | J30: =IF(J$4="","",ABS(J24/J$4)) -> 0.038121529 | K30: =IF(K$4="","",ABS(K24/K$4)) -> 0.079206875 | L30: =IF(L$4="","",ABS(L24/L$4)) -> 0.064624217 | M30: =IF(M$4="","",ABS(M24/M$4)) -> 0.056595507 | N30: =IF(N$4="","",ABS(N24/N$4)) -> 0.05951689 | ... Q30: =IF(Q$4="","",ABS(Q24/Q$4))
B31: =B25 -> R&D | C31: 0 | G31: =IF(G$4="","",ABS(G25/G$4)) -> 0 | H31: =IF(H$4="","",ABS(H25/H$4)) -> 0 | I31: =IF(I$4="","",ABS(I25/I$4)) -> 0 | J31: =IF(J$4="","",ABS(J25/J$4)) -> 0 | K31: =IF(K$4="","",ABS(K25/K$4)) -> 0 | L31: =IF(L$4="","",ABS(L25/L$4)) -> 0 | M31: =IF(M$4="","",ABS(M25/M$4)) -> 0 | N31: =IF(N$4="","",ABS(N25/N$4)) -> 0 | ... Q31: =IF(Q$4="","",ABS(Q25/Q$4))
B32: Variable Costs | C32: =ABS(C26/$C$4) -> 0.53643826 | G32: =IF(G$4="","",ABS(G26/G$4)) -> 0.50994226 | H32: =IF(H$4="","",ABS(H26/H$4)) -> 0.4480685 | I32: =IF(I$4="","",ABS(I26/I$4)) -> 0.3985087 | J32: =IF(J$4="","",ABS(J26/J$4)) -> 0.41705213 | K32: =IF(K$4="","",ABS(K26/K$4)) -> 0.61154865 | L32: =IF(L$4="","",ABS(L26/L$4)) -> 0.55064523 | M32: =IF(M$4="","",ABS(M26/M$4)) -> 0.54100917 | N32: =IF(N$4="","",ABS(N26/N$4)) -> 0.51935383 | ... Q32: =IF(Q$4="","",ABS(Q26/Q$4))
B34: Fixed Costs
B35: G&A and other Opex | C35: =G35 -> -208899 | G35: =IF(G4="","",Data!C41) -> -208899 | H35: =IF(H4="","",Data!D41) -> -201296 | I35: =IF(I4="","",Data!E41) -> -207812 | J35: =IF(J4="","",Data!F41) -> -207903 | K35: =IF(K4="","",Data!G41) -> -181914 | L35: =IF(L4="","",Data!H41) -> -182291 | M35: =IF(M4="","",Data!I41) -> -205351 | N35: =IF(N4="","",Data!J41) -> -202034 | ... Q35: =IF(Q4="","",Data!M41)
B37: Fixed Costs % of Sales
B38: G&A and other Opex | C38: =ABS(C35/$C$4) -> 0.045898754 | G38: =IF(G$4="","",ABS(G35/G$4)) -> 0.041308879 | H38: =IF(H$4="","",ABS(H35/H$4)) -> 0.034169696 | I38: =IF(I$4="","",ABS(I35/I$4)) -> 0.025297518 | J38: =IF(J$4="","",ABS(J35/J$4)) -> 0.029382186 | K38: =IF(K$4="","",ABS(K35/K$4)) -> 0.045513192 | L38: =IF(L$4="","",ABS(L35/L$4)) -> 0.047112042 | M38: =IF(M$4="","",ABS(M35/M$4)) -> 0.055708409 | N38: =IF(N$4="","",ABS(N35/N$4)) -> 0.058190823 | ... Q38: =IF(Q$4="","",ABS(Q35/Q$4))
B40: Tax % of Pre-tax Profit
B41: Income Tax Rate | C41: 0.25 | E41: Use the marginal tax rate | G41: =IF(G$4="","",-G12/SUM(G8+G9,G10)) -> 0.3082741 | H41: =IF(H$4="","",-H12/SUM(H8+H9,H10)) -> 0.29774594 | I41: =IF(I$4="","",-I12/SUM(I8+I9,I10)) -> 0.27718435 | J41: =IF(J$4="","",-J12/SUM(J8+J9,J10)) -> 0.27260125 | K41: =IF(K$4="","",-K12/SUM(K8+K9,K10)) -> 0.31030045 | L41: =IF(L$4="","",-L12/SUM(L8+L9,L10)) -> 0.29341667 | M41: =IF(M$4="","",-M12/SUM(M8+M9,M10)) -> 0.32812515 | N41: =IF(N$4="","",-N12/SUM(N8+N9,N10)) -> 0.31705451 | ... Q41: =IF(Q$4="","",-Q12/SUM(Q8+Q9,Q10))
B43: Non-operating Income | E43: Notes
B44: Interest
B45: Interest Expense | C45: =-BS!G31*Normalized_FCF!C52 -> -2620.62 | G45: =Data!C51 -> -1746 | H45: =Data!D51 -> -2921 | I45: =Data!E51 -> -1360 | J45: =Data!F51 -> -1275 | K45: =Data!G51 -> 0 | L45: =Data!H51 -> 0 | M45: =Data!I51 -> 0 | N45: =Data!J51 -> 0 | ... Q45: =Data!M51
B46: Operating Interest Income | C46: =BS!D75*C51 -> 12533.131 | G46: =IFERROR(IF(G$4="","",($C$46/$C$47)*G47),0) -> 38558.985 | H46: =IFERROR(IF(H$4="","",($C$46/$C$47)*H47),0) -> 35845.942 | I46: =IFERROR(IF(I$4="","",($C$46/$C$47)*I47),0) -> 22102.982 | J46: =IFERROR(IF(J$4="","",($C$46/$C$47)*J47),0) -> 14363.728 | K46: =IFERROR(IF(K$4="","",($C$46/$C$47)*K47),0) -> 0 | L46: =IFERROR(IF(L$4="","",($C$46/$C$47)*L47),0) -> 0 | M46: =IFERROR(IF(M$4="","",($C$46/$C$47)*M47),0) -> 0 | N46: =IFERROR(IF(N$4="","",($C$46/$C$47)*N47),0) -> 0 | ... Q46: =IFERROR(IF(Q$4="","",($C$46/$C$47)*Q47),0)
...

Sheet DCF
B2: No-Growth DCF Valuation
B3: No-Growth DCF | C3: =scaling_factor -> 1000 | E3: FV adjustments | H3: Normalized Values
B4: Normalized FCFE | C4: =Normalized_FCF!C19 -> 1097140.1 | D4: =Reporting_currency -> HKD | E4: Interest-bearing Debt | F4: =-BS!G31 -> -43677 | G4: =Reporting_currency -> HKD | H4: Revenues | I4: =Normalized_FCF!C4 -> 4551300
B5: /Equity Cost of Capital | C5: =Equity_Cost -> 0.0725 | E5: Non-operating Cash | F5: =BS!D66 -> 8029573.9 | G5: =Reporting_currency -> HKD | H5: Fixed Costs | I5: =Normalized_FCF!C7 -> -208899
B6: Stable Income Value | C6: =(C4*(1+Terminal_Growth))/(Equity_Cost-Terminal_Growth) -> 15132967 | D6: =Reporting_currency -> HKD | E6: Other Non-op. Assets | F6: =BS!H42 -> 263512.2 | G6: =Reporting_currency -> HKD | H6: Other Income, includes | I6: =I7+I8 -> 9912.5106
B7: + FV adjustments | C7: =F7 -> 8249409.1 | E7: FV adjustments | F7: =SUM(F4:F6) -> 8249409.1 | G7: =Reporting_currency -> HKD | H7: Non-op EBIT | I7: =Normalized_FCF!C9 -> 0
B8: Equity Value | C8: =C6+C7 -> 23382376 | D8: =Reporting_currency -> HKD | E8: FV adj. per share | F8: =FV_adjustments*scaling_factor/Common_Shares*Exchange_Rate -> 1.6203698 | G8: =Market_currency -> HKD | H8: =Normalized_FCF!B10 -> Net Interest Income | I8: =Normalized_FCF!C10 -> 9912.5106
B9: ="*"&Thesis!E15 -> *HKD | C9: =Exchange_Rate -> 1 | D9: =Thesis!E15 -> HKD | H9: =Normalized_FCF!B79 -> NCI’s Share of Profits | I9: =Normalized_FCF!C79 -> 0.073819875
B10: Value | C10: =C8*Exchange_Rate -> 23382376 | D10: =Market_currency -> HKD | H10: Tax rate | I10: =Normalized_FCF!C41 -> 0.25
B11: Value per share | C11: =(C10*scaling_factor)/Common_Shares -> 4.5928254 | D11: =Market_currency -> HKD
B13: Growth DCF Valuation
B14: Stage | C14: I | E14: Stage | F14: =IF(F17=C17,"I","II") -> I | H14: Terminal Stage
B15: High g Period (HGP) | C15: =Scenarios!C45 -> 3 | E15: =IF(F14="II","Change year","Terminal Year") -> Terminal Year | F15: =IF(F14="II",_xlfn.CEILING.MATH(C15/2),C15+1) -> 4 | H15: Terminal g Rate: | I15: =Terminal_Growth -> 0
B16: High g Rate (HGR) | C16: =Scenarios!C46 -> 0.0013 | E16: High Growth Rate_II | F16: =Scenarios!C41 -> 0.0013
B17: Contribution Margin | C17: =Normalized_FCF!C32 -> 0.53643826 | E17: Contribution Margin_II | F17: =Scenarios!C40 -> 0.53643826 | H17: Output
B18: D&A - maint. Capx | C18: =Normalized_FCF!C81-Normalized_FCF!C82 -> 0 | E18: D&A - maint. Capx | F18: =IF(F14="II",C18/2,C18) -> 0 | H18: Value Per Share | I18: =(L52+FV_adjustments)*Exchange_Rate/Common_Shares*scaling_factor -> 4.603592 | J18: =Market_currency -> HKD
A20: Stage | B20: Year | C20: Revenues | D20: Growth Rates | E20: Contribution Margin | F20: Fixed Costs | G20: EBIT | H20: =B18 -> D&A - maint. Capx | I20: FCFE/TV | J20: FCFE g | K20: Disc. Factor | L20: PV of FCFE/TV
A21: =IF($C$15<B21,"",IF(B21>=$F$15,"II","I")) -> I | B21: 1 | C21: =I4*(1+D21) -> 4557216.7 | D21: =IF(A21="",0,IF(A21="I",$C$16,$F$16)) -> 0.0013 | E21: =$C$17 -> 0.53643826 | F21: =I5*(1+D21) -> -209170.57 | G21: =C21*(1-E21)+F21+$I$6 -> 1913293.2 | H21: =IF(A21="",0%,IF(A21="I",$C$18,$F$18)) -> 0 | I21: =(G21*(1-$I$10)+C21*(H21-$I$9)) -> 1098556.7 | J21: =I21/C4-1 -> 0.001291191 | K21: =IF($C$15<B21,0,1/(1+Equity_Cost)^B21) -> 0.93240093 | L21: =I21*K21 -> 1024295.3
A22: =IF($C$15<B22,"",IF(B22>=$F$15,"II","I")) -> I | B22: 2 | C22: =IF(A22="",0,C21*(1+D22)) -> 4563141.1 | D22: =IF(A22="",0,IF(A22="I",$C$16,$F$16)) -> 0.0013 | E22: =IF($C$15<B22,0,IF(B22>=$F$15,$F$17,$C$17)) -> 0.53643826 | F22: =IF(A22="",0,F21*(1+D22)) -> -209442.49 | G22: =IF(A22="", 0,C22*(1-E22)+F22+$I$6) -> 1915767.6 | H22: =IF(A22="",0%,IF(A22="I",$C$18,$F$18)) -> 0 | I22: =IF(A22="", 0,G22*(1-$I$10)+C22*(H22-$I$9)) -> 1099975.2 | J22: =IF(A22="", 0,I22/I21-1) -> 0.0012912024 | K22: =IF($C$15<B22,0,1/(1+Equity_Cost)^B22) -> 0.8693715 | L22: =I22*K22 -> 956287.09
A23: =IF($C$15<B23,"",IF(B23>=$F$15,"II","I")) -> I | B23: 3 | C23: =IF(A23="",0,C22*(1+D23)) -> 4569073.2 | D23: =IF(A23="",0,IF(A23="I",$C$16,$F$16)) -> 0.0013 | E23: =IF($C$15<B23,0,IF(B23>=$F$15,$F$17,$C$17)) -> 0.53643826 | F23: =IF(A23="",0,F22*(1+D23)) -> -209714.77 | G23: =IF(A23="", 0,C23*(1-E23)+F23+$I$6) -> 1918245.2 | H23: =IF(A23="",0%,IF(A23="I",$C$18,$F$18)) -> 0 | I23: =IF(A23="", 0,G23*(1-$I$10)+C23*(H23-$I$9)) -> 1101395.5 | J23: =IF(A23="", 0,I23/I22-1) -> 0.0012912137 | K23: =IF($C$15<B23,0,1/(1+Equity_Cost)^B23) -> 0.8106028 | L23: =I23*K23 -> 892794.28
A24: =IF($C$15<B24,"",IF(B24>=$F$15,"II","I")) | B24: 4 | C24: =IF(A24="",0,C23*(1+D24)) -> 0 | D24: =IF(A24="",0,IF(A24="I",$C$16,$F$16)) -> 0 | E24: =IF($C$15<B24,0,IF(B24>=$F$15,$F$17,$C$17)) -> 0 | F24: =IF(A24="",0,F23*(1+D24)) -> 0 | G24: =IF(A24="", 0,C24*(1-E24)+F24+$I$6) -> 0 | H24: =IF(A24="",0%,IF(A24="I",$C$18,$F$18)) -> 0 | I24: =IF(A24="", 0,G24*(1-$I$10)+C24*(H24-$I$9)) -> 0 | J24: =IF(A24="", 0,I24/I23-1) -> 0 | K24: =IF($C$15<B24,0,1/(1+Equity_Cost)^B24) -> 0 | L24: =I24*K24 -> 0
A25: =IF($C$15<B25,"",IF(B25>=$F$15,"II","I")) | B25: 5 | C25: =IF(A25="",0,C24*(1+D25)) -> 0 | D25: =IF(A25="",0,IF(A25="I",$C$16,$F$16)) -> 0 | E25: =IF($C$15<B25,0,IF(B25>=$F$15,$F$17,$C$17)) -> 0 | F25: =IF(A25="",0,F24*(1+D25)) -> 0 | G25: =IF(A25="", 0,C25*(1-E25)+F25+$I$6) -> 0 | H25: =IF(A25="",0%,IF(A25="I",$C$18,$F$18)) -> 0 | I25: =IF(A25="", 0,G25*(1-$I$10)+C25*(H25-$I$9)) -> 0 | J25: =IF(A25="", 0,I25/I24-1) -> 0 | K25: =IF($C$15<B25,0,1/(1+Equity_Cost)^B25) -> 0 | L25: =I25*K25 -> 0
A26: =IF($C$15<B26,"",IF(B26>=$F$15,"II","I")) | B26: 6 | C26: =IF(A26="",0,C25*(1+D26)) -> 0 | D26: =IF(A26="",0,IF(A26="I",$C$16,$F$16)) -> 0 | E26: =IF($C$15<B26,0,IF(B26>=$F$15,$F$17,$C$17)) -> 0 | F26: =IF(A26="",0,F25*(1+D26)) -> 0 | G26: =IF(A26="", 0,C26*(1-E26)+F26+$I$6) -> 0 | H26: =IF(A26="",0%,IF(A26="I",$C$18,$F$18)) -> 0 | I26: =IF(A26="", 0,G26*(1-$I$10)+C26*(H26-$I$9)) -> 0 | J26: =IF(A26="", 0,I26/I25-1) -> 0 | K26: =IF($C$15<B26,0,1/(1+Equity_Cost)^B26) -> 0 | L26: =I26*K26 -> 0
A27: =IF($C$15<B27,"",IF(B27>=$F$15,"II","I")) | B27: 7 | C27: =IF(A27="",0,C26*(1+D27)) -> 0 | D27: =IF(A27="",0,IF(A27="I",$C$16,$F$16)) -> 0 | E27: =IF($C$15<B27,0,IF(B27>=$F$15,$F$17,$C$17)) -> 0 | F27: =IF(A27="",0,F26*(1+D27)) -> 0 | G27: =IF(A27="", 0,C27*(1-E27)+F27+$I$6) -> 0 | H27: =IF(A27="",0%,IF(A27="I",$C$18,$F$18)) -> 0 | I27: =IF(A27="", 0,G27*(1-$I$10)+C27*(H27-$I$9)) -> 0 | J27: =IF(A27="", 0,I27/I26-1) -> 0 | K27: =IF($C$15<B27,0,1/(1+Equity_Cost)^B27) -> 0 | L27: =I27*K27 -> 0
A28: =IF($C$15<B28,"",IF(B28>=$F$15,"II","I")) | B28: 8 | C28: =IF(A28="",0,C27*(1+D28)) -> 0 | D28: =IF(A28="",0,IF(A28="I",$C$16,$F$16)) -> 0 | E28: =IF($C$15<B28,0,IF(B28>=$F$15,$F$17,$C$17)) -> 0 | F28: =IF(A28="",0,F27*(1+D28)) -> 0 | G28: =IF(A28="", 0,C28*(1-E28)+F28+$I$6) -> 0 | H28: =IF(A28="",0%,IF(A28="I",$C$18,$F$18)) -> 0 | I28: =IF(A28="", 0,G28*(1-$I$10)+C28*(H28-$I$9)) -> 0 | J28: =IF(A28="", 0,I28/I27-1) -> 0 | K28: =IF($C$15<B28,0,1/(1+Equity_Cost)^B28) -> 0 | L28: =I28*K28 -> 0
A29: =IF($C$15<B29,"",IF(B29>=$F$15,"II","I")) | B29: 9 | C29: =IF(A29="",0,C28*(1+D29)) -> 0 | D29: =IF(A29="",0,IF(A29="I",$C$16,$F$16)) -> 0 | E29: =IF($C$15<B29,0,IF(B29>=$F$15,$F$17,$C$17)) -> 0 | F29: =IF(A29="",0,F28*(1+D29)) -> 0 | G29: =IF(A29="", 0,C29*(1-E29)+F29+$I$6) -> 0 | H29: =IF(A29="",0%,IF(A29="I",$C$18,$F$18)) -> 0 | I29: =IF(A29="", 0,G29*(1-$I$10)+C29*(H29-$I$9)) -> 0 | J29: =IF(A29="", 0,I29/I28-1) -> 0 | K29: =IF($C$15<B29,0,1/(1+Equity_Cost)^B29) -> 0 | L29: =I29*K29 -> 0
A30: =IF($C$15<B30,"",IF(B30>=$F$15,"II","I")) | B30: 10 | C30: =IF(A30="",0,C29*(1+D30)) -> 0 | D30: =IF(A30="",0,IF(A30="I",$C$16,$F$16)) -> 0 | E30: =IF($C$15<B30,0,IF(B30>=$F$15,$F$17,$C$17)) -> 0 | F30: =IF(A30="",0,F29*(1+D30)) -> 0 | G30: =IF(A30="", 0,C30*(1-E30)+F30+$I$6) -> 0 | H30: =IF(A30="",0%,IF(A30="I",$C$18,$F$18)) -> 0 | I30: =IF(A30="", 0,G30*(1-$I$10)+C30*(H30-$I$9)) -> 0 | J30: =IF(A30="", 0,I30/I29-1) -> 0 | K30: =IF($C$15<B30,0,1/(1+Equity_Cost)^B30) -> 0 | L30: =I30*K30 -> 0
A31: =IF($C$15<B31,"",IF(B31>=$F$15,"II","I")) | B31: 11 | C31: =IF(A31="",0,C30*(1+D31)) -> 0 | D31: =IF(A31="",0,IF(A31="I",$C$16,$F$16)) -> 0 | E31: =IF($C$15<B31,0,IF(B31>=$F$15,$F$17,$C$17)) -> 0 | F31: =IF(A31="",0,F30*(1+D31)) -> 0 | G31: =IF(A31="", 0,C31*(1-E31)+F31+$I$6) -> 0 | H31: =IF(A31="",0%,IF(A31="I",$C$18,$F$18)) -> 0 | I31: =IF(A31="", 0,G31*(1-$I$10)+C31*(H31-$I$9)) -> 0 | J31: =IF(A31="", 0,I31/I30-1) -> 0 | K31: =IF($C$15<B31,0,1/(1+Equity_Cost)^B31) -> 0 | L31: =I31*K31 -> 0
A32: =IF($C$15<B32,"",IF(B32>=$F$15,"II","I")) | B32: 12 | C32: =IF(A32="",0,C31*(1+D32)) -> 0 | D32: =IF(A32="",0,IF(A32="I",$C$16,$F$16)) -> 0 | E32: =IF($C$15<B32,0,IF(B32>=$F$15,$F$17,$C$17)) -> 0 | F32: =IF(A32="",0,F31*(1+D32)) -> 0 | G32: =IF(A32="", 0,C32*(1-E32)+F32+$I$6) -> 0 | H32: =IF(A32="",0%,IF(A32="I",$C$18,$F$18)) -> 0 | I32: =IF(A32="", 0,G32*(1-$I$10)+C32*(H32-$I$9)) -> 0 | J32: =IF(A32="", 0,I32/I31-1) -> 0 | K32: =IF($C$15<B32,0,1/(1+Equity_Cost)^B32) -> 0 | L32: =I32*K32 -> 0
A33: =IF($C$15<B33,"",IF(B33>=$F$15,"II","I")) | B33: 13 | C33: =IF(A33="",0,C32*(1+D33)) -> 0 | D33: =IF(A33="",0,IF(A33="I",$C$16,$F$16)) -> 0 | E33: =IF($C$15<B33,0,IF(B33>=$F$15,$F$17,$C$17)) -> 0 | F33: =IF(A33="",0,F32*(1+D33)) -> 0 | G33: =IF(A33="", 0,C33*(1-E33)+F33+$I$6) -> 0 | H33: =IF(A33="",0%,IF(A33="I",$C$18,$F$18)) -> 0 | I33: =IF(A33="", 0,G33*(1-$I$10)+C33*(H33-$I$9)) -> 0 | J33: =IF(A33="", 0,I33/I32-1) -> 0 | K33: =IF($C$15<B33,0,1/(1+Equity_Cost)^B33) -> 0 | L33: =I33*K33 -> 0
... A50: =IF($C$15<B50,"",IF(B50>=$F$15,"II","I")) | B50: 30 | C50: =IF(A50="",0,C49*(1+D50)) -> 0 | D50: =IF(A50="",0,IF(A50="I",$C$16,$F$16)) -> 0 | E50: =IF($C$15<B50,0,IF(B50>=$F$15,$F$17,$C$17)) -> 0 | F50: =IF(A50="",0,F49*(1+D50)) -> 0 | G50: =IF(A50="", 0,C50*(1-E50)+F50+$I$6) -> 0 | H50: =IF(A50="",0%,IF(A50="I",$C$18,$F$18)) -> 0 | I50: =IF(A50="", 0,G50*(1-$I$10)+C50*(H50-$I$9)) -> 0 | J50: =IF(A50="", 0,I50/I49-1) -> 0 | K50: =IF($C$15<B50,0,1/(1+Equity_Cost)^B50) -> 0 | L50: =I50*K50 -> 0
A51: T | B51: =C15+1 -> 4 | C51: =VLOOKUP(C15,B21:C50,2,FALSE)*(1+Terminal_Growth) -> 4569073.2 | D51: =Terminal_Growth -> 0 | E51: =F17 -> 0.53643826 | F51: =VLOOKUP(C15,B21:F50,5,FALSE)*(1+Terminal_Growth) -> -209714.77 | G51: =C51*(1-E51)+F51+$I$6 -> 1918245.2 | H51: =F18 -> 0 | I51: =(G51*(1-$I$10)+C51*(H51-$I$9))/Equity_Cost -> 15191662 | J51: =(G51*(1-$I$10)+C51*(H51-$I$9))/VLOOKUP(C15,B21:I50,8,FALSE)-1 -> 0 | K51: =1/(1+Equity_Cost)^C15 -> 0.8106028 | L51: =I51*K51 -> 12314404
J52: PV of total FCFE = | L52: =SUM(L21:L51) -> 15187781
B54: Sensitivity Analysis (Enterprise Value)
A55: =L52 -> 15187781 | B55: =C94 -> 0.04 | C55: =C93 -> -0.15 | D55: =C92 -> 0 | E55: =C91 -> 0.02 | F55: =C90 -> -0.3
A56: 1 | B56: 15734184 | C56: 12878404 | D56: 15132967 | E56: 15433576 | F56: 10623840
A57: 2 | B57: 16317183 | C57: 11091570 | D57: 15132967 | E57: 15719469 | F57: 7680820
A58: 3 | B58: 16882514 | C58: 9675431.5 | D58: 15132967 | E58: 15991368 | F58: 5759967.7
A59: 4 | B59: 17430715 | C59: 8553084 | D59: 15132967 | E59: 16249957 | F59: 4506264.6
A60: 5 | B60: 17962303 | C60: 7663577.7 | D60: 15132967 | E60: 16495887 | F60: 3687996.8
...

Sheet Scenarios
B2: Current Situation
B3: Selection | D3: Prompt for fundamental Analysis
B4: Past Years Selected | C4: 2 | D4: ="DCF Model Inputs for " & Thesis!C5 & " – " & Thesis!C4 & ": Please develop Base, Pessimistic, and Optimistic scenarios under the following unified framework. " & "Assume a consistent high-growth period across all cases, with each scenario using a single FCFE CAGR during this phase. " & "Apply a two-stage model only if there is a material shift in FCFE margin or growth, and ensure this structure is used consistently across scenarios. " & "Margins should remain constant within each stage and be identical across all scenarios; any variation in outlook should be reflected through adjustments to the growth rate, not the margin. " & "Terminal growth is fixed at 0%, so modify the high-growth duration or rate accordingly to reflect long-term expectations. " & "Specify the FCFE margin (stage-specific if applicable) for all scenarios. " & "For each scenario, specify the FCFE CAGR during the high-growth period. Accompany each with a concise business narrative and respective probability explaining the key drivers behind the scenario." -> DCF Model Inputs for 0639.HK – 首钢资源: Please develop Base, Pessimistic, and Optimistic scenarios under the following unified framework. Assume a consistent high-growth period across all cases, with each scenario using a single FCFE CAGR during this phase. Apply a two-stage model only if there is a material shift in FCFE margin or growth, and ensure this structure is used consistently across scenarios. Margins should remain constant within each stage and be identical across all scenarios; any variation in outlook should be reflected through adjustments to the growth rate, not the margin. Terminal growth is fixed at 0%, so modify the high-growth duration or rate accordingly to reflect long-term expectations. Specify the FCFE margin (stage-specific if applicable) for all scenarios. For each scenario, specify the FCFE CAGR during the high-growth period. Accompany each with a concise business narrative and respective probability explaining the key drivers behind the scenario.
B6: Latest | C6: =DCF!C3&" "&Reporting_currency -> 1000 HKD
B7: EBIT | C7: =Normalized_FCF!G8 -> 2269323
B8: FCFE | C8: =Normalized_FCF!G19 -> 1274305
B9: Normalized | C9: =Normalized_FCF!C19 -> 1097140.1
B11: YoY CAGR
B12: Sales | C12: =(Normalized_FCF!G4/OFFSET(Normalized_FCF!G4, 0, $C$4))^(1/$C$4) - 1 -> -0.21539672
B13: Operating EBIT | C13: =(Normalized_FCF!G8/OFFSET(Normalized_FCF!G8, 0, $C$4))^(1/$C$4) - 1 -> -0.30758333
B14: FCFE | C14: =(Normalized_FCF!G19/OFFSET(Normalized_FCF!G19, 0, $C$4))^(1/$C$4) - 1 -> -0.33056173
B16: Scenarios Analysis
B17: Assumption | E17: Note on Manual Adjustments
B18: High Growth Period (HGP) | C18: 3 | E18: accepts 5-10, 15, 20, 25, or 30
B20: General Scenarios
B21: Scenarios | C21: HGR | D21: HGP | E21: ="Value per share ("&Market_currency&")" -> Value per share (HKD) | F21: Probabilities | G21: Adj. Probabilities
B22: Optimistic | C22: 0.02 | D22: =C18 -> 3 | E22: =DCF!E91 -> 4.7614346 | F22: =1-F23-F24 -> 0.2 | G22: =F22*(1-F$29-F$30) -> 0.16
B23: Base | C23: 0 | D23: =C18 -> 3 | E23: =DCF!E92 -> 4.5928254 | F23: 0.55 | G23: =F23*(1-F$29-F$30) -> 0.44
B24: Pessimistic | C24: -0.15 | D24: =C18 -> 3 | E24: =DCF!E93 -> 3.5208425 | F24: 0.25 | G24: =F24*(1-F$29-F$30) -> 0.2
B25: Under General Scenario | C25: =E23*F23+E24*F24+E22*F22 -> 4.3585515 | D25: =Market_currency -> HKD
B27: Extreme Scenarios
B28: Scenarios | C28: HGR | D28: HGP | E28: ="Value per share ("&Market_currency&")" -> Value per share (HKD) | F28: Probabilities | G28: Adj. Probabilities
B29: Snowball Scenario | C29: -0.3 | D29: =C18 -> 3 | E29: =DCF!E90 -> 2.7517572 | F29: 0.15 | G29: =F29 -> 0.15
B30: Devil's advocate | C30: 0.04 | D30: =C18 -> 3 | E30: =DCF!E94 -> 4.9364759 | F30: 0.05 | G30: =F30 -> 0.05
B32: Conclusion
B33: Annual Dividend per share | C33: =Normalized_FCF!C88*(1-dividend_tax_rate) -> 0.27 | D33: =Market_currency -> HKD | E33: With a holding period of | F33: =Holding_Period -> 3
B34: Market Price | C34: =Market_Price -> 3.16 | D34: =Market_currency -> HKD | E34: Implied Annual Return | F34: =RATE(Holding_Period,$C$33,-C34,$C$36) -> 0.17337144
B35: No-g Model Value per share | C35: =DCF!C11 -> 4.5928254 | D35: =Market_currency -> HKD | E35: Implied Annual Return | F35: =RATE(Holding_Period,$C$33,-C35,$C$36) -> 0.027256442
B36: g Model Value per share | C36: =E22*G22+E23*G23+E24*G24+E30*G30+E29*G29 -> 4.1464286 | D36: =Market_currency -> HKD | E36: is assumed to be the | F36: Expected Value
B38: Stage II Normalized Values
B39: =IF(DCF!F14="II","2","1")&"-stage DCF" -> 1-stage DCF | E39: Note on Manual Adjustments
B40: Contribution Margin_II | C40: =DCF!C17 -> 0.53643826 | E40: Try obtain this number by reverse engineering.
B41: High Growth Rate_II | C41: =DCF!C16 -> 0.0013
B43: Growth Classification
B44: Equity Value Driving Factors | E44: Note on Manual Adjustments
B45: High Growth Period (HGP) | C45: =C18 -> 3 | E45: Use general Scenarios' HGP assumption
B46: High Growth Rate (HGR) | C46: 0.0013 | E46: Use Excel Goal Seek to find the HGR
B47: Equity Value per share | C47: =DCF!I18 -> 4.603592 | D47: =Market_currency -> HKD | E47: Set to Expected Equity Value
B49: Type of Company | E49: Note on the logic
B50: Negative Growth | C50: =IF(C36<C35,"Y","N") -> Y
...

Sheet 投资主题
A2: 执行摘要
E3: 更新日期: | F3: =Thesis!F3 -> 45930
B4: 公司： | C4: =Thesis!C4 -> 首钢资源 | E4: 组合: | F4: =Thesis!F4 -> INT
B5: 股票代码： | C5: =Thesis!C5 -> 0639.HK | E5: 精选: | F5: =Thesis!F5 -> Y
B6: 对比板块: | C6: =Thesis!C6 -> MAT_01
B7: 市价货币： | C7: =Market_currency -> HKD
B8: 市场价格： | C8: =Market_Price -> 3.16
B9: 股份数量： | C9: =Common_Shares -> 5091065770
B10: 市值： | C10: =投资主题!C8*Common_Shares/1000000 -> 16087.768 | D10: 隐含年回报率: | E10: =Scenarios!F34 -> 0.17337144
B12: 指导说明：该模型使用结构化的投资流程来评估公司，确定其内在价值和目标价格。它关注可持续的自由现金流（FCF）能力，调整财务结构，纳入增长情景，并根据得出的内在价值计算预期回报。
B14: 估值概述
B15: 商业模式风险溢价: | C15: =Thesis!C15 -> N | D15: 外汇符号： | E15: =IF(E17=C7,C7,E17&"/"&C7) -> HKD
B16: 管理风险溢价: | C16: =Thesis!C16 -> N | D16: 汇率： | E16: =Exchange_Rate -> 1
B17: 永续增长率 (g) = | C17: =Terminal_Growth -> 0 | D17: 报告货币: | E17: =Reporting_currency -> HKD
B18: ="预期股权价值 ("&C7&") :" -> 预期股权价值 (HKD) : | C18: =C125 -> 4.1464286 | D18: 报告间隔： | E18: =Thesis!E18 -> 6
B19: 增长分类: | C19: =IF(Scenarios!C50="Y",Scenarios!B50,"")&IF(Scenarios!C51="Y",Scenarios!B51,"")&IF(Scenarios!C52="Y",Scenarios!B52,"")&" "&IF(Scenarios!C53="Y",Scenarios!B53,"") -> Negative Growth | D19: 下次更新日期： | E19: =EOMONTH(EDATE(BS!C1,E18+2),0) -> 46081
B21: 投资决策 | C21: =C138&" ("&Market_currency&")" -> (HKD) | D21: 持有期 | E21: =Holding_Period -> 3
B22: 目标价格 | C22: =E140 -> 2.4048565 | D22: @目标回报率 | E22: =Thesis!E22 -> 0.29465259
B23: 入场价格 | C23: =E141 -> 2.9631301 | D23: @入场收益率 | E23: =Thesis!E23 -> 0.20075184
B24: 退出价格 | C24: =E144 -> 3.6233986 | D24: @基准收益率 | E24: =Thesis!E24 -> 0.1174
B25: 卖出价格 | C25: =E145 -> 4.0664479 | D25: @基础Equity Cost | E25: =Thesis!E25 -> 0.0725
A27: 步骤1：确定公司可持续盈利能力（计算标准化FCFE）
B29: 目标：量化业务持续生成的潜在自由现金流（FCFE），去除临时波动或会计选择的影响。
B30: FCFE = (Normalized Operating EBIT + Depreciation & Amortization – Capital Expenditures) + Stable Non-Operating EBIT + Net Interest Income – Taxes – NCI’s Share of Profits – Working Capital Investment
B32: 关键组成部分 | C32: =scaling_factor -> 1000
B33: • Normalized Operating EBIT：核心业务运营的税前息前利润，调整以剔除一次性或非经常性项目，形成可持续盈利基础。
B34: Normalized Operating EBIT = | C34: =Normalized_FCF!C8 -> 1900909.5 | D34: =Reporting_currency -> HKD
B36: • Depreciation & Amortization (D&A): 非现金费用，加入以反映运营产生的现金。 • Capital Expenditures (Capex): 维持或扩展运营资产所需的现金流出。
B37: D&A = | C37: =Normalized_FCF!C15 -> 0 | D37: =Reporting_currency -> HKD
B38: Capex = | C38: =Normalized_FCF!C16 -> 0 | D38: =Reporting_currency -> HKD
B40: • Stable Non-Operating EBIT: 来自非核心资产的持续收益，如固定收益投资、支付股息的股票或租赁物业。
B41: Stable Non-Operating EBIT = | C41: =Normalized_FCF!C9 -> 0 | D41: =Reporting_currency -> HKD
B43: • Net Interest Income: 利息收入减去利息支出
B44: Operating Interest Income = | C44: =Normalized_FCF!C46 -> 12533.131 | D44: =Reporting_currency -> HKD
B45: Interest Expense = | C45: =Normalized_FCF!C45 -> -2620.62 | D45: =Reporting_currency -> HKD
B46: Net Interest Income = | C46: =Normalized_FCF!C10 -> 9912.5106 | D46: =Reporting_currency -> HKD
B48: • NCI’s Share of Profits: NCI代表子公司中母公司未拥有的股权部分。
B49: Est. NCI’s Share of Profits = | C49: =Normalized_FCF!C13 -> -335976.4 | D49: =Reporting_currency -> HKD
B51: • Taxes: Tax = (Normalized Operating EBIT + Stable Non-Operating EBIT + Interest Income – Interest Expense) × Tax Rate
B52: Taxes = | C52: =Normalized_FCF!C12 -> -477705.51 | D52: =Reporting_currency -> HKD
...
