Workbook
Name Common_Shares: Thesis!$C$11
Name Equity_Cost: Valuation_Model!$C$5
Name Exchange_Rate: Thesis!$C$13
Name Market_currency: Thesis!$D$10
Name Market_Price: Thesis!$C$10
Name Reporting_currency: Thesis!$C$12
Name Terminal_Growth: Valuation_Model!$F$4

Sheet Thesis
B1: Investment Thesis for | C1: 首程控股 | D1: 0697.HK
B2: Model last updated: | C2: 45643 | E2: Status: Not Held
A3: Introduction
B4: Comapny Information
B5: Comp_Sector: | C5: C0008
B6: Review Interval: | C6: 8
B7: Review Date: | C7: =EOMONTH(EDATE(BS!C1,Thesis!C6),0) -> 45716
B9: =D1&" Stock Information" -> 0697.HK Stock Information
B10: Market Price: | C10: 1.7 | D10: HKD
B11: Number of Shares: | C11: 7286015440
B12: Reporting Currency: | C12: CNY
B13: Exchange Rate: | C13: 1.06 | D13: =IF(C12=D10,D10,C12&"/"&D10) -> CNY/HKD
B14: Capitalization: | C14: =Thesis!C10*Thesis!C11/1000000 -> 12386.226
A16: Stock Analysis
A18: ="1." -> 1. | B18: Adjusted FCFE Calculation
B19: Formula:
B20: Adjusted FCFE = Net Income + D&A – Maintenance Capex ± WCInv (if material).
B22: Variables | C22: =Data!C3 -> 1000
B23: Operating after-tax Profit = | C23: =Normalized_FCF!C16 -> 203787.93 | D23: =C12 -> CNY
B24: Non-Operating after-tax Profit = | C24: =Normalized_FCF!C11 -> 124963.87
B25: Net Income = | C25: =C23+C24 -> 328751.8
B27: Adjusted FCFE = | C27: =Normalized_FCF!C19 -> 203787.93
B28: Adjusted FCFE per share = | C28: =C27/(Common_Shares/Data!C3) -> 0.027969737
B29: FCFE/Market Price = | C29: =C28/Market_Price -> 0.016452786
B31: Notes:
B32: 1. the model explicitly avoids aggressive growth assumptions and prioritizes downside protection.
B33: 2. Net borrowing is excluded (fixed at 0), and WCInv is only included if it materially distorts FCFE (>5% volatility).
B34: 3. Normalization: 5-year averages will smooth cyclicality for 590.HK.
A36: ="2." -> 2. | B36: Equity Cost of Capital (Buffett Method)
B37: Equity Cost of Capital (r) = | C37: 0.1
B39: Qualitative Adjustments
B40: Nonexistent moats | C40: 0 | D40: HK
B41: Weak balance sheets | C41: 0 | D41: Stable Business
B42: Poor management | C42: 0
B43: Qualitative Adjustments | C43: =SUM(C40:C42) -> 0
A45: ="3." -> 3. | B45: No-Growth DCF Valuation
B46: Key Metrics:
B47: Adjusted Earnings Yield = Adjusted FCFE / Market Cap.
B48: Intrinsic Value (No Growth) = Adjusted FCFE / Equity Cost of Capital.
B50: Decision Rule:
...

Sheet Data
B1: =Thesis!C12 -> CNY | C1: 45291 | D1: =EOMONTH(EDATE(C1,-12),0) -> 44926 | E1: =EOMONTH(EDATE(D1,-12),0) -> 44561 | F1: =EOMONTH(EDATE(E1,-12),0) -> 44196 | G1: =EOMONTH(EDATE(F1,-12),0) -> 43830 | H1: =EOMONTH(EDATE(G1,-12),0) -> 43465 | I1: =EOMONTH(EDATE(H1,-12),0) -> 43100 | J1: =EOMONTH(EDATE(I1,-12),0) -> 42735 | K1: =EOMONTH(EDATE(J1,-12),0) -> 42369 | ... M1: =EOMONTH(EDATE(L1,-12),0) -> 41639
B2: Data (Dirty)
B3: Income Statement | C3: 1000
B4: Sales | C4: 883478 | D4: 1599809 | E4: 1195031 | F4: 705854 | G4: 396091 | H4: 1676296
B5: COGS | C5: 523759 | D5: 535391 | E5: 647828 | F5: 531460 | G5: 193695 | H5: 1515759
B6: OPEX | C6: 299979 | D6: 378568 | E6: 343154 | F6: 250972 | G6: 231174 | H6: 164177
B7: Incl. Selling Expenses
B8: R&D
B9: Share of JV or associate Results | C9: =-31502-31381 -> -62883 | D9: =499-60820 -> -60321
B10: Dividend or Interests from FA | C10: 328373 | D10: 414899
B11: Investment property
B12: Interest Expense | C12: 105689 | D12: 102356 | E12: 74343 | F12: 77168 | G12: 27358 | H12: 5699
B13: Interest Income | C13: 127073 | D13: 62873
B14: Income Tax Paid | C14: 6906 | D14: 269091
B15: Reported Net Income | C15: 459545 | D15: 914347
B16: Non-controling Interests | C16: 55980 | D16: -7663
B18: Cash Flow Statement
B19: D&A | C19: 35974 | D19: 32106 | E19: 181.018 | F19: 186.147
B20: CAPX | C20: 15312 | D20: 11600
B21: WCInv | C21: -169280 | D21: -50846
B22: ="Dividend per share ("&Market_currency&")" -> Dividend per share (HKD) | C22: 0.0548 | D22: 0.0952
B24: Balance Sheet
B25: ST AR
B26: ST Inventory
B27: Total Liabilities | C27: 642877 | D27: 734909 | E27: 677999 | F27: 1352795 | G27: 1205068
B28: Total Equity | C28: 3027292 | D28: 2824568 | E28: 2735259 | F28: 250534 | G28: 13930
B30: Other Data
B31: Contingent Liabilities | D31: 18682 | E31: 61277 | F31: 51229 | G31: 23195
B33: IS & CF Statements (Clean)
B34: Income Statement
B35: Sales | C35: =IF(C$4="","",C4) -> 883478 | D35: =IF(D$4="","",D4) -> 1599809 | E35: =IF(E$4="","",E4) -> 1195031 | F35: =IF(F$4="","",F4) -> 705854 | G35: =IF(G$4="","",G4) -> 396091 | H35: =IF(H$4="","",H4) -> 1676296 | I35: =IF(I$4="","",I4) | J35: =IF(J$4="","",J4) | ... M35: =IF(M$4="","",M4)
B36: COGS | C36: =IF(C$4="","",-C5) -> -523759 | D36: =IF(D$4="","",-D5) -> -535391 | E36: =IF(E$4="","",-E5) -> -647828 | F36: =IF(F$4="","",-F5) -> -531460 | G36: =IF(G$4="","",-G5) -> -193695 | H36: =IF(H$4="","",-H5) -> -1515759 | I36: =IF(I$4="","",-I5) | J36: =IF(J$4="","",-J5) | ... M36: =IF(M$4="","",-M5)
B37: Gross Margin | C37: =IF(C35="","",C35+C36) -> 359719 | D37: =IF(D35="","",D35+D36) -> 1064418 | E37: =IF(E35="","",E35+E36) -> 547203 | F37: =IF(F35="","",F35+F36) -> 174394 | G37: =IF(G35="","",G35+G36) -> 202396 | H37: =IF(H35="","",H35+H36) -> 160537 | I37: =IF(I35="","",I35+I36) | J37: =IF(J35="","",J35+J36) | ... M37: =IF(M35="","",M35+M36)
B38: OPEX | C38: =IF(C$4="","",-C6) -> -299979 | D38: =IF(D$4="","",-D6) -> -378568 | E38: =IF(E$4="","",-E6) -> -343154 | F38: =IF(F$4="","",-F6) -> -250972 | G38: =IF(G$4="","",-G6) -> -231174 | H38: =IF(H$4="","",-H6) -> -164177 | I38: =IF(I$4="","",-I6) | J38: =IF(J$4="","",-J6) | ... M38: =IF(M$4="","",-M6)
B39: Incl. Selling Expenses | C39: =IF(C$4="","",-C7) -> 0 | D39: =IF(D$4="","",-D7) -> 0 | E39: =IF(E$4="","",-E7) -> 0 | F39: =IF(F$4="","",-F7) -> 0 | G39: =IF(G$4="","",-G7) -> 0 | H39: =IF(H$4="","",-H7) -> 0 | I39: =IF(I$4="","",-I7) | J39: =IF(J$4="","",-J7) | ... M39: =IF(M$4="","",-M7)
B40: Incl. Other Opex | C40: =IF(C$4="","",C38-C39) -> -299979 | D40: =IF(D$4="","",D38-D39) -> -378568 | E40: =IF(E$4="","",E38-E39) -> -343154 | F40: =IF(F$4="","",F38-F39) -> -250972 | G40: =IF(G$4="","",G38-G39) -> -231174 | H40: =IF(H$4="","",H38-H39) -> -164177 | I40: =IF(I$4="","",I38-I39) | J40: =IF(J$4="","",J38-J39) | ... M40: =IF(M$4="","",M38-M39)
B41: R&D | C41: =IF(C$4="","",-C8) -> 0 | D41: =IF(D$4="","",-D8) -> 0 | E41: =IF(E$4="","",-E8) -> 0 | F41: =IF(F$4="","",-F8) -> 0 | G41: =IF(G$4="","",-G8) -> 0 | H41: =IF(H$4="","",-H8) -> 0 | I41: =IF(I$4="","",-I8) | J41: =IF(J$4="","",-J8) | ... M41: =IF(M$4="","",-M8)
B42: Operating EBIT | C42: =IF(C$4="","",C37+C38+C41) -> 59740 | D42: =IF(D$4="","",D37+D38+D41) -> 685850 | E42: =IF(E$4="","",E37+E38+E41) -> 204049 | F42: =IF(F$4="","",F37+F38+F41) -> -76578 | G42: =IF(G$4="","",G37+G38+G41) -> -28778 | H42: =IF(H$4="","",H37+H38+H41) -> -3640 | I42: =IF(I$4="","",I37+I38+I41) | J42: =IF(J$4="","",J37+J38+J41) | ... M42: =IF(M$4="","",M37+M38+M41)
B43: Non-operating EBIT | C43: =IF(C$4="","",C46-C45-C44-C42) -> 385327 | D43: =IF(D$4="","",D46-D45-D44-D42) -> 537071 | E43: =IF(E$4="","",E46-E45-E44-E42) -> -129706 | F43: =IF(F$4="","",F46-F45-F44-F42) -> 153746 | G43: =IF(G$4="","",G46-G45-G44-G42) -> 56136 | H43: =IF(H$4="","",H46-H45-H44-H42) -> 9339 | I43: =IF(I$4="","",I46-I45-I44-I42) | J43: =IF(J$4="","",J46-J45-J44-J42) | ... M43: =IF(M$4="","",M46-M45-M44-M42)
B44: Net Interest Income | C44: =IF(C$4="","",C50+C51) -> 21384 | D44: =IF(D$4="","",D50+D51) -> -39483 | E44: =IF(E$4="","",E50+E51) -> -74343 | F44: =IF(F$4="","",F50+F51) -> -77168 | G44: =IF(G$4="","",G50+G51) -> -27358 | H44: =IF(H$4="","",H50+H51) -> -5699 | I44: =IF(I$4="","",I50+I51) | J44: =IF(J$4="","",J50+J51) | ... M44: =IF(M$4="","",M50+M51)
...

Sheet Normalized_FCF
B1: =Thesis!C12 -> CNY | C1: Normalized | G1: =Data!C1 -> 45291 | H1: =EOMONTH(EDATE(G1,-12),0) -> 44926 | I1: =EOMONTH(EDATE(H1,-12),0) -> 44561 | J1: =EOMONTH(EDATE(I1,-12),0) -> 44196 | K1: =EOMONTH(EDATE(J1,-12),0) -> 43830 | L1: =EOMONTH(EDATE(K1,-12),0) -> 43465 | M1: =EOMONTH(EDATE(L1,-12),0) -> 43100 | N1: =EOMONTH(EDATE(M1,-12),0) -> 42735 | O1: =EOMONTH(EDATE(N1,-12),0) -> 42369 | ... Q1: =EOMONTH(EDATE(P1,-12),0) -> 41639
B2: FCFE Analysis | E2: Notes
B3: Adjusted FCFE | C3: =Data!C3 -> 1000
B4: Sales | C4: =AVERAGE(G4:I4) -> 1226106 | E4: Historical Average | G4: =Data!C35 -> 883478 | H4: =Data!D35 -> 1599809 | I4: =Data!E35 -> 1195031 | J4: =Data!F35 -> 705854 | K4: =Data!G35 -> 396091 | L4: =Data!H35 -> 1676296 | M4: =Data!I35 | N4: =Data!J35 | ... Q4: =Data!M35
B5: Variable Costs | C5: =C49 -> -738887.81 | G5: =G49 -> -523759 | H5: =H49 -> -535391 | I5: =I49 -> -647828 | J5: =J49 -> -531460 | K5: =K49 -> -193695 | L5: =L49 -> -1515759 | M5: =M49 | N5: =N49 | ... Q5: =Q49
B6: Contribution Margin | C6: =C4+C5 -> 487218.19 | G6: =IF(G4="","",G4+G5) -> 359719 | H6: =IF(H4="","",H4+H5) -> 1064418 | I6: =IF(I4="","",I4+I5) -> 547203 | J6: =IF(J4="","",J4+J5) -> 174394 | K6: =IF(K4="","",K4+K5) -> 202396 | L6: =IF(L4="","",L4+L5) -> 160537 | M6: =IF(M4="","",M4+M5) | N6: =IF(N4="","",N4+N5) | ... Q6: =IF(Q4="","",Q4+Q5)
B7: Fixed Costs | C7: =C52 -> -339273.5 | G7: =G52 -> -299979 | H7: =H52 -> -378568 | I7: =I52 -> -343154 | J7: =J52 -> -250972 | K7: =K52 -> -231174 | L7: =L52 -> -164177 | M7: =M52 | N7: =N52 | ... Q7: =Q52
B8: Add Back D&A | C8: =BS!$G$29*BS!C43 -> 35974 | G8: =IF(Data!C60="","",-Data!C60) -> 35974 | H8: =IF(Data!D60="","",-Data!D60) -> 32106 | I8: =IF(Data!E60="","",-Data!E60) -> 181.018 | J8: =IF(Data!F60="","",-Data!F60) -> 186.147 | K8: =IF(Data!G60="","",-Data!G60) -> 0 | L8: =IF(Data!H60="","",-Data!H60) -> 0 | M8: =IF(Data!I60="","",-Data!I60) | N8: =IF(Data!J60="","",-Data!J60) | ... Q8: =IF(Data!M60="","",-Data!M60)
B9: Maintenance Capex | C9: =-C4*C31 -> -35974 | G9: =Data!C61 -> -15312 | H9: =Data!D61 -> -11600 | I9: =Data!E61 -> 0 | J9: =Data!F61 -> 0 | K9: =Data!G61 -> 0 | L9: =Data!H61 -> 0 | M9: =Data!I61 | N9: =Data!J61 | ... Q9: =Data!M61
B10: Operating EBIT | C10: =SUM(C6:C9) -> 147944.69 | G10: =IF(G$4="","",SUM(G6:G9)) -> 80402 | H10: =IF(H$4="","",SUM(H6:H9)) -> 706356 | I10: =IF(I$4="","",SUM(I6:I9)) -> 204230.02 | J10: =IF(J$4="","",SUM(J6:J9)) -> -76391.853 | K10: =IF(K$4="","",SUM(K6:K9)) -> -28778 | L10: =IF(L$4="","",SUM(L6:L9)) -> -3640 | M10: =IF(M$4="","",SUM(M6:M9)) | N10: =IF(N$4="","",SUM(N6:N9)) | ... Q10: =IF(Q$4="","",SUM(Q6:Q9))
B11: Non-Operating EBIT | C11: =C67 -> 124963.87 | E11: Stable Non-Operating CF | G11: =G67 -> 385327 | H11: =H67 -> 537071 | I11: =I67 -> -129706 | J11: =J67 -> 153746 | K11: =K67 -> 56136 | L11: =L67 -> 9339 | M11: =M67 | N11: =N67 | ... Q11: =Q67
B12: Net Interest Income | C12: =C78 -> 14989.54 | G12: =G78 -> 21384 | H12: =H78 -> -39483 | I12: =I78 -> -74343 | J12: =J78 -> -77168 | K12: =K78 -> -27358 | L12: =L78 -> -5699 | M12: =M78 | N12: =N78 | ... Q12: =Q78
B13: Pre-tax Profit | C13: =SUM(C10:C12) -> 287898.1 | G13: =IF(G$4="","",SUM(G10:G12)) -> 487113 | H13: =IF(H$4="","",SUM(H10:H12)) -> 1203944 | I13: =IF(I$4="","",SUM(I10:I12)) -> 181.018 | J13: =IF(J$4="","",SUM(J10:J12)) -> 186.147 | K13: =IF(K$4="","",SUM(K10:K12)) -> 0 | L13: =IF(L$4="","",SUM(L10:L12)) -> 0 | M13: =IF(M$4="","",SUM(M10:M12)) | N13: =IF(N$4="","",SUM(N10:N12)) | ... Q13: =IF(Q$4="","",SUM(Q10:Q12))
B14: Income Tax | C14: =-C13*C36 -> -71974.524 | G14: =Data!C45 -> -6906 | H14: =Data!D45 -> -269091 | I14: =Data!E45 -> 0 | J14: =Data!F45 -> 0 | K14: =Data!G45 -> 0 | L14: =Data!H45 -> 0 | M14: =Data!I45 | N14: =Data!J45 | ... Q14: =Data!M45
B15: Non-controling Interests | C15: =-C4*C33 -> -12135.639 | G15: =Data!C47 -> -55980 | H15: =Data!D47 -> 0 | I15: =Data!E47 -> 0 | J15: =Data!F47 -> 0 | K15: =Data!G47 -> 0 | L15: =Data!H47 -> 0 | M15: =Data!I47 | N15: =Data!J47 | ... Q15: =Data!M47
B16: After-tax Profit | C16: =SUM(C13:C15) -> 203787.93 | G16: =IF(G$4="","",SUM(G13:G15)) -> 424227 | H16: =IF(H$4="","",SUM(H13:H15)) -> 934853 | I16: =IF(I$4="","",SUM(I13:I15)) -> 181.018 | J16: =IF(J$4="","",SUM(J13:J15)) -> 186.147 | K16: =IF(K$4="","",SUM(K13:K15)) -> 0 | L16: =IF(L$4="","",SUM(L13:L15)) -> 0 | M16: =IF(M$4="","",SUM(M13:M15)) | N16: =IF(N$4="","",SUM(N13:N15)) | ... Q16: =IF(Q$4="","",SUM(Q13:Q15))
B17: WCInv | C17: =-C4*C32 -> 0 | E17: WCInv is excluded
B18: Net Borrowing | C18: 0 | E18: Net borrowing is excluded
B19: Total FCFE | C19: =SUM(C16:C18) -> 203787.93 | G19: =IF(G$4="","",SUM(G16:G18)) -> 424227 | H19: =IF(H$4="","",SUM(H16:H18)) -> 934853 | I19: =IF(I$4="","",SUM(I16:I18)) -> 181.018 | J19: =IF(J$4="","",SUM(J16:J18)) -> 186.147 | K19: =IF(K$4="","",SUM(K16:K18)) -> 0 | L19: =IF(L$4="","",SUM(L16:L18)) -> 0 | M19: =IF(M$4="","",SUM(M16:M18)) | N19: =IF(N$4="","",SUM(N16:N18)) | ... Q19: =IF(Q$4="","",SUM(Q16:Q18))
B21: % Sales
B22: Variable Costs | C22: =ABS(C5/C$4) -> 0.60262963 | G22: =IF(G$4="","",ABS(G5/G$4)) -> 0.59283763 | H22: =IF(H$4="","",ABS(H5/H$4)) -> 0.33465932 | I22: =IF(I$4="","",ABS(I5/I$4)) -> 0.54210142 | J22: =IF(J$4="","",ABS(J5/J$4)) -> 0.75293191 | K22: =IF(K$4="","",ABS(K5/K$4)) -> 0.48901641 | L22: =IF(L$4="","",ABS(L5/L$4)) -> 0.90423111 | M22: =IF(M$4="","",ABS(M5/M$4)) | N22: =IF(N$4="","",ABS(N5/N$4)) | ... Q22: =IF(Q$4="","",ABS(Q5/Q$4))
B23: Contribution Margin | C23: =ABS(C6/C$4) -> 0.39737037 | G23: =IF(G$4="","",ABS(G6/G$4)) -> 0.40716237 | H23: =IF(H$4="","",ABS(H6/H$4)) -> 0.66534068 | I23: =IF(I$4="","",ABS(I6/I$4)) -> 0.45789858 | J23: =IF(J$4="","",ABS(J6/J$4)) -> 0.24706809 | K23: =IF(K$4="","",ABS(K6/K$4)) -> 0.51098359 | L23: =IF(L$4="","",ABS(L6/L$4)) -> 0.095768886 | M23: =IF(M$4="","",ABS(M6/M$4)) | N23: =IF(N$4="","",ABS(N6/N$4)) | ... Q23: =IF(Q$4="","",ABS(Q6/Q$4))
B24: Fixed Costs | C24: =ABS(C7/C$4) -> 0.27670813 | G24: =IF(G$4="","",ABS(G7/G$4)) -> 0.33954326 | H24: =IF(H$4="","",ABS(H7/H$4)) -> 0.23663325 | I24: =IF(I$4="","",ABS(I7/I$4)) -> 0.28715071 | J24: =IF(J$4="","",ABS(J7/J$4)) -> 0.35555795 | K24: =IF(K$4="","",ABS(K7/K$4)) -> 0.58363861 | L24: =IF(L$4="","",ABS(L7/L$4)) -> 0.09794034 | M24: =IF(M$4="","",ABS(M7/M$4)) | N24: =IF(N$4="","",ABS(N7/N$4)) | ... Q24: =IF(Q$4="","",ABS(Q7/Q$4))
B25: Operating EBIT | C25: =ABS(C10/C$4) -> 0.12066223 | G25: =IF(G$4="","",ABS(G10/G$4)) -> 0.091006228 | H25: =IF(H$4="","",ABS(H10/H$4)) -> 0.44152521 | I25: =IF(I$4="","",ABS(I10/I$4)) -> 0.17089935 | J25: =IF(J$4="","",ABS(J10/J$4)) -> 0.10822614 | K25: =IF(K$4="","",ABS(K10/K$4)) -> 0.072655021 | L25: =IF(L$4="","",ABS(L10/L$4)) -> 0.0021714542 | M25: =IF(M$4="","",ABS(M10/M$4)) | N25: =IF(N$4="","",ABS(N10/N$4)) | ... Q25: =IF(Q$4="","",ABS(Q10/Q$4))
B26: Net Interest Income | C26: =ABS(C12/C$4) -> 0.012225321 | G26: =IF(G$4="","",ABS(G12/G$4)) -> 0.024204338 | H26: =IF(H$4="","",ABS(H12/H$4)) -> 0.024679821 | I26: =IF(I$4="","",ABS(I12/I$4)) -> 0.062210102 | J26: =IF(J$4="","",ABS(J12/J$4)) -> 0.10932572 | K26: =IF(K$4="","",ABS(K12/K$4)) -> 0.069069986 | L26: =IF(L$4="","",ABS(L12/L$4)) -> 0.0033997576 | M26: =IF(M$4="","",ABS(M12/M$4)) | N26: =IF(N$4="","",ABS(N12/N$4)) | ... Q26: =IF(Q$4="","",ABS(Q12/Q$4))
B27: Income Tax | C27: =ABS(C14/C$4) -> 0.058701714 | G27: =IF(G$4="","",ABS(G14/G$4)) -> 0.007816833 | H27: =IF(H$4="","",ABS(H14/H$4)) -> 0.16820195 | I27: =IF(I$4="","",ABS(I14/I$4)) -> 0 | J27: =IF(J$4="","",ABS(J14/J$4)) -> 0 | K27: =IF(K$4="","",ABS(K14/K$4)) -> 0 | L27: =IF(L$4="","",ABS(L14/L$4)) -> 0 | M27: =IF(M$4="","",ABS(M14/M$4)) | N27: =IF(N$4="","",ABS(N14/N$4)) | ... Q27: =IF(Q$4="","",ABS(Q14/Q$4))
C28: =ABS(C16/C$4) -> 0.16620743 | G28: =IF(G$4="","",ABS(G16/G$4)) -> 0.48017834 | H28: =IF(H$4="","",ABS(H16/H$4)) -> 0.58435288 | I28: =IF(I$4="","",ABS(I16/I$4)) -> 0.00015147557 | J28: =IF(J$4="","",ABS(J16/J$4)) -> 0.00026371884 | K28: =IF(K$4="","",ABS(K16/K$4)) -> 0 | L28: =IF(L$4="","",ABS(L16/L$4)) -> 0 | M28: =IF(M$4="","",ABS(M16/M$4)) | N28: =IF(N$4="","",ABS(N16/N$4)) | ... Q28: =IF(Q$4="","",ABS(Q16/Q$4))
B29: Non-Operating Income | C29: =ABS(C11/C$4) -> 0.1019193 | G29: =IF(G$4="","",G11/G$4) -> 0.43614782 | H29: =IF(H$4="","",H11/H$4) -> 0.33570945 | I29: =IF(I$4="","",I11/I$4) -> -0.10853777 | J29: =IF(J$4="","",J11/J$4) -> 0.21781558 | K29: =IF(K$4="","",K11/K$4) -> 0.14172501 | L29: =IF(L$4="","",L11/L$4) -> 0.0055712118 | M29: =IF(M$4="","",M11/M$4) | N29: =IF(N$4="","",N11/N$4) | ... Q29: =IF(Q$4="","",Q11/Q$4)
B30: Add Back D&A | C30: =ABS(C8/C$4) -> 0.029340041 | G30: =IF(G$4="","",G8/G$4) -> 0.040718614 | H30: =IF(H$4="","",H8/H$4) -> 0.020068646 | I30: =IF(I$4="","",I8/I$4) -> 0.00015147557 | J30: =IF(J$4="","",J8/J$4) -> 0.00026371884 | K30: =IF(K$4="","",K8/K$4) -> 0 | L30: =IF(L$4="","",L8/L$4) -> 0 | M30: =IF(M$4="","",M8/M$4) | N30: =IF(N$4="","",N8/N$4) | ... Q30: =IF(Q$4="","",Q8/Q$4)
B31: Maintenance Capex | C31: =MAX(AVERAGE(G31:J31),C30) -> 0.029340041 | E31: Historical Average or D&A | G31: =IF(G$4="","",-G9/G$4) -> 0.017331501 | H31: =IF(H$4="","",-H9/H$4) -> 0.0072508656 | I31: =IF(I$4="","",-I9/I$4) -> 0 | J31: =IF(J$4="","",-J9/J$4) -> 0 | K31: =IF(K$4="","",-K9/K$4) -> 0 | L31: =IF(L$4="","",-L9/L$4) -> 0 | M31: =IF(M$4="","",-M9/M$4) | N31: =IF(N$4="","",-N9/N$4) | ... Q31: =IF(Q$4="","",-Q9/Q$4)
B32: WCInv | C32: =MIN(AVERAGE(G32:J32)/2,0) -> 0 | E32: WCInv effect is reduced | G32: =IF(G$4="","",-G17/G$4) -> 0 | H32: =IF(H$4="","",-H17/H$4) -> 0 | I32: =IF(I$4="","",-I17/I$4) -> 0 | J32: =IF(J$4="","",-J17/J$4) -> 0 | K32: =IF(K$4="","",-K17/K$4) -> 0 | L32: =IF(L$4="","",-L17/L$4) -> 0 | M32: =IF(M$4="","",-M17/M$4) | N32: =IF(N$4="","",-N17/N$4) | ... Q32: =IF(Q$4="","",-Q17/Q$4)
B33: Non-controling Interests | C33: =IF(BS!G33<=0,0,BS!G33/BS!G34) -> 0.0098977083 | G33: =IF(G$4="","",-G15/G$4) -> 0.063363208 | H33: =IF(H$4="","",-H15/H$4) -> 0 | I33: =IF(I$4="","",-I15/I$4) -> 0 | J33: =IF(J$4="","",-J15/J$4) -> 0 | K33: =IF(K$4="","",-K15/K$4) -> 0 | L33: =IF(L$4="","",-L15/L$4) -> 0 | M33: =IF(M$4="","",-M15/M$4) | N33: =IF(N$4="","",-N15/N$4) | ... Q33: =IF(Q$4="","",-Q15/Q$4)
B34: Total FCFE | C34: =ABS(C19/C$4) -> 0.16620743 | G34: =IF(G$4="","",ABS(G19/G$4)) -> 0.48017834 | H34: =IF(H$4="","",ABS(H19/H$4)) -> 0.58435288 | I34: =IF(I$4="","",ABS(I19/I$4)) -> 0.00015147557 | J34: =IF(J$4="","",ABS(J19/J$4)) -> 0.00026371884 | K34: =IF(K$4="","",ABS(K19/K$4)) -> 0 | L34: =IF(L$4="","",ABS(L19/L$4)) -> 0 | M34: =IF(M$4="","",ABS(M19/M$4)) | N34: =IF(N$4="","",ABS(N19/N$4)) | ... Q34: =IF(Q$4="","",ABS(Q19/Q$4))
B36: Income Tax Rate | C36: 0.25 | E36: Use the highest past tax rate | G36: =IF(G$4="","",-G14/G16) -> 0.01627902 | H36: =IF(H$4="","",-H14/H16) -> 0.28784312 | I36: =IF(I$4="","",-I14/I16) -> 0 | J36: =IF(J$4="","",-J14/J16) -> 0 | K36: =IF(K$4="","",-K14/K16) -> #DIV/0! | L36: =IF(L$4="","",-L14/L16) -> #DIV/0! | M36: =IF(M$4="","",-M14/M16) | N36: =IF(N$4="","",-N14/N16) | ... Q36: =IF(Q$4="","",-Q14/Q16)
B38: YoY Growth Rates
B39: Sales | C39: =C4/G4-1 -> 0.38781724 | G39: =IF(H4="","",G4/H4-1) -> -0.44776033 | H39: =IF(I4="","",H4/I4-1) -> 0.33871757 | I39: =IF(J4="","",I4/J4-1) -> 0.69302859 | J39: =IF(K4="","",J4/K4-1) -> 0.78205008 | K39: =IF(L4="","",K4/L4-1) -> -0.76371059 | L39: =IF(M4="","",L4/M4-1) | M39: =IF(N4="","",M4/N4-1) | N39: =IF(O4="","",N4/O4-1) | ... Q39: =IF(R4="","",Q4/R4-1)
B41: Per Share Indicators
B42: ="FCFE per share ("&Market_currency&")" -> FCFE per share (HKD) | C42: =C19*$C$3/Common_Shares*Exchange_Rate -> 0.029647921 | G42: =IF(G$4="","",G19*$C$3/Common_Shares*Exchange_Rate) -> 0.061718318 | H42: =IF(H$4="","",H19*$C$3/Common_Shares*Exchange_Rate) -> 0.13600632 | I42: =IF(I$4="","",I19*$C$3/Common_Shares*Exchange_Rate) -> 2.6335256e-05 | J42: =IF(J$4="","",J19*$C$3/Common_Shares*Exchange_Rate) -> 2.7081444e-05 | K42: =IF(K$4="","",K19*$C$3/Common_Shares*Exchange_Rate) -> 0 | L42: =IF(L$4="","",L19*$C$3/Common_Shares*Exchange_Rate) -> 0 | M42: =IF(M$4="","",M19*$C$3/Common_Shares*Exchange_Rate) | N42: =IF(N$4="","",N19*$C$3/Common_Shares*Exchange_Rate) | ... Q42: =IF(Q$4="","",Q19*$C$3/Common_Shares*Exchange_Rate)
B43: FCFE/Market Price | C43: =C42/Market_Price -> 0.017439953 | G43: =IF(G$4="","",G42/Market_Price) -> 0.036304893 | H43: =IF(H$4="","",H42/Market_Price) -> 0.08000372 | I43: =IF(I$4="","",I42/Market_Price) -> 1.5491327e-05 | J43: =IF(J$4="","",J42/Market_Price) -> 1.5930261e-05 | K43: =IF(K$4="","",K42/Market_Price) -> 0 | L43: =IF(L$4="","",L42/Market_Price) -> 0 | M43: =IF(M$4="","",M42/Market_Price) | N43: =IF(N$4="","",N42/Market_Price) | ... Q43: =IF(Q$4="","",Q42/Market_Price)
B45: Detailed Analysis | E45: Notes
...

Sheet BS
B1: Most Recent Quarter | C1: 45473 | F1: =IF(MONTH(C1)=MONTH(Normalized_FCF!G1),"FY","Quarter")&" Report" -> Quarter Report
B2: Lastest Balance Sheet
B3: Operating Assets | C3: =Data!C3 -> 1000 | D3: Valued @ | F3: Non-Operating Assets | H3: Valued @
B4: ST AR | C4: 649112 | D4: 0.6 | F4: Cash and cash equivalents | G4: 4022618 | H4: 0.9
B5: Operating ST Financial Assets | C5: 0 | D5: 0.6 | F5: Restricted cash | G5: 0 | H5: 0.8
B6: Prepayments and Contract Assets | C6: 0 | D6: 0.1 | F6: ST Income Stock/Debt | G6: 0 | H6: 0.7
B7: Inventory | C7: 0 | D7: 0.5 | F7: ST Other Securities | G7: 171402 | H7: 0.6
B8: Operating Properties held for sale | C8: 0 | D8: 0.6 | F8: Properties held for sale | G8: 0 | H8: 0.6
B9: ST DTA | C9: 0 | D9: 0.9 | F9: Properties under development | G9: 0 | H9: 0.6
B10: Other ST Assets | C10: 0 | D10: 0.05 | F10: Non-Operating ST Assets | G10: =SUM(G4:G9) -> 4194020 | H10: =G4*H4+G5*H5+G6*H6+G7*H7+G8*H8+G9*H9 -> 3723197.4
B11: Operating ST Assets | C11: =SUM(C4:C10) -> 649112 | D11: =C4*D4+C5*D5+C6*D6+C7*D7+C8*D8+C9*D9+C10*D10 -> 389467.2 | F11: LT Depositis | G11: 0 | H11: 0.8
B12: LT AR | C12: 103165 | D12: 0.4 | F12: LT Income Stock/Debt | G12: =2479179+572769 -> 3051948 | H12: 0.7
B13: Operating LT Financial Assets | C13: 0 | D13: 0.5 | F13: LT Other Securities | G13: =4626423-G12 -> 1574475 | H13: 0.6
B14: Operating Investment Properties | C14: 875642 | D14: 0.6 | F14: Investments in JV or associate | G14: 781196 | H14: 0.1
B15: PP&E & Right of Use Assets | C15: 2545809 | D15: 0.1 | F15: Investment property | G15: 0 | H15: 0.2
B16: Biological assets | C16: 0 | D16: 0.05 | F16: Properties under development | G16: 0 | H16: 0.1
B17: Intangible assets | C17: 0 | D17: 0.05 | F17: Non-Operating LT Assets | G17: =SUM(G11:G16) -> 5407619 | H17: =G11*H11+G12*H12+G13*H13+G14*H14+G15*H15+G16*H16 -> 3159168.2
B18: LT DTA | C18: 23095 | D18: 0.9
B19: Other assets & Goodwill | C19: 553636 | D19: 0 | F19: Operating Assets | G19: =C11+C20 -> 4750459 | H19: =D11+D20 -> 1231484.8
B20: Operating LT Assets | C20: =SUM(C12:C19) -> 4101347 | D20: =C12*D12+C13*D13+C14*D14+C15*D15+C16*D16+C17*D17+C18*D18+C19*D19 -> 842017.6 | F20: Non-operating Assets | G20: =G10+G17 -> 9601639 | H20: =H10+H17 -> 6882365.6
B22: Liabilities | G22: Book | H22: Estimate
B23: ST Borrowing | C23: 30697 | F23: Total Assets | G23: =G19+G20 -> 14352098 | H23: =H19+H20 -> 8113850.4
B24: ST Lease liabilities | C24: 143877 | F24: incl. Cash | G24: =G4+G5+G11 -> 4022618
B25: ST SH Loan | C25: 0 | F25: incl. Income Stock/Debt | G25: =G6+G12 -> 3051948
B26: ST Financial Liabilities | C26: 222396 | F26: incl. JV or associate | G26: =G14 -> 781196
B27: ST Debt | C27: =SUM(C23:C26) -> 396970 | F27: incl. Investment property | G27: =G15 -> 0
B28: Other ST liabilities | C28: =C29-C27 -> 844275 | F28: incl. Other Securities | G28: =G7+G13 -> 1745877 | H28: =G7*H7+G13*H13 -> 1047526.2
B29: Current Liabilities | C29: 1241245 | F29: incl. Fixed Assets | G29: =SUM(C14:C17)+SUM(G15:G16) -> 3421451
B30: LT Borrowing | C30: 1075543 | F30: Total Liabilities | G30: =C29+C36 -> 4197215
B31: LT Lease liabilities | C31: 1679438 | F31: incl. Interest-bearing Debt | G31: =C27+C34 -> 3241182
B32: LT SH Loan | C32: 0 | F32: Total Equity | G32: =G23-G30 -> 10154883 | H32: =H23-G30 -> 3916635.4
B33: LT Financial Liabilities | C33: 89231 | F33: Incl. Non-common Interest | G33: 99525
B34: LT Debt | C34: =SUM(C30:C33) -> 2844212 | F34: Incl. Common Equity | G34: =G32-G33 -> 10055358 | H34: =H32-G33 -> 3817110.4
B35: Other LT liabilities | C35: =C36-C34 -> 111758
B36: Noncurrent Liabilities | C36: 2955970
B38: Balance Sheet Analysis
B39: Asset Value | C39: Book | D39: Estimate
B40: ="Equity per share ("&Market_currency&")" -> Equity per share (HKD) | C40: =G34*C3/Common_Shares*Exchange_Rate -> 1.4628955 | D40: =H34*C3/Common_Shares*Exchange_Rate -> 0.55532919
B42: Leverage % | C42: Normalized | D42: Latest | F42: Notes
B43: D&A/Fixed Assets | C43: =D43 -> 0.010514253 | D43: =Normalized_FCF!G8/BS!$G$29 -> 0.010514253 | F43: Same as Last year's D&A
...

Sheet Valuation_Model
B2: No-Growth DCF Valuation Analysis | H2: Notes
B3: No-Growth DCF | C3: =Normalized_FCF!C3 -> 1000 | E3: Special Assumption
B4: Adjusted FCFE | C4: =Normalized_FCF!C19 -> 203787.93 | D4: =Reporting_currency -> CNY | E4: Terminal Growth Rate: | F4: 0
B5: /Equity Cost of Capital | C5: =Thesis!C37 -> 0.1 | E5: - Expects no significant growth at terminal years
B6: = Enterprise Value | C6: =(C4*(1+Terminal_Growth))/(Equity_Cost-Terminal_Growth) -> 2037879.3 | E6: - Avoids overvaluation.
B7: - Interest Bearing Debt | C7: =BS!G31 -> 3241182
B8: + Other Securities | C8: =BS!H28 -> 1047526.2
B9: = Equity Value | C9: =C6-C7+C8 -> -155776.47 | D9: =Reporting_currency -> CNY
B10: * Exchange rate | C10: =Exchange_Rate -> 1.06
B11: Equity Value per share | C11: =(C9*C3)/Common_Shares*C10 -> -0.022663013 | D11: =Market_currency -> HKD
B13: Implied Growth Sensitivity Test
B14: FCFE Projection
B15: High Growth Period (HGP) | C15: =Scenarios!C25 -> 0.17
B16: High Growth Rate (HGR) | C16: =Scenarios!C24 -> 15
B17: Value Per Share | C17: =(F51-C7)/Common_Shares*C3 -> 0.34543073 | D17: =IF(ROUND(C17,1)=ROUND(Scenarios!C29,1),"equals Market Price","a Current Projection") -> a Current Projection
B19: Year | C19: FCFE | D19: Growth Rates | E19: Discount Factor | F19: PV of FCFE
B20: 1 | C20: =C4*(1+D20) -> 238431.88 | D20: =IF($C$16<B20,0,Valuation_Model!$C$15) -> 0.17 | E20: =IF($C$16<B20,0,1/(1+Equity_Cost)^B20) -> 0.90909091 | F20: =C20*E20 -> 216756.26
B21: 2 | C21: =IF(ROW()-ROW($C$20)<$C$16, $C$20*(1+D21)^(ROW()-ROW($C$20)), 0) -> 278965.3 | D21: =IF($C$16<B21,0,Valuation_Model!$C$15) -> 0.17 | E21: =IF($C$16<B21,0,1/(1+Equity_Cost)^B21) -> 0.82644628 | F21: =C21*E21 -> 230549.84
B22: 3 | C22: =IF(ROW()-ROW($C$20)<$C$16, $C$20*(1+D22)^(ROW()-ROW($C$20)), 0) -> 326389.4 | D22: =IF($C$16<B22,0,Valuation_Model!$C$15) -> 0.17 | E22: =IF($C$16<B22,0,1/(1+Equity_Cost)^B22) -> 0.7513148 | F22: =C22*E22 -> 245221.19
B23: 4 | C23: =IF(ROW()-ROW($C$20)<$C$16, $C$20*(1+D23)^(ROW()-ROW($C$20)), 0) -> 381875.6 | D23: =IF($C$16<B23,0,Valuation_Model!$C$15) -> 0.17 | E23: =IF($C$16<B23,0,1/(1+Equity_Cost)^B23) -> 0.68301346 | F23: =C23*E23 -> 260826.17
B24: 5 | C24: =IF(ROW()-ROW($C$20)<$C$16, $C$20*(1+D24)^(ROW()-ROW($C$20)), 0) -> 446794.45 | D24: =IF($C$16<B24,0,Valuation_Model!$C$15) -> 0.17 | E24: =IF($C$16<B24,0,1/(1+Equity_Cost)^B24) -> 0.62092132 | F24: =C24*E24 -> 277424.2
B25: 6 | C25: =IF(ROW()-ROW($C$20)<$C$16, $C$20*(1+D25)^(ROW()-ROW($C$20)), 0) -> 522749.51 | D25: =IF($C$16<B25,0,Valuation_Model!$C$15) -> 0.17 | E25: =IF($C$16<B25,0,1/(1+Equity_Cost)^B25) -> 0.56447393 | F25: =C25*E25 -> 295078.47
B26: 7 | C26: =IF(ROW()-ROW($C$20)<$C$16, $C$20*(1+D26)^(ROW()-ROW($C$20)), 0) -> 611616.93 | D26: =IF($C$16<B26,0,Valuation_Model!$C$15) -> 0.17 | E26: =IF($C$16<B26,0,1/(1+Equity_Cost)^B26) -> 0.51315812 | F26: =C26*E26 -> 313856.19
B27: 8 | C27: =IF(ROW()-ROW($C$20)<$C$16, $C$20*(1+D27)^(ROW()-ROW($C$20)), 0) -> 715591.8 | D27: =IF($C$16<B27,0,Valuation_Model!$C$15) -> 0.17 | E27: =IF($C$16<B27,0,1/(1+Equity_Cost)^B27) -> 0.46650738 | F27: =C27*E27 -> 333828.86
B28: 9 | C28: =IF(ROW()-ROW($C$20)<$C$16, $C$20*(1+D28)^(ROW()-ROW($C$20)), 0) -> 837242.41 | D28: =IF($C$16<B28,0,Valuation_Model!$C$15) -> 0.17 | E28: =IF($C$16<B28,0,1/(1+Equity_Cost)^B28) -> 0.42409762 | F28: =C28*E28 -> 355072.51
B29: 10 | C29: =IF(ROW()-ROW($C$20)<$C$16, $C$20*(1+D29)^(ROW()-ROW($C$20)), 0) -> 979573.62 | D29: =IF($C$16<B29,0,Valuation_Model!$C$15) -> 0.17 | E29: =IF($C$16<B29,0,1/(1+Equity_Cost)^B29) -> 0.38554329 | F29: =C29*E29 -> 377668.04
B30: 11 | C30: =IF(ROW()-ROW($C$20)<$C$16, $C$20*(1+D30)^(ROW()-ROW($C$20)), 0) -> 1146101.1 | D30: =IF($C$16<B30,0,Valuation_Model!$C$15) -> 0.17 | E30: =IF($C$16<B30,0,1/(1+Equity_Cost)^B30) -> 0.3504939 | F30: =C30*E30 -> 401701.46
B31: 12 | C31: =IF(ROW()-ROW($C$20)<$C$16, $C$20*(1+D31)^(ROW()-ROW($C$20)), 0) -> 1340938.3 | D31: =IF($C$16<B31,0,Valuation_Model!$C$15) -> 0.17 | E31: =IF($C$16<B31,0,1/(1+Equity_Cost)^B31) -> 0.31863082 | F31: =C31*E31 -> 427264.28
B32: 13 | C32: =IF(ROW()-ROW($C$20)<$C$16, $C$20*(1+D32)^(ROW()-ROW($C$20)), 0) -> 1568897.8 | D32: =IF($C$16<B32,0,Valuation_Model!$C$15) -> 0.17 | E32: =IF($C$16<B32,0,1/(1+Equity_Cost)^B32) -> 0.28966438 | F32: =C32*E32 -> 454453.82
... B49: 30 | C49: =IF(ROW()-ROW($C$20)<$C$16, $C$20*(1+D49)^(ROW()-ROW($C$20)), 0) -> 0 | D49: =IF($C$16<B49,0,Valuation_Model!$C$15) -> 0 | E49: =IF($C$16<B49,0,1/(1+Equity_Cost)^B49) -> 0 | F49: =C49*E49 -> 0
B50: Terminal Year | C50: =C$20*(1+Terminal_Growth)^$C$16/Equity_Cost -> 2384318.8 | D50: =Terminal_Growth -> 0 | E50: =1/(1+Equity_Cost)^C16 -> 0.23939205 | F50: =C50*E50 -> 570786.97
E51: Total PV | F51: =SUM(F20:F50) -> 5757995.6
B53: Sensitivity Analysis (Enterprise Value)
A54: =F51 -> 5757995.6 | B54: =C77 -> -0.05 | C54: =C76 -> 0.05 | D54: =C75 -> 0.15 | E54: =C74 -> 0.15 | F54: =C73 -> 0.2
A55: 5 | B55: 1872646.2 | C55: 2216763.3 | D55: 2621766.4 | E55: 2621766.4 | F55: 2851332.9
A56: 10 | B56: 1739129.1 | C56: 2416926.4 | D56: 3527103.1 | E56: 3527103.1 | F56: 4335121.3
A57: 15 | B57: 1610971.9 | C57: 2661951.4 | D57: 5004177.6 | E57: 5004177.6 | F57: 7159584.9
A58: 20 | B58: 1509654 | C58: 2909775.1 | D58: 7063977.8 | E58: 7063977.8 | F58: 11853815
A59: 25 | B59: 1436297.3 | C59: 3139479.6 | D59: 9770004.8 | E59: 9770004.8 | F59: 19311723
A60: 30 | B60: 1385729.5 | C60: 3342197.5 | D60: 13232474 | E60: 13232474 | F60: 30961912
...

Sheet Scenarios
B2: Current Situation
B3: Selection
B4: Past Years Selected | C4: 4 | E4: Tie the business story into the three levers of value: FCFE, growth and risk.
B6: FCFE | C6: =Valuation_Model!C3 -> 1000 | E6: Prompt for Scenario Analysis
B7: Lastest | C7: =Normalized_FCF!G19 -> 424227 | E7: Given 六福珠宝’s (0590.HK) normalized FCFE of HKD 1,270,672,000, please analyze its valuation assumptions under three scenarios (Base, Pessimistic, Optimistic) using a two-stage model, a growth stage and a terminal stage. Define the growth period, growth rates and probabilities for each scenario. Explain the rationale behind the probabilities. Summarize the business drivers and scenario narratives to align with the model’s inputs. For context only, the terminal value assumes 0% growth to prevent overvaluation. The finalized scenarios will be incorporated directly into the valuation framework.”
B8: Normalized | C8: =Normalized_FCF!C19 -> 203787.93
B10: Growth Rate
B11: Sales Growth Rates | C11: =AVERAGE(Normalized_FCF!G39:INDEX(Normalized_FCF!G39:Q39, $C$4)) -> 0.34150898
B12: Op. FCFE Before WCInv
B13: Non-Operating Income
B15: Margin
B16: Contribution Margin
B17: Op. FCFE Before WCInv
B19: Objective Scenarios
B20: No Growth Scenario | E20: Business Story
B21: Value per share | C21: =Valuation_Model!E76 -> 0.032482336 | D21: =Reporting_currency -> CNY | E21: Unbiased Scenario where the company FCFE has no growth and no risk.
B23: Market Scenario
B24: High Growth Period (HGP) | C24: 15
B25: High Growth Rate (HGR) | C25: 0.17
B26: Value per share | C26: =Valuation_Model!C17 -> 0.34543073
B28: Reference Price Points
B29: Market Price | C29: =Market_Price -> 1.7
B30: 52 week High | C30: 13
B31: 52 week Low
B33: General Scenarios
B34: Assumption
B35: High Growth Period (HGP) | C35: 10 | E35: For both Base and Pessimistic case, I would use 10 yrs to do forecast
B37: Base | E37: Business Story
B38: High Growth Period (HGP) | C38: =C35 -> 10
B39: High Growth Rate (HGR) | C39: 0.15
B40: Value per share | C40: =Valuation_Model!E75 -> 0.1939955 | D40: =Market_currency -> HKD
B41: Probabilities | C41: 0.5
B43: Pessimistic | E43: Business Story
B44: High Growth Period (HGP) | C44: =C35 -> 10
B45: High Growth Rate (HGR) | C45: 0.05
B46: Value per share | C46: =Valuation_Model!E76 -> 0.032482336 | D46: =Market_currency -> HKD
B47: Probabilities | C47: 0.25
B49: Optimistic | E49: Business Story
B50: High Growth Period (HGP) | C50: 10
B51: High Growth Rate (HGR) | C51: 0.15
...
