Workbook
Name Common_Shares: Thesis!$C$7
Name Equity_Cost: Valuation_Model!$C$5
Name Exchange_Rate: Thesis!$C$17
Name Market_currency: Thesis!$D$6
Name Market_Price: Thesis!$C$6
Name Reporting_currency: Thesis!$C$16
Name Terminal_Growth: Valuation_Model!$F$4

Sheet Thesis
B1: Model last updated: | C1: 45754 | E1: Selected: | F1: N
A2: Executive Summary
B4: =D5&" Stock Information" -> 0806.HK Stock Information
B5: Company Name | C5: 惠理集團 | D5: 0806.HK
B6: Market Price: | C6: 1.35 | D6: HKD
B7: Number of Shares: | C7: 1826709831
B8: Report Interval: | C8: 6
B9: Update Required After: | C9: =EOMONTH(EDATE(BS!C1,C8+2),0) -> 45900
B10: ="Capitalization ("&Market_currency&"):" -> Capitalization (HKD): | C10: =Thesis!C6*Thesis!C7/1000000 -> 2466.0583
B12: Guidance Note: This model determines a target buy price consistent with defined investment criteria. It follows a logical progression: establishing current sustainable earnings, adjusting for financial structure, incorporating growth scenarios, and finally applying the investor’s required return.
B14: Valuation Overview
B15: Growth Classification: | C15: =IF(Scenarios!C69="Y",Scenarios!B69,"")&IF(Scenarios!C70="Y",Scenarios!B70,"")&IF(Scenarios!C71="Y",Scenarios!B71,"")&" "&IF(Scenarios!C72="Y",Scenarios!B72,"") -> Low Growth Asset Play
B16: Reporting Currency: | C16: HKD
B17: Exchange Rate: | C17: 1 | D17: =IF(C16=D6,D6,C16&"/"&D6) -> HKD
B18: Comp_Sector: | C18: FIN_02
B19: Target Annual Return: | C19: 0.25
B20: ="Target Buy Price ("&Market_currency&"):" -> Target Buy Price (HKD): | C20: =C129 -> 0.28748109 | D20: assuming a holding period of | E20: 3
B21: Implied Market Annual Return: | C21: =Scenarios!C87 -> -0.26037178
A23: Step 1: Establishing the Company’s Sustainable Earning Power (Calculating Normalized FCFE)
B25: Goal: To quantify the underlying FCFE the business consistently generates for its equity owners, stripping away temporary fluctuations or accounting choices.The FCFE/Market Cap yield gives a direct measure of this cash generation relative to the current market price.
B26: FCFE = (Normalized Operating EBIT + Depreciation & Amortization – Capital Expenditures) + Stable Non-Operating EBIT + Net Interest Income – Taxes – NCI’s Share of Profits – Working Capital Investment
B28: Key Components | C28: =Data!C3 -> 1000
B29: • Normalized Operating EBIT: Earnings before interest and taxes from core business operations, adjusted to remove one-time or irregular items for a sustainable earnings base.
B30: Normalized Operating EBIT = | C30: =Normalized_FCF!C8 -> -62266 | D30: =Reporting_currency -> HKD
B32: • Depreciation & Amortization (D&A): Non-cash expenses added back to reflect cash generated from operations. • Capital Expenditures (Capex): Cash outflows required to maintain or expand operational assets
B33: D&A = | C33: =Normalized_FCF!C9 -> 0 | D33: =Reporting_currency -> HKD
B34: Capex = | C34: =Normalized_FCF!C10 -> 0 | D34: =Reporting_currency -> HKD
B36: • Stable Non-Operating EBIT: Consistent earnings from non-core assets, such as fixed-income investments, dividend-paying stocks, or rental properties.
B37: Stable Non-Operating EBIT = | C37: =Normalized_FCF!C11 -> 70547.28 | D37: =Reporting_currency -> HKD
B39: • Net Interest Income: Interest income minus interest expense
B40: Operating Interest Income = | C40: =Normalized_FCF!C48 -> 5314.0836 | D40: =Reporting_currency -> HKD
B41: Interest Expense = | C41: =Normalized_FCF!C47 -> -8149 | D41: =Reporting_currency -> HKD
B42: Net Interest Income = | C42: =Normalized_FCF!C12 -> -2834.9164 | D42: =Reporting_currency -> HKD
B44: • NCI’s Share of Profits: NCI represents the portion of a subsidiary’s equity not owned by the parent company.
B45: Est. NCI’s Share of Profits = | C45: =Normalized_FCF!C15 -> 0 | D45: =Reporting_currency -> HKD
B47: • Taxes: Tax = (Normalized Operating EBIT + Stable Non-Operating EBIT + Interest Income – Interest Expense) × Tax Rate
B48: Taxes = | C48: =Normalized_FCF!C14 -> -1361.5909 | D48: =Reporting_currency -> HKD
B50: • Working Capital Investment (WCInv): WCInv is only included if it materially distorts FCFE.
B51: WCInv = | C51: =Normalized_FCF!C17 -> 0 | D51: =Reporting_currency -> HKD
B53: Note on Net Borrowing: In theory, principal repayments are accounted for through Net Borrowing. However, this model aims to avoid explicitly forecasting debt issuance or repayments. Instead, principal repayments are reflected in the Equity Value adjustment through interest-bearing debt.
...

Sheet Data
B1: =Thesis!C16 -> HKD | C1: 45657 | D1: =EOMONTH(EDATE(C1,-12),0) -> 45291 | E1: =EOMONTH(EDATE(D1,-12),0) -> 44926 | F1: =EOMONTH(EDATE(E1,-12),0) -> 44561 | G1: =EOMONTH(EDATE(F1,-12),0) -> 44196 | H1: =EOMONTH(EDATE(G1,-12),0) -> 43830 | I1: =EOMONTH(EDATE(H1,-12),0) -> 43465 | J1: =EOMONTH(EDATE(I1,-12),0) -> 43100 | K1: =EOMONTH(EDATE(J1,-12),0) -> 42735 | ... M1: =EOMONTH(EDATE(L1,-12),0) -> 42004
B2: Data (Dirty)
B3: Income Statement | C3: 1000
B4: Sales | C4: 247271 | D4: 281951 | E4: 331953 | F4: 755414 | G4: 2050629
B5: COGS | C5: 219537 | D5: 232905
B6: OPEX | C6: =227454+5669+14513+113831 -> 361467 | D6: =250848+7069+19250+113116 -> 390283 | E6: 330088 | F6: 389543 | G6: 672911
B7: Incl. Selling Expenses
B8: R&D
B9: Share of JV or associate Results
B10: Dividend or Interests from FA | C10: =52198+11417 -> 63615 | D10: =48974+5641 -> 54615
B11: Investment property | C11: 12454 | D11: 12191
B12: Interest Expense | C12: 8149 | D12: 7447 | E12: 5293 | F12: 3968 | G12: 0
B13: Interest Income | C13: 34933 | D13: 42648
B14: Income Tax Paid | C14: 2918 | D14: 4507 | E14: 3959 | F14: 50081 | G14: 221776
B15: Reported Net Income | C15: 30811 | D15: 23088 | E15: -544315 | F15: 457813 | G15: 1379475
B16: Non-controling Interests | C16: -424 | D16: 0 | E16: 0 | F16: 0 | G16: 0
B18: Cash Flow Statement
B19: D&A
B20: CAPX | C20: -1.006 | D20: -1.006 | E20: -0.986 | F20: -5.18 | G20: -8.445
B21: WCInv | C21: 34.15 | D21: 34.15 | E21: -39.788 | F21: 0.91 | G21: 980.628
B22: CFO | C22: -2094 | D22: 56325 | E22: -76641 | F22: 1075649 | G22: 212852
B23: CFI | C23: 459814 | D23: -67601 | E23: 398831 | F23: -706056 | G23: -13297
B24: CFF | C24: -937078 | D24: -89539 | E24: -232800 | F24: -678918 | G24: -439768
B25: ="Dividend per share ("&Market_currency&")" -> Dividend per share (HKD) | C25: 0.01 | D25: 0 | E25: 0.034 | F25: 0.08 | G25: 0.26
B27: Balance Sheet | C27: Latest Asset Value
B28: ST AR | C28: =BS!C4 -> 83455 | D28: 56325 | E28: 67131 | F28: 190060 | G28: 1495304
B29: ST Inventory | C29: =BS!C6 -> 0 | D29: 0 | E29: 0 | F29: 0 | G29: 0
B30: Total Liabilities | C30: =BS!C33+BS!C42 -> 215440 | D30: 1135384 | E30: 253658 | F30: 405587 | G30: 880771
B31: Total Equity | C31: =BS!G27 -> 3559773 | D31: 3542698 | E31: 4494199 | F31: 5264755 | G31: 5418042
B32: Non-common Interest | C32: =BS!G28 -> 7710 | D32: 0 | E32: 0 | F32: 0 | G32: 0
B34: IS & CF Statements (Clean)
B35: Income Statement
B36: Sales | C36: =IF(C$4="","",C4) -> 247271 | D36: =IF(D$4="","",D4) -> 281951 | E36: =IF(E$4="","",E4) -> 331953 | F36: =IF(F$4="","",F4) -> 755414 | G36: =IF(G$4="","",G4) -> 2050629 | H36: =IF(H$4="","",H4) | I36: =IF(I$4="","",I4) | J36: =IF(J$4="","",J4) | ... M36: =IF(M$4="","",M4)
B37: COGS | C37: =IF(C$4="","",-C5) -> -219537 | D37: =IF(D$4="","",-D5) -> -232905 | E37: =IF(E$4="","",-E5) -> 0 | F37: =IF(F$4="","",-F5) -> 0 | G37: =IF(G$4="","",-G5) -> 0 | H37: =IF(H$4="","",-H5) | I37: =IF(I$4="","",-I5) | J37: =IF(J$4="","",-J5) | ... M37: =IF(M$4="","",-M5)
B38: Gross Margin | C38: =IF(C36="","",C36+C37) -> 27734 | D38: =IF(D36="","",D36+D37) -> 49046 | E38: =IF(E36="","",E36+E37) -> 331953 | F38: =IF(F36="","",F36+F37) -> 755414 | G38: =IF(G36="","",G36+G37) -> 2050629 | H38: =IF(H36="","",H36+H37) | I38: =IF(I36="","",I36+I37) | J38: =IF(J36="","",J36+J37) | ... M38: =IF(M36="","",M36+M37)
B39: OPEX | C39: =IF(C$4="","",-C6) -> -361467 | D39: =IF(D$4="","",-D6) -> -390283 | E39: =IF(E$4="","",-E6) -> -330088 | F39: =IF(F$4="","",-F6) -> -389543 | G39: =IF(G$4="","",-G6) -> -672911 | H39: =IF(H$4="","",-H6) | I39: =IF(I$4="","",-I6) | J39: =IF(J$4="","",-J6) | ... M39: =IF(M$4="","",-M6)
B40: Incl. Selling Expenses | C40: =IF(C$4="","",-C7) -> 0 | D40: =IF(D$4="","",-D7) -> 0 | E40: =IF(E$4="","",-E7) -> 0 | F40: =IF(F$4="","",-F7) -> 0 | G40: =IF(G$4="","",-G7) -> 0 | H40: =IF(H$4="","",-H7) | I40: =IF(I$4="","",-I7) | J40: =IF(J$4="","",-J7) | ... M40: =IF(M$4="","",-M7)
B41: Incl. Other Opex | C41: =IF(C$4="","",C39-C40) -> -361467 | D41: =IF(D$4="","",D39-D40) -> -390283 | E41: =IF(E$4="","",E39-E40) -> -330088 | F41: =IF(F$4="","",F39-F40) -> -389543 | G41: =IF(G$4="","",G39-G40) -> -672911 | H41: =IF(H$4="","",H39-H40) | I41: =IF(I$4="","",I39-I40) | J41: =IF(J$4="","",J39-J40) | ... M41: =IF(M$4="","",M39-M40)
B42: R&D | C42: =IF(C$4="","",-C8) -> 0 | D42: =IF(D$4="","",-D8) -> 0 | E42: =IF(E$4="","",-E8) -> 0 | F42: =IF(F$4="","",-F8) -> 0 | G42: =IF(G$4="","",-G8) -> 0 | H42: =IF(H$4="","",-H8) | I42: =IF(I$4="","",-I8) | J42: =IF(J$4="","",-J8) | ... M42: =IF(M$4="","",-M8)
B43: Operating EBIT | C43: =IF(C$4="","",C38+C39+C42) -> -333733 | D43: =IF(D$4="","",D38+D39+D42) -> -341237 | E43: =IF(E$4="","",E38+E39+E42) -> 1865 | F43: =IF(F$4="","",F38+F39+F42) -> 365871 | G43: =IF(G$4="","",G38+G39+G42) -> 1377718 | H43: =IF(H$4="","",H38+H39+H42) | I43: =IF(I$4="","",I38+I39+I42) | J43: =IF(J$4="","",J38+J39+J42) | ... M43: =IF(M$4="","",M38+M39+M42)
...

Sheet BS
B1: Most Recent Quarter | C1: 45657 | F1: =IF(MONTH(C1)=MONTH(Normalized_FCF!G1),"FY","Quarter")&" Report" -> FY Report | H1: =Data!C3 -> 1000
B2: Lastest Balance Sheet
B3: ST Operating Assets | C3: Book | D3: Valued @ | F3: ST Non-Operating Assets | G3: Book | H3: Valued @
B4: ST AR | C4: =37674+19634+26147 -> 83455 | D4: 0.6 | F4: Cash and cash equivalents | G4: 1077437 | H4: 0.9
B5: Operating ST Financial Assets | C5: 0 | D5: 0.6 | F5: Restricted cash | G5: 0 | H5: 0.7
B6: Inventory | C6: 0 | D6: 0.5 | F6: Securities with stable income | G6: 0 | H6: 0.6
B7: Properties held for sale | C7: 0 | D7: 0.6 | F7: Other Securities | G7: 60407 | H7: 0.6
B8: Properties held for income | C8: 0 | D8: 0.6 | F8: Properties with stable income | G8: 0 | H8: 0.6
B9: Prepayments and Contract Assets | C9: 15614 | D9: 0.1 | F9: Other Properties | G9: 0 | H9: 0.6
B10: ST DTA | C10: 0 | D10: 0.9
B11: Other ST Assets | C11: 0 | D11: 0.05
B12: Operating ST Assets | C12: =SUM(C4:C11) -> 99069 | D12: =C4*D4+C5*D5+C9*D9+C6*D6+C8*D8+C7*D7+C10*D10+C11*D11 -> 51634.4 | F12: Non-Operating ST Assets | G12: =SUM(G4:G9) -> 1137844 | H12: =G4*H4+G5*H5+G6*H6+G7*H7+G8*H8+G9*H9 -> 1005937.5
B14: LT Operating Assets | C14: Book | D14: Valued @ | F14: LT Non-Operating Assets | G14: Book | H14: Valued @
B15: LT AR | C15: 0 | D15: 0.4 | F15: LT Depositis | G15: 0 | H15: 0.8
B16: Operating LT Financial Assets | C16: 0 | D16: 0.5 | F16: Securities with stable income | G16: 1688685 | H16: 0.6
B17: Properties held for sale | C17: 0 | D17: 0.6 | F17: Other Securities | G17: 0 | H17: 0.6
B18: Properties held for income | C18: 0 | D18: 0.6 | F18: JV or associate with stable income | G18: 0 | H18: 0.1
B19: PP&E & Right of Use Assets | C19: =145400+31250 -> 176650 | D19: 0.1 | F19: Other JV or associate | G19: =479666+1388 -> 481054 | H19: 0.1
B20: Biological assets | C20: 0 | D20: 0.05 | F20: Properties with stable income | G20: 173307 | H20: 0.2
B21: Intangible assets | C21: 9357 | D21: 0.05 | F21: Other Properties | G21: 0 | H21: 0.1
B22: LT DTA | C22: 2304 | D22: 0.9
B23: Other assets & Goodwill | C23: 6943 | D23: 0
B24: Operating LT Assets | C24: =SUM(C15:C23) -> 195254 | D24: =C15*D15+C16*D16+C18*D18+C17*D17+C19*D19+C20*D20+C21*D21+C22*D22+C23*D23 -> 20206.45 | F24: Non-Operating LT Assets | G24: =SUM(G15:G21) -> 2343046 | H24: =G15*H15+G16*H16+G17*H17+G18*H18+G19*H19+G20*H20+G21*H21 -> 1095977.8
B26: ST Liabilities | C26: Book | F26: BS Summary | G26: Book | H26: Valued @
B27: ST Borrowing | C27: 65941 | F27: Total Equity | G27: =G32-G30 -> 3559773 | H27: =H32-G30 -> 1958316.1
B28: ST Lease liabilities | C28: 12865 | F28: Incl. Minority Interest (NCI) | G28: 7710
B29: ST SH Loan | C29: 0 | F29: Incl. Common Equity | G29: =G27-G28 -> 3552063 | H29: =H27-G28 -> 1950606.1
B30: ST Financial Liabilities | C30: 0 | F30: Total Liabilities | G30: =C33+C42 -> 215440
B31: ST Interest-bearing Debt | C31: =SUM(C27:C30) -> 78806 | F31: incl. Interest-bearing Debt | G31: =C31+C40 -> 97365
B32: Other ST liabilities | C32: =C33-C31 -> 116223 | F32: Total Assets | G32: =G35+G40 -> 3775213 | H32: =H35+H40 -> 2173756.1
B33: Current Liabilities | C33: 195029
F34: Assets Summary | G34: Book | H34: Valued @
B35: LT Liabilities | C35: Book | F35: Operating Assets | G35: =C12+C24 -> 294323 | H35: =D12+D24 -> 71840.85
B36: LT Borrowing | C36: 0 | F36: incl. AR | G36: =C4+C15 -> 83455
B37: LT Lease liabilities | C37: 18559 | F37: incl. inventory | G37: =C6 -> 0
B38: LT SH Loan | C38: 0 | F38: incl. Properties held for sale | G38: =C7+C17 -> 0
B39: LT Financial Liabilities | C39: 0 | F39: incl. Fixed Assets | G39: =C7+C17+C19+C20 -> 176650 | H39: =C7*D7+C17*D17+C19*D19+C20*D20 -> 17665
B40: LT Interest-bearing Debt | C40: =SUM(C36:C39) -> 18559 | F40: Non-operating Assets | G40: =G12+G24 -> 3480890 | H40: =H12+H24 -> 2101915.3
B41: Other LT liabilities | C41: =C42-C40 -> 1852 | F41: incl. Assets with stable income | G41: =C70 -> 2939429 | H41: =H40-H42 -> 2017565.7
B42: Noncurrent Liabilities | C42: 20411 | F42: incl. Other Assets | G42: =C82 -> 541461 | H42: =D82 -> 84349.6
...

Sheet Normalized_FCF
B1: =Thesis!C16 -> HKD | C1: Normalized | G1: =Data!C1 -> 45657 | H1: =EOMONTH(EDATE(G1,-12),0) -> 45291 | I1: =EOMONTH(EDATE(H1,-12),0) -> 44926 | J1: =EOMONTH(EDATE(I1,-12),0) -> 44561 | K1: =EOMONTH(EDATE(J1,-12),0) -> 44196 | L1: =EOMONTH(EDATE(K1,-12),0) -> 43830 | M1: =EOMONTH(EDATE(L1,-12),0) -> 43465 | N1: =EOMONTH(EDATE(M1,-12),0) -> 43100 | O1: =EOMONTH(EDATE(N1,-12),0) -> 42735 | ... Q1: =EOMONTH(EDATE(P1,-12),0) -> 42004
B2: FCFE Analysis | E2: Notes
B3: FCFE | C3: =Data!C3 -> 1000
B4: Sales | C4: =G4 -> 247271 | G4: =Data!C36 -> 247271 | H4: =Data!D36 -> 281951 | I4: =Data!E36 -> 331953 | J4: =Data!F36 -> 755414 | K4: =Data!G36 -> 2050629 | L4: =Data!H36 | M4: =Data!I36 | N4: =Data!J36 | ... Q4: =Data!M36
B5: Variable Costs | C5: =C25 -> -219537 | G5: =G25 -> -219537 | H5: =H25 -> -232905 | I5: =I25 -> 0 | J5: =J25 -> 0 | K5: =K25 -> 0 | L5: =L25 | M5: =M25 | N5: =N25 | ... Q5: =Q25
B6: Contribution Margin | C6: =C4+C5 -> 27734 | G6: =IF(G4="","",G4+G5) -> 27734 | H6: =IF(H4="","",H4+H5) -> 49046 | I6: =IF(I4="","",I4+I5) -> 331953 | J6: =IF(J4="","",J4+J5) -> 755414 | K6: =IF(K4="","",K4+K5) -> 2050629 | L6: =IF(L4="","",L4+L5) | M6: =IF(M4="","",M4+M5) | N6: =IF(N4="","",N4+N5) | ... Q6: =IF(Q4="","",Q4+Q5)
B7: Fixed Costs | C7: =C35 -> -90000 | G7: =G35 -> -361467 | H7: =H35 -> -390283 | I7: =I35 -> -330088 | J7: =J35 -> -389543 | K7: =K35 -> -672911 | L7: =L35 | M7: =M35 | N7: =N35 | ... Q7: =Q35
B8: Operating EBIT | C8: =C6+C7 -> -62266 | G8: =IF(G$4="","",G6+G7) -> -333733 | H8: =IF(H$4="","",H6+H7) -> -341237 | I8: =IF(I$4="","",I6+I7) -> 1865 | J8: =IF(J$4="","",J6+J7) -> 365871 | K8: =IF(K$4="","",K6+K7) -> 1377718 | L8: =IF(L$4="","",L6+L7) | M8: =IF(M$4="","",M6+M7) | N8: =IF(N$4="","",N6+N7) | ... Q8: =IF(Q$4="","",Q6+Q7)
B9: Add Back D&A | C9: =BS!$G$39*BS!D58 -> 0 | G9: =IF(Data!C61="","",-Data!C61) -> 0 | H9: =IF(Data!D61="","",-Data!D61) -> 0 | I9: =IF(Data!E61="","",-Data!E61) -> 0 | J9: =IF(Data!F61="","",-Data!F61) -> 0 | K9: =IF(Data!G61="","",-Data!G61) -> 0 | L9: =IF(Data!H61="","",-Data!H61) | M9: =IF(Data!I61="","",-Data!I61) | N9: =IF(Data!J61="","",-Data!J61) | ... Q9: =IF(Data!M61="","",-Data!M61)
B10: Maintenance Capex | C10: =-C4*C78 -> 0 | G10: =Data!C62 -> 1.006 | H10: =Data!D62 -> 1.006 | I10: =Data!E62 -> 0.986 | J10: =Data!F62 -> 5.18 | K10: =Data!G62 -> 8.445 | L10: =Data!H62 | M10: =Data!I62 | N10: =Data!J62 | ... Q10: =Data!M62
B11: Stable Non-Operating EBIT | C11: =C63 -> 70547.28 | G11: =G61 -> 76069 | H11: =H61 -> 66806 | I11: =I61 -> 0 | J11: =J61 -> 0 | K11: =K61 -> 0 | L11: =L61 | M11: =M61 | N11: =N61 | ... Q11: =Q61
B12: Net Interest Income | C12: =C50 -> -2834.9164 | G12: =G50 -> -2834.9164 | H12: =H50 -> -959.2939 | I12: =I50 -> -5293 | J12: =J50 -> -3968 | K12: =K50 -> 0 | L12: =L50 | M12: =M50 | N12: =N50 | ... Q12: =Q50
B13: Pre-tax Profit | C13: =SUM(C8:C12) -> 5446.3636 | G13: =IF(G$4="","",SUM(G8:G12)) -> -260497.91 | H13: =IF(H$4="","",SUM(H8:H12)) -> -275389.29 | I13: =IF(I$4="","",SUM(I8:I12)) -> -3427.014 | J13: =IF(J$4="","",SUM(J8:J12)) -> 361908.18 | K13: =IF(K$4="","",SUM(K8:K12)) -> 1377726.4 | L13: =IF(L$4="","",SUM(L8:L12)) | M13: =IF(M$4="","",SUM(M8:M12)) | N13: =IF(N$4="","",SUM(N8:N12)) | ... Q13: =IF(Q$4="","",SUM(Q8:Q12))
B14: Income Tax | C14: =-SUM(C8+C11,C12)*C43 -> -1361.5909 | G14: =Data!C46 -> -2918 | H14: =Data!D46 -> -4507 | I14: =Data!E46 -> -3959 | J14: =Data!F46 -> -50081 | K14: =Data!G46 -> -221776 | L14: =Data!H46 | M14: =Data!I46 | N14: =Data!J46 | ... Q14: =Data!M46
B15: NCI’s Share of Profits | C15: =-C4*C83 -> 0 | G15: =Data!C48 -> 0 | H15: =Data!D48 -> 0 | I15: =Data!E48 -> 0 | J15: =Data!F48 -> 0 | K15: =Data!G48 -> 0 | L15: =Data!H48 | M15: =Data!I48 | N15: =Data!J48 | ... Q15: =Data!M48
B16: After-tax Profit | C16: =SUM(C13:C15) -> 4084.7727 | G16: =IF(G$4="","",SUM(G13:G15)) -> -263415.91 | H16: =IF(H$4="","",SUM(H13:H15)) -> -279896.29 | I16: =IF(I$4="","",SUM(I13:I15)) -> -7386.014 | J16: =IF(J$4="","",SUM(J13:J15)) -> 311827.18 | K16: =IF(K$4="","",SUM(K13:K15)) -> 1155950.4 | L16: =IF(L$4="","",SUM(L13:L15)) | M16: =IF(M$4="","",SUM(M13:M15)) | N16: =IF(N$4="","",SUM(N13:N15)) | ... Q16: =IF(Q$4="","",SUM(Q13:Q15))
B17: WCInv | C17: =-C4*C85 -> 0 | E17: WCInv is by default excluded
B18: Net Borrowing | C18: 0 | E18: Net borrowing is excluded
B19: FCFE | C19: =C16+C17 -> 4084.7727 | G19: =IF(G$4="","",G16+G17) -> -263415.91 | H19: =IF(H$4="","",H16+H17) -> -279896.29 | I19: =IF(I$4="","",I16+I17) -> -7386.014 | J19: =IF(J$4="","",J16+J17) -> 311827.18 | K19: =IF(K$4="","",K16+K17) -> 1155950.4 | L19: =IF(L$4="","",L16+L17) | M19: =IF(M$4="","",M16+M17) | N19: =IF(N$4="","",N16+N17) | ... Q19: =IF(Q$4="","",Q16+Q17)
B21: Operating Cost Structure | E21: Notes
B22: Variable Costs
B23: COGS | C23: =-C4*C28 -> -219537 | G23: =Data!C37 -> -219537 | H23: =Data!D37 -> -232905 | I23: =Data!E37 -> 0 | J23: =Data!F37 -> 0 | K23: =Data!G37 -> 0 | L23: =Data!H37 | M23: =Data!I37 | N23: =Data!J37 | ... Q23: =Data!M37
B24: Selling Expenses | C24: =-C4*C29 -> 0 | G24: =Data!C40 -> 0 | H24: =Data!D40 -> 0 | I24: =Data!E40 -> 0 | J24: =Data!F40 -> 0 | K24: =Data!G40 -> 0 | L24: =Data!H40 | M24: =Data!I40 | N24: =Data!J40 | ... Q24: =Data!M40
B25: Variable Costs | C25: =C23+C24 -> -219537 | G25: =IF(G$4="","",G23+G24) -> -219537 | H25: =IF(H$4="","",H23+H24) -> -232905 | I25: =IF(I$4="","",I23+I24) -> 0 | J25: =IF(J$4="","",J23+J24) -> 0 | K25: =IF(K$4="","",K23+K24) -> 0 | L25: =IF(L$4="","",L23+L24) | M25: =IF(M$4="","",M23+M24) | N25: =IF(N$4="","",N23+N24) | ... Q25: =IF(Q$4="","",Q23+Q24)
B27: Variable Costs % of Sales
B28: COGS | C28: =G28 -> 0.88783966 | E28: Historical Average | G28: =IF(G$4="","",ABS(G23/G$4)) -> 0.88783966 | H28: =IF(H$4="","",ABS(H23/H$4)) -> 0.82604779 | I28: =IF(I$4="","",ABS(I23/I$4)) -> 0 | J28: =IF(J$4="","",ABS(J23/J$4)) -> 0 | K28: =IF(K$4="","",ABS(K23/K$4)) -> 0 | L28: =IF(L$4="","",ABS(L23/L$4)) | M28: =IF(M$4="","",ABS(M23/M$4)) | N28: =IF(N$4="","",ABS(N23/N$4)) | ... Q28: =IF(Q$4="","",ABS(Q23/Q$4))
B29: =B24 -> Selling Expenses | C29: =AVERAGE(G29:J29) -> 0 | E29: Historical Average | G29: =IF(G$4="","",ABS(G24/G$4)) -> 0 | H29: =IF(H$4="","",ABS(H24/H$4)) -> 0 | I29: =IF(I$4="","",ABS(I24/I$4)) -> 0 | J29: =IF(J$4="","",ABS(J24/J$4)) -> 0 | K29: =IF(K$4="","",ABS(K24/K$4)) -> 0 | L29: =IF(L$4="","",ABS(L24/L$4)) | M29: =IF(M$4="","",ABS(M24/M$4)) | N29: =IF(N$4="","",ABS(N24/N$4)) | ... Q29: =IF(Q$4="","",ABS(Q24/Q$4))
B30: Variable Costs | C30: =ABS(C25/$C$4) -> 0.88783966 | G30: =IF(G$4="","",ABS(G25/G$4)) -> 0.88783966 | H30: =IF(H$4="","",ABS(H25/H$4)) -> 0.82604779 | I30: =IF(I$4="","",ABS(I25/I$4)) -> 0 | J30: =IF(J$4="","",ABS(J25/J$4)) -> 0 | K30: =IF(K$4="","",ABS(K25/K$4)) -> 0 | L30: =IF(L$4="","",ABS(L25/L$4)) | M30: =IF(M$4="","",ABS(M25/M$4)) | N30: =IF(N$4="","",ABS(N25/N$4)) | ... Q30: =IF(Q$4="","",ABS(Q25/Q$4))
B32: Fixed Costs
B33: G&A and other Opex | C33: -90000 | E33: Historical Average | G33: =Data!C41 -> -361467 | H33: =Data!D41 -> -390283 | I33: =Data!E41 -> -330088 | J33: =Data!F41 -> -389543 | K33: =Data!G41 -> -672911 | L33: =Data!H41 | M33: =Data!I41 | N33: =Data!J41 | ... Q33: =Data!M41
B34: R&D | C34: =AVERAGE(G34:J34) -> 0 | E34: Historical Average | G34: =Data!C42 -> 0 | H34: =Data!D42 -> 0 | I34: =Data!E42 -> 0 | J34: =Data!F42 -> 0 | K34: =Data!G42 -> 0 | L34: =Data!H42 | M34: =Data!I42 | N34: =Data!J42 | ... Q34: =Data!M42
B35: Fixed Costs | C35: =C33+C34 -> -90000 | G35: =IF(G4="","",G33+G34) -> -361467 | H35: =IF(H4="","",H33+H34) -> -390283 | I35: =IF(I4="","",I33+I34) -> -330088 | J35: =IF(J4="","",J33+J34) -> -389543 | K35: =IF(K4="","",K33+K34) -> -672911 | L35: =IF(L4="","",L33+L34) | M35: =IF(M4="","",M33+M34) | N35: =IF(N4="","",N33+N34) | ... Q35: =IF(Q4="","",Q33+Q34)
B37: Fixed Costs % of Sales
B38: =B33 -> G&A and other Opex | C38: =ABS(C33/$C$4) -> 0.36397313 | G38: =IF(G$4="","",ABS(G33/G$4)) -> 1.4618253 | H38: =IF(H$4="","",ABS(H33/H$4)) -> 1.3842228 | I38: =IF(I$4="","",ABS(I33/I$4)) -> 0.99438173 | J38: =IF(J$4="","",ABS(J33/J$4)) -> 0.51566823 | K38: =IF(K$4="","",ABS(K33/K$4)) -> 0.32814858 | L38: =IF(L$4="","",ABS(L33/L$4)) | M38: =IF(M$4="","",ABS(M33/M$4)) | N38: =IF(N$4="","",ABS(N33/N$4)) | ... Q38: =IF(Q$4="","",ABS(Q33/Q$4))
B39: =B34 -> R&D | C39: =ABS(C34/$C$4) -> 0 | G39: =IF(G$4="","",ABS(G34/G$4)) -> 0 | H39: =IF(H$4="","",ABS(H34/H$4)) -> 0 | I39: =IF(I$4="","",ABS(I34/I$4)) -> 0 | J39: =IF(J$4="","",ABS(J34/J$4)) -> 0 | K39: =IF(K$4="","",ABS(K34/K$4)) -> 0 | L39: =IF(L$4="","",ABS(L34/L$4)) | M39: =IF(M$4="","",ABS(M34/M$4)) | N39: =IF(N$4="","",ABS(N34/N$4)) | ... Q39: =IF(Q$4="","",ABS(Q34/Q$4))
B40: Fixed Costs | C40: =ABS(C35/$C$4) -> 0.36397313 | G40: =IF(G$4="","",ABS(G35/G$4)) -> 1.4618253 | H40: =IF(H$4="","",ABS(H35/H$4)) -> 1.3842228 | I40: =IF(I$4="","",ABS(I35/I$4)) -> 0.99438173 | J40: =IF(J$4="","",ABS(J35/J$4)) -> 0.51566823 | K40: =IF(K$4="","",ABS(K35/K$4)) -> 0.32814858 | L40: =IF(L$4="","",ABS(L35/L$4)) | M40: =IF(M$4="","",ABS(M35/M$4)) | N40: =IF(N$4="","",ABS(N35/N$4)) | ... Q40: =IF(Q$4="","",ABS(Q35/Q$4))
B42: Tax % of Pre-tax Profit
B43: Income Tax Rate | C43: 0.25 | E43: Use the highest past tax rate | G43: =IF(G$4="","",-G14/SUM(G8+G11,G12)) -> -0.011201582 | H43: =IF(H$4="","",-H14/SUM(H8+H11,H12)) -> -0.016365864 | I43: =IF(I$4="","",-I14/SUM(I8+I11,I12)) -> -1.1549008 | J43: =IF(J$4="","",-J14/SUM(J8+J11,J12)) -> 0.13838238 | K43: =IF(K$4="","",-K14/SUM(K8+K11,K12)) -> 0.16097344 | L43: =IF(L$4="","",-L14/SUM(L8+L11,L12)) | M43: =IF(M$4="","",-M14/SUM(M8+M11,M12)) | N43: =IF(N$4="","",-N14/SUM(N8+N11,N12)) | ... Q43: =IF(Q$4="","",-Q14/SUM(Q8+Q11,Q12))
B45: Non-operating Income | E45: Notes
B46: Interest
...

Sheet Valuation_Model
B2: No-Growth DCF Valuation | H2: Notes
B3: No-Growth DCF | C3: =Normalized_FCF!C3 -> 1000 | E3: Special Assumption
B4: Adjusted FCFE | C4: =Normalized_FCF!C19 -> 4084.7727 | D4: =Reporting_currency -> HKD | E4: Terminal Growth Rate (g): | F4: =Thesis!C76 -> 0
B5: /Equity Cost of Capital | C5: =Thesis!C70 -> 0.08
B6: Stable Income Value | C6: =(C4*(1+Terminal_Growth))/(Equity_Cost-Terminal_Growth) -> 51059.659 | D6: =Reporting_currency -> HKD | E6: Conservative Valuation: Setting g=0 can be a conservative assumption to avoid overestimating the stock’s value, especially if future growth is uncertain or unreliable.
B7: - Interest-bearing Debt | C7: =BS!G31 -> 97365 | D7: =Reporting_currency -> HKD
B8: + Non-operating Cash | C8: =BS!D66 -> 913534.95 | D8: =Reporting_currency -> HKD
B9: + Other Non-operating Assets | C9: =BS!H42 -> 84349.6 | D9: =Reporting_currency -> HKD
B10: Equity Value | C10: =C6-C7+C8+C9 -> 951579.21 | D10: =Reporting_currency -> HKD
B11: * Exchange rate | C11: =Exchange_Rate -> 1 | D11: =Thesis!D17 -> HKD
B12: Equity Value per share | C12: =(C10*C3)/Common_Shares*C11 -> 0.52092521 | D12: =Market_currency -> HKD
B14: Implied Growth Scenario Analysis
B15: FCFE Projection
B16: High Growth Period (HGP) | C16: =Scenarios!C65 -> 0.046574871
B17: High Growth Rate (HGR) | C17: =Scenarios!C64 -> 10
B18: Value Per Share | C18: =(F52-C7+C8+C9)*Exchange_Rate/Common_Shares*C3 -> 0.52541102 | D18: =Market_currency -> HKD
B20: Year | C20: FCFE | D20: Growth Rates | E20: Discount Factor | F20: PV of FCFE
B21: 1 | C21: =C4*(1+D21) -> 4275.0205 | D21: =IF($C$17<B21,0,Valuation_Model!$C$16) -> 0.046574871 | E21: =IF($C$17<B21,0,1/(1+Equity_Cost)^B21) -> 0.92592593 | F21: =C21*E21 -> 3958.3523
B22: 2 | C22: =IF(ROW()-ROW($C$21)<$C$17, $C$21*(1+D22)^(ROW()-ROW($C$21)), 0) -> 4474.129 | D22: =IF($C$17<B22,0,Valuation_Model!$C$16) -> 0.046574871 | E22: =IF($C$17<B22,0,1/(1+Equity_Cost)^B22) -> 0.85733882 | F22: =C22*E22 -> 3835.8445
B23: 3 | C23: =IF(ROW()-ROW($C$21)<$C$17, $C$21*(1+D23)^(ROW()-ROW($C$21)), 0) -> 4682.511 | D23: =IF($C$17<B23,0,Valuation_Model!$C$16) -> 0.046574871 | E23: =IF($C$17<B23,0,1/(1+Equity_Cost)^B23) -> 0.79383224 | F23: =C23*E23 -> 3717.1282
B24: 4 | C24: =IF(ROW()-ROW($C$21)<$C$17, $C$21*(1+D24)^(ROW()-ROW($C$21)), 0) -> 4900.5983 | D24: =IF($C$17<B24,0,Valuation_Model!$C$16) -> 0.046574871 | E24: =IF($C$17<B24,0,1/(1+Equity_Cost)^B24) -> 0.73502985 | F24: =C24*E24 -> 3602.086
B25: 5 | C25: =IF(ROW()-ROW($C$21)<$C$17, $C$21*(1+D25)^(ROW()-ROW($C$21)), 0) -> 5128.843 | D25: =IF($C$17<B25,0,Valuation_Model!$C$16) -> 0.046574871 | E25: =IF($C$17<B25,0,1/(1+Equity_Cost)^B25) -> 0.6805832 | F25: =C25*E25 -> 3490.6044
B26: 6 | C26: =IF(ROW()-ROW($C$21)<$C$17, $C$21*(1+D26)^(ROW()-ROW($C$21)), 0) -> 5367.7182 | D26: =IF($C$17<B26,0,Valuation_Model!$C$16) -> 0.046574871 | E26: =IF($C$17<B26,0,1/(1+Equity_Cost)^B26) -> 0.63016963 | F26: =C26*E26 -> 3382.573
B27: 7 | C27: =IF(ROW()-ROW($C$21)<$C$17, $C$21*(1+D27)^(ROW()-ROW($C$21)), 0) -> 5617.719 | D27: =IF($C$17<B27,0,Valuation_Model!$C$16) -> 0.046574871 | E27: =IF($C$17<B27,0,1/(1+Equity_Cost)^B27) -> 0.5834904 | F27: =C27*E27 -> 3277.8851
B28: 8 | C28: =IF(ROW()-ROW($C$21)<$C$17, $C$21*(1+D28)^(ROW()-ROW($C$21)), 0) -> 5879.3636 | D28: =IF($C$17<B28,0,Valuation_Model!$C$16) -> 0.046574871 | E28: =IF($C$17<B28,0,1/(1+Equity_Cost)^B28) -> 0.54026888 | F28: =C28*E28 -> 3176.4372
B29: 9 | C29: =IF(ROW()-ROW($C$21)<$C$17, $C$21*(1+D29)^(ROW()-ROW($C$21)), 0) -> 6153.1942 | D29: =IF($C$17<B29,0,Valuation_Model!$C$16) -> 0.046574871 | E29: =IF($C$17<B29,0,1/(1+Equity_Cost)^B29) -> 0.50024897 | F29: =C29*E29 -> 3078.129
B30: 10 | C30: =IF(ROW()-ROW($C$21)<$C$17, $C$21*(1+D30)^(ROW()-ROW($C$21)), 0) -> 6439.7784 | D30: =IF($C$17<B30,0,Valuation_Model!$C$16) -> 0.046574871 | E30: =IF($C$17<B30,0,1/(1+Equity_Cost)^B30) -> 0.46319349 | F30: =C30*E30 -> 2982.8634
B31: 11 | C31: =IF(ROW()-ROW($C$21)<$C$17, $C$21*(1+D31)^(ROW()-ROW($C$21)), 0) -> 0 | D31: =IF($C$17<B31,0,Valuation_Model!$C$16) -> 0 | E31: =IF($C$17<B31,0,1/(1+Equity_Cost)^B31) -> 0 | F31: =C31*E31 -> 0
B32: 12 | C32: =IF(ROW()-ROW($C$21)<$C$17, $C$21*(1+D32)^(ROW()-ROW($C$21)), 0) -> 0 | D32: =IF($C$17<B32,0,Valuation_Model!$C$16) -> 0 | E32: =IF($C$17<B32,0,1/(1+Equity_Cost)^B32) -> 0 | F32: =C32*E32 -> 0
B33: 13 | C33: =IF(ROW()-ROW($C$21)<$C$17, $C$21*(1+D33)^(ROW()-ROW($C$21)), 0) -> 0 | D33: =IF($C$17<B33,0,Valuation_Model!$C$16) -> 0 | E33: =IF($C$17<B33,0,1/(1+Equity_Cost)^B33) -> 0 | F33: =C33*E33 -> 0
... B50: 30 | C50: =IF(ROW()-ROW($C$21)<$C$17, $C$21*(1+D50)^(ROW()-ROW($C$21)), 0) -> 0 | D50: =IF($C$17<B50,0,Valuation_Model!$C$16) -> 0 | E50: =IF($C$17<B50,0,1/(1+Equity_Cost)^B50) -> 0 | F50: =C50*E50 -> 0
B51: Terminal Year | C51: =C$21*(1+Terminal_Growth)^$C$17/Equity_Cost -> 53437.756 | D51: =Terminal_Growth -> 0 | E51: =1/(1+Equity_Cost)^C17 -> 0.46319349 | F51: =C51*E51 -> 24752.02
E52: Total PV | F52: =SUM(F21:F51) -> 59253.924
B54: Sensitivity Analysis (Enterprise Value)
A55: =F52 -> 59253.924 | B55: =C78 -> 0 | C55: =C77 -> 0.02 | D55: =C76 -> 0 | E55: =C75 -> 0.06 | F55: =C74 -> 0.1
A56: 5 | B56: 51059.659 | C56: 52707.111 | D56: 51059.659 | E56: 56152.201 | F56: 59812.311
A57: 10 | B57: 51059.659 | C57: 54356.079 | D57: 51059.659 | E57: 61979.633 | F57: 71263.616
A58: 15 | B58: 51059.659 | C58: 56397.136 | D58: 51059.659 | E58: 69995.492 | F58: 88888.45
A59: 20 | B59: 51059.659 | C59: 58476.645 | D59: 51059.659 | E59: 79139.407 | F59: 111659.53
A60: 25 | B60: 51059.659 | C60: 60410.703 | D60: 51059.659 | E60: 88721.952 | F60: 138968.48
...

Sheet Scenarios
B2: Current Situation | H2: Warning: Do Not Remove this logic
B3: Selection | H3: 0 | I3: =-Market_Price -> -1.35
B4: Past Years Selected | C4: 3 | E4: Tie the business story into the three levers of value: FCFE, growth and risk. | H4: 1 | I4: =IF(ROW()-3 < $C$76, $C$77, IF(ROW()-3 = $C$76, $C$77 + $C$60, "")) -> 0.01
H5: 2 | I5: =IF(ROW()-3 < $C$76, $C$77, IF(ROW()-3 = $C$76, $C$77 + $C$60, "")) -> 0.01
B6: Latest | C6: =Valuation_Model!C3 -> 1000 | E6: Prompt for fundamental Analysis | H6: 3 | I6: =IF(ROW()-3 < $C$76, $C$77, IF(ROW()-3 = $C$76, $C$77 + $C$60, "")) -> 0.5333615
B7: EBIT | C7: =Normalized_FCF!G8 -> -333733 | D7: =Reporting_currency -> HKD | E7: ="Please develop three logical "&C18&"-year scenarios (Base Case, Pessimistic Case, Optimistic Case) and two extreme "&C46&"-year scenarios (Success Scenario, Devil’s Advocate Scenario) for "&Thesis!C5&"("&Thesis!D5&"). Each scenario should include the Compound Growth Rate, the Probability Assessment, and the Business Narrative." -> Please develop three logical 10-year scenarios (Base Case, Pessimistic Case, Optimistic Case) and two extreme 15-year scenarios (Success Scenario, Devil’s Advocate Scenario) for 惠理集團(0806.HK). Each scenario should include the Compound Growth Rate, the Probability Assessment, and the Business Narrative. | H7: 4 | I7: =IF(ROW()-3 < $C$76, $C$77, IF(ROW()-3 = $C$76, $C$77 + $C$60, ""))
B8: FCFE | C8: =Normalized_FCF!G19 -> -263415.91 | D8: =Reporting_currency -> HKD | H8: 5 | I8: =IF(ROW()-3 < $C$76, $C$77, IF(ROW()-3 = $C$76, $C$77 + $C$60, ""))
B9: Normalized | C9: =Normalized_FCF!C19 -> 4084.7727 | D9: =Reporting_currency -> HKD | H9: 6 | I9: =IF(ROW()-3 < $C$76, $C$77, IF(ROW()-3 = $C$76, $C$77 + $C$60, ""))
H10: 7 | I10: =IF(ROW()-3 < $C$76, $C$77, IF(ROW()-3 = $C$76, $C$77 + $C$60, ""))
B11: CAGR | H11: 8 | I11: =IF(ROW()-3 < $C$76, $C$77, IF(ROW()-3 = $C$76, $C$77 + $C$60, ""))
B12: Sales | C12: =(Normalized_FCF!G4/OFFSET(Normalized_FCF!G4, 0, $C$4))^(1/$C$4) - 1 -> -0.31082521 | H12: 9 | I12: =IF(ROW()-3 < $C$76, $C$77, IF(ROW()-3 = $C$76, $C$77 + $C$60, ""))
B13: Operating EBIT | C13: =(Normalized_FCF!G8/OFFSET(Normalized_FCF!G8, 0, $C$4))^(1/$C$4) - 1 -> -1.9698183 | H13: 10 | I13: =IF(ROW()-3 < $C$76, $C$77, IF(ROW()-3 = $C$76, $C$77 + $C$60, ""))
B14: FCFE | C14: =(Normalized_FCF!G19/OFFSET(Normalized_FCF!G19, 0, $C$4))^(1/$C$4) - 1 -> -1.9453138
B16: General Scenarios
B17: Assumption | E17: Guidance Note
B18: High Growth Period (HGP) | C18: 10 | E18: Fundamental analysis and market signal analysis should be combined, with fundamental analysis given priority and market signal analysis serving as a supplement. Market signal analysis predicts a company's future trend, while fundamental analysis interprets the trend and identifies relevant fundamental factors and possibilities.
B20: Reference
B21: Market Price | C21: =Market_Price -> 1.35 | D21: =Market_currency -> HKD
B22: No Growth Value per share | C22: =Valuation_Model!C12 -> 0.52092521 | D22: =Market_currency -> HKD
B24: Base | E24: Business Story
B25: High Growth Period (HGP) | C25: =C18 -> 10
B26: High Growth Rate (HGR) | C26: 0
B27: Value per share | C27: =Valuation_Model!E76 -> 0.52092521 | D27: =Market_currency -> HKD
B28: Probabilities | C28: 0.6
B30: Pessimistic | E30: Business Story
B31: High Growth Period (HGP) | C31: =C18 -> 10
B32: High Growth Rate (HGR) | C32: 0.02
B33: Value per share | C33: =Valuation_Model!E77 -> 0.52272978 | D33: =Market_currency -> HKD
B34: Probabilities | C34: 0.2
B36: Optimistic | E36: Business Story
B37: High Growth Period (HGP) | C37: =C18 -> 10
B38: High Growth Rate (HGR) | C38: 0.06
B39: Value per share | C39: =Valuation_Model!E75 -> 0.52690316 | D39: =Market_currency -> HKD
B40: Probabilities | C40: =1-C28-C34 -> 0.2
B42: Expected Value = | C42: =C27*C28+C33*C34+C39*C40 -> 0.52248172 | D42: =Market_currency -> HKD
B44: Extreme Scenarios
B45: Assumption
B46: High Growth Period (HGP) | C46: 15
B48: Devil's advocate | E48: Business Story
B49: High Growth Period (HGP) | C49: =C46 -> 15
...
