Workbook
Name Common_Shares: Thesis!$C$9
Name dividend_tax_rate: Normalized_FCF!$C$91
Name Equity_Cost: Thesis!$C$101
Name Exchange_Rate: Thesis!$E$16
Name FV_adjustments: DCF!$F$7
Name Holding_Period: Thesis!$E$21
Name Market_currency: Thesis!$C$7
Name Market_Price: Thesis!$C$8
Name Reporting_currency: Thesis!$E$17
Name scaling_factor: Data!$C$3
Name Terminal_Growth: Thesis!$C$17

Sheet Thesis
A2: Executive Summary
E3: Last Updated: | F3: 46038
B4: Company: | C4: 中国移动 | E4: Portfolio: | F4: INT
B5: Symbol: | C5: 0941.HK | E5: Selected: | F5: Y
B6: Comp_Sector: | C6: TMT_01
B7: Market Currency: | C7: HKD
B8: Market Price: | C8: 79.95
B9: Number of Shares: | C9: =20741838745+902767867 -> 21644606612
B10: Market Capitalization: | C10: =Thesis!C8*Common_Shares/1000000 -> 1730486.3 | D10: Implied Annual Return: | E10: =Scenarios!F34 -> 0.19891674
B12: Guidance Note: This model evaluates the company using a structured investment process to determine its intrinsic value and target prices. It focuses on sustainable FCF capacity, adjusts for financial structure, incorporates growth scenarios, and calculates expected returns based on the derived intrinsic value.
B14: =Scenarios!B39&" Valuation Conclusion" -> 1-stage DCF Valuation Conclusion
B15: Business Model Risk Premium: | C15: N | D15: Forex Symbol: | E15: =IF(E17=C7,C7,E17&"/"&C7) -> CNY/HKD
B16: Management Risk Premium: | C16: N | D16: Exchange Rate: | E16: 1.1348425
B17: Terminal Growth Rate (g) | C17: 0.02 | D17: Reporting Currency: | E17: CNY
B18: ="Expected Equity Value ("&C7&") :" -> Expected Equity Value (HKD) : | C18: =C125 -> 121.12182 | D18: Report Interval: | E18: 6
B19: Growth Classification: | C19: =IF(Terminal_Growth<2%, "Lower than Inflation rate", IF(Terminal_Growth<5%, "Low growth", IF(Terminal_Growth<8%, "Medium growth", "High growth"))) -> Low growth | D19: Update Required After: | E19: =EOMONTH(EDATE(BS!C1,E18+2),0) -> 46081
B21: Price Targets | C21: =C138&" ("&Market_currency&")" -> (HKD) | D21: Holding Period | E21: 3
B22: Target Price | C22: =E140 -> 64.199058 | D22: @Target return | E22: 0.29465259
B23: Entry Price | C23: =E141 -> 79.600506 | D23: @Entry yield | E23: 0.20075184
B24: Exit Price | C24: =E144 -> 97.867461 | D24: @Benchmark yield | E24: 0.1174
B25: Sell Price | C25: =E145 -> 110.14898 | D25: @Base equity cost | E25: 0.0725
A27: Step 1: Establishing the Company’s Sustainable Earning Power (Calculating Normalized FCFE)
B29: Goal: To quantify the underlying FCFE the business consistently generates, stripping away temporary fluctuations or accounting choices.
B30: FCFE = (Normalized Operating EBIT + Depreciation & Amortization – Capital Expenditures) + Stable Non-Operating EBIT + Net Interest Income – Taxes – NCI’s Share of Profits – Working Capital Investment
B32: Key Components | C32: =scaling_factor -> 1000000
B33: • Normalized Operating EBIT: Earnings before interest and taxes from core business operations, adjusted to remove one-time or irregular items for a sustainable earnings base.
B34: Normalized Operating EBIT = | C34: =Normalized_FCF!C8 -> 135679.52 | D34: =Reporting_currency -> CNY
B36: • Depreciation & Amortization (D&A): Non-cash expenses added back to reflect cash generated from operations. • Capital Expenditures (Capex): Cash outflows required to maintain or expand operational assets
B37: D&A = | C37: =Normalized_FCF!C15 -> 191101 | D37: =Reporting_currency -> CNY
B38: Capex = | C38: =Normalized_FCF!C16 -> -191101 | D38: =Reporting_currency -> CNY
B40: • Stable Non-Operating EBIT: Consistent earnings from non-core assets, such as fixed-income investments, dividend-paying stocks, or rental properties.
B41: Stable Non-Operating EBIT = | C41: =Normalized_FCF!C9 -> 7974.2 | D41: =Reporting_currency -> CNY
B43: • Net Interest Income: Interest income minus interest expense
B44: Operating Interest Income = | C44: =Normalized_FCF!C46 -> 507.62527 | D44: =Reporting_currency -> CNY
B45: Interest Expense = | C45: =Normalized_FCF!C45 -> -5515.92 | D45: =Reporting_currency -> CNY
B46: Net Interest Income = | C46: =Normalized_FCF!C10 -> -5008.2947 | D46: =Reporting_currency -> CNY
B48: • NCI’s Share of Profits: NCI represents the portion of a subsidiary’s equity not owned by the parent company.
B49: Est. NCI’s Share of Profits = | C49: =Normalized_FCF!C13 -> -193.85602 | D49: =Reporting_currency -> CNY
B51: • Taxes: Tax = (Normalized Operating EBIT + Stable Non-Operating EBIT + Interest Income – Interest Expense) × Tax Rate
B52: Taxes = | C52: =Normalized_FCF!C12 -> -34661.355 | D52: =Reporting_currency -> CNY
...

Sheet Data
B1: =Thesis!E17 -> CNY | C1: 45657 | D1: =EOMONTH(EDATE(C1,-12),0) -> 45291 | E1: =EOMONTH(EDATE(D1,-12),0) -> 44926 | F1: =EOMONTH(EDATE(E1,-12),0) -> 44561 | G1: =EOMONTH(EDATE(F1,-12),0) -> 44196 | H1: =EOMONTH(EDATE(G1,-12),0) -> 43830 | I1: =EOMONTH(EDATE(H1,-12),0) -> 43465 | J1: =EOMONTH(EDATE(I1,-12),0) -> 43100 | K1: =EOMONTH(EDATE(J1,-12),0) -> 42735 | ... M1: =EOMONTH(EDATE(L1,-12),0) -> 42004
B2: Data (Dirty)
B3: Income Statement | C3: 1000000
B4: Sales | C4: 1040759 | D4: 1009309 | E4: 937259 | F4: 848258
B5: COGS | C5: =283341+191101+151944 -> 626386 | D5: =268895+207132+144333 -> 620360 | E5: =254182+200077+130157 -> 584416 | F5: =225010+193045+118680 -> 536735
B6: OPEX | C6: =67979+C7 -> 271783 | D6: =D7+59319 -> 254603 | E6: =51409+E7 -> 223744 | F6: =49234+F7 -> 194551
B7: Incl. Selling Expenses | C7: =54564+149240 -> 203804 | D7: =52477+142807 -> 195284 | E7: =49592+122743 -> 172335 | F7: =96083+49234 -> 145317
B8: R&D
B9: Share of JV or associate Results | C9: 11097 | D9: 8958 | E9: 10986 | F9: 11914
B10: Dividend or Interests from FA
B11: Investment property
B12: Interest Expense | C12: 3273 | D12: 3730 | E12: 2330 | F12: 2679
B13: Interest Income | C13: 23005 | D13: 21134 | E13: 15729 | F13: 16729
B14: Income Tax Paid | C14: 39863 | D14: 38596 | E14: 37278 | F14: 35878
B15: Reported Net Income | C15: 138526 | D15: 131935 | E15: 125594 | F15: 116306
B16: Non-controling Interests | C16: 153 | D16: 169 | E16: 135 | F16: 158
B18: Cash Flow Statement
B19: D&A | C19: 191101 | D19: 207132 | E19: 200077 | F19: 193045
B20: CAPX
B21: WCInv
B22: CFO | C22: 354393 | D22: 361933 | E22: 280750 | F22: 314764
B23: CFI | C23: -185194 | D23: -205699 | E23: -238053 | F23: -238296
B24: CFF | C24: -105167 | D24: -123843 | E24: -120514 | F24: -45201
B25: ="Dividend per share ("&Market_currency&")" -> Dividend per share (HKD) | C25: =2.49+2.6 -> 5.09 | D25: =2.4+2.43 -> 4.83 | E25: =2.21+2.2 -> 4.41 | F25: =2.43+1.63 -> 4.06
B27: Balance Sheet | C27: Latest Asset Value
B28: ST AR | C28: =BS!C4 -> 125999 | D28: =54881+12342+1205 -> 68428 | E28: =40245+12838+2537 -> 55620 | F28: =34668+10137+2612 -> 47417
B29: ST Inventory | C29: =BS!C6 -> 11378 | D29: 12026 | E29: 11696 | F29: 10203
B30: Total Liabilities | C30: =BS!C33+BS!C42 -> 693546 | D30: 646672 | E30: 634115 | F30: 631035
B31: Total Equity | C31: =BS!G27 -> 1434194 | D31: 1345985 | E31: 1301423 | F31: 1210292
B32: Non-common Interest | C32: =BS!G28 -> 4523 | D32: 4253 | E32: 4075 | F32: 3942
B34: IS & CF Statements (Clean)
B35: Income Statement
B36: Sales | C36: =IF(C$4="","",C4) -> 1040759 | D36: =IF(D$4="","",D4) -> 1009309 | E36: =IF(E$4="","",E4) -> 937259 | F36: =IF(F$4="","",F4) -> 848258 | G36: =IF(G$4="","",G4) | H36: =IF(H$4="","",H4) | I36: =IF(I$4="","",I4) | J36: =IF(J$4="","",J4) | ... M36: =IF(M$4="","",M4)
B37: COGS | C37: =IF(C$4="","",-C5) -> -626386 | D37: =IF(D$4="","",-D5) -> -620360 | E37: =IF(E$4="","",-E5) -> -584416 | F37: =IF(F$4="","",-F5) -> -536735 | G37: =IF(G$4="","",-G5) | H37: =IF(H$4="","",-H5) | I37: =IF(I$4="","",-I5) | J37: =IF(J$4="","",-J5) | ... M37: =IF(M$4="","",-M5)
B38: Gross Margin | C38: =IF(C36="","",C36+C37) -> 414373 | D38: =IF(D36="","",D36+D37) -> 388949 | E38: =IF(E36="","",E36+E37) -> 352843 | F38: =IF(F36="","",F36+F37) -> 311523 | G38: =IF(G36="","",G36+G37) | H38: =IF(H36="","",H36+H37) | I38: =IF(I36="","",I36+I37) | J38: =IF(J36="","",J36+J37) | ... M38: =IF(M36="","",M36+M37)
B39: OPEX | C39: =IF(C$4="","",-C6) -> -271783 | D39: =IF(D$4="","",-D6) -> -254603 | E39: =IF(E$4="","",-E6) -> -223744 | F39: =IF(F$4="","",-F6) -> -194551 | G39: =IF(G$4="","",-G6) | H39: =IF(H$4="","",-H6) | I39: =IF(I$4="","",-I6) | J39: =IF(J$4="","",-J6) | ... M39: =IF(M$4="","",-M6)
B40: Incl. Selling Expenses | C40: =IF(C$4="","",-C7) -> -203804 | D40: =IF(D$4="","",-D7) -> -195284 | E40: =IF(E$4="","",-E7) -> -172335 | F40: =IF(F$4="","",-F7) -> -145317 | G40: =IF(G$4="","",-G7) | H40: =IF(H$4="","",-H7) | I40: =IF(I$4="","",-I7) | J40: =IF(J$4="","",-J7) | ... M40: =IF(M$4="","",-M7)
B41: Incl. Other Opex | C41: =IF(C$4="","",C39-C40) -> -67979 | D41: =IF(D$4="","",D39-D40) -> -59319 | E41: =IF(E$4="","",E39-E40) -> -51409 | F41: =IF(F$4="","",F39-F40) -> -49234 | G41: =IF(G$4="","",G39-G40) | H41: =IF(H$4="","",H39-H40) | I41: =IF(I$4="","",I39-I40) | J41: =IF(J$4="","",J39-J40) | ... M41: =IF(M$4="","",M39-M40)
B42: R&D | C42: =IF(C$4="","",-C8) -> 0 | D42: =IF(D$4="","",-D8) -> 0 | E42: =IF(E$4="","",-E8) -> 0 | F42: =IF(F$4="","",-F8) -> 0 | G42: =IF(G$4="","",-G8) | H42: =IF(H$4="","",-H8) | I42: =IF(I$4="","",-I8) | J42: =IF(J$4="","",-J8) | ... M42: =IF(M$4="","",-M8)
B43: Operating EBIT | C43: =IF(C$4="","",C38+C39+C42) -> 142590 | D43: =IF(D$4="","",D38+D39+D42) -> 134346 | E43: =IF(E$4="","",E38+E39+E42) -> 129099 | F43: =IF(F$4="","",F38+F39+F42) -> 116972 | G43: =IF(G$4="","",G38+G39+G42) | H43: =IF(H$4="","",H38+H39+H42) | I43: =IF(I$4="","",I38+I39+I42) | J43: =IF(J$4="","",J38+J39+J42) | ... M43: =IF(M$4="","",M38+M39+M42)
...

Sheet BS
B1: Most Recent Quarter | C1: 45838 | F1: =IF(MONTH(C1)=MONTH(Normalized_FCF!G1),"FY","Quarter")&" Report" -> Quarter Report | H1: =scaling_factor -> 1000000
B2: Lastest Balance Sheet
B3: ST Operating Assets | C3: Book | D3: Valued @ | F3: ST Non-Operating Assets | G3: Book | H3: Valued @
B4: ST AR | C4: =105822+19725+452 -> 125999 | D4: 0.6 | F4: Cash and cash equivalents | G4: =95696+94566 -> 190262 | H4: 0.9
B5: Operating ST Financial Assets | C5: 0 | D5: 0.6 | F5: Restricted cash | G5: 0 | H5: 0.7
B6: Inventory | C6: 11378 | D6: 0.5 | F6: Securities with stable income | G6: 0 | H6: 0.6
B7: Properties held for sale | C7: 0 | D7: 0.6 | F7: Other Securities | G7: =145688+12656 -> 158344 | H7: 0.6
B8: Properties held for income | C8: 0 | D8: 0.6 | F8: Properties with stable income | G8: 0 | H8: 0.6
B9: Prepayments and Contract Assets | C9: =21813+9977 -> 31790 | D9: 0.1 | F9: Other Properties | G9: 0 | H9: 0.6
B10: ST DTA | C10: 410 | D10: 0.9 | F10: Assets held for sale | G10: 0 | H10: 0.6
B11: Other ST Assets | C11: =26591 -> 26591 | D11: 0.05
B12: Operating ST Assets | C12: =SUM(C4:C11) -> 196168 | D12: =C4*D4+C5*D5+C9*D9+C6*D6+C8*D8+C7*D7+C10*D10+C11*D11 -> 86165.95 | F12: Non-Operating ST Assets | G12: =SUM(G4:G10) -> 348606 | H12: =G4*H4+G5*H5+G6*H6+G7*H7+G8*H8+G9*H9+G10*H10 -> 266242.2
B14: LT Operating Assets | C14: Book | D14: Valued @ | F14: LT Non-Operating Assets | G14: Book | H14: Valued @
B15: LT AR and Prepayments | C15: 0 | D15: 0.4 | F15: LT Depositis | G15: 61316 | H15: 0.8
B16: Operating LT Financial Assets | C16: 0 | D16: 0.5 | F16: Securities with stable income | G16: 0 | H16: 0.6
B17: Properties held for sale | C17: 0 | D17: 0.6 | F17: Other Securities | G17: =29456+242399+7357 -> 279212 | H17: 0.6
B18: Properties held for income | C18: 0 | D18: 0.6 | F18: JV or associate with stable income | G18: 199355 | H18: 0.1
B19: PP&E & Right of Use Assets | C19: =673565+95328+81508+14255 -> 864656 | D19: 0.1 | F19: Other JV or associate | G19: 0 | H19: 0.1
B20: Biological assets | C20: 0 | D20: 0.05 | F20: Properties with stable income | G20: 0 | H20: 0.2
B21: Intangible assets | C21: 33529 | D21: 0.05 | F21: Other Properties | G21: 0 | H21: 0.1
B22: LT DTA | C22: 54333 | D22: 0.9
B23: Other assets & Goodwill | C23: =35305+3141+52119 -> 90565 | D23: 0
B24: Operating LT Assets | C24: =SUM(C15:C23) -> 1043083 | D24: =C15*D15+C16*D16+C18*D18+C17*D17+C19*D19+C20*D20+C21*D21+C22*D22+C23*D23 -> 137041.75 | F24: Non-Operating LT Assets | G24: =SUM(G15:G21) -> 539883 | H24: =G15*H15+G16*H16+G17*H17+G18*H18+G19*H19+G20*H20+G21*H21 -> 236515.5
B26: ST Liabilities | C26: Book | F26: BS Summary | G26: Book | H26: Valued @
B27: ST Borrowing | C27: 0 | F27: Total Equity | G27: =G32-G30 -> 1434194 | H27: =H32-G30 -> 32419.4
B28: ST Lease liabilities | C28: 37495 | F28: Incl. Minority Interest (NCI) | G28: 4523
B29: ST SH Loan | C29: 0 | F29: Incl. Common Equity | G29: =G27-G28 -> 1429671 | H29: =H27-G28 -> 27896.4
B30: ST Financial Liabilities | C30: 0 | F30: Total Liabilities | G30: =C33+C42 -> 693546
B31: ST Interest-bearing Debt | C31: =SUM(C27:C30) -> 37495 | F31: incl. Interest-bearing Debt | G31: =C31+C40 -> 91932
B32: Other ST liabilities | C32: =C33-C31 -> 578929 | F32: Total Assets | G32: =G35+G40 -> 2127740 | H32: =H35+H40 -> 725965.4
B33: Current Liabilities | C33: 616424
F34: Assets Summary | G34: Book | H34: Valued @
B35: LT Liabilities | C35: Book | F35: Operating Assets | G35: =C12+C24 -> 1239251 | H35: =D12+D24 -> 223207.7
B36: LT Borrowing | C36: 0 | F36: incl. AR | G36: =C4+C15 -> 125999
B37: LT Lease liabilities | C37: 54437 | F37: incl. inventory | G37: =C6 -> 11378
B38: LT SH Loan | C38: 0 | F38: incl. Properties held for sale | G38: =C7+C17 -> 0
B39: LT Financial Liabilities | C39: 0 | F39: incl. Fixed Assets | G39: =C7+C17+C19+C20 -> 864656 | H39: =C7*D7+C17*D17+C19*D19+C20*D20 -> 86465.6
B40: LT Interest-bearing Debt | C40: =SUM(C36:C39) -> 54437 | F40: Non-operating Assets | G40: =G12+G24 -> 888489 | H40: =H12+H24 -> 502757.7
B41: Other LT liabilities | C41: =C42-C40 -> 22685 | F41: incl. Assets with stable income | G41: =C70 -> 450933 | H41: =H40-H42 -> 240224.1
B42: Noncurrent Liabilities | C42: 77122 | F42: incl. Other Assets | G42: =C82 -> 437556 | H42: =D82 -> 262533.6
...

Sheet Normalized_FCF
B1: =Thesis!E17 -> CNY | C1: Normalized | G1: =Data!C1 -> 45657 | H1: =EOMONTH(EDATE(G1,-12),0) -> 45291 | I1: =EOMONTH(EDATE(H1,-12),0) -> 44926 | J1: =EOMONTH(EDATE(I1,-12),0) -> 44561 | K1: =EOMONTH(EDATE(J1,-12),0) -> 44196 | L1: =EOMONTH(EDATE(K1,-12),0) -> 43830 | M1: =EOMONTH(EDATE(L1,-12),0) -> 43465 | N1: =EOMONTH(EDATE(M1,-12),0) -> 43100 | O1: =EOMONTH(EDATE(N1,-12),0) -> 42735 | ... Q1: =EOMONTH(EDATE(P1,-12),0) -> 42004
B2: FCFE Analysis | E2: Notes
B3: Normalized FCFE | C3: =scaling_factor -> 1000000 | G3: Historical FCFE | H3: =scaling_factor -> 1000000
B4: Sales | C4: =C100*C117 -> 1040759 | G4: =Data!C36 -> 1040759 | H4: =Data!D36 -> 1009309 | I4: =Data!E36 -> 937259 | J4: =Data!F36 -> 848258 | K4: =Data!G36 | L4: =Data!H36 | M4: =Data!I36 | N4: =Data!J36 | ... Q4: =Data!M36
B5: Variable Costs | C5: =C26 -> -837100.48 | G5: =G26 -> -830190 | H5: =H26 -> -815644 | I5: =I26 -> -756751 | J5: =J26 -> -682052 | K5: =K26 | L5: =L26 | M5: =M26 | N5: =N26 | ... Q5: =Q26
B6: Contribution Margin | C6: =C4+C5 -> 203658.52 | G6: =IF(G4="","",G4+G5) -> 210569 | H6: =IF(H4="","",H4+H5) -> 193665 | I6: =IF(I4="","",I4+I5) -> 180508 | J6: =IF(J4="","",J4+J5) -> 166206 | K6: =IF(K4="","",K4+K5) | L6: =IF(L4="","",L4+L5) | M6: =IF(M4="","",M4+M5) | N6: =IF(N4="","",N4+N5) | ... Q6: =IF(Q4="","",Q4+Q5)
B7: Fixed Costs | C7: =C35 -> -67979 | G7: =G35 -> -67979 | H7: =H35 -> -59319 | I7: =I35 -> -51409 | J7: =J35 -> -49234 | K7: =K35 | L7: =L35 | M7: =M35 | N7: =N35 | ... Q7: =Q35
B8: Operating EBIT | C8: =C6+C7 -> 135679.52 | G8: =IF(G$4="","",G6+G7) -> 142590 | H8: =IF(H$4="","",H6+H7) -> 134346 | I8: =IF(I$4="","",I6+I7) -> 129099 | J8: =IF(J$4="","",J6+J7) -> 116972 | K8: =IF(K$4="","",K6+K7) | L8: =IF(L$4="","",L6+L7) | M8: =IF(M$4="","",M6+M7) | N8: =IF(N$4="","",N6+N7) | ... Q8: =IF(Q$4="","",Q6+Q7)
B9: Stable Non-Operating EBIT | C9: =C61 -> 7974.2 | G9: =G59 -> 11097 | H9: =H59 -> 8958 | I9: =I59 -> 10986 | J9: =J59 -> 11914 | K9: =K59 | L9: =L59 | M9: =M59 | N9: =N59 | ... Q9: =Q59
B10: Net Interest Income | C10: =C48 -> -5008.2947 | G10: =G48 -> 4463.447 | H10: =H48 -> 3377.2407 | I10: =I48 -> 2959.5708 | J10: =J48 -> 2946.8649 | K10: =K48 | L10: =L48 | M10: =M48 | N10: =N48 | ... Q10: =Q48
B11: Pre-tax Profit | C11: =SUM(C8:C10) -> 138645.42 | G11: =IF(G$4="","",SUM(G8:G10)) -> 158150.45 | H11: =IF(H$4="","",SUM(H8:H10)) -> 146681.24 | I11: =IF(I$4="","",SUM(I8:I10)) -> 143044.57 | J11: =IF(J$4="","",SUM(J8:J10)) -> 131832.86 | K11: =IF(K$4="","",SUM(K8:K10)) | L11: =IF(L$4="","",SUM(L8:L10)) | M11: =IF(M$4="","",SUM(M8:M10)) | N11: =IF(N$4="","",SUM(N8:N10)) | ... Q11: =IF(Q$4="","",SUM(Q8:Q10))
B12: Income Tax | C12: =-C11*C41 -> -34661.355 | G12: =Data!C46 -> -39863 | H12: =Data!D46 -> -38596 | I12: =Data!E46 -> -37278 | J12: =Data!F46 -> -35878 | K12: =Data!G46 | L12: =Data!H46 | M12: =Data!I46 | N12: =Data!J46 | ... Q12: =Data!M46
B13: NCI’s Share of Profits | C13: =-C4*C79 -> -193.85602 | G13: =Data!C48 -> -153 | H13: =Data!D48 -> -169 | I13: =Data!E48 -> -135 | J13: =Data!F48 -> -158 | K13: =Data!G48 | L13: =Data!H48 | M13: =Data!I48 | N13: =Data!J48 | ... Q13: =Data!M48
B14: After-tax Profit | C14: =SUM(C11:C13) -> 103790.21 | G14: =IF(G$4="","",SUM(G11:G13)) -> 118134.45 | H14: =IF(H$4="","",SUM(H11:H13)) -> 107916.24 | I14: =IF(I$4="","",SUM(I11:I13)) -> 105631.57 | J14: =IF(J$4="","",SUM(J11:J13)) -> 95796.865 | K14: =IF(K$4="","",SUM(K11:K13)) | L14: =IF(L$4="","",SUM(L11:L13)) | M14: =IF(M$4="","",SUM(M11:M13)) | N14: =IF(N$4="","",SUM(N11:N13)) | ... Q14: =IF(Q$4="","",SUM(Q11:Q13))
B15: Add Back D&A | C15: =BS!$G$39*BS!D58 -> 191101 | G15: =IF(Data!C61="","",-Data!C61) -> 191101 | H15: =IF(Data!D61="","",-Data!D61) -> 207132 | I15: =IF(Data!E61="","",-Data!E61) -> 200077 | J15: =IF(Data!F61="","",-Data!F61) -> 193045 | K15: =IF(Data!G61="","",-Data!G61) | L15: =IF(Data!H61="","",-Data!H61) | M15: =IF(Data!I61="","",-Data!I61) | N15: =IF(Data!J61="","",-Data!J61) | ... Q15: =IF(Data!M61="","",-Data!M61)
B16: Maintenance Capex | C16: =-C4*C82 -> -191101 | G16: =Data!C62 -> -191101 | H16: =Data!D62 -> -207132 | I16: =Data!E62 -> -200077 | J16: =Data!F62 -> -193045 | K16: =Data!G62 | L16: =Data!H62 | M16: =Data!I62 | N16: =Data!J62 | ... Q16: =Data!M62
B17: WCInv | C17: =-C4*C83 -> 0 | E17: WCInv is by default excluded
B18: Net Borrowing | C18: 0 | E18: Net borrowing is excluded
B19: FCFE | C19: =C14+C17 -> 103790.21 | G19: =IF(G$4="","",G14+G17) -> 118134.45 | H19: =IF(H$4="","",H14+H17) -> 107916.24 | I19: =IF(I$4="","",I14+I17) -> 105631.57 | J19: =IF(J$4="","",J14+J17) -> 95796.865 | K19: =IF(K$4="","",K14+K17) | L19: =IF(L$4="","",L14+L17) | M19: =IF(M$4="","",M14+M17) | N19: =IF(N$4="","",N14+N17) | ... Q19: =IF(Q$4="","",Q14+Q17)
B21: Operating Cost Structure | E21: Notes
B22: Variable Costs
B23: COGS | C23: =-C4*C29 -> -643392.11 | G23: =Data!C37 -> -626386 | H23: =Data!D37 -> -620360 | I23: =Data!E37 -> -584416 | J23: =Data!F37 -> -536735 | K23: =Data!G37 | L23: =Data!H37 | M23: =Data!I37 | N23: =Data!J37 | ... Q23: =Data!M37
B24: Selling Expenses | C24: =-C4*C30 -> -193708.37 | G24: =Data!C40 -> -203804 | H24: =Data!D40 -> -195284 | I24: =Data!E40 -> -172335 | J24: =Data!F40 -> -145317 | K24: =Data!G40 | L24: =Data!H40 | M24: =Data!I40 | N24: =Data!J40 | ... Q24: =Data!M40
B25: R&D | C25: =-C4*C31 -> 0 | G25: =Data!C42 -> 0 | H25: =Data!D42 -> 0 | I25: =Data!E42 -> 0 | J25: =Data!F42 -> 0 | K25: =Data!G42 | L25: =Data!H42 | M25: =Data!I42 | N25: =Data!J42 | ... Q25: =Data!M42
B26: Variable Costs | C26: =SUM(C23:C25) -> -837100.48 | G26: =IF(G$4="","",SUM(G23:G25)) -> -830190 | H26: =IF(H$4="","",SUM(H23:H25)) -> -815644 | I26: =IF(I$4="","",SUM(I23:I25)) -> -756751 | J26: =IF(J$4="","",SUM(J23:J25)) -> -682052 | K26: =IF(K$4="","",SUM(K23:K25)) | L26: =IF(L$4="","",SUM(L23:L25)) | M26: =IF(M$4="","",SUM(M23:M25)) | N26: =IF(N$4="","",SUM(N23:N25)) | ... Q26: =IF(Q$4="","",SUM(Q23:Q25))
B28: Variable Costs % of Sales
B29: COGS | C29: =AVERAGE(G29:J29) -> 0.6181951 | G29: =IF(G$4="","",ABS(G23/G$4)) -> 0.60185499 | H29: =IF(H$4="","",ABS(H23/H$4)) -> 0.61463833 | I29: =IF(I$4="","",ABS(I23/I$4)) -> 0.62353736 | J29: =IF(J$4="","",ABS(J23/J$4)) -> 0.63274971 | K29: =IF(K$4="","",ABS(K23/K$4)) | L29: =IF(L$4="","",ABS(L23/L$4)) | M29: =IF(M$4="","",ABS(M23/M$4)) | N29: =IF(N$4="","",ABS(N23/N$4)) | ... Q29: =IF(Q$4="","",ABS(Q23/Q$4))
B30: =B24 -> Selling Expenses | C30: =AVERAGE(G30:J30) -> 0.18612222 | G30: =IF(G$4="","",ABS(G24/G$4)) -> 0.19582247 | H30: =IF(H$4="","",ABS(H24/H$4)) -> 0.19348287 | I30: =IF(I$4="","",ABS(I24/I$4)) -> 0.18387127 | J30: =IF(J$4="","",ABS(J24/J$4)) -> 0.17131227 | K30: =IF(K$4="","",ABS(K24/K$4)) | L30: =IF(L$4="","",ABS(L24/L$4)) | M30: =IF(M$4="","",ABS(M24/M$4)) | N30: =IF(N$4="","",ABS(N24/N$4)) | ... Q30: =IF(Q$4="","",ABS(Q24/Q$4))
B31: =B25 -> R&D | C31: 0 | G31: =IF(G$4="","",ABS(G25/G$4)) -> 0 | H31: =IF(H$4="","",ABS(H25/H$4)) -> 0 | I31: =IF(I$4="","",ABS(I25/I$4)) -> 0 | J31: =IF(J$4="","",ABS(J25/J$4)) -> 0 | K31: =IF(K$4="","",ABS(K25/K$4)) | L31: =IF(L$4="","",ABS(L25/L$4)) | M31: =IF(M$4="","",ABS(M25/M$4)) | N31: =IF(N$4="","",ABS(N25/N$4)) | ... Q31: =IF(Q$4="","",ABS(Q25/Q$4))
B32: Variable Costs | C32: =ABS(C26/$C$4) -> 0.80431732 | G32: =IF(G$4="","",ABS(G26/G$4)) -> 0.79767746 | H32: =IF(H$4="","",ABS(H26/H$4)) -> 0.8081212 | I32: =IF(I$4="","",ABS(I26/I$4)) -> 0.80740862 | J32: =IF(J$4="","",ABS(J26/J$4)) -> 0.80406197 | K32: =IF(K$4="","",ABS(K26/K$4)) | L32: =IF(L$4="","",ABS(L26/L$4)) | M32: =IF(M$4="","",ABS(M26/M$4)) | N32: =IF(N$4="","",ABS(N26/N$4)) | ... Q32: =IF(Q$4="","",ABS(Q26/Q$4))
B34: Fixed Costs
B35: G&A and other Opex | C35: =G35 -> -67979 | G35: =IF(G4="","",Data!C41) -> -67979 | H35: =IF(H4="","",Data!D41) -> -59319 | I35: =IF(I4="","",Data!E41) -> -51409 | J35: =IF(J4="","",Data!F41) -> -49234 | K35: =IF(K4="","",Data!G41) | L35: =IF(L4="","",Data!H41) | M35: =IF(M4="","",Data!I41) | N35: =IF(N4="","",Data!J41) | ... Q35: =IF(Q4="","",Data!M41)
B37: Fixed Costs % of Sales
B38: G&A and other Opex | C38: =ABS(C35/$C$4) -> 0.065316754 | G38: =IF(G$4="","",ABS(G35/G$4)) -> 0.065316754 | H38: =IF(H$4="","",ABS(H35/H$4)) -> 0.058771892 | I38: =IF(I$4="","",ABS(I35/I$4)) -> 0.054850367 | J38: =IF(J$4="","",ABS(J35/J$4)) -> 0.058041303 | K38: =IF(K$4="","",ABS(K35/K$4)) | L38: =IF(L$4="","",ABS(L35/L$4)) | M38: =IF(M$4="","",ABS(M35/M$4)) | N38: =IF(N$4="","",ABS(N35/N$4)) | ... Q38: =IF(Q$4="","",ABS(Q35/Q$4))
B40: Tax % of Pre-tax Profit
B41: Income Tax Rate | C41: 0.25 | E41: Use the marginal tax rate | G41: =IF(G$4="","",-G12/SUM(G8+G9,G10)) -> 0.25205746 | H41: =IF(H$4="","",-H12/SUM(H8+H9,H10)) -> 0.2631284 | I41: =IF(I$4="","",-I12/SUM(I8+I9,I10)) -> 0.26060409 | J41: =IF(J$4="","",-J12/SUM(J8+J9,J10)) -> 0.27214762 | K41: =IF(K$4="","",-K12/SUM(K8+K9,K10)) | L41: =IF(L$4="","",-L12/SUM(L8+L9,L10)) | M41: =IF(M$4="","",-M12/SUM(M8+M9,M10)) | N41: =IF(N$4="","",-N12/SUM(N8+N9,N10)) | ... Q41: =IF(Q$4="","",-Q12/SUM(Q8+Q9,Q10))
B43: Non-operating Income | E43: Notes
B44: Interest
B45: Interest Expense | C45: =-BS!G31*Normalized_FCF!C52 -> -5515.92 | G45: =Data!C51 -> -3273 | H45: =Data!D51 -> -3730 | I45: =Data!E51 -> -2330 | J45: =Data!F51 -> -2679 | K45: =Data!G51 | L45: =Data!H51 | M45: =Data!I51 | N45: =Data!J51 | ... Q45: =Data!M51
B46: Operating Interest Income | C46: =BS!D75*C51 -> 507.62527 | G46: =IFERROR(IF(G$4="","",($C$46/$C$47)*G47),0) -> 7736.447 | H46: =IFERROR(IF(H$4="","",($C$46/$C$47)*H47),0) -> 7107.2407 | I46: =IFERROR(IF(I$4="","",($C$46/$C$47)*I47),0) -> 5289.5708 | J46: =IFERROR(IF(J$4="","",($C$46/$C$47)*J47),0) -> 5625.8649 | K46: =IFERROR(IF(K$4="","",($C$46/$C$47)*K47),0) | L46: =IFERROR(IF(L$4="","",($C$46/$C$47)*L47),0) | M46: =IFERROR(IF(M$4="","",($C$46/$C$47)*M47),0) | N46: =IFERROR(IF(N$4="","",($C$46/$C$47)*N47),0) | ... Q46: =IFERROR(IF(Q$4="","",($C$46/$C$47)*Q47),0)
...

Sheet DCF
B2: No-Growth DCF Valuation
B3: No-Growth DCF | C3: =scaling_factor -> 1000000 | E3: FV adjustments | H3: Normalized Values
B4: Normalized FCFE | C4: =Normalized_FCF!C19 -> 103790.21 | D4: =Reporting_currency -> CNY | E4: Interest-bearing Debt | F4: =-BS!G31 -> -91932 | G4: =Reporting_currency -> CNY | H4: Revenues | I4: =Normalized_FCF!C4 -> 1040759
B5: /Equity Cost of Capital | C5: =Equity_Cost -> 0.0725 | E5: Non-operating Cash | F5: =BS!D66 -> 166973.79 | G5: =Reporting_currency -> CNY | H5: Fixed Costs | I5: =Normalized_FCF!C7 -> -67979
B6: Stable Income Value | C6: =(C4*(1+Terminal_Growth))/(Equity_Cost-Terminal_Growth) -> 2016495.5 | D6: =Reporting_currency -> CNY | E6: Other Non-op. Assets | F6: =BS!H42 -> 262533.6 | G6: =Reporting_currency -> CNY | H6: Other Income, includes | I6: =I7+I8 -> 2965.9053
B7: + FV adjustments | C7: =F7 -> 337575.39 | E7: FV adjustments | F7: =SUM(F4:F6) -> 337575.39 | G7: =Reporting_currency -> CNY | H7: Non-op EBIT | I7: =Normalized_FCF!C9 -> 7974.2
B8: Equity Value | C8: =C6+C7 -> 2354070.9 | D8: =Reporting_currency -> CNY | E8: FV adj. per share | F8: =FV_adjustments*scaling_factor/Common_Shares*Exchange_Rate -> 17.699324 | G8: =Market_currency -> HKD | H8: =Normalized_FCF!B10 -> Net Interest Income | I8: =Normalized_FCF!C10 -> -5008.2947
B9: ="*"&Thesis!E15 -> *CNY/HKD | C9: =Exchange_Rate -> 1.1348425 | D9: =Thesis!E15 -> CNY/HKD | H9: =Normalized_FCF!B79 -> NCI’s Share of Profits | I9: =Normalized_FCF!C79 -> 0.00018626408
B10: Value | C10: =C8*Exchange_Rate -> 2671499.7 | D10: =Market_currency -> HKD | H10: Tax rate | I10: =Normalized_FCF!C41 -> 0.25
B11: Value per share | C11: =(C10*scaling_factor)/Common_Shares -> 123.42565 | D11: =Market_currency -> HKD
B13: Growth DCF Valuation
B14: Stage | C14: I | E14: Stage | F14: =IF(ROUND(F17,4)=ROUND(C17,4),"I","II") -> I | H14: Terminal Stage
B15: High g Period (HGP) | C15: =Scenarios!C45 -> 30 | E15: =IF(F14="II","Change year","Terminal Year") -> Terminal Year | F15: =IF(F14="II",_xlfn.CEILING.MATH(C15/2),C15+1) -> 31 | H15: Terminal g Rate: | I15: =Terminal_Growth -> 0.02
B16: High g Rate (HGR) | C16: =Scenarios!C46 -> 0.022781556 | E16: High Growth Rate_II | F16: =Scenarios!C41 -> 0.022781556
B17: Pre-tax Profit Margin | C17: =Normalized_FCF!C77 -> 0.13321568 | E17: Pre-tax Profit Margin_II | F17: =Scenarios!C40 -> 0.13321568 | H17: Output
B18: D&A - maint. Capx | C18: =Normalized_FCF!C81-Normalized_FCF!C82 -> 0 | E18: D&A - maint. Capx | F18: =IF(F14="II",C18/2,C18) -> 0 | H18: Value Per Share | I18: =(L52+FV_adjustments)*Exchange_Rate/Common_Shares*scaling_factor -> 121.12604 | J18: =Market_currency -> HKD
A20: Stage | B20: Year | C20: Revenues | D20: Growth Rates | E20: Pre-tax Profit Margin | F20: Pre-tax Profit | G20: =B18 -> D&A - maint. Capx | H20: FCFE and TV | I20: FCFE g | J20: FCFE Margin | K20: Disc. Factor | L20: PV of FCFE/TV
A21: =IF($C$15<B21,"",IF(B21>=$F$15,"II","I")) -> I | B21: 1 | C21: =I4*(1+D21) -> 1064469.1 | D21: =IF(A21="",0,IF(A21="I",$C$16,$F$16)) -> 0.022781556 | E21: =$C$17 -> 0.13321568 | F21: =C21*E21 -> 141803.98 | G21: =IF(A21="",0%,IF(A21="I",$C$18,$F$18)) -> 0 | H21: =(F21*(1-$I$10)+C21*(G21-$I$9)) -> 106154.71 | I21: =H21/C4-1 -> 0.022781556 | J21: =H21/C21 -> 0.099725498 | K21: =IF($C$15<B21,0,1/(1+Equity_Cost)^B21) -> 0.93240093 | L21: =H21*K21 -> 98978.753
A22: =IF($C$15<B22,"",IF(B22>=$F$15,"II","I")) -> I | B22: 2 | C22: =IF(A22="",0,C21*(1+D22)) -> 1088719.4 | D22: =IF(A22="",0,IF(A22="I",$C$16,$F$16)) -> 0.022781556 | E22: =IF($C$15<B22,0,IF(B22>=$F$15,$F$17,$C$17)) -> 0.13321568 | F22: =IF(A22="", 0,C22*E22) -> 145034.49 | G22: =IF(A22="",0%,IF(A22="I",$C$18,$F$18)) -> 0 | H22: =IF(A22="", 0,F22*(1-$I$10)+C22*(G22-$I$9)) -> 108573.08 | I22: =IF(A22="", 0,H22/H21-1) -> 0.022781556 | J22: =IF(A22="", 0,H22/C22) -> 0.099725498 | K22: =IF($C$15<B22,0,1/(1+Equity_Cost)^B22) -> 0.8693715 | L22: =H22*K22 -> 94390.343
A23: =IF($C$15<B23,"",IF(B23>=$F$15,"II","I")) -> I | B23: 3 | C23: =IF(A23="",0,C22*(1+D23)) -> 1113522.1 | D23: =IF(A23="",0,IF(A23="I",$C$16,$F$16)) -> 0.022781556 | E23: =IF($C$15<B23,0,IF(B23>=$F$15,$F$17,$C$17)) -> 0.13321568 | F23: =IF(A23="", 0,C23*E23) -> 148338.61 | G23: =IF(A23="",0%,IF(A23="I",$C$18,$F$18)) -> 0 | H23: =IF(A23="", 0,F23*(1-$I$10)+C23*(G23-$I$9)) -> 111046.55 | I23: =IF(A23="", 0,H23/H22-1) -> 0.022781556 | J23: =IF(A23="", 0,H23/C23) -> 0.099725498 | K23: =IF($C$15<B23,0,1/(1+Equity_Cost)^B23) -> 0.8106028 | L23: =H23*K23 -> 90014.64
A24: =IF($C$15<B24,"",IF(B24>=$F$15,"II","I")) -> I | B24: 4 | C24: =IF(A24="",0,C23*(1+D24)) -> 1138889.9 | D24: =IF(A24="",0,IF(A24="I",$C$16,$F$16)) -> 0.022781556 | E24: =IF($C$15<B24,0,IF(B24>=$F$15,$F$17,$C$17)) -> 0.13321568 | F24: =IF(A24="", 0,C24*E24) -> 151717.99 | G24: =IF(A24="",0%,IF(A24="I",$C$18,$F$18)) -> 0 | H24: =IF(A24="", 0,F24*(1-$I$10)+C24*(G24-$I$9)) -> 113576.36 | I24: =IF(A24="", 0,H24/H23-1) -> 0.022781556 | J24: =IF(A24="", 0,H24/C24) -> 0.099725498 | K24: =IF($C$15<B24,0,1/(1+Equity_Cost)^B24) -> 0.7558068 | L24: =H24*K24 -> 85841.784
A25: =IF($C$15<B25,"",IF(B25>=$F$15,"II","I")) -> I | B25: 5 | C25: =IF(A25="",0,C24*(1+D25)) -> 1164835.5 | D25: =IF(A25="",0,IF(A25="I",$C$16,$F$16)) -> 0.022781556 | E25: =IF($C$15<B25,0,IF(B25>=$F$15,$F$17,$C$17)) -> 0.13321568 | F25: =IF(A25="", 0,C25*E25) -> 155174.36 | G25: =IF(A25="",0%,IF(A25="I",$C$18,$F$18)) -> 0 | H25: =IF(A25="", 0,F25*(1-$I$10)+C25*(G25-$I$9)) -> 116163.8 | I25: =IF(A25="", 0,H25/H24-1) -> 0.022781556 | J25: =IF(A25="", 0,H25/C25) -> 0.099725498 | K25: =IF($C$15<B25,0,1/(1+Equity_Cost)^B25) -> 0.70471497 | L25: =H25*K25 -> 81862.372
A26: =IF($C$15<B26,"",IF(B26>=$F$15,"II","I")) -> I | B26: 6 | C26: =IF(A26="",0,C25*(1+D26)) -> 1191372.3 | D26: =IF(A26="",0,IF(A26="I",$C$16,$F$16)) -> 0.022781556 | E26: =IF($C$15<B26,0,IF(B26>=$F$15,$F$17,$C$17)) -> 0.13321568 | F26: =IF(A26="", 0,C26*E26) -> 158709.48 | G26: =IF(A26="",0%,IF(A26="I",$C$18,$F$18)) -> 0 | H26: =IF(A26="", 0,F26*(1-$I$10)+C26*(G26-$I$9)) -> 118810.2 | I26: =IF(A26="", 0,H26/H25-1) -> 0.022781556 | J26: =IF(A26="", 0,H26/C26) -> 0.099725498 | K26: =IF($C$15<B26,0,1/(1+Equity_Cost)^B26) -> 0.65707689 | L26: =H26*K26 -> 78067.435
A27: =IF($C$15<B27,"",IF(B27>=$F$15,"II","I")) -> I | B27: 7 | C27: =IF(A27="",0,C26*(1+D27)) -> 1218513.6 | D27: =IF(A27="",0,IF(A27="I",$C$16,$F$16)) -> 0.022781556 | E27: =IF($C$15<B27,0,IF(B27>=$F$15,$F$17,$C$17)) -> 0.13321568 | F27: =IF(A27="", 0,C27*E27) -> 162325.12 | G27: =IF(A27="",0%,IF(A27="I",$C$18,$F$18)) -> 0 | H27: =IF(A27="", 0,F27*(1-$I$10)+C27*(G27-$I$9)) -> 121516.88 | I27: =IF(A27="", 0,H27/H26-1) -> 0.022781556 | J27: =IF(A27="", 0,H27/C27) -> 0.099725498 | K27: =IF($C$15<B27,0,1/(1+Equity_Cost)^B27) -> 0.61265911 | L27: =H27*K27 -> 74448.422
A28: =IF($C$15<B28,"",IF(B28>=$F$15,"II","I")) -> I | B28: 8 | C28: =IF(A28="",0,C27*(1+D28)) -> 1246273.3 | D28: =IF(A28="",0,IF(A28="I",$C$16,$F$16)) -> 0.022781556 | E28: =IF($C$15<B28,0,IF(B28>=$F$15,$F$17,$C$17)) -> 0.13321568 | F28: =IF(A28="", 0,C28*E28) -> 166023.14 | G28: =IF(A28="",0%,IF(A28="I",$C$18,$F$18)) -> 0 | H28: =IF(A28="", 0,F28*(1-$I$10)+C28*(G28-$I$9)) -> 124285.22 | I28: =IF(A28="", 0,H28/H27-1) -> 0.022781556 | J28: =IF(A28="", 0,H28/C28) -> 0.099725498 | K28: =IF($C$15<B28,0,1/(1+Equity_Cost)^B28) -> 0.57124392 | L28: =H28*K28 -> 70997.178
A29: =IF($C$15<B29,"",IF(B29>=$F$15,"II","I")) -> I | B29: 9 | C29: =IF(A29="",0,C28*(1+D29)) -> 1274665.3 | D29: =IF(A29="",0,IF(A29="I",$C$16,$F$16)) -> 0.022781556 | E29: =IF($C$15<B29,0,IF(B29>=$F$15,$F$17,$C$17)) -> 0.13321568 | F29: =IF(A29="", 0,C29*E29) -> 169805.41 | G29: =IF(A29="",0%,IF(A29="I",$C$18,$F$18)) -> 0 | H29: =IF(A29="", 0,F29*(1-$I$10)+C29*(G29-$I$9)) -> 127116.63 | I29: =IF(A29="", 0,H29/H28-1) -> 0.022781556 | J29: =IF(A29="", 0,H29/C29) -> 0.099725498 | K29: =IF($C$15<B29,0,1/(1+Equity_Cost)^B29) -> 0.53262837 | L29: =H29*K29 -> 67705.924
A30: =IF($C$15<B30,"",IF(B30>=$F$15,"II","I")) -> I | B30: 10 | C30: =IF(A30="",0,C29*(1+D30)) -> 1303704.2 | D30: =IF(A30="",0,IF(A30="I",$C$16,$F$16)) -> 0.022781556 | E30: =IF($C$15<B30,0,IF(B30>=$F$15,$F$17,$C$17)) -> 0.13321568 | F30: =IF(A30="", 0,C30*E30) -> 173673.84 | G30: =IF(A30="",0%,IF(A30="I",$C$18,$F$18)) -> 0 | H30: =IF(A30="", 0,F30*(1-$I$10)+C30*(G30-$I$9)) -> 130012.55 | I30: =IF(A30="", 0,H30/H29-1) -> 0.022781556 | J30: =IF(A30="", 0,H30/C30) -> 0.099725498 | K30: =IF($C$15<B30,0,1/(1+Equity_Cost)^B30) -> 0.49662319 | L30: =H30*K30 -> 64567.245
A31: =IF($C$15<B31,"",IF(B31>=$F$15,"II","I")) -> I | B31: 11 | C31: =IF(A31="",0,C30*(1+D31)) -> 1333404.6 | D31: =IF(A31="",0,IF(A31="I",$C$16,$F$16)) -> 0.022781556 | E31: =IF($C$15<B31,0,IF(B31>=$F$15,$F$17,$C$17)) -> 0.13321568 | F31: =IF(A31="", 0,C31*E31) -> 177630.4 | G31: =IF(A31="",0%,IF(A31="I",$C$18,$F$18)) -> 0 | H31: =IF(A31="", 0,F31*(1-$I$10)+C31*(G31-$I$9)) -> 132974.44 | I31: =IF(A31="", 0,H31/H30-1) -> 0.022781556 | J31: =IF(A31="", 0,H31/C31) -> 0.099725498 | K31: =IF($C$15<B31,0,1/(1+Equity_Cost)^B31) -> 0.46305192 | L31: =H31*K31 -> 61574.068
A32: =IF($C$15<B32,"",IF(B32>=$F$15,"II","I")) -> I | B32: 12 | C32: =IF(A32="",0,C31*(1+D32)) -> 1363781.6 | D32: =IF(A32="",0,IF(A32="I",$C$16,$F$16)) -> 0.022781556 | E32: =IF($C$15<B32,0,IF(B32>=$F$15,$F$17,$C$17)) -> 0.13321568 | F32: =IF(A32="", 0,C32*E32) -> 181677.1 | G32: =IF(A32="",0%,IF(A32="I",$C$18,$F$18)) -> 0 | H32: =IF(A32="", 0,F32*(1-$I$10)+C32*(G32-$I$9)) -> 136003.8 | I32: =IF(A32="", 0,H32/H31-1) -> 0.022781556 | J32: =IF(A32="", 0,H32/C32) -> 0.099725498 | K32: =IF($C$15<B32,0,1/(1+Equity_Cost)^B32) -> 0.43175004 | L32: =H32*K32 -> 58719.647
A33: =IF($C$15<B33,"",IF(B33>=$F$15,"II","I")) -> I | B33: 13 | C33: =IF(A33="",0,C32*(1+D33)) -> 1394850.7 | D33: =IF(A33="",0,IF(A33="I",$C$16,$F$16)) -> 0.022781556 | E33: =IF($C$15<B33,0,IF(B33>=$F$15,$F$17,$C$17)) -> 0.13321568 | F33: =IF(A33="", 0,C33*E33) -> 185815.99 | G33: =IF(A33="",0%,IF(A33="I",$C$18,$F$18)) -> 0 | H33: =IF(A33="", 0,F33*(1-$I$10)+C33*(G33-$I$9)) -> 139102.18 | I33: =IF(A33="", 0,H33/H32-1) -> 0.022781556 | J33: =IF(A33="", 0,H33/C33) -> 0.099725498 | K33: =IF($C$15<B33,0,1/(1+Equity_Cost)^B33) -> 0.40256414 | L33: =H33*K33 -> 55997.549
... A50: =IF($C$15<B50,"",IF(B50>=$F$15,"II","I")) -> I | B50: 30 | C50: =IF(A50="",0,C49*(1+D50)) -> 2045675.8 | D50: =IF(A50="",0,IF(A50="I",$C$16,$F$16)) -> 0.022781556 | E50: =IF($C$15<B50,0,IF(B50>=$F$15,$F$17,$C$17)) -> 0.13321568 | F50: =IF(A50="", 0,C50*E50) -> 272516.1 | G50: =IF(A50="",0%,IF(A50="I",$C$18,$F$18)) -> 0 | H50: =IF(A50="", 0,F50*(1-$I$10)+C50*(G50-$I$9)) -> 204006.04 | I50: =IF(A50="", 0,H50/H49-1) -> 0.022781556 | J50: =IF(A50="", 0,H50/C50) -> 0.099725498 | K50: =IF($C$15<B50,0,1/(1+Equity_Cost)^B50) -> 0.12248446 | L50: =H50*K50 -> 24987.569
A51: T | B51: =C15+1 -> 31 | C51: =VLOOKUP(C15,B21:C50,2,FALSE)*(1+Terminal_Growth) -> 2086589.3 | D51: =Terminal_Growth -> 0.02 | E51: =F17 -> 0.13321568 | F51: =C51*E51 -> 277966.42 | G51: =F18 -> 0 | H51: =(F51*(1-$I$10)+C51*(G51-$I$9))/Equity_Cost -> 2870153.9 | I51: =(F51*(1-$I$10)+C51*(G51-$I$9))/VLOOKUP(C15,B21:H50,COLUMN(H20)-1,FALSE)-1 -> 0.02 | K51: =1/(1+Equity_Cost)^C15 -> 0.12248446 | L51: =H51*K51 -> 351549.24
J52: PV of total FCFE = | L52: =SUM(L21:L51) -> 1972635.5
B54: Sensitivity Analysis (Enterprise Value)
A55: =L52 -> 1972635.5 | B55: =C94 -> 0 | C55: =C93 -> 0.01 | D55: =C92 -> 0.02 | E55: =C91 -> 0.03 | F55: =C90 -> 0.04
A56: 1 | B56: 1458285.4 | C56: 1472868.3 | D56: 1487451.1 | E56: 1502034 | F56: 1516616.8
A57: 2 | B57: 1456480.8 | C57: 1484778.6 | D57: 1513348.4 | E57: 1542190.1 | F57: 1571303.8
A58: 3 | B58: 1454798.1 | C58: 1495994.9 | D58: 1537978 | E58: 1580755 | F58: 1624333.6
A59: 4 | B59: 1453229.2 | C59: 1506557.5 | D59: 1561401.9 | E59: 1617791.7 | F59: 1675756.4
A60: 5 | B60: 1451766.3 | C60: 1516504.6 | D60: 1583679.2 | E60: 1653360.7 | F60: 1725620.9
...

Sheet Scenarios
B2: Current Situation
B3: Selection | D3: Prompt for fundamental Analysis
B4: Past Years Selected | C4: 2 | D4: ="DCF Model Inputs for " & Thesis!C5 & " – " & Thesis!C4 & ": Please develop Base, Pessimistic, and Optimistic scenarios under the following unified framework. " & "Assume a consistent high-growth period across all cases, with each scenario using a single FCFE CAGR during this phase. " & "Apply a two-stage model only if there is a material shift in FCFE margin or growth, and ensure this structure is used consistently across scenarios. " & "Margins should remain constant within each stage and be identical across all scenarios; any variation in outlook should be reflected through adjustments to the growth rate, not the margin. " & "Terminal growth is fixed at 0%, so modify the high-growth duration or rate accordingly to reflect long-term expectations. " & "Specify the FCFE margin (stage-specific if applicable) for all scenarios. " & "For each scenario, specify the FCFE CAGR during the high-growth period. Accompany each with a concise business narrative and respective probability explaining the key drivers behind the scenario." -> DCF Model Inputs for 0941.HK – 中国移动: Please develop Base, Pessimistic, and Optimistic scenarios under the following unified framework. Assume a consistent high-growth period across all cases, with each scenario using a single FCFE CAGR during this phase. Apply a two-stage model only if there is a material shift in FCFE margin or growth, and ensure this structure is used consistently across scenarios. Margins should remain constant within each stage and be identical across all scenarios; any variation in outlook should be reflected through adjustments to the growth rate, not the margin. Terminal growth is fixed at 0%, so modify the high-growth duration or rate accordingly to reflect long-term expectations. Specify the FCFE margin (stage-specific if applicable) for all scenarios. For each scenario, specify the FCFE CAGR during the high-growth period. Accompany each with a concise business narrative and respective probability explaining the key drivers behind the scenario.
B6: Latest | C6: =DCF!C3&" "&Reporting_currency -> 1000000 CNY
B7: EBIT | C7: =Normalized_FCF!G8 -> 142590
B8: FCFE | C8: =Normalized_FCF!G19 -> 118134.45
B9: Normalized | C9: =Normalized_FCF!C19 -> 103790.21
B11: YoY CAGR
B12: Sales | C12: =(Normalized_FCF!G4/OFFSET(Normalized_FCF!G4, 0, $C$4))^(1/$C$4) - 1 -> 0.053768659
B13: Operating EBIT | C13: =(Normalized_FCF!G8/OFFSET(Normalized_FCF!G8, 0, $C$4))^(1/$C$4) - 1 -> 0.050952519
B14: FCFE | C14: =(Normalized_FCF!G19/OFFSET(Normalized_FCF!G19, 0, $C$4))^(1/$C$4) - 1 -> 0.057526862
B16: Scenarios Analysis
B17: Assumption | E17: Note on Manual Adjustments
B18: High Growth Period (HGP) | C18: 30 | E18: accepts 5-10, 15, 20, 25, or 30
B20: General Scenarios
B21: Scenarios | C21: HGR | D21: HGP | E21: ="Value per share ("&Market_currency&")" -> Value per share (HKD) | F21: Probabilities | G21: Adj. Probabilities
B22: Optimistic | C22: 0.03 | D22: =C18 -> 30 | E22: =DCF!E91 -> 133.1352 | F22: =1-F23-F24 -> 0.2 | G22: =F22*(1-F$29-F$30) -> 0.16
B23: Base | C23: 0.02 | D23: =C18 -> 30 | E23: =DCF!E92 -> 116.9548 | F23: 0.55 | G23: =F23*(1-F$29-F$30) -> 0.44
B24: Pessimistic | C24: 0.01 | D24: =C18 -> 30 | E24: =DCF!E93 -> 103.76019 | F24: 0.25 | G24: =F24*(1-F$29-F$30) -> 0.2
B25: Under General Scenario | C25: =E23*F23+E24*F24+E22*F22 -> 116.89223 | D25: =Market_currency -> HKD
B27: Extreme Scenarios
B28: Scenarios | C28: HGR | D28: HGP | E28: ="Value per share ("&Market_currency&")" -> Value per share (HKD) | F28: Probabilities | G28: Adj. Probabilities
B29: Snowball Scenario | C29: 0.04 | D29: =C18 -> 30 | E29: =DCF!E90 -> 153.07279 | F29: 0.15 | G29: =F29 -> 0.15
B30: Devil's advocate | C30: 0 | D30: =C18 -> 30 | E30: =DCF!E94 -> 92.942455 | F30: 0.05 | G30: =F30 -> 0.05
B32: Conclusion
B33: Annual Dividend per share | C33: =Normalized_FCF!C88*(1-dividend_tax_rate) -> 4.581 | D33: =Market_currency -> HKD | E33: With a holding period of | F33: =Holding_Period -> 3
B34: Market Price | C34: =Market_Price -> 79.95 | D34: =Market_currency -> HKD | E34: Implied Annual Return | F34: =RATE(Holding_Period,$C$33,-C34,$C$36) -> 0.19891674
B35: No-g Model Value per share | C35: =DCF!C11 -> 123.42565 | D35: =Market_currency -> HKD | E35: Implied Annual Return | F35: =RATE(Holding_Period,$C$33,-C35,$C$36) -> 0.031083005
B36: g Model Value per share | C36: =E22*G22+E23*G23+E24*G24+E30*G30+E29*G29 -> 121.12182 | D36: =Market_currency -> HKD | E36: is assumed to be the | F36: Expected Value
B38: Stage II Normalized Values
B39: =IF(DCF!F14="II","2","1")&"-stage DCF" -> 1-stage DCF | E39: Note on Manual Adjustments
B40: Pre-tax Profit Margin_II | C40: =Normalized_FCF!E116 -> 0.13321568 | E40: Try obtain this number by reverse engineering.
B41: High Growth Rate_II | C41: =DCF!C16 -> 0.022781556
B43: Growth Classification
B44: Equity Value Driving Factors | E44: Note on Manual Adjustments
B45: High Growth Period (HGP) | C45: =C18 -> 30 | E45: Use general Scenarios' HGP assumption
B46: High Growth Rate (HGR) | C46: 0.022781556 | E46: Use Excel Goal Seek to find the HGR
B47: Equity Value per share | C47: =DCF!I18 -> 121.12604 | D47: =Market_currency -> HKD | E47: Set to Expected Equity Value
B49: Type of Company | C49: =IF(Scenarios!C50="Y",Scenarios!B50,"")&IF(Scenarios!C51="Y",Scenarios!B51,"")&IF(Scenarios!C52="Y",Scenarios!B52,"")&" "&IF(Scenarios!C53="Y",Scenarios!B53,"") -> Negative Growth | E49: Note on the logic
B50: Negative Growth | C50: =IF(C36<C35,"Y","N") -> Y
...

Sheet 投资主题
A2: 执行摘要
E3: 更新日期: | F3: =Thesis!F3 -> 46038
B4: 公司： | C4: =Thesis!C4 -> 中国移动 | E4: 组合: | F4: =Thesis!F4 -> INT
B5: 股票代码： | C5: =Thesis!C5 -> 0941.HK | E5: 精选: | F5: =Thesis!F5 -> Y
B6: 对比板块: | C6: =Thesis!C6 -> TMT_01
B7: 市价货币： | C7: =Market_currency -> HKD
B8: 市场价格： | C8: =Market_Price -> 79.95
B9: 股份数量： | C9: =Common_Shares -> 21644606612
B10: 市值： | C10: =投资主题!C8*Common_Shares/1000000 -> 1730486.3 | D10: 隐含年回报率: | E10: =Scenarios!F34 -> 0.19891674
B12: 指导说明：该模型使用结构化的投资流程来评估公司，确定其内在价值和目标价格。它关注可持续的自由现金流（FCF）能力，调整财务结构，纳入增长情景，并根据得出的内在价值计算预期回报。
B14: 估值概述
B15: 商业模式风险溢价: | C15: =Thesis!C15 -> N | D15: 外汇符号： | E15: =IF(E17=C7,C7,E17&"/"&C7) -> CNY/HKD
B16: 管理风险溢价: | C16: =Thesis!C16 -> N | D16: 汇率： | E16: =Exchange_Rate -> 1.1348425
B17: 永续增长率 (g) = | C17: =Terminal_Growth -> 0.02 | D17: 报告货币: | E17: =Reporting_currency -> CNY
B18: ="预期股权价值 ("&C7&") :" -> 预期股权价值 (HKD) : | C18: =C125 -> 121.12182 | D18: 报告间隔： | E18: =Thesis!E18 -> 6
B19: 增长分类: | C19: =IF(Scenarios!C50="Y",Scenarios!B50,"")&IF(Scenarios!C51="Y",Scenarios!B51,"")&IF(Scenarios!C52="Y",Scenarios!B52,"")&" "&IF(Scenarios!C53="Y",Scenarios!B53,"") -> Negative Growth | D19: 下次更新日期： | E19: =EOMONTH(EDATE(BS!C1,E18+2),0) -> 46081
B21: 投资决策 | C21: =C138&" ("&Market_currency&")" -> (HKD) | D21: 持有期 | E21: =Holding_Period -> 3
B22: 目标价格 | C22: =E140 -> 64.199058 | D22: @目标回报率 | E22: =Thesis!E22 -> 0.29465259
B23: 入场价格 | C23: =E141 -> 79.600506 | D23: @入场收益率 | E23: =Thesis!E23 -> 0.20075184
B24: 退出价格 | C24: =E144 -> 97.867461 | D24: @基准收益率 | E24: =Thesis!E24 -> 0.1174
B25: 卖出价格 | C25: =E145 -> 110.14898 | D25: @基础Equity Cost | E25: =Thesis!E25 -> 0.0725
A27: 步骤1：确定公司可持续盈利能力（计算标准化FCFE）
B29: 目标：量化业务持续生成的潜在自由现金流（FCFE），去除临时波动或会计选择的影响。
B30: FCFE = (Normalized Operating EBIT + Depreciation & Amortization – Capital Expenditures) + Stable Non-Operating EBIT + Net Interest Income – Taxes – NCI’s Share of Profits – Working Capital Investment
B32: 关键组成部分 | C32: =scaling_factor -> 1000000
B33: • Normalized Operating EBIT：核心业务运营的税前息前利润，调整以剔除一次性或非经常性项目，形成可持续盈利基础。
B34: Normalized Operating EBIT = | C34: =Normalized_FCF!C8 -> 135679.52 | D34: =Reporting_currency -> CNY
B36: • Depreciation & Amortization (D&A): 非现金费用，加入以反映运营产生的现金。 • Capital Expenditures (Capex): 维持或扩展运营资产所需的现金流出。
B37: D&A = | C37: =Normalized_FCF!C15 -> 191101 | D37: =Reporting_currency -> CNY
B38: Capex = | C38: =Normalized_FCF!C16 -> -191101 | D38: =Reporting_currency -> CNY
B40: • Stable Non-Operating EBIT: 来自非核心资产的持续收益，如固定收益投资、支付股息的股票或租赁物业。
B41: Stable Non-Operating EBIT = | C41: =Normalized_FCF!C9 -> 7974.2 | D41: =Reporting_currency -> CNY
B43: • Net Interest Income: 利息收入减去利息支出
B44: Operating Interest Income = | C44: =Normalized_FCF!C46 -> 507.62527 | D44: =Reporting_currency -> CNY
B45: Interest Expense = | C45: =Normalized_FCF!C45 -> -5515.92 | D45: =Reporting_currency -> CNY
B46: Net Interest Income = | C46: =Normalized_FCF!C10 -> -5008.2947 | D46: =Reporting_currency -> CNY
B48: • NCI’s Share of Profits: NCI代表子公司中母公司未拥有的股权部分。
B49: Est. NCI’s Share of Profits = | C49: =Normalized_FCF!C13 -> -193.85602 | D49: =Reporting_currency -> CNY
B51: • Taxes: Tax = (Normalized Operating EBIT + Stable Non-Operating EBIT + Interest Income – Interest Expense) × Tax Rate
B52: Taxes = | C52: =Normalized_FCF!C12 -> -34661.355 | D52: =Reporting_currency -> CNY
...
