Workbook
Name Common_Shares: [1]Thesis!$C$9
Name Common_Shares: Thesis!$C$9
Name dividend_tax_rate: [1]Normalized_FCF!$C$91
Name dividend_tax_rate: Normalized_FCF!$C$91
Name Equity_Cost: [1]Thesis!$C$101
Name Equity_Cost: Thesis!$C$101
Name Exchange_Rate: [1]Thesis!$E$16
Name Exchange_Rate: Thesis!$E$16
Name FV_adjustments: [1]DCF!$F$7
Name FV_adjustments: DCF!$F$7
Name Holding_Period: [1]Thesis!$E$21
Name Holding_Period: Thesis!$E$21
Name Market_currency: [1]Thesis!$C$7
Name Market_currency: Thesis!$C$7
Name Market_Price: [1]Thesis!$C$8
Name Market_Price: Thesis!$C$8
Name Reporting_currency: [1]Thesis!$E$17
Name Reporting_currency: Thesis!$E$17
Name scaling_factor: [1]Data!$C$3
Name scaling_factor: Data!$C$3
Name Terminal_Growth: [1]Thesis!$C$17
Name Terminal_Growth: Thesis!$C$17

Sheet Thesis
A2: Executive Summary
E3: Last Updated: | F3: 45930
B4: Company: | C4: 福寿园 | E4: Portfolio: | F4: INT
B5: Symbol: | C5: 1448.HK | E5: Selected: | F5: N
B6: Comp_Sector: | C6: CNS_01
B7: Market Currency: | C7: HKD
B8: Market Price: | C8: 2.96
B9: Number of Shares: | C9: 2319863422
B10: Market Capitalization: | C10: =Thesis!C8*Common_Shares/1000000 -> 6866.7957 | D10: Implied Annual Return: | E10: =Scenarios!F34 -> 0.09008407
B12: Guidance Note: This model evaluates the company using a structured investment process to determine its intrinsic value and target prices. It focuses on sustainable FCF capacity, adjusts for financial structure, incorporates growth scenarios, and calculates expected returns based on the derived intrinsic value.
B14: =Scenarios!B39&" Valuation Conclusion" -> 1-stage DCF Valuation Conclusion
B15: Business Model Risk Premium: | C15: N | D15: Forex Symbol: | E15: =IF(E17=C7,C7,E17&"/"&C7) -> CNY/HKD
B16: Management Risk Premium: | C16: N | D16: Exchange Rate: | E16: 1.0934132
B17: Terminal Growth Rate (g) | C17: 0 | D17: Reporting Currency: | E17: CNY
B18: ="Expected Equity Value ("&C7&") :" -> Expected Equity Value (HKD) : | C18: =C125 -> 3.1845771 | D18: Report Interval: | E18: 6
B19: Growth Classification: | C19: =IF(Scenarios!C50="Y",Scenarios!B50,"")&IF(Scenarios!C51="Y",Scenarios!B51,"")&IF(Scenarios!C52="Y",Scenarios!B52,"")&" "&IF(Scenarios!C53="Y",Scenarios!B53,"") -> Low Growth | D19: Update Required After: | E19: =EOMONTH(EDATE(BS!C1,E18+2),0) -> 46081
B21: Price Targets | C21: =C138&" ("&Market_currency&")" -> (HKD) | D21: Holding Period | E21: 2
B22: Target Price | C22: =E140 -> 1.9526459 | D22: @Target return | E22: 0.35
B23: Entry Price | C23: =E141 -> 2.2673774 | D23: @Entry yield | E23: 0.25
B24: Exit Price | C24: =E144 -> 2.8205317 | D24: @Benchmark yield | E24: 0.1174
B25: Sell Price | C25: =E145 -> 3.0554228 | D25: @Base equity cost | E25: 0.0725
A27: Step 1: Establishing the Company’s Sustainable Earning Power (Calculating Normalized FCFE)
B29: Goal: To quantify the underlying FCFE the business consistently generates, stripping away temporary fluctuations or accounting choices.
B30: FCFE = (Normalized Operating EBIT + Depreciation & Amortization – Capital Expenditures) + Stable Non-Operating EBIT + Net Interest Income – Taxes – NCI’s Share of Profits – Working Capital Investment
B32: Key Components | C32: =scaling_factor -> 1000
B33: • Normalized Operating EBIT: Earnings before interest and taxes from core business operations, adjusted to remove one-time or irregular items for a sustainable earnings base.
B34: Normalized Operating EBIT = | C34: =Normalized_FCF!C8 -> 611412.7 | D34: =Reporting_currency -> CNY
B36: • Depreciation & Amortization (D&A): Non-cash expenses added back to reflect cash generated from operations. • Capital Expenditures (Capex): Cash outflows required to maintain or expand operational assets
B37: D&A = | C37: =Normalized_FCF!C15 -> 173179 | D37: =Reporting_currency -> CNY
B38: Capex = | C38: =Normalized_FCF!C16 -> -173179 | D38: =Reporting_currency -> CNY
B40: • Stable Non-Operating EBIT: Consistent earnings from non-core assets, such as fixed-income investments, dividend-paying stocks, or rental properties.
B41: Stable Non-Operating EBIT = | C41: =Normalized_FCF!C9 -> -2798 | D41: =Reporting_currency -> CNY
B43: • Net Interest Income: Interest income minus interest expense
B44: Operating Interest Income = | C44: =Normalized_FCF!C46 -> 3636.4451 | D44: =Reporting_currency -> CNY
B45: Interest Expense = | C45: =Normalized_FCF!C45 -> -8088.24 | D45: =Reporting_currency -> CNY
B46: Net Interest Income = | C46: =Normalized_FCF!C10 -> -4451.7949 | D46: =Reporting_currency -> CNY
B48: • NCI’s Share of Profits: NCI represents the portion of a subsidiary’s equity not owned by the parent company.
B49: Est. NCI’s Share of Profits = | C49: =Normalized_FCF!C13 -> -106049.45 | D49: =Reporting_currency -> CNY
B51: • Taxes: Tax = (Normalized Operating EBIT + Stable Non-Operating EBIT + Interest Income – Interest Expense) × Tax Rate
B52: Taxes = | C52: =Normalized_FCF!C12 -> -151040.73 | D52: =Reporting_currency -> CNY
...

Sheet Data
B1: =Thesis!E17 -> CNY | C1: 45657 | D1: =EOMONTH(EDATE(C1,-12),0) -> 45291 | E1: =EOMONTH(EDATE(D1,-12),0) -> 44926 | F1: =EOMONTH(EDATE(E1,-12),0) -> 44561 | G1: =EOMONTH(EDATE(F1,-12),0) -> 44196 | H1: =EOMONTH(EDATE(G1,-12),0) -> 43830 | I1: =EOMONTH(EDATE(H1,-12),0) -> 43465 | J1: =EOMONTH(EDATE(I1,-12),0) -> 43100 | K1: =EOMONTH(EDATE(J1,-12),0) -> 42735 | ... M1: =EOMONTH(EDATE(L1,-12),0) -> 42004
B2: Data (Dirty)
B3: Income Statement | C3: 1000
B4: Sales | C4: 2077484 | D4: 2628029 | E4: 2171626 | F4: 2325848 | G4: 1892537 | H4: 1850574 | I4: 1651299 | J4: 1477208 | K4: 1267655 | L4: 1107960
B5: COGS | C5: 467126 | D5: 362473 | E5: 479666 | F5: 516304 | G5: 409351 | H5: 387398 | I5: 324344 | J5: 292316 | K5: 265303 | L5: 248161
B6: OPEX | C6: 528317 | D6: 555259 | E6: 506779 | F6: 522738 | G6: 421877 | H6: 454796 | I6: 445068 | J6: 543726 | K6: 496391 | L6: 455577
B7: Incl. Selling Expenses | C7: 41597 | D7: 48899 | E7: 43155 | F7: 53122 | G7: 36072 | H7: 38671 | I7: 43876 | J7: 250830 | K7: 217517 | L7: 205442
B8: R&D
B9: Share of JV or associate Results | C9: -2798 | D9: -18436 | E9: -7407 | F9: -11577 | G9: 4 | H9: -176 | I9: 0 | J9: 398 | K9: 485 | L9: 0
B10: Dividend or Interests from FA
B11: Investment property
B12: Interest Expense | C12: 16422 | D12: 7392 | E12: 5008 | F12: 7246 | G12: 9525 | H12: 11128 | I12: 8293 | J12: 15585 | K12: 8256 | L12: 7799
B13: Interest Income | C13: 21811 | D13: 17341
B14: Income Tax Paid | C14: 313181 | D14: 455638 | E14: 281476 | F14: 289591 | G14: 222784 | H14: 211350 | I14: 159140 | J14: 134611 | K14: 108508 | L14: 94437
B15: Reported Net Income | C15: 497328 | D15: 975916 | E15: 810729 | F15: 889644 | G15: 757305 | H15: 735319 | I15: 615633 | J15: 550173 | K15: 448505 | L15: 365169
B16: Non-controling Interests | C16: 124194 | D16: 184676 | E16: 152133 | F16: 169611 | G16: 137241 | H16: 156740 | I16: 127269 | J16: 132823 | K16: 109531 | L16: 80725
B18: Cash Flow Statement
B19: D&A | C19: 173179 | D19: 166609
B20: CAPX
B21: WCInv
B22: CFO | C22: 708532 | D22: 1102878 | E22: 852933 | F22: 992369 | G22: 822349 | H22: 707084 | I22: 670523 | J22: 648172 | K22: 455423 | L22: 366578
B23: CFI | C23: 130841 | D23: -362126 | E23: 413235 | F23: -648300 | G23: -1109086 | H23: -12368 | I23: -1021467 | J23: 134672 | K23: -340500 | L23: -381434
B24: CFF | C24: -1078214 | D24: -387518 | E24: -399541 | F24: -502485 | G24: -486383 | H24: -181225 | I24: -92397 | J24: -84758 | K24: -152778 | L24: -5140
B25: ="Dividend per share ("&Market_currency&")" -> Dividend per share (HKD) | C25: =0.0638+0.0954 -> 0.1592 | D25: =0.0906+0.0686 -> 0.1592
B27: Balance Sheet | C27: Latest Asset Value
B28: ST AR | C28: =BS!C4 -> 144049 | D28: 139113 | E28: 137875 | F28: 108344 | G28: 63265 | H28: 56480 | I28: 14778 | J28: 6310 | K28: 19038 | L28: 9622
B29: ST Inventory | C29: =BS!C6 -> 558421 | D29: 557991 | E29: 558958 | F29: 544487 | G29: 502263 | H29: 481059 | I29: 448003 | J29: 426381 | K29: 372407 | L29: 339522
B30: Total Liabilities | C30: =BS!C33+BS!C42 -> 2372648 | D30: 2093923 | E30: 1701887 | F30: 1733130 | G30: 1536089 | H30: 1400407 | I30: 1186821 | J30: 1057531 | K30: 907178 | L30: 913796
B31: Total Equity | C31: =BS!G27 -> 4865631 | D31: 6155828 | E31: 6573864 | F31: 6114004 | G31: 5672320 | H31: 5142086 | I31: 4585213 | J31: 4050883 | K31: 3604504 | L31: 3029040 | M31: 2649769
B32: Non-common Interest | C32: =BS!G28 -> 574396 | D32: 594674 | E32: 653809 | F32: 638246 | G32: 628880 | H32: 574205 | I32: 542143 | J32: 538452 | K32: 586341 | L32: 492860 | M32: 413840
B34: IS & CF Statements (Clean)
B35: Income Statement
B36: Sales | C36: =IF(C$4="","",C4) -> 2077484 | D36: =IF(D$4="","",D4) -> 2628029 | E36: =IF(E$4="","",E4) -> 2171626 | F36: =IF(F$4="","",F4) -> 2325848 | G36: =IF(G$4="","",G4) -> 1892537 | H36: =IF(H$4="","",H4) -> 1850574 | I36: =IF(I$4="","",I4) -> 1651299 | J36: =IF(J$4="","",J4) -> 1477208 | ... M36: =IF(M$4="","",M4)
B37: COGS | C37: =IF(C$4="","",-C5) -> -467126 | D37: =IF(D$4="","",-D5) -> -362473 | E37: =IF(E$4="","",-E5) -> -479666 | F37: =IF(F$4="","",-F5) -> -516304 | G37: =IF(G$4="","",-G5) -> -409351 | H37: =IF(H$4="","",-H5) -> -387398 | I37: =IF(I$4="","",-I5) -> -324344 | J37: =IF(J$4="","",-J5) -> -292316 | ... M37: =IF(M$4="","",-M5)
B38: Gross Margin | C38: =IF(C36="","",C36+C37) -> 1610358 | D38: =IF(D36="","",D36+D37) -> 2265556 | E38: =IF(E36="","",E36+E37) -> 1691960 | F38: =IF(F36="","",F36+F37) -> 1809544 | G38: =IF(G36="","",G36+G37) -> 1483186 | H38: =IF(H36="","",H36+H37) -> 1463176 | I38: =IF(I36="","",I36+I37) -> 1326955 | J38: =IF(J36="","",J36+J37) -> 1184892 | ... M38: =IF(M36="","",M36+M37)
B39: OPEX | C39: =IF(C$4="","",-C6) -> -528317 | D39: =IF(D$4="","",-D6) -> -555259 | E39: =IF(E$4="","",-E6) -> -506779 | F39: =IF(F$4="","",-F6) -> -522738 | G39: =IF(G$4="","",-G6) -> -421877 | H39: =IF(H$4="","",-H6) -> -454796 | I39: =IF(I$4="","",-I6) -> -445068 | J39: =IF(J$4="","",-J6) -> -543726 | ... M39: =IF(M$4="","",-M6)
B40: Incl. Selling Expenses | C40: =IF(C$4="","",-C7) -> -41597 | D40: =IF(D$4="","",-D7) -> -48899 | E40: =IF(E$4="","",-E7) -> -43155 | F40: =IF(F$4="","",-F7) -> -53122 | G40: =IF(G$4="","",-G7) -> -36072 | H40: =IF(H$4="","",-H7) -> -38671 | I40: =IF(I$4="","",-I7) -> -43876 | J40: =IF(J$4="","",-J7) -> -250830 | ... M40: =IF(M$4="","",-M7)
B41: Incl. Other Opex | C41: =IF(C$4="","",C39-C40) -> -486720 | D41: =IF(D$4="","",D39-D40) -> -506360 | E41: =IF(E$4="","",E39-E40) -> -463624 | F41: =IF(F$4="","",F39-F40) -> -469616 | G41: =IF(G$4="","",G39-G40) -> -385805 | H41: =IF(H$4="","",H39-H40) -> -416125 | I41: =IF(I$4="","",I39-I40) -> -401192 | J41: =IF(J$4="","",J39-J40) -> -292896 | ... M41: =IF(M$4="","",M39-M40)
B42: R&D | C42: =IF(C$4="","",-C8) -> 0 | D42: =IF(D$4="","",-D8) -> 0 | E42: =IF(E$4="","",-E8) -> 0 | F42: =IF(F$4="","",-F8) -> 0 | G42: =IF(G$4="","",-G8) -> 0 | H42: =IF(H$4="","",-H8) -> 0 | I42: =IF(I$4="","",-I8) -> 0 | J42: =IF(J$4="","",-J8) -> 0 | ... M42: =IF(M$4="","",-M8)
B43: Operating EBIT | C43: =IF(C$4="","",C38+C39+C42) -> 1082041 | D43: =IF(D$4="","",D38+D39+D42) -> 1710297 | E43: =IF(E$4="","",E38+E39+E42) -> 1185181 | F43: =IF(F$4="","",F38+F39+F42) -> 1286806 | G43: =IF(G$4="","",G38+G39+G42) -> 1061309 | H43: =IF(H$4="","",H38+H39+H42) -> 1008380 | I43: =IF(I$4="","",I38+I39+I42) -> 881887 | J43: =IF(J$4="","",J38+J39+J42) -> 641166 | ... M43: =IF(M$4="","",M38+M39+M42)
...

Sheet BS
B1: Most Recent Quarter | C1: 45838 | F1: =IF(MONTH(C1)=MONTH(Normalized_FCF!G1),"FY","Quarter")&" Report" -> Quarter Report | H1: =scaling_factor -> 1000
B2: Lastest Balance Sheet
B3: ST Operating Assets | C3: Book | D3: Valued @ | F3: ST Non-Operating Assets | G3: Book | H3: Valued @
B4: ST AR | C4: =144049 -> 144049 | D4: 0.6 | F4: Cash and cash equivalents | G4: =171238+1622742 -> 1793980 | H4: 0.9
B5: Operating ST Financial Assets | C5: 0 | D5: 0.6 | F5: Restricted cash | G5: 0 | H5: 0.7
B6: Inventory | C6: 558421 | D6: 0.5 | F6: Securities with stable income | G6: 0 | H6: 0.6
B7: Properties held for sale | C7: 0 | D7: 0.6 | F7: Other Securities | G7: 311892 | H7: 0.6
B8: Properties held for income | C8: 0 | D8: 0.6 | F8: Properties with stable income | G8: 0 | H8: 0.6
B9: Prepayments and Contract Assets | C9: 12976 | D9: 0.1 | F9: Other Properties | G9: 0 | H9: 0.6
B10: ST DTA | C10: 0 | D10: 0.9 | F10: Assets held for sale | G10: 26801 | H10: 0.6
B11: Other ST Assets | C11: 0 | D11: 0.05
B12: Operating ST Assets | C12: =SUM(C4:C11) -> 715446 | D12: =C4*D4+C5*D5+C9*D9+C6*D6+C8*D8+C7*D7+C10*D10+C11*D11 -> 366937.5 | F12: Non-Operating ST Assets | G12: =SUM(G4:G10) -> 2132673 | H12: =G4*H4+G5*H5+G6*H6+G7*H7+G8*H8+G9*H9+G10*H10 -> 1817797.8
B14: LT Operating Assets | C14: Book | D14: Valued @ | F14: LT Non-Operating Assets | G14: Book | H14: Valued @
B15: LT AR and Prepayments | C15: 0 | D15: 0.4 | F15: LT Depositis | G15: =210586+109272 -> 319858 | H15: 0.8
B16: Operating LT Financial Assets | C16: 0 | D16: 0.5 | F16: Securities with stable income | G16: 0 | H16: 0.6
B17: Properties held for sale | C17: =1922097+21963 -> 1944060 | D17: 0.6 | F17: Other Securities | G17: 0 | H17: 0.6
B18: Properties held for income | C18: 0 | D18: 0.6 | F18: JV or associate with stable income | G18: =13948+51286 -> 65234 | H18: 0.1
B19: PP&E & Right of Use Assets | C19: =571235+160809 -> 732044 | D19: 0.1 | F19: Other JV or associate | G19: 0 | H19: 0.1
B20: Biological assets | C20: 0 | D20: 0.05 | F20: Properties with stable income | G20: 0 | H20: 0.2
B21: Intangible assets | C21: 255046 | D21: 0.05 | F21: Other Properties | G21: 6509 | H21: 0.1
B22: LT DTA | C22: 124199 | D22: 0.9
B23: Other assets & Goodwill | C23: =940923+2287 -> 943210 | D23: 0
B24: Operating LT Assets | C24: =SUM(C15:C23) -> 3998559 | D24: =C15*D15+C16*D16+C18*D18+C17*D17+C19*D19+C20*D20+C21*D21+C22*D22+C23*D23 -> 1364171.8 | F24: Non-Operating LT Assets | G24: =SUM(G15:G21) -> 391601 | H24: =G15*H15+G16*H16+G17*H17+G18*H18+G19*H19+G20*H20+G21*H21 -> 263060.7
B26: ST Liabilities | C26: Book | F26: BS Summary | G26: Book | H26: Valued @
B27: ST Borrowing | C27: 30472 | F27: Total Equity | G27: =G32-G30 -> 4865631 | H27: =H32-G30 -> 1439319.8
B28: ST Lease liabilities | C28: 13400 | F28: Incl. Minority Interest (NCI) | G28: 574396
B29: ST SH Loan | C29: 0 | F29: Incl. Common Equity | G29: =G27-G28 -> 4291235 | H29: =H27-G28 -> 864923.8
B30: ST Financial Liabilities | C30: 0 | F30: Total Liabilities | G30: =C33+C42 -> 2372648
B31: ST Interest-bearing Debt | C31: =SUM(C27:C30) -> 43872 | F31: incl. Interest-bearing Debt | G31: =C31+C40 -> 134804
B32: Other ST liabilities | C32: =C33-C31 -> 1513696 | F32: Total Assets | G32: =G35+G40 -> 7238279 | H32: =H35+H40 -> 3811967.8
B33: Current Liabilities | C33: 1557568
F34: Assets Summary | G34: Book | H34: Valued @
B35: LT Liabilities | C35: Book | F35: Operating Assets | G35: =C12+C24 -> 4714005 | H35: =D12+D24 -> 1731109.3
B36: LT Borrowing | C36: 0 | F36: incl. AR | G36: =C4+C15 -> 144049
B37: LT Lease liabilities | C37: 90932 | F37: incl. inventory | G37: =C6 -> 558421
B38: LT SH Loan | C38: 0 | F38: incl. Properties held for sale | G38: =C7+C17 -> 1944060
B39: LT Financial Liabilities | C39: 0 | F39: incl. Fixed Assets | G39: =C7+C17+C19+C20 -> 2676104 | H39: =C7*D7+C17*D17+C19*D19+C20*D20 -> 1239640.4
B40: LT Interest-bearing Debt | C40: =SUM(C36:C39) -> 90932 | F40: Non-operating Assets | G40: =G12+G24 -> 2524274 | H40: =H12+H24 -> 2080858.5
B41: Other LT liabilities | C41: =C42-C40 -> 724148 | F41: incl. Assets with stable income | G41: =C70 -> 2179072 | H41: =H40-H42 -> 1893072.4
B42: Noncurrent Liabilities | C42: 815080 | F42: incl. Other Assets | G42: =C82 -> 318401 | H42: =D82 -> 187786.1
...

Sheet Normalized_FCF
B1: =Thesis!E17 -> CNY | C1: Normalized | G1: =Data!C1 -> 45657 | H1: =EOMONTH(EDATE(G1,-12),0) -> 45291 | I1: =EOMONTH(EDATE(H1,-12),0) -> 44926 | J1: =EOMONTH(EDATE(I1,-12),0) -> 44561 | K1: =EOMONTH(EDATE(J1,-12),0) -> 44196 | L1: =EOMONTH(EDATE(K1,-12),0) -> 43830 | M1: =EOMONTH(EDATE(L1,-12),0) -> 43465 | N1: =EOMONTH(EDATE(M1,-12),0) -> 43100 | O1: =EOMONTH(EDATE(N1,-12),0) -> 42735 | ... Q1: =EOMONTH(EDATE(P1,-12),0) -> 42004
B2: FCFE Analysis | E2: Notes
B3: Normalized FCFE | C3: =scaling_factor -> 1000 | G3: Historical FCFE | H3: =scaling_factor -> 1000
B4: Sales | C4: =G4*0.7 -> 1454238.8 | G4: =Data!C36 -> 2077484 | H4: =Data!D36 -> 2628029 | I4: =Data!E36 -> 2171626 | J4: =Data!F36 -> 2325848 | K4: =Data!G36 -> 1892537 | L4: =Data!H36 -> 1850574 | M4: =Data!I36 -> 1651299 | N4: =Data!J36 -> 1477208 | ... Q4: =Data!M36
B5: Variable Costs | C5: =C26 -> -356106.1 | G5: =G26 -> -508723 | H5: =H26 -> -411372 | I5: =I26 -> -522821 | J5: =J26 -> -569426 | K5: =K26 -> -445423 | L5: =L26 -> -426069 | M5: =M26 -> -368220 | N5: =N26 -> -543146 | ... Q5: =Q26
B6: Contribution Margin | C6: =C4+C5 -> 1098132.7 | G6: =IF(G4="","",G4+G5) -> 1568761 | H6: =IF(H4="","",H4+H5) -> 2216657 | I6: =IF(I4="","",I4+I5) -> 1648805 | J6: =IF(J4="","",J4+J5) -> 1756422 | K6: =IF(K4="","",K4+K5) -> 1447114 | L6: =IF(L4="","",L4+L5) -> 1424505 | M6: =IF(M4="","",M4+M5) -> 1283079 | N6: =IF(N4="","",N4+N5) -> 934062 | ... Q6: =IF(Q4="","",Q4+Q5)
B7: Fixed Costs | C7: =C35 -> -486720 | G7: =G35 -> -486720 | H7: =H35 -> -506360 | I7: =I35 -> -463624 | J7: =J35 -> -469616 | K7: =K35 -> -385805 | L7: =L35 -> -416125 | M7: =M35 -> -401192 | N7: =N35 -> -292896 | ... Q7: =Q35
B8: Operating EBIT | C8: =C6+C7 -> 611412.7 | G8: =IF(G$4="","",G6+G7) -> 1082041 | H8: =IF(H$4="","",H6+H7) -> 1710297 | I8: =IF(I$4="","",I6+I7) -> 1185181 | J8: =IF(J$4="","",J6+J7) -> 1286806 | K8: =IF(K$4="","",K6+K7) -> 1061309 | L8: =IF(L$4="","",L6+L7) -> 1008380 | M8: =IF(M$4="","",M6+M7) -> 881887 | N8: =IF(N$4="","",N6+N7) -> 641166 | ... Q8: =IF(Q$4="","",Q6+Q7)
B9: Stable Non-Operating EBIT | C9: =C61 -> -2798 | G9: =G59 -> -2798 | H9: =H59 -> -18436 | I9: =I59 -> -7407 | J9: =J59 -> -11577 | K9: =K59 -> 4 | L9: =L59 -> -176 | M9: =M59 -> 0 | N9: =N59 -> 398 | ... Q9: =Q59
B10: Net Interest Income | C10: =C48 -> -4451.7949 | G10: =G48 -> -10168.406 | H10: =H48 -> -2420.0332 | I10: =I48 -> -5008 | J10: =J48 -> -7246 | K10: =K48 -> -9525 | L10: =L48 -> -11128 | M10: =M48 -> -8293 | N10: =N48 -> -15585 | ... Q10: =Q48
B11: Pre-tax Profit | C11: =SUM(C8:C10) -> 604162.91 | G11: =IF(G$4="","",SUM(G8:G10)) -> 1069074.6 | H11: =IF(H$4="","",SUM(H8:H10)) -> 1689441 | I11: =IF(I$4="","",SUM(I8:I10)) -> 1172766 | J11: =IF(J$4="","",SUM(J8:J10)) -> 1267983 | K11: =IF(K$4="","",SUM(K8:K10)) -> 1051788 | L11: =IF(L$4="","",SUM(L8:L10)) -> 997076 | M11: =IF(M$4="","",SUM(M8:M10)) -> 873594 | N11: =IF(N$4="","",SUM(N8:N10)) -> 625979 | ... Q11: =IF(Q$4="","",SUM(Q8:Q10))
B12: Income Tax | C12: =-C11*C41 -> -151040.73 | G12: =Data!C46 -> -313181 | H12: =Data!D46 -> -455638 | I12: =Data!E46 -> -281476 | J12: =Data!F46 -> -289591 | K12: =Data!G46 -> -222784 | L12: =Data!H46 -> -211350 | M12: =Data!I46 -> -159140 | N12: =Data!J46 -> -134611 | ... Q12: =Data!M46
B13: NCI’s Share of Profits | C13: =-C4*C79 -> -106049.45 | G13: =Data!C48 -> -124194 | H13: =Data!D48 -> -184676 | I13: =Data!E48 -> -152133 | J13: =Data!F48 -> -169611 | K13: =Data!G48 -> -137241 | L13: =Data!H48 -> -156740 | M13: =Data!I48 -> -127269 | N13: =Data!J48 -> -132823 | ... Q13: =Data!M48
B14: After-tax Profit | C14: =SUM(C11:C13) -> 347072.73 | G14: =IF(G$4="","",SUM(G11:G13)) -> 631699.59 | H14: =IF(H$4="","",SUM(H11:H13)) -> 1049127 | I14: =IF(I$4="","",SUM(I11:I13)) -> 739157 | J14: =IF(J$4="","",SUM(J11:J13)) -> 808781 | K14: =IF(K$4="","",SUM(K11:K13)) -> 691763 | L14: =IF(L$4="","",SUM(L11:L13)) -> 628986 | M14: =IF(M$4="","",SUM(M11:M13)) -> 587185 | N14: =IF(N$4="","",SUM(N11:N13)) -> 358545 | ... Q14: =IF(Q$4="","",SUM(Q11:Q13))
B15: Add Back D&A | C15: =BS!$G$39*BS!D58 -> 173179 | G15: =IF(Data!C61="","",-Data!C61) -> 173179 | H15: =IF(Data!D61="","",-Data!D61) -> 166609 | I15: =IF(Data!E61="","",-Data!E61) -> 0 | J15: =IF(Data!F61="","",-Data!F61) -> 0 | K15: =IF(Data!G61="","",-Data!G61) -> 0 | L15: =IF(Data!H61="","",-Data!H61) -> 0 | M15: =IF(Data!I61="","",-Data!I61) -> 0 | N15: =IF(Data!J61="","",-Data!J61) -> 0 | ... Q15: =IF(Data!M61="","",-Data!M61)
B16: Maintenance Capex | C16: =-C4*C82 -> -173179 | G16: =Data!C62 -> -173179 | H16: =Data!D62 -> -166609 | I16: =Data!E62 -> 0 | J16: =Data!F62 -> 0 | K16: =Data!G62 -> 0 | L16: =Data!H62 -> 0 | M16: =Data!I62 -> 0 | N16: =Data!J62 -> 0 | ... Q16: =Data!M62
B17: WCInv | C17: =-C4*C83 -> 0 | E17: WCInv is by default excluded
B18: Net Borrowing | C18: 0 | E18: Net borrowing is excluded
B19: FCFE | C19: =C14+C17 -> 347072.73 | G19: =IF(G$4="","",G14+G17) -> 631699.59 | H19: =IF(H$4="","",H14+H17) -> 1049127 | I19: =IF(I$4="","",I14+I17) -> 739157 | J19: =IF(J$4="","",J14+J17) -> 808781 | K19: =IF(K$4="","",K14+K17) -> 691763 | L19: =IF(L$4="","",L14+L17) -> 628986 | M19: =IF(M$4="","",M14+M17) -> 587185 | N19: =IF(N$4="","",N14+N17) -> 358545 | ... Q19: =IF(Q$4="","",Q14+Q17)
B21: Operating Cost Structure | E21: Notes
B22: Variable Costs
B23: COGS | C23: =-C4*C29 -> -326988.2 | G23: =Data!C37 -> -467126 | H23: =Data!D37 -> -362473 | I23: =Data!E37 -> -479666 | J23: =Data!F37 -> -516304 | K23: =Data!G37 -> -409351 | L23: =Data!H37 -> -387398 | M23: =Data!I37 -> -324344 | N23: =Data!J37 -> -292316 | ... Q23: =Data!M37
B24: Selling Expenses | C24: =-C4*C30 -> -29117.9 | G24: =Data!C40 -> -41597 | H24: =Data!D40 -> -48899 | I24: =Data!E40 -> -43155 | J24: =Data!F40 -> -53122 | K24: =Data!G40 -> -36072 | L24: =Data!H40 -> -38671 | M24: =Data!I40 -> -43876 | N24: =Data!J40 -> -250830 | ... Q24: =Data!M40
B25: R&D | C25: =-C4*C31 -> 0 | G25: =Data!C42 -> 0 | H25: =Data!D42 -> 0 | I25: =Data!E42 -> 0 | J25: =Data!F42 -> 0 | K25: =Data!G42 -> 0 | L25: =Data!H42 -> 0 | M25: =Data!I42 -> 0 | N25: =Data!J42 -> 0 | ... Q25: =Data!M42
B26: Variable Costs | C26: =SUM(C23:C25) -> -356106.1 | G26: =IF(G$4="","",SUM(G23:G25)) -> -508723 | H26: =IF(H$4="","",SUM(H23:H25)) -> -411372 | I26: =IF(I$4="","",SUM(I23:I25)) -> -522821 | J26: =IF(J$4="","",SUM(J23:J25)) -> -569426 | K26: =IF(K$4="","",SUM(K23:K25)) -> -445423 | L26: =IF(L$4="","",SUM(L23:L25)) -> -426069 | M26: =IF(M$4="","",SUM(M23:M25)) -> -368220 | N26: =IF(N$4="","",SUM(N23:N25)) -> -543146 | ... Q26: =IF(Q$4="","",SUM(Q23:Q25))
B28: Variable Costs % of Sales
B29: COGS | C29: =G29 -> 0.22485179 | G29: =IF(G$4="","",ABS(G23/G$4)) -> 0.22485179 | H29: =IF(H$4="","",ABS(H23/H$4)) -> 0.1379258 | I29: =IF(I$4="","",ABS(I23/I$4)) -> 0.22087873 | J29: =IF(J$4="","",ABS(J23/J$4)) -> 0.22198527 | K29: =IF(K$4="","",ABS(K23/K$4)) -> 0.21629749 | L29: =IF(L$4="","",ABS(L23/L$4)) -> 0.20933937 | M29: =IF(M$4="","",ABS(M23/M$4)) -> 0.19641749 | N29: =IF(N$4="","",ABS(N23/N$4)) -> 0.19788412 | ... Q29: =IF(Q$4="","",ABS(Q23/Q$4))
B30: =B24 -> Selling Expenses | C30: =G30 -> 0.020022778 | G30: =IF(G$4="","",ABS(G24/G$4)) -> 0.020022778 | H30: =IF(H$4="","",ABS(H24/H$4)) -> 0.01860672 | I30: =IF(I$4="","",ABS(I24/I$4)) -> 0.019872206 | J30: =IF(J$4="","",ABS(J24/J$4)) -> 0.022839842 | K30: =IF(K$4="","",ABS(K24/K$4)) -> 0.019060129 | L30: =IF(L$4="","",ABS(L24/L$4)) -> 0.02089676 | M30: =IF(M$4="","",ABS(M24/M$4)) -> 0.026570597 | N30: =IF(N$4="","",ABS(N24/N$4)) -> 0.16980006 | ... Q30: =IF(Q$4="","",ABS(Q24/Q$4))
B31: =B25 -> R&D | C31: 0 | G31: =IF(G$4="","",ABS(G25/G$4)) -> 0 | H31: =IF(H$4="","",ABS(H25/H$4)) -> 0 | I31: =IF(I$4="","",ABS(I25/I$4)) -> 0 | J31: =IF(J$4="","",ABS(J25/J$4)) -> 0 | K31: =IF(K$4="","",ABS(K25/K$4)) -> 0 | L31: =IF(L$4="","",ABS(L25/L$4)) -> 0 | M31: =IF(M$4="","",ABS(M25/M$4)) -> 0 | N31: =IF(N$4="","",ABS(N25/N$4)) -> 0 | ... Q31: =IF(Q$4="","",ABS(Q25/Q$4))
B32: Variable Costs | C32: =ABS(C26/$C$4) -> 0.24487457 | G32: =IF(G$4="","",ABS(G26/G$4)) -> 0.24487457 | H32: =IF(H$4="","",ABS(H26/H$4)) -> 0.15653252 | I32: =IF(I$4="","",ABS(I26/I$4)) -> 0.24075094 | J32: =IF(J$4="","",ABS(J26/J$4)) -> 0.24482511 | K32: =IF(K$4="","",ABS(K26/K$4)) -> 0.23535762 | L32: =IF(L$4="","",ABS(L26/L$4)) -> 0.23023613 | M32: =IF(M$4="","",ABS(M26/M$4)) -> 0.22298808 | N32: =IF(N$4="","",ABS(N26/N$4)) -> 0.36768417 | ... Q32: =IF(Q$4="","",ABS(Q26/Q$4))
B34: Fixed Costs
B35: G&A and other Opex | C35: =G35 -> -486720 | G35: =IF(G4="","",Data!C41) -> -486720 | H35: =IF(H4="","",Data!D41) -> -506360 | I35: =IF(I4="","",Data!E41) -> -463624 | J35: =IF(J4="","",Data!F41) -> -469616 | K35: =IF(K4="","",Data!G41) -> -385805 | L35: =IF(L4="","",Data!H41) -> -416125 | M35: =IF(M4="","",Data!I41) -> -401192 | N35: =IF(N4="","",Data!J41) -> -292896 | ... Q35: =IF(Q4="","",Data!M41)
B37: Fixed Costs % of Sales
B38: G&A and other Opex | C38: =ABS(C35/$C$4) -> 0.33469056 | G38: =IF(G$4="","",ABS(G35/G$4)) -> 0.23428339 | H38: =IF(H$4="","",ABS(H35/H$4)) -> 0.19267672 | I38: =IF(I$4="","",ABS(I35/I$4)) -> 0.21349164 | J38: =IF(J$4="","",ABS(J35/J$4)) -> 0.20191173 | K38: =IF(K$4="","",ABS(K35/K$4)) -> 0.20385599 | L38: =IF(L$4="","",ABS(L35/L$4)) -> 0.22486266 | M38: =IF(M$4="","",ABS(M35/M$4)) -> 0.24295539 | N38: =IF(N$4="","",ABS(N35/N$4)) -> 0.19827675 | ... Q38: =IF(Q$4="","",ABS(Q35/Q$4))
B40: Tax % of Pre-tax Profit
B41: Income Tax Rate | C41: 0.25 | E41: Use the marginal tax rate | G41: =IF(G$4="","",-G12/SUM(G8+G9,G10)) -> 0.29294588 | H41: =IF(H$4="","",-H12/SUM(H8+H9,H10)) -> 0.2696975 | I41: =IF(I$4="","",-I12/SUM(I8+I9,I10)) -> 0.24001037 | J41: =IF(J$4="","",-J12/SUM(J8+J9,J10)) -> 0.22838713 | K41: =IF(K$4="","",-K12/SUM(K8+K9,K10)) -> 0.21181455 | L41: =IF(L$4="","",-L12/SUM(L8+L9,L10)) -> 0.2119698 | M41: =IF(M$4="","",-M12/SUM(M8+M9,M10)) -> 0.182167 | N41: =IF(N$4="","",-N12/SUM(N8+N9,N10)) -> 0.21504076 | ... Q41: =IF(Q$4="","",-Q12/SUM(Q8+Q9,Q10))
B43: Non-operating Income | E43: Notes
B44: Interest
B45: Interest Expense | C45: =-BS!G31*Normalized_FCF!C52 -> -8088.24 | G45: =Data!C51 -> -16422 | H45: =Data!D51 -> -7392 | I45: =Data!E51 -> -5008 | J45: =Data!F51 -> -7246 | K45: =Data!G51 -> -9525 | L45: =Data!H51 -> -11128 | M45: =Data!I51 -> -8293 | N45: =Data!J51 -> -15585 | ... Q45: =Data!M51
B46: Operating Interest Income | C46: =BS!D75*C51 -> 3636.4451 | G46: =IFERROR(IF(G$4="","",($C$46/$C$47)*G47),0) -> 6253.5937 | H46: =IFERROR(IF(H$4="","",($C$46/$C$47)*H47),0) -> 4971.9668 | I46: =IFERROR(IF(I$4="","",($C$46/$C$47)*I47),0) -> 0 | J46: =IFERROR(IF(J$4="","",($C$46/$C$47)*J47),0) -> 0 | K46: =IFERROR(IF(K$4="","",($C$46/$C$47)*K47),0) -> 0 | L46: =IFERROR(IF(L$4="","",($C$46/$C$47)*L47),0) -> 0 | M46: =IFERROR(IF(M$4="","",($C$46/$C$47)*M47),0) -> 0 | N46: =IFERROR(IF(N$4="","",($C$46/$C$47)*N47),0) -> 0 | ... Q46: =IFERROR(IF(Q$4="","",($C$46/$C$47)*Q47),0)
...

Sheet DCF
B2: No-Growth DCF Valuation
B3: No-Growth DCF | C3: =scaling_factor -> 1000 | E3: FV adjustments | H3: Normalized Values
B4: Normalized FCFE | C4: =Normalized_FCF!C19 -> 347072.73 | D4: =Reporting_currency -> CNY | E4: Interest-bearing Debt | F4: =-BS!G31 -> -134804 | G4: =Reporting_currency -> CNY | H4: Revenues | I4: =Normalized_FCF!C4 -> 1454238.8
B5: /Equity Cost of Capital | C5: =Equity_Cost -> 0.0725 | E5: Non-operating Cash | F5: =BS!D66 -> 1507763.8 | G5: =Reporting_currency -> CNY | H5: Fixed Costs | I5: =Normalized_FCF!C7 -> -486720
B6: Stable Income Value | C6: =(C4*(1+Terminal_Growth))/(Equity_Cost-Terminal_Growth) -> 4787210.1 | D6: =Reporting_currency -> CNY | E6: Other Non-op. Assets | F6: =BS!H42 -> 187786.1 | G6: =Reporting_currency -> CNY | H6: Other Income, includes | I6: =I7+I8 -> -7249.7949
B7: + FV adjustments | C7: =F7 -> 1560745.9 | E7: FV adjustments | F7: =SUM(F4:F6) -> 1560745.9 | G7: =Reporting_currency -> CNY | H7: Non-op EBIT | I7: =Normalized_FCF!C9 -> -2798
B8: Equity Value | C8: =C6+C7 -> 6347956 | D8: =Reporting_currency -> CNY | E8: FV adj. per share | F8: =FV_adjustments*scaling_factor/Common_Shares*Exchange_Rate -> 0.73562094 | G8: =Market_currency -> HKD | H8: =Normalized_FCF!B10 -> Net Interest Income | I8: =Normalized_FCF!C10 -> -4451.7949
B9: ="*"&Thesis!E15 -> *CNY/HKD | C9: =Exchange_Rate -> 1.0934132 | D9: =Thesis!E15 -> CNY/HKD | H9: =Normalized_FCF!B79 -> NCI’s Share of Profits | I9: =Normalized_FCF!C79 -> 0.07292437
B10: Value | C10: =C8*Exchange_Rate -> 6940938.6 | D10: =Market_currency -> HKD | H10: Tax rate | I10: =Normalized_FCF!C41 -> 0.25
B11: Value per share | C11: =(C10*scaling_factor)/Common_Shares -> 2.99196 | D11: =Market_currency -> HKD
B13: Growth DCF Valuation
B14: Stage | C14: I | E14: Stage | F14: =IF(F17=C17,"I","II") -> I | H14: Terminal Stage
B15: High g Period (HGP) | C15: =Scenarios!C45 -> 5 | E15: =IF(F14="II","Change year","Terminal Year") -> Terminal Year | F15: =IF(F14="II",_xlfn.CEILING.MATH(C15/2),C15+1) -> 6 | H15: Terminal g Rate: | I15: =Terminal_Growth -> 0
B16: High g Rate (HGR) | C16: =Scenarios!C46 -> 0.018613012 | E16: High Growth Rate_II | F16: =Scenarios!C41 -> 0.018613012
B17: Contribution Margin | C17: =Normalized_FCF!C32 -> 0.24487457 | E17: Contribution Margin_II | F17: =Scenarios!C40 -> 0.24487457 | H17: Output
B18: D&A - maint. Capx | C18: =Normalized_FCF!C81-Normalized_FCF!C82 -> 0 | E18: D&A - maint. Capx | F18: =IF(F14="II",C18/2,C18) -> 0 | H18: Value Per Share | I18: =(L52+FV_adjustments)*Exchange_Rate/Common_Shares*scaling_factor -> 3.1848543 | J18: =Market_currency -> HKD
A20: Stage | B20: Year | C20: Revenues | D20: Growth Rates | E20: Contribution Margin | F20: Fixed Costs | G20: EBIT | H20: =B18 -> D&A - maint. Capx | I20: FCFE/TV | J20: FCFE g | K20: Disc. Factor | L20: PV of FCFE/TV
A21: =IF($C$15<B21,"",IF(B21>=$F$15,"II","I")) -> I | B21: 1 | C21: =I4*(1+D21) -> 1481306.6 | D21: =IF(A21="",0,IF(A21="I",$C$16,$F$16)) -> 0.018613012 | E21: =$C$17 -> 0.24487457 | F21: =I5*(1+D21) -> -495779.33 | G21: =C21*(1-E21)+F21+$I$6 -> 615543.14 | H21: =IF(A21="",0%,IF(A21="I",$C$18,$F$18)) -> 0 | I21: =(G21*(1-$I$10)+C21*(H21-$I$9)) -> 353634 | J21: =I21/C4-1 -> 0.018904609 | K21: =IF($C$15<B21,0,1/(1+Equity_Cost)^B21) -> 0.93240093 | L21: =I21*K21 -> 329728.68
A22: =IF($C$15<B22,"",IF(B22>=$F$15,"II","I")) -> I | B22: 2 | C22: =IF(A22="",0,C21*(1+D22)) -> 1508878.1 | D22: =IF(A22="",0,IF(A22="I",$C$16,$F$16)) -> 0.018613012 | E22: =IF($C$15<B22,0,IF(B22>=$F$15,$F$17,$C$17)) -> 0.24487457 | F22: =IF(A22="",0,F21*(1+D22)) -> -505007.27 | G22: =IF(A22="", 0,C22*(1-E22)+F22+$I$6) -> 627135.19 | H22: =IF(A22="",0%,IF(A22="I",$C$18,$F$18)) -> 0 | I22: =IF(A22="", 0,G22*(1-$I$10)+C22*(H22-$I$9)) -> 360317.4 | J22: =IF(A22="", 0,I22/I21-1) -> 0.018899199 | K22: =IF($C$15<B22,0,1/(1+Equity_Cost)^B22) -> 0.8693715 | L22: =I22*K22 -> 313249.68
A23: =IF($C$15<B23,"",IF(B23>=$F$15,"II","I")) -> I | B23: 3 | C23: =IF(A23="",0,C22*(1+D23)) -> 1536962.9 | D23: =IF(A23="",0,IF(A23="I",$C$16,$F$16)) -> 0.018613012 | E23: =IF($C$15<B23,0,IF(B23>=$F$15,$F$17,$C$17)) -> 0.24487457 | F23: =IF(A23="",0,F22*(1+D23)) -> -514406.98 | G23: =IF(A23="", 0,C23*(1-E23)+F23+$I$6) -> 638943 | H23: =IF(A23="",0%,IF(A23="I",$C$18,$F$18)) -> 0 | I23: =IF(A23="", 0,G23*(1-$I$10)+C23*(H23-$I$9)) -> 367125.2 | J23: =IF(A23="", 0,I23/I22-1) -> 0.018893891 | K23: =IF($C$15<B23,0,1/(1+Equity_Cost)^B23) -> 0.8106028 | L23: =I23*K23 -> 297592.72
A24: =IF($C$15<B24,"",IF(B24>=$F$15,"II","I")) -> I | B24: 4 | C24: =IF(A24="",0,C23*(1+D24)) -> 1565570.4 | D24: =IF(A24="",0,IF(A24="I",$C$16,$F$16)) -> 0.018613012 | E24: =IF($C$15<B24,0,IF(B24>=$F$15,$F$17,$C$17)) -> 0.24487457 | F24: =IF(A24="",0,F23*(1+D24)) -> -523981.64 | G24: =IF(A24="", 0,C24*(1-E24)+F24+$I$6) -> 650970.6 | H24: =IF(A24="",0%,IF(A24="I",$C$18,$F$18)) -> 0 | I24: =IF(A24="", 0,G24*(1-$I$10)+C24*(H24-$I$9)) -> 374059.71 | J24: =IF(A24="", 0,I24/I23-1) -> 0.018888682 | K24: =IF($C$15<B24,0,1/(1+Equity_Cost)^B24) -> 0.7558068 | L24: =I24*K24 -> 282716.88
A25: =IF($C$15<B25,"",IF(B25>=$F$15,"II","I")) -> I | B25: 5 | C25: =IF(A25="",0,C24*(1+D25)) -> 1594710.4 | D25: =IF(A25="",0,IF(A25="I",$C$16,$F$16)) -> 0.018613012 | E25: =IF($C$15<B25,0,IF(B25>=$F$15,$F$17,$C$17)) -> 0.24487457 | F25: =IF(A25="",0,F24*(1+D25)) -> -533734.52 | G25: =IF(A25="", 0,C25*(1-E25)+F25+$I$6) -> 663222.06 | H25: =IF(A25="",0%,IF(A25="I",$C$18,$F$18)) -> 0 | I25: =IF(A25="", 0,G25*(1-$I$10)+C25*(H25-$I$9)) -> 381123.3 | J25: =IF(A25="", 0,I25/I24-1) -> 0.018883572 | K25: =IF($C$15<B25,0,1/(1+Equity_Cost)^B25) -> 0.70471497 | L25: =I25*K25 -> 268583.29
A26: =IF($C$15<B26,"",IF(B26>=$F$15,"II","I")) | B26: 6 | C26: =IF(A26="",0,C25*(1+D26)) -> 0 | D26: =IF(A26="",0,IF(A26="I",$C$16,$F$16)) -> 0 | E26: =IF($C$15<B26,0,IF(B26>=$F$15,$F$17,$C$17)) -> 0 | F26: =IF(A26="",0,F25*(1+D26)) -> 0 | G26: =IF(A26="", 0,C26*(1-E26)+F26+$I$6) -> 0 | H26: =IF(A26="",0%,IF(A26="I",$C$18,$F$18)) -> 0 | I26: =IF(A26="", 0,G26*(1-$I$10)+C26*(H26-$I$9)) -> 0 | J26: =IF(A26="", 0,I26/I25-1) -> 0 | K26: =IF($C$15<B26,0,1/(1+Equity_Cost)^B26) -> 0 | L26: =I26*K26 -> 0
A27: =IF($C$15<B27,"",IF(B27>=$F$15,"II","I")) | B27: 7 | C27: =IF(A27="",0,C26*(1+D27)) -> 0 | D27: =IF(A27="",0,IF(A27="I",$C$16,$F$16)) -> 0 | E27: =IF($C$15<B27,0,IF(B27>=$F$15,$F$17,$C$17)) -> 0 | F27: =IF(A27="",0,F26*(1+D27)) -> 0 | G27: =IF(A27="", 0,C27*(1-E27)+F27+$I$6) -> 0 | H27: =IF(A27="",0%,IF(A27="I",$C$18,$F$18)) -> 0 | I27: =IF(A27="", 0,G27*(1-$I$10)+C27*(H27-$I$9)) -> 0 | J27: =IF(A27="", 0,I27/I26-1) -> 0 | K27: =IF($C$15<B27,0,1/(1+Equity_Cost)^B27) -> 0 | L27: =I27*K27 -> 0
A28: =IF($C$15<B28,"",IF(B28>=$F$15,"II","I")) | B28: 8 | C28: =IF(A28="",0,C27*(1+D28)) -> 0 | D28: =IF(A28="",0,IF(A28="I",$C$16,$F$16)) -> 0 | E28: =IF($C$15<B28,0,IF(B28>=$F$15,$F$17,$C$17)) -> 0 | F28: =IF(A28="",0,F27*(1+D28)) -> 0 | G28: =IF(A28="", 0,C28*(1-E28)+F28+$I$6) -> 0 | H28: =IF(A28="",0%,IF(A28="I",$C$18,$F$18)) -> 0 | I28: =IF(A28="", 0,G28*(1-$I$10)+C28*(H28-$I$9)) -> 0 | J28: =IF(A28="", 0,I28/I27-1) -> 0 | K28: =IF($C$15<B28,0,1/(1+Equity_Cost)^B28) -> 0 | L28: =I28*K28 -> 0
A29: =IF($C$15<B29,"",IF(B29>=$F$15,"II","I")) | B29: 9 | C29: =IF(A29="",0,C28*(1+D29)) -> 0 | D29: =IF(A29="",0,IF(A29="I",$C$16,$F$16)) -> 0 | E29: =IF($C$15<B29,0,IF(B29>=$F$15,$F$17,$C$17)) -> 0 | F29: =IF(A29="",0,F28*(1+D29)) -> 0 | G29: =IF(A29="", 0,C29*(1-E29)+F29+$I$6) -> 0 | H29: =IF(A29="",0%,IF(A29="I",$C$18,$F$18)) -> 0 | I29: =IF(A29="", 0,G29*(1-$I$10)+C29*(H29-$I$9)) -> 0 | J29: =IF(A29="", 0,I29/I28-1) -> 0 | K29: =IF($C$15<B29,0,1/(1+Equity_Cost)^B29) -> 0 | L29: =I29*K29 -> 0
A30: =IF($C$15<B30,"",IF(B30>=$F$15,"II","I")) | B30: 10 | C30: =IF(A30="",0,C29*(1+D30)) -> 0 | D30: =IF(A30="",0,IF(A30="I",$C$16,$F$16)) -> 0 | E30: =IF($C$15<B30,0,IF(B30>=$F$15,$F$17,$C$17)) -> 0 | F30: =IF(A30="",0,F29*(1+D30)) -> 0 | G30: =IF(A30="", 0,C30*(1-E30)+F30+$I$6) -> 0 | H30: =IF(A30="",0%,IF(A30="I",$C$18,$F$18)) -> 0 | I30: =IF(A30="", 0,G30*(1-$I$10)+C30*(H30-$I$9)) -> 0 | J30: =IF(A30="", 0,I30/I29-1) -> 0 | K30: =IF($C$15<B30,0,1/(1+Equity_Cost)^B30) -> 0 | L30: =I30*K30 -> 0
A31: =IF($C$15<B31,"",IF(B31>=$F$15,"II","I")) | B31: 11 | C31: =IF(A31="",0,C30*(1+D31)) -> 0 | D31: =IF(A31="",0,IF(A31="I",$C$16,$F$16)) -> 0 | E31: =IF($C$15<B31,0,IF(B31>=$F$15,$F$17,$C$17)) -> 0 | F31: =IF(A31="",0,F30*(1+D31)) -> 0 | G31: =IF(A31="", 0,C31*(1-E31)+F31+$I$6) -> 0 | H31: =IF(A31="",0%,IF(A31="I",$C$18,$F$18)) -> 0 | I31: =IF(A31="", 0,G31*(1-$I$10)+C31*(H31-$I$9)) -> 0 | J31: =IF(A31="", 0,I31/I30-1) -> 0 | K31: =IF($C$15<B31,0,1/(1+Equity_Cost)^B31) -> 0 | L31: =I31*K31 -> 0
A32: =IF($C$15<B32,"",IF(B32>=$F$15,"II","I")) | B32: 12 | C32: =IF(A32="",0,C31*(1+D32)) -> 0 | D32: =IF(A32="",0,IF(A32="I",$C$16,$F$16)) -> 0 | E32: =IF($C$15<B32,0,IF(B32>=$F$15,$F$17,$C$17)) -> 0 | F32: =IF(A32="",0,F31*(1+D32)) -> 0 | G32: =IF(A32="", 0,C32*(1-E32)+F32+$I$6) -> 0 | H32: =IF(A32="",0%,IF(A32="I",$C$18,$F$18)) -> 0 | I32: =IF(A32="", 0,G32*(1-$I$10)+C32*(H32-$I$9)) -> 0 | J32: =IF(A32="", 0,I32/I31-1) -> 0 | K32: =IF($C$15<B32,0,1/(1+Equity_Cost)^B32) -> 0 | L32: =I32*K32 -> 0
A33: =IF($C$15<B33,"",IF(B33>=$F$15,"II","I")) | B33: 13 | C33: =IF(A33="",0,C32*(1+D33)) -> 0 | D33: =IF(A33="",0,IF(A33="I",$C$16,$F$16)) -> 0 | E33: =IF($C$15<B33,0,IF(B33>=$F$15,$F$17,$C$17)) -> 0 | F33: =IF(A33="",0,F32*(1+D33)) -> 0 | G33: =IF(A33="", 0,C33*(1-E33)+F33+$I$6) -> 0 | H33: =IF(A33="",0%,IF(A33="I",$C$18,$F$18)) -> 0 | I33: =IF(A33="", 0,G33*(1-$I$10)+C33*(H33-$I$9)) -> 0 | J33: =IF(A33="", 0,I33/I32-1) -> 0 | K33: =IF($C$15<B33,0,1/(1+Equity_Cost)^B33) -> 0 | L33: =I33*K33 -> 0
... A50: =IF($C$15<B50,"",IF(B50>=$F$15,"II","I")) | B50: 30 | C50: =IF(A50="",0,C49*(1+D50)) -> 0 | D50: =IF(A50="",0,IF(A50="I",$C$16,$F$16)) -> 0 | E50: =IF($C$15<B50,0,IF(B50>=$F$15,$F$17,$C$17)) -> 0 | F50: =IF(A50="",0,F49*(1+D50)) -> 0 | G50: =IF(A50="", 0,C50*(1-E50)+F50+$I$6) -> 0 | H50: =IF(A50="",0%,IF(A50="I",$C$18,$F$18)) -> 0 | I50: =IF(A50="", 0,G50*(1-$I$10)+C50*(H50-$I$9)) -> 0 | J50: =IF(A50="", 0,I50/I49-1) -> 0 | K50: =IF($C$15<B50,0,1/(1+Equity_Cost)^B50) -> 0 | L50: =I50*K50 -> 0
A51: T | B51: =C15+1 -> 6 | C51: =VLOOKUP(C15,B21:C50,2,FALSE)*(1+Terminal_Growth) -> 1594710.4 | D51: =Terminal_Growth -> 0 | E51: =F17 -> 0.24487457 | F51: =VLOOKUP(C15,B21:F50,5,FALSE)*(1+Terminal_Growth) -> -533734.52 | G51: =C51*(1-E51)+F51+$I$6 -> 663222.06 | H51: =F18 -> 0 | I51: =(G51*(1-$I$10)+C51*(H51-$I$9))/Equity_Cost -> 5256873.1 | J51: =(G51*(1-$I$10)+C51*(H51-$I$9))/VLOOKUP(C15,B21:I50,8,FALSE)-1 -> 0 | K51: =1/(1+Equity_Cost)^C15 -> 0.70471497 | L51: =I51*K51 -> 3704597.1
J52: PV of total FCFE = | L52: =SUM(L21:L51) -> 5196468.4
B54: Sensitivity Analysis (Enterprise Value)
A55: =L52 -> 5196468.4 | B55: =C78 -> -0.1 | C55: =C77 -> 0.01 | D55: =C76 -> 0.02 | E55: =C75 -> 0.03 | F55: =C74 -> 0.08
A56: 5 | B56: 3022147.9 | C56: 5003589.6 | D56: 5228102.5 | E56: 5460984.3 | F56: 6759485.3
A57: 10 | B57: 2287657.6 | C57: 5163853.8 | D57: 5571144.3 | E57: 6011429.4 | F57: 8801692.5
A58: 15 | B58: 1982016.2 | C58: 5282555.4 | D58: 5838052.2 | E58: 6461119.9 | F58: 10916311
A59: 20 | B59: 1854830.6 | C59: 5370473.3 | D59: 6045723.1 | E59: 6828497.9 | F59: 13105909
A60: 25 | B60: 1801905.2 | C60: 5435590.8 | D60: 6207304 | E60: 7128630.3 | F60: 15373144
...

Sheet Scenarios
B2: Current Situation
B3: Selection | E3: Prompt for fundamental Analysis
B4: Past Years Selected | C4: 2 | E4: ="Please develop three logical "&C18&"-year scenarios (Base Case, Pessimistic Case, Optimistic Case) and two extreme "&C18&"-year scenarios (Success Scenario, Devil’s Advocate Scenario) for "&Thesis!C4&"("&Thesis!C5&"). Each scenario should include the Compound Growth Rate, the Probability Assessment, and the Business Narrative." -> Please develop three logical 5-year scenarios (Base Case, Pessimistic Case, Optimistic Case) and two extreme 5-year scenarios (Success Scenario, Devil’s Advocate Scenario) for 福寿园(1448.HK). Each scenario should include the Compound Growth Rate, the Probability Assessment, and the Business Narrative.
B6: Latest | C6: =DCF!C3 -> 1000
B7: EBIT | C7: =Normalized_FCF!G8 -> 1082041 | D7: =Reporting_currency -> CNY
B8: FCFE | C8: =Normalized_FCF!G19 -> 631699.59 | D8: =Reporting_currency -> CNY
B9: Normalized | C9: =Normalized_FCF!C19 -> 347072.73 | D9: =Reporting_currency -> CNY
B11: YoY CAGR
B12: Sales | C12: =(Normalized_FCF!G4/OFFSET(Normalized_FCF!G4, 0, $C$4))^(1/$C$4) - 1 -> -0.02191561
B13: Operating EBIT | C13: =(Normalized_FCF!G8/OFFSET(Normalized_FCF!G8, 0, $C$4))^(1/$C$4) - 1 -> -0.044502581
B14: FCFE | C14: =(Normalized_FCF!G19/OFFSET(Normalized_FCF!G19, 0, $C$4))^(1/$C$4) - 1 -> -0.075542497
B16: Scenarios Analysis
B17: Assumption
B18: High Growth Period (HGP) | C18: 5
B20: General Scenarios
B21: Scenarios | C21: HGR | D21: HGP | E21: ="Value per share ("&Market_currency&")" -> Value per share (HKD) | F21: Probabilities | G21: Adj. Probabilities
B22: Optimistic | C22: 0.03 | D22: =C18 -> 5 | E22: =DCF!E75 -> 3.3095277 | F22: =1-F23-F24 -> 0.2 | G22: =F22*(1-F$29-F$30) -> 0.18
B23: Base | C23: 0.02 | D23: =C18 -> 5 | E23: =DCF!E76 -> 3.1997643 | F23: 0.6 | G23: =F23*(1-F$29-F$30) -> 0.54
B24: Pessimistic | C24: 0.01 | D24: =C18 -> 5 | E24: =DCF!E77 -> 3.0939454 | F24: 0.2 | G24: =F24*(1-F$29-F$30) -> 0.18
B25: Under General Scenario | C25: =E23*F23+E24*F24+E22*F22 -> 3.2005532 | D25: =Market_currency -> HKD
B27: Extreme Scenarios
B28: Scenarios | C28: HGR | D28: HGP | E28: ="Value per share ("&Market_currency&")" -> Value per share (HKD) | F28: Probabilities | G28: Adj. Probabilities
B29: Snowball Scenario | C29: 0.08 | D29: =C18 -> 5 | E29: =DCF!E74 -> 3.9215456 | F29: 0.05 | G29: =F29 -> 0.05
B30: Devil's advocate | C30: -0.1 | D30: =C18 -> 5 | E30: =DCF!E78 -> 2.1600394 | F30: 0.05 | G30: =F30 -> 0.05
B32: Conclusion
B33: Annual Dividend per share | C33: =Normalized_FCF!C88*(1-dividend_tax_rate) -> 0.1592 | D33: =Market_currency -> HKD | E33: With a holding period of | F33: =Holding_Period -> 2
B34: Market Price | C34: =Market_Price -> 2.96 | D34: =Market_currency -> HKD | E34: Implied Annual Return | F34: =RATE(Holding_Period,$C$33,-C34,$C$36) -> 0.09008407
B35: No-g Model Value per share | C35: =DCF!C11 -> 2.99196 | D35: =Market_currency -> HKD | E35: Implied Annual Return | F35: =RATE(Holding_Period,$C$33,-C35,$C$36) -> 0.084099464
B36: g Model Value per share | C36: =E22*G22+E23*G23+E24*G24+E30*G30+E29*G29 -> 3.1845771 | D36: =Market_currency -> HKD | E36: is assumed to be the | F36: Expected Value
B38: Stage II Normalized Values
B39: =IF(DCF!F14="II","2","1")&"-stage DCF" -> 1-stage DCF | E39: Note on Manual Adjustments
B40: Contribution Margin_II | C40: =DCF!C17 -> 0.24487457 | E40: Try obtain this number by reverse engineering.
B41: High Growth Rate_II | C41: =DCF!C16 -> 0.018613012
B43: Growth Classification
B44: Equity Value Driving Factors | E44: Note on Manual Adjustments
B45: High Growth Period (HGP) | C45: =C18 -> 5 | E45: Use general Scenarios' HGP assumption
B46: High Growth Rate (HGR) | C46: 0.018613012 | E46: Use Excel Goal Seek to find the HGR
B47: Equity Value per share | C47: =DCF!I18 -> 3.1848543 | D47: =Market_currency -> HKD | E47: Set to Expected Equity Value
B49: Type of Company | E49: Note on the logic
B50: Negative Growth | C50: =IF(C36<C35,"Y","N") -> N
...

Sheet 投资主题
A2: 执行摘要
E3: 更新日期: | F3: =Thesis!F3 -> 45930
B4: 公司： | C4: =Thesis!C4 -> 福寿园 | E4: 组合: | F4: =Thesis!F4 -> INT
B5: 股票代码： | C5: =Thesis!C5 -> 1448.HK | E5: 精选: | F5: =Thesis!F5 -> N
B6: 对比板块: | C6: =Thesis!C6 -> CNS_01
B7: 市价货币： | C7: =Market_currency -> HKD
B8: 市场价格： | C8: =Market_Price -> 2.96 | D8: 隐含年回报率: | E8: =Scenarios!F34 -> 0.09008407
B9: 股份数量： | C9: =Common_Shares -> 2319863422
B10: 市值： | C10: =投资主题!C8*Common_Shares/1000000 -> 6866.7957
B12: 指导说明：该模型使用结构化的投资流程来评估公司，确定其内在价值和目标价格。它关注可持续的自由现金流（FCF）能力，调整财务结构，纳入增长情景，并根据得出的内在价值计算预期回报。
B14: 估值概述
B15: 商业模式风险溢价: | C15: =Thesis!C15 -> N | D15: 外汇符号： | E15: =IF(E17=C7,C7,E17&"/"&C7) -> CNY/HKD
B16: 管理风险溢价: | C16: =Thesis!C16 -> N | D16: 汇率： | E16: =Exchange_Rate -> 1.0934132
B17: 永续增长率 (g) = | C17: =Terminal_Growth -> 0 | D17: 报告货币: | E17: =Reporting_currency -> CNY
B18: ="预期股权价值 ("&C7&") :" -> 预期股权价值 (HKD) : | C18: =C125 -> 3.1845771 | D18: 报告间隔： | E18: =Thesis!E18 -> 6
B19: 增长分类: | C19: =IF(Scenarios!C50="Y",Scenarios!B50,"")&IF(Scenarios!C51="Y",Scenarios!B51,"")&IF(Scenarios!C52="Y",Scenarios!B52,"")&" "&IF(Scenarios!C53="Y",Scenarios!B53,"") -> Low Growth | D19: 下次更新日期： | E19: =EOMONTH(EDATE(BS!C1,E18+2),0) -> 46081
B21: 投资决策 | C21: =C138&" ("&Market_currency&")" -> (HKD) | D21: 持有期 | E21: =Holding_Period -> 2
B22: 目标价格 | C22: =E140 -> 1.9526459 | D22: @目标回报率 | E22: =Thesis!E22 -> 0.35
B23: 入场价格 | C23: =E141 -> 2.2673774 | D23: @入场收益率 | E23: =Thesis!E23 -> 0.25
B24: 退出价格 | C24: =E144 -> 2.8205317 | D24: @基准收益率 | E24: =Thesis!E24 -> 0.1174
B25: 卖出价格 | C25: =E145 -> 3.0554228 | D25: @基础Equity Cost | E25: =Thesis!E25 -> 0.0725
A27: 步骤1：确定公司可持续盈利能力（计算标准化FCFE）
B29: 目标：量化业务持续生成的潜在自由现金流（FCFE），去除临时波动或会计选择的影响。
B30: FCFE = (Normalized Operating EBIT + Depreciation & Amortization – Capital Expenditures) + Stable Non-Operating EBIT + Net Interest Income – Taxes – NCI’s Share of Profits – Working Capital Investment
B32: 关键组成部分 | C32: =scaling_factor -> 1000
B33: • Normalized Operating EBIT：核心业务运营的税前息前利润，调整以剔除一次性或非经常性项目，形成可持续盈利基础。
B34: Normalized Operating EBIT = | C34: =Normalized_FCF!C8 -> 611412.7 | D34: =Reporting_currency -> CNY
B36: • Depreciation & Amortization (D&A): 非现金费用，加入以反映运营产生的现金。 • Capital Expenditures (Capex): 维持或扩展运营资产所需的现金流出。
B37: D&A = | C37: =Normalized_FCF!C15 -> 173179 | D37: =Reporting_currency -> CNY
B38: Capex = | C38: =Normalized_FCF!C16 -> -173179 | D38: =Reporting_currency -> CNY
B40: • Stable Non-Operating EBIT: 来自非核心资产的持续收益，如固定收益投资、支付股息的股票或租赁物业。
B41: Stable Non-Operating EBIT = | C41: =Normalized_FCF!C9 -> -2798 | D41: =Reporting_currency -> CNY
B43: • Net Interest Income: 利息收入减去利息支出
B44: Operating Interest Income = | C44: =Normalized_FCF!C46 -> 3636.4451 | D44: =Reporting_currency -> CNY
B45: Interest Expense = | C45: =Normalized_FCF!C45 -> -8088.24 | D45: =Reporting_currency -> CNY
B46: Net Interest Income = | C46: =Normalized_FCF!C10 -> -4451.7949 | D46: =Reporting_currency -> CNY
B48: • NCI’s Share of Profits: NCI代表子公司中母公司未拥有的股权部分。
B49: Est. NCI’s Share of Profits = | C49: =Normalized_FCF!C13 -> -106049.45 | D49: =Reporting_currency -> CNY
B51: • Taxes: Tax = (Normalized Operating EBIT + Stable Non-Operating EBIT + Interest Income – Interest Expense) × Tax Rate
B52: Taxes = | C52: =Normalized_FCF!C12 -> -151040.73 | D52: =Reporting_currency -> CNY
...

Sheet Breakdown
B2: Divisional Analysis (Optional)
