Workbook
Name Common_Shares: Thesis!$C$6
Name dividend_tax_rate: Normalized_FCF!$C$93
Name Equity_Cost: Thesis!$C$86
Name Exchange_Rate: Thesis!$C$16
Name Market_currency: Thesis!$C$13
Name Market_Price: Thesis!$C$12
Name Reporting_currency: Thesis!$C$25
Name scaling_factor: Data!$C$3
Name Terminal_Growth: Thesis!$C$92
Name valuation_method: Thesis!$E$21

Sheet Thesis
B1: Model last updated: | C1: 45780 | D1: CN | E1: Selected: | F1: Y
A2: Executive Summary
B4: Company Information
B5: Company Name | C5: 重庆啤酒
B6: Number of Shares: | C6: 483971198
B7: Report Interval: | C7: 6
B8: Update Required After: | C8: =EOMONTH(EDATE(BS!C1,C7+2),0) -> 45900
B10: Listing Information
B11: Symbol: | C11: 600132.SS
B12: Market Price: | C12: 55.15
B13: Market Currency | C13: CNY
B14: Capitalization: | C14: =Thesis!C12*Common_Shares/1000000 -> 26691.012 | D14: =IF(D11="","",Thesis!D12*Common_Shares/1000000)
B15: Forex Symbol: | C15: =IF(C25=C13,C13,C25&"/"&C13) -> CNY | D15: =IF(D11="","",IF(C25=D13,D13,C25&"/"&D13))
B16: Exchange Rate: | C16: 1
B18: Guidance Note: This model determines a target buy price consistent with defined investment criteria. It follows a logical progression: establishing current sustainable earnings, adjusting for financial structure, incorporating growth scenarios, and finally applying the investor’s required return.
B20: Valuation Overview
B21: Growth Classification: | C21: =IF(Scenarios!C69="Y",Scenarios!B69,"")&IF(Scenarios!C70="Y",Scenarios!B70,"")&IF(Scenarios!C71="Y",Scenarios!B71,"")&" "&IF(Scenarios!C72="Y",Scenarios!B72,"") -> Low Growth | D21: Valuation Method | E21: DCF
B22: Comp_Sector: | C22: CNS_03 | D22: =IF(valuation_method="DDM","DDM Terminal Value","")
B23: Business Model Risk Premium: | C23: N
B24: Management Risk Premium: | C24: N
B25: Reporting Currency: | C25: CNY | D25: =IF(D11="","",Market_currency&"/"&D13&":") | E25: =IF(D11="","",1/Exchange_Rate*D16)
B26: ="Expected Equity Value ("&C13&") :" -> Expected Equity Value (CNY) : | C26: =C132 -> 82.720031 | D26: Market Implied Annual Return: | E26: =Scenarios!C87 -> 0.17920704
B28: Valuation Outputs | C28: =C145&" ("&Market_currency&")" -> 600132.SS (CNY) | D28: =IF(D11="","",D145&" ("&D13&")") | E28: Holding Period | F28: 3
B29: Target Price | C29: =C149 -> 38.33886 | D29: =D149 | E29: Target return | F29: 0.337
B30: Entry Price | C30: =C157 -> 54.104774 | D30: =D157 | E30: Entry yield | F30: 0.187
B31: Sell Price | C31: =C165 -> 75.227039 | D31: =D165 | E31: Base equity cost | F31: 0.06
B32: Exit Price | C32: =C173 -> 69.902329 | D32: =D173 | E32: Benchmark yield | F32: 0.087
A34: Step 1: Establishing the Company’s Sustainable Earning Power (Calculating Normalized FCFE)
B36: Goal: To quantify the underlying FCFE the business consistently generates for its equity owners, stripping away temporary fluctuations or accounting choices.The FCFE/Market Cap yield gives a direct measure of this cash generation relative to the current market price.
B37: FCFE = (Normalized Operating EBIT + Depreciation & Amortization – Capital Expenditures) + Stable Non-Operating EBIT + Net Interest Income – Taxes – NCI’s Share of Profits – Working Capital Investment
B39: Key Components | C39: =scaling_factor -> 1
B40: • Normalized Operating EBIT: Earnings before interest and taxes from core business operations, adjusted to remove one-time or irregular items for a sustainable earnings base.
B41: Normalized Operating EBIT = | C41: =Normalized_FCF!C8 -> 2.9577151e+09 | D41: =Reporting_currency -> CNY
B43: • Depreciation & Amortization (D&A): Non-cash expenses added back to reflect cash generated from operations. • Capital Expenditures (Capex): Cash outflows required to maintain or expand operational assets
B44: D&A = | C44: =Normalized_FCF!C9 -> 575917865 | D44: =Reporting_currency -> CNY
B45: Capex = | C45: =Normalized_FCF!C10 -> -575917865 | D45: =Reporting_currency -> CNY
B47: • Stable Non-Operating EBIT: Consistent earnings from non-core assets, such as fixed-income investments, dividend-paying stocks, or rental properties.
B48: Stable Non-Operating EBIT = | C48: =Normalized_FCF!C11 -> 0 | D48: =Reporting_currency -> CNY
B50: • Net Interest Income: Interest income minus interest expense
B51: Operating Interest Income = | C51: =Normalized_FCF!C48 -> 39079015 | D51: =Reporting_currency -> CNY
...

Sheet Data
B1: =Thesis!C25 -> CNY | C1: 45657 | D1: =EOMONTH(EDATE(C1,-12),0) -> 45291 | E1: =EOMONTH(EDATE(D1,-12),0) -> 44926 | F1: =EOMONTH(EDATE(E1,-12),0) -> 44561 | G1: =EOMONTH(EDATE(F1,-12),0) -> 44196 | H1: =EOMONTH(EDATE(G1,-12),0) -> 43830 | I1: =EOMONTH(EDATE(H1,-12),0) -> 43465 | J1: =EOMONTH(EDATE(I1,-12),0) -> 43100 | K1: =EOMONTH(EDATE(J1,-12),0) -> 42735 | ... M1: =EOMONTH(EDATE(L1,-12),0) -> 42004
B2: Data (Dirty)
B3: Income Statement | C3: 1
B4: Sales | C4: 14644597842 | D4: 14814836410 | E4: 14039040539 | F4: 13119310688 | G4: 10941631163 | H4: 3581923735 | I4: 3467335930 | J4: 3175519522 | K4: 3195921516 | L4: 3323745278
B5: COGS | C5: 8483123346 | D5: 8491525016 | E5: 7873287284 | F5: 7328418046 | G5: 6166079008 | H5: 2359127300 | I5: 2362728713 | J5: 2190920673 | K5: 2209433704 | L5: 2369740058
B6: OPEX | C6: =516942154+C7 -> 3029595871 | D6: =494670738+D7 -> 3027292571 | E6: =534570349+E7 -> 2860787576 | F6: =516877145+F7 -> 2729771806 | G6: =684104925+G7 -> 2988418106 | H6: =161996928+H7 -> 654203552 | I6: =153940810+I7 -> 609225228 | J6: =155718230+J7 -> 620936767 | K6: =183628555+K7 -> 629182097 | L6: =232657686+L7 -> 722526234
B7: Incl. Selling Expenses | C7: 2512653717 | D7: 2532621833 | E7: 2326217227 | F7: 2212894661 | G7: 2304313181 | H7: 492206624 | I7: 455284418 | J7: 465218537 | K7: 445553542 | L7: 489868548
B8: R&D | C8: 22666046 | D8: 26232056 | E8: 110747936 | F8: 163151285 | G8: 84212617 | H8: 0 | I8: 0
B9: Share of JV or associate Results
B10: Dividend or Interests from FA
B11: Investment property
B12: Interest Expense | C12: 7672861 | D12: 5921669 | E12: 3696844 | F12: 14186775 | G12: 35823675 | H12: 10770646 | I12: 12333775
B13: Interest Income | C13: 41044772 | D13: 71308016 | E13: 65718589 | F13: 36050786 | G13: 44443082 | H13: 8582394 | I13: 6609967
B14: Income Tax Paid | C14: 670547120 | D14: 664121997 | E14: 711879179 | F14: 541923819 | G14: 378467716 | H14: 98780687 | I14: 61018006 | J14: 18873927 | K14: 16833271 | L14: 42979625
B15: Reported Net Income | C15: 2249380492 | D15: 2711568555 | E15: 2586899641 | F15: 2399156196 | G15: 1752317096 | H15: 728536930 | I15: 421259471 | J15: 326122335 | K15: 139941169 | L15: -153552021
B16: Non-controling Interests | C16: 146792828
B18: Cash Flow Statement
B19: D&A | C19: 575917865 | D19: 514817738 | E19: 504410326 | F19: 451827434 | G19: 413794059 | H19: 174070610 | I19: 173632673
B20: CAPX
B21: WCInv
B22: CFO | C22: 2542046725 | D22: 3096948817 | E22: 3752648259 | F22: 3564787113 | G22: 3689730876 | H22: 705779861 | I22: 744379875 | J22: 820031927 | K22: 569431362 | L22: 448312451
B23: CFI | C23: -633430356 | D23: -1050978857 | E23: -388086486 | F23: -1151748524 | G23: -2804885087 | H23: -22429423 | I23: -17918687 | J23: 6460189 | K23: -71411814 | L23: -100881139
B24: CFF | C24: -3527746522 | D24: -2742702995 | E24: -2133485949 | F24: -2013680615 | G24: -587625771 | H24: -398002277 | I24: -448634809 | J24: -405497889 | K24: -449187720 | L24: -252880739
B25: ="Dividend per share ("&Market_currency&")" -> Dividend per share (CNY) | C25: =(9+15)/10 -> 2.4
B27: Balance Sheet | C27: Latest Asset Value
B28: ST AR | C28: =BS!C4 -> 91009310 | D28: 64628136 | E28: 65511539 | F28: 109244674 | G28: 114510542 | H28: 58261577 | I28: 67050347 | J28: 26764864 | K28: 51244805 | L28: 61946543
B29: ST Inventory | C29: =BS!C6 -> 2.1858356e+09 | D29: 2100354952 | E29: 2166477563 | F29: 1886751987 | G29: 1420570476 | H29: 364381375 | I29: 336913911 | J29: 631313453 | K29: 825981328 | L29: 1074501976
B30: Total Liabilities | C30: =BS!C33+BS!C42 -> 8.5146816e+09 | D30: 8734763046 | E30: 8874519390 | F30: 8404513904 | G30: 8026536570 | H30: 2003002194 | I30: 2135750535 | J30: 2340923121 | K30: 2123382866 | L30: 2502070463
B31: Total Equity | C31: =BS!G27 -> 2.4536581e+09 | D31: 3652148548 | E31: 3623022779 | F31: 3128295240 | G31: 1568836504 | H31: 1511351330 | I31: 1161882585 | J31: 1165260073 | K31: 1242276954 | L31: 1219123567
B32: Non-common Interest | C32: =BS!G28 -> 1.2684378e+09 | D32: 1511947928 | E32: 1566866997 | F32: 1373750136 | G32: 983547315 | H32: 92634421 | I32: 16868025 | J32: 1596604 | K32: 12325253 | L32: 77762305
B34: IS & CF Statements (Clean)
B35: Income Statement
B36: Sales | C36: =IF(C$4="","",C4) -> 14644597842 | D36: =IF(D$4="","",D4) -> 14814836410 | E36: =IF(E$4="","",E4) -> 14039040539 | F36: =IF(F$4="","",F4) -> 13119310688 | G36: =IF(G$4="","",G4) -> 10941631163 | H36: =IF(H$4="","",H4) -> 3581923735 | I36: =IF(I$4="","",I4) -> 3467335930 | J36: =IF(J$4="","",J4) -> 3175519522 | ... M36: =IF(M$4="","",M4)
B37: COGS | C37: =IF(C$4="","",-C5) -> -8483123346 | D37: =IF(D$4="","",-D5) -> -8491525016 | E37: =IF(E$4="","",-E5) -> -7873287284 | F37: =IF(F$4="","",-F5) -> -7328418046 | G37: =IF(G$4="","",-G5) -> -6166079008 | H37: =IF(H$4="","",-H5) -> -2359127300 | I37: =IF(I$4="","",-I5) -> -2362728713 | J37: =IF(J$4="","",-J5) -> -2190920673 | ... M37: =IF(M$4="","",-M5)
B38: Gross Margin | C38: =IF(C36="","",C36+C37) -> 6161474496 | D38: =IF(D36="","",D36+D37) -> 6323311394 | E38: =IF(E36="","",E36+E37) -> 6165753255 | F38: =IF(F36="","",F36+F37) -> 5790892642 | G38: =IF(G36="","",G36+G37) -> 4775552155 | H38: =IF(H36="","",H36+H37) -> 1222796435 | I38: =IF(I36="","",I36+I37) -> 1104607217 | J38: =IF(J36="","",J36+J37) -> 984598849 | ... M38: =IF(M36="","",M36+M37)
B39: OPEX | C39: =IF(C$4="","",-C6) -> -3029595871 | D39: =IF(D$4="","",-D6) -> -3027292571 | E39: =IF(E$4="","",-E6) -> -2860787576 | F39: =IF(F$4="","",-F6) -> -2729771806 | G39: =IF(G$4="","",-G6) -> -2988418106 | H39: =IF(H$4="","",-H6) -> -654203552 | I39: =IF(I$4="","",-I6) -> -609225228 | J39: =IF(J$4="","",-J6) -> -620936767 | ... M39: =IF(M$4="","",-M6)
B40: Incl. Selling Expenses | C40: =IF(C$4="","",-C7) -> -2512653717 | D40: =IF(D$4="","",-D7) -> -2532621833 | E40: =IF(E$4="","",-E7) -> -2326217227 | F40: =IF(F$4="","",-F7) -> -2212894661 | G40: =IF(G$4="","",-G7) -> -2304313181 | H40: =IF(H$4="","",-H7) -> -492206624 | I40: =IF(I$4="","",-I7) -> -455284418 | J40: =IF(J$4="","",-J7) -> -465218537 | ... M40: =IF(M$4="","",-M7)
B41: Incl. Other Opex | C41: =IF(C$4="","",C39-C40) -> -516942154 | D41: =IF(D$4="","",D39-D40) -> -494670738 | E41: =IF(E$4="","",E39-E40) -> -534570349 | F41: =IF(F$4="","",F39-F40) -> -516877145 | G41: =IF(G$4="","",G39-G40) -> -684104925 | H41: =IF(H$4="","",H39-H40) -> -161996928 | I41: =IF(I$4="","",I39-I40) -> -153940810 | J41: =IF(J$4="","",J39-J40) -> -155718230 | ... M41: =IF(M$4="","",M39-M40)
B42: R&D | C42: =IF(C$4="","",-C8) -> -22666046 | D42: =IF(D$4="","",-D8) -> -26232056 | E42: =IF(E$4="","",-E8) -> -110747936 | F42: =IF(F$4="","",-F8) -> -163151285 | G42: =IF(G$4="","",-G8) -> -84212617 | H42: =IF(H$4="","",-H8) -> 0 | I42: =IF(I$4="","",-I8) -> 0 | J42: =IF(J$4="","",-J8) -> 0 | ... M42: =IF(M$4="","",-M8)
B43: Operating EBIT | C43: =IF(C$4="","",C38+C39+C42) -> 3109212579 | D43: =IF(D$4="","",D38+D39+D42) -> 3269786767 | E43: =IF(E$4="","",E38+E39+E42) -> 3194217743 | F43: =IF(F$4="","",F38+F39+F42) -> 2897969551 | G43: =IF(G$4="","",G38+G39+G42) -> 1702921432 | H43: =IF(H$4="","",H38+H39+H42) -> 568592883 | I43: =IF(I$4="","",I38+I39+I42) -> 495381989 | J43: =IF(J$4="","",J38+J39+J42) -> 363662082 | ... M43: =IF(M$4="","",M38+M39+M42)
...

Sheet BS
B1: Most Recent Quarter | C1: 45657 | F1: =IF(MONTH(C1)=MONTH(Normalized_FCF!G1),"FY","Quarter")&" Report" -> FY Report | H1: =scaling_factor -> 1
B2: Lastest Balance Sheet
B3: ST Operating Assets | C3: Book | D3: Valued @ | F3: ST Non-Operating Assets | G3: Book | H3: Valued @
B4: ST AR | C4: =63423634.85+27585675 -> 91009310 | D4: 0.6 | F4: Cash and cash equivalents | G4: 1.0816591e+09 | H4: 0.9
B5: Operating ST Financial Assets | C5: 0 | D5: 0.6 | F5: Restricted cash | G5: 0 | H5: 0.7
B6: Inventory | C6: 2.1858356e+09 | D6: 0.5 | F6: Securities with stable income | G6: 0 | H6: 0.6
B7: Properties held for sale | C7: 0 | D7: 0.6 | F7: Other Securities | G7: 22482126 | H7: 0.6
B8: Properties held for income | C8: 0 | D8: 0.6 | F8: Properties with stable income | G8: 0 | H8: 0.6
B9: Prepayments and Contract Assets | C9: 28013000 | D9: 0.1 | F9: Other Properties | G9: 0 | H9: 0.6
B10: ST DTA | C10: 0 | D10: 0.9
B11: Other ST Assets | C11: 2.7003836e+08 | D11: 0.05
B12: Operating ST Assets | C12: =SUM(C4:C11) -> 2.5748963e+09 | D12: =C4*D4+C5*D5+C9*D9+C6*D6+C8*D8+C7*D7+C10*D10+C11*D11 -> 1.1638266e+09 | F12: Non-Operating ST Assets | G12: =SUM(G4:G9) -> 1.1041412e+09 | H12: =G4*H4+G5*H5+G6*H6+G7*H7+G8*H8+G9*H9 -> 9.8698244e+08
B14: LT Operating Assets | C14: Book | D14: Valued @ | F14: LT Non-Operating Assets | G14: Book | H14: Valued @
B15: LT AR and Prepayments | C15: 0 | D15: 0.4 | F15: LT Depositis | G15: 0 | H15: 0.8
B16: Operating LT Financial Assets | C16: 0 | D16: 0.5 | F16: Securities with stable income | G16: 0 | H16: 0.6
B17: Properties held for sale | C17: 0 | D17: 0.6 | F17: Other Securities | G17: 0 | H17: 0.6
B18: Properties held for income | C18: 0 | D18: 0.6 | F18: JV or associate with stable income | G18: 0 | H18: 0.1
B19: PP&E & Right of Use Assets | C19: =4755026247.47+159772560.73+160044048.75 -> 5.0748429e+09 | D19: 0.1 | F19: Other JV or associate | G19: =142861296.29+17825955.91 -> 1.6068725e+08 | H19: 0.1
B20: Biological assets | C20: 0 | D20: 0.05 | F20: Properties with stable income | G20: 0 | H20: 0.2
B21: Intangible assets | C21: 6.506348e+08 | D21: 0.05 | F21: Other Properties | G21: 0 | H21: 0.1
B22: LT DTA | C22: 7.0346537e+08 | D22: 0.9
B23: Other assets & Goodwill | C23: =699192456.06+479496.08 -> 6.9967195e+08 | D23: 0
B24: Operating LT Assets | C24: =SUM(C15:C23) -> 7.128615e+09 | D24: =C15*D15+C16*D16+C18*D18+C17*D17+C19*D19+C20*D20+C21*D21+C22*D22+C23*D23 -> 1.1731349e+09 | F24: Non-Operating LT Assets | G24: =SUM(G15:G21) -> 1.6068725e+08 | H24: =G15*H15+G16*H16+G17*H17+G18*H18+G19*H19+G20*H20+G21*H21 -> 16068725
B26: ST Liabilities | C26: Book | F26: BS Summary | G26: Book | H26: Valued @
B27: ST Borrowing | C27: 0 | F27: Total Equity | G27: =G32-G30 -> 2.4536581e+09 | H27: =H32-G30 -> -5.174669e+09
B28: ST Lease liabilities | C28: 0 | F28: Incl. Minority Interest (NCI) | G28: 1.2684378e+09
B29: ST SH Loan | C29: 0 | F29: Incl. Common Equity | G29: =G27-G28 -> 1.1852203e+09 | H29: =H27-G28 -> -6.4431068e+09
B30: ST Financial Liabilities | C30: 897606.82 | F30: Total Liabilities | G30: =C33+C42 -> 8.5146816e+09
B31: ST Interest-bearing Debt | C31: =SUM(C27:C30) -> 897606.82 | F31: incl. Interest-bearing Debt | G31: =C31+C40 -> 1.235217e+08
B32: Other ST liabilities | C32: =C33-C31 -> 7.7384123e+09 | F32: Total Assets | G32: =G35+G40 -> 1.096834e+10 | H32: =H35+H40 -> 3.3400126e+09
B33: Current Liabilities | C33: 7.7393099e+09
F34: Assets Summary | G34: Book | H34: Valued @
B35: LT Liabilities | C35: Book | F35: Operating Assets | G35: =C12+C24 -> 9.7035113e+09 | H35: =D12+D24 -> 2.3369615e+09
B36: LT Borrowing | C36: 0 | F36: incl. AR | G36: =C4+C15 -> 91009310
B37: LT Lease liabilities | C37: 1.226241e+08 | F37: incl. inventory | G37: =C6 -> 2.1858356e+09
B38: LT SH Loan | C38: 0 | F38: incl. Properties held for sale | G38: =C7+C17 -> 0
B39: LT Financial Liabilities | C39: 0 | F39: incl. Fixed Assets | G39: =C7+C17+C19+C20 -> 5.0748429e+09 | H39: =C7*D7+C17*D17+C19*D19+C20*D20 -> 5.0748429e+08
B40: LT Interest-bearing Debt | C40: =SUM(C36:C39) -> 1.226241e+08 | F40: Non-operating Assets | G40: =G12+G24 -> 1.2648285e+09 | H40: =H12+H24 -> 1.0030512e+09
B41: Other LT liabilities | C41: =C42-C40 -> 6.5274758e+08 | F41: incl. Assets with stable income | G41: =C70 -> 1.0816591e+09 | H41: =H40-H42 -> 9.7349317e+08
B42: Noncurrent Liabilities | C42: 7.7537168e+08 | F42: incl. Other Assets | G42: =C82 -> 1.8316938e+08 | H42: =D82 -> 29558001
...

Sheet Normalized_FCF
B1: =Thesis!C25 -> CNY | C1: Normalized | G1: =Data!C1 -> 45657 | H1: =EOMONTH(EDATE(G1,-12),0) -> 45291 | I1: =EOMONTH(EDATE(H1,-12),0) -> 44926 | J1: =EOMONTH(EDATE(I1,-12),0) -> 44561 | K1: =EOMONTH(EDATE(J1,-12),0) -> 44196 | L1: =EOMONTH(EDATE(K1,-12),0) -> 43830 | M1: =EOMONTH(EDATE(L1,-12),0) -> 43465 | N1: =EOMONTH(EDATE(M1,-12),0) -> 43100 | O1: =EOMONTH(EDATE(N1,-12),0) -> 42735 | ... Q1: =EOMONTH(EDATE(P1,-12),0) -> 42004
B2: FCFE Analysis | E2: Notes
B3: FCFE | C3: =scaling_factor -> 1
B4: Sales | C4: =AVERAGE(G4:J4) -> 1.4154446e+10 | G4: =Data!C36 -> 14644597842 | H4: =Data!D36 -> 14814836410 | I4: =Data!E36 -> 14039040539 | J4: =Data!F36 -> 13119310688 | K4: =Data!G36 -> 10941631163 | L4: =Data!H36 -> 3581923735 | M4: =Data!I36 -> 3467335930 | N4: =Data!J36 -> 3175519522 | ... Q4: =Data!M36
B5: Variable Costs | C5: =C25 -> -1.0627751e+10 | G5: =G25 -> -10995777063 | H5: =H25 -> -11024146849 | I5: =I25 -> -10199504511 | J5: =J25 -> -9541312707 | K5: =K25 -> -8470392189 | L5: =L25 -> -2851333924 | M5: =M25 -> -2818013131 | N5: =N25 -> -2656139210 | ... Q5: =Q25
B6: Contribution Margin | C6: =C4+C5 -> 3.5266955e+09 | G6: =IF(G4="","",G4+G5) -> 3648820779 | H6: =IF(H4="","",H4+H5) -> 3790689561 | I6: =IF(I4="","",I4+I5) -> 3839536028 | J6: =IF(J4="","",J4+J5) -> 3577997981 | K6: =IF(K4="","",K4+K5) -> 2471238974 | L6: =IF(L4="","",L4+L5) -> 730589811 | M6: =IF(M4="","",M4+M5) -> 649322799 | N6: =IF(N4="","",N4+N5) -> 519380312 | ... Q6: =IF(Q4="","",Q4+Q5)
B7: Fixed Costs | C7: =C35 -> -5.6898044e+08 | G7: =G35 -> -539608200 | H7: =H35 -> -520902794 | I7: =I35 -> -645318285 | J7: =J35 -> -680028430 | K7: =K35 -> -768317542 | L7: =L35 -> -161996928 | M7: =M35 -> -153940810 | N7: =N35 -> -155718230 | ... Q7: =Q35
B8: Operating EBIT | C8: =C6+C7 -> 2.9577151e+09 | G8: =IF(G$4="","",G6+G7) -> 3109212579 | H8: =IF(H$4="","",H6+H7) -> 3269786767 | I8: =IF(I$4="","",I6+I7) -> 3194217743 | J8: =IF(J$4="","",J6+J7) -> 2897969551 | K8: =IF(K$4="","",K6+K7) -> 1702921432 | L8: =IF(L$4="","",L6+L7) -> 568592883 | M8: =IF(M$4="","",M6+M7) -> 495381989 | N8: =IF(N$4="","",N6+N7) -> 363662082 | ... Q8: =IF(Q$4="","",Q6+Q7)
B9: Add Back D&A | C9: =BS!$G$39*BS!D58 -> 575917865 | G9: =IF(Data!C61="","",-Data!C61) -> 575917865 | H9: =IF(Data!D61="","",-Data!D61) -> 514817738 | I9: =IF(Data!E61="","",-Data!E61) -> 504410326 | J9: =IF(Data!F61="","",-Data!F61) -> 451827434 | K9: =IF(Data!G61="","",-Data!G61) -> 413794059 | L9: =IF(Data!H61="","",-Data!H61) -> 174070610 | M9: =IF(Data!I61="","",-Data!I61) -> 173632673 | N9: =IF(Data!J61="","",-Data!J61) -> 0 | ... Q9: =IF(Data!M61="","",-Data!M61)
B10: Maintenance Capex | C10: =-C4*C78 -> -575917865 | G10: =Data!C62 -> -575917865 | H10: =Data!D62 -> -514817738 | I10: =Data!E62 -> -504410326 | J10: =Data!F62 -> -451827434 | K10: =Data!G62 -> -413794059 | L10: =Data!H62 -> -174070610 | M10: =Data!I62 -> -173632673 | N10: =Data!J62 -> 0 | ... Q10: =Data!M62
B11: Stable Non-Operating EBIT | C11: =C63 -> 0 | G11: =G61 -> 0 | H11: =H61 -> 0 | I11: =I61 -> 0 | J11: =J61 -> 0 | K11: =K61 -> 0 | L11: =L61 -> 0 | M11: =M61 -> 0 | N11: =N61 -> 0 | ... Q11: =Q61
B12: Net Interest Income | C12: =C50 -> 31406154 | G12: =G50 -> 31406154 | H12: =H50 -> 61971192 | I12: =I50 -> 58874285 | J12: =J50 -> 20137431 | K12: =K50 -> 6490894.6 | L12: =L50 -> -2599288.6 | M12: =M50 -> -6040379.1 | N12: =N50 -> 0 | ... Q12: =Q50
B13: Pre-tax Profit | C13: =SUM(C8:C12) -> 2.9891213e+09 | G13: =IF(G$4="","",SUM(G8:G12)) -> 3.1406187e+09 | H13: =IF(H$4="","",SUM(H8:H12)) -> 3.331758e+09 | I13: =IF(I$4="","",SUM(I8:I12)) -> 3.253092e+09 | J13: =IF(J$4="","",SUM(J8:J12)) -> 2.918107e+09 | K13: =IF(K$4="","",SUM(K8:K12)) -> 1.7094123e+09 | L13: =IF(L$4="","",SUM(L8:L12)) -> 5.6599359e+08 | M13: =IF(M$4="","",SUM(M8:M12)) -> 4.8934161e+08 | N13: =IF(N$4="","",SUM(N8:N12)) -> 363662082 | ... Q13: =IF(Q$4="","",SUM(Q8:Q12))
B14: Income Tax | C14: =-SUM(C8+C11,C12)*C43 -> -7.4728032e+08 | G14: =Data!C46 -> -670547120 | H14: =Data!D46 -> -664121997 | I14: =Data!E46 -> -711879179 | J14: =Data!F46 -> -541923819 | K14: =Data!G46 -> -378467716 | L14: =Data!H46 -> -98780687 | M14: =Data!I46 -> -61018006 | N14: =Data!J46 -> -18873927 | ... Q14: =Data!M46
B15: NCI’s Share of Profits | C15: =-C4*C83 -> -1.418797e+08 | G15: =Data!C48 -> -146792828 | H15: =Data!D48 -> 0 | I15: =Data!E48 -> 0 | J15: =Data!F48 -> 0 | K15: =Data!G48 -> 0 | L15: =Data!H48 -> 0 | M15: =Data!I48 -> 0 | N15: =Data!J48 -> 0 | ... Q15: =Data!M48
B16: After-tax Profit | C16: =SUM(C13:C15) -> 2.0999612e+09 | G16: =IF(G$4="","",SUM(G13:G15)) -> 2.3232788e+09 | H16: =IF(H$4="","",SUM(H13:H15)) -> 2.667636e+09 | I16: =IF(I$4="","",SUM(I13:I15)) -> 2.5412128e+09 | J16: =IF(J$4="","",SUM(J13:J15)) -> 2.3761832e+09 | K16: =IF(K$4="","",SUM(K13:K15)) -> 1.3309446e+09 | L16: =IF(L$4="","",SUM(L13:L15)) -> 4.6721291e+08 | M16: =IF(M$4="","",SUM(M13:M15)) -> 4.283236e+08 | N16: =IF(N$4="","",SUM(N13:N15)) -> 344788155 | ... Q16: =IF(Q$4="","",SUM(Q13:Q15))
B17: WCInv | C17: =-C4*C85 -> 0 | E17: WCInv is by default excluded
B18: Net Borrowing | C18: 0 | E18: Net borrowing is excluded
B19: FCFE | C19: =C16+C17 -> 2.0999612e+09 | G19: =IF(G$4="","",G16+G17) -> 2.3232788e+09 | H19: =IF(H$4="","",H16+H17) -> 2.667636e+09 | I19: =IF(I$4="","",I16+I17) -> 2.5412128e+09 | J19: =IF(J$4="","",J16+J17) -> 2.3761832e+09 | K19: =IF(K$4="","",K16+K17) -> 1.3309446e+09 | L19: =IF(L$4="","",L16+L17) -> 4.6721291e+08 | M19: =IF(M$4="","",M16+M17) -> 4.283236e+08 | N19: =IF(N$4="","",N16+N17) -> 344788155 | ... Q19: =IF(Q$4="","",Q16+Q17)
B21: Operating Cost Structure | E21: Notes
B22: Variable Costs
B23: COGS | C23: =-C4*C28 -> -8.1991951e+09 | G23: =Data!C37 -> -8483123346 | H23: =Data!D37 -> -8491525016 | I23: =Data!E37 -> -7873287284 | J23: =Data!F37 -> -7328418046 | K23: =Data!G37 -> -6166079008 | L23: =Data!H37 -> -2359127300 | M23: =Data!I37 -> -2362728713 | N23: =Data!J37 -> -2190920673 | ... Q23: =Data!M37
B24: Selling Expenses | C24: =-C4*C29 -> -2.4285557e+09 | G24: =Data!C40 -> -2512653717 | H24: =Data!D40 -> -2532621833 | I24: =Data!E40 -> -2326217227 | J24: =Data!F40 -> -2212894661 | K24: =Data!G40 -> -2304313181 | L24: =Data!H40 -> -492206624 | M24: =Data!I40 -> -455284418 | N24: =Data!J40 -> -465218537 | ... Q24: =Data!M40
B25: Variable Costs | C25: =C23+C24 -> -1.0627751e+10 | G25: =IF(G$4="","",G23+G24) -> -10995777063 | H25: =IF(H$4="","",H23+H24) -> -11024146849 | I25: =IF(I$4="","",I23+I24) -> -10199504511 | J25: =IF(J$4="","",J23+J24) -> -9541312707 | K25: =IF(K$4="","",K23+K24) -> -8470392189 | L25: =IF(L$4="","",L23+L24) -> -2851333924 | M25: =IF(M$4="","",M23+M24) -> -2818013131 | N25: =IF(N$4="","",N23+N24) -> -2656139210 | ... Q25: =IF(Q$4="","",Q23+Q24)
B27: Variable Costs % of Sales
B28: COGS | C28: =G28 -> 0.57926639 | E28: Historical Average | G28: =IF(G$4="","",ABS(G23/G$4)) -> 0.57926639 | H28: =IF(H$4="","",ABS(H23/H$4)) -> 0.5731771 | I28: =IF(I$4="","",ABS(I23/I$4)) -> 0.56081377 | J28: =IF(J$4="","",ABS(J23/J$4)) -> 0.5585978 | K28: =IF(K$4="","",ABS(K23/K$4)) -> 0.56354294 | L28: =IF(L$4="","",ABS(L23/L$4)) -> 0.65862019 | M28: =IF(M$4="","",ABS(M23/M$4)) -> 0.68142481 | N28: =IF(N$4="","",ABS(N23/N$4)) -> 0.68994086 | ... Q28: =IF(Q$4="","",ABS(Q23/Q$4))
B29: =B24 -> Selling Expenses | C29: =G29 -> 0.17157547 | E29: Historical Average | G29: =IF(G$4="","",ABS(G24/G$4)) -> 0.17157547 | H29: =IF(H$4="","",ABS(H24/H$4)) -> 0.17095172 | I29: =IF(I$4="","",ABS(I24/I$4)) -> 0.16569631 | J29: =IF(J$4="","",ABS(J24/J$4)) -> 0.16867461 | K29: =IF(K$4="","",ABS(K24/K$4)) -> 0.21060052 | L29: =IF(L$4="","",ABS(L24/L$4)) -> 0.13741404 | M29: =IF(M$4="","",ABS(M24/M$4)) -> 0.13130669 | N29: =IF(N$4="","",ABS(N24/N$4)) -> 0.14650155 | ... Q29: =IF(Q$4="","",ABS(Q24/Q$4))
B30: Variable Costs | C30: =ABS(C25/$C$4) -> 0.75084186 | G30: =IF(G$4="","",ABS(G25/G$4)) -> 0.75084186 | H30: =IF(H$4="","",ABS(H25/H$4)) -> 0.74412883 | I30: =IF(I$4="","",ABS(I25/I$4)) -> 0.72651008 | J30: =IF(J$4="","",ABS(J25/J$4)) -> 0.72727241 | K30: =IF(K$4="","",ABS(K25/K$4)) -> 0.77414346 | L30: =IF(L$4="","",ABS(L25/L$4)) -> 0.79603424 | M30: =IF(M$4="","",ABS(M25/M$4)) -> 0.8127315 | N30: =IF(N$4="","",ABS(N25/N$4)) -> 0.83644241 | ... Q30: =IF(Q$4="","",ABS(Q25/Q$4))
B32: Fixed Costs
B33: G&A and other Opex | C33: =AVERAGE(G33:J33) -> -5.157651e+08 | E33: Historical Average | G33: =Data!C41 -> -516942154 | H33: =Data!D41 -> -494670738 | I33: =Data!E41 -> -534570349 | J33: =Data!F41 -> -516877145 | K33: =Data!G41 -> -684104925 | L33: =Data!H41 -> -161996928 | M33: =Data!I41 -> -153940810 | N33: =Data!J41 -> -155718230 | ... Q33: =Data!M41
B34: R&D | C34: =AVERAGE(G34:I34) -> -53215346 | E34: Historical Average | G34: =Data!C42 -> -22666046 | H34: =Data!D42 -> -26232056 | I34: =Data!E42 -> -110747936 | J34: =Data!F42 -> -163151285 | K34: =Data!G42 -> -84212617 | L34: =Data!H42 -> 0 | M34: =Data!I42 -> 0 | N34: =Data!J42 -> 0 | ... Q34: =Data!M42
B35: Fixed Costs | C35: =C33+C34 -> -5.6898044e+08 | G35: =IF(G4="","",G33+G34) -> -539608200 | H35: =IF(H4="","",H33+H34) -> -520902794 | I35: =IF(I4="","",I33+I34) -> -645318285 | J35: =IF(J4="","",J33+J34) -> -680028430 | K35: =IF(K4="","",K33+K34) -> -768317542 | L35: =IF(L4="","",L33+L34) -> -161996928 | M35: =IF(M4="","",M33+M34) -> -153940810 | N35: =IF(N4="","",N33+N34) -> -155718230 | ... Q35: =IF(Q4="","",Q33+Q34)
B37: Fixed Costs % of Sales
B38: =B33 -> G&A and other Opex | C38: =ABS(C33/$C$4) -> 0.03643838 | G38: =IF(G$4="","",ABS(G33/G$4)) -> 0.03529917 | H38: =IF(H$4="","",ABS(H33/H$4)) -> 0.033390226 | I38: =IF(I$4="","",ABS(I33/I$4)) -> 0.038077413 | J38: =IF(J$4="","",ABS(J33/J$4)) -> 0.039398194 | K38: =IF(K$4="","",ABS(K33/K$4)) -> 0.062523121 | L38: =IF(L$4="","",ABS(L33/L$4)) -> 0.045226236 | M38: =IF(M$4="","",ABS(M33/M$4)) -> 0.044397432 | N38: =IF(N$4="","",ABS(N33/N$4)) -> 0.049037088 | ... Q38: =IF(Q$4="","",ABS(Q33/Q$4))
B39: =B34 -> R&D | C39: =ABS(C34/$C$4) -> 0.0037596204 | G39: =IF(G$4="","",ABS(G34/G$4)) -> 0.0015477411 | H39: =IF(H$4="","",ABS(H34/H$4)) -> 0.0017706612 | I39: =IF(I$4="","",ABS(I34/I$4)) -> 0.0078885687 | J39: =IF(J$4="","",ABS(J34/J$4)) -> 0.012435965 | K39: =IF(K$4="","",ABS(K34/K$4)) -> 0.0076965322 | L39: =IF(L$4="","",ABS(L34/L$4)) -> 0 | M39: =IF(M$4="","",ABS(M34/M$4)) -> 0 | N39: =IF(N$4="","",ABS(N34/N$4)) -> 0 | ... Q39: =IF(Q$4="","",ABS(Q34/Q$4))
B40: Fixed Costs | C40: =ABS(C35/$C$4) -> 0.040198001 | G40: =IF(G$4="","",ABS(G35/G$4)) -> 0.036846911 | H40: =IF(H$4="","",ABS(H35/H$4)) -> 0.035160887 | I40: =IF(I$4="","",ABS(I35/I$4)) -> 0.045965982 | J40: =IF(J$4="","",ABS(J35/J$4)) -> 0.051834159 | K40: =IF(K$4="","",ABS(K35/K$4)) -> 0.070219653 | L40: =IF(L$4="","",ABS(L35/L$4)) -> 0.045226236 | M40: =IF(M$4="","",ABS(M35/M$4)) -> 0.044397432 | N40: =IF(N$4="","",ABS(N35/N$4)) -> 0.049037088 | ... Q40: =IF(Q$4="","",ABS(Q35/Q$4))
B42: Tax % of Pre-tax Profit
B43: Income Tax Rate | C43: 0.25 | E43: Use the highest past tax rate | G43: =IF(G$4="","",-G14/SUM(G8+G11,G12)) -> 0.21350797 | H43: =IF(H$4="","",-H14/SUM(H8+H11,H12)) -> 0.19933081 | I43: =IF(I$4="","",-I14/SUM(I8+I11,I12)) -> 0.21883155 | J43: =IF(J$4="","",-J14/SUM(J8+J11,J12)) -> 0.18571074 | K43: =IF(K$4="","",-K14/SUM(K8+K11,K12)) -> 0.22140224 | L43: =IF(L$4="","",-L14/SUM(L8+L11,L12)) -> 0.17452616 | M43: =IF(M$4="","",-M14/SUM(M8+M11,M12)) -> 0.12469409 | N43: =IF(N$4="","",-N14/SUM(N8+N11,N12)) -> 0.051899629 | ... Q43: =IF(Q$4="","",-Q14/SUM(Q8+Q11,Q12))
B45: Non-operating Income | E45: Notes
B46: Interest
...

Sheet DCF
B2: No-Growth DCF Valuation | H2: Notes
B3: No-Growth DCF | C3: =scaling_factor -> 1 | E3: Special Assumption
B4: Adjusted FCFE | C4: =Normalized_FCF!C19 -> 2.0999612e+09 | D4: =Reporting_currency -> CNY | E4: Terminal Growth Rate (g): | F4: =Terminal_Growth -> 0
B5: /Equity Cost of Capital | C5: =Equity_Cost -> 0.06
B6: Stable Income Value | C6: =(C4*(1+Terminal_Growth))/(Equity_Cost-Terminal_Growth) -> 3.4999354e+10 | D6: =Reporting_currency -> CNY | E6: Conservative Valuation: Setting g=0 can be a conservative assumption to avoid overestimating the stock’s value, especially if future growth is uncertain or unreliable.
B7: - Interest-bearing Debt | C7: =BS!G31 -> 1.235217e+08 | D7: =Reporting_currency -> CNY
B8: + Non-operating Cash | C8: =BS!D66 -> 51803896 | D8: =Reporting_currency -> CNY
B9: + Other Non-operating Assets | C9: =BS!H42 -> 29558001 | D9: =Reporting_currency -> CNY
B10: Equity Value | C10: =C6-C7+C8+C9 -> 3.4957194e+10 | D10: =Reporting_currency -> CNY
B11: * Exchange rate | C11: =Exchange_Rate -> 1 | D11: =Thesis!C15 -> CNY
B12: Equity Value per share | C12: =(C10*scaling_factor)/Common_Shares*Exchange_Rate -> 72.229906 | D12: =Market_currency -> CNY
B14: Implied Growth Scenario Analysis
B15: FCFE Projection
B16: High Growth Period (HGP) | C16: =Scenarios!C65 -> 0.046574871
B17: High Growth Rate (HGR) | C17: =Scenarios!C64 -> 10
B18: Value Per Share | C18: =(F52-C7+C8+C9)*Exchange_Rate/Common_Shares*scaling_factor -> 82.654784 | D18: =Market_currency -> CNY
B20: Year | C20: FCFE | D20: Growth Rates | E20: Discount Factor | F20: PV of FCFE
B21: 1 | C21: =C4*(1+D21) -> 2.1977667e+09 | D21: =IF($C$17<B21,0,DCF!$C$16) -> 0.046574871 | E21: =IF($C$17<B21,0,1/(1+Equity_Cost)^B21) -> 0.94339623 | F21: =C21*E21 -> 2.0733648e+09
B22: 2 | C22: =IF(ROW()-ROW($C$21)<$C$17, $C$21*(1+D22)^(ROW()-ROW($C$21)), 0) -> 2.3001274e+09 | D22: =IF($C$17<B22,0,DCF!$C$16) -> 0.046574871 | E22: =IF($C$17<B22,0,1/(1+Equity_Cost)^B22) -> 0.88999644 | F22: =C22*E22 -> 2.0471052e+09
B23: 3 | C23: =IF(ROW()-ROW($C$21)<$C$17, $C$21*(1+D23)^(ROW()-ROW($C$21)), 0) -> 2.4072555e+09 | D23: =IF($C$17<B23,0,DCF!$C$16) -> 0.046574871 | E23: =IF($C$17<B23,0,1/(1+Equity_Cost)^B23) -> 0.83961928 | F23: =C23*E23 -> 2.0211781e+09
B24: 4 | C24: =IF(ROW()-ROW($C$21)<$C$17, $C$21*(1+D24)^(ROW()-ROW($C$21)), 0) -> 2.5193731e+09 | D24: =IF($C$17<B24,0,DCF!$C$16) -> 0.046574871 | E24: =IF($C$17<B24,0,1/(1+Equity_Cost)^B24) -> 0.79209366 | F24: =C24*E24 -> 1.9955795e+09
B25: 5 | C25: =IF(ROW()-ROW($C$21)<$C$17, $C$21*(1+D25)^(ROW()-ROW($C$21)), 0) -> 2.6367126e+09 | D25: =IF($C$17<B25,0,DCF!$C$16) -> 0.046574871 | E25: =IF($C$17<B25,0,1/(1+Equity_Cost)^B25) -> 0.74725817 | F25: =C25*E25 -> 1.970305e+09
B26: 6 | C26: =IF(ROW()-ROW($C$21)<$C$17, $C$21*(1+D26)^(ROW()-ROW($C$21)), 0) -> 2.7595171e+09 | D26: =IF($C$17<B26,0,DCF!$C$16) -> 0.046574871 | E26: =IF($C$17<B26,0,1/(1+Equity_Cost)^B26) -> 0.70496054 | F26: =C26*E26 -> 1.9453507e+09
B27: 7 | C27: =IF(ROW()-ROW($C$21)<$C$17, $C$21*(1+D27)^(ROW()-ROW($C$21)), 0) -> 2.8880413e+09 | D27: =IF($C$17<B27,0,DCF!$C$16) -> 0.046574871 | E27: =IF($C$17<B27,0,1/(1+Equity_Cost)^B27) -> 0.66505711 | F27: =C27*E27 -> 1.9207124e+09
B28: 8 | C28: =IF(ROW()-ROW($C$21)<$C$17, $C$21*(1+D28)^(ROW()-ROW($C$21)), 0) -> 3.0225514e+09 | D28: =IF($C$17<B28,0,DCF!$C$16) -> 0.046574871 | E28: =IF($C$17<B28,0,1/(1+Equity_Cost)^B28) -> 0.62741237 | F28: =C28*E28 -> 1.8963862e+09
B29: 9 | C29: =IF(ROW()-ROW($C$21)<$C$17, $C$21*(1+D29)^(ROW()-ROW($C$21)), 0) -> 3.1633264e+09 | D29: =IF($C$17<B29,0,DCF!$C$16) -> 0.046574871 | E29: =IF($C$17<B29,0,1/(1+Equity_Cost)^B29) -> 0.59189846 | F29: =C29*E29 -> 1.872368e+09
B30: 10 | C30: =IF(ROW()-ROW($C$21)<$C$17, $C$21*(1+D30)^(ROW()-ROW($C$21)), 0) -> 3.3106579e+09 | D30: =IF($C$17<B30,0,DCF!$C$16) -> 0.046574871 | E30: =IF($C$17<B30,0,1/(1+Equity_Cost)^B30) -> 0.55839478 | F30: =C30*E30 -> 1.8486541e+09
B31: 11 | C31: =IF(ROW()-ROW($C$21)<$C$17, $C$21*(1+D31)^(ROW()-ROW($C$21)), 0) -> 0 | D31: =IF($C$17<B31,0,DCF!$C$16) -> 0 | E31: =IF($C$17<B31,0,1/(1+Equity_Cost)^B31) -> 0 | F31: =C31*E31 -> 0
B32: 12 | C32: =IF(ROW()-ROW($C$21)<$C$17, $C$21*(1+D32)^(ROW()-ROW($C$21)), 0) -> 0 | D32: =IF($C$17<B32,0,DCF!$C$16) -> 0 | E32: =IF($C$17<B32,0,1/(1+Equity_Cost)^B32) -> 0 | F32: =C32*E32 -> 0
B33: 13 | C33: =IF(ROW()-ROW($C$21)<$C$17, $C$21*(1+D33)^(ROW()-ROW($C$21)), 0) -> 0 | D33: =IF($C$17<B33,0,DCF!$C$16) -> 0 | E33: =IF($C$17<B33,0,1/(1+Equity_Cost)^B33) -> 0 | F33: =C33*E33 -> 0
... B50: 30 | C50: =IF(ROW()-ROW($C$21)<$C$17, $C$21*(1+D50)^(ROW()-ROW($C$21)), 0) -> 0 | D50: =IF($C$17<B50,0,DCF!$C$16) -> 0 | E50: =IF($C$17<B50,0,1/(1+Equity_Cost)^B50) -> 0 | F50: =C50*E50 -> 0
B51: Terminal Year | C51: =C$21*(1+Terminal_Growth)^$C$17/Equity_Cost -> 3.6629444e+10 | D51: =Terminal_Growth -> 0 | E51: =1/(1+Equity_Cost)^C17 -> 0.55839478 | F51: =C51*E51 -> 2.045369e+10
E52: Total PV | F52: =SUM(F21:F51) -> 4.0044694e+10
B54: Sensitivity Analysis (Enterprise Value)
A55: =F52 -> 4.0044694e+10 | B55: =C78 -> 0 | C55: =C77 -> 0.02 | D55: =C76 -> 0.04 | E55: =C75 -> 0.06 | F55: =C74 -> 0.1
A56: 5 | B56: 3.4999354e+10 | C56: 3.6045913e+10 | D56: 3.7119915e+10 | E56: 3.8222573e+10 | F56: 4.0518897e+10
A57: 10 | B57: 3.4999354e+10 | C57: 3.703359e+10 | D57: 3.9264419e+10 | E57: 4.1715676e+10 | F57: 4.7388511e+10
A58: 15 | B58: 3.4999354e+10 | C58: 3.837284e+10 | D58: 4.2327055e+10 | E58: 4.6979667e+10 | F58: 5.8973005e+10
A59: 20 | B59: 3.4999354e+10 | C59: 3.9869617e+10 | D59: 4.5943125e+10 | E59: 5.3566967e+10 | F59: 7.5393318e+10
A60: 25 | B60: 3.4999354e+10 | C60: 4.139732e+10 | D60: 4.9852155e+10 | E60: 6.1143121e+10 | F60: 9.7006894e+10
...

Sheet DDM
B2: No-Growth DDM Valuation | H2: Notes
B3: No-Growth DDM | C3: =scaling_factor -> 1 | E3: Special Assumption
B4: Dividend | C4: =Normalized_FCF!C91*(1-dividend_tax_rate) -> 1.0453778e+09 | D4: =Market_currency -> CNY | E4: Terminal Growth Rate (g): | F4: =Thesis!E22 -> 0
B5: /Equity Cost of Capital | C5: =Equity_Cost -> 0.06
B6: Dividend Value | C6: =(C4*(1+Terminal_Growth))/(Equity_Cost-Terminal_Growth) -> 17422963128 | D6: =Reporting_currency -> CNY
B7: Dividend Value per share | C7: =(C6*scaling_factor)/Common_Shares*Exchange_Rate -> 36 | D7: =Market_currency -> CNY
B9: Implied Growth Scenario Analysis
B10: FCFE Projection
B11: High Growth Period (HGP) | C11: =Scenarios!C65 -> 0.046574871
B12: High Growth Rate (HGR) | C12: =Scenarios!C64 -> 10
B13: Value Per Share | C13: =F47/Common_Shares*scaling_factor -> 41.189589 | D13: =Market_currency -> CNY
B15: Year | C15: Dividends | D15: Growth Rates | E15: Discount Factor | F15: PV of Dividends
B16: 1 | C16: =C4*(1+D16) -> 1.0940661e+09 | D16: =IF($C$12<B16,0,DDM!$C$11) -> 0.046574871 | E16: =IF($C$12<B16,0,1/(1+Equity_Cost)^B16) -> 0.94339623 | F16: =C16*E16 -> 1.0321379e+09
B17: 2 | C17: =IF(ROW()-ROW($C$16)<$C$12, $C$16*(1+D17)^(ROW()-ROW($C$16)), 0) -> 1.1450221e+09 | D17: =IF($C$12<B17,0,DDM!$C$11) -> 0.046574871 | E17: =IF($C$12<B17,0,1/(1+Equity_Cost)^B17) -> 0.88999644 | F17: =C17*E17 -> 1.0190656e+09
B18: 3 | C18: =IF(ROW()-ROW($C$16)<$C$12, $C$16*(1+D18)^(ROW()-ROW($C$16)), 0) -> 1.1983514e+09 | D18: =IF($C$12<B18,0,DDM!$C$11) -> 0.046574871 | E18: =IF($C$12<B18,0,1/(1+Equity_Cost)^B18) -> 0.83961928 | F18: =C18*E18 -> 1.0061589e+09
B19: 4 | C19: =IF(ROW()-ROW($C$16)<$C$12, $C$16*(1+D19)^(ROW()-ROW($C$16)), 0) -> 1.2541644e+09 | D19: =IF($C$12<B19,0,DDM!$C$11) -> 0.046574871 | E19: =IF($C$12<B19,0,1/(1+Equity_Cost)^B19) -> 0.79209366 | F19: =C19*E19 -> 9.934157e+08
B20: 5 | C20: =IF(ROW()-ROW($C$16)<$C$12, $C$16*(1+D20)^(ROW()-ROW($C$16)), 0) -> 1.312577e+09 | D20: =IF($C$12<B20,0,DDM!$C$11) -> 0.046574871 | E20: =IF($C$12<B20,0,1/(1+Equity_Cost)^B20) -> 0.74725817 | F20: =C20*E20 -> 9.8083387e+08
B21: 6 | C21: =IF(ROW()-ROW($C$16)<$C$12, $C$16*(1+D21)^(ROW()-ROW($C$16)), 0) -> 1.3737101e+09 | D21: =IF($C$12<B21,0,DDM!$C$11) -> 0.046574871 | E21: =IF($C$12<B21,0,1/(1+Equity_Cost)^B21) -> 0.70496054 | F21: =C21*E21 -> 9.684114e+08
B22: 7 | C22: =IF(ROW()-ROW($C$16)<$C$12, $C$16*(1+D22)^(ROW()-ROW($C$16)), 0) -> 1.4376904e+09 | D22: =IF($C$12<B22,0,DDM!$C$11) -> 0.046574871 | E22: =IF($C$12<B22,0,1/(1+Equity_Cost)^B22) -> 0.66505711 | F22: =C22*E22 -> 9.5614626e+08
B23: 8 | C23: =IF(ROW()-ROW($C$16)<$C$12, $C$16*(1+D23)^(ROW()-ROW($C$16)), 0) -> 1.5046507e+09 | D23: =IF($C$12<B23,0,DDM!$C$11) -> 0.046574871 | E23: =IF($C$12<B23,0,1/(1+Equity_Cost)^B23) -> 0.62741237 | F23: =C23*E23 -> 9.4403646e+08
B24: 9 | C24: =IF(ROW()-ROW($C$16)<$C$12, $C$16*(1+D24)^(ROW()-ROW($C$16)), 0) -> 1.5747296e+09 | D24: =IF($C$12<B24,0,DDM!$C$11) -> 0.046574871 | E24: =IF($C$12<B24,0,1/(1+Equity_Cost)^B24) -> 0.59189846 | F24: =C24*E24 -> 9.3208003e+08
B25: 10 | C25: =IF(ROW()-ROW($C$16)<$C$12, $C$16*(1+D25)^(ROW()-ROW($C$16)), 0) -> 1.6480724e+09 | D25: =IF($C$12<B25,0,DDM!$C$11) -> 0.046574871 | E25: =IF($C$12<B25,0,1/(1+Equity_Cost)^B25) -> 0.55839478 | F25: =C25*E25 -> 9.2027504e+08
B26: 11 | C26: =IF(ROW()-ROW($C$16)<$C$12, $C$16*(1+D26)^(ROW()-ROW($C$16)), 0) -> 0 | D26: =IF($C$12<B26,0,DDM!$C$11) -> 0 | E26: =IF($C$12<B26,0,1/(1+Equity_Cost)^B26) -> 0 | F26: =C26*E26 -> 0
B27: 12 | C27: =IF(ROW()-ROW($C$16)<$C$12, $C$16*(1+D27)^(ROW()-ROW($C$16)), 0) -> 0 | D27: =IF($C$12<B27,0,DDM!$C$11) -> 0 | E27: =IF($C$12<B27,0,1/(1+Equity_Cost)^B27) -> 0 | F27: =C27*E27 -> 0
B28: 13 | C28: =IF(ROW()-ROW($C$16)<$C$12, $C$16*(1+D28)^(ROW()-ROW($C$16)), 0) -> 0 | D28: =IF($C$12<B28,0,DDM!$C$11) -> 0 | E28: =IF($C$12<B28,0,1/(1+Equity_Cost)^B28) -> 0 | F28: =C28*E28 -> 0
... B45: 30 | C45: =IF(ROW()-ROW($C$16)<$C$12, $C$16*(1+D45)^(ROW()-ROW($C$16)), 0) -> 0 | D45: =IF($C$12<B45,0,DDM!$C$11) -> 0 | E45: =IF($C$12<B45,0,1/(1+Equity_Cost)^B45) -> 0 | F45: =C45*E45 -> 0
B46: Terminal Year | C46: =C$16*(1+F4)^$C$12/Equity_Cost -> 1.8234435e+10 | D46: =Terminal_Growth -> 0 | E46: =1/(1+Equity_Cost)^C12 -> 0.55839478 | F46: =C46*E46 -> 1.0182013e+10
E47: Total PV | F47: =SUM(F16:F46) -> 1.9934575e+10
B49: Sensitivity Analysis (Enterprise Value)
A50: =F47 -> 1.9934575e+10 | B50: =C73 -> 0 | C50: =C72 -> 0.02 | D50: =C71 -> 0.04 | E50: =C70 -> 0.06 | F50: =C69 -> 0.1
A51: 5 | B51: 1.7422963e+10 | C51: 1.7943949e+10 | D51: 1.8478595e+10 | E51: 1.9027508e+10 | F51: 2.0170637e+10
A52: 10 | B52: 1.7422963e+10 | C52: 1.8435622e+10 | D52: 1.9546147e+10 | E52: 2.0766403e+10 | F52: 2.3590386e+10
A53: 15 | B53: 1.7422963e+10 | C53: 1.9102312e+10 | D53: 2.1070753e+10 | E53: 2.338686e+10 | F53: 2.9357241e+10
A54: 20 | B54: 1.7422963e+10 | C54: 1.9847419e+10 | D54: 2.2870861e+10 | E54: 2.6666072e+10 | F54: 3.7531407e+10
A55: 25 | B55: 1.7422963e+10 | C55: 2.0607923e+10 | D55: 2.4816808e+10 | E55: 3.0437543e+10 | F55: 4.8290821e+10
A56: 30 | B56: 1.7422963e+10 | C56: 2.1344287e+10 | D56: 2.6817154e+10 | E56: 3.4576859e+10 | F56: 6.1928448e+10
B58: Sensitivity Analysis (Equity Value per share)
B59: =B50 -> 0 | C59: =C50 -> 0.02 | D59: =D50 -> 0.04 | E59: =E50 -> 0.06 | F59: =F50 -> 0.1
A60: 0 | B60: =C7 -> 36 | C60: =C7 -> 36 | D60: =C7 -> 36 | E60: =C7 -> 36 | F60: =C7 -> 36
A61: =A51 -> 5 | B61: =B51/Common_Shares*$C$3*Exchange_Rate -> 36 | C61: =C51/Common_Shares*$C$3*Exchange_Rate -> 37.07648 | D61: =D51/Common_Shares*$C$3*Exchange_Rate -> 38.181188 | E61: =E51/Common_Shares*$C$3*Exchange_Rate -> 39.315372 | F61: =F51/Common_Shares*$C$3*Exchange_Rate -> 41.677349
...

Sheet Scenarios
B2: Current Situation | H2: Warning: Do Not Remove this logic
B3: Selection | H3: 0 | I3: =-Market_Price -> -55.15
B4: Past Years Selected | C4: 3 | E4: Tie the business story into the three levers of value: FCFE, growth and risk. | H4: 1 | I4: =IF(ROW()-3 < $C$76, $C$77, IF(ROW()-3 = $C$76, $C$77 + $C$60, "")) -> 2.16
H5: 2 | I5: =IF(ROW()-3 < $C$76, $C$77, IF(ROW()-3 = $C$76, $C$77 + $C$60, "")) -> 2.16
B6: Latest | C6: =DCF!C3 -> 1 | E6: Prompt for fundamental Analysis | H6: 3 | I6: =IF(ROW()-3 < $C$76, $C$77, IF(ROW()-3 = $C$76, $C$77 + $C$60, "")) -> 84.880031
B7: EBIT | C7: =Normalized_FCF!G8 -> 3109212579 | D7: =Reporting_currency -> CNY | E7: ="Please develop three logical "&C18&"-year scenarios (Base Case, Pessimistic Case, Optimistic Case) and two extreme "&C46&"-year scenarios (Success Scenario, Devil’s Advocate Scenario) for "&Thesis!C5&"("&Thesis!C11&"). Each scenario should include the Compound Growth Rate, the Probability Assessment, and the Business Narrative." -> Please develop three logical 10-year scenarios (Base Case, Pessimistic Case, Optimistic Case) and two extreme 15-year scenarios (Success Scenario, Devil’s Advocate Scenario) for 重庆啤酒(600132.SS). Each scenario should include the Compound Growth Rate, the Probability Assessment, and the Business Narrative. | H7: 4 | I7: =IF(ROW()-3 < $C$76, $C$77, IF(ROW()-3 = $C$76, $C$77 + $C$60, ""))
B8: FCFE | C8: =Normalized_FCF!G19 -> 2.3232788e+09 | D8: =Reporting_currency -> CNY | H8: 5 | I8: =IF(ROW()-3 < $C$76, $C$77, IF(ROW()-3 = $C$76, $C$77 + $C$60, ""))
B9: Normalized | C9: =Normalized_FCF!C19 -> 2.0999612e+09 | D9: =Reporting_currency -> CNY | H9: 6 | I9: =IF(ROW()-3 < $C$76, $C$77, IF(ROW()-3 = $C$76, $C$77 + $C$60, ""))
H10: 7 | I10: =IF(ROW()-3 < $C$76, $C$77, IF(ROW()-3 = $C$76, $C$77 + $C$60, ""))
B11: YoY CAGR | H11: 8 | I11: =IF(ROW()-3 < $C$76, $C$77, IF(ROW()-3 = $C$76, $C$77 + $C$60, ""))
B12: Sales | C12: =(Normalized_FCF!G4/OFFSET(Normalized_FCF!G4, 0, $C$4))^(1/$C$4) - 1 -> 0.037342435 | H12: 9 | I12: =IF(ROW()-3 < $C$76, $C$77, IF(ROW()-3 = $C$76, $C$77 + $C$60, ""))
B13: Operating EBIT | C13: =(Normalized_FCF!G8/OFFSET(Normalized_FCF!G8, 0, $C$4))^(1/$C$4) - 1 -> 0.023730241 | H13: 10 | I13: =IF(ROW()-3 < $C$76, $C$77, IF(ROW()-3 = $C$76, $C$77 + $C$60, ""))
B14: FCFE | C14: =(Normalized_FCF!G19/OFFSET(Normalized_FCF!G19, 0, $C$4))^(1/$C$4) - 1 -> -0.0074772486
B16: General Scenarios
B17: Assumption | E17: Guidance Note
B18: High Growth Period (HGP) | C18: 10 | E18: Fundamental analysis and market signal analysis should be combined, with fundamental analysis given priority and market signal analysis serving as a supplement. Market signal analysis predicts a company's future trend, while fundamental analysis interprets the trend and identifies relevant fundamental factors and possibilities.
B20: Reference
B21: Market Price | C21: =Market_Price -> 55.15 | D21: =Market_currency -> CNY
B22: No Growth Value per share | C22: =IF(valuation_method="DCF",DCF!C12,DDM!C7) -> 72.229906 | D22: =Market_currency -> CNY
B24: Base | E24: Business Story
B25: High Growth Period (HGP) | C25: =C18 -> 10
B26: High Growth Rate (HGR) | C26: 0.04
B27: Value per share | C27: =IF(valuation_method="DCF",DCF!E76,DDM!E71) -> 81.042549 | D27: =Market_currency -> CNY
B28: Probabilities | C28: 0.6
B30: Pessimistic | E30: Business Story
B31: High Growth Period (HGP) | C31: =C18 -> 10
B32: High Growth Rate (HGR) | C32: 0.02
B33: Value per share | C33: =IF(valuation_method="DCF",DCF!E77,DDM!E72) -> 76.433123 | D33: =Market_currency -> CNY
B34: Probabilities | C34: 0.2
B36: Optimistic | E36: Business Story
B37: High Growth Period (HGP) | C37: =C18 -> 10
B38: High Growth Rate (HGR) | C38: 0.06
B39: Value per share | C39: =IF(valuation_method="DCF",DCF!E75,DDM!E70) -> 86.107431 | D39: =Market_currency -> CNY
B40: Probabilities | C40: =1-C28-C34 -> 0.2
B42: Expected Value = | C42: =C27*C28+C33*C34+C39*C40 -> 81.13364 | D42: =Market_currency -> CNY
B44: Extreme Scenarios
B45: Assumption
B46: High Growth Period (HGP) | C46: 15
B48: Devil's advocate | E48: Business Story
B49: High Growth Period (HGP) | C49: =C46 -> 15
...
