Workbook
Name Common_Shares: Thesis!$C$6
Name Equity_Cost: Thesis!$C$86
Name Exchange_Rate: Thesis!$C$16
Name Market_currency: Thesis!$C$13
Name Market_Price: Thesis!$C$12
Name Reporting_currency: Thesis!$C$25
Name scaling_factor: Data!$C$3
Name Terminal_Growth: Thesis!$C$92
Name valuation_method: Thesis!$E$21

Sheet Thesis
B1: Model last updated: | C1: 45797 | D1: CN | E1: Selected: | F1: Y
A2: Executive Summary
B4: Company Information
B5: Company Name | C5: 浙江鼎力
B6: Number of Shares: | C6: 506347879
B7: Report Interval: | C7: 6
B8: Update Required After: | C8: =EOMONTH(EDATE(BS!C1,C7+2),0) -> 45900
B10: Listing Information
B11: Symbol: | C11: 603338.SS
B12: Market Price: | C12: 45.93
B13: Market Currency | C13: CNY
B14: Capitalization: | C14: =Thesis!C12*Common_Shares/1000000 -> 23256.558 | D14: =IF(D11="","",Thesis!D12*Common_Shares/1000000)
B15: Forex Symbol: | C15: =IF(C25=C13,C13,C25&"/"&C13) -> CNY | D15: =IF(D11="","",IF(C25=D13,D13,C25&"/"&D13))
B16: Exchange Rate: | C16: 1
B18: Guidance Note: This model determines a target buy price consistent with defined investment criteria. It follows a logical progression: establishing current sustainable earnings, adjusting for financial structure, incorporating growth scenarios, and finally applying the investor’s required return.
B20: Valuation Overview
B21: Growth Classification: | C21: =IF(Scenarios!C69="Y",Scenarios!B69,"")&IF(Scenarios!C70="Y",Scenarios!B70,"")&IF(Scenarios!C71="Y",Scenarios!B71,"")&" "&IF(Scenarios!C72="Y",Scenarios!B72,"") -> Low Growth | D21: Valuation Method | E21: DCF
B22: Comp_Sector: | C22: IND_01 | D22: =IF(valuation_method="DDM","DDM Terminal Value","")
B23: Business Model Risk Premium: | C23: N
B24: Management Risk Premium: | C24: N
B25: Reporting Currency: | C25: CNY | D25: =IF(D11="","",Market_currency&"/"&D13&":") | E25: =IF(D11="","",1/Exchange_Rate*D16)
B26: ="Expected Equity Value ("&C13&") :" -> Expected Equity Value (CNY) : | C26: =C132 -> 64.714648 | D26: Market Implied Annual Return: | E26: =Scenarios!C87 -> 0.14060796
B28: Valuation Outputs | C28: =C145&" ("&Market_currency&")" -> 603338.SS (CNY) | D28: =IF(D11="","",D145&" ("&D13&")") | E28: Holding Period | F28: 3
B29: Target Price | C29: =C149 -> 28.803264 | D29: =D149 | E29: Target return | F29: 0.337
B30: Entry Price | C30: =C157 -> 40.844732 | D30: =D157 | E30: Entry yield | F30: 0.187
B31: Sell Price | C31: =C165 -> 57.008678 | D31: =D165 | E31: Base equity cost | F31: 0.06
B32: Exit Price | C32: =C173 -> 52.931363 | D32: =D173 | E32: Benchmark yield | F32: 0.087
A34: Step 1: Establishing the Company’s Sustainable Earning Power (Calculating Normalized FCFE)
B36: Goal: To quantify the underlying FCFE the business consistently generates for its equity owners, stripping away temporary fluctuations or accounting choices.The FCFE/Market Cap yield gives a direct measure of this cash generation relative to the current market price.
B37: FCFE = (Normalized Operating EBIT + Depreciation & Amortization – Capital Expenditures) + Stable Non-Operating EBIT + Net Interest Income – Taxes – NCI’s Share of Profits – Working Capital Investment
B39: Key Components | C39: =scaling_factor -> 1
B40: • Normalized Operating EBIT: Earnings before interest and taxes from core business operations, adjusted to remove one-time or irregular items for a sustainable earnings base.
B41: Normalized Operating EBIT = | C41: =Normalized_FCF!C8 -> 1.4620555e+09 | D41: =Reporting_currency -> CNY
B43: • Depreciation & Amortization (D&A): Non-cash expenses added back to reflect cash generated from operations. • Capital Expenditures (Capex): Cash outflows required to maintain or expand operational assets
B44: D&A = | C44: =Normalized_FCF!C9 -> 213032611 | D44: =Reporting_currency -> CNY
B45: Capex = | C45: =Normalized_FCF!C10 -> -2.1303261e+08 | D45: =Reporting_currency -> CNY
B47: • Stable Non-Operating EBIT: Consistent earnings from non-core assets, such as fixed-income investments, dividend-paying stocks, or rental properties.
B48: Stable Non-Operating EBIT = | C48: =Normalized_FCF!C11 -> 0 | D48: =Reporting_currency -> CNY
B50: • Net Interest Income: Interest income minus interest expense
B51: Operating Interest Income = | C51: =Normalized_FCF!C48 -> 9271615.3 | D51: =Reporting_currency -> CNY
...

Sheet Data
B1: =Thesis!C25 -> CNY | C1: 45657 | D1: =EOMONTH(EDATE(C1,-12),0) -> 45291 | E1: =EOMONTH(EDATE(D1,-12),0) -> 44926 | F1: =EOMONTH(EDATE(E1,-12),0) -> 44561 | G1: =EOMONTH(EDATE(F1,-12),0) -> 44196 | H1: =EOMONTH(EDATE(G1,-12),0) -> 43830 | I1: =EOMONTH(EDATE(H1,-12),0) -> 43465 | J1: =EOMONTH(EDATE(I1,-12),0) -> 43100 | K1: =EOMONTH(EDATE(J1,-12),0) -> 42735 | ... M1: =EOMONTH(EDATE(L1,-12),0) -> 42004
B2: Data (Dirty)
B3: Income Statement | C3: 1
B4: Sales | C4: 7798913979 | D4: 6311963850 | E4: 5445152633 | F4: 4939315985 | G4: 2956758302 | H4: 2389355321 | I4: 1707538304 | J4: 1139183826 | K4: 694657422 | L4: 479151199
B5: COGS | C5: 5114327878 | D5: 3915820963 | E5: 3767200164 | F5: 3505125804 | G5: 1936776307 | H5: 1447475772 | I5: 1008193651 | J5: 672472586 | K5: 406608482 | L5: 285219753
B6: OPEX | C6: 478714939 | D6: 373685879 | E6: 280986971 | F6: 199250773 | G6: 157114047 | H6: 162036874 | I6: 148533985 | J6: 122587394 | K6: 111709735 | L6: 77990782
B7: Incl. Selling Expenses | C7: 253881041 | D7: 232460848 | E7: 157533022 | F7: 110815428 | G7: 99736422 | H7: 104708887 | I7: 91880229 | J7: 50830792 | K7: 39460173 | L7: 32507628
B8: R&D | C8: 255918596 | D8: 220006702 | E8: 202331051 | F8: 154945424 | G8: 104720121 | H8: 79166101 | I8: 61487163
B9: Share of JV or associate Results | C9: -70283969 | D9: 76220632 | E9: 20133006 | F9: 1499444 | G9: 11085542 | H9: 38861023 | I9: -12704453 | J9: 0 | K9: 0 | L9: 0
B10: Dividend or Interests from FA
B11: Investment property
B12: Interest Expense | C12: 10773913 | D12: 19213222 | E12: 16787986 | F12: 5280756 | G12: 1093564 | H12: 2759318 | I12: 1307356
B13: Interest Income | C13: 156551394 | D13: 159297476 | E13: 52423241 | F13: 16165039 | G13: 12495464 | H13: 24748172 | I13: 14095046
B14: Income Tax Paid | C14: 309204387 | D14: 307004817 | E14: 202660810 | F14: 136628407 | G14: 109313998 | H14: 110812786 | I14: 84670792 | J14: 49833797 | K14: 31011793 | L14: 21880350
B15: Reported Net Income | C15: 1629038383 | D15: 1867145469 | E15: 1257239986 | F15: 884463388 | G15: 664140193 | H15: 694081237 | I15: 480468472 | J15: 283145541 | K15: 174985183 | L15: 125750467
B16: Non-controling Interests | C16: 233229 | D16: 0 | E16: 0 | F16: 0 | G16: 0 | H16: 0 | I16: 0 | J16: 0 | K16: 202868 | L16: 16241
B18: Cash Flow Statement
B19: D&A | C19: 213032611 | D19: 135475921 | E19: 104602959 | F19: 78877993 | G19: 40782935 | H19: 28330776 | I19: 25091208
B20: CAPX
B21: WCInv
B22: CFO | C22: 1916547999 | D22: 2227397039 | E22: 936702406 | F22: 373661725 | G22: 891764853 | H22: 696158346 | I22: 415714136 | J22: 348706422 | K22: 142342727 | L22: 112359422
B23: CFI | C23: -178527168 | D23: -862617775 | E23: -1221538814 | F23: -69051239 | G23: -707286524 | H23: -666330101 | I23: 156611794 | J23: -1034615747 | K23: -185922892 | L23: -345198556
B24: CFF | C24: -996799146 | D24: -520447150 | E24: 44534961 | F24: 2069283867 | G24: -192224576 | H24: 147431845 | I24: 83396087 | J24: 893792882 | K24: -14815942 | L24: 409943115
B25: ="Dividend per share ("&Market_currency&")" -> Dividend per share (CNY) | C25: =10/10 -> 1 | D25: =10/10 -> 1 | E25: =5/10 -> 0.5
B27: Balance Sheet | C27: Latest Asset Value
B28: ST AR | C28: =BS!C4 -> 2.4703637e+09 | D28: 2391271680 | E28: 2078427810 | F28: 1620191874 | G28: 635971724 | H28: 797615199 | I28: 525650211 | J28: 299236277 | K28: 180459802 | L28: 105834918
B29: ST Inventory | C29: =BS!C6 -> 2.3421363e+09 | D29: 1921374942 | E29: 1795225840 | F29: 1387177645 | G29: 941597028 | H29: 460791109 | I29: 359087239 | J29: 243055593 | K29: 179108332 | L29: 137707371
B30: Total Liabilities | C30: =BS!C33+BS!C42 -> 5.3156493e+09 | D30: 5242067251 | E30: 4736625835 | F30: 3596300871 | G30: 2124874675 | H30: 1651958950 | I30: 1032202540 | J30: 576053698 | K30: 285486746 | L30: 172274845
B31: Total Equity | C31: =BS!G27 -> 1.0038197e+10 | D31: 8965233891 | E31: 7065182676 | F31: 5978168759 | G31: 3744157600 | H31: 3207493644 | I31: 2601382187 | J31: 2202505763 | K31: 1085805361 | L31: 922655590
B32: Non-common Interest | C32: =BS!G28 -> 2901653.6 | D32: 0 | E32: 0 | F32: 0 | G32: 0 | H32: 0 | I32: 0 | J32: 0 | K32: 0 | L32: 6016241
B34: IS & CF Statements (Clean)
B35: Income Statement
B36: Sales | C36: =IF(C$4="","",C4) -> 7798913979 | D36: =IF(D$4="","",D4) -> 6311963850 | E36: =IF(E$4="","",E4) -> 5445152633 | F36: =IF(F$4="","",F4) -> 4939315985 | G36: =IF(G$4="","",G4) -> 2956758302 | H36: =IF(H$4="","",H4) -> 2389355321 | I36: =IF(I$4="","",I4) -> 1707538304 | J36: =IF(J$4="","",J4) -> 1139183826 | ... M36: =IF(M$4="","",M4)
B37: COGS | C37: =IF(C$4="","",-C5) -> -5114327878 | D37: =IF(D$4="","",-D5) -> -3915820963 | E37: =IF(E$4="","",-E5) -> -3767200164 | F37: =IF(F$4="","",-F5) -> -3505125804 | G37: =IF(G$4="","",-G5) -> -1936776307 | H37: =IF(H$4="","",-H5) -> -1447475772 | I37: =IF(I$4="","",-I5) -> -1008193651 | J37: =IF(J$4="","",-J5) -> -672472586 | ... M37: =IF(M$4="","",-M5)
B38: Gross Margin | C38: =IF(C36="","",C36+C37) -> 2684586101 | D38: =IF(D36="","",D36+D37) -> 2396142887 | E38: =IF(E36="","",E36+E37) -> 1677952469 | F38: =IF(F36="","",F36+F37) -> 1434190181 | G38: =IF(G36="","",G36+G37) -> 1019981995 | H38: =IF(H36="","",H36+H37) -> 941879549 | I38: =IF(I36="","",I36+I37) -> 699344653 | J38: =IF(J36="","",J36+J37) -> 466711240 | ... M38: =IF(M36="","",M36+M37)
B39: OPEX | C39: =IF(C$4="","",-C6) -> -478714939 | D39: =IF(D$4="","",-D6) -> -373685879 | E39: =IF(E$4="","",-E6) -> -280986971 | F39: =IF(F$4="","",-F6) -> -199250773 | G39: =IF(G$4="","",-G6) -> -157114047 | H39: =IF(H$4="","",-H6) -> -162036874 | I39: =IF(I$4="","",-I6) -> -148533985 | J39: =IF(J$4="","",-J6) -> -122587394 | ... M39: =IF(M$4="","",-M6)
B40: Incl. Selling Expenses | C40: =IF(C$4="","",-C7) -> -253881041 | D40: =IF(D$4="","",-D7) -> -232460848 | E40: =IF(E$4="","",-E7) -> -157533022 | F40: =IF(F$4="","",-F7) -> -110815428 | G40: =IF(G$4="","",-G7) -> -99736422 | H40: =IF(H$4="","",-H7) -> -104708887 | I40: =IF(I$4="","",-I7) -> -91880229 | J40: =IF(J$4="","",-J7) -> -50830792 | ... M40: =IF(M$4="","",-M7)
B41: Incl. Other Opex | C41: =IF(C$4="","",C39-C40) -> -224833898 | D41: =IF(D$4="","",D39-D40) -> -141225031 | E41: =IF(E$4="","",E39-E40) -> -123453949 | F41: =IF(F$4="","",F39-F40) -> -88435345 | G41: =IF(G$4="","",G39-G40) -> -57377625 | H41: =IF(H$4="","",H39-H40) -> -57327987 | I41: =IF(I$4="","",I39-I40) -> -56653756 | J41: =IF(J$4="","",J39-J40) -> -71756602 | ... M41: =IF(M$4="","",M39-M40)
B42: R&D | C42: =IF(C$4="","",-C8) -> -255918596 | D42: =IF(D$4="","",-D8) -> -220006702 | E42: =IF(E$4="","",-E8) -> -202331051 | F42: =IF(F$4="","",-F8) -> -154945424 | G42: =IF(G$4="","",-G8) -> -104720121 | H42: =IF(H$4="","",-H8) -> -79166101 | I42: =IF(I$4="","",-I8) -> -61487163 | J42: =IF(J$4="","",-J8) -> 0 | ... M42: =IF(M$4="","",-M8)
B43: Operating EBIT | C43: =IF(C$4="","",C38+C39+C42) -> 1949952566 | D43: =IF(D$4="","",D38+D39+D42) -> 1802450306 | E43: =IF(E$4="","",E38+E39+E42) -> 1194634447 | F43: =IF(F$4="","",F38+F39+F42) -> 1079993984 | G43: =IF(G$4="","",G38+G39+G42) -> 758147827 | H43: =IF(H$4="","",H38+H39+H42) -> 700676574 | I43: =IF(I$4="","",I38+I39+I42) -> 489323505 | J43: =IF(J$4="","",J38+J39+J42) -> 344123846 | ... M43: =IF(M$4="","",M38+M39+M42)
...

Sheet BS
B1: Most Recent Quarter | C1: 45657 | F1: =IF(MONTH(C1)=MONTH(Normalized_FCF!G1),"FY","Quarter")&" Report" -> FY Report | H1: =scaling_factor -> 1
B2: Lastest Balance Sheet
B3: ST Operating Assets | C3: Book | D3: Valued @ | F3: ST Non-Operating Assets | G3: Book | H3: Valued @
B4: ST AR | C4: =20196142.69+2309129845.46+18315265.15+122722445.83 -> 2.4703637e+09 | D4: 0.6 | F4: Cash and cash equivalents | G4: 5.0780174e+09 | H4: 0.9
B5: Operating ST Financial Assets | C5: 14974287 | D5: 0.6 | F5: Restricted cash | G5: 0 | H5: 0.7
B6: Inventory | C6: 2.3421363e+09 | D6: 0.5 | F6: Securities with stable income | G6: 0 | H6: 0.6
B7: Properties held for sale | C7: 0 | D7: 0.6 | F7: Other Securities | G7: 2.0873459e+08 | H7: 0.6
B8: Properties held for income | C8: 0 | D8: 0.6 | F8: Properties with stable income | G8: 0 | H8: 0.6
B9: Prepayments and Contract Assets | C9: 26411605 | D9: 0.1 | F9: Other Properties | G9: 0 | H9: 0.6
B10: ST DTA | C10: 0 | D10: 0.9
B11: Other ST Assets | C11: =1154749077.73+69993040.32 -> 1.2247421e+09 | D11: 0.05
B12: Operating ST Assets | C12: =SUM(C4:C11) -> 6.078628e+09 | D12: =C4*D4+C5*D5+C9*D9+C6*D6+C8*D8+C7*D7+C10*D10+C11*D11 -> 2.7261492e+09 | F12: Non-Operating ST Assets | G12: =SUM(G4:G9) -> 5.2867519e+09 | H12: =G4*H4+G5*H5+G6*H6+G7*H7+G8*H8+G9*H9 -> 4.6954564e+09
B14: LT Operating Assets | C14: Book | D14: Valued @ | F14: LT Non-Operating Assets | G14: Book | H14: Valued @
B15: LT AR | C15: 1.0171513e+09 | D15: 0.4 | F15: LT Depositis | G15: 0 | H15: 0.8
B16: Operating LT Financial Assets | C16: 0 | D16: 0.5 | F16: Securities with stable income | G16: 40867997 | H16: 0.6
B17: Properties held for sale | C17: 0 | D17: 0.6 | F17: Other Securities | G17: 0 | H17: 0.6
B18: Properties held for income | C18: 0 | D18: 0.6 | F18: JV or associate with stable income | G18: 0 | H18: 0.1
B19: PP&E & Right of Use Assets | C19: =1799948914+58349007.87+51120522.33 -> 1.9094184e+09 | D19: 0.1 | F19: Other JV or associate | G19: 0 | H19: 0.1
B20: Biological assets | C20: 0 | D20: 0.05 | F20: Properties with stable income | G20: 0 | H20: 0.2
B21: Intangible assets | C21: 7.8359044e+08 | D21: 0.05 | F21: Other Properties | G21: 0 | H21: 0.1
B22: LT DTA | C22: 83517871 | D22: 0.9
B23: Other assets & Goodwill | C23: =140139590.91+2936428.79+10844760 -> 1.5392078e+08 | D23: 0
B24: Operating LT Assets | C24: =SUM(C15:C23) -> 3.9475988e+09 | D24: =C15*D15+C16*D16+C18*D18+C17*D17+C19*D19+C20*D20+C21*D21+C22*D22+C23*D23 -> 7.1214796e+08 | F24: Non-Operating LT Assets | G24: =SUM(G15:G21) -> 40867997 | H24: =G15*H15+G16*H16+G17*H17+G18*H18+G19*H19+G20*H20+G21*H21 -> 24520798
B26: ST Liabilities | C26: Book | F26: BS Summary | G26: Book | H26: Valued @
B27: ST Borrowing | C27: 1.1007069e+08 | F27: Total Equity | G27: =G32-G30 -> 1.0038197e+10 | H27: =H32-G30 -> 2.842625e+09
B28: ST Lease liabilities | C28: 0 | F28: Incl. Minority Interest (NCI) | G28: 2901653.6
B29: ST SH Loan | C29: 0 | F29: Incl. Common Equity | G29: =G27-G28 -> 1.0035296e+10 | H29: =H27-G28 -> 2.8397234e+09
B30: ST Financial Liabilities | C30: 999897.45 | F30: Total Liabilities | G30: =C33+C42 -> 5.3156493e+09
B31: ST Interest-bearing Debt | C31: =SUM(C27:C30) -> 1.1107059e+08 | F31: incl. Interest-bearing Debt | G31: =C31+C40 -> 5.3348119e+08
B32: Other ST liabilities | C32: =C33-C31 -> 4.4116357e+09 | F32: Total Assets | G32: =G35+G40 -> 1.5353847e+10 | H32: =H35+H40 -> 8.1582744e+09
B33: Current Liabilities | C33: 4.5227063e+09
F34: Assets Summary | G34: Book | H34: Valued @
B35: LT Liabilities | C35: Book | F35: Operating Assets | G35: =C12+C24 -> 1.0026227e+10 | H35: =D12+D24 -> 3.4382972e+09
B36: LT Borrowing | C36: 3.7805537e+08 | F36: incl. AR | G36: =C4+C15 -> 3.487515e+09
B37: LT Lease liabilities | C37: 44355236 | F37: incl. inventory | G37: =C6 -> 2.3421363e+09
B38: LT SH Loan | C38: 0 | F38: incl. Properties held for sale | G38: =C7+C17 -> 0
B39: LT Financial Liabilities | C39: 0 | F39: incl. Fixed Assets | G39: =C7+C17+C19+C20 -> 1.9094184e+09 | H39: =C7*D7+C17*D17+C19*D19+C20*D20 -> 1.9094184e+08
B40: LT Interest-bearing Debt | C40: =SUM(C36:C39) -> 4.224106e+08 | F40: Non-operating Assets | G40: =G12+G24 -> 5.3276199e+09 | H40: =H12+H24 -> 4.7199772e+09
B41: Other LT liabilities | C41: =C42-C40 -> 3.7053242e+08 | F41: incl. Assets with stable income | G41: =C70 -> 5.1188854e+09 | H41: =H40-H42 -> 4.5947364e+09
B42: Noncurrent Liabilities | C42: 7.9294302e+08 | F42: incl. Other Assets | G42: =C82 -> 2.0873459e+08 | H42: =D82 -> 1.2524075e+08
...

Sheet Normalized_FCF
B1: =Thesis!C25 -> CNY | C1: Normalized | G1: =Data!C1 -> 45657 | H1: =EOMONTH(EDATE(G1,-12),0) -> 45291 | I1: =EOMONTH(EDATE(H1,-12),0) -> 44926 | J1: =EOMONTH(EDATE(I1,-12),0) -> 44561 | K1: =EOMONTH(EDATE(J1,-12),0) -> 44196 | L1: =EOMONTH(EDATE(K1,-12),0) -> 43830 | M1: =EOMONTH(EDATE(L1,-12),0) -> 43465 | N1: =EOMONTH(EDATE(M1,-12),0) -> 43100 | O1: =EOMONTH(EDATE(N1,-12),0) -> 42735 | ... Q1: =EOMONTH(EDATE(P1,-12),0) -> 42004
B2: FCFE Analysis | E2: Notes
B3: FCFE | C3: =scaling_factor -> 1
B4: Sales | C4: =AVERAGE(G4:I4) -> 6.5186768e+09 | G4: =Data!C36 -> 7798913979 | H4: =Data!D36 -> 6311963850 | I4: =Data!E36 -> 5445152633 | J4: =Data!F36 -> 4939315985 | K4: =Data!G36 -> 2956758302 | L4: =Data!H36 -> 2389355321 | M4: =Data!I36 -> 1707538304 | N4: =Data!J36 -> 1139183826 | ... Q4: =Data!M36
B5: Variable Costs | C5: =C25 -> -4.5758688e+09 | G5: =G25 -> -5368208919 | H5: =H25 -> -4148281811 | I5: =I25 -> -3924733186 | J5: =J25 -> -3615941232 | K5: =K25 -> -2036512729 | L5: =L25 -> -1552184659 | M5: =M25 -> -1100073880 | N5: =N25 -> -723303378 | ... Q5: =Q25
B6: Contribution Margin | C6: =C4+C5 -> 1.942808e+09 | G6: =IF(G4="","",G4+G5) -> 2430705060 | H6: =IF(H4="","",H4+H5) -> 2163682039 | I6: =IF(I4="","",I4+I5) -> 1520419447 | J6: =IF(J4="","",J4+J5) -> 1323374753 | K6: =IF(K4="","",K4+K5) -> 920245573 | L6: =IF(L4="","",L4+L5) -> 837170662 | M6: =IF(M4="","",M4+M5) -> 607464424 | N6: =IF(N4="","",N4+N5) -> 415880448 | ... Q6: =IF(Q4="","",Q4+Q5)
B7: Fixed Costs | C7: =C35 -> -480752494 | G7: =G35 -> -480752494 | H7: =H35 -> -361231733 | I7: =I35 -> -325785000 | J7: =J35 -> -243380769 | K7: =K35 -> -162097746 | L7: =L35 -> -136494088 | M7: =M35 -> -118140919 | N7: =N35 -> -71756602 | ... Q7: =Q35
B8: Operating EBIT | C8: =C6+C7 -> 1.4620555e+09 | G8: =IF(G$4="","",G6+G7) -> 1949952566 | H8: =IF(H$4="","",H6+H7) -> 1802450306 | I8: =IF(I$4="","",I6+I7) -> 1194634447 | J8: =IF(J$4="","",J6+J7) -> 1079993984 | K8: =IF(K$4="","",K6+K7) -> 758147827 | L8: =IF(L$4="","",L6+L7) -> 700676574 | M8: =IF(M$4="","",M6+M7) -> 489323505 | N8: =IF(N$4="","",N6+N7) -> 344123846 | ... Q8: =IF(Q$4="","",Q6+Q7)
B9: Add Back D&A | C9: =BS!$G$39*BS!D58 -> 213032611 | G9: =IF(Data!C61="","",-Data!C61) -> 213032611 | H9: =IF(Data!D61="","",-Data!D61) -> 135475921 | I9: =IF(Data!E61="","",-Data!E61) -> 104602959 | J9: =IF(Data!F61="","",-Data!F61) -> 78877993 | K9: =IF(Data!G61="","",-Data!G61) -> 40782935 | L9: =IF(Data!H61="","",-Data!H61) -> 28330776 | M9: =IF(Data!I61="","",-Data!I61) -> 25091208 | N9: =IF(Data!J61="","",-Data!J61) -> 0 | ... Q9: =IF(Data!M61="","",-Data!M61)
B10: Maintenance Capex | C10: =-C4*C78 -> -2.1303261e+08 | G10: =Data!C62 -> -213032611 | H10: =Data!D62 -> -135475921 | I10: =Data!E62 -> -104602959 | J10: =Data!F62 -> -78877993 | K10: =Data!G62 -> -40782935 | L10: =Data!H62 -> -28330776 | M10: =Data!I62 -> -25091208 | N10: =Data!J62 -> 0 | ... Q10: =Data!M62
B11: Stable Non-Operating EBIT | C11: =C63 -> 0 | G11: =G61 -> -70283969 | H11: =H61 -> 76220632 | I11: =I61 -> 20133006 | J11: =J61 -> 1499444 | K11: =K61 -> 11085542 | L11: =L61 -> 38861023 | M11: =M61 -> -12704453 | N11: =N61 -> 0 | ... Q11: =Q61
B12: Net Interest Income | C12: =C50 -> -1502297.7 | G12: =G50 -> 17809768 | H12: =H50 -> 9871848.2 | I12: =I50 -> -7216373.9 | J12: =J50 -> -2329288.7 | K12: =K50 -> 1187899.9 | L12: =L50 -> 1759286.7 | M12: =M50 -> 1266165 | N12: =N50 -> 0 | ... Q12: =Q50
B13: Pre-tax Profit | C13: =SUM(C8:C12) -> 1.4605532e+09 | G13: =IF(G$4="","",SUM(G8:G12)) -> 1.8974784e+09 | H13: =IF(H$4="","",SUM(H8:H12)) -> 1.8885428e+09 | I13: =IF(I$4="","",SUM(I8:I12)) -> 1.2075511e+09 | J13: =IF(J$4="","",SUM(J8:J12)) -> 1.0791641e+09 | K13: =IF(K$4="","",SUM(K8:K12)) -> 7.7042127e+08 | L13: =IF(L$4="","",SUM(L8:L12)) -> 7.4129688e+08 | M13: =IF(M$4="","",SUM(M8:M12)) -> 4.7788522e+08 | N13: =IF(N$4="","",SUM(N8:N12)) -> 344123846 | ... Q13: =IF(Q$4="","",SUM(Q8:Q12))
B14: Income Tax | C14: =-SUM(C8+C11,C12)*C43 -> -3.6513831e+08 | G14: =Data!C46 -> -309204387 | H14: =Data!D46 -> -307004817 | I14: =Data!E46 -> -202660810 | J14: =Data!F46 -> -136628407 | K14: =Data!G46 -> -109313998 | L14: =Data!H46 -> -110812786 | M14: =Data!I46 -> -84670792 | N14: =Data!J46 -> -49833797 | ... Q14: =Data!M46
B15: NCI’s Share of Profits | C15: =-C4*C83 -> -194943.1 | G15: =Data!C48 -> -233229 | H15: =Data!D48 -> 0 | I15: =Data!E48 -> 0 | J15: =Data!F48 -> 0 | K15: =Data!G48 -> 0 | L15: =Data!H48 -> 0 | M15: =Data!I48 -> 0 | N15: =Data!J48 -> 0 | ... Q15: =Data!M48
B16: After-tax Profit | C16: =SUM(C13:C15) -> 1.09522e+09 | G16: =IF(G$4="","",SUM(G13:G15)) -> 1.5880407e+09 | H16: =IF(H$4="","",SUM(H13:H15)) -> 1.581538e+09 | I16: =IF(I$4="","",SUM(I13:I15)) -> 1.0048903e+09 | J16: =IF(J$4="","",SUM(J13:J15)) -> 9.4253573e+08 | K16: =IF(K$4="","",SUM(K13:K15)) -> 6.6110727e+08 | L16: =IF(L$4="","",SUM(L13:L15)) -> 6.304841e+08 | M16: =IF(M$4="","",SUM(M13:M15)) -> 3.9321443e+08 | N16: =IF(N$4="","",SUM(N13:N15)) -> 294290049 | ... Q16: =IF(Q$4="","",SUM(Q13:Q15))
B17: WCInv | C17: =-C4*C85 -> 0 | E17: WCInv is by default excluded
B18: Net Borrowing | C18: 0 | E18: Net borrowing is excluded
B19: FCFE | C19: =C16+C17 -> 1.09522e+09 | G19: =IF(G$4="","",G16+G17) -> 1.5880407e+09 | H19: =IF(H$4="","",H16+H17) -> 1.581538e+09 | I19: =IF(I$4="","",I16+I17) -> 1.0048903e+09 | J19: =IF(J$4="","",J16+J17) -> 9.4253573e+08 | K19: =IF(K$4="","",K16+K17) -> 6.6110727e+08 | L19: =IF(L$4="","",L16+L17) -> 6.304841e+08 | M19: =IF(M$4="","",M16+M17) -> 3.9321443e+08 | N19: =IF(N$4="","",N16+N17) -> 294290049 | ... Q19: =IF(Q$4="","",Q16+Q17)
B21: Operating Cost Structure | E21: Notes
B22: Variable Costs
B23: COGS | C23: =-C4*C28 -> -4.3636638e+09 | G23: =Data!C37 -> -5114327878 | H23: =Data!D37 -> -3915820963 | I23: =Data!E37 -> -3767200164 | J23: =Data!F37 -> -3505125804 | K23: =Data!G37 -> -1936776307 | L23: =Data!H37 -> -1447475772 | M23: =Data!I37 -> -1008193651 | N23: =Data!J37 -> -672472586 | ... Q23: =Data!M37
B24: Selling Expenses | C24: =-C4*C29 -> -2.1220499e+08 | G24: =Data!C40 -> -253881041 | H24: =Data!D40 -> -232460848 | I24: =Data!E40 -> -157533022 | J24: =Data!F40 -> -110815428 | K24: =Data!G40 -> -99736422 | L24: =Data!H40 -> -104708887 | M24: =Data!I40 -> -91880229 | N24: =Data!J40 -> -50830792 | ... Q24: =Data!M40
B25: Variable Costs | C25: =C23+C24 -> -4.5758688e+09 | G25: =IF(G$4="","",G23+G24) -> -5368208919 | H25: =IF(H$4="","",H23+H24) -> -4148281811 | I25: =IF(I$4="","",I23+I24) -> -3924733186 | J25: =IF(J$4="","",J23+J24) -> -3615941232 | K25: =IF(K$4="","",K23+K24) -> -2036512729 | L25: =IF(L$4="","",L23+L24) -> -1552184659 | M25: =IF(M$4="","",M23+M24) -> -1100073880 | N25: =IF(N$4="","",N23+N24) -> -723303378 | ... Q25: =IF(Q$4="","",Q23+Q24)
B27: Variable Costs % of Sales
B28: COGS | C28: =AVERAGE(G28:J28) -> 0.66940944 | E28: Historical Average | G28: =IF(G$4="","",ABS(G23/G$4)) -> 0.65577437 | H28: =IF(H$4="","",ABS(H23/H$4)) -> 0.62038077 | I28: =IF(I$4="","",ABS(I23/I$4)) -> 0.69184473 | J28: =IF(J$4="","",ABS(J23/J$4)) -> 0.7096379 | K28: =IF(K$4="","",ABS(K23/K$4)) -> 0.65503369 | L28: =IF(L$4="","",ABS(L23/L$4)) -> 0.60580181 | M28: =IF(M$4="","",ABS(M23/M$4)) -> 0.59043692 | N28: =IF(N$4="","",ABS(N23/N$4)) -> 0.59031086 | ... Q28: =IF(Q$4="","",ABS(Q23/Q$4))
B29: =B24 -> Selling Expenses | C29: =G29 -> 0.032553384 | E29: Historical Average | G29: =IF(G$4="","",ABS(G24/G$4)) -> 0.032553384 | H29: =IF(H$4="","",ABS(H24/H$4)) -> 0.036828609 | I29: =IF(I$4="","",ABS(I24/I$4)) -> 0.028930873 | J29: =IF(J$4="","",ABS(J24/J$4)) -> 0.022435379 | K29: =IF(K$4="","",ABS(K24/K$4)) -> 0.033731679 | L29: =IF(L$4="","",ABS(L24/L$4)) -> 0.043823071 | M29: =IF(M$4="","",ABS(M24/M$4)) -> 0.05380859 | N29: =IF(N$4="","",ABS(N24/N$4)) -> 0.04462036 | ... Q29: =IF(Q$4="","",ABS(Q24/Q$4))
B30: Variable Costs | C30: =ABS(C25/$C$4) -> 0.70196282 | G30: =IF(G$4="","",ABS(G25/G$4)) -> 0.68832775 | H30: =IF(H$4="","",ABS(H25/H$4)) -> 0.65720937 | I30: =IF(I$4="","",ABS(I25/I$4)) -> 0.72077561 | J30: =IF(J$4="","",ABS(J25/J$4)) -> 0.73207328 | K30: =IF(K$4="","",ABS(K25/K$4)) -> 0.68876537 | L30: =IF(L$4="","",ABS(L25/L$4)) -> 0.64962488 | M30: =IF(M$4="","",ABS(M25/M$4)) -> 0.64424551 | N30: =IF(N$4="","",ABS(N25/N$4)) -> 0.63493122 | ... Q30: =IF(Q$4="","",ABS(Q25/Q$4))
B32: Fixed Costs
B33: G&A and other Opex | C33: =G33 -> -224833898 | E33: Historical Average | G33: =Data!C41 -> -224833898 | H33: =Data!D41 -> -141225031 | I33: =Data!E41 -> -123453949 | J33: =Data!F41 -> -88435345 | K33: =Data!G41 -> -57377625 | L33: =Data!H41 -> -57327987 | M33: =Data!I41 -> -56653756 | N33: =Data!J41 -> -71756602 | ... Q33: =Data!M41
B34: R&D | C34: =G34 -> -255918596 | E34: Historical Average | G34: =Data!C42 -> -255918596 | H34: =Data!D42 -> -220006702 | I34: =Data!E42 -> -202331051 | J34: =Data!F42 -> -154945424 | K34: =Data!G42 -> -104720121 | L34: =Data!H42 -> -79166101 | M34: =Data!I42 -> -61487163 | N34: =Data!J42 -> 0 | ... Q34: =Data!M42
B35: Fixed Costs | C35: =C33+C34 -> -480752494 | G35: =IF(G4="","",G33+G34) -> -480752494 | H35: =IF(H4="","",H33+H34) -> -361231733 | I35: =IF(I4="","",I33+I34) -> -325785000 | J35: =IF(J4="","",J33+J34) -> -243380769 | K35: =IF(K4="","",K33+K34) -> -162097746 | L35: =IF(L4="","",L33+L34) -> -136494088 | M35: =IF(M4="","",M33+M34) -> -118140919 | N35: =IF(N4="","",N33+N34) -> -71756602 | ... Q35: =IF(Q4="","",Q33+Q34)
B37: Fixed Costs % of Sales
B38: =B33 -> G&A and other Opex | C38: =ABS(C33/$C$4) -> 0.034490726 | G38: =IF(G$4="","",ABS(G33/G$4)) -> 0.028828873 | H38: =IF(H$4="","",ABS(H33/H$4)) -> 0.022374182 | I38: =IF(I$4="","",ABS(I33/I$4)) -> 0.022672266 | J38: =IF(J$4="","",ABS(J33/J$4)) -> 0.017904371 | K38: =IF(K$4="","",ABS(K33/K$4)) -> 0.019405585 | L38: =IF(L$4="","",ABS(L33/L$4)) -> 0.023993077 | M38: =IF(M$4="","",ABS(M33/M$4)) -> 0.033178615 | N38: =IF(N$4="","",ABS(N33/N$4)) -> 0.062989485 | ... Q38: =IF(Q$4="","",ABS(Q33/Q$4))
B39: =B34 -> R&D | C39: =ABS(C34/$C$4) -> 0.039259286 | G39: =IF(G$4="","",ABS(G34/G$4)) -> 0.032814645 | H39: =IF(H$4="","",ABS(H34/H$4)) -> 0.034855507 | I39: =IF(I$4="","",ABS(I34/I$4)) -> 0.037158013 | J39: =IF(J$4="","",ABS(J34/J$4)) -> 0.031369814 | K39: =IF(K$4="","",ABS(K34/K$4)) -> 0.035417207 | L39: =IF(L$4="","",ABS(L34/L$4)) -> 0.033132829 | M39: =IF(M$4="","",ABS(M34/M$4)) -> 0.036009244 | N39: =IF(N$4="","",ABS(N34/N$4)) -> 0 | ... Q39: =IF(Q$4="","",ABS(Q34/Q$4))
B40: Fixed Costs | C40: =ABS(C35/$C$4) -> 0.073750012 | G40: =IF(G$4="","",ABS(G35/G$4)) -> 0.061643518 | H40: =IF(H$4="","",ABS(H35/H$4)) -> 0.05722969 | I40: =IF(I$4="","",ABS(I35/I$4)) -> 0.059830279 | J40: =IF(J$4="","",ABS(J35/J$4)) -> 0.049274185 | K40: =IF(K$4="","",ABS(K35/K$4)) -> 0.054822792 | L40: =IF(L$4="","",ABS(L35/L$4)) -> 0.057125906 | M40: =IF(M$4="","",ABS(M35/M$4)) -> 0.069187859 | N40: =IF(N$4="","",ABS(N35/N$4)) -> 0.062989485 | ... Q40: =IF(Q$4="","",ABS(Q35/Q$4))
B42: Tax % of Pre-tax Profit
B43: Income Tax Rate | C43: 0.25 | E43: Use the highest past tax rate | G43: =IF(G$4="","",-G14/SUM(G8+G11,G12)) -> 0.16295542 | H43: =IF(H$4="","",-H14/SUM(H8+H11,H12)) -> 0.16256175 | I43: =IF(I$4="","",-I14/SUM(I8+I11,I12)) -> 0.16782794 | J43: =IF(J$4="","",-J14/SUM(J8+J11,J12)) -> 0.12660577 | K43: =IF(K$4="","",-K14/SUM(K8+K11,K12)) -> 0.1418886 | L43: =IF(L$4="","",-L14/SUM(L8+L11,L12)) -> 0.14948503 | M43: =IF(M$4="","",-M14/SUM(M8+M11,M12)) -> 0.17717809 | N43: =IF(N$4="","",-N14/SUM(N8+N11,N12)) -> 0.14481355 | ... Q43: =IF(Q$4="","",-Q14/SUM(Q8+Q11,Q12))
B45: Non-operating Income | E45: Notes
B46: Interest
...

Sheet DCF
B2: No-Growth DCF Valuation | H2: Notes
B3: No-Growth DCF | C3: =scaling_factor -> 1 | E3: Special Assumption
B4: Adjusted FCFE | C4: =Normalized_FCF!C19 -> 1.09522e+09 | D4: =Reporting_currency -> CNY | E4: Terminal Growth Rate (g): | F4: =Terminal_Growth -> 0
B5: /Equity Cost of Capital | C5: =Equity_Cost -> 0.06
B6: Stable Income Value | C6: =(C4*(1+Terminal_Growth))/(Equity_Cost-Terminal_Growth) -> 1.8253666e+10 | D6: =Reporting_currency -> CNY | E6: Conservative Valuation: Setting g=0 can be a conservative assumption to avoid overestimating the stock’s value, especially if future growth is uncertain or unreliable.
B7: - Interest-bearing Debt | C7: =BS!G31 -> 5.3348119e+08 | D7: =Reporting_currency -> CNY
B8: + Non-operating Cash | C8: =BS!D66 -> 4.1508558e+09 | D8: =Reporting_currency -> CNY
B9: + Other Non-operating Assets | C9: =BS!H42 -> 1.2524075e+08 | D9: =Reporting_currency -> CNY
B10: Equity Value | C10: =C6-C7+C8+C9 -> 2.1996282e+10 | D10: =Reporting_currency -> CNY
B11: * Exchange rate | C11: =Exchange_Rate -> 1 | D11: =Thesis!C15 -> CNY
B12: Equity Value per share | C12: =(C10*scaling_factor)/Common_Shares*Exchange_Rate -> 43.441047 | D12: =Market_currency -> CNY
B14: Implied Growth Scenario Analysis
B15: FCFE Projection
B16: High Growth Period (HGP) | C16: =Scenarios!C65 -> 0.042510317
B17: High Growth Rate (HGR) | C17: =Scenarios!C64 -> 30
B18: Value Per Share | C18: =(F52-C7+C8+C9)*Exchange_Rate/Common_Shares*scaling_factor -> 64.595614 | D18: =Market_currency -> CNY
B20: Year | C20: FCFE | D20: Growth Rates | E20: Discount Factor | F20: PV of FCFE
B21: 1 | C21: =C4*(1+D21) -> 1.1417781e+09 | D21: =IF($C$17<B21,0,DCF!$C$16) -> 0.042510317 | E21: =IF($C$17<B21,0,1/(1+Equity_Cost)^B21) -> 0.94339623 | F21: =C21*E21 -> 1.0771492e+09
B22: 2 | C22: =IF(ROW()-ROW($C$21)<$C$17, $C$21*(1+D22)^(ROW()-ROW($C$21)), 0) -> 1.1903155e+09 | D22: =IF($C$17<B22,0,DCF!$C$16) -> 0.042510317 | E22: =IF($C$17<B22,0,1/(1+Equity_Cost)^B22) -> 0.88999644 | F22: =C22*E22 -> 1.0593765e+09
B23: 3 | C23: =IF(ROW()-ROW($C$21)<$C$17, $C$21*(1+D23)^(ROW()-ROW($C$21)), 0) -> 1.2409162e+09 | D23: =IF($C$17<B23,0,DCF!$C$16) -> 0.042510317 | E23: =IF($C$17<B23,0,1/(1+Equity_Cost)^B23) -> 0.83961928 | F23: =C23*E23 -> 1.0418971e+09
B24: 4 | C24: =IF(ROW()-ROW($C$21)<$C$17, $C$21*(1+D24)^(ROW()-ROW($C$21)), 0) -> 1.2936679e+09 | D24: =IF($C$17<B24,0,DCF!$C$16) -> 0.042510317 | E24: =IF($C$17<B24,0,1/(1+Equity_Cost)^B24) -> 0.79209366 | F24: =C24*E24 -> 1.0247062e+09
B25: 5 | C25: =IF(ROW()-ROW($C$21)<$C$17, $C$21*(1+D25)^(ROW()-ROW($C$21)), 0) -> 1.3486621e+09 | D25: =IF($C$17<B25,0,DCF!$C$16) -> 0.042510317 | E25: =IF($C$17<B25,0,1/(1+Equity_Cost)^B25) -> 0.74725817 | F25: =C25*E25 -> 1.0077988e+09
B26: 6 | C26: =IF(ROW()-ROW($C$21)<$C$17, $C$21*(1+D26)^(ROW()-ROW($C$21)), 0) -> 1.4059942e+09 | D26: =IF($C$17<B26,0,DCF!$C$16) -> 0.042510317 | E26: =IF($C$17<B26,0,1/(1+Equity_Cost)^B26) -> 0.70496054 | F26: =C26*E26 -> 9.9117043e+08
B27: 7 | C27: =IF(ROW()-ROW($C$21)<$C$17, $C$21*(1+D27)^(ROW()-ROW($C$21)), 0) -> 1.4657635e+09 | D27: =IF($C$17<B27,0,DCF!$C$16) -> 0.042510317 | E27: =IF($C$17<B27,0,1/(1+Equity_Cost)^B27) -> 0.66505711 | F27: =C27*E27 -> 9.7481641e+08
B28: 8 | C28: =IF(ROW()-ROW($C$21)<$C$17, $C$21*(1+D28)^(ROW()-ROW($C$21)), 0) -> 1.5280735e+09 | D28: =IF($C$17<B28,0,DCF!$C$16) -> 0.042510317 | E28: =IF($C$17<B28,0,1/(1+Equity_Cost)^B28) -> 0.62741237 | F28: =C28*E28 -> 9.5873223e+08
B29: 9 | C29: =IF(ROW()-ROW($C$21)<$C$17, $C$21*(1+D29)^(ROW()-ROW($C$21)), 0) -> 1.5930324e+09 | D29: =IF($C$17<B29,0,DCF!$C$16) -> 0.042510317 | E29: =IF($C$17<B29,0,1/(1+Equity_Cost)^B29) -> 0.59189846 | F29: =C29*E29 -> 9.4291344e+08
B30: 10 | C30: =IF(ROW()-ROW($C$21)<$C$17, $C$21*(1+D30)^(ROW()-ROW($C$21)), 0) -> 1.6607527e+09 | D30: =IF($C$17<B30,0,DCF!$C$16) -> 0.042510317 | E30: =IF($C$17<B30,0,1/(1+Equity_Cost)^B30) -> 0.55839478 | F30: =C30*E30 -> 9.2735565e+08
B31: 11 | C31: =IF(ROW()-ROW($C$21)<$C$17, $C$21*(1+D31)^(ROW()-ROW($C$21)), 0) -> 1.7313519e+09 | D31: =IF($C$17<B31,0,DCF!$C$16) -> 0.042510317 | E31: =IF($C$17<B31,0,1/(1+Equity_Cost)^B31) -> 0.52678753 | F31: =C31*E31 -> 9.1205456e+08
B32: 12 | C32: =IF(ROW()-ROW($C$21)<$C$17, $C$21*(1+D32)^(ROW()-ROW($C$21)), 0) -> 1.8049522e+09 | D32: =IF($C$17<B32,0,DCF!$C$16) -> 0.042510317 | E32: =IF($C$17<B32,0,1/(1+Equity_Cost)^B32) -> 0.49696936 | F32: =C32*E32 -> 8.9700593e+08
B33: 13 | C33: =IF(ROW()-ROW($C$21)<$C$17, $C$21*(1+D33)^(ROW()-ROW($C$21)), 0) -> 1.8816813e+09 | D33: =IF($C$17<B33,0,DCF!$C$16) -> 0.042510317 | E33: =IF($C$17<B33,0,1/(1+Equity_Cost)^B33) -> 0.46883902 | F33: =C33*E33 -> 8.822056e+08
... B50: 30 | C50: =IF(ROW()-ROW($C$21)<$C$17, $C$21*(1+D50)^(ROW()-ROW($C$21)), 0) -> 3.8186706e+09 | D50: =IF($C$17<B50,0,DCF!$C$16) -> 0.042510317 | E50: =IF($C$17<B50,0,1/(1+Equity_Cost)^B50) -> 0.17411013 | F50: =C50*E50 -> 6.6486925e+08
B51: Terminal Year | C51: =C$21*(1+Terminal_Growth)^$C$17/Equity_Cost -> 1.9029636e+10 | D51: =Terminal_Growth -> 0 | E51: =1/(1+Equity_Cost)^C17 -> 0.17411013 | F51: =C51*E51 -> 3.3132523e+09
E52: Total PV | F52: =SUM(F21:F51) -> 2.8965237e+10
B54: Sensitivity Analysis (Enterprise Value)
A55: =F52 -> 2.8965237e+10 | B55: =C78 -> 0 | C55: =C77 -> 0.02 | D55: =C76 -> 0.04 | E55: =C75 -> 0.06 | F55: =C74 -> 0.08
A56: 5 | B56: 1.8253666e+10 | C56: 1.8799492e+10 | D56: 1.935963e+10 | E56: 1.9934713e+10 | F56: 2.0525395e+10
A57: 10 | B57: 1.8253666e+10 | C57: 1.9314608e+10 | D57: 2.0478081e+10 | E57: 2.1756517e+10 | F57: 2.3163747e+10
A58: 15 | B58: 1.8253666e+10 | C58: 2.0013084e+10 | D58: 2.2075377e+10 | E58: 2.4501914e+10 | F58: 2.7366349e+10
A59: 20 | B59: 1.8253666e+10 | C59: 2.0793718e+10 | D59: 2.3961313e+10 | E59: 2.7937474e+10 | F59: 3.2956421e+10
A60: 25 | B60: 1.8253666e+10 | C60: 2.1590481e+10 | D60: 2.600004e+10 | E60: 3.1888764e+10 | F60: 3.9823276e+10
...

Sheet DDM
B2: No-Growth DDM Valuation | H2: Notes
B3: No-Growth DDM | C3: =scaling_factor -> 1 | E3: Special Assumption
B4: Dividend | C4: =Normalized_FCF!C91 -> 506347879 | D4: =Market_currency -> CNY | E4: Terminal Growth Rate (g): | F4: =Thesis!E22 -> 0
B5: /Equity Cost of Capital | C5: =Equity_Cost -> 0.06
B6: Dividend Value | C6: =(C4*(1+Terminal_Growth))/(Equity_Cost-Terminal_Growth) -> 8.4391313e+09 | D6: =Reporting_currency -> CNY
B7: Dividend Value per share | C7: =(C6*scaling_factor)/Common_Shares*Exchange_Rate -> 16.666667 | D7: =Market_currency -> CNY
B9: Implied Growth Scenario Analysis
B10: FCFE Projection
B11: High Growth Period (HGP) | C11: =Scenarios!C65 -> 0.042510317
B12: High Growth Rate (HGR) | C12: =Scenarios!C64 -> 30
B13: Value Per Share | C13: =F47/Common_Shares*scaling_factor -> 26.446958 | D13: =Market_currency -> CNY
B15: Year | C15: Dividends | D15: Growth Rates | E15: Discount Factor | F15: PV of Dividends
B16: 1 | C16: =C4*(1+D16) -> 5.2787289e+08 | D16: =IF($C$12<B16,0,DDM!$C$11) -> 0.042510317 | E16: =IF($C$12<B16,0,1/(1+Equity_Cost)^B16) -> 0.94339623 | F16: =C16*E16 -> 4.9799329e+08
B17: 2 | C17: =IF(ROW()-ROW($C$16)<$C$12, $C$16*(1+D17)^(ROW()-ROW($C$16)), 0) -> 5.5031293e+08 | D17: =IF($C$12<B17,0,DDM!$C$11) -> 0.042510317 | E17: =IF($C$12<B17,0,1/(1+Equity_Cost)^B17) -> 0.88999644 | F17: =C17*E17 -> 4.8977655e+08
B18: 3 | C18: =IF(ROW()-ROW($C$16)<$C$12, $C$16*(1+D18)^(ROW()-ROW($C$16)), 0) -> 5.7370691e+08 | D18: =IF($C$12<B18,0,DDM!$C$11) -> 0.042510317 | E18: =IF($C$12<B18,0,1/(1+Equity_Cost)^B18) -> 0.83961928 | F18: =C18*E18 -> 4.8169538e+08
B19: 4 | C19: =IF(ROW()-ROW($C$16)<$C$12, $C$16*(1+D19)^(ROW()-ROW($C$16)), 0) -> 5.9809537e+08 | D19: =IF($C$12<B19,0,DDM!$C$11) -> 0.042510317 | E19: =IF($C$12<B19,0,1/(1+Equity_Cost)^B19) -> 0.79209366 | F19: =C19*E19 -> 4.7374755e+08
B20: 5 | C20: =IF(ROW()-ROW($C$16)<$C$12, $C$16*(1+D20)^(ROW()-ROW($C$16)), 0) -> 6.2352059e+08 | D20: =IF($C$12<B20,0,DDM!$C$11) -> 0.042510317 | E20: =IF($C$12<B20,0,1/(1+Equity_Cost)^B20) -> 0.74725817 | F20: =C20*E20 -> 4.6593086e+08
B21: 6 | C21: =IF(ROW()-ROW($C$16)<$C$12, $C$16*(1+D21)^(ROW()-ROW($C$16)), 0) -> 6.5002665e+08 | D21: =IF($C$12<B21,0,DDM!$C$11) -> 0.042510317 | E21: =IF($C$12<B21,0,1/(1+Equity_Cost)^B21) -> 0.70496054 | F21: =C21*E21 -> 4.5824314e+08
B22: 7 | C22: =IF(ROW()-ROW($C$16)<$C$12, $C$16*(1+D22)^(ROW()-ROW($C$16)), 0) -> 6.7765949e+08 | D22: =IF($C$12<B22,0,DDM!$C$11) -> 0.042510317 | E22: =IF($C$12<B22,0,1/(1+Equity_Cost)^B22) -> 0.66505711 | F22: =C22*E22 -> 4.5068226e+08
B23: 8 | C23: =IF(ROW()-ROW($C$16)<$C$12, $C$16*(1+D23)^(ROW()-ROW($C$16)), 0) -> 7.0646701e+08 | D23: =IF($C$12<B23,0,DDM!$C$11) -> 0.042510317 | E23: =IF($C$12<B23,0,1/(1+Equity_Cost)^B23) -> 0.62741237 | F23: =C23*E23 -> 4.4324614e+08
B24: 9 | C24: =IF(ROW()-ROW($C$16)<$C$12, $C$16*(1+D24)^(ROW()-ROW($C$16)), 0) -> 7.3649915e+08 | D24: =IF($C$12<B24,0,DDM!$C$11) -> 0.042510317 | E24: =IF($C$12<B24,0,1/(1+Equity_Cost)^B24) -> 0.59189846 | F24: =C24*E24 -> 4.3593271e+08
B25: 10 | C25: =IF(ROW()-ROW($C$16)<$C$12, $C$16*(1+D25)^(ROW()-ROW($C$16)), 0) -> 7.6780796e+08 | D25: =IF($C$12<B25,0,DDM!$C$11) -> 0.042510317 | E25: =IF($C$12<B25,0,1/(1+Equity_Cost)^B25) -> 0.55839478 | F25: =C25*E25 -> 4.2873995e+08
B26: 11 | C26: =IF(ROW()-ROW($C$16)<$C$12, $C$16*(1+D26)^(ROW()-ROW($C$16)), 0) -> 8.0044772e+08 | D26: =IF($C$12<B26,0,DDM!$C$11) -> 0.042510317 | E26: =IF($C$12<B26,0,1/(1+Equity_Cost)^B26) -> 0.52678753 | F26: =C26*E26 -> 4.2166587e+08
B27: 12 | C27: =IF(ROW()-ROW($C$16)<$C$12, $C$16*(1+D27)^(ROW()-ROW($C$16)), 0) -> 8.34475e+08 | D27: =IF($C$12<B27,0,DDM!$C$11) -> 0.042510317 | E27: =IF($C$12<B27,0,1/(1+Equity_Cost)^B27) -> 0.49696936 | F27: =C27*E27 -> 4.1470851e+08
B28: 13 | C28: =IF(ROW()-ROW($C$16)<$C$12, $C$16*(1+D28)^(ROW()-ROW($C$16)), 0) -> 8.699488e+08 | D28: =IF($C$12<B28,0,DDM!$C$11) -> 0.042510317 | E28: =IF($C$12<B28,0,1/(1+Equity_Cost)^B28) -> 0.46883902 | F28: =C28*E28 -> 4.0786594e+08
... B45: 30 | C45: =IF(ROW()-ROW($C$16)<$C$12, $C$16*(1+D45)^(ROW()-ROW($C$16)), 0) -> 1.7654679e+09 | D45: =IF($C$12<B45,0,DDM!$C$11) -> 0.042510317 | E45: =IF($C$12<B45,0,1/(1+Equity_Cost)^B45) -> 0.17411013 | F45: =C45*E45 -> 3.0738586e+08
B46: Terminal Year | C46: =C$16*(1+F4)^$C$12/Equity_Cost -> 8.7978815e+09 | D46: =Terminal_Growth -> 0 | E46: =1/(1+Equity_Cost)^C12 -> 0.17411013 | F46: =C46*E46 -> 1.5318003e+09
E47: Total PV | F47: =SUM(F16:F46) -> 1.3391361e+10
B49: Sensitivity Analysis (Enterprise Value)
A50: =F47 -> 1.3391361e+10 | B50: =C73 -> 0 | C50: =C72 -> 0.02 | D50: =C71 -> 0.04 | E50: =C70 -> 0.06 | F50: =C69 -> 0.08
A51: 5 | B51: 8.4391313e+09 | C51: 8.6914802e+09 | D51: 8.9504462e+09 | E51: 9.2163218e+09 | F51: 9.4894086e+09
A52: 10 | B52: 8.4391313e+09 | C52: 8.9296313e+09 | D52: 9.4675344e+09 | E52: 1.0058588e+10 | F52: 1.0709186e+10
A53: 15 | B53: 8.4391313e+09 | C53: 9.2525547e+09 | D53: 1.0206005e+10 | E53: 1.1327854e+10 | F53: 1.2652155e+10
A54: 20 | B54: 8.4391313e+09 | C54: 9.6134611e+09 | D54: 1.1077921e+10 | E54: 1.29162e+10 | F54: 1.5236586e+10
A55: 25 | B55: 8.4391313e+09 | C55: 9.9818249e+09 | D55: 1.2020476e+10 | E55: 1.4742981e+10 | F55: 1.8411307e+10
A56: 30 | B56: 8.4391313e+09 | C56: 1.0338497e+10 | D56: 1.298938e+10 | E56: 1.6747935e+10 | F56: 2.2148947e+10
B58: Sensitivity Analysis (Equity Value per share)
B59: =B50 -> 0 | C59: =C50 -> 0.02 | D59: =D50 -> 0.04 | E59: =E50 -> 0.06 | F59: =F50 -> 0.08
A60: 0 | B60: =C7 -> 16.666667 | C60: =C7 -> 16.666667 | D60: =C7 -> 16.666667 | E60: =C7 -> 16.666667 | F60: =C7 -> 16.666667
A61: =A51 -> 5 | B61: =B51/Common_Shares*$C$3*Exchange_Rate -> 16.666667 | C61: =C51/Common_Shares*$C$3*Exchange_Rate -> 17.165037 | D61: =D51/Common_Shares*$C$3*Exchange_Rate -> 17.676476 | E61: =E51/Common_Shares*$C$3*Exchange_Rate -> 18.201561 | F61: =F51/Common_Shares*$C$3*Exchange_Rate -> 18.740887
...

Sheet Scenarios
B2: Current Situation | H2: Warning: Do Not Remove this logic
B3: Selection | H3: 0 | I3: =-Market_Price -> -45.93
B4: Past Years Selected | C4: 3 | E4: Tie the business story into the three levers of value: FCFE, growth and risk. | H4: 1 | I4: =IF(ROW()-3 < $C$76, $C$77, IF(ROW()-3 = $C$76, $C$77 + $C$60, "")) -> 1
H5: 2 | I5: =IF(ROW()-3 < $C$76, $C$77, IF(ROW()-3 = $C$76, $C$77 + $C$60, "")) -> 1
B6: Latest | C6: =DCF!C3 -> 1 | E6: Prompt for fundamental Analysis | H6: 3 | I6: =IF(ROW()-3 < $C$76, $C$77, IF(ROW()-3 = $C$76, $C$77 + $C$60, "")) -> 65.714648
B7: EBIT | C7: =Normalized_FCF!G8 -> 1949952566 | D7: =Reporting_currency -> CNY | E7: ="Please develop three logical "&C18&"-year scenarios (Base Case, Pessimistic Case, Optimistic Case) and two extreme "&C46&"-year scenarios (Success Scenario, Devil’s Advocate Scenario) for "&Thesis!C5&"("&Thesis!C11&"). Each scenario should include the Compound Growth Rate, the Probability Assessment, and the Business Narrative." -> Please develop three logical 30-year scenarios (Base Case, Pessimistic Case, Optimistic Case) and two extreme 30-year scenarios (Success Scenario, Devil’s Advocate Scenario) for 浙江鼎力(603338.SS). Each scenario should include the Compound Growth Rate, the Probability Assessment, and the Business Narrative. | H7: 4 | I7: =IF(ROW()-3 < $C$76, $C$77, IF(ROW()-3 = $C$76, $C$77 + $C$60, ""))
B8: FCFE | C8: =Normalized_FCF!G19 -> 1.5880407e+09 | D8: =Reporting_currency -> CNY | H8: 5 | I8: =IF(ROW()-3 < $C$76, $C$77, IF(ROW()-3 = $C$76, $C$77 + $C$60, ""))
B9: Normalized | C9: =Normalized_FCF!C19 -> 1.09522e+09 | D9: =Reporting_currency -> CNY | H9: 6 | I9: =IF(ROW()-3 < $C$76, $C$77, IF(ROW()-3 = $C$76, $C$77 + $C$60, ""))
H10: 7 | I10: =IF(ROW()-3 < $C$76, $C$77, IF(ROW()-3 = $C$76, $C$77 + $C$60, ""))
B11: YoY CAGR | H11: 8 | I11: =IF(ROW()-3 < $C$76, $C$77, IF(ROW()-3 = $C$76, $C$77 + $C$60, ""))
B12: Sales | C12: =(Normalized_FCF!G4/OFFSET(Normalized_FCF!G4, 0, $C$4))^(1/$C$4) - 1 -> 0.16445428 | H12: 9 | I12: =IF(ROW()-3 < $C$76, $C$77, IF(ROW()-3 = $C$76, $C$77 + $C$60, ""))
B13: Operating EBIT | C13: =(Normalized_FCF!G8/OFFSET(Normalized_FCF!G8, 0, $C$4))^(1/$C$4) - 1 -> 0.21768298 | H13: 10 | I13: =IF(ROW()-3 < $C$76, $C$77, IF(ROW()-3 = $C$76, $C$77 + $C$60, ""))
B14: FCFE | C14: =(Normalized_FCF!G19/OFFSET(Normalized_FCF!G19, 0, $C$4))^(1/$C$4) - 1 -> 0.18992961
B16: General Scenarios
B17: Assumption | E17: Guidance Note
B18: High Growth Period (HGP) | C18: 30 | E18: Fundamental analysis and market signal analysis should be combined, with fundamental analysis given priority and market signal analysis serving as a supplement. Market signal analysis predicts a company's future trend, while fundamental analysis interprets the trend and identifies relevant fundamental factors and possibilities.
B20: Reference
B21: Market Price | C21: =Market_Price -> 45.93 | D21: =Market_currency -> CNY
B22: No Growth Value per share | C22: =IF(valuation_method="DCF",DCF!C12,DDM!C7) -> 43.441047 | D22: =Market_currency -> CNY
B24: Base | E24: Business Story
B25: High Growth Period (HGP) | C25: =C18 -> 30
B26: High Growth Rate (HGR) | C26: 0.04
B27: Value per share | C27: =IF(valuation_method="DCF",DCF!E76,DDM!E71) -> 62.87846 | D27: =Market_currency -> CNY
B28: Probabilities | C28: 0.6
B30: Pessimistic | E30: Business Story
B31: High Growth Period (HGP) | C31: =C18 -> 30
B32: High Growth Rate (HGR) | C32: 0.02
B33: Value per share | C33: =IF(valuation_method="DCF",DCF!E77,DDM!E72) -> 51.554614 | D33: =Market_currency -> CNY
B34: Probabilities | C34: 0.2
B36: Optimistic | E36: Business Story
B37: High Growth Period (HGP) | C37: =C18 -> 30
B38: High Growth Rate (HGR) | C38: 0.06
B39: Value per share | C39: =IF(valuation_method="DCF",DCF!E75,DDM!E70) -> 78.933978 | D39: =Market_currency -> CNY
B40: Probabilities | C40: =1-C28-C34 -> 0.2
B42: Expected Value = | C42: =C27*C28+C33*C34+C39*C40 -> 63.824794 | D42: =Market_currency -> CNY
B44: Extreme Scenarios
B45: Assumption
B46: High Growth Period (HGP) | C46: 30
B48: Devil's advocate | E48: Business Story
B49: High Growth Period (HGP) | C49: =C46 -> 30
...
