Workbook
Name Common_Shares: Thesis!$C$6
Name dividend_tax_rate: Normalized_FCF!$C$91
Name Equity_Cost: Thesis!$C$86
Name Exchange_Rate: Thesis!$C$16
Name Market_currency: Thesis!$C$13
Name Market_Price: Thesis!$C$12
Name Reporting_currency: Thesis!$C$25
Name scaling_factor: Data!$C$3
Name Terminal_Growth: Thesis!$C$92
Name valuation_method: Thesis!$E$23

Sheet Thesis
B1: Model last updated: | C1: 45917 | D1: INT | E1: Selected: | F1: N
A2: Executive Summary
B4: Company Information
B5: Company Name: | C5: 海底捞
B6: Number of Shares: | C6: 5574000000
B7: Report Interval: | C7: 6
B8: Update Required After: | C8: =EOMONTH(EDATE(BS!C1,C7+2),0) -> 46265
B10: Listing Information
B11: Symbol: | C11: 6862.HK
B12: Market Price: | C12: 13.11
B13: Market Currency: | C13: HKD
B14: Market Capitalization: | C14: =Thesis!C12*Common_Shares/1000000 -> 73075.14 | D14: =IF(D11="","",Thesis!D12*Common_Shares/1000000)
B15: Forex Symbol: | C15: =IF(C25=C13,C13,C25&"/"&C13) -> CNY/HKD | D15: =IF(D11="","",IF(C25=D13,D13,C25&"/"&D13))
B16: Exchange Rate: | C16: 1.0923594
B18: Guidance Note: This model evaluates the company using a structured investment process to determine its intrinsic value and target prices. It focuses on sustainable FCF capacity, adjusts for financial structure, incorporates growth scenarios, and calculates expected returns based on the derived intrinsic value.
B20: Valuation Conclusion
B21: Growth Classification: | C21: =IF(Scenarios!C74="Y",Scenarios!B74,"")&IF(Scenarios!C75="Y",Scenarios!B75,"")&IF(Scenarios!C76="Y",Scenarios!B76,"")&" "&IF(Scenarios!C77="Y",Scenarios!B77,"") -> Low Growth
B22: Comp_Sector: | C22: CNS_01
B23: Business Model Risk Premium: | C23: N | D23: Valuation Method | E23: DCF
B24: Management Risk Premium: | C24: N | D24: Base equity cost | E24: 0.075
B25: Reporting Currency: | C25: CNY | D25: Holding Period | E25: 3
B26: ="Expected Equity Value ("&C13&") :" -> Expected Equity Value (HKD) : | C26: =C132 -> 12.001067 | D26: Market Implied Annual Return: | E26: =Scenarios!C92 -> -0.029030191
B28: Price Targets | C28: =C145&" ("&Market_currency&")" -> 6862.HK (HKD)
B29: Target Price | C29: =C149 -> 4.8777391 | D29: Target return | E29: 0.35
B30: Entry Price | C30: =C157 -> 6.1445465 | D30: Entry yield | E30: 0.25
B31: Sell Price | C31: =C165 -> 9.660386 | D31: Benchmark yield | E31: 0.1174
B32: Exit Price | C32: =C173 -> 8.6018897
A34: Step 1: Establishing the Company’s Sustainable Earning Power (Calculating Normalized FCFE)
B36: Goal: To quantify the underlying FCFE the business consistently generates, stripping away temporary fluctuations or accounting choices.
B37: FCFE = (Normalized Operating EBIT + Depreciation & Amortization – Capital Expenditures) + Stable Non-Operating EBIT + Net Interest Income – Taxes – NCI’s Share of Profits – Working Capital Investment
B39: Key Components | C39: =scaling_factor -> 1000
B40: • Normalized Operating EBIT: Earnings before interest and taxes from core business operations, adjusted to remove one-time or irregular items for a sustainable earnings base.
B41: Normalized Operating EBIT = | C41: =Normalized_FCF!C8 -> 4831254 | D41: =Reporting_currency -> CNY
B43: • Depreciation & Amortization (D&A): Non-cash expenses added back to reflect cash generated from operations. • Capital Expenditures (Capex): Cash outflows required to maintain or expand operational assets
B44: D&A = | C44: =Normalized_FCF!C9 -> 0 | D44: =Reporting_currency -> CNY
B45: Capex = | C45: =Normalized_FCF!C10 -> 0 | D45: =Reporting_currency -> CNY
B47: • Stable Non-Operating EBIT: Consistent earnings from non-core assets, such as fixed-income investments, dividend-paying stocks, or rental properties.
B48: Stable Non-Operating EBIT = | C48: =Normalized_FCF!C11 -> 51775 | D48: =Reporting_currency -> CNY
B50: • Net Interest Income: Interest income minus interest expense
B51: Operating Interest Income = | C51: =Normalized_FCF!C46 -> 62121.272 | D51: =Reporting_currency -> CNY
...

Sheet Data
B1: =Thesis!C25 -> CNY | C1: 45657 | D1: =EOMONTH(EDATE(C1,-12),0) -> 45291 | E1: =EOMONTH(EDATE(D1,-12),0) -> 44926 | F1: =EOMONTH(EDATE(E1,-12),0) -> 44561 | G1: =EOMONTH(EDATE(F1,-12),0) -> 44196 | H1: =EOMONTH(EDATE(G1,-12),0) -> 43830 | I1: =EOMONTH(EDATE(H1,-12),0) -> 43465 | J1: =EOMONTH(EDATE(I1,-12),0) -> 43100 | K1: =EOMONTH(EDATE(J1,-12),0) -> 42735 | ... M1: =EOMONTH(EDATE(L1,-12),0) -> 42004
B2: Data (Dirty)
B3: Income Statement | C3: 1000
B4: Sales | C4: 42754687 | D4: 41453348
B5: COGS | C5: 16211077 | D5: 16946214
B6: OPEX | C6: =14113263+425543+1465696+2558496+257408+1864070 -> 20684476 | D6: =13039844+361903+1374307+2945399+204302+1611015 -> 19536770
B7: Incl. Selling Expenses
B8: R&D
B9: Share of JV or associate Results | C9: =56897-5122 -> 51775 | D9: =53372-7509 -> 45863
B10: Dividend or Interests from FA
B11: Investment property
B12: Interest Expense | C12: 274678 | D12: 351430
B13: Interest Income | C13: 382926 | D13: 326889
B14: Income Tax Paid | C14: 1923777 | D14: 1337673
B15: Reported Net Income | C15: 4708084 | D15: 4499080
B16: Non-controling Interests | C16: 7806 | D16: 3681
B18: Cash Flow Statement
B19: D&A
B20: CAPX
B21: WCInv
B22: CFO | C22: 7634465 | D22: 9000350 | E22: 6152295 | F22: 3806125 | G22: 2921451 | H22: 4580484 | I22: 2388393 | J22: 1399716 | K22: 1414061 | L22: 641989
B23: CFI | C23: -91488 | D23: -5310684 | E23: -756888 | F23: -4952514 | G23: -4691020 | H23: -5026276 | I23: -3867075 | J23: -1564855 | K23: -1280876 | L23: -915920
B24: CFF | C24: -7630060 | D24: -3501732 | E24: -4987546 | F24: 4310825 | G24: 2339705 | H24: -1489718 | I24: 5339398 | J24: 104943 | K24: 157735 | L24: 158591
B25: ="Dividend per share ("&Market_currency&")" -> Dividend per share (HKD) | C25: 0
B27: Balance Sheet | C27: Latest Asset Value
B28: ST AR | C28: =BS!C4 -> 1791826 | D28: 411995 | E28: 306856 | F28: 367668 | G28: 275233 | H28: 203571 | I28: 150093 | J28: 172951 | K28: 63644 | L28: 29587
B29: ST Inventory | C29: =BS!C6 -> 1060641 | D29: 1074627 | E29: 1141813 | F29: 1456237 | G29: 1154215 | H29: 1199666 | I29: 457124 | J29: 95118 | K29: 49707 | L29: 41065
B30: Total Liabilities | C30: =BS!C33+BS!C42 -> 12363761 | D30: 13160058 | E30: 13983063 | F30: 20092862 | G30: 17289886 | H30: 9987899 | I30: 3315085 | J30: 2644844 | K30: 1677783 | L30: 1249700
B31: Total Equity | C31: =BS!G27 -> 10417496 | D31: 11516940 | E31: 7456092 | F31: 7928625 | G31: 10237258 | H31: 10626033 | I31: 8629558 | J31: 1090981 | K31: 1071740 | L31: 1156918
B32: Non-common Interest | C32: =BS!G28 -> -16298 | D32: -9690 | E32: 12905 | F32: 14065 | G32: 3307 | H32: 3032 | I32: 4586 | J32: 1896 | K32: 269723 | L32: 437690
B34: IS & CF Statements (Clean)
B35: Income Statement
B36: Sales | C36: =IF(C$4="","",C4) -> 42754687 | D36: =IF(D$4="","",D4) -> 41453348 | E36: =IF(E$4="","",E4) | F36: =IF(F$4="","",F4) | G36: =IF(G$4="","",G4) | H36: =IF(H$4="","",H4) | I36: =IF(I$4="","",I4) | J36: =IF(J$4="","",J4) | ... M36: =IF(M$4="","",M4)
B37: COGS | C37: =IF(C$4="","",-C5) -> -16211077 | D37: =IF(D$4="","",-D5) -> -16946214 | E37: =IF(E$4="","",-E5) | F37: =IF(F$4="","",-F5) | G37: =IF(G$4="","",-G5) | H37: =IF(H$4="","",-H5) | I37: =IF(I$4="","",-I5) | J37: =IF(J$4="","",-J5) | ... M37: =IF(M$4="","",-M5)
B38: Gross Margin | C38: =IF(C36="","",C36+C37) -> 26543610 | D38: =IF(D36="","",D36+D37) -> 24507134 | E38: =IF(E36="","",E36+E37) | F38: =IF(F36="","",F36+F37) | G38: =IF(G36="","",G36+G37) | H38: =IF(H36="","",H36+H37) | I38: =IF(I36="","",I36+I37) | J38: =IF(J36="","",J36+J37) | ... M38: =IF(M36="","",M36+M37)
B39: OPEX | C39: =IF(C$4="","",-C6) -> -20684476 | D39: =IF(D$4="","",-D6) -> -19536770 | E39: =IF(E$4="","",-E6) | F39: =IF(F$4="","",-F6) | G39: =IF(G$4="","",-G6) | H39: =IF(H$4="","",-H6) | I39: =IF(I$4="","",-I6) | J39: =IF(J$4="","",-J6) | ... M39: =IF(M$4="","",-M6)
B40: Incl. Selling Expenses | C40: =IF(C$4="","",-C7) -> 0 | D40: =IF(D$4="","",-D7) -> 0 | E40: =IF(E$4="","",-E7) | F40: =IF(F$4="","",-F7) | G40: =IF(G$4="","",-G7) | H40: =IF(H$4="","",-H7) | I40: =IF(I$4="","",-I7) | J40: =IF(J$4="","",-J7) | ... M40: =IF(M$4="","",-M7)
B41: Incl. Other Opex | C41: =IF(C$4="","",C39-C40) -> -20684476 | D41: =IF(D$4="","",D39-D40) -> -19536770 | E41: =IF(E$4="","",E39-E40) | F41: =IF(F$4="","",F39-F40) | G41: =IF(G$4="","",G39-G40) | H41: =IF(H$4="","",H39-H40) | I41: =IF(I$4="","",I39-I40) | J41: =IF(J$4="","",J39-J40) | ... M41: =IF(M$4="","",M39-M40)
B42: R&D | C42: =IF(C$4="","",-C8) -> 0 | D42: =IF(D$4="","",-D8) -> 0 | E42: =IF(E$4="","",-E8) | F42: =IF(F$4="","",-F8) | G42: =IF(G$4="","",-G8) | H42: =IF(H$4="","",-H8) | I42: =IF(I$4="","",-I8) | J42: =IF(J$4="","",-J8) | ... M42: =IF(M$4="","",-M8)
B43: Operating EBIT | C43: =IF(C$4="","",C38+C39+C42) -> 5859134 | D43: =IF(D$4="","",D38+D39+D42) -> 4970364 | E43: =IF(E$4="","",E38+E39+E42) | F43: =IF(F$4="","",F38+F39+F42) | G43: =IF(G$4="","",G38+G39+G42) | H43: =IF(H$4="","",H38+H39+H42) | I43: =IF(I$4="","",I38+I39+I42) | J43: =IF(J$4="","",J38+J39+J42) | ... M43: =IF(M$4="","",M38+M39+M42)
...

Sheet BS
B1: Most Recent Quarter | C1: 46022 | F1: =IF(MONTH(C1)=MONTH(Normalized_FCF!G1),"FY","Quarter")&" Report" -> FY Report | H1: =scaling_factor -> 1000
B2: Lastest Balance Sheet
B3: ST Operating Assets | C3: Book | D3: Valued @ | F3: ST Non-Operating Assets | G3: Book | H3: Valued @
B4: ST AR | C4: =1517431+274395 -> 1791826 | D4: 0.6 | F4: Cash and cash equivalents | G4: 7474820 | H4: 0.9
B5: Operating ST Financial Assets | C5: 0 | D5: 0.6 | F5: Restricted cash | G5: 371676 | H5: 0.7
B6: Inventory | C6: 1060641 | D6: 0.5 | F6: Securities with stable income | G6: 0 | H6: 0.6
B7: Properties held for sale | C7: 0 | D7: 0.6 | F7: Other Securities | G7: =964975+1139998 -> 2104973 | H7: 0.6
B8: Properties held for income | C8: 0 | D8: 0.6 | F8: Properties with stable income | G8: 0 | H8: 0.6
B9: Prepayments and Contract Assets | C9: 70244 | D9: 0.1 | F9: Other Properties | G9: 0 | H9: 0.6
B10: ST DTA | C10: 0 | D10: 0.9 | F10: Assets held for sale | G10: 149978 | H10: 0.6
B11: Other ST Assets | C11: 0 | D11: 0.05
B12: Operating ST Assets | C12: =SUM(C4:C11) -> 2922711 | D12: =C4*D4+C5*D5+C9*D9+C6*D6+C8*D8+C7*D7+C10*D10+C11*D11 -> 1612440.5 | F12: Non-Operating ST Assets | G12: =SUM(G4:G10) -> 10101447 | H12: =G4*H4+G5*H5+G6*H6+G7*H7+G8*H8+G9*H9+G10*H10 -> 8340481.8
B14: LT Operating Assets | C14: Book | D14: Valued @ | F14: LT Non-Operating Assets | G14: Book | H14: Valued @
B15: LT AR and Prepayments | C15: 174430 | D15: 0.4 | F15: LT Depositis | G15: 2172 | H15: 0.8
B16: Operating LT Financial Assets | C16: 0 | D16: 0.5 | F16: Securities with stable income | G16: 0 | H16: 0.6
B17: Properties held for sale | C17: 0 | D17: 0.6 | F17: Other Securities | G17: =1981265+17227+323929 -> 2322421 | H17: 0.6
B18: Properties held for income | C18: 0 | D18: 0.6 | F18: JV or associate with stable income | G18: 179959 | H18: 0.1
B19: PP&E & Right of Use Assets | C19: =3319749+3018798 -> 6338547 | D19: 0.1 | F19: Other JV or associate | G19: 0 | H19: 0.1
B20: Biological assets | C20: 0 | D20: 0.05 | F20: Properties with stable income | G20: 0 | H20: 0.2
B21: Intangible assets | C21: 52198 | D21: 0.05 | F21: Other Properties | G21: 0 | H21: 0.1
B22: LT DTA | C22: 602527 | D22: 0.9
B23: Other assets & Goodwill | C23: 84845 | D23: 0
B24: Operating LT Assets | C24: =SUM(C15:C23) -> 7252547 | D24: =C15*D15+C16*D16+C18*D18+C17*D17+C19*D19+C20*D20+C21*D21+C22*D22+C23*D23 -> 1248510.9 | F24: Non-Operating LT Assets | G24: =SUM(G15:G21) -> 2504552 | H24: =G15*H15+G16*H16+G17*H17+G18*H18+G19*H19+G20*H20+G21*H21 -> 1413186.1
B26: ST Liabilities | C26: Book | F26: BS Summary | G26: Book | H26: Valued @
B27: ST Borrowing | C27: 97549 | F27: Total Equity | G27: =G32-G30 -> 10417496 | H27: =H32-G30 -> 250858.3
B28: ST Lease liabilities | C28: 888821 | F28: Incl. Minority Interest (NCI) | G28: -16298
B29: ST SH Loan | C29: 0 | F29: Incl. Common Equity | G29: =G27-G28 -> 10433794 | H29: =H27-G28 -> 267156.3
B30: ST Financial Liabilities | C30: 45308 | F30: Total Liabilities | G30: =C33+C42 -> 12363761
B31: ST Interest-bearing Debt | C31: =SUM(C27:C30) -> 1031678 | F31: incl. Interest-bearing Debt | G31: =C31+C40 -> 6168246
B32: Other ST liabilities | C32: =C33-C31 -> 6072143 | F32: Total Assets | G32: =G35+G40 -> 22781257 | H32: =H35+H40 -> 12614619
B33: Current Liabilities | C33: 7103821
F34: Assets Summary | G34: Book | H34: Valued @
B35: LT Liabilities | C35: Book | F35: Operating Assets | G35: =C12+C24 -> 10175258 | H35: =D12+D24 -> 2860951.4
B36: LT Borrowing | C36: 0 | F36: incl. AR | G36: =C4+C15 -> 1966256
B37: LT Lease liabilities | C37: 3108701 | F37: incl. inventory | G37: =C6 -> 1060641
B38: LT SH Loan | C38: 0 | F38: incl. Properties held for sale | G38: =C7+C17 -> 0
B39: LT Financial Liabilities | C39: 2027867 | F39: incl. Fixed Assets | G39: =C7+C17+C19+C20 -> 6338547 | H39: =C7*D7+C17*D17+C19*D19+C20*D20 -> 633854.7
B40: LT Interest-bearing Debt | C40: =SUM(C36:C39) -> 5136568 | F40: Non-operating Assets | G40: =G12+G24 -> 12605999 | H40: =H12+H24 -> 9753667.9
B41: Other LT liabilities | C41: =C42-C40 -> 123372 | F41: incl. Assets with stable income | G41: =C70 -> 8028627 | H41: =H40-H42 -> 7097231.5
B42: Noncurrent Liabilities | C42: 5259940 | F42: incl. Other Assets | G42: =C82 -> 4427394 | H42: =D82 -> 2656436.4
...

Sheet Normalized_FCF
B1: =Thesis!C25 -> CNY | C1: Normalized | G1: =Data!C1 -> 45657 | H1: =EOMONTH(EDATE(G1,-12),0) -> 45291 | I1: =EOMONTH(EDATE(H1,-12),0) -> 44926 | J1: =EOMONTH(EDATE(I1,-12),0) -> 44561 | K1: =EOMONTH(EDATE(J1,-12),0) -> 44196 | L1: =EOMONTH(EDATE(K1,-12),0) -> 43830 | M1: =EOMONTH(EDATE(L1,-12),0) -> 43465 | N1: =EOMONTH(EDATE(M1,-12),0) -> 43100 | O1: =EOMONTH(EDATE(N1,-12),0) -> 42735 | ... Q1: =EOMONTH(EDATE(P1,-12),0) -> 42004
B2: FCFE Analysis | E2: Notes
B3: FCFE | C3: =scaling_factor -> 1000
B4: Sales | C4: =AVERAGE(G4:H4) -> 42104018 | G4: =Data!C36 -> 42754687 | H4: =Data!D36 -> 41453348 | I4: =Data!E36 | J4: =Data!F36 | K4: =Data!G36 | L4: =Data!H36 | M4: =Data!I36 | N4: =Data!J36 | ... Q4: =Data!M36
B5: Variable Costs | C5: =C26 -> -16588287 | G5: =G26 -> -16211077 | H5: =H26 -> -16946214 | I5: =I26 | J5: =J26 | K5: =K26 | L5: =L26 | M5: =M26 | N5: =N26 | ... Q5: =Q26
B6: Contribution Margin | C6: =C4+C5 -> 25515730 | G6: =IF(G4="","",G4+G5) -> 26543610 | H6: =IF(H4="","",H4+H5) -> 24507134 | I6: =IF(I4="","",I4+I5) | J6: =IF(J4="","",J4+J5) | K6: =IF(K4="","",K4+K5) | L6: =IF(L4="","",L4+L5) | M6: =IF(M4="","",M4+M5) | N6: =IF(N4="","",N4+N5) | ... Q6: =IF(Q4="","",Q4+Q5)
B7: Fixed Costs | C7: =C35 -> -20684476 | G7: =G35 -> -20684476 | H7: =H35 -> -19536770 | I7: =I35 | J7: =J35 | K7: =K35 | L7: =L35 | M7: =M35 | N7: =N35 | ... Q7: =Q35
B8: Operating EBIT | C8: =C6+C7 -> 4831254 | G8: =IF(G$4="","",G6+G7) -> 5859134 | H8: =IF(H$4="","",H6+H7) -> 4970364 | I8: =IF(I$4="","",I6+I7) | J8: =IF(J$4="","",J6+J7) | K8: =IF(K$4="","",K6+K7) | L8: =IF(L$4="","",L6+L7) | M8: =IF(M$4="","",M6+M7) | N8: =IF(N$4="","",N6+N7) | ... Q8: =IF(Q$4="","",Q6+Q7)
B9: Add Back D&A | C9: =BS!$G$39*BS!D58 -> 0 | G9: =IF(Data!C61="","",-Data!C61) -> 0 | H9: =IF(Data!D61="","",-Data!D61) -> 0 | I9: =IF(Data!E61="","",-Data!E61) | J9: =IF(Data!F61="","",-Data!F61) | K9: =IF(Data!G61="","",-Data!G61) | L9: =IF(Data!H61="","",-Data!H61) | M9: =IF(Data!I61="","",-Data!I61) | N9: =IF(Data!J61="","",-Data!J61) | ... Q9: =IF(Data!M61="","",-Data!M61)
B10: Maintenance Capex | C10: =-C4*C76 -> 0 | G10: =Data!C62 -> 0 | H10: =Data!D62 -> 0 | I10: =Data!E62 | J10: =Data!F62 | K10: =Data!G62 | L10: =Data!H62 | M10: =Data!I62 | N10: =Data!J62 | ... Q10: =Data!M62
B11: Stable Non-Operating EBIT | C11: =C61 -> 51775 | G11: =G59 -> 51775 | H11: =H59 -> 45863 | I11: =I59 | J11: =J59 | K11: =K59 | L11: =L59 | M11: =M59 | N11: =N59 | ... Q11: =Q59
B12: Net Interest Income | C12: =C48 -> -92084.878 | G12: =G48 -> -123137.32 | H12: =H48 -> -222065.62 | I12: =I48 | J12: =J48 | K12: =K48 | L12: =L48 | M12: =M48 | N12: =N48 | ... Q12: =Q48
B13: Pre-tax Profit | C13: =SUM(C8:C12) -> 4790944.1 | G13: =IF(G$4="","",SUM(G8:G12)) -> 5787771.7 | H13: =IF(H$4="","",SUM(H8:H12)) -> 4794161.4 | I13: =IF(I$4="","",SUM(I8:I12)) | J13: =IF(J$4="","",SUM(J8:J12)) | K13: =IF(K$4="","",SUM(K8:K12)) | L13: =IF(L$4="","",SUM(L8:L12)) | M13: =IF(M$4="","",SUM(M8:M12)) | N13: =IF(N$4="","",SUM(N8:N12)) | ... Q13: =IF(Q$4="","",SUM(Q8:Q12))
B14: Income Tax | C14: =-SUM(C8+C11,C12)*C41 -> -1197736 | G14: =Data!C46 -> -1923777 | H14: =Data!D46 -> -1337673 | I14: =Data!E46 | J14: =Data!F46 | K14: =Data!G46 | L14: =Data!H46 | M14: =Data!I46 | N14: =Data!J46 | ... Q14: =Data!M46
B15: NCI’s Share of Profits | C15: =-C4*C81 -> 0 | G15: =Data!C48 -> -7806 | H15: =Data!D48 -> -3681 | I15: =Data!E48 | J15: =Data!F48 | K15: =Data!G48 | L15: =Data!H48 | M15: =Data!I48 | N15: =Data!J48 | ... Q15: =Data!M48
B16: After-tax Profit | C16: =SUM(C13:C15) -> 3593208.1 | G16: =IF(G$4="","",SUM(G13:G15)) -> 3856188.7 | H16: =IF(H$4="","",SUM(H13:H15)) -> 3452807.4 | I16: =IF(I$4="","",SUM(I13:I15)) | J16: =IF(J$4="","",SUM(J13:J15)) | K16: =IF(K$4="","",SUM(K13:K15)) | L16: =IF(L$4="","",SUM(L13:L15)) | M16: =IF(M$4="","",SUM(M13:M15)) | N16: =IF(N$4="","",SUM(N13:N15)) | ... Q16: =IF(Q$4="","",SUM(Q13:Q15))
B17: WCInv | C17: =-C4*C83 -> 0 | E17: WCInv is by default excluded
B18: Net Borrowing | C18: 0 | E18: Net borrowing is excluded
B19: FCFE | C19: =C16+C17 -> 3593208.1 | G19: =IF(G$4="","",G16+G17) -> 3856188.7 | H19: =IF(H$4="","",H16+H17) -> 3452807.4 | I19: =IF(I$4="","",I16+I17) | J19: =IF(J$4="","",J16+J17) | K19: =IF(K$4="","",K16+K17) | L19: =IF(L$4="","",L16+L17) | M19: =IF(M$4="","",M16+M17) | N19: =IF(N$4="","",N16+N17) | ... Q19: =IF(Q$4="","",Q16+Q17)
B21: Operating Cost Structure | E21: Notes
B22: Variable Costs
B23: COGS | C23: =-C4*C29 -> -16588287 | G23: =Data!C37 -> -16211077 | H23: =Data!D37 -> -16946214 | I23: =Data!E37 | J23: =Data!F37 | K23: =Data!G37 | L23: =Data!H37 | M23: =Data!I37 | N23: =Data!J37 | ... Q23: =Data!M37
B24: Selling Expenses | C24: =-C4*C30 -> 0 | G24: =Data!C40 -> 0 | H24: =Data!D40 -> 0 | I24: =Data!E40 | J24: =Data!F40 | K24: =Data!G40 | L24: =Data!H40 | M24: =Data!I40 | N24: =Data!J40 | ... Q24: =Data!M40
B25: R&D | C25: =-C4*C31 -> 0 | G25: =Data!C42 -> 0 | H25: =Data!D42 -> 0 | I25: =Data!E42 | J25: =Data!F42 | K25: =Data!G42 | L25: =Data!H42 | M25: =Data!I42 | N25: =Data!J42 | ... Q25: =Data!M42
B26: Variable Costs | C26: =SUM(C23:C25) -> -16588287 | G26: =IF(G$4="","",SUM(G23:G25)) -> -16211077 | H26: =IF(H$4="","",SUM(H23:H25)) -> -16946214 | I26: =IF(I$4="","",SUM(I23:I25)) | J26: =IF(J$4="","",SUM(J23:J25)) | K26: =IF(K$4="","",SUM(K23:K25)) | L26: =IF(L$4="","",SUM(L23:L25)) | M26: =IF(M$4="","",SUM(M23:M25)) | N26: =IF(N$4="","",SUM(N23:N25)) | ... Q26: =IF(Q$4="","",SUM(Q23:Q25))
B28: Variable Costs % of Sales
B29: COGS | C29: =AVERAGE(G29:H29) -> 0.39398348 | G29: =IF(G$4="","",ABS(G23/G$4)) -> 0.37916491 | H29: =IF(H$4="","",ABS(H23/H$4)) -> 0.40880206 | I29: =IF(I$4="","",ABS(I23/I$4)) | J29: =IF(J$4="","",ABS(J23/J$4)) | K29: =IF(K$4="","",ABS(K23/K$4)) | L29: =IF(L$4="","",ABS(L23/L$4)) | M29: =IF(M$4="","",ABS(M23/M$4)) | N29: =IF(N$4="","",ABS(N23/N$4)) | ... Q29: =IF(Q$4="","",ABS(Q23/Q$4))
B30: =B24 -> Selling Expenses | C30: 0 | G30: =IF(G$4="","",ABS(G24/G$4)) -> 0 | H30: =IF(H$4="","",ABS(H24/H$4)) -> 0 | I30: =IF(I$4="","",ABS(I24/I$4)) | J30: =IF(J$4="","",ABS(J24/J$4)) | K30: =IF(K$4="","",ABS(K24/K$4)) | L30: =IF(L$4="","",ABS(L24/L$4)) | M30: =IF(M$4="","",ABS(M24/M$4)) | N30: =IF(N$4="","",ABS(N24/N$4)) | ... Q30: =IF(Q$4="","",ABS(Q24/Q$4))
B31: =B25 -> R&D | C31: 0 | G31: =IF(G$4="","",ABS(G25/G$4)) -> 0 | H31: =IF(H$4="","",ABS(H25/H$4)) -> 0 | I31: =IF(I$4="","",ABS(I25/I$4)) | J31: =IF(J$4="","",ABS(J25/J$4)) | K31: =IF(K$4="","",ABS(K25/K$4)) | L31: =IF(L$4="","",ABS(L25/L$4)) | M31: =IF(M$4="","",ABS(M25/M$4)) | N31: =IF(N$4="","",ABS(N25/N$4)) | ... Q31: =IF(Q$4="","",ABS(Q25/Q$4))
B32: Variable Costs | C32: =ABS(C26/$C$4) -> 0.39398348 | G32: =IF(G$4="","",ABS(G26/G$4)) -> 0.37916491 | H32: =IF(H$4="","",ABS(H26/H$4)) -> 0.40880206 | I32: =IF(I$4="","",ABS(I26/I$4)) | J32: =IF(J$4="","",ABS(J26/J$4)) | K32: =IF(K$4="","",ABS(K26/K$4)) | L32: =IF(L$4="","",ABS(L26/L$4)) | M32: =IF(M$4="","",ABS(M26/M$4)) | N32: =IF(N$4="","",ABS(N26/N$4)) | ... Q32: =IF(Q$4="","",ABS(Q26/Q$4))
B34: Fixed Costs
B35: G&A and other Opex | C35: =G35 -> -20684476 | G35: =IF(G4="","",Data!C41) -> -20684476 | H35: =IF(H4="","",Data!D41) -> -19536770 | I35: =IF(I4="","",Data!E41) | J35: =IF(J4="","",Data!F41) | K35: =IF(K4="","",Data!G41) | L35: =IF(L4="","",Data!H41) | M35: =IF(M4="","",Data!I41) | N35: =IF(N4="","",Data!J41) | ... Q35: =IF(Q4="","",Data!M41)
B37: Fixed Costs % of Sales
B38: G&A and other Opex | C38: =ABS(C35/$C$4) -> 0.49127084 | G38: =IF(G$4="","",ABS(G35/G$4)) -> 0.48379435 | H38: =IF(H$4="","",ABS(H35/H$4)) -> 0.47129535 | I38: =IF(I$4="","",ABS(I35/I$4)) | J38: =IF(J$4="","",ABS(J35/J$4)) | K38: =IF(K$4="","",ABS(K35/K$4)) | L38: =IF(L$4="","",ABS(L35/L$4)) | M38: =IF(M$4="","",ABS(M35/M$4)) | N38: =IF(N$4="","",ABS(N35/N$4)) | ... Q38: =IF(Q$4="","",ABS(Q35/Q$4))
B40: Tax % of Pre-tax Profit
B41: Income Tax Rate | C41: 0.25 | E41: Use the marginal tax rate | G41: =IF(G$4="","",-G14/SUM(G8+G11,G12)) -> 0.33238647 | H41: =IF(H$4="","",-H14/SUM(H8+H11,H12)) -> 0.27902127 | I41: =IF(I$4="","",-I14/SUM(I8+I11,I12)) | J41: =IF(J$4="","",-J14/SUM(J8+J11,J12)) | K41: =IF(K$4="","",-K14/SUM(K8+K11,K12)) | L41: =IF(L$4="","",-L14/SUM(L8+L11,L12)) | M41: =IF(M$4="","",-M14/SUM(M8+M11,M12)) | N41: =IF(N$4="","",-N14/SUM(N8+N11,N12)) | ... Q41: =IF(Q$4="","",-Q14/SUM(Q8+Q11,Q12))
B43: Non-operating Income | E43: Notes
B44: Interest
B45: Interest Expense | C45: =-BS!G31*Normalized_FCF!C52 -> -154206.15 | G45: =Data!C51 -> -274678 | H45: =Data!D51 -> -351430 | I45: =Data!E51 | J45: =Data!F51 | K45: =Data!G51 | L45: =Data!H51 | M45: =Data!I51 | N45: =Data!J51 | ... Q45: =Data!M51
B46: Operating Interest Income | C46: =BS!D75*C51 -> 62121.272 | G46: =IFERROR(IF(G$4="","",($C$46/$C$47)*G47),0) -> 151540.68 | H46: =IFERROR(IF(H$4="","",($C$46/$C$47)*H47),0) -> 129364.38 | I46: =IFERROR(IF(I$4="","",($C$46/$C$47)*I47),0) | J46: =IFERROR(IF(J$4="","",($C$46/$C$47)*J47),0) | K46: =IFERROR(IF(K$4="","",($C$46/$C$47)*K47),0) | L46: =IFERROR(IF(L$4="","",($C$46/$C$47)*L47),0) | M46: =IFERROR(IF(M$4="","",($C$46/$C$47)*M47),0) | N46: =IFERROR(IF(N$4="","",($C$46/$C$47)*N47),0) | ... Q46: =IFERROR(IF(Q$4="","",($C$46/$C$47)*Q47),0)
...

Sheet DCF
B2: No-Growth DCF Valuation
B3: No-Growth DCF | C3: =scaling_factor -> 1000 | E3: Normalized Values
B4: Normalized FCFE | C4: =Normalized_FCF!C19 -> 3593208.1 | D4: =Reporting_currency -> CNY | E4: Stage | F4: I | H4: Stage | I4: =IF(I6=F6,"I","II") -> I
B5: /Equity Cost of Capital | C5: =Equity_Cost -> 0.075 | E5: Revenues | F5: =Normalized_FCF!C4 -> 42104018 | H5: Change year | I5: =IF(I4="II",_xlfn.CEILING.MATH(C17/2),C17+1) -> 6
B6: Stable Income Value | C6: =(C4*(1+Terminal_Growth))/(Equity_Cost-Terminal_Growth) -> 47909441 | D6: =Reporting_currency -> CNY | E6: Contribution Margin | F6: =Normalized_FCF!C32 -> 0.39398348 | H6: Contribution Margin_II | I6: =Scenarios!C64 -> 0.39398348
B7: - Interest-bearing Debt | C7: =BS!G31 -> 6168246 | D7: =Reporting_currency -> CNY | E7: Fixed Costs | F7: =Normalized_FCF!C7 -> -20684476 | H7: High Growth Rate_II | I7: =IF(I4="II",C16/2,C16) -> 0.052329465
B8: + Non-operating Cash | C8: =BS!D66 -> 4742604.4 | D8: =Reporting_currency -> CNY | E8: D&A - Maintenance Capx | F8: =Normalized_FCF!C75-Normalized_FCF!C76 -> 0
B9: + Other Non-operating Assets | C9: =BS!H42 -> 2656436.4 | D9: =Reporting_currency -> CNY | E9: Other Income | F9: =Normalized_FCF!C11+Normalized_FCF!C12 -> -40309.878 | H9: Special Assumption
B10: Equity Value | C10: =C6-C7+C8+C9 -> 49140236 | D10: =Reporting_currency -> CNY | E10: Tax rate | F10: =Normalized_FCF!C41 -> 0.25 | H10: Terminal Growth Rate (g): | I10: =Terminal_Growth -> 0
B11: * Exchange rate | C11: =Exchange_Rate -> 1.0923594 | D11: =Thesis!C15 -> CNY/HKD
B12: Equity Value per share | C12: =(C10*scaling_factor)/Common_Shares*Exchange_Rate -> 9.6302115 | D12: =Market_currency -> HKD | E12: Note on g=0: It's to avoid overestimating the stock’s value, especially if future growth is uncertain or unreliable.
B14: Implied Growth Scenario Analysis
B15: FCFE Projection
B16: High Growth Rate (HGR) | C16: =Scenarios!C70 -> 0.052329465
B17: High Growth Period (HGP) | C17: =Scenarios!C69 -> 5
B18: Value Per Share | C18: =(I52-C7+C8+C9)*Exchange_Rate/Common_Shares*scaling_factor -> 12.005184 | D18: =Market_currency -> HKD
A20: Stage | B20: Year | C20: Revenues | D20: Contribution Margin | E20: Fixed Costs | F20: FCFE | G20: Growth Rates | H20: Discount Factor | I20: PV of FCFE
A21: =IF($C$17<B21,"",IF(B21>=$I$5,"II","I")) -> I | B21: 1 | C21: =F5*(1+G21) -> 44307298 | D21: =$F$6 -> 0.39398348 | E21: =F7*(1+G21) -> -21766884 | F21: =(C21*(1-(D21+$F$8))+E21+$F$9)*(1-$F$10) -> 3782820.8 | G21: =IF(A21="",0,IF(A21="I",$C$16,$I$7)) -> 0.052329465 | H21: =IF($C$17<B21,0,1/(1+Equity_Cost)^B21) -> 0.93023256 | I21: =F21*H21 -> 3518903.1
A22: =IF($C$17<B22,"",IF(B22>=$I$5,"II","I")) -> I | B22: 2 | C22: =IF(A22="",0,C21*(1+G22)) -> 46625875 | D22: =IF($C$17<B22,0,IF(B22>=$I$5,$I$6,$F$6)) -> 0.39398348 | E22: =IF(A22="",0,E21*(1+G22)) -> -22905933 | F22: =IF(A22="", 0,(C22*(1-(D22+$F$8))+E22+$F$9)*(1-$F$10)) -> 3982355.8 | G22: =IF(A22="",0,IF(A22="I",$C$16,$I$7)) -> 0.052329465 | H22: =IF($C$17<B22,0,1/(1+Equity_Cost)^B22) -> 0.86533261 | I22: =F22*H22 -> 3446062.4
A23: =IF($C$17<B23,"",IF(B23>=$I$5,"II","I")) -> I | B23: 3 | C23: =IF(A23="",0,C22*(1+G23)) -> 49065783 | D23: =IF($C$17<B23,0,IF(B23>=$I$5,$I$6,$F$6)) -> 0.39398348 | E23: =IF(A23="",0,E22*(1+G23)) -> -24104588 | F23: =IF(A23="", 0,(C23*(1-(D23+$F$8))+E23+$F$9)*(1-$F$10)) -> 4192332.4 | G23: =IF(A23="",0,IF(A23="I",$C$16,$I$7)) -> 0.052329465 | H23: =IF($C$17<B23,0,1/(1+Equity_Cost)^B23) -> 0.80496057 | I23: =F23*H23 -> 3374662.3
A24: =IF($C$17<B24,"",IF(B24>=$I$5,"II","I")) -> I | B24: 4 | C24: =IF(A24="",0,C23*(1+G24)) -> 51633369 | D24: =IF($C$17<B24,0,IF(B24>=$I$5,$I$6,$F$6)) -> 0.39398348 | E24: =IF(A24="",0,E23*(1+G24)) -> -25365968 | F24: =IF(A24="", 0,(C24*(1-(D24+$F$8))+E24+$F$9)*(1-$F$10)) -> 4413297 | G24: =IF(A24="",0,IF(A24="I",$C$16,$I$7)) -> 0.052329465 | H24: =IF($C$17<B24,0,1/(1+Equity_Cost)^B24) -> 0.74880053 | I24: =F24*H24 -> 3304679.1
A25: =IF($C$17<B25,"",IF(B25>=$I$5,"II","I")) -> I | B25: 5 | C25: =IF(A25="",0,C24*(1+G25)) -> 54335315 | D25: =IF($C$17<B25,0,IF(B25>=$I$5,$I$6,$F$6)) -> 0.39398348 | E25: =IF(A25="",0,E24*(1+G25)) -> -26693356 | F25: =IF(A25="", 0,(C25*(1-(D25+$F$8))+E25+$F$9)*(1-$F$10)) -> 4645824.5 | G25: =IF(A25="",0,IF(A25="I",$C$16,$I$7)) -> 0.052329465 | H25: =IF($C$17<B25,0,1/(1+Equity_Cost)^B25) -> 0.69655863 | I25: =F25*H25 -> 3236089.2
A26: =IF($C$17<B26,"",IF(B26>=$I$5,"II","I")) | B26: 6 | C26: =IF(A26="",0,C25*(1+G26)) -> 0 | D26: =IF($C$17<B26,0,IF(B26>=$I$5,$I$6,$F$6)) -> 0 | E26: =IF(A26="",0,E25*(1+G26)) -> 0 | F26: =IF(A26="", 0,(C26*(1-(D26+$F$8))+E26+$F$9)*(1-$F$10)) -> 0 | G26: =IF(A26="",0,IF(A26="I",$C$16,$I$7)) -> 0 | H26: =IF($C$17<B26,0,1/(1+Equity_Cost)^B26) -> 0 | I26: =F26*H26 -> 0
A27: =IF($C$17<B27,"",IF(B27>=$I$5,"II","I")) | B27: 7 | C27: =IF(A27="",0,C26*(1+G27)) -> 0 | D27: =IF($C$17<B27,0,IF(B27>=$I$5,$I$6,$F$6)) -> 0 | E27: =IF(A27="",0,E26*(1+G27)) -> 0 | F27: =IF(A27="", 0,(C27*(1-(D27+$F$8))+E27+$F$9)*(1-$F$10)) -> 0 | G27: =IF(A27="",0,IF(A27="I",$C$16,$I$7)) -> 0 | H27: =IF($C$17<B27,0,1/(1+Equity_Cost)^B27) -> 0 | I27: =F27*H27 -> 0
A28: =IF($C$17<B28,"",IF(B28>=$I$5,"II","I")) | B28: 8 | C28: =IF(A28="",0,C27*(1+G28)) -> 0 | D28: =IF($C$17<B28,0,IF(B28>=$I$5,$I$6,$F$6)) -> 0 | E28: =IF(A28="",0,E27*(1+G28)) -> 0 | F28: =IF(A28="", 0,(C28*(1-(D28+$F$8))+E28+$F$9)*(1-$F$10)) -> 0 | G28: =IF(A28="",0,IF(A28="I",$C$16,$I$7)) -> 0 | H28: =IF($C$17<B28,0,1/(1+Equity_Cost)^B28) -> 0 | I28: =F28*H28 -> 0
A29: =IF($C$17<B29,"",IF(B29>=$I$5,"II","I")) | B29: 9 | C29: =IF(A29="",0,C28*(1+G29)) -> 0 | D29: =IF($C$17<B29,0,IF(B29>=$I$5,$I$6,$F$6)) -> 0 | E29: =IF(A29="",0,E28*(1+G29)) -> 0 | F29: =IF(A29="", 0,(C29*(1-(D29+$F$8))+E29+$F$9)*(1-$F$10)) -> 0 | G29: =IF(A29="",0,IF(A29="I",$C$16,$I$7)) -> 0 | H29: =IF($C$17<B29,0,1/(1+Equity_Cost)^B29) -> 0 | I29: =F29*H29 -> 0
A30: =IF($C$17<B30,"",IF(B30>=$I$5,"II","I")) | B30: 10 | C30: =IF(A30="",0,C29*(1+G30)) -> 0 | D30: =IF($C$17<B30,0,IF(B30>=$I$5,$I$6,$F$6)) -> 0 | E30: =IF(A30="",0,E29*(1+G30)) -> 0 | F30: =IF(A30="", 0,(C30*(1-(D30+$F$8))+E30+$F$9)*(1-$F$10)) -> 0 | G30: =IF(A30="",0,IF(A30="I",$C$16,$I$7)) -> 0 | H30: =IF($C$17<B30,0,1/(1+Equity_Cost)^B30) -> 0 | I30: =F30*H30 -> 0
A31: =IF($C$17<B31,"",IF(B31>=$I$5,"II","I")) | B31: 11 | C31: =IF(A31="",0,C30*(1+G31)) -> 0 | D31: =IF($C$17<B31,0,IF(B31>=$I$5,$I$6,$F$6)) -> 0 | E31: =IF(A31="",0,E30*(1+G31)) -> 0 | F31: =IF(A31="", 0,(C31*(1-(D31+$F$8))+E31+$F$9)*(1-$F$10)) -> 0 | G31: =IF(A31="",0,IF(A31="I",$C$16,$I$7)) -> 0 | H31: =IF($C$17<B31,0,1/(1+Equity_Cost)^B31) -> 0 | I31: =F31*H31 -> 0
A32: =IF($C$17<B32,"",IF(B32>=$I$5,"II","I")) | B32: 12 | C32: =IF(A32="",0,C31*(1+G32)) -> 0 | D32: =IF($C$17<B32,0,IF(B32>=$I$5,$I$6,$F$6)) -> 0 | E32: =IF(A32="",0,E31*(1+G32)) -> 0 | F32: =IF(A32="", 0,(C32*(1-(D32+$F$8))+E32+$F$9)*(1-$F$10)) -> 0 | G32: =IF(A32="",0,IF(A32="I",$C$16,$I$7)) -> 0 | H32: =IF($C$17<B32,0,1/(1+Equity_Cost)^B32) -> 0 | I32: =F32*H32 -> 0
A33: =IF($C$17<B33,"",IF(B33>=$I$5,"II","I")) | B33: 13 | C33: =IF(A33="",0,C32*(1+G33)) -> 0 | D33: =IF($C$17<B33,0,IF(B33>=$I$5,$I$6,$F$6)) -> 0 | E33: =IF(A33="",0,E32*(1+G33)) -> 0 | F33: =IF(A33="", 0,(C33*(1-(D33+$F$8))+E33+$F$9)*(1-$F$10)) -> 0 | G33: =IF(A33="",0,IF(A33="I",$C$16,$I$7)) -> 0 | H33: =IF($C$17<B33,0,1/(1+Equity_Cost)^B33) -> 0 | I33: =F33*H33 -> 0
... A50: =IF($C$17<B50,"",IF(B50>=$I$5,"II","I")) | B50: 30 | C50: =IF(A50="",0,C49*(1+G50)) -> 0 | D50: =IF($C$17<B50,0,IF(B50>=$I$5,$I$6,$F$6)) -> 0 | E50: =IF(A50="",0,E49*(1+G50)) -> 0 | F50: =IF(A50="", 0,(C50*(1-(D50+$F$8))+E50+$F$9)*(1-$F$10)) -> 0 | G50: =IF(A50="",0,IF(A50="I",$C$16,$I$7)) -> 0 | H50: =IF($C$17<B50,0,1/(1+Equity_Cost)^B50) -> 0 | I50: =F50*H50 -> 0
B51: Terminal Year | C51: =VLOOKUP(C17,B21:C50,2,FALSE)*(1+Terminal_Growth) -> 54335315 | D51: =I6 -> 0.39398348 | E51: =VLOOKUP(C17,B21:E50,4,FALSE)*(1+Terminal_Growth) -> -26693356 | F51: =(C51*(1-(D51+$F$8))+E51+$F$9)*(1-$F$10)/Equity_Cost -> 61944327 | G51: =Terminal_Growth -> 0 | H51: =1/(1+Equity_Cost)^C17 -> 0.69655863 | I51: =F51*H51 -> 43147856
H52: Total PV | I52: =SUM(I21:I51) -> 60028252
B54: Sensitivity Analysis (Enterprise Value)
A55: =I52 -> 60028252 | B55: =C78 -> 0 | C55: =C77 -> 0.02 | D55: =C76 -> 0.05 | E55: =C75 -> 0.08 | F55: =C74 -> 0.12
A56: 5 | B56: 47909441 | C56: 52270987 | D56: 59438716 | E56: 67415063 | F56: 79427561
A57: 10 | B57: 47909441 | C57: 55625264 | D57: 69688298 | E57: 87378543 | F57: 1.181184e+08
A58: 15 | B58: 47909441 | C58: 58204895 | D58: 78800227 | E58: 1.0781063e+08 | F58: 1.6561427e+08
A59: 20 | B59: 47909441 | C59: 60188777 | D59: 86900777 | E59: 1.2872232e+08 | F59: 2.2391899e+08
A60: 25 | B60: 47909441 | C60: 61714496 | D60: 94102206 | E60: 1.5012488e+08 | F60: 2.9549236e+08
...

Sheet Scenarios
B2: Current Situation | H2: Warning: Do Not Remove this logic*
B3: Selection | H3: 0 | I3: =-Market_Price -> -13.11
B4: Past Years Selected | C4: 3 | E4: Tie the business story into the three levers of value: FCFE, growth and risk. | H4: 1 | I4: =IF(ROW()-3 < $C$81, $C$82, IF(ROW()-3 = $C$81, $C$82 + $C$60, "")) -> 0
H5: 2 | I5: =IF(ROW()-3 < $C$81, $C$82, IF(ROW()-3 = $C$81, $C$82 + $C$60, "")) -> 0
B6: Latest | C6: =DCF!C3 -> 1000 | E6: Prompt for fundamental Analysis | H6: 3 | I6: =IF(ROW()-3 < $C$81, $C$82, IF(ROW()-3 = $C$81, $C$82 + $C$60, "")) -> 12.001067
B7: EBIT | C7: =Normalized_FCF!G8 -> 5859134 | D7: =Reporting_currency -> CNY | E7: ="Please develop three logical "&C18&"-year scenarios (Base Case, Pessimistic Case, Optimistic Case) and two extreme "&C46&"-year scenarios (Success Scenario, Devil’s Advocate Scenario) for "&Thesis!C5&"("&Thesis!C11&"). Each scenario should include the Compound Growth Rate, the Probability Assessment, and the Business Narrative." -> Please develop three logical 5-year scenarios (Base Case, Pessimistic Case, Optimistic Case) and two extreme 5-year scenarios (Success Scenario, Devil’s Advocate Scenario) for 海底捞(6862.HK). Each scenario should include the Compound Growth Rate, the Probability Assessment, and the Business Narrative. | H7: 4 | I7: =IF(ROW()-3 < $C$81, $C$82, IF(ROW()-3 = $C$81, $C$82 + $C$60, ""))
B8: FCFE | C8: =Normalized_FCF!G19 -> 3856188.7 | D8: =Reporting_currency -> CNY | H8: 5 | I8: =IF(ROW()-3 < $C$81, $C$82, IF(ROW()-3 = $C$81, $C$82 + $C$60, ""))
B9: Normalized | C9: =Normalized_FCF!C19 -> 3593208.1 | D9: =Reporting_currency -> CNY | H9: 6 | I9: =IF(ROW()-3 < $C$81, $C$82, IF(ROW()-3 = $C$81, $C$82 + $C$60, ""))
H10: 7 | I10: =IF(ROW()-3 < $C$81, $C$82, IF(ROW()-3 = $C$81, $C$82 + $C$60, ""))
B11: YoY CAGR | H11: 8 | I11: =IF(ROW()-3 < $C$81, $C$82, IF(ROW()-3 = $C$81, $C$82 + $C$60, ""))
B12: Sales | C12: =(Normalized_FCF!G4/OFFSET(Normalized_FCF!G4, 0, $C$4))^(1/$C$4) - 1 -> #VALUE! | H12: 9 | I12: =IF(ROW()-3 < $C$81, $C$82, IF(ROW()-3 = $C$81, $C$82 + $C$60, ""))
B13: Operating EBIT | C13: =(Normalized_FCF!G8/OFFSET(Normalized_FCF!G8, 0, $C$4))^(1/$C$4) - 1 -> #VALUE! | H13: 10 | I13: =IF(ROW()-3 < $C$81, $C$82, IF(ROW()-3 = $C$81, $C$82 + $C$60, ""))
B14: FCFE | C14: =(Normalized_FCF!G19/OFFSET(Normalized_FCF!G19, 0, $C$4))^(1/$C$4) - 1 -> #VALUE! | H14: *It calculates Annual Return
B16: General Scenarios
B17: Assumption | E17: Guidance Note
B18: High Growth Period (HGP) | C18: 5 | E18: Fundamental analysis and market signal analysis should be combined, with fundamental analysis given priority and market signal analysis serving as a supplement. Market signal analysis predicts a company's future trend, while fundamental analysis interprets the trend and identifies relevant fundamental factors and possibilities.
B20: Reference
B21: Market Price | C21: =Market_Price -> 13.11 | D21: =Market_currency -> HKD
B22: No Growth Value per share | C22: =IF(valuation_method="DCF",DCF!C12,#REF!) -> 9.6302115 | D22: =Market_currency -> HKD
B24: Base | E24: Business Story
B25: High Growth Period (HGP) | C25: =C18 -> 5
B26: High Growth Rate (HGR) | C26: 0.05
B27: Value per share | C27: =IF(valuation_method="DCF",DCF!E76,#REF!) -> 11.88965 | D27: =Market_currency -> HKD
B28: Probabilities | C28: 0.6
B30: Pessimistic | E30: Business Story
B31: High Growth Period (HGP) | C31: =C18 -> 5
B32: High Growth Rate (HGR) | C32: 0.02
B33: Value per share | C33: =IF(valuation_method="DCF",DCF!E77,#REF!) -> 10.484961 | D33: =Market_currency -> HKD
B34: Probabilities | C34: 0.2
B36: Optimistic | E36: Business Story
B37: High Growth Period (HGP) | C37: =C18 -> 5
B38: High Growth Rate (HGR) | C38: 0.08
B39: Value per share | C39: =IF(valuation_method="DCF",DCF!E75,#REF!) -> 13.452807 | D39: =Market_currency -> HKD
B40: Probabilities | C40: =1-C28-C34 -> 0.2
B42: Expected Value = | C42: =C27*C28+C33*C34+C39*C40 -> 11.921344 | D42: =Market_currency -> HKD
B44: Extreme Scenarios
B45: Assumption
B46: High Growth Period (HGP) | C46: =C18 -> 5
B48: Devil's advocate | E48: Business Story
B49: High Growth Period (HGP) | C49: =C46 -> 5
...

Sheet Breakdown
B2: Divisional Analysis (Optional)

Sheet 投资主题
B1: 模型最后更新日期: | C1: =Thesis!C1 -> 45917 | D1: =Thesis!D1 -> INT | E1: Selected: | F1: =Thesis!F1 -> N
A2: 执行摘要
B4: 公司信息
B5: 公司名称： | C5: =Thesis!C5 -> 海底捞
B6: 股份数量： | C6: =Common_Shares -> 5574000000
B7: 报告间隔： | C7: =Thesis!C7 -> 6
B8: 下次更新日期： | C8: =EOMONTH(EDATE(BS!C1,C7+2),0) -> 46265
B10: 上市信息
B11: 股票代码： | C11: =Thesis!C11 -> 6862.HK
B12: 市场价格： | C12: =Market_Price -> 13.11
B13: 市价货币： | C13: =Market_currency -> HKD
B14: 市值： | C14: =投资主题!C12*Common_Shares/1000000 -> 73075.14 | D14: =IF(D11="","",投资主题!D12*Common_Shares/1000000)
B15: 外汇符号： | C15: =IF(C25=C13,C13,C25&"/"&C13) -> CNY/HKD | D15: =IF(D11="","",IF(C25=D13,D13,C25&"/"&D13))
B16: 汇率： | C16: =Exchange_Rate -> 1.0923594
B18: 指导说明：该模型使用结构化的投资流程来评估公司，确定其内在价值和目标价格。它关注可持续的自由现金流（FCF）能力，调整财务结构，纳入增长情景，并根据得出的内在价值计算预期回报。
B20: 估值概述
B21: 增长分类: | C21: =IF(Scenarios!C74="Y",Scenarios!B74,"")&IF(Scenarios!C75="Y",Scenarios!B75,"")&IF(Scenarios!C76="Y",Scenarios!B76,"")&" "&IF(Scenarios!C77="Y",Scenarios!B77,"") -> Low Growth | D21: 估值方法 | E21: =valuation_method -> DCF
B22: 对比板块: | C22: =Thesis!C22 -> CNS_01 | D22: =IF(valuation_method="DDM","终值贴现率","") | E22: =Thesis!E22 -> 0
B23: 商业模式风险溢价: | C23: =Thesis!C23 -> N
B24: 管理风险溢价: | C24: =Thesis!C24 -> N
B25: 报告货币: | C25: =Reporting_currency -> CNY | D25: =IF(D11="","",Market_currency&"/"&D13&":") | E25: =IF(D11="","",1/Exchange_Rate*D16)
B26: ="预期股权价值 ("&C13&") :" -> 预期股权价值 (HKD) : | C26: =C132 -> 12.001067 | D26: 市场隐含年回报率: | E26: =Scenarios!C92 -> -0.029030191
B28: 估值输出 | C28: =C145&" ("&Market_currency&")" -> 6862.HK (HKD) | D28: =IF(D11="","",D145&" ("&D13&")") | E28: 持有期 | F28: =Thesis!E25 -> 3
B29: 目标价格 | C29: =C149 -> 4.8777391 | D29: =D149 | E29: 目标回报率 | F29: =Thesis!E29 -> 0.35
B30: 入场价格 | C30: =C157 -> 6.1445465 | D30: =D157 | E30: 入场收益率 | F30: =Thesis!E30 -> 0.25
B31: 卖出价格 | C31: =C165 -> 9.660386 | D31: =D165 | E31: 基础Equity Cost | F31: =Thesis!E24 -> 0.075
B32: 退出价格 | C32: =C173 -> 8.6018897 | D32: =D173 | E32: 基准收益率 | F32: =Thesis!E31 -> 0.1174
A34: 步骤1：确定公司可持续盈利能力（计算标准化FCFE）
B36: 目标：量化业务持续生成的潜在自由现金流（FCFE），去除临时波动或会计选择的影响。
B37: FCFE = (Normalized Operating EBIT + Depreciation & Amortization – Capital Expenditures) + Stable Non-Operating EBIT + Net Interest Income – Taxes – NCI’s Share of Profits – Working Capital Investment
B39: 关键组成部分 | C39: =scaling_factor -> 1000
B40: • Normalized Operating EBIT：核心业务运营的税前息前利润，调整以剔除一次性或非经常性项目，形成可持续盈利基础。
B41: Normalized Operating EBIT = | C41: =Normalized_FCF!C8 -> 4831254 | D41: =Reporting_currency -> CNY
B43: • Depreciation & Amortization (D&A): 非现金费用，加入以反映运营产生的现金。 • Capital Expenditures (Capex): 维持或扩展运营资产所需的现金流出。
B44: D&A = | C44: =Normalized_FCF!C9 -> 0 | D44: =Reporting_currency -> CNY
B45: Capex = | C45: =Normalized_FCF!C10 -> 0 | D45: =Reporting_currency -> CNY
B47: • Stable Non-Operating EBIT: 来自非核心资产的持续收益，如固定收益投资、支付股息的股票或租赁物业。
B48: Stable Non-Operating EBIT = | C48: =Normalized_FCF!C11 -> 51775 | D48: =Reporting_currency -> CNY
B50: • Net Interest Income: 利息收入减去利息支出
B51: Operating Interest Income = | C51: =Normalized_FCF!C46 -> 62121.272 | D51: =Reporting_currency -> CNY
...
