Workbook
Name Common_Shares: Thesis!$C$6
Name dividend_tax_rate: Normalized_FCF!$C$93
Name Equity_Cost: Thesis!$C$86
Name Exchange_Rate: Thesis!$C$16
Name Market_currency: Thesis!$C$13
Name Market_Price: Thesis!$C$12
Name Reporting_currency: Thesis!$C$25
Name scaling_factor: Data!$C$3
Name Terminal_Growth: Thesis!$C$92
Name valuation_method: Thesis!$E$21

Sheet Thesis
B1: Model last updated: | C1: 45874 | D1: INT | E1: Selected: | F1: N
A2: Executive Summary
B4: Company Information
B5: Company Name: | C5: lululemon athletica inc.
B6: Number of Shares: | C6: =114729430+5115961 -> 119845391
B7: Report Interval: | C7: 6
B8: Update Required After: | C8: =EOMONTH(EDATE(BS!C1,C7+2),0) -> 46053
B10: Listing Information
B11: Symbol: | C11: LULU
B12: Market Price: | C12: 196.45
B13: Market Currency: | C13: USD
B14: Market Capitalization: | C14: =Thesis!C12*Common_Shares/1000000 -> 23543.627 | D14: =IF(D11="","",Thesis!D12*Common_Shares/1000000)
B15: Forex Symbol: | C15: =IF(C25=C13,C13,C25&"/"&C13) -> USD | D15: =IF(D11="","",IF(C25=D13,D13,C25&"/"&D13))
B16: Exchange Rate: | C16: 1
B18: Guidance Note: This model evaluates the company using a structured investment process to determine its intrinsic value and target prices. It focuses on sustainable FCF capacity, adjusts for financial structure, incorporates growth scenarios, and calculates expected returns based on the derived intrinsic value.
B20: Valuation Overview
B21: Growth Classification: | C21: =IF(Scenarios!C69="Y",Scenarios!B69,"")&IF(Scenarios!C70="Y",Scenarios!B70,"")&IF(Scenarios!C71="Y",Scenarios!B71,"")&" "&IF(Scenarios!C72="Y",Scenarios!B72,"") -> Low Growth | D21: Valuation Method | E21: DCF
B22: Comp_Sector: | C22: CNS_02 | D22: =IF(valuation_method="DDM","Terminal Value Discount Rate","")
B23: Business Model Risk Premium: | C23: N
B24: Management Risk Premium: | C24: N
B25: Reporting Currency: | C25: USD | D25: =IF(D11="","",Market_currency&"/"&D13&":") | E25: =IF(D11="","",1/Exchange_Rate*D16)
B26: ="Expected Equity Value ("&C13&") :" -> Expected Equity Value (USD) : | C26: =C132 -> 177.33733 | D26: Market Implied Annual Return: | E26: =Scenarios!C87 -> -0.033542605
B28: Valuation Outputs | C28: =C145&" ("&Market_currency&")" -> LULU (USD) | D28: =IF(D11="","",D145&" ("&D13&")") | E28: Holding Period | F28: 3
B29: Target Price | C29: =C149 -> 72.077359 | D29: =D149 | E29: Target return | F29: 0.35
B30: Entry Price | C30: =C157 -> 90.796715 | D30: =D157 | E30: Entry yield | F30: 0.25
B31: Sell Price | C31: =C165 -> 142.74956 | D31: =D165 | E31: Base equity cost | F31: 0.075
B32: Exit Price | C32: =C173 -> 127.10838 | D32: =D173 | E32: Benchmark yield | F32: 0.1174
A34: Step 1: Establishing the Company’s Sustainable Earning Power (Calculating Normalized FCFE)
B36: Goal: To quantify the underlying FCFE the business consistently generates, stripping away temporary fluctuations or accounting choices.
B37: FCFE = (Normalized Operating EBIT + Depreciation & Amortization – Capital Expenditures) + Stable Non-Operating EBIT + Net Interest Income – Taxes – NCI’s Share of Profits – Working Capital Investment
B39: Key Components | C39: =scaling_factor -> 1000
B40: • Normalized Operating EBIT: Earnings before interest and taxes from core business operations, adjusted to remove one-time or irregular items for a sustainable earnings base.
B41: Normalized Operating EBIT = | C41: =Normalized_FCF!C8 -> 2062510.7 | D41: =Reporting_currency -> USD
B43: • Depreciation & Amortization (D&A): Non-cash expenses added back to reflect cash generated from operations. • Capital Expenditures (Capex): Cash outflows required to maintain or expand operational assets
B44: D&A = | C44: =Normalized_FCF!C9 -> 0 | D44: =Reporting_currency -> USD
B45: Capex = | C45: =Normalized_FCF!C10 -> 0 | D45: =Reporting_currency -> USD
B47: • Stable Non-Operating EBIT: Consistent earnings from non-core assets, such as fixed-income investments, dividend-paying stocks, or rental properties.
B48: Stable Non-Operating EBIT = | C48: =Normalized_FCF!C11 -> 0 | D48: =Reporting_currency -> USD
B50: • Net Interest Income: Interest income minus interest expense
B51: Operating Interest Income = | C51: =Normalized_FCF!C48 -> 0 | D51: =Reporting_currency -> USD
...

Sheet Data
B1: =Thesis!C25 -> USD | C1: 45688 | D1: =EOMONTH(EDATE(C1,-12),0) -> 45322 | E1: =EOMONTH(EDATE(D1,-12),0) -> 44957 | F1: =EOMONTH(EDATE(E1,-12),0) -> 44592 | G1: =EOMONTH(EDATE(F1,-12),0) -> 44227 | H1: =EOMONTH(EDATE(G1,-12),0) -> 43861 | I1: =EOMONTH(EDATE(H1,-12),0) -> 43496 | J1: =EOMONTH(EDATE(I1,-12),0) -> 43131 | K1: =EOMONTH(EDATE(J1,-12),0) -> 42766 | ... M1: =EOMONTH(EDATE(L1,-12),0) -> 42035
B2: Data (Dirty)
B3: Income Statement | C3: 1000
B4: Sales | C4: 10588126 | D4: 9619278 | E4: 8110518 | F4: 6256617 | G4: 4401879 | H4: 3979296 | I4: 3288319 | J4: 2649181 | K4: 2344392 | L4: 2060523
B5: COGS | C5: 4317315 | D5: 4009873 | E5: 3618178 | F5: 2648052 | G5: 1937888 | H5: 1755910 | I5: 1472032 | J5: 1250391 | K5: 1144775 | L5: 1063357
B6: OPEX | C6: 3762379 | D6: 3397218 | E6: 2757447 | F6: 2225034 | G6: 1609003 | H6: 1334276 | I6: 1110451 | J6: 904264 | K6: 778465 | L6: 628090
B7: Incl. Selling Expenses
B8: R&D
B9: Share of JV or associate Results
B10: Dividend or Interests from FA
B11: Investment property
B12: Interest Expense
B13: Interest Income
B14: Income Tax Paid | C14: 761461 | D14: 625545 | E14: 477771 | F14: 358547 | G14: 230437 | H14: 251797 | I14: 231449 | J14: 201336 | K14: 119348 | L14: 102448
B15: Reported Net Income | C15: 1814616 | D15: 1550190 | E15: 854800 | F15: 975322 | G15: 588913 | H15: 645596 | I15: 483801 | J15: 258662 | K15: 303381 | L15: 266047
B16: Non-controling Interests
B18: Cash Flow Statement
B19: D&A
B20: CAPX
B21: WCInv
B22: CFO | C22: 2272713 | D22: 2296164 | E22: 966463 | F22: 1389108 | G22: 803336 | H22: 669316 | I22: 742779 | J22: 489337 | K22: 385119 | L22: 298740
B23: CFI | C23: -798174 | D23: -654132 | E23: -569937 | F23: -427891 | G23: -695532 | H23: -278408 | I23: -242794 | J23: -173392 | K23: -149511 | L23: -143487
B24: CFF | C24: -1652508 | D24: -548828 | E24: -467487 | F24: -844987 | G24: -80788 | H24: -177173 | I24: -590214 | J24: -97862 | K24: -25338 | L24: -273693
B25: ="Dividend per share ("&Market_currency&")" -> Dividend per share (USD)
B27: Balance Sheet | C27: Latest Asset Value
B28: ST AR | C28: =BS!C4 -> 0 | D28: 124769 | E28: 132906 | F28: 77001 | G28: 62399 | H28: 40219 | I28: 35786 | J28: 19173 | K28: 9200 | L28: 13108
B29: ST Inventory | C29: =BS!C6 -> 1652091 | D29: 1323602 | E29: 1447367 | F29: 966481 | G29: 647230 | H29: 518513 | I29: 404842 | J29: 329562 | K29: 298432 | L29: 284009
B30: Total Liabilities | C30: =BS!C33+BS!C42 -> 3140973 | D30: 2859860 | E30: 2458239 | F30: 2202432 | G30: 1626649 | H30: 1329136 | I30: 638736 | J30: 401523 | K30: 297568 | L30: 286595
B31: Total Equity | C31: =BS!G27 -> 4289570 | D31: 4232081 | E31: 3148799 | F31: 2740046 | G31: 2558566 | H31: 1952218 | I31: 1445975 | J31: 1596960 | K31: 1359973 | L31: 1027482
B32: Non-common Interest | C32: =BS!G28 -> 0
B34: IS & CF Statements (Clean)
B35: Income Statement
B36: Sales | C36: =IF(C$4="","",C4) -> 10588126 | D36: =IF(D$4="","",D4) -> 9619278 | E36: =IF(E$4="","",E4) -> 8110518 | F36: =IF(F$4="","",F4) -> 6256617 | G36: =IF(G$4="","",G4) -> 4401879 | H36: =IF(H$4="","",H4) -> 3979296 | I36: =IF(I$4="","",I4) -> 3288319 | J36: =IF(J$4="","",J4) -> 2649181 | ... M36: =IF(M$4="","",M4)
B37: COGS | C37: =IF(C$4="","",-C5) -> -4317315 | D37: =IF(D$4="","",-D5) -> -4009873 | E37: =IF(E$4="","",-E5) -> -3618178 | F37: =IF(F$4="","",-F5) -> -2648052 | G37: =IF(G$4="","",-G5) -> -1937888 | H37: =IF(H$4="","",-H5) -> -1755910 | I37: =IF(I$4="","",-I5) -> -1472032 | J37: =IF(J$4="","",-J5) -> -1250391 | ... M37: =IF(M$4="","",-M5)
B38: Gross Margin | C38: =IF(C36="","",C36+C37) -> 6270811 | D38: =IF(D36="","",D36+D37) -> 5609405 | E38: =IF(E36="","",E36+E37) -> 4492340 | F38: =IF(F36="","",F36+F37) -> 3608565 | G38: =IF(G36="","",G36+G37) -> 2463991 | H38: =IF(H36="","",H36+H37) -> 2223386 | I38: =IF(I36="","",I36+I37) -> 1816287 | J38: =IF(J36="","",J36+J37) -> 1398790 | ... M38: =IF(M36="","",M36+M37)
B39: OPEX | C39: =IF(C$4="","",-C6) -> -3762379 | D39: =IF(D$4="","",-D6) -> -3397218 | E39: =IF(E$4="","",-E6) -> -2757447 | F39: =IF(F$4="","",-F6) -> -2225034 | G39: =IF(G$4="","",-G6) -> -1609003 | H39: =IF(H$4="","",-H6) -> -1334276 | I39: =IF(I$4="","",-I6) -> -1110451 | J39: =IF(J$4="","",-J6) -> -904264 | ... M39: =IF(M$4="","",-M6)
B40: Incl. Selling Expenses | C40: =IF(C$4="","",-C7) -> 0 | D40: =IF(D$4="","",-D7) -> 0 | E40: =IF(E$4="","",-E7) -> 0 | F40: =IF(F$4="","",-F7) -> 0 | G40: =IF(G$4="","",-G7) -> 0 | H40: =IF(H$4="","",-H7) -> 0 | I40: =IF(I$4="","",-I7) -> 0 | J40: =IF(J$4="","",-J7) -> 0 | ... M40: =IF(M$4="","",-M7)
B41: Incl. Other Opex | C41: =IF(C$4="","",C39-C40) -> -3762379 | D41: =IF(D$4="","",D39-D40) -> -3397218 | E41: =IF(E$4="","",E39-E40) -> -2757447 | F41: =IF(F$4="","",F39-F40) -> -2225034 | G41: =IF(G$4="","",G39-G40) -> -1609003 | H41: =IF(H$4="","",H39-H40) -> -1334276 | I41: =IF(I$4="","",I39-I40) -> -1110451 | J41: =IF(J$4="","",J39-J40) -> -904264 | ... M41: =IF(M$4="","",M39-M40)
B42: R&D | C42: =IF(C$4="","",-C8) -> 0 | D42: =IF(D$4="","",-D8) -> 0 | E42: =IF(E$4="","",-E8) -> 0 | F42: =IF(F$4="","",-F8) -> 0 | G42: =IF(G$4="","",-G8) -> 0 | H42: =IF(H$4="","",-H8) -> 0 | I42: =IF(I$4="","",-I8) -> 0 | J42: =IF(J$4="","",-J8) -> 0 | ... M42: =IF(M$4="","",-M8)
B43: Operating EBIT | C43: =IF(C$4="","",C38+C39+C42) -> 2508432 | D43: =IF(D$4="","",D38+D39+D42) -> 2212187 | E43: =IF(E$4="","",E38+E39+E42) -> 1734893 | F43: =IF(F$4="","",F38+F39+F42) -> 1383531 | G43: =IF(G$4="","",G38+G39+G42) -> 854988 | H43: =IF(H$4="","",H38+H39+H42) -> 889110 | I43: =IF(I$4="","",I38+I39+I42) -> 705836 | J43: =IF(J$4="","",J38+J39+J42) -> 494526 | ... M43: =IF(M$4="","",M38+M39+M42)
...

Sheet BS
B1: Most Recent Quarter | C1: 45781 | F1: =IF(MONTH(C1)=MONTH(Normalized_FCF!G1),"FY","Quarter")&" Report" -> Quarter Report | H1: =scaling_factor -> 1000
B2: Lastest Balance Sheet
B3: ST Operating Assets | C3: Book | D3: Valued @ | F3: ST Non-Operating Assets | G3: Book | H3: Valued @
B4: ST AR | C4: 0 | D4: 0.6 | F4: Cash and cash equivalents | G4: 1325272 | H4: 0.9
B5: Operating ST Financial Assets | C5: 0 | D5: 0.6 | F5: Restricted cash | G5: 0 | H5: 0.7
B6: Inventory | C6: 1652091 | D6: 0.5 | F6: Securities with stable income | G6: 0 | H6: 0.6
B7: Properties held for sale | C7: 0 | D7: 0.6 | F7: Other Securities | G7: 0 | H7: 0.6
B8: Properties held for income | C8: 0 | D8: 0.6 | F8: Properties with stable income | G8: 0 | H8: 0.6
B9: Prepayments and Contract Assets | C9: 0 | D9: 0.1 | F9: Other Properties | G9: 0 | H9: 0.6
B10: ST DTA | C10: 230280 | D10: 0.9
B11: Other ST Assets | C11: 374874 | D11: 0.05
B12: Operating ST Assets | C12: =SUM(C4:C11) -> 2257245 | D12: =C4*D4+C5*D5+C9*D9+C6*D6+C8*D8+C7*D7+C10*D10+C11*D11 -> 1052041.2 | F12: Non-Operating ST Assets | G12: =SUM(G4:G9) -> 1325272 | H12: =G4*H4+G5*H5+G6*H6+G7*H7+G8*H8+G9*H9 -> 1192744.8
B14: LT Operating Assets | C14: Book | D14: Valued @ | F14: LT Non-Operating Assets | G14: Book | H14: Valued @
B15: LT AR and Prepayments | C15: 0 | D15: 0.4 | F15: LT Depositis | G15: 0 | H15: 0.8
B16: Operating LT Financial Assets | C16: 0 | D16: 0.5 | F16: Securities with stable income | G16: 0 | H16: 0.6
B17: Properties held for sale | C17: 0 | D17: 0.6 | F17: Other Securities | G17: 0 | H17: 0.6
B18: Properties held for income | C18: 0 | D18: 0.6 | F18: JV or associate with stable income | G18: 0 | H18: 0.1
B19: PP&E & Right of Use Assets | C19: =1846609+1549401 -> 3396010 | D19: 0.1 | F19: Other JV or associate | G19: 0 | H19: 0.1
B20: Biological assets | C20: 0 | D20: 0.05 | F20: Properties with stable income | G20: 0 | H20: 0.2
B21: Intangible assets | C21: 0 | D21: 0.05 | F21: Other Properties | G21: 0 | H21: 0.1
B22: LT DTA | C22: 0 | D22: 0.9
B23: Other assets & Goodwill | C23: =178001+274015 -> 452016 | D23: 0
B24: Operating LT Assets | C24: =SUM(C15:C23) -> 3848026 | D24: =C15*D15+C16*D16+C18*D18+C17*D17+C19*D19+C20*D20+C21*D21+C22*D22+C23*D23 -> 339601 | F24: Non-Operating LT Assets | G24: =SUM(G15:G21) -> 0 | H24: =G15*H15+G16*H16+G17*H17+G18*H18+G19*H19+G20*H20+G21*H21 -> 0
B26: ST Liabilities | C26: Book | F26: BS Summary | G26: Book | H26: Valued @
B27: ST Borrowing | C27: 0 | F27: Total Equity | G27: =G32-G30 -> 4289570 | H27: =H32-G30 -> -556586
B28: ST Lease liabilities | C28: 281837 | F28: Incl. Minority Interest (NCI) | G28: 0
B29: ST SH Loan | C29: 0 | F29: Incl. Common Equity | G29: =G27-G28 -> 4289570 | H29: =H27-G28 -> -556586
B30: ST Financial Liabilities | C30: 0 | F30: Total Liabilities | G30: =C33+C42 -> 3140973
B31: ST Interest-bearing Debt | C31: =SUM(C27:C30) -> 281837 | F31: incl. Interest-bearing Debt | G31: =C31+C40 -> 1706782
B32: Other ST liabilities | C32: =C33-C31 -> 1290548 | F32: Total Assets | G32: =G35+G40 -> 7430543 | H32: =H35+H40 -> 2584387
B33: Current Liabilities | C33: 1572385
F34: Assets Summary | G34: Book | H34: Valued @
B35: LT Liabilities | C35: Book | F35: Operating Assets | G35: =C12+C24 -> 6105271 | H35: =D12+D24 -> 1391642.2
B36: LT Borrowing | C36: 0 | F36: incl. AR | G36: =C4+C15 -> 0
B37: LT Lease liabilities | C37: 1424945 | F37: incl. inventory | G37: =C6 -> 1652091
B38: LT SH Loan | C38: 0 | F38: incl. Properties held for sale | G38: =C7+C17 -> 0
B39: LT Financial Liabilities | C39: 0 | F39: incl. Fixed Assets | G39: =C7+C17+C19+C20 -> 3396010 | H39: =C7*D7+C17*D17+C19*D19+C20*D20 -> 339601
B40: LT Interest-bearing Debt | C40: =SUM(C36:C39) -> 1424945 | F40: Non-operating Assets | G40: =G12+G24 -> 1325272 | H40: =H12+H24 -> 1192744.8
B41: Other LT liabilities | C41: =C42-C40 -> 143643 | F41: incl. Assets with stable income | G41: =C70 -> 1325272 | H41: =H40-H42 -> 1192744.8
B42: Noncurrent Liabilities | C42: =C37+98189+45454 -> 1568588 | F42: incl. Other Assets | G42: =C82 -> 0 | H42: =D82 -> 0
...

Sheet Normalized_FCF
B1: =Thesis!C25 -> USD | C1: Normalized | G1: =Data!C1 -> 45688 | H1: =EOMONTH(EDATE(G1,-12),0) -> 45322 | I1: =EOMONTH(EDATE(H1,-12),0) -> 44957 | J1: =EOMONTH(EDATE(I1,-12),0) -> 44592 | K1: =EOMONTH(EDATE(J1,-12),0) -> 44227 | L1: =EOMONTH(EDATE(K1,-12),0) -> 43861 | M1: =EOMONTH(EDATE(L1,-12),0) -> 43496 | N1: =EOMONTH(EDATE(M1,-12),0) -> 43131 | O1: =EOMONTH(EDATE(N1,-12),0) -> 42766 | ... Q1: =EOMONTH(EDATE(P1,-12),0) -> 42035
B2: FCFE Analysis | E2: Notes
B3: FCFE | C3: =scaling_factor -> 1000
B4: Sales | C4: =AVERAGE(G4:H4) -> 10103702 | G4: =Data!C36 -> 10588126 | H4: =Data!D36 -> 9619278 | I4: =Data!E36 -> 8110518 | J4: =Data!F36 -> 6256617 | K4: =Data!G36 -> 4401879 | L4: =Data!H36 -> 3979296 | M4: =Data!I36 -> 3288319 | N4: =Data!J36 -> 2649181 | ... Q4: =Data!M36
B5: Variable Costs | C5: =C25 -> -4278812.3 | G5: =G25 -> -4317315 | H5: =H25 -> -4009873 | I5: =I25 -> -3618178 | J5: =J25 -> -2648052 | K5: =K25 -> -1937888 | L5: =L25 -> -1755910 | M5: =M25 -> -1472032 | N5: =N25 -> -1250391 | ... Q5: =Q25
B6: Contribution Margin | C6: =C4+C5 -> 5824889.7 | G6: =IF(G4="","",G4+G5) -> 6270811 | H6: =IF(H4="","",H4+H5) -> 5609405 | I6: =IF(I4="","",I4+I5) -> 4492340 | J6: =IF(J4="","",J4+J5) -> 3608565 | K6: =IF(K4="","",K4+K5) -> 2463991 | L6: =IF(L4="","",L4+L5) -> 2223386 | M6: =IF(M4="","",M4+M5) -> 1816287 | N6: =IF(N4="","",N4+N5) -> 1398790 | ... Q6: =IF(Q4="","",Q4+Q5)
B7: Fixed Costs | C7: =C35 -> -3762379 | G7: =G35 -> -3762379 | H7: =H35 -> -3397218 | I7: =I35 -> -2757447 | J7: =J35 -> -2225034 | K7: =K35 -> -1609003 | L7: =L35 -> -1334276 | M7: =M35 -> -1110451 | N7: =N35 -> -904264 | ... Q7: =Q35
B8: Operating EBIT | C8: =C6+C7 -> 2062510.7 | G8: =IF(G$4="","",G6+G7) -> 2508432 | H8: =IF(H$4="","",H6+H7) -> 2212187 | I8: =IF(I$4="","",I6+I7) -> 1734893 | J8: =IF(J$4="","",J6+J7) -> 1383531 | K8: =IF(K$4="","",K6+K7) -> 854988 | L8: =IF(L$4="","",L6+L7) -> 889110 | M8: =IF(M$4="","",M6+M7) -> 705836 | N8: =IF(N$4="","",N6+N7) -> 494526 | ... Q8: =IF(Q$4="","",Q6+Q7)
B9: Add Back D&A | C9: =BS!$G$39*BS!D58 -> 0 | G9: =IF(Data!C61="","",-Data!C61) -> 0 | H9: =IF(Data!D61="","",-Data!D61) -> 0 | I9: =IF(Data!E61="","",-Data!E61) -> 0 | J9: =IF(Data!F61="","",-Data!F61) -> 0 | K9: =IF(Data!G61="","",-Data!G61) -> 0 | L9: =IF(Data!H61="","",-Data!H61) -> 0 | M9: =IF(Data!I61="","",-Data!I61) -> 0 | N9: =IF(Data!J61="","",-Data!J61) -> 0 | ... Q9: =IF(Data!M61="","",-Data!M61)
B10: Maintenance Capex | C10: =-C4*C78 -> 0 | G10: =Data!C62 -> 0 | H10: =Data!D62 -> 0 | I10: =Data!E62 -> 0 | J10: =Data!F62 -> 0 | K10: =Data!G62 -> 0 | L10: =Data!H62 -> 0 | M10: =Data!I62 -> 0 | N10: =Data!J62 -> 0 | ... Q10: =Data!M62
B11: Stable Non-Operating EBIT | C11: =C63 -> 0 | G11: =G61 -> 0 | H11: =H61 -> 0 | I11: =I61 -> 0 | J11: =J61 -> 0 | K11: =K61 -> 0 | L11: =L61 -> 0 | M11: =M61 -> 0 | N11: =N61 -> 0 | ... Q11: =Q61
B12: Net Interest Income | C12: =C50 -> 0 | G12: =G50 -> 0 | H12: =H50 -> 0 | I12: =I50 -> 0 | J12: =J50 -> 0 | K12: =K50 -> 0 | L12: =L50 -> 0 | M12: =M50 -> 0 | N12: =N50 -> 0 | ... Q12: =Q50
B13: Pre-tax Profit | C13: =SUM(C8:C12) -> 2062510.7 | G13: =IF(G$4="","",SUM(G8:G12)) -> 2508432 | H13: =IF(H$4="","",SUM(H8:H12)) -> 2212187 | I13: =IF(I$4="","",SUM(I8:I12)) -> 1734893 | J13: =IF(J$4="","",SUM(J8:J12)) -> 1383531 | K13: =IF(K$4="","",SUM(K8:K12)) -> 854988 | L13: =IF(L$4="","",SUM(L8:L12)) -> 889110 | M13: =IF(M$4="","",SUM(M8:M12)) -> 705836 | N13: =IF(N$4="","",SUM(N8:N12)) -> 494526 | ... Q13: =IF(Q$4="","",SUM(Q8:Q12))
B14: Income Tax | C14: =-SUM(C8+C11,C12)*C43 -> -531509.02 | G14: =Data!C46 -> -761461 | H14: =Data!D46 -> -625545 | I14: =Data!E46 -> -477771 | J14: =Data!F46 -> -358547 | K14: =Data!G46 -> -230437 | L14: =Data!H46 -> -251797 | M14: =Data!I46 -> -231449 | N14: =Data!J46 -> -201336 | ... Q14: =Data!M46
B15: NCI’s Share of Profits | C15: =-C4*C83 -> 0 | G15: =Data!C48 -> 0 | H15: =Data!D48 -> 0 | I15: =Data!E48 -> 0 | J15: =Data!F48 -> 0 | K15: =Data!G48 -> 0 | L15: =Data!H48 -> 0 | M15: =Data!I48 -> 0 | N15: =Data!J48 -> 0 | ... Q15: =Data!M48
B16: After-tax Profit | C16: =SUM(C13:C15) -> 1531001.7 | G16: =IF(G$4="","",SUM(G13:G15)) -> 1746971 | H16: =IF(H$4="","",SUM(H13:H15)) -> 1586642 | I16: =IF(I$4="","",SUM(I13:I15)) -> 1257122 | J16: =IF(J$4="","",SUM(J13:J15)) -> 1024984 | K16: =IF(K$4="","",SUM(K13:K15)) -> 624551 | L16: =IF(L$4="","",SUM(L13:L15)) -> 637313 | M16: =IF(M$4="","",SUM(M13:M15)) -> 474387 | N16: =IF(N$4="","",SUM(N13:N15)) -> 293190 | ... Q16: =IF(Q$4="","",SUM(Q13:Q15))
B17: WCInv | C17: =-C4*C85 -> 0 | E17: WCInv is by default excluded
B18: Net Borrowing | C18: 0 | E18: Net borrowing is excluded
B19: FCFE | C19: =C16+C17 -> 1531001.7 | G19: =IF(G$4="","",G16+G17) -> 1746971 | H19: =IF(H$4="","",H16+H17) -> 1586642 | I19: =IF(I$4="","",I16+I17) -> 1257122 | J19: =IF(J$4="","",J16+J17) -> 1024984 | K19: =IF(K$4="","",K16+K17) -> 624551 | L19: =IF(L$4="","",L16+L17) -> 637313 | M19: =IF(M$4="","",M16+M17) -> 474387 | N19: =IF(N$4="","",N16+N17) -> 293190 | ... Q19: =IF(Q$4="","",Q16+Q17)
B21: Operating Cost Structure | E21: Notes
B22: Variable Costs
B23: COGS | C23: =-C4*C28 -> -4278812.3 | G23: =Data!C37 -> -4317315 | H23: =Data!D37 -> -4009873 | I23: =Data!E37 -> -3618178 | J23: =Data!F37 -> -2648052 | K23: =Data!G37 -> -1937888 | L23: =Data!H37 -> -1755910 | M23: =Data!I37 -> -1472032 | N23: =Data!J37 -> -1250391 | ... Q23: =Data!M37
B24: Selling Expenses | C24: =-C4*C29 -> 0 | G24: =Data!C40 -> 0 | H24: =Data!D40 -> 0 | I24: =Data!E40 -> 0 | J24: =Data!F40 -> 0 | K24: =Data!G40 -> 0 | L24: =Data!H40 -> 0 | M24: =Data!I40 -> 0 | N24: =Data!J40 -> 0 | ... Q24: =Data!M40
B25: Variable Costs | C25: =C23+C24 -> -4278812.3 | G25: =IF(G$4="","",G23+G24) -> -4317315 | H25: =IF(H$4="","",H23+H24) -> -4009873 | I25: =IF(I$4="","",I23+I24) -> -3618178 | J25: =IF(J$4="","",J23+J24) -> -2648052 | K25: =IF(K$4="","",K23+K24) -> -1937888 | L25: =IF(L$4="","",L23+L24) -> -1755910 | M25: =IF(M$4="","",M23+M24) -> -1472032 | N25: =IF(N$4="","",N23+N24) -> -1250391 | ... Q25: =IF(Q$4="","",Q23+Q24)
B27: Variable Costs % of Sales
B28: COGS | C28: =AVERAGE(G28:J28) -> 0.42348955 | E28: Historical Average | G28: =IF(G$4="","",ABS(G23/G$4)) -> 0.40775063 | H28: =IF(H$4="","",ABS(H23/H$4)) -> 0.416858 | I28: =IF(I$4="","",ABS(I23/I$4)) -> 0.44610936 | J28: =IF(J$4="","",ABS(J23/J$4)) -> 0.42324023 | K28: =IF(K$4="","",ABS(K23/K$4)) -> 0.44024109 | L28: =IF(L$4="","",ABS(L23/L$4)) -> 0.44126147 | M28: =IF(M$4="","",ABS(M23/M$4)) -> 0.44765487 | N28: =IF(N$4="","",ABS(N23/N$4)) -> 0.47199153 | ... Q28: =IF(Q$4="","",ABS(Q23/Q$4))
B29: =B24 -> Selling Expenses | C29: =AVERAGE(G29:J29) -> 0 | E29: Historical Average | G29: =IF(G$4="","",ABS(G24/G$4)) -> 0 | H29: =IF(H$4="","",ABS(H24/H$4)) -> 0 | I29: =IF(I$4="","",ABS(I24/I$4)) -> 0 | J29: =IF(J$4="","",ABS(J24/J$4)) -> 0 | K29: =IF(K$4="","",ABS(K24/K$4)) -> 0 | L29: =IF(L$4="","",ABS(L24/L$4)) -> 0 | M29: =IF(M$4="","",ABS(M24/M$4)) -> 0 | N29: =IF(N$4="","",ABS(N24/N$4)) -> 0 | ... Q29: =IF(Q$4="","",ABS(Q24/Q$4))
B30: Variable Costs | C30: =ABS(C25/$C$4) -> 0.42348955 | G30: =IF(G$4="","",ABS(G25/G$4)) -> 0.40775063 | H30: =IF(H$4="","",ABS(H25/H$4)) -> 0.416858 | I30: =IF(I$4="","",ABS(I25/I$4)) -> 0.44610936 | J30: =IF(J$4="","",ABS(J25/J$4)) -> 0.42324023 | K30: =IF(K$4="","",ABS(K25/K$4)) -> 0.44024109 | L30: =IF(L$4="","",ABS(L25/L$4)) -> 0.44126147 | M30: =IF(M$4="","",ABS(M25/M$4)) -> 0.44765487 | N30: =IF(N$4="","",ABS(N25/N$4)) -> 0.47199153 | ... Q30: =IF(Q$4="","",ABS(Q25/Q$4))
B32: Fixed Costs
B33: G&A and other Opex | C33: =G33 -> -3762379 | E33: Historical Average | G33: =Data!C41 -> -3762379 | H33: =Data!D41 -> -3397218 | I33: =Data!E41 -> -2757447 | J33: =Data!F41 -> -2225034 | K33: =Data!G41 -> -1609003 | L33: =Data!H41 -> -1334276 | M33: =Data!I41 -> -1110451 | N33: =Data!J41 -> -904264 | ... Q33: =Data!M41
B34: R&D | C34: =AVERAGE(G34:J34) -> 0 | E34: Historical Average | G34: =Data!C42 -> 0 | H34: =Data!D42 -> 0 | I34: =Data!E42 -> 0 | J34: =Data!F42 -> 0 | K34: =Data!G42 -> 0 | L34: =Data!H42 -> 0 | M34: =Data!I42 -> 0 | N34: =Data!J42 -> 0 | ... Q34: =Data!M42
B35: Fixed Costs | C35: =C33+C34 -> -3762379 | G35: =IF(G4="","",G33+G34) -> -3762379 | H35: =IF(H4="","",H33+H34) -> -3397218 | I35: =IF(I4="","",I33+I34) -> -2757447 | J35: =IF(J4="","",J33+J34) -> -2225034 | K35: =IF(K4="","",K33+K34) -> -1609003 | L35: =IF(L4="","",L33+L34) -> -1334276 | M35: =IF(M4="","",M33+M34) -> -1110451 | N35: =IF(N4="","",N33+N34) -> -904264 | ... Q35: =IF(Q4="","",Q33+Q34)
B37: Fixed Costs % of Sales
B38: =B33 -> G&A and other Opex | C38: =ABS(C33/$C$4) -> 0.37237628 | G38: =IF(G$4="","",ABS(G33/G$4)) -> 0.35533946 | H38: =IF(H$4="","",ABS(H33/H$4)) -> 0.35316767 | I38: =IF(I$4="","",ABS(I33/I$4)) -> 0.33998408 | J38: =IF(J$4="","",ABS(J33/J$4)) -> 0.35562893 | K38: =IF(K$4="","",ABS(K33/K$4)) -> 0.3655264 | L38: =IF(L$4="","",ABS(L33/L$4)) -> 0.33530454 | M38: =IF(M$4="","",ABS(M33/M$4)) -> 0.33769564 | N38: =IF(N$4="","",ABS(N33/N$4)) -> 0.34133719 | ... Q38: =IF(Q$4="","",ABS(Q33/Q$4))
B39: =B34 -> R&D | C39: =ABS(C34/$C$4) -> 0 | G39: =IF(G$4="","",ABS(G34/G$4)) -> 0 | H39: =IF(H$4="","",ABS(H34/H$4)) -> 0 | I39: =IF(I$4="","",ABS(I34/I$4)) -> 0 | J39: =IF(J$4="","",ABS(J34/J$4)) -> 0 | K39: =IF(K$4="","",ABS(K34/K$4)) -> 0 | L39: =IF(L$4="","",ABS(L34/L$4)) -> 0 | M39: =IF(M$4="","",ABS(M34/M$4)) -> 0 | N39: =IF(N$4="","",ABS(N34/N$4)) -> 0 | ... Q39: =IF(Q$4="","",ABS(Q34/Q$4))
B40: Fixed Costs | C40: =ABS(C35/$C$4) -> 0.37237628 | G40: =IF(G$4="","",ABS(G35/G$4)) -> 0.35533946 | H40: =IF(H$4="","",ABS(H35/H$4)) -> 0.35316767 | I40: =IF(I$4="","",ABS(I35/I$4)) -> 0.33998408 | J40: =IF(J$4="","",ABS(J35/J$4)) -> 0.35562893 | K40: =IF(K$4="","",ABS(K35/K$4)) -> 0.3655264 | L40: =IF(L$4="","",ABS(L35/L$4)) -> 0.33530454 | M40: =IF(M$4="","",ABS(M35/M$4)) -> 0.33769564 | N40: =IF(N$4="","",ABS(N35/N$4)) -> 0.34133719 | ... Q40: =IF(Q$4="","",ABS(Q35/Q$4))
B42: Tax % of Pre-tax Profit
B43: Income Tax Rate | C43: 0.2577 | E43: Use the highest past tax rate | G43: =IF(G$4="","",-G14/SUM(G8+G11,G12)) -> 0.30356055 | H43: =IF(H$4="","",-H14/SUM(H8+H11,H12)) -> 0.28277221 | I43: =IF(I$4="","",-I14/SUM(I8+I11,I12)) -> 0.27538932 | J43: =IF(J$4="","",-J14/SUM(J8+J11,J12)) -> 0.25915357 | K43: =IF(K$4="","",-K14/SUM(K8+K11,K12)) -> 0.26952074 | L43: =IF(L$4="","",-L14/SUM(L8+L11,L12)) -> 0.28320118 | M43: =IF(M$4="","",-M14/SUM(M8+M11,M12)) -> 0.32790762 | N43: =IF(N$4="","",-N14/SUM(N8+N11,N12)) -> 0.40712925 | ... Q43: =IF(Q$4="","",-Q14/SUM(Q8+Q11,Q12))
B45: Non-operating Income | E45: Notes
B46: Interest
...

Sheet DCF
B2: No-Growth DCF Valuation | H2: Notes
B3: No-Growth DCF | C3: =scaling_factor -> 1000 | E3: Special Assumption
B4: Adjusted FCFE | C4: =Normalized_FCF!C19 -> 1531001.7 | D4: =Reporting_currency -> USD | E4: Terminal Growth Rate (g): | F4: =Terminal_Growth -> 0
B5: /Equity Cost of Capital | C5: =Equity_Cost -> 0.075
B6: Stable Income Value | C6: =(C4*(1+Terminal_Growth))/(Equity_Cost-Terminal_Growth) -> 20413356 | D6: =Reporting_currency -> USD | E6: Conservative Valuation: Setting g=0 can be a conservative assumption to avoid overestimating the stock’s value, especially if future growth is uncertain or unreliable.
B7: - Interest-bearing Debt | C7: =BS!G31 -> 1706782 | D7: =Reporting_currency -> USD
B8: + Non-operating Cash | C8: =BS!D66 -> 655172.73 | D8: =Reporting_currency -> USD
B9: + Other Non-operating Assets | C9: =BS!H42 -> 0 | D9: =Reporting_currency -> USD
B10: Equity Value | C10: =C6-C7+C8+C9 -> 19361747 | D10: =Reporting_currency -> USD
B11: * Exchange rate | C11: =Exchange_Rate -> 1 | D11: =Thesis!C15 -> USD
B12: Equity Value per share | C12: =(C10*scaling_factor)/Common_Shares*Exchange_Rate -> 161.55604 | D12: =Market_currency -> USD
B14: Implied Growth Scenario Analysis
B15: FCFE Projection
B16: High Growth Period (HGP) | C16: =Scenarios!C65 -> 0.056956408
B17: High Growth Rate (HGR) | C17: =Scenarios!C64 -> 5
B18: Value Per Share | C18: =(F52-C7+C8+C9)*Exchange_Rate/Common_Shares*scaling_factor -> 177.35705 | D18: =Market_currency -> USD
B20: Year | C20: FCFE | D20: Growth Rates | E20: Discount Factor | F20: PV of FCFE
B21: 1 | C21: =C4*(1+D21) -> 1618202.1 | D21: =IF($C$17<B21,0,DCF!$C$16) -> 0.056956408 | E21: =IF($C$17<B21,0,1/(1+Equity_Cost)^B21) -> 0.93023256 | F21: =C21*E21 -> 1505304.3
B22: 2 | C22: =IF(ROW()-ROW($C$21)<$C$17, $C$21*(1+D22)^(ROW()-ROW($C$21)), 0) -> 1710369.1 | D22: =IF($C$17<B22,0,DCF!$C$16) -> 0.056956408 | E22: =IF($C$17<B22,0,1/(1+Equity_Cost)^B22) -> 0.86533261 | F22: =C22*E22 -> 1480038.1
B23: 3 | C23: =IF(ROW()-ROW($C$21)<$C$17, $C$21*(1+D23)^(ROW()-ROW($C$21)), 0) -> 1807785.5 | D23: =IF($C$17<B23,0,DCF!$C$16) -> 0.056956408 | E23: =IF($C$17<B23,0,1/(1+Equity_Cost)^B23) -> 0.80496057 | F23: =C23*E23 -> 1455196.1
B24: 4 | C24: =IF(ROW()-ROW($C$21)<$C$17, $C$21*(1+D24)^(ROW()-ROW($C$21)), 0) -> 1910750.5 | D24: =IF($C$17<B24,0,DCF!$C$16) -> 0.056956408 | E24: =IF($C$17<B24,0,1/(1+Equity_Cost)^B24) -> 0.74880053 | F24: =C24*E24 -> 1430771
B25: 5 | C25: =IF(ROW()-ROW($C$21)<$C$17, $C$21*(1+D25)^(ROW()-ROW($C$21)), 0) -> 2019580 | D25: =IF($C$17<B25,0,DCF!$C$16) -> 0.056956408 | E25: =IF($C$17<B25,0,1/(1+Equity_Cost)^B25) -> 0.69655863 | F25: =C25*E25 -> 1406755.9
B26: 6 | C26: =IF(ROW()-ROW($C$21)<$C$17, $C$21*(1+D26)^(ROW()-ROW($C$21)), 0) -> 0 | D26: =IF($C$17<B26,0,DCF!$C$16) -> 0 | E26: =IF($C$17<B26,0,1/(1+Equity_Cost)^B26) -> 0 | F26: =C26*E26 -> 0
B27: 7 | C27: =IF(ROW()-ROW($C$21)<$C$17, $C$21*(1+D27)^(ROW()-ROW($C$21)), 0) -> 0 | D27: =IF($C$17<B27,0,DCF!$C$16) -> 0 | E27: =IF($C$17<B27,0,1/(1+Equity_Cost)^B27) -> 0 | F27: =C27*E27 -> 0
B28: 8 | C28: =IF(ROW()-ROW($C$21)<$C$17, $C$21*(1+D28)^(ROW()-ROW($C$21)), 0) -> 0 | D28: =IF($C$17<B28,0,DCF!$C$16) -> 0 | E28: =IF($C$17<B28,0,1/(1+Equity_Cost)^B28) -> 0 | F28: =C28*E28 -> 0
B29: 9 | C29: =IF(ROW()-ROW($C$21)<$C$17, $C$21*(1+D29)^(ROW()-ROW($C$21)), 0) -> 0 | D29: =IF($C$17<B29,0,DCF!$C$16) -> 0 | E29: =IF($C$17<B29,0,1/(1+Equity_Cost)^B29) -> 0 | F29: =C29*E29 -> 0
B30: 10 | C30: =IF(ROW()-ROW($C$21)<$C$17, $C$21*(1+D30)^(ROW()-ROW($C$21)), 0) -> 0 | D30: =IF($C$17<B30,0,DCF!$C$16) -> 0 | E30: =IF($C$17<B30,0,1/(1+Equity_Cost)^B30) -> 0 | F30: =C30*E30 -> 0
B31: 11 | C31: =IF(ROW()-ROW($C$21)<$C$17, $C$21*(1+D31)^(ROW()-ROW($C$21)), 0) -> 0 | D31: =IF($C$17<B31,0,DCF!$C$16) -> 0 | E31: =IF($C$17<B31,0,1/(1+Equity_Cost)^B31) -> 0 | F31: =C31*E31 -> 0
B32: 12 | C32: =IF(ROW()-ROW($C$21)<$C$17, $C$21*(1+D32)^(ROW()-ROW($C$21)), 0) -> 0 | D32: =IF($C$17<B32,0,DCF!$C$16) -> 0 | E32: =IF($C$17<B32,0,1/(1+Equity_Cost)^B32) -> 0 | F32: =C32*E32 -> 0
B33: 13 | C33: =IF(ROW()-ROW($C$21)<$C$17, $C$21*(1+D33)^(ROW()-ROW($C$21)), 0) -> 0 | D33: =IF($C$17<B33,0,DCF!$C$16) -> 0 | E33: =IF($C$17<B33,0,1/(1+Equity_Cost)^B33) -> 0 | F33: =C33*E33 -> 0
... B50: 30 | C50: =IF(ROW()-ROW($C$21)<$C$17, $C$21*(1+D50)^(ROW()-ROW($C$21)), 0) -> 0 | D50: =IF($C$17<B50,0,DCF!$C$16) -> 0 | E50: =IF($C$17<B50,0,1/(1+Equity_Cost)^B50) -> 0 | F50: =C50*E50 -> 0
B51: Terminal Year | C51: =C$21*(1+Terminal_Growth)^$C$17/Equity_Cost -> 21576028 | D51: =Terminal_Growth -> 0 | E51: =1/(1+Equity_Cost)^C17 -> 0.69655863 | F51: =C51*E51 -> 15028968
E52: Total PV | F52: =SUM(F21:F51) -> 22307034
B54: Sensitivity Analysis (Enterprise Value)
A55: =F52 -> 22307034 | B55: =C78 -> 0 | C55: =C77 -> 0.02 | D55: =C76 -> 0.05 | E55: =C75 -> 0.08 | F55: =C74 -> 0.1
A56: 5 | B56: 20413356 | C56: 21060674 | D56: 22067267 | E56: 23119115 | F56: 23846940
A57: 10 | B57: 20413356 | C57: 21702573 | D57: 23881888 | E57: 26403976 | F57: 28306345
A58: 15 | B58: 20413356 | C58: 22515292 | D58: 26366953 | E58: 31289312 | F58: 35327289
A59: 20 | B59: 20413356 | C59: 23362564 | D59: 29183488 | E59: 37350437 | F59: 44609366
A60: 25 | B60: 20413356 | C60: 24168972 | D60: 32110422 | E60: 44292965 | F60: 56001413
...

Sheet DDM
B2: No-Growth DDM Valuation | H2: Notes
B3: No-Growth DDM | C3: =scaling_factor -> 1000 | E3: Special Assumption
B4: Dividend | C4: =Normalized_FCF!C91*(1-dividend_tax_rate) -> 0 | D4: =Market_currency -> USD | E4: Terminal Growth Rate (g): | F4: =Thesis!E22 -> 0
B5: /Equity Cost of Capital | C5: =Equity_Cost -> 0.075
B6: Dividend Value | C6: =(C4*(1+Terminal_Growth))/(Equity_Cost-Terminal_Growth) -> 0 | D6: =Reporting_currency -> USD
B7: Dividend Value per share | C7: =(C6*scaling_factor)/Common_Shares*Exchange_Rate -> 0 | D7: =Market_currency -> USD
B9: Implied Growth Scenario Analysis
B10: FCFE Projection
B11: High Growth Period (HGP) | C11: =Scenarios!C65 -> 0.056956408
B12: High Growth Rate (HGR) | C12: =Scenarios!C64 -> 5
B13: Value Per Share | C13: =F47/Common_Shares*scaling_factor -> 0 | D13: =Market_currency -> USD
B15: Year | C15: Dividends | D15: Growth Rates | E15: Discount Factor | F15: PV of Dividends
B16: 1 | C16: =C4*(1+D16) -> 0 | D16: =IF($C$12<B16,0,DDM!$C$11) -> 0.056956408 | E16: =IF($C$12<B16,0,1/(1+Equity_Cost)^B16) -> 0.93023256 | F16: =C16*E16 -> 0
B17: 2 | C17: =IF(ROW()-ROW($C$16)<$C$12, $C$16*(1+D17)^(ROW()-ROW($C$16)), 0) -> 0 | D17: =IF($C$12<B17,0,DDM!$C$11) -> 0.056956408 | E17: =IF($C$12<B17,0,1/(1+Equity_Cost)^B17) -> 0.86533261 | F17: =C17*E17 -> 0
B18: 3 | C18: =IF(ROW()-ROW($C$16)<$C$12, $C$16*(1+D18)^(ROW()-ROW($C$16)), 0) -> 0 | D18: =IF($C$12<B18,0,DDM!$C$11) -> 0.056956408 | E18: =IF($C$12<B18,0,1/(1+Equity_Cost)^B18) -> 0.80496057 | F18: =C18*E18 -> 0
B19: 4 | C19: =IF(ROW()-ROW($C$16)<$C$12, $C$16*(1+D19)^(ROW()-ROW($C$16)), 0) -> 0 | D19: =IF($C$12<B19,0,DDM!$C$11) -> 0.056956408 | E19: =IF($C$12<B19,0,1/(1+Equity_Cost)^B19) -> 0.74880053 | F19: =C19*E19 -> 0
B20: 5 | C20: =IF(ROW()-ROW($C$16)<$C$12, $C$16*(1+D20)^(ROW()-ROW($C$16)), 0) -> 0 | D20: =IF($C$12<B20,0,DDM!$C$11) -> 0.056956408 | E20: =IF($C$12<B20,0,1/(1+Equity_Cost)^B20) -> 0.69655863 | F20: =C20*E20 -> 0
B21: 6 | C21: =IF(ROW()-ROW($C$16)<$C$12, $C$16*(1+D21)^(ROW()-ROW($C$16)), 0) -> 0 | D21: =IF($C$12<B21,0,DDM!$C$11) -> 0 | E21: =IF($C$12<B21,0,1/(1+Equity_Cost)^B21) -> 0 | F21: =C21*E21 -> 0
B22: 7 | C22: =IF(ROW()-ROW($C$16)<$C$12, $C$16*(1+D22)^(ROW()-ROW($C$16)), 0) -> 0 | D22: =IF($C$12<B22,0,DDM!$C$11) -> 0 | E22: =IF($C$12<B22,0,1/(1+Equity_Cost)^B22) -> 0 | F22: =C22*E22 -> 0
B23: 8 | C23: =IF(ROW()-ROW($C$16)<$C$12, $C$16*(1+D23)^(ROW()-ROW($C$16)), 0) -> 0 | D23: =IF($C$12<B23,0,DDM!$C$11) -> 0 | E23: =IF($C$12<B23,0,1/(1+Equity_Cost)^B23) -> 0 | F23: =C23*E23 -> 0
B24: 9 | C24: =IF(ROW()-ROW($C$16)<$C$12, $C$16*(1+D24)^(ROW()-ROW($C$16)), 0) -> 0 | D24: =IF($C$12<B24,0,DDM!$C$11) -> 0 | E24: =IF($C$12<B24,0,1/(1+Equity_Cost)^B24) -> 0 | F24: =C24*E24 -> 0
B25: 10 | C25: =IF(ROW()-ROW($C$16)<$C$12, $C$16*(1+D25)^(ROW()-ROW($C$16)), 0) -> 0 | D25: =IF($C$12<B25,0,DDM!$C$11) -> 0 | E25: =IF($C$12<B25,0,1/(1+Equity_Cost)^B25) -> 0 | F25: =C25*E25 -> 0
B26: 11 | C26: =IF(ROW()-ROW($C$16)<$C$12, $C$16*(1+D26)^(ROW()-ROW($C$16)), 0) -> 0 | D26: =IF($C$12<B26,0,DDM!$C$11) -> 0 | E26: =IF($C$12<B26,0,1/(1+Equity_Cost)^B26) -> 0 | F26: =C26*E26 -> 0
B27: 12 | C27: =IF(ROW()-ROW($C$16)<$C$12, $C$16*(1+D27)^(ROW()-ROW($C$16)), 0) -> 0 | D27: =IF($C$12<B27,0,DDM!$C$11) -> 0 | E27: =IF($C$12<B27,0,1/(1+Equity_Cost)^B27) -> 0 | F27: =C27*E27 -> 0
B28: 13 | C28: =IF(ROW()-ROW($C$16)<$C$12, $C$16*(1+D28)^(ROW()-ROW($C$16)), 0) -> 0 | D28: =IF($C$12<B28,0,DDM!$C$11) -> 0 | E28: =IF($C$12<B28,0,1/(1+Equity_Cost)^B28) -> 0 | F28: =C28*E28 -> 0
... B45: 30 | C45: =IF(ROW()-ROW($C$16)<$C$12, $C$16*(1+D45)^(ROW()-ROW($C$16)), 0) -> 0 | D45: =IF($C$12<B45,0,DDM!$C$11) -> 0 | E45: =IF($C$12<B45,0,1/(1+Equity_Cost)^B45) -> 0 | F45: =C45*E45 -> 0
B46: Terminal Year | C46: =C$16*(1+F4)^$C$12/Equity_Cost -> 0 | D46: =Terminal_Growth -> 0 | E46: =1/(1+Equity_Cost)^C12 -> 0.69655863 | F46: =C46*E46 -> 0
E47: Total PV | F47: =SUM(F16:F46) -> 0
B49: Sensitivity Analysis (Enterprise Value)
A50: =F47 -> 0 | B50: =C73 -> 0 | C50: =C72 -> 0.02 | D50: =C71 -> 0.05 | E50: =C70 -> 0.08 | F50: =C69 -> 0.1
A51: 5 | B51: 0 | C51: 0 | D51: 0 | E51: 0 | F51: 0
A52: 10 | B52: 0 | C52: 0 | D52: 0 | E52: 0 | F52: 0
A53: 15 | B53: 0 | C53: 0 | D53: 0 | E53: 0 | F53: 0
A54: 20 | B54: 0 | C54: 0 | D54: 0 | E54: 0 | F54: 0
A55: 25 | B55: 0 | C55: 0 | D55: 0 | E55: 0 | F55: 0
A56: 30 | B56: 0 | C56: 0 | D56: 0 | E56: 0 | F56: 0
B58: Sensitivity Analysis (Equity Value per share)
B59: =B50 -> 0 | C59: =C50 -> 0.02 | D59: =D50 -> 0.05 | E59: =E50 -> 0.08 | F59: =F50 -> 0.1
A60: 0 | B60: =C7 -> 0 | C60: =C7 -> 0 | D60: =C7 -> 0 | E60: =C7 -> 0 | F60: =C7 -> 0
A61: =A51 -> 5 | B61: =B51/Common_Shares*$C$3*Exchange_Rate -> 0 | C61: =C51/Common_Shares*$C$3*Exchange_Rate -> 0 | D61: =D51/Common_Shares*$C$3*Exchange_Rate -> 0 | E61: =E51/Common_Shares*$C$3*Exchange_Rate -> 0 | F61: =F51/Common_Shares*$C$3*Exchange_Rate -> 0
...

Sheet Scenarios
B2: Current Situation | H2: Warning: Do Not Remove this logic
B3: Selection | H3: 0 | I3: =-Market_Price -> -196.45
B4: Past Years Selected | C4: 3 | E4: Tie the business story into the three levers of value: FCFE, growth and risk. | H4: 1 | I4: =IF(ROW()-3 < $C$76, $C$77, IF(ROW()-3 = $C$76, $C$77 + $C$60, "")) -> 0
H5: 2 | I5: =IF(ROW()-3 < $C$76, $C$77, IF(ROW()-3 = $C$76, $C$77 + $C$60, "")) -> 0
B6: Latest | C6: =DCF!C3 -> 1000 | E6: Prompt for fundamental Analysis | H6: 3 | I6: =IF(ROW()-3 < $C$76, $C$77, IF(ROW()-3 = $C$76, $C$77 + $C$60, "")) -> 177.33733
B7: EBIT | C7: =Normalized_FCF!G8 -> 2508432 | D7: =Reporting_currency -> USD | E7: ="Please develop three logical "&C18&"-year scenarios (Base Case, Pessimistic Case, Optimistic Case) and two extreme "&C46&"-year scenarios (Success Scenario, Devil’s Advocate Scenario) for "&Thesis!C5&"("&Thesis!C11&"). Each scenario should include the Compound Growth Rate, the Probability Assessment, and the Business Narrative." -> Please develop three logical 5-year scenarios (Base Case, Pessimistic Case, Optimistic Case) and two extreme 10-year scenarios (Success Scenario, Devil’s Advocate Scenario) for lululemon athletica inc.(LULU). Each scenario should include the Compound Growth Rate, the Probability Assessment, and the Business Narrative. | H7: 4 | I7: =IF(ROW()-3 < $C$76, $C$77, IF(ROW()-3 = $C$76, $C$77 + $C$60, ""))
B8: FCFE | C8: =Normalized_FCF!G19 -> 1746971 | D8: =Reporting_currency -> USD | H8: 5 | I8: =IF(ROW()-3 < $C$76, $C$77, IF(ROW()-3 = $C$76, $C$77 + $C$60, ""))
B9: Normalized | C9: =Normalized_FCF!C19 -> 1531001.7 | D9: =Reporting_currency -> USD | H9: 6 | I9: =IF(ROW()-3 < $C$76, $C$77, IF(ROW()-3 = $C$76, $C$77 + $C$60, ""))
H10: 7 | I10: =IF(ROW()-3 < $C$76, $C$77, IF(ROW()-3 = $C$76, $C$77 + $C$60, ""))
B11: YoY CAGR | H11: 8 | I11: =IF(ROW()-3 < $C$76, $C$77, IF(ROW()-3 = $C$76, $C$77 + $C$60, ""))
B12: Sales | C12: =(Normalized_FCF!G4/OFFSET(Normalized_FCF!G4, 0, $C$4))^(1/$C$4) - 1 -> 0.19168053 | H12: 9 | I12: =IF(ROW()-3 < $C$76, $C$77, IF(ROW()-3 = $C$76, $C$77 + $C$60, ""))
B13: Operating EBIT | C13: =(Normalized_FCF!G8/OFFSET(Normalized_FCF!G8, 0, $C$4))^(1/$C$4) - 1 -> 0.21937648 | H13: 10 | I13: =IF(ROW()-3 < $C$76, $C$77, IF(ROW()-3 = $C$76, $C$77 + $C$60, ""))
B14: FCFE | C14: =(Normalized_FCF!G19/OFFSET(Normalized_FCF!G19, 0, $C$4))^(1/$C$4) - 1 -> 0.1945093
B16: General Scenarios
B17: Assumption | E17: Guidance Note
B18: High Growth Period (HGP) | C18: 5 | E18: Fundamental analysis and market signal analysis should be combined, with fundamental analysis given priority and market signal analysis serving as a supplement. Market signal analysis predicts a company's future trend, while fundamental analysis interprets the trend and identifies relevant fundamental factors and possibilities.
B20: Reference
B21: Market Price | C21: =Market_Price -> 196.45 | D21: =Market_currency -> USD
B22: No Growth Value per share | C22: =IF(valuation_method="DCF",DCF!C12,DDM!C7) -> 161.55604 | D22: =Market_currency -> USD
B24: Base | E24: Business Story
B25: High Growth Period (HGP) | C25: =C18 -> 5
B26: High Growth Rate (HGR) | C26: 0.05
B27: Value per share | C27: =IF(valuation_method="DCF",DCF!E76,DDM!E71) -> 175.35641 | D27: =Market_currency -> USD
B28: Probabilities | C28: 0.6
B30: Pessimistic | E30: Business Story
B31: High Growth Period (HGP) | C31: =C18 -> 5
B32: High Growth Rate (HGR) | C32: 0.02
B33: Value per share | C33: =IF(valuation_method="DCF",DCF!E77,DDM!E72) -> 166.95732 | D33: =Market_currency -> USD
B34: Probabilities | C34: 0.2
B36: Optimistic | E36: Business Story
B37: High Growth Period (HGP) | C37: =C18 -> 5
B38: High Growth Rate (HGR) | C38: 0.08
B39: Value per share | C39: =IF(valuation_method="DCF",DCF!E75,DDM!E70) -> 184.13312 | D39: =Market_currency -> USD
B40: Probabilities | C40: =1-C28-C34 -> 0.2
B42: Expected Value = | C42: =C27*C28+C33*C34+C39*C40 -> 175.43193 | D42: =Market_currency -> USD
B44: Extreme Scenarios
B45: Assumption
B46: High Growth Period (HGP) | C46: 10
B48: Devil's advocate | E48: Business Story
B49: High Growth Period (HGP) | C49: =C46 -> 10
...

Sheet Breakdown
B2: Divisional Analysis (Optional)

Sheet 投资主题
B1: 模型最后更新日期: | C1: =Thesis!C1 -> 45874 | D1: =Thesis!D1 -> INT | E1: Selected: | F1: =Thesis!F1 -> N
A2: 执行摘要
B4: 公司信息
B5: 公司名称： | C5: =Thesis!C5 -> lululemon athletica inc.
B6: 股份数量： | C6: =Common_Shares -> 119845391
B7: 报告间隔： | C7: =Thesis!C7 -> 6
B8: 下次更新日期： | C8: =EOMONTH(EDATE(BS!C1,C7+2),0) -> 46053
B10: 上市信息
B11: 股票代码： | C11: =Thesis!C11 -> LULU
B12: 市场价格： | C12: =Market_Price -> 196.45
B13: 市价货币： | C13: =Market_currency -> USD
B14: 市值： | C14: =投资主题!C12*Common_Shares/1000000 -> 23543.627 | D14: =IF(D11="","",投资主题!D12*Common_Shares/1000000)
B15: 外汇符号： | C15: =IF(C25=C13,C13,C25&"/"&C13) -> USD | D15: =IF(D11="","",IF(C25=D13,D13,C25&"/"&D13))
B16: 汇率： | C16: =Exchange_Rate -> 1
B18: 指导说明：该模型使用结构化的投资流程来评估公司，确定其内在价值和目标价格。它关注可持续的自由现金流（FCF）能力，调整财务结构，纳入增长情景，并根据得出的内在价值计算预期回报。
B20: 估值概述
B21: 增长分类: | C21: =IF(Scenarios!C69="Y",Scenarios!B69,"")&IF(Scenarios!C70="Y",Scenarios!B70,"")&IF(Scenarios!C71="Y",Scenarios!B71,"")&" "&IF(Scenarios!C72="Y",Scenarios!B72,"") -> Low Growth | D21: 估值方法 | E21: =valuation_method -> DCF
B22: 对比板块: | C22: =Thesis!C22 -> CNS_02 | D22: =IF(valuation_method="DDM","终值贴现率","") | E22: =Thesis!E22 -> 0
B23: 商业模式风险溢价: | C23: =Thesis!C23 -> N
B24: 管理风险溢价: | C24: =Thesis!C24 -> N
B25: 报告货币: | C25: =Reporting_currency -> USD | D25: =IF(D11="","",Market_currency&"/"&D13&":") | E25: =IF(D11="","",1/Exchange_Rate*D16)
B26: ="预期股权价值 ("&C13&") :" -> 预期股权价值 (USD) : | C26: =C132 -> 177.33733 | D26: 市场隐含年回报率: | E26: =Scenarios!C87 -> -0.033542605
B28: 估值输出 | C28: =C145&" ("&Market_currency&")" -> LULU (USD) | D28: =IF(D11="","",D145&" ("&D13&")") | E28: 持有期 | F28: =Thesis!F28 -> 3
B29: 目标价格 | C29: =C149 -> 72.077359 | D29: =D149 | E29: 目标回报率 | F29: =Thesis!F29 -> 0.35
B30: 入场价格 | C30: =C157 -> 90.796715 | D30: =D157 | E30: 入场收益率 | F30: =Thesis!F30 -> 0.25
B31: 卖出价格 | C31: =C165 -> 142.74956 | D31: =D165 | E31: 基础Equity Cost | F31: =Thesis!F31 -> 0.075
B32: 退出价格 | C32: =C173 -> 127.10838 | D32: =D173 | E32: 基准收益率 | F32: =Thesis!F32 -> 0.1174
A34: 步骤1：确定公司可持续盈利能力（计算标准化FCFE）
B36: 目标：量化业务持续生成的潜在自由现金流（FCFE），去除临时波动或会计选择的影响。
B37: FCFE = (Normalized Operating EBIT + Depreciation & Amortization – Capital Expenditures) + Stable Non-Operating EBIT + Net Interest Income – Taxes – NCI’s Share of Profits – Working Capital Investment
B39: 关键组成部分 | C39: =scaling_factor -> 1000
B40: • Normalized Operating EBIT：核心业务运营的税前息前利润，调整以剔除一次性或非经常性项目，形成可持续盈利基础。
B41: Normalized Operating EBIT = | C41: =Normalized_FCF!C8 -> 2062510.7 | D41: =Reporting_currency -> USD
B43: • Depreciation & Amortization (D&A): 非现金费用，加入以反映运营产生的现金。 • Capital Expenditures (Capex): 维持或扩展运营资产所需的现金流出。
B44: D&A = | C44: =Normalized_FCF!C9 -> 0 | D44: =Reporting_currency -> USD
B45: Capex = | C45: =Normalized_FCF!C10 -> 0 | D45: =Reporting_currency -> USD
B47: • Stable Non-Operating EBIT: 来自非核心资产的持续收益，如固定收益投资、支付股息的股票或租赁物业。
B48: Stable Non-Operating EBIT = | C48: =Normalized_FCF!C11 -> 0 | D48: =Reporting_currency -> USD
B50: • Net Interest Income: 利息收入减去利息支出
B51: Operating Interest Income = | C51: =Normalized_FCF!C48 -> 0 | D51: =Reporting_currency -> USD
...
