Workbook
Name Common_Shares: [1]Thesis!$C$6
Name Common_Shares: Thesis!$C$6
Name dividend_tax_rate: [1]Normalized_FCF!$C$93
Name dividend_tax_rate: Normalized_FCF!$C$93
Name Equity_Cost: [1]Thesis!$C$86
Name Equity_Cost: Thesis!$C$86
Name Exchange_Rate: [1]Thesis!$C$16
Name Exchange_Rate: Thesis!$C$16
Name Market_currency: [1]Thesis!$C$13
Name Market_currency: Thesis!$C$13
Name Market_Price: [1]Thesis!$C$12
Name Market_Price: Thesis!$C$12
Name Reporting_currency: [1]Thesis!$C$25
Name Reporting_currency: Thesis!$C$25
Name scaling_factor: [1]Data!$C$3
Name scaling_factor: Data!$C$3
Name Terminal_Growth: [1]Thesis!$C$92
Name Terminal_Growth: Thesis!$C$92
Name valuation_method: [1]Thesis!$E$21
Name valuation_method: Thesis!$E$21

Sheet Thesis
B1: Model last updated: | C1: 45754 | D1: INT | E1: Selected: | F1: N
A2: Executive Summary
B4: Company Information
B5: Company Name | C5: Sirius XM
B6: Number of Shares: | C6: 338656000
B7: Report Interval: | C7: 6
B8: Update Required After: | C8: =EOMONTH(EDATE(BS!C1,C7+2),0) -> 45900
B10: Listing Information
B11: Symbol: | C11: SIRI
B12: Market Price: | C12: 24.27
B13: Market Currency | C13: USD
B14: Capitalization: | C14: =Thesis!C12*Common_Shares/1000000 -> 8219.1811 | D14: =IF(D11="","",Thesis!D12*Common_Shares/1000000)
B15: Forex Symbol: | C15: =IF(C25=C13,C13,C25&"/"&C13) -> USD | D15: =IF(D11="","",IF(C25=D13,D13,C25&"/"&D13))
B16: Exchange Rate: | C16: 1
B18: Guidance Note: This model determines a target buy price consistent with defined investment criteria. It follows a logical progression: establishing current sustainable earnings, adjusting for financial structure, incorporating growth scenarios, and finally applying the investor’s required return.
B20: Valuation Overview
B21: Growth Classification: | C21: =IF(Scenarios!C69="Y",Scenarios!B69,"")&IF(Scenarios!C70="Y",Scenarios!B70,"")&IF(Scenarios!C71="Y",Scenarios!B71,"")&" "&IF(Scenarios!C72="Y",Scenarios!B72,"") -> Low Growth | D21: Valuation Method | E21: DCF
B22: Comp_Sector: | C22: TMT_05 | D22: =IF(valuation_method="DDM","DDM Terminal Value","")
B23: Business Model Risk Premium: | C23: N
B24: Management Risk Premium: | C24: N
B25: Reporting Currency: | C25: USD | D25: =IF(D11="","",Market_currency&"/"&D13&":") | E25: =IF(D11="","",1/Exchange_Rate*D16)
B26: ="Expected Equity Value ("&C13&") :" -> Expected Equity Value (USD) : | C26: =C132 -> 33.230162 | D26: Market Implied Annual Return: | E26: =Scenarios!C87 -> 0.12591034
B28: Valuation Outputs | C28: =C145&" ("&Market_currency&")" -> SIRI (USD) | D28: =IF(D11="","",D145&" ("&D13&")") | E28: Holding Period | F28: 3
B29: Target Price | C29: =C149 -> 14.210809 | D29: =D149 | E29: Target return | F29: 0.35
B30: Entry Price | C30: =C157 -> 17.824938 | D30: =D157 | E30: Entry yield | F30: 0.25
B31: Sell Price | C31: =C165 -> 27.82954 | D31: =D165 | E31: Base equity cost | F31: 0.075
B32: Exit Price | C32: =C173 -> 24.820549 | D32: =D173 | E32: Benchmark yield | F32: 0.1174
A34: Step 1: Establishing the Company’s Sustainable Earning Power (Calculating Normalized FCFE)
B36: Goal: To quantify the underlying FCFE the business consistently generates for its equity owners, stripping away temporary fluctuations or accounting choices.The FCFE/Market Cap yield gives a direct measure of this cash generation relative to the current market price.
B37: FCFE = (Normalized Operating EBIT + Depreciation & Amortization – Capital Expenditures) + Stable Non-Operating EBIT + Net Interest Income – Taxes – NCI’s Share of Profits – Working Capital Investment
B39: Key Components | C39: =scaling_factor -> 1000000
B40: • Normalized Operating EBIT: Earnings before interest and taxes from core business operations, adjusted to remove one-time or irregular items for a sustainable earnings base.
B41: Normalized Operating EBIT = | C41: =Normalized_FCF!C8 -> 2626.9774 | D41: =Reporting_currency -> USD
B43: • Depreciation & Amortization (D&A): Non-cash expenses added back to reflect cash generated from operations. • Capital Expenditures (Capex): Cash outflows required to maintain or expand operational assets
B44: D&A = | C44: =Normalized_FCF!C9 -> 578 | D44: =Reporting_currency -> USD
B45: Capex = | C45: =Normalized_FCF!C10 -> -632.3134 | D45: =Reporting_currency -> USD
B47: • Stable Non-Operating EBIT: Consistent earnings from non-core assets, such as fixed-income investments, dividend-paying stocks, or rental properties.
B48: Stable Non-Operating EBIT = | C48: =Normalized_FCF!C11 -> 0 | D48: =Reporting_currency -> USD
B50: • Net Interest Income: Interest income minus interest expense
B51: Operating Interest Income = | C51: =Normalized_FCF!C48 -> 0 | D51: =Reporting_currency -> USD
...

Sheet Data
B1: =Thesis!C25 -> USD | C1: 45657 | D1: =EOMONTH(EDATE(C1,-12),0) -> 45291 | E1: =EOMONTH(EDATE(D1,-12),0) -> 44926 | F1: =EOMONTH(EDATE(E1,-12),0) -> 44561 | G1: =EOMONTH(EDATE(F1,-12),0) -> 44196 | H1: =EOMONTH(EDATE(G1,-12),0) -> 43830 | I1: =EOMONTH(EDATE(H1,-12),0) -> 43465 | J1: =EOMONTH(EDATE(I1,-12),0) -> 43100 | K1: =EOMONTH(EDATE(J1,-12),0) -> 42735 | ... M1: =EOMONTH(EDATE(L1,-12),0) -> 42004
B2: Data (Dirty)
B3: Income Statement | C3: 1000000
B4: Sales | C4: 8699 | D4: 8953 | E4: 9003 | F4: 8696 | G4: 8040 | H4: 7794 | I4: 5770.692 | J4: 5425.129 | K4: 5017.22 | L4: 4570.058
B5: COGS | C5: 4129 | D5: 4209 | E5: 4130 | F5: 3968 | G5: 3579 | H5: 3427 | I5: 2308.606 | J5: 2101.982 | K5: 1993.327 | L5: 1843.164
B6: OPEX | C6: =296+497+578+C7 -> 2634 | D6: =322+608+624+D7 -> 2844
B7: Incl. Selling Expenses | C7: =369+894 -> 1263 | D7: =359+931 -> 1290
B8: R&D
B9: Share of JV or associate Results
B10: Dividend or Interests from FA
B11: Investment property
B12: Interest Expense | C12: 496 | D12: 423 | E12: 422 | F12: 415 | G12: 394 | H12: 390 | I12: 350.073 | J12: 345.82 | K12: 331.225 | L12: 299.103
B13: Interest Income
B14: Income Tax Paid | C14: 210 | D14: 260 | E14: 392 | F14: 212 | G14: 299 | H14: 283 | I14: 244.681 | J14: 616.301 | K14: 345.727 | L14: 382.24
B15: Reported Net Income | C15: -2075 | D15: 1258 | E15: 1213 | F15: 1314 | G15: 131 | H15: 914 | I15: 1175.893 | J15: 647.908 | K15: 745.933 | L15: 509.724
B16: Non-controling Interests | C16: -410 | D16: 202
B18: Cash Flow Statement
B19: D&A | C19: 578 | D19: 624
B20: CAPX | C20: 728 | D20: 728 | E20: 650 | F20: 426 | G20: 388
B21: WCInv | C21: 259 | D21: 259 | E21: 169 | F21: 340 | G21: 411
B22: CFO | C22: 1741 | D22: 1850 | E22: 1976 | F22: 1998 | G22: 2018 | H22: 2017 | I22: 1880.418 | J22: 1855.589 | K22: 1719.237 | L22: 1244.051
B23: CFI | C23: -970 | D23: -686 | E23: -548 | F23: -200 | G23: -741 | H23: -3 | I23: -379.276 | J23: -1146.812 | K23: -210.124 | L23: -138.858
B24: CFF | C24: -916 | D24: -1005 | E24: -1562 | F24: -1682 | G24: -1314 | H24: -1959 | I24: -1515.146 | J24: -853.694 | K24: -1407.012 | L24: -1141.079
B25: ="Dividend per share ("&Market_currency&")" -> Dividend per share (USD) | C25: =0.27+0.27+0.027+0.0266 -> 0.5936
B27: Balance Sheet | C27: Latest Asset Value
B28: ST AR | C28: =BS!C4 -> 676 | D28: 709 | E28: 655 | F28: 722 | G28: 672 | H28: 670 | I28: 232.986 | J28: 241.727 | K28: 223.029 | L28: 234.782
B29: ST Inventory | C29: =BS!C6 -> 0
B30: Total Liabilities | C30: =BS!C33+BS!C42 -> 16447 | D30: 12939 | E30: 13373 | F30: 12899 | G30: 12618 | H30: 11885 | I30: 9989.657 | J30: 9853.248 | K30: 8795.61 | L30: 8213.153
B31: Total Equity | C31: =BS!G27 -> 11074 | D31: -2565 | E31: -3351 | F31: -2625 | G31: -2285 | H31: -736 | I31: -1816.921 | J31: -1523.874 | K31: -792.015 | L31: -166.491
B32: Non-common Interest | C32: =BS!G28 -> 0
B34: IS & CF Statements (Clean)
B35: Income Statement
B36: Sales | C36: =IF(C$4="","",C4) -> 8699 | D36: =IF(D$4="","",D4) -> 8953 | E36: =IF(E$4="","",E4) -> 9003 | F36: =IF(F$4="","",F4) -> 8696 | G36: =IF(G$4="","",G4) -> 8040 | H36: =IF(H$4="","",H4) -> 7794 | I36: =IF(I$4="","",I4) -> 5770.692 | J36: =IF(J$4="","",J4) -> 5425.129 | ... M36: =IF(M$4="","",M4)
B37: COGS | C37: =IF(C$4="","",-C5) -> -4129 | D37: =IF(D$4="","",-D5) -> -4209 | E37: =IF(E$4="","",-E5) -> -4130 | F37: =IF(F$4="","",-F5) -> -3968 | G37: =IF(G$4="","",-G5) -> -3579 | H37: =IF(H$4="","",-H5) -> -3427 | I37: =IF(I$4="","",-I5) -> -2308.606 | J37: =IF(J$4="","",-J5) -> -2101.982 | ... M37: =IF(M$4="","",-M5)
B38: Gross Margin | C38: =IF(C36="","",C36+C37) -> 4570 | D38: =IF(D36="","",D36+D37) -> 4744 | E38: =IF(E36="","",E36+E37) -> 4873 | F38: =IF(F36="","",F36+F37) -> 4728 | G38: =IF(G36="","",G36+G37) -> 4461 | H38: =IF(H36="","",H36+H37) -> 4367 | I38: =IF(I36="","",I36+I37) -> 3462.086 | J38: =IF(J36="","",J36+J37) -> 3323.147 | ... M38: =IF(M36="","",M36+M37)
B39: OPEX | C39: =IF(C$4="","",-C6) -> -2634 | D39: =IF(D$4="","",-D6) -> -2844 | E39: =IF(E$4="","",-E6) -> 0 | F39: =IF(F$4="","",-F6) -> 0 | G39: =IF(G$4="","",-G6) -> 0 | H39: =IF(H$4="","",-H6) -> 0 | I39: =IF(I$4="","",-I6) -> 0 | J39: =IF(J$4="","",-J6) -> 0 | ... M39: =IF(M$4="","",-M6)
B40: Incl. Selling Expenses | C40: =IF(C$4="","",-C7) -> -1263 | D40: =IF(D$4="","",-D7) -> -1290 | E40: =IF(E$4="","",-E7) -> 0 | F40: =IF(F$4="","",-F7) -> 0 | G40: =IF(G$4="","",-G7) -> 0 | H40: =IF(H$4="","",-H7) -> 0 | I40: =IF(I$4="","",-I7) -> 0 | J40: =IF(J$4="","",-J7) -> 0 | ... M40: =IF(M$4="","",-M7)
B41: Incl. Other Opex | C41: =IF(C$4="","",C39-C40) -> -1371 | D41: =IF(D$4="","",D39-D40) -> -1554 | E41: =IF(E$4="","",E39-E40) -> 0 | F41: =IF(F$4="","",F39-F40) -> 0 | G41: =IF(G$4="","",G39-G40) -> 0 | H41: =IF(H$4="","",H39-H40) -> 0 | I41: =IF(I$4="","",I39-I40) -> 0 | J41: =IF(J$4="","",J39-J40) -> 0 | ... M41: =IF(M$4="","",M39-M40)
B42: R&D | C42: =IF(C$4="","",-C8) -> 0 | D42: =IF(D$4="","",-D8) -> 0 | E42: =IF(E$4="","",-E8) -> 0 | F42: =IF(F$4="","",-F8) -> 0 | G42: =IF(G$4="","",-G8) -> 0 | H42: =IF(H$4="","",-H8) -> 0 | I42: =IF(I$4="","",-I8) -> 0 | J42: =IF(J$4="","",-J8) -> 0 | ... M42: =IF(M$4="","",-M8)
B43: Operating EBIT | C43: =IF(C$4="","",C38+C39+C42) -> 1936 | D43: =IF(D$4="","",D38+D39+D42) -> 1900 | E43: =IF(E$4="","",E38+E39+E42) -> 4873 | F43: =IF(F$4="","",F38+F39+F42) -> 4728 | G43: =IF(G$4="","",G38+G39+G42) -> 4461 | H43: =IF(H$4="","",H38+H39+H42) -> 4367 | I43: =IF(I$4="","",I38+I39+I42) -> 3462.086 | J43: =IF(J$4="","",J38+J39+J42) -> 3323.147 | ... M43: =IF(M$4="","",M38+M39+M42)
...

Sheet BS
B1: Most Recent Quarter | C1: 45657 | F1: =IF(MONTH(C1)=MONTH(Normalized_FCF!G1),"FY","Quarter")&" Report" -> FY Report | H1: =scaling_factor -> 1000000
B2: Lastest Balance Sheet
B3: ST Operating Assets | C3: Book | D3: Valued @ | F3: ST Non-Operating Assets | G3: Book | H3: Valued @
B4: ST AR | C4: 676 | D4: 0.6 | F4: Cash and cash equivalents | G4: 162 | H4: 0.9
B5: Operating ST Financial Assets | C5: 0 | D5: 0.6 | F5: Restricted cash | G5: 0 | H5: 0.7
B6: Inventory | C6: 0 | D6: 0.5 | F6: Securities with stable income | G6: 0 | H6: 0.6
B7: Properties held for sale | C7: 0 | D7: 0.6 | F7: Other Securities | G7: 0 | H7: 0.6
B8: Properties held for income | C8: 0 | D8: 0.6 | F8: Properties with stable income | G8: 0 | H8: 0.6
B9: Prepayments and Contract Assets | C9: 290 | D9: 0.1 | F9: Other Properties | G9: 0 | H9: 0.6
B10: ST DTA | C10: 0 | D10: 0.9
B11: Other ST Assets | C11: 21 | D11: 0.05
B12: Operating ST Assets | C12: =SUM(C4:C11) -> 987 | D12: =C4*D4+C5*D5+C9*D9+C6*D6+C8*D8+C7*D7+C10*D10+C11*D11 -> 435.65 | F12: Non-Operating ST Assets | G12: =SUM(G4:G9) -> 162 | H12: =G4*H4+G5*H5+G6*H6+G7*H7+G8*H8+G9*H9 -> 145.8
B14: LT Operating Assets | C14: Book | D14: Valued @ | F14: LT Non-Operating Assets | G14: Book | H14: Valued @
B15: LT AR and Prepayments | C15: 0 | D15: 0.4 | F15: LT Depositis | G15: 0 | H15: 0.8
B16: Operating LT Financial Assets | C16: 0 | D16: 0.5 | F16: Securities with stable income | G16: 0 | H16: 0.6
B17: Properties held for sale | C17: 0 | D17: 0.6 | F17: Other Securities | G17: 1043 | H17: 0.6
B18: Properties held for income | C18: 0 | D18: 0.6 | F18: JV or associate with stable income | G18: 0 | H18: 0.1
B19: PP&E & Right of Use Assets | C19: 2109 | D19: 0.1 | F19: Other JV or associate | G19: 0 | H19: 0.1
B20: Biological assets | C20: 0 | D20: 0.05 | F20: Properties with stable income | G20: 0 | H20: 0.2
B21: Intangible assets | C21: =8610+1579 -> 10189 | D21: 0.2 | F21: Other Properties | G21: 0 | H21: 0.1
B22: LT DTA | C22: 0 | D22: 0.9
B23: Other assets & Goodwill | C23: =12390+641 -> 13031 | D23: 0
B24: Operating LT Assets | C24: =SUM(C15:C23) -> 25329 | D24: =C15*D15+C16*D16+C18*D18+C17*D17+C19*D19+C20*D20+C21*D21+C22*D22+C23*D23 -> 2248.7 | F24: Non-Operating LT Assets | G24: =SUM(G15:G21) -> 1043 | H24: =G15*H15+G16*H16+G17*H17+G18*H18+G19*H19+G20*H20+G21*H21 -> 625.8
B26: ST Liabilities | C26: Book | F26: BS Summary | G26: Book | H26: Valued @
B27: ST Borrowing | C27: 172 | F27: Total Equity | G27: =G32-G30 -> 11074 | H27: =H32-G30 -> -12991.05
B28: ST Lease liabilities | C28: 0 | F28: Incl. Minority Interest (NCI) | G28: 0
B29: ST SH Loan | C29: 0 | F29: Incl. Common Equity | G29: =G27-G28 -> 11074 | H29: =H27-G28 -> -12991.05
B30: ST Financial Liabilities | C30: 61 | F30: Total Liabilities | G30: =C33+C42 -> 16447
B31: ST Interest-bearing Debt | C31: =SUM(C27:C30) -> 233 | F31: incl. Interest-bearing Debt | G31: =C31+C40 -> 10547
B32: Other ST liabilities | C32: =C33-C31 -> 2498 | F32: Total Assets | G32: =G35+G40 -> 27521 | H32: =H35+H40 -> 3455.95
B33: Current Liabilities | C33: 2731
F34: Assets Summary | G34: Book | H34: Valued @
B35: LT Liabilities | C35: Book | F35: Operating Assets | G35: =C12+C24 -> 26316 | H35: =D12+D24 -> 2684.35
B36: LT Borrowing | C36: 0 | F36: incl. AR | G36: =C4+C15 -> 676
B37: LT Lease liabilities | C37: 0 | F37: incl. inventory | G37: =C6 -> 0
B38: LT SH Loan | C38: 0 | F38: incl. Properties held for sale | G38: =C7+C17 -> 0
B39: LT Financial Liabilities | C39: 10314 | F39: incl. Fixed Assets | G39: =C7+C17+C19+C20 -> 2109 | H39: =C7*D7+C17*D17+C19*D19+C20*D20 -> 210.9
B40: LT Interest-bearing Debt | C40: =SUM(C36:C39) -> 10314 | F40: Non-operating Assets | G40: =G12+G24 -> 1205 | H40: =H12+H24 -> 771.6
B41: Other LT liabilities | C41: =C42-C40 -> 3402 | F41: incl. Assets with stable income | G41: =C70 -> 162 | H41: =H40-H42 -> 145.8
B42: Noncurrent Liabilities | C42: 13716 | F42: incl. Other Assets | G42: =C82 -> 1043 | H42: =D82 -> 625.8
...

Sheet Normalized_FCF
B1: =Thesis!C25 -> USD | C1: Normalized | G1: =Data!C1 -> 45657 | H1: =EOMONTH(EDATE(G1,-12),0) -> 45291 | I1: =EOMONTH(EDATE(H1,-12),0) -> 44926 | J1: =EOMONTH(EDATE(I1,-12),0) -> 44561 | K1: =EOMONTH(EDATE(J1,-12),0) -> 44196 | L1: =EOMONTH(EDATE(K1,-12),0) -> 43830 | M1: =EOMONTH(EDATE(L1,-12),0) -> 43465 | N1: =EOMONTH(EDATE(M1,-12),0) -> 43100 | O1: =EOMONTH(EDATE(N1,-12),0) -> 42735 | ... Q1: =EOMONTH(EDATE(P1,-12),0) -> 42004
B2: FCFE Analysis | E2: Notes
B3: FCFE | C3: =scaling_factor -> 1000000
B4: Sales | C4: =AVERAGE(G4:J4) -> 8837.75 | G4: =Data!C36 -> 8699 | H4: =Data!D36 -> 8953 | I4: =Data!E36 -> 9003 | J4: =Data!F36 -> 8696 | K4: =Data!G36 -> 8040 | L4: =Data!H36 -> 7794 | M4: =Data!I36 -> 5770.692 | N4: =Data!J36 -> 5425.129 | ... Q4: =Data!M36
B5: Variable Costs | C5: =C25 -> -4748.2726 | G5: =G25 -> -5392 | H5: =H25 -> -5499 | I5: =I25 -> -4130 | J5: =J25 -> -3968 | K5: =K25 -> -3579 | L5: =L25 -> -3427 | M5: =M25 -> -2308.606 | N5: =N25 -> -2101.982 | ... Q5: =Q25
B6: Contribution Margin | C6: =C4+C5 -> 4089.4774 | G6: =IF(G4="","",G4+G5) -> 3307 | H6: =IF(H4="","",H4+H5) -> 3454 | I6: =IF(I4="","",I4+I5) -> 4873 | J6: =IF(J4="","",J4+J5) -> 4728 | K6: =IF(K4="","",K4+K5) -> 4461 | L6: =IF(L4="","",L4+L5) -> 4367 | M6: =IF(M4="","",M4+M5) -> 3462.086 | N6: =IF(N4="","",N4+N5) -> 3323.147 | ... Q6: =IF(Q4="","",Q4+Q5)
B7: Fixed Costs | C7: =C35 -> -1462.5 | G7: =G35 -> -1371 | H7: =H35 -> -1554 | I7: =I35 -> 0 | J7: =J35 -> 0 | K7: =K35 -> 0 | L7: =L35 -> 0 | M7: =M35 -> 0 | N7: =N35 -> 0 | ... Q7: =Q35
B8: Operating EBIT | C8: =C6+C7 -> 2626.9774 | G8: =IF(G$4="","",G6+G7) -> 1936 | H8: =IF(H$4="","",H6+H7) -> 1900 | I8: =IF(I$4="","",I6+I7) -> 4873 | J8: =IF(J$4="","",J6+J7) -> 4728 | K8: =IF(K$4="","",K6+K7) -> 4461 | L8: =IF(L$4="","",L6+L7) -> 4367 | M8: =IF(M$4="","",M6+M7) -> 3462.086 | N8: =IF(N$4="","",N6+N7) -> 3323.147 | ... Q8: =IF(Q$4="","",Q6+Q7)
B9: Add Back D&A | C9: =BS!$G$39*BS!D58 -> 578 | G9: =IF(Data!C61="","",-Data!C61) -> 578 | H9: =IF(Data!D61="","",-Data!D61) -> 624 | I9: =IF(Data!E61="","",-Data!E61) -> 0 | J9: =IF(Data!F61="","",-Data!F61) -> 0 | K9: =IF(Data!G61="","",-Data!G61) -> 0 | L9: =IF(Data!H61="","",-Data!H61) -> 0 | M9: =IF(Data!I61="","",-Data!I61) -> 0 | N9: =IF(Data!J61="","",-Data!J61) -> 0 | ... Q9: =IF(Data!M61="","",-Data!M61)
B10: Maintenance Capex | C10: =-C4*C78 -> -632.3134 | G10: =Data!C62 -> -728 | H10: =Data!D62 -> -728 | I10: =Data!E62 -> -650 | J10: =Data!F62 -> -426 | K10: =Data!G62 -> -388 | L10: =Data!H62 -> 0 | M10: =Data!I62 -> 0 | N10: =Data!J62 -> 0 | ... Q10: =Data!M62
B11: Stable Non-Operating EBIT | C11: =C63 -> 0 | G11: =G61 -> 0 | H11: =H61 -> 0 | I11: =I61 -> 0 | J11: =J61 -> 0 | K11: =K61 -> 0 | L11: =L61 -> 0 | M11: =M61 -> 0 | N11: =N61 -> 0 | ... Q11: =Q61
B12: Net Interest Income | C12: =C50 -> -496 | G12: =G50 -> -496 | H12: =H50 -> -423 | I12: =I50 -> -422 | J12: =J50 -> -415 | K12: =K50 -> -394 | L12: =L50 -> -390 | M12: =M50 -> -350.073 | N12: =N50 -> -345.82 | ... Q12: =Q50
B13: Pre-tax Profit | C13: =SUM(C8:C12) -> 2076.664 | G13: =IF(G$4="","",SUM(G8:G12)) -> 1290 | H13: =IF(H$4="","",SUM(H8:H12)) -> 1373 | I13: =IF(I$4="","",SUM(I8:I12)) -> 3801 | J13: =IF(J$4="","",SUM(J8:J12)) -> 3887 | K13: =IF(K$4="","",SUM(K8:K12)) -> 3679 | L13: =IF(L$4="","",SUM(L8:L12)) -> 3977 | M13: =IF(M$4="","",SUM(M8:M12)) -> 3112.013 | N13: =IF(N$4="","",SUM(N8:N12)) -> 2977.327 | ... Q13: =IF(Q$4="","",SUM(Q8:Q12))
B14: Income Tax | C14: =-SUM(C8+C11,C12)*C43 -> -532.74436 | G14: =Data!C46 -> -210 | H14: =Data!D46 -> -260 | I14: =Data!E46 -> -392 | J14: =Data!F46 -> -212 | K14: =Data!G46 -> -299 | L14: =Data!H46 -> -283 | M14: =Data!I46 -> -244.681 | N14: =Data!J46 -> -616.301 | ... Q14: =Data!M46
B15: NCI’s Share of Profits | C15: =-C4*C83 -> 0 | G15: =Data!C48 -> 0 | H15: =Data!D48 -> -202 | I15: =Data!E48 -> 0 | J15: =Data!F48 -> 0 | K15: =Data!G48 -> 0 | L15: =Data!H48 -> 0 | M15: =Data!I48 -> 0 | N15: =Data!J48 -> 0 | ... Q15: =Data!M48
B16: After-tax Profit | C16: =SUM(C13:C15) -> 1543.9197 | G16: =IF(G$4="","",SUM(G13:G15)) -> 1080 | H16: =IF(H$4="","",SUM(H13:H15)) -> 911 | I16: =IF(I$4="","",SUM(I13:I15)) -> 3409 | J16: =IF(J$4="","",SUM(J13:J15)) -> 3675 | K16: =IF(K$4="","",SUM(K13:K15)) -> 3380 | L16: =IF(L$4="","",SUM(L13:L15)) -> 3694 | M16: =IF(M$4="","",SUM(M13:M15)) -> 2867.332 | N16: =IF(N$4="","",SUM(N13:N15)) -> 2361.026 | ... Q16: =IF(Q$4="","",SUM(Q13:Q15))
B17: WCInv | C17: =-C4*C85 -> 0 | E17: WCInv is by default excluded
B18: Net Borrowing | C18: 0 | E18: Net borrowing is excluded
B19: FCFE | C19: =C16+C17 -> 1543.9197 | G19: =IF(G$4="","",G16+G17) -> 1080 | H19: =IF(H$4="","",H16+H17) -> 911 | I19: =IF(I$4="","",I16+I17) -> 3409 | J19: =IF(J$4="","",J16+J17) -> 3675 | K19: =IF(K$4="","",K16+K17) -> 3380 | L19: =IF(L$4="","",L16+L17) -> 3694 | M19: =IF(M$4="","",M16+M17) -> 2867.332 | N19: =IF(N$4="","",N16+N17) -> 2361.026 | ... Q19: =IF(Q$4="","",Q16+Q17)
B21: Operating Cost Structure | E21: Notes
B22: Variable Costs
B23: COGS | C23: =-C4*C28 -> -4109.1378 | G23: =Data!C37 -> -4129 | H23: =Data!D37 -> -4209 | I23: =Data!E37 -> -4130 | J23: =Data!F37 -> -3968 | K23: =Data!G37 -> -3579 | L23: =Data!H37 -> -3427 | M23: =Data!I37 -> -2308.606 | N23: =Data!J37 -> -2101.982 | ... Q23: =Data!M37
B24: Selling Expenses | C24: =-C4*C29 -> -639.13478 | G24: =Data!C40 -> -1263 | H24: =Data!D40 -> -1290 | I24: =Data!E40 -> 0 | J24: =Data!F40 -> 0 | K24: =Data!G40 -> 0 | L24: =Data!H40 -> 0 | M24: =Data!I40 -> 0 | N24: =Data!J40 -> 0 | ... Q24: =Data!M40
B25: Variable Costs | C25: =C23+C24 -> -4748.2726 | G25: =IF(G$4="","",G23+G24) -> -5392 | H25: =IF(H$4="","",H23+H24) -> -5499 | I25: =IF(I$4="","",I23+I24) -> -4130 | J25: =IF(J$4="","",J23+J24) -> -3968 | K25: =IF(K$4="","",K23+K24) -> -3579 | L25: =IF(L$4="","",L23+L24) -> -3427 | M25: =IF(M$4="","",M23+M24) -> -2308.606 | N25: =IF(N$4="","",N23+N24) -> -2101.982 | ... Q25: =IF(Q$4="","",Q23+Q24)
B27: Variable Costs % of Sales
B28: COGS | C28: =AVERAGE(G28:J28) -> 0.46495293 | E28: Historical Average | G28: =IF(G$4="","",ABS(G23/G$4)) -> 0.47465226 | H28: =IF(H$4="","",ABS(H23/H$4)) -> 0.47012175 | I28: =IF(I$4="","",ABS(I23/I$4)) -> 0.45873598 | J28: =IF(J$4="","",ABS(J23/J$4)) -> 0.45630175 | K28: =IF(K$4="","",ABS(K23/K$4)) -> 0.44514925 | L28: =IF(L$4="","",ABS(L23/L$4)) -> 0.4396972 | M28: =IF(M$4="","",ABS(M23/M$4)) -> 0.40005705 | N28: =IF(N$4="","",ABS(N23/N$4)) -> 0.38745291 | ... Q28: =IF(Q$4="","",ABS(Q23/Q$4))
B29: =B24 -> Selling Expenses | C29: =AVERAGE(G29:J29) -> 0.072318721 | E29: Historical Average | G29: =IF(G$4="","",ABS(G24/G$4)) -> 0.1451891 | H29: =IF(H$4="","",ABS(H24/H$4)) -> 0.14408578 | I29: =IF(I$4="","",ABS(I24/I$4)) -> 0 | J29: =IF(J$4="","",ABS(J24/J$4)) -> 0 | K29: =IF(K$4="","",ABS(K24/K$4)) -> 0 | L29: =IF(L$4="","",ABS(L24/L$4)) -> 0 | M29: =IF(M$4="","",ABS(M24/M$4)) -> 0 | N29: =IF(N$4="","",ABS(N24/N$4)) -> 0 | ... Q29: =IF(Q$4="","",ABS(Q24/Q$4))
B30: Variable Costs | C30: =ABS(C25/$C$4) -> 0.53727165 | G30: =IF(G$4="","",ABS(G25/G$4)) -> 0.61984136 | H30: =IF(H$4="","",ABS(H25/H$4)) -> 0.61420753 | I30: =IF(I$4="","",ABS(I25/I$4)) -> 0.45873598 | J30: =IF(J$4="","",ABS(J25/J$4)) -> 0.45630175 | K30: =IF(K$4="","",ABS(K25/K$4)) -> 0.44514925 | L30: =IF(L$4="","",ABS(L25/L$4)) -> 0.4396972 | M30: =IF(M$4="","",ABS(M25/M$4)) -> 0.40005705 | N30: =IF(N$4="","",ABS(N25/N$4)) -> 0.38745291 | ... Q30: =IF(Q$4="","",ABS(Q25/Q$4))
B32: Fixed Costs
B33: G&A and other Opex | C33: =AVERAGE(G33:H33) -> -1462.5 | E33: Historical Average | G33: =Data!C41 -> -1371 | H33: =Data!D41 -> -1554 | I33: =Data!E41 -> 0 | J33: =Data!F41 -> 0 | K33: =Data!G41 -> 0 | L33: =Data!H41 -> 0 | M33: =Data!I41 -> 0 | N33: =Data!J41 -> 0 | ... Q33: =Data!M41
B34: R&D | C34: =AVERAGE(G34:J34) -> 0 | E34: Historical Average | G34: =Data!C42 -> 0 | H34: =Data!D42 -> 0 | I34: =Data!E42 -> 0 | J34: =Data!F42 -> 0 | K34: =Data!G42 -> 0 | L34: =Data!H42 -> 0 | M34: =Data!I42 -> 0 | N34: =Data!J42 -> 0 | ... Q34: =Data!M42
B35: Fixed Costs | C35: =C33+C34 -> -1462.5 | G35: =IF(G4="","",G33+G34) -> -1371 | H35: =IF(H4="","",H33+H34) -> -1554 | I35: =IF(I4="","",I33+I34) -> 0 | J35: =IF(J4="","",J33+J34) -> 0 | K35: =IF(K4="","",K33+K34) -> 0 | L35: =IF(L4="","",L33+L34) -> 0 | M35: =IF(M4="","",M33+M34) -> 0 | N35: =IF(N4="","",N33+N34) -> 0 | ... Q35: =IF(Q4="","",Q33+Q34)
B37: Fixed Costs % of Sales
B38: =B33 -> G&A and other Opex | C38: =ABS(C33/$C$4) -> 0.1654833 | G38: =IF(G$4="","",ABS(G33/G$4)) -> 0.15760432 | H38: =IF(H$4="","",ABS(H33/H$4)) -> 0.1735731 | I38: =IF(I$4="","",ABS(I33/I$4)) -> 0 | J38: =IF(J$4="","",ABS(J33/J$4)) -> 0 | K38: =IF(K$4="","",ABS(K33/K$4)) -> 0 | L38: =IF(L$4="","",ABS(L33/L$4)) -> 0 | M38: =IF(M$4="","",ABS(M33/M$4)) -> 0 | N38: =IF(N$4="","",ABS(N33/N$4)) -> 0 | ... Q38: =IF(Q$4="","",ABS(Q33/Q$4))
B39: =B34 -> R&D | C39: =ABS(C34/$C$4) -> 0 | G39: =IF(G$4="","",ABS(G34/G$4)) -> 0 | H39: =IF(H$4="","",ABS(H34/H$4)) -> 0 | I39: =IF(I$4="","",ABS(I34/I$4)) -> 0 | J39: =IF(J$4="","",ABS(J34/J$4)) -> 0 | K39: =IF(K$4="","",ABS(K34/K$4)) -> 0 | L39: =IF(L$4="","",ABS(L34/L$4)) -> 0 | M39: =IF(M$4="","",ABS(M34/M$4)) -> 0 | N39: =IF(N$4="","",ABS(N34/N$4)) -> 0 | ... Q39: =IF(Q$4="","",ABS(Q34/Q$4))
B40: Fixed Costs | C40: =ABS(C35/$C$4) -> 0.1654833 | G40: =IF(G$4="","",ABS(G35/G$4)) -> 0.15760432 | H40: =IF(H$4="","",ABS(H35/H$4)) -> 0.1735731 | I40: =IF(I$4="","",ABS(I35/I$4)) -> 0 | J40: =IF(J$4="","",ABS(J35/J$4)) -> 0 | K40: =IF(K$4="","",ABS(K35/K$4)) -> 0 | L40: =IF(L$4="","",ABS(L35/L$4)) -> 0 | M40: =IF(M$4="","",ABS(M35/M$4)) -> 0 | N40: =IF(N$4="","",ABS(N35/N$4)) -> 0 | ... Q40: =IF(Q$4="","",ABS(Q35/Q$4))
B42: Tax % of Pre-tax Profit
B43: Income Tax Rate | C43: 0.25 | E43: Use the highest past tax rate | G43: =IF(G$4="","",-G14/SUM(G8+G11,G12)) -> 0.14583333 | H43: =IF(H$4="","",-H14/SUM(H8+H11,H12)) -> 0.1760325 | I43: =IF(I$4="","",-I14/SUM(I8+I11,I12)) -> 0.088070097 | J43: =IF(J$4="","",-J14/SUM(J8+J11,J12)) -> 0.049153721 | K43: =IF(K$4="","",-K14/SUM(K8+K11,K12)) -> 0.073518564 | L43: =IF(L$4="","",-L14/SUM(L8+L11,L12)) -> 0.071159165 | M43: =IF(M$4="","",-M14/SUM(M8+M11,M12)) -> 0.078624672 | N43: =IF(N$4="","",-N14/SUM(N8+N11,N12)) -> 0.20699809 | ... Q43: =IF(Q$4="","",-Q14/SUM(Q8+Q11,Q12))
B45: Non-operating Income | E45: Notes
B46: Interest
...

Sheet DCF
B2: No-Growth DCF Valuation | H2: Notes
B3: No-Growth DCF | C3: =scaling_factor -> 1000000 | E3: Special Assumption
B4: Adjusted FCFE | C4: =Normalized_FCF!C19 -> 1543.9197 | D4: =Reporting_currency -> USD | E4: Terminal Growth Rate (g): | F4: =Terminal_Growth -> 0
B5: /Equity Cost of Capital | C5: =Equity_Cost -> 0.075
B6: Stable Income Value | C6: =(C4*(1+Terminal_Growth))/(Equity_Cost-Terminal_Growth) -> 20585.596 | D6: =Reporting_currency -> USD | E6: Conservative Valuation: Setting g=0 can be a conservative assumption to avoid overestimating the stock’s value, especially if future growth is uncertain or unreliable.
B7: - Interest-bearing Debt | C7: =BS!G31 -> 10547 | D7: =Reporting_currency -> USD
B8: + Non-operating Cash | C8: =BS!D66 -> -372.31656 | D8: =Reporting_currency -> USD
B9: + Other Non-operating Assets | C9: =BS!H42 -> 625.8 | D9: =Reporting_currency -> USD
B10: Equity Value | C10: =C6-C7+C8+C9 -> 10292.079 | D10: =Reporting_currency -> USD
B11: * Exchange rate | C11: =Exchange_Rate -> 1 | D11: =Thesis!C15 -> USD
B12: Equity Value per share | C12: =(C10*scaling_factor)/Common_Shares*Exchange_Rate -> 30.390955 | D12: =Market_currency -> USD
B14: Implied Growth Scenario Analysis
B15: FCFE Projection
B16: High Growth Period (HGP) | C16: =Scenarios!C65 -> 0.014959784
B17: High Growth Rate (HGR) | C17: =Scenarios!C64 -> 10
B18: Value Per Share | C18: =(F52-C7+C8+C9)*Exchange_Rate/Common_Shares*scaling_factor -> 33.228136 | D18: =Market_currency -> USD
B20: Year | C20: FCFE | D20: Growth Rates | E20: Discount Factor | F20: PV of FCFE
B21: 1 | C21: =C4*(1+D21) -> 1567.0164 | D21: =IF($C$17<B21,0,DCF!$C$16) -> 0.014959784 | E21: =IF($C$17<B21,0,1/(1+Equity_Cost)^B21) -> 0.93023256 | F21: =C21*E21 -> 1457.6897
B22: 2 | C22: =IF(ROW()-ROW($C$21)<$C$17, $C$21*(1+D22)^(ROW()-ROW($C$21)), 0) -> 1590.4586 | D22: =IF($C$17<B22,0,DCF!$C$16) -> 0.014959784 | E22: =IF($C$17<B22,0,1/(1+Equity_Cost)^B22) -> 0.86533261 | F22: =C22*E22 -> 1376.2757
B23: 3 | C23: =IF(ROW()-ROW($C$21)<$C$17, $C$21*(1+D23)^(ROW()-ROW($C$21)), 0) -> 1614.2515 | D23: =IF($C$17<B23,0,DCF!$C$16) -> 0.014959784 | E23: =IF($C$17<B23,0,1/(1+Equity_Cost)^B23) -> 0.80496057 | F23: =C23*E23 -> 1299.4088
B24: 4 | C24: =IF(ROW()-ROW($C$21)<$C$17, $C$21*(1+D24)^(ROW()-ROW($C$21)), 0) -> 1638.4004 | D24: =IF($C$17<B24,0,DCF!$C$16) -> 0.014959784 | E24: =IF($C$17<B24,0,1/(1+Equity_Cost)^B24) -> 0.74880053 | F24: =C24*E24 -> 1226.8351
B25: 5 | C25: =IF(ROW()-ROW($C$21)<$C$17, $C$21*(1+D25)^(ROW()-ROW($C$21)), 0) -> 1662.9105 | D25: =IF($C$17<B25,0,DCF!$C$16) -> 0.014959784 | E25: =IF($C$17<B25,0,1/(1+Equity_Cost)^B25) -> 0.69655863 | F25: =C25*E25 -> 1158.3147
B26: 6 | C26: =IF(ROW()-ROW($C$21)<$C$17, $C$21*(1+D26)^(ROW()-ROW($C$21)), 0) -> 1687.7873 | D26: =IF($C$17<B26,0,DCF!$C$16) -> 0.014959784 | E26: =IF($C$17<B26,0,1/(1+Equity_Cost)^B26) -> 0.64796152 | F26: =C26*E26 -> 1093.6212
B27: 7 | C27: =IF(ROW()-ROW($C$21)<$C$17, $C$21*(1+D27)^(ROW()-ROW($C$21)), 0) -> 1713.0362 | D27: =IF($C$17<B27,0,DCF!$C$16) -> 0.014959784 | E27: =IF($C$17<B27,0,1/(1+Equity_Cost)^B27) -> 0.6027549 | F27: =C27*E27 -> 1032.541
B28: 8 | C28: =IF(ROW()-ROW($C$21)<$C$17, $C$21*(1+D28)^(ROW()-ROW($C$21)), 0) -> 1738.6629 | D28: =IF($C$17<B28,0,DCF!$C$16) -> 0.014959784 | E28: =IF($C$17<B28,0,1/(1+Equity_Cost)^B28) -> 0.56070223 | F28: =C28*E28 -> 974.87215
B29: 9 | C29: =IF(ROW()-ROW($C$21)<$C$17, $C$21*(1+D29)^(ROW()-ROW($C$21)), 0) -> 1764.6729 | D29: =IF($C$17<B29,0,DCF!$C$16) -> 0.014959784 | E29: =IF($C$17<B29,0,1/(1+Equity_Cost)^B29) -> 0.52158347 | F29: =C29*E29 -> 920.42422
B30: 10 | C30: =IF(ROW()-ROW($C$21)<$C$17, $C$21*(1+D30)^(ROW()-ROW($C$21)), 0) -> 1791.072 | D30: =IF($C$17<B30,0,DCF!$C$16) -> 0.014959784 | E30: =IF($C$17<B30,0,1/(1+Equity_Cost)^B30) -> 0.48519393 | F30: =C30*E30 -> 869.01727
B31: 11 | C31: =IF(ROW()-ROW($C$21)<$C$17, $C$21*(1+D31)^(ROW()-ROW($C$21)), 0) -> 0 | D31: =IF($C$17<B31,0,DCF!$C$16) -> 0 | E31: =IF($C$17<B31,0,1/(1+Equity_Cost)^B31) -> 0 | F31: =C31*E31 -> 0
B32: 12 | C32: =IF(ROW()-ROW($C$21)<$C$17, $C$21*(1+D32)^(ROW()-ROW($C$21)), 0) -> 0 | D32: =IF($C$17<B32,0,DCF!$C$16) -> 0 | E32: =IF($C$17<B32,0,1/(1+Equity_Cost)^B32) -> 0 | F32: =C32*E32 -> 0
B33: 13 | C33: =IF(ROW()-ROW($C$21)<$C$17, $C$21*(1+D33)^(ROW()-ROW($C$21)), 0) -> 0 | D33: =IF($C$17<B33,0,DCF!$C$16) -> 0 | E33: =IF($C$17<B33,0,1/(1+Equity_Cost)^B33) -> 0 | F33: =C33*E33 -> 0
... B50: 30 | C50: =IF(ROW()-ROW($C$21)<$C$17, $C$21*(1+D50)^(ROW()-ROW($C$21)), 0) -> 0 | D50: =IF($C$17<B50,0,DCF!$C$16) -> 0 | E50: =IF($C$17<B50,0,1/(1+Equity_Cost)^B50) -> 0 | F50: =C50*E50 -> 0
B51: Terminal Year | C51: =C$21*(1+Terminal_Growth)^$C$17/Equity_Cost -> 20893.552 | D51: =Terminal_Growth -> 0 | E51: =1/(1+Equity_Cost)^C17 -> 0.48519393 | F51: =C51*E51 -> 10137.424
E52: Total PV | F52: =SUM(F21:F51) -> 21546.424
B54: Sensitivity Analysis (Enterprise Value)
A55: =F52 -> 21546.424 | B55: =C78 -> -0.05 | C55: =C77 -> -0.01 | D55: =C76 -> 0.015 | E55: =C75 -> 0.035 | F55: =C74 -> 0.055
A56: 5 | B56: 19031.588 | C56: 20266.083 | D56: 21073.43 | E56: 21740.395 | F56: 22427.001
A57: 10 | B57: 17813.688 | C57: 19979.681 | D57: 21549.099 | E57: 22944.909 | F57: 24481.698
A58: 15 | B58: 16505.922 | C58: 19642.91 | D58: 22143.782 | E58: 24530.139 | F58: 27333.735
A59: 20 | B59: 15347.362 | C59: 19317.395 | D59: 22755.629 | E59: 26251.684 | F59: 30613.825
A60: 25 | B60: 14406.892 | C60: 19030.419 | D60: 23330.105 | E60: 27961.561 | F60: 34076.15
...

Sheet DDM
B2: No-Growth DDM Valuation | H2: Notes
B3: No-Growth DDM | C3: =scaling_factor -> 1000000 | E3: Special Assumption
B4: Dividend | C4: =Normalized_FCF!C91*(1-dividend_tax_rate) -> 140.71834 | D4: =Market_currency -> USD | E4: Terminal Growth Rate (g): | F4: =Thesis!E22 -> 0
B5: /Equity Cost of Capital | C5: =Equity_Cost -> 0.075
B6: Dividend Value | C6: =(C4*(1+Terminal_Growth))/(Equity_Cost-Terminal_Growth) -> 1876.2445 | D6: =Reporting_currency -> USD
B7: Dividend Value per share | C7: =(C6*scaling_factor)/Common_Shares*Exchange_Rate -> 5.5402667 | D7: =Market_currency -> USD
B9: Implied Growth Scenario Analysis
B10: FCFE Projection
B11: High Growth Period (HGP) | C11: =Scenarios!C65 -> 0.014959784
B12: High Growth Rate (HGR) | C12: =Scenarios!C64 -> 10
B13: Value Per Share | C13: =F47/Common_Shares*scaling_factor -> 5.7988575 | D13: =Market_currency -> USD
B15: Year | C15: Dividends | D15: Growth Rates | E15: Discount Factor | F15: PV of Dividends
B16: 1 | C16: =C4*(1+D16) -> 142.82346 | D16: =IF($C$12<B16,0,DDM!$C$11) -> 0.014959784 | E16: =IF($C$12<B16,0,1/(1+Equity_Cost)^B16) -> 0.93023256 | F16: =C16*E16 -> 132.85903
B17: 2 | C17: =IF(ROW()-ROW($C$16)<$C$12, $C$16*(1+D17)^(ROW()-ROW($C$16)), 0) -> 144.96007 | D17: =IF($C$12<B17,0,DDM!$C$11) -> 0.014959784 | E17: =IF($C$12<B17,0,1/(1+Equity_Cost)^B17) -> 0.86533261 | F17: =C17*E17 -> 125.43867
B18: 3 | C18: =IF(ROW()-ROW($C$16)<$C$12, $C$16*(1+D18)^(ROW()-ROW($C$16)), 0) -> 147.12864 | D18: =IF($C$12<B18,0,DDM!$C$11) -> 0.014959784 | E18: =IF($C$12<B18,0,1/(1+Equity_Cost)^B18) -> 0.80496057 | F18: =C18*E18 -> 118.43275
B19: 4 | C19: =IF(ROW()-ROW($C$16)<$C$12, $C$16*(1+D19)^(ROW()-ROW($C$16)), 0) -> 149.32965 | D19: =IF($C$12<B19,0,DDM!$C$11) -> 0.014959784 | E19: =IF($C$12<B19,0,1/(1+Equity_Cost)^B19) -> 0.74880053 | F19: =C19*E19 -> 111.81812
B20: 5 | C20: =IF(ROW()-ROW($C$16)<$C$12, $C$16*(1+D20)^(ROW()-ROW($C$16)), 0) -> 151.56359 | D20: =IF($C$12<B20,0,DDM!$C$11) -> 0.014959784 | E20: =IF($C$12<B20,0,1/(1+Equity_Cost)^B20) -> 0.69655863 | F20: =C20*E20 -> 105.57293
B21: 6 | C21: =IF(ROW()-ROW($C$16)<$C$12, $C$16*(1+D21)^(ROW()-ROW($C$16)), 0) -> 153.83095 | D21: =IF($C$12<B21,0,DDM!$C$11) -> 0.014959784 | E21: =IF($C$12<B21,0,1/(1+Equity_Cost)^B21) -> 0.64796152 | F21: =C21*E21 -> 99.676534
B22: 7 | C22: =IF(ROW()-ROW($C$16)<$C$12, $C$16*(1+D22)^(ROW()-ROW($C$16)), 0) -> 156.13222 | D22: =IF($C$12<B22,0,DDM!$C$11) -> 0.014959784 | E22: =IF($C$12<B22,0,1/(1+Equity_Cost)^B22) -> 0.6027549 | F22: =C22*E22 -> 94.109464
B23: 8 | C23: =IF(ROW()-ROW($C$16)<$C$12, $C$16*(1+D23)^(ROW()-ROW($C$16)), 0) -> 158.46793 | D23: =IF($C$12<B23,0,DDM!$C$11) -> 0.014959784 | E23: =IF($C$12<B23,0,1/(1+Equity_Cost)^B23) -> 0.56070223 | F23: =C23*E23 -> 88.853322
B24: 9 | C24: =IF(ROW()-ROW($C$16)<$C$12, $C$16*(1+D24)^(ROW()-ROW($C$16)), 0) -> 160.83858 | D24: =IF($C$12<B24,0,DDM!$C$11) -> 0.014959784 | E24: =IF($C$12<B24,0,1/(1+Equity_Cost)^B24) -> 0.52158347 | F24: =C24*E24 -> 83.890743
B25: 10 | C25: =IF(ROW()-ROW($C$16)<$C$12, $C$16*(1+D25)^(ROW()-ROW($C$16)), 0) -> 163.24469 | D25: =IF($C$12<B25,0,DDM!$C$11) -> 0.014959784 | E25: =IF($C$12<B25,0,1/(1+Equity_Cost)^B25) -> 0.48519393 | F25: =C25*E25 -> 79.20533
B26: 11 | C26: =IF(ROW()-ROW($C$16)<$C$12, $C$16*(1+D26)^(ROW()-ROW($C$16)), 0) -> 0 | D26: =IF($C$12<B26,0,DDM!$C$11) -> 0 | E26: =IF($C$12<B26,0,1/(1+Equity_Cost)^B26) -> 0 | F26: =C26*E26 -> 0
B27: 12 | C27: =IF(ROW()-ROW($C$16)<$C$12, $C$16*(1+D27)^(ROW()-ROW($C$16)), 0) -> 0 | D27: =IF($C$12<B27,0,DDM!$C$11) -> 0 | E27: =IF($C$12<B27,0,1/(1+Equity_Cost)^B27) -> 0 | F27: =C27*E27 -> 0
B28: 13 | C28: =IF(ROW()-ROW($C$16)<$C$12, $C$16*(1+D28)^(ROW()-ROW($C$16)), 0) -> 0 | D28: =IF($C$12<B28,0,DDM!$C$11) -> 0 | E28: =IF($C$12<B28,0,1/(1+Equity_Cost)^B28) -> 0 | F28: =C28*E28 -> 0
... B45: 30 | C45: =IF(ROW()-ROW($C$16)<$C$12, $C$16*(1+D45)^(ROW()-ROW($C$16)), 0) -> 0 | D45: =IF($C$12<B45,0,DDM!$C$11) -> 0 | E45: =IF($C$12<B45,0,1/(1+Equity_Cost)^B45) -> 0 | F45: =C45*E45 -> 0
B46: Terminal Year | C46: =C$16*(1+F4)^$C$12/Equity_Cost -> 1904.3128 | D46: =Terminal_Growth -> 0 | E46: =1/(1+Equity_Cost)^C12 -> 0.48519393 | F46: =C46*E46 -> 923.96099
E47: Total PV | F47: =SUM(F16:F46) -> 1963.8179
B49: Sensitivity Analysis (Enterprise Value)
A50: =F47 -> 1963.8179 | B50: =C73 -> -0.05 | C50: =C72 -> -0.01 | D50: =C71 -> 0.015 | E50: =C70 -> 0.035 | F50: =C69 -> 0.055
A51: 5 | B51: 1734.6067 | C51: 1847.123 | D51: 1920.7075 | E51: 1981.497 | F51: 2044.0767
A52: 10 | B52: 1623.603 | C52: 1821.0193 | D52: 1964.0617 | E52: 2091.2807 | F52: 2231.3492
A53: 15 | B53: 1504.4085 | C53: 1790.3248 | D53: 2018.2632 | E53: 2235.7643 | F53: 2491.294
A54: 20 | B54: 1398.8133 | C54: 1760.6562 | D54: 2074.0291 | E54: 2392.672 | F54: 2790.2531
A55: 25 | B55: 1313.0955 | C55: 1734.5002 | D55: 2126.3889 | E55: 2548.5163 | F55: 3105.8218
A56: 30 | B56: 1246.8315 | C56: 1712.6441 | D56: 2173.0026 | E56: 2695.5806 | F56: 3423.3407
B58: Sensitivity Analysis (Equity Value per share)
B59: =B50 -> -0.05 | C59: =C50 -> -0.01 | D59: =D50 -> 0.015 | E59: =E50 -> 0.035 | F59: =F50 -> 0.055
A60: 0 | B60: =C7 -> 5.5402667 | C60: =C7 -> 5.5402667 | D60: =C7 -> 5.5402667 | E60: =C7 -> 5.5402667 | F60: =C7 -> 5.5402667
A61: =A51 -> 5 | B61: =B51/Common_Shares*$C$3*Exchange_Rate -> 5.1220316 | C61: =C51/Common_Shares*$C$3*Exchange_Rate -> 5.4542752 | D61: =D51/Common_Shares*$C$3*Exchange_Rate -> 5.671559 | E61: =E51/Common_Shares*$C$3*Exchange_Rate -> 5.8510613 | F61: =F51/Common_Shares*$C$3*Exchange_Rate -> 6.0358498
...

Sheet Scenarios
B2: Current Situation | H2: Warning: Do Not Remove this logic
B3: Selection | H3: 0 | I3: =-Market_Price -> -24.27
B4: Past Years Selected | C4: 3 | E4: Tie the business story into the three levers of value: FCFE, growth and risk. | H4: 1 | I4: =IF(ROW()-3 < $C$76, $C$77, IF(ROW()-3 = $C$76, $C$77 + $C$60, "")) -> 0.41552
H5: 2 | I5: =IF(ROW()-3 < $C$76, $C$77, IF(ROW()-3 = $C$76, $C$77 + $C$60, "")) -> 0.41552
B6: Latest | C6: =DCF!C3 -> 1000000 | E6: Prompt for fundamental Analysis | H6: 3 | I6: =IF(ROW()-3 < $C$76, $C$77, IF(ROW()-3 = $C$76, $C$77 + $C$60, "")) -> 33.645682
B7: EBIT | C7: =Normalized_FCF!G8 -> 1936 | D7: =Reporting_currency -> USD | E7: ="Please develop three logical "&C18&"-year scenarios (Base Case, Pessimistic Case, Optimistic Case) and two extreme "&C46&"-year scenarios (Success Scenario, Devil’s Advocate Scenario) for "&Thesis!C5&"("&Thesis!C11&"). Each scenario should include the Compound Growth Rate, the Probability Assessment, and the Business Narrative." -> Please develop three logical 10-year scenarios (Base Case, Pessimistic Case, Optimistic Case) and two extreme 15-year scenarios (Success Scenario, Devil’s Advocate Scenario) for Sirius XM(SIRI). Each scenario should include the Compound Growth Rate, the Probability Assessment, and the Business Narrative. | H7: 4 | I7: =IF(ROW()-3 < $C$76, $C$77, IF(ROW()-3 = $C$76, $C$77 + $C$60, ""))
B8: FCFE | C8: =Normalized_FCF!G19 -> 1080 | D8: =Reporting_currency -> USD | H8: 5 | I8: =IF(ROW()-3 < $C$76, $C$77, IF(ROW()-3 = $C$76, $C$77 + $C$60, ""))
B9: Normalized | C9: =Normalized_FCF!C19 -> 1543.9197 | D9: =Reporting_currency -> USD | H9: 6 | I9: =IF(ROW()-3 < $C$76, $C$77, IF(ROW()-3 = $C$76, $C$77 + $C$60, ""))
H10: 7 | I10: =IF(ROW()-3 < $C$76, $C$77, IF(ROW()-3 = $C$76, $C$77 + $C$60, ""))
B11: YoY CAGR | H11: 8 | I11: =IF(ROW()-3 < $C$76, $C$77, IF(ROW()-3 = $C$76, $C$77 + $C$60, ""))
B12: Sales | C12: =(Normalized_FCF!G4/OFFSET(Normalized_FCF!G4, 0, $C$4))^(1/$C$4) - 1 -> 0.00011498218 | H12: 9 | I12: =IF(ROW()-3 < $C$76, $C$77, IF(ROW()-3 = $C$76, $C$77 + $C$60, ""))
B13: Operating EBIT | C13: =(Normalized_FCF!G8/OFFSET(Normalized_FCF!G8, 0, $C$4))^(1/$C$4) - 1 -> -0.25742106 | H13: 10 | I13: =IF(ROW()-3 < $C$76, $C$77, IF(ROW()-3 = $C$76, $C$77 + $C$60, ""))
B14: FCFE | C14: =(Normalized_FCF!G19/OFFSET(Normalized_FCF!G19, 0, $C$4))^(1/$C$4) - 1 -> -0.33515235
B16: General Scenarios
B17: Assumption | E17: Guidance Note
B18: High Growth Period (HGP) | C18: 10 | E18: Fundamental analysis and market signal analysis should be combined, with fundamental analysis given priority and market signal analysis serving as a supplement. Market signal analysis predicts a company's future trend, while fundamental analysis interprets the trend and identifies relevant fundamental factors and possibilities.
B20: Reference
B21: Market Price | C21: =Market_Price -> 24.27 | D21: =Market_currency -> USD
B22: No Growth Value per share | C22: =IF(valuation_method="DCF",DCF!C12,DDM!C7) -> 30.390955 | D22: =Market_currency -> USD
B24: Base | E24: Business Story
B25: High Growth Period (HGP) | C25: =C18 -> 10
B26: High Growth Rate (HGR) | C26: 0.015
B27: Value per share | C27: =IF(valuation_method="DCF",DCF!E76,DDM!E71) -> 33.236035 | D27: =Market_currency -> USD
B28: Probabilities | C28: 0.5
B30: Pessimistic | E30: Business Story
B31: High Growth Period (HGP) | C31: =C18 -> 10
B32: High Growth Rate (HGR) | C32: -0.01
B33: Value per share | C33: =IF(valuation_method="DCF",DCF!E77,DDM!E72) -> 28.601781 | D33: =Market_currency -> USD
B34: Probabilities | C34: 0.25
B36: Optimistic | E36: Business Story
B37: High Growth Period (HGP) | C37: =C18 -> 10
B38: High Growth Rate (HGR) | C38: 0.035
B39: Value per share | C39: =IF(valuation_method="DCF",DCF!E75,DDM!E70) -> 37.357649 | D39: =Market_currency -> USD
B40: Probabilities | C40: =1-C28-C34 -> 0.25
B42: Expected Value = | C42: =C27*C28+C33*C34+C39*C40 -> 33.107875 | D42: =Market_currency -> USD
B44: Extreme Scenarios
B45: Assumption
B46: High Growth Period (HGP) | C46: 15
B48: Devil's advocate | E48: Business Story
B49: High Growth Period (HGP) | C49: =C46 -> 15
...

Sheet Breakdown
B2: Divisional Analysis (Optional)
